Workbook

Sheet Start Here
B2: Lesson 4.5
B3: Statistics & Forecasting
B4: Advanced · about 70 minutes · Bluestone Health System (fictional)
B6: What you'll learn
B7: • | C7: Summarize distributions with the Analysis ToolPak and histograms
B8: • | C8: Measure relationships with correlation and linear regression
B9: • | C9: Test differences with t-tests and quantify uncertainty with confidence intervals
B10: • | C10: Forecast volumes and monitor processes with control charts
B12: How to use this workbook
B13: 1. Read the guide | C13: The lesson guide (README) explains each skill with examples: https://github.com/lmansf/learn-excel/tree/main/04-advanced-analysis/05-statistics-forecasting
B14: 2. Practice | C14: Go to the 'Practice' sheet. Type a formula or value into each yellow cell.
B15: 3. Check yourself | C15: The Check column shows ✔ Correct (green) or ✘ Not yet (red).
B16: 4. Bonus | C16: Finished? Try the harder 'Bonus' sheet.
B17: 5. Answers | C17: The 'Answer Key' and 'Bonus Key' sheets are hidden. Right-click any sheet tab → Unhide… → pick one → OK. (Try first!)
B18: Note | C18: Several tasks can be answered with the Analysis ToolPak (Data → Data Analysis). Turn it on first: File → Options → Add-ins → Manage Excel Add-ins → Go (Mac: Tools → Excel Add-ins). The guide shows how.
B19: Note | C19: Control limits and statistical tests here are for learning process-monitoring methods, not clinical or regulatory reporting.
B21: Color legend
B22: Yellow cell | C22: Your answer goes here.
B23: ✔ Correct | C23: Your answer matches the key.
B24: ✘ Not yet | C24: Not matching yet. Check the hint and try again.
B26: Sheets in this workbook
B27: Stays | C27: Data: 400 rows, in the Excel Table 'tblStays'
B28: Bins | C28: Data: 7 rows, in the Excel Table 'tblBins'
B29: EDWaits | C29: Data: 1,628 rows, in the Excel Table 'tblEDWaits'
B30: EDDaily | C30: Data: 731 rows, in the Excel Table 'tblEDDaily'
B31: Monthly | C31: Data: 24 rows, in the Excel Table 'tblMonthly'
B32: About the data | C32: A random sample of 400 inpatient stays discharged in 2025 (200 each from Bluestone Memorial and Cedar Ridge), every Q4 2025 emergency department visit at the three hospitals with door-to-provider minutes, daily ED arrivals per hospital for 2024–2025, and 24 months of system-wide ED, LWBS, inpatient, and 30-day readmission counts.
B33: Disclaimer | C33: All people, places, and numbers are synthetic and fictional. Not clinical guidance.

Sheet Practice
A1: Lesson 4.5 · Practice
A2: Stays (rows 2–401) holds the 400 sampled inpatient stays: Bluestone Memorial in rows 2–201 and Cedar Ridge in rows 202–401. Bins (A4:A10) holds the LOS histogram bins. EDWaits holds Q4 2025 ED visits sorted by hospital. EDDaily holds one row per day from 01/01/2024 (row 2) to 12/31/2025 (row 732), with 2025 starting in row 368. Monthly holds Jan 2024 (row 2) to Dec 2025 (row 25). Answer with formulas where you can. Where a task says the ToolPak, a worksheet formula gives the same number. Each yellow cell holds one number, so wrap FREQUENCY or LINEST in INDEX there. Otherwise they spill into the cells below.
A3: Type a formula or value in each yellow cell. The Check column turns green when your answer matches. Stuck? Read the hint, then the lesson guide. Answers: right-click a sheet tab → Unhide… → 'Answer Key'.
A4: ="Score: "&COUNTIF(E6:E18,"✔*")&" of 13 auto-checked tasks correct"
A5: # | B5: Task | C5: Hint | D5: Your Answer | E5: Check
A6: 1 | B6: Run Data Analysis → Descriptive Statistics on LOSDays for all 400 stays (tick Summary statistics). What Skewness does the output report? Enter it to 2 decimal places, or use the worksheet function that calculates it. | C6: The ToolPak's Skewness row is the SKEW function | E6: =IF(IFERROR(D6="",FALSE),"",IF(IFERROR(AND(ISNUMBER(D6),OR(ABS(D6-'Answer Key'!$C$5)<=0.0051)),FALSE),"✔ Correct","✘ Not yet"))
A7: 2 | B7: Build a histogram of LOSDays (all 400 stays) using the bins on the Bins sheet, with the Histogram tool or FREQUENCY. How many stays fall in the bin labeled 6? Enter that one count. | C7: A bin's number is its upper limit. Which LOS values does that bin collect? | E7: =IF(IFERROR(D7="",FALSE),"",IF(IFERROR(AND(ISNUMBER(D7),OR(ABS(D7-'Answer Key'!$C$6)<=0.0001)),FALSE),"✔ Correct","✘ Not yet"))
A8: 3 | B8: How strongly is a patient's age related to length of stay? Calculate the correlation coefficient between Age and LOSDays for all 400 stays, to 3 decimal places. | C8: CORREL(array1, array2) | E8: =IF(IFERROR(D8="",FALSE),"",IF(IFERROR(AND(ISNUMBER(D8),OR(ABS(D8-'Answer Key'!$C$7)<=0.0006)),FALSE),"✔ Correct","✘ Not yet"))
A9: 4 | B9: Finance wants to know how much a day of stay adds to the bill. Fit a straight line that predicts TotalCharges from LOSDays (all 400 stays). What is the slope, in dollars per day? Enter it to 2 decimal places. | C9: SLOPE(known_y's, known_x's). The thing you predict goes first | E9: =IF(IFERROR(D9="",FALSE),"",IF(IFERROR(AND(ISNUMBER(D9),OR(ABS(D9-'Answer Key'!$C$8)<=0.0051)),FALSE),"✔ Correct","✘ Not yet"))
A10: 5 | B10: Using the straight line that predicts LOSDays from Age (all 400 stays), what LOS does it predict for an 80-year-old patient? Enter days to 2 decimal places. | C10: FORECAST.LINEAR(x, known_y's, known_x's), or INTERCEPT + SLOPE × 80 | E10: =IF(IFERROR(D10="",FALSE),"",IF(IFERROR(AND(ISNUMBER(D10),OR(ABS(D10-'Answer Key'!$C$9)<=0.0051)),FALSE),"✔ Correct","✘ Not yet"))
A11: 6 | B11: Is the age effect from Task 5 real, or could it be chance? Run Regression (Data Analysis) with LOSDays as the Y range and Age as the X range, or build the p-value from LINEST as in guide section 7. What p-value does it report for the Age coefficient? Enter it to 4 decimal places. | C11: t Stat = coefficient ÷ its standard error. T.DIST.2T turns t into a two-tailed p-value | E11: =IF(IFERROR(D11="",FALSE),"",IF(IFERROR(AND(ISNUMBER(D11),OR(ABS(D11-'Answer Key'!$C$10)<=6e-05)),FALSE),"✔ Correct","✘ Not yet"))
A12: 7 | B12: Finance would rather quote a range than a single number. For the TotalCharges-on-LOSDays line from Task 4, what is the lower end of the 95% confidence interval for the slope? It's the "Lower 95%" value the Regression tool reports for LOSDays. Enter dollars per day to 2 decimal places. | C12: slope − t × (standard error of the slope), where t = T.INV.2T(0.05, residual df) | E12: =IF(IFERROR(D12="",FALSE),"",IF(IFERROR(AND(ISNUMBER(D12),OR(ABS(D12-'Answer Key'!$C$11)<=0.0051)),FALSE),"✔ Correct","✘ Not yet"))
A13: 8 | B13: Do Bluestone Memorial and Cedar Ridge differ in average LOS? Run a two-tailed t-test that does not assume equal variances, comparing Memorial's LOSDays (rows 2–201) with Cedar Ridge's (rows 202–401). Enter the p-value to 3 decimal places. | C13: T.TEST(array1, array2, tails, type). Type 3 = two-sample, unequal variance | E13: =IF(IFERROR(D13="",FALSE),"",IF(IFERROR(AND(ISNUMBER(D13),OR(ABS(D13-'Answer Key'!$C$12)<=0.0006)),FALSE),"✔ Correct","✘ Not yet"))
A14: 9 | B14: Estimate Ashby Falls' true average door-to-provider time with a 95% confidence interval, using its Q4 2025 visits (EDWaits rows 1158–1383). What is the interval's half-width (the ± margin), in minutes to 2 decimal places? Blank cells are patients who left without being seen. | C14: CONFIDENCE.T(alpha, standard_dev, size). Alpha for 95% is 0.05 | E14: =IF(IFERROR(D14="",FALSE),"",IF(IFERROR(AND(ISNUMBER(D14),OR(ABS(D14-'Answer Key'!$C$13)<=0.0051)),FALSE),"✔ Correct","✘ Not yet"))
A15: 10 | B15: A trailing 7-day moving average smooths out the weekday pattern. What was the 7-day moving average of Memorial's daily arrivals on 02/25/2025 (that day and the 6 days before it)? Enter it to 2 decimal places. | C15: 02/25/2025 is EDDaily row 423. Average 7 rows ending there | E15: =IF(IFERROR(D15="",FALSE),"",IF(IFERROR(AND(ISNUMBER(D15),OR(ABS(D15-'Answer Key'!$C$14)<=0.0051)),FALSE),"✔ Correct","✘ Not yet"))
A16: 11 | B16: Fit a linear trend to the 24 monthly EDVisits values, using MonthNum (1–24) as x. What does it forecast for month 25 (January 2026)? Enter it to 1 decimal place. | C16: FORECAST.LINEAR(x, known_y's, known_x's) | E16: =IF(IFERROR(D16="",FALSE),"",IF(IFERROR(AND(ISNUMBER(D16),OR(ABS(D16-'Answer Key'!$C$15)<=0.051)),FALSE),"✔ Correct","✘ Not yet"))
A17: 12 | B17: Build an individuals (I) chart for Memorial's daily arrivals with 2024 as the baseline (EDDaily rows 2–367). The moving ranges are the absolute day-to-day changes, σ̂ = average moving range ÷ 1.128, and UCL = mean + 3 × σ̂. What is the UCL? Enter it to 2 decimal places. | C17: Average |today − yesterday| over 2024, divide by 1.128, triple it, add the mean | E17: =IF(IFERROR(D17="",FALSE),"",IF(IFERROR(AND(ISNUMBER(D17),OR(ABS(D17-'Answer Key'!$C$16)<=0.0051)),FALSE),"✔ Correct","✘ Not yet"))
A18: 13 | B18: Monitor 2025 against the 2024 limits. On how many days in 2025 (EDDaily rows 368–732) did Memorial's arrivals exceed the UCL from Task 12? | C18: COUNTIF with ">"& your Task 12 cell (D17) | E18: =IF(IFERROR(D18="",FALSE),"",IF(IFERROR(AND(ISNUMBER(D18),OR(ABS(D18-'Answer Key'!$C$17)<=0.0001)),FALSE),"✔ Correct","✘ Not yet"))

Sheet Stays
A1: EncounterID | B1: Facility | C1: DischargeDate | D1: Age | E1: DxCategory | F1: LOSDays | G1: TotalCharges
A2: ENC110372 | B2: Bluestone Memorial | C2: 45660 | D2: 69 | E2: Infectious | F2: 12 | G2: 137793.93
A3: ENC110504 | B3: Bluestone Memorial | C3: 45660 | D3: 73 | E3: Infectious | F3: 9 | G3: 66350.71
A4: ENC110810 | B4: Bluestone Memorial | C4: 45662 | D4: 43 | E4: Pregnancy | F4: 2 | G4: 11479.66
A5: ENC110821 | B5: Bluestone Memorial | C5: 45662 | D5: 43 | E5: Pregnancy | F5: 2 | G5: 19238.72
A6: ENC110669 | B6: Bluestone Memorial | C6: 45663 | D6: 58 | E6: Infectious | F6: 6 | G6: 65357.42
A7: ENC110685 | B7: Bluestone Memorial | C7: 45665 | D7: 47 | E7: Respiratory | F7: 8 | G7: 71535.8
A8: ENC110749 | B8: Bluestone Memorial | C8: 45668 | D8: 46 | E8: Respiratory | F8: 9 | G8: 81781.81
A9: ENC111152 | B9: Bluestone Memorial | C9: 45672 | D9: 56 | E9: Respiratory | F9: 2 | G9: 11711.1
A10: ENC111168 | B10: Bluestone Memorial | C10: 45673 | D10: 74 | E10: Endocrine | F10: 3 | G10: 17460.99
A11: ENC111104 | B11: Bluestone Memorial | C11: 45674 | D11: 55 | E11: Circulatory | F11: 6 | G11: 110148.87
A12: ENC111252 | B12: Bluestone Memorial | C12: 45674 | D12: 2 | E12: Infectious | F12: 2 | G12: 9278.94
A13: ENC111181 | B13: Bluestone Memorial | C13: 45675 | D13: 67 | E13: Endocrine | F13: 5 | G13: 18532.7
... A401: ENC121693 | B401: Cedar Ridge | C401: 46020 | D401: 62 | E401: Circulatory | F401: 3 | G401: 27034.35

Sheet Bins
A1: Bin range for the LOS histogram (Task 2)
A2: Bin upper limits. Use A4:A10 with FREQUENCY, or start the Histogram tool from this sheet (see the guide).
A3: LOSBin
A4: 2
A5: 4
A6: 6
A7: 8
A8: 10
A9: 12
A10: 14

Sheet EDWaits
A1: EDVisitID | B1: Facility | C1: ArrivalDateTime | D1: ESILevel | E1: DoorToProviderMin
A2: ED210665 | B2: Bluestone Memorial | C2: 45931.134 | D2: 3 | E2: 52
A3: ED210666 | B3: Bluestone Memorial | C3: 45931.36 | D3: 4 | E3: 33
A4: ED210667 | B4: Bluestone Memorial | C4: 45931.381 | D4: 3 | E4: 52
A5: ED210668 | B5: Bluestone Memorial | C5: 45931.418 | D5: 3 | E5: 61
A6: ED210670 | B6: Bluestone Memorial | C6: 45931.436 | D6: 3 | E6: 105
A7: ED210671 | B7: Bluestone Memorial | C7: 45931.507 | D7: 4 | E7: 74
A8: ED210672 | B8: Bluestone Memorial | C8: 45931.538 | D8: 4 | E8: 36
A9: ED210673 | B9: Bluestone Memorial | C9: 45931.557 | D9: 4 | E9: 38
A10: ED210675 | B10: Bluestone Memorial | C10: 45931.696 | D10: 2 | E10: 25
A11: ED210678 | B11: Bluestone Memorial | C11: 45931.816 | D11: 3 | E11: 114
A12: ED210679 | B12: Bluestone Memorial | C12: 45932.037 | D12: 3 | E12: 51
A13: ED210680 | B13: Bluestone Memorial | C13: 45932.29 | D13: 2 | E13: 31
... A35: ED210716 | B35: Bluestone Memorial | C35: 45934.278 | D35: 4 | E35: 30
A36: ED210717 | B36: Bluestone Memorial | C36: 45934.377 | D36: 4
A37: ED210719 | B37: Bluestone Memorial | C37: 45934.507 | D37: 3 | E37: 65
A38: ED210720 | B38: Bluestone Memorial | C38: 45934.594 | D38: 3 | E38: 85
A39: ED210721 | B39: Bluestone Memorial | C39: 45934.627 | D39: 2 | E39: 42
A40: ED210722 | B40: Bluestone Memorial | C40: 45934.683 | D40: 1 | E40: 3
A41: ED210723 | B41: Bluestone Memorial | C41: 45934.719 | D41: 4 | E41: 136
A42: ED210724 | B42: Bluestone Memorial | C42: 45934.72 | D42: 3 | E42: 99
A43: ED210725 | B43: Bluestone Memorial | C43: 45934.738 | D43: 4 | E43: 40
A44: ED210726 | B44: Bluestone Memorial | C44: 45934.771 | D44: 3 | E44: 96
A45: ED210727 | B45: Bluestone Memorial | C45: 45934.777 | D45: 3 | E45: 88
A46: ED210728 | B46: Bluestone Memorial | C46: 45934.791 | D46: 4 | E46: 40
A47: ED210730 | B47: Bluestone Memorial | C47: 45934.867 | D47: 5 | E47: 86
A48: ED210731 | B48: Bluestone Memorial | C48: 45934.933 | D48: 5 | E48: 87
... A71: ED210764 | B71: Bluestone Memorial | C71: 45936.758 | D71: 3 | E71: 31
A72: ED210765 | B72: Bluestone Memorial | C72: 45936.782 | D72: 3
A73: ED210766 | B73: Bluestone Memorial | C73: 45936.908 | D73: 2 | E73: 18
A74: ED210767 | B74: Bluestone Memorial | C74: 45936.951 | D74: 5 | E74: 41
A75: ED210768 | B75: Bluestone Memorial | C75: 45937.022 | D75: 5 | E75: 81
A76: ED210769 | B76: Bluestone Memorial | C76: 45937.064 | D76: 3 | E76: 21
A77: ED210770 | B77: Bluestone Memorial | C77: 45937.219 | D77: 4 | E77: 22
A78: ED210771 | B78: Bluestone Memorial | C78: 45937.347 | D78: 5 | E78: 45
A79: ED210776 | B79: Bluestone Memorial | C79: 45937.684 | D79: 2 | E79: 18
A80: ED210777 | B80: Bluestone Memorial | C80: 45937.693 | D80: 5 | E80: 67
A81: ED210778 | B81: Bluestone Memorial | C81: 45937.698 | D81: 3 | E81: 16
A82: ED210779 | B82: Bluestone Memorial | C82: 45937.704 | D82: 2 | E82: 29
A83: ED210780 | B83: Bluestone Memorial | C83: 45937.861 | D83: 2 | E83: 10
...

Sheet EDDaily
A1: Date | B1: Weekday | C1: Memorial | D1: AshbyFalls | E1: CedarRidge | F1: AllEDs
A2: 45292 | B2: Mon | C2: 12 | D2: 1 | E2: 4 | F2: 17
A3: 45293 | B3: Tue | C3: 16 | D3: 4 | E3: 2 | F3: 22
A4: 45294 | B4: Wed | C4: 21 | D4: 2 | E4: 2 | F4: 25
A5: 45295 | B5: Thu | C5: 19 | D5: 3 | E5: 1 | F5: 23
A6: 45296 | B6: Fri | C6: 11 | D6: 6 | E6: 6 | F6: 23
A7: 45297 | B7: Sat | C7: 15 | D7: 2 | E7: 1 | F7: 18
A8: 45298 | B8: Sun | C8: 13 | D8: 5 | E8: 1 | F8: 19
A9: 45299 | B9: Mon | C9: 17 | D9: 4 | E9: 2 | F9: 23
A10: 45300 | B10: Tue | C10: 10 | D10: 4 | E10: 1 | F10: 15
A11: 45301 | B11: Wed | C11: 7 | D11: 2 | E11: 3 | F11: 12
A12: 45302 | B12: Thu | C12: 8 | D12: 2 | E12: 5 | F12: 15
A13: 45303 | B13: Fri | C13: 13 | D13: 1 | E13: 5 | F13: 19
... A732: 46022 | B732: Wed | C732: 12 | D732: 2 | E732: 1 | F732: 15

Sheet Monthly
A1: MonthStart | B1: MonthNum | C1: EDVisits | D1: LWBS | E1: InpatientDischarges | F1: IndexStays | G1: Readmits30
A2: 45292 | B2: 1 | C2: 580 | D2: 15 | E2: 233 | F2: 226 | G2: 25
A3: 45323 | B3: 2 | C3: 586 | D3: 21 | E3: 228 | F3: 222 | G3: 37
A4: 45352 | B4: 3 | C4: 579 | D4: 14 | E4: 256 | F4: 253 | G4: 33
A5: 45383 | B5: 4 | C5: 466 | D5: 10 | E5: 200 | F5: 196 | G5: 22
A6: 45413 | B6: 5 | C6: 477 | D6: 9 | E6: 227 | F6: 222 | G6: 23
A7: 45444 | B7: 6 | C7: 422 | D7: 3 | E7: 188 | F7: 186 | G7: 28
A8: 45474 | B8: 7 | C8: 444 | D8: 7 | E8: 235 | F8: 233 | G8: 23
A9: 45505 | B9: 8 | C9: 469 | D9: 9 | E9: 206 | F9: 203 | G9: 38
A10: 45536 | B10: 9 | C10: 403 | D10: 15 | E10: 183 | F10: 177 | G10: 25
A11: 45566 | B11: 10 | C11: 466 | D11: 8 | E11: 225 | F11: 219 | G11: 36
A12: 45597 | B12: 11 | C12: 562 | D12: 8 | E12: 233 | F12: 226 | G12: 40
A13: 45627 | B13: 12 | C13: 621 | D13: 18 | E13: 267 | F13: 261 | G13: 37
... A25: 45992 | B25: 24 | C25: 595 | D25: 19 | E25: 310 | F25: 306 | G25: 23

Sheet Bonus
A1: Lesson 4.5 · Bonus: Is the readmission rate out of control?
A2: The quality committee wants a p-chart of Bluestone's system-wide 30-day readmission rate by discharge month, January 2024 to December 2025 (Monthly sheet, rows 2–25). For each month, n = IndexStays (inpatient discharges of patients who didn't die) and the rate = Readmits30 ÷ IndexStays. The center line p̄ = total readmissions ÷ total index stays, and each month gets its own limits: p̄ ± 3 × √(p̄ × (1 − p̄) ÷ n). Your B1 answer lands in cell D6 of this sheet, so later parts can refer to it. Helper columns for each month's rate, UCL, and LCL make this much easier. Put them in empty columns to the right of the Monthly table.
A3: Type a formula or value in each yellow cell. The Check column turns green when your answer matches. Stuck? Read the hint, then the lesson guide. Answers: right-click a sheet tab → Unhide… → 'Bonus Key'.
A4: ="Score: "&COUNTIF(E6:E10,"✔*")&" of 5 auto-checked tasks correct"
A5: # | B5: Task | C5: Hint | D5: Your Answer | E5: Check
A6: B1 | B6: What is the center line p̄ for all 24 months? Enter it as a percentage to 2 decimal places. | C6: Total readmissions ÷ total index stays. Don't average the 24 monthly rates | E6: =IF(IFERROR(D6="",FALSE),"",IF(IFERROR(AND(ISNUMBER(D6),OR(ABS(D6-'Bonus Key'!$C$5)<=0.00051,ABS(D6-'Bonus Key'!$C$5*100)<=0.051000000000000004)),FALSE),"✔ Correct","✘ Not yet"))
A7: B2 | B7: September 2024 had the fewest index stays (177). What is its upper control limit? Enter it as a percentage to 2 decimal places. | C7: p̄ + 3 × SQRT(p̄ × (1 − p̄) / n), with this month's n | E7: =IF(IFERROR(D7="",FALSE),"",IF(IFERROR(AND(ISNUMBER(D7),OR(ABS(D7-'Bonus Key'!$C$6)<=0.00051,ABS(D7-'Bonus Key'!$C$6*100)<=0.051000000000000004)),FALSE),"✔ Correct","✘ Not yet"))
A8: B3 | B8: How many of the 24 months fall outside their control limits (above the UCL or below the LCL)? | C8: Compare each month's rate with its own limits. Add helper columns for the rate, UCL, LCL, and a TRUE/FALSE flag, then COUNTIF the flags. One SUMPRODUCT also works | E8: =IF(IFERROR(D8="",FALSE),"",IF(IFERROR(AND(ISNUMBER(D8),OR(ABS(D8-'Bonus Key'!$C$7)<=0.0001)),FALSE),"✔ Correct","✘ Not yet"))
A9: B4 | B9: Which month is it? Enter its MonthStart date. | C9: Read it off your helper columns, or XLOOKUP(TRUE, your test, the MonthStart column) | E9: =IF(IFERROR(D9="",FALSE),"",IF(IFERROR(AND(ISNUMBER(D9),INT(D9)=INT('Bonus Key'!$C$8)),FALSE),"✔ Correct","✘ Not yet"))
A10: B5 | B10: Drop December 2025 and recompute p̄ from the other 23 months (rows 2–24). The highest remaining month is February 2025 (row 15). How many standard errors above the new center line is it? Calculate z = (rate − p̄) ÷ √(p̄ × (1 − p̄) ÷ n) and enter it to 2 decimal places. | C10: LET(p, new p̄, n, that month's IndexStays, (rate − p) / SQRT(p*(1−p)/n)) | E10: =IF(IFERROR(D10="",FALSE),"",IF(IFERROR(AND(ISNUMBER(D10),OR(ABS(D10-'Bonus Key'!$C$9)<=0.0051)),FALSE),"✔ Correct","✘ Not yet"))

Sheet Answer Key
A1: 🔑 Answer Key — Lesson 4.5
A2: Spoiler alert: try every task before reading this sheet. Column C is the value the Check column compares against. Column D is a sample solution, and column E recalculates a formula for it live, proving the answer.
A4: # | B4: Task | C4: Answer | D4: Sample solution | E4: Live result | F4: Explanation
A5: 1 | B5: Run Data Analysis → Descriptive Statistics on LOSDays for all 400 stays (tick Summary statistics). What Skewness does the output report? Enter it to 2 decimal places, or use the worksheet function that calculates it. | C5: 1.7806483 | D5: =SKEW(Stays!F2:F401) | E5: {=SKEW(Stays!F2:F401)} | F5: Skewness measures how lopsided a distribution is. Zero means symmetric, and a positive value means a long tail to the right. LOS has a skewness of 1.78, because most stays are short (median 4 days) while a few run to 19 days. The ToolPak's Descriptive Statistics output is a block of typed-in numbers, not formulas, so it won't update if the data changes. SKEW will. The output's Kurtosis row (4.65) is KURT. A positive value means heavier tails than a bell curve.
A6: 2 | B6: Build a histogram of LOSDays (all 400 stays) using the bins on the Bins sheet, with the Histogram tool or FREQUENCY. How many stays fall in the bin labeled 6? Enter that one count. | C6: 92 | D6: =INDEX(FREQUENCY(Stays!F2:F401,Bins!A4:A10),3) | E6: {=INDEX(FREQUENCY(Stays!F2:F401,Bins!A4:A10),3)} | F6: Each bin counts the values above the previous limit, up to and including its own limit. Bin 6 therefore counts stays of 5 or 6 days: more than 4, at most 6. FREQUENCY returns one count per bin plus a final "More" count (5 stays over 14 days), and INDEX picks count number 3. =COUNTIFS(Stays!F2:F401,">4",Stays!F2:F401,"<=6") gives the same 92. If you read the label as "6 to 7 days" you'd get 66, which is the most common histogram mistake.
A7: 3 | B7: How strongly is a patient's age related to length of stay? Calculate the correlation coefficient between Age and LOSDays for all 400 stays, to 3 decimal places. | C7: 0.12989914 | D7: =CORREL(Stays!D2:D401,Stays!F2:F401) | E7: {=CORREL(Stays!D2:D401,Stays!F2:F401)} | F7: r = 0.130 is a weak positive correlation. Older patients stay slightly longer on average, but the scatter plot is a cloud, not a line. Squaring r gives R² = 0.017, so age accounts for only about 1.7% of the variation in LOS. PEARSON returns the same value, and the order of the two ranges doesn't matter for correlation.
A8: 4 | B8: Finance wants to know how much a day of stay adds to the bill. Fit a straight line that predicts TotalCharges from LOSDays (all 400 stays). What is the slope, in dollars per day? Enter it to 2 decimal places. | C8: 6665.4258 | D8: =SLOPE(Stays!G2:G401,Stays!F2:F401) | E8: {=SLOPE(Stays!G2:G401,Stays!F2:F401)} | F8: Each extra day of stay goes with about $6,665.43 more in charges. The line is Charges = $2,600.11 + $6,665.43 × LOSDays, and =INTERCEPT(Stays!G2:G401,Stays!F2:F401) gives the intercept. =RSQ(Stays!G2:G401,Stays!F2:F401) gives R² = 43.8%, so LOS explains a little under half of the stay-to-stay differences in charges. The rest comes from diagnosis, procedures, ICU days, and so on. Swapping the arguments gives the slope of LOS on charges (0.000066 days per dollar), which answers a different question. SLOPE always takes the y-values (the outcome) first.
A9: 5 | B9: Using the straight line that predicts LOSDays from Age (all 400 stays), what LOS does it predict for an 80-year-old patient? Enter days to 2 decimal places. | C9: 5.1060155 | D9: =FORECAST.LINEAR(80,Stays!F2:F401,Stays!D2:D401) | E9: {=_xlfn.FORECAST.LINEAR(80,Stays!F2:F401,Stays!D2:D401)} | F9: The line is LOS = 3.726 + 0.0173 × Age, so at age 80 it predicts 5.11 days. That's the average LOS the line expects for 80-year-olds, not a forecast for one patient. The typical miss around the line (STEYX) is 2.80 days, far more than the 0.52-day difference the line predicts between a 50-year-old and an 80-year-old. =TREND(Stays!F2:F401,Stays!D2:D401,80) and =INTERCEPT(Stays!F2:F401,Stays!D2:D401)+SLOPE(Stays!F2:F401,Stays!D2:D401)*80 give the same result. The older FORECAST function does too.
A10: 6 | B10: Is the age effect from Task 5 real, or could it be chance? Run Regression (Data Analysis) with LOSDays as the Y range and Age as the X range, or build the p-value from LINEST as in guide section 7. What p-value does it report for the Age coefficient? Enter it to 4 decimal places. | C10: 0.0092984734 | D10: =LET(fit,LINEST(Stays!F2:F401,Stays!D2:D401,TRUE,TRUE),tstat,INDEX(fit,1,1)/INDEX(fit,2,1),T.DIST.2T(ABS(tstat),INDEX(fit,4,2))) | E10: {=_xlfn.LET(_xlpm.fit,LINEST(Stays!F2:F401,Stays!D2:D401,TRUE,TRUE),_xlpm.tstat,INDEX(_xlpm.fit,1,1)/INDEX(_xlpm.fit,2,1),_xlfn.T.DIST.2T(ABS(_xlpm.tstat),INDEX(_xlpm.fit,4,2)))} | F10: With stats set to TRUE, LINEST returns a 5 × 2 block: row 1 holds the slope (0.0173) and intercept, row 2 their standard errors (0.0066 for the slope), and row 4 column 2 the residual degrees of freedom (398). The t Stat is 0.0173 ÷ 0.0066 = 2.61, and T.DIST.2T gives p = 0.0093. That's below 0.05, so the slope is statistically significant: a true slope of zero would rarely produce a sample like this one. Yet R² is only 1.7%, so age explains almost none of the variation in LOS. Significant means "probably not zero," not "large" or "useful." Without LET (Excel 2019 and earlier), write =T.DIST.2T(ABS(INDEX(LINEST(Stays!F2:F401,Stays!D2:D401,TRUE,TRUE),1,1)/INDEX(LINEST(Stays!F2:F401,Stays!D2:D401,TRUE,TRUE),2,1)),INDEX(LINEST(Stays!F2:F401,Stays!D2:D401,TRUE,TRUE),4,2)).
A11: 7 | B11: Finance would rather quote a range than a single number. For the TotalCharges-on-LOSDays line from Task 4, what is the lower end of the 95% confidence interval for the slope? It's the "Lower 95%" value the Regression tool reports for LOSDays. Enter dollars per day to 2 decimal places. | C11: 5920.6586 | D11: =LET(fit,LINEST(Stays!G2:G401,Stays!F2:F401,TRUE,TRUE),INDEX(fit,1,1)-T.INV.2T(0.05,INDEX(fit,4,2))*INDEX(fit,2,1)) | E11: {=_xlfn.LET(_xlpm.fit,LINEST(Stays!G2:G401,Stays!F2:F401,TRUE,TRUE),INDEX(_xlpm.fit,1,1)-_xlfn.T.INV.2T(0.05,INDEX(_xlpm.fit,4,2))*INDEX(_xlpm.fit,2,1))} | F11: The slope is $6,665.43 with a standard error of $378.83. With 398 residual degrees of freedom, T.INV.2T(0.05,398) = 1.9659, so the interval is $6,665.43 ± 1.9659 × $378.83, which runs from $5,920.66 to $7,410.19 per day. Finance can say each extra day goes with roughly $5,921 to $7,410 more in charges. It's the same t × standard error recipe CONFIDENCE.T uses for a mean (guide section 9), applied to a slope. Without LET, repeat the LINEST call inside each INDEX.
A12: 8 | B12: Do Bluestone Memorial and Cedar Ridge differ in average LOS? Run a two-tailed t-test that does not assume equal variances, comparing Memorial's LOSDays (rows 2–201) with Cedar Ridge's (rows 202–401). Enter the p-value to 3 decimal places. | C12: 0.51324885 | D12: =T.TEST(Stays!F2:F201,Stays!F202:F401,2,3) | E12: {=_xlfn.T.TEST(Stays!F2:F201,Stays!F202:F401,2,3)} | F12: The sample means are 4.845 days (Memorial) and 4.660 days (Cedar Ridge), a difference of 0.185 days. T.TEST returns the p-value directly: 0.513. If the hospitals' true averages were equal, random sampling alone would produce a gap at least this large about 51% of the time, so you can't conclude they differ. That's not proof they're the same, only that this sample can't tell them apart. A one-tailed test (tails = 1) gives half the p-value (0.257). Type 2 (equal variances) gives 0.513 too, because with equal group sizes both tests use the same t statistic (0.654) and differ only slightly in degrees of freedom. The ToolPak's "t-Test: Two-Sample Assuming Unequal Variances" reports the same value as P(T<=t) two-tail.
A13: 9 | B13: Estimate Ashby Falls' true average door-to-provider time with a 95% confidence interval, using its Q4 2025 visits (EDWaits rows 1158–1383). What is the interval's half-width (the ± margin), in minutes to 2 decimal places? Blank cells are patients who left without being seen. | C13: 6.0903228 | D13: =CONFIDENCE.T(0.05,STDEV.S(EDWaits!E1158:E1383),COUNT(EDWaits!E1158:E1383)) | E13: {=_xlfn.CONFIDENCE.T(0.05,_xlfn.STDEV.S(EDWaits!E1158:E1383),COUNT(EDWaits!E1158:E1383))} | F13: 217 patients saw a provider. Their mean wait was 49.15 minutes with a standard deviation of 45.52. The margin is t × s ÷ √n = 1.9710 × 45.52 ÷ √217 = 6.09, so the 95% confidence interval is 43.1 to 55.2 minutes. Use COUNT, not ROWS: ROWS also counts the 9 blank rows, which aren't measurements, and gives 5.97. COUNTA agrees with COUNT here only because the blank cells are truly empty. It would also count a text entry such as "LWBS" if an export had one. CONFIDENCE.NORM (and the old CONFIDENCE) uses 1.96 instead of t and gives 6.06, slightly too narrow. The ToolPak's "Confidence Level(95.0%)" row is CONFIDENCE.T.
A14: 10 | B14: A trailing 7-day moving average smooths out the weekday pattern. What was the 7-day moving average of Memorial's daily arrivals on 02/25/2025 (that day and the 6 days before it)? Enter it to 2 decimal places. | C14: 17.571429 | D14: =AVERAGE(EDDaily!C417:C423) | E14: {=AVERAGE(EDDaily!C417:C423)} | F14: Rows 417–423 cover 02/19 through 02/25/2025, one of each weekday, so the Monday peak and the weekend dip cancel out. 17.57 arrivals a day was the highest 7-day average of 2025, against a 2025 daily mean of 12.17. A centered average (3 days either side) gives 14.86 for this date. Trailing averages are what you can calculate today, and centered ones are for describing the past. The ToolPak's Moving Average tool and a chart's Moving Average trendline are both trailing.
A15: 11 | B15: Fit a linear trend to the 24 monthly EDVisits values, using MonthNum (1–24) as x. What does it forecast for month 25 (January 2026)? Enter it to 1 decimal place. | C15: 510.14493 | D15: =FORECAST.LINEAR(25,Monthly!C2:C25,Monthly!B2:B25) | E15: {=_xlfn.FORECAST.LINEAR(25,Monthly!C2:C25,Monthly!B2:B25)} | F15: The trend line is almost flat (slope -0.16 visits a month, R² = 0.0003), so the forecast is close to the 24-month average of 512.2. But winter is the busy season: the two Januaries had 580 and 631 visits, and the two Decembers 621 and 595. A straight line can't see seasons, so it under-forecasts winter and over-forecasts summer. A seasonal index or FORECAST.ETS (see the guide) handles that. =TREND(…,…,25) gives the same number as FORECAST.LINEAR.
A16: 12 | B16: Build an individuals (I) chart for Memorial's daily arrivals with 2024 as the baseline (EDDaily rows 2–367). The moving ranges are the absolute day-to-day changes, σ̂ = average moving range ÷ 1.128, and UCL = mean + 3 × σ̂. What is the UCL? Enter it to 2 decimal places. | C16: 22.804993 | D16: =AVERAGE(EDDaily!C2:C367)+3*SUMPRODUCT(ABS(EDDaily!C3:C367-EDDaily!C2:C366))/COUNT(EDDaily!C3:C367)/1.128 | E16: {=AVERAGE(EDDaily!C2:C367)+3*SUMPRODUCT(ABS(EDDaily!C3:C367-EDDaily!C2:C366))/COUNT(EDDaily!C3:C367)/1.128} | F16: 2024 averaged 11.773 arrivals a day. The 365 moving ranges average 4.148, so σ̂ = 4.148 ÷ 1.128 = 3.677 and UCL = 11.773 + 3 × 3.677 = 22.80. The LCL is 0.74. Many references write this as mean ± 2.66 × MR̄, which is the same thing, because 3 ÷ 1.128 ≈ 2.66. A helper column of =ABS(C3-C2) filled down and averaged works too. The moving range measures short-term, day-to-day noise, so a slow seasonal swing doesn't widen the limits the way STDEV.S does (it would put the UCL at 23.35).
A17: 13 | B17: Monitor 2025 against the 2024 limits. On how many days in 2025 (EDDaily rows 368–732) did Memorial's arrivals exceed the UCL from Task 12? | C17: 4 | D17: =COUNTIF(EDDaily!C368:C732,">"&D17) | E17: {=COUNTIF(EDDaily!C368:C732,">"&(AVERAGE(EDDaily!C2:C367)+3*SUMPRODUCT(ABS(EDDaily!C3:C367-EDDaily!C2:C366))/COUNT(EDDaily!C3:C367)/1.128))} | F17: 4 days broke the limit: 02/19 (24), 05/02 (23), 12/08 (24), 12/23 (23). Each is a special-cause signal worth a look, and in an ED the usual causes are respiratory season, a mass-casualty event, or a neighboring ED on diversion. No day fell below the LCL. Freezing the limits from a baseline year is standard practice: if you recalculate them with the new data, a lasting change gets absorbed into the limits. Limits from STDEV.S would flag only 2 days.

Sheet Bonus Key
A1: 🔑 Bonus Key — Lesson 4.5
A2: Spoiler alert: try every task before reading this sheet. Column C is the value the Check column compares against. Column D is a sample solution, and column E recalculates a formula for it live, proving the answer.
A4: # | B4: Task | C4: Answer | D4: Sample solution | E4: Live result | F4: Explanation
A5: B1 | B5: What is the center line p̄ for all 24 months? Enter it as a percentage to 2 decimal places. | C5: 0.14617212 | D5: =SUM(Monthly!G2:G25)/SUM(Monthly!F2:F25) | E5: {=SUM(Monthly!G2:G25)/SUM(Monthly!F2:F25)} | F5: 800 readmissions ÷ 5,473 index stays = 14.62%. Averaging the 24 monthly rates gives 14.66% instead, because it weights a small month the same as a big one. A rate for a period is total ÷ total (Lesson 1.4).
A6: B2 | B6: September 2024 had the fewest index stays (177). What is its upper control limit? Enter it as a percentage to 2 decimal places. | C6: 0.22583427 | D6: =D6+3*SQRT(D6*(1-D6)/Monthly!F10) | E6: {=(SUM(Monthly!G2:G25)/SUM(Monthly!F2:F25))+3*SQRT((SUM(Monthly!G2:G25)/SUM(Monthly!F2:F25))*(1-(SUM(Monthly!G2:G25)/SUM(Monthly!F2:F25)))/Monthly!F10)} | F6: √(0.1462 × 0.8538 ÷ 177) = 0.0266, so the UCL is 0.1462 + 3 × that = 22.58%. The biggest month (Dec 2025, n = 306) gets a UCL of 20.68%. Smaller months get wider limits because a rate from fewer patients bounces around more. That's why a p-chart's limit lines look like a staircase.
A7: B3 | B7: How many of the 24 months fall outside their control limits (above the UCL or below the LCL)? | C7: 1 | D7: =SUMPRODUCT(--(ABS(Monthly!G2:G25/Monthly!F2:F25-D6)>3*SQRT(D6*(1-D6)/Monthly!F2:F25))) | E7: {=SUMPRODUCT(--(ABS(Monthly!G2:G25/Monthly!F2:F25-(SUM(Monthly!G2:G25)/SUM(Monthly!F2:F25)))>3*SQRT((SUM(Monthly!G2:G25)/SUM(Monthly!F2:F25))*(1-(SUM(Monthly!G2:G25)/SUM(Monthly!F2:F25)))/Monthly!F2:F25)))} | F7: Only one month signals, and it falls below its LCL. No month is above its UCL. ABS(rate − p̄) > 3σ catches both directions in one test because every LCL here is above zero. When n is small, p̄ − 3σ can go negative and the LCL is set to 0, so test the two sides separately. With helper columns on the Monthly sheet: Rate =G2/F2, UCL =Bonus!$D$6+3*SQRT(Bonus!$D$6*(1-Bonus!$D$6)/F2), LCL the same with − instead of +, and a flag column that tests whether the rate is above the UCL or below the LCL. Then COUNTIF the flags.
A8: B4 | B8: Which month is it? Enter its MonthStart date. | C8: 45992 | D8: =XLOOKUP(TRUE,ABS(Monthly!G2:G25/Monthly!F2:F25-D6)>3*SQRT(D6*(1-D6)/Monthly!F2:F25),Monthly!A2:A25) | E8: {=_xlfn.XLOOKUP(TRUE,ABS(Monthly!G2:G25/Monthly!F2:F25-(SUM(Monthly!G2:G25)/SUM(Monthly!F2:F25)))>3*SQRT((SUM(Monthly!G2:G25)/SUM(Monthly!F2:F25))*(1-(SUM(Monthly!G2:G25)/SUM(Monthly!F2:F25)))/Monthly!F2:F25),Monthly!A2:A25)} | F8: December 2025: 23 readmissions out of 306 index stays = 7.52%, below its LCL of 8.56%. Before anyone celebrates, ask why. The data ends on 12/31/2025, so a patient discharged on 12/20 has only 11 days of follow-up in the data, and any readmission in January 2026 hasn't happened yet. December's rate is low because the 30-day window isn't complete. That's a data artifact, not an improvement. Excluding months with incomplete follow-up is standard for readmission reporting.
A9: B5 | B9: Drop December 2025 and recompute p̄ from the other 23 months (rows 2–24). The highest remaining month is February 2025 (row 15). How many standard errors above the new center line is it? Calculate z = (rate − p̄) ÷ √(p̄ × (1 − p̄) ÷ n) and enter it to 2 decimal places. | C9: 1.9314724 | D9: =LET(p,SUM(Monthly!G2:G24)/SUM(Monthly!F2:F24),n,Monthly!F15,(Monthly!G15/n-p)/SQRT(p*(1-p)/n)) | E9: {=_xlfn.LET(_xlpm.p,SUM(Monthly!G2:G24)/SUM(Monthly!F2:F24),_xlpm.n,Monthly!F15,(Monthly!G15/_xlpm.n-_xlpm.p)/SQRT(_xlpm.p*(1-_xlpm.p)/_xlpm.n))} | F9: The corrected p̄ is 15.04%, higher than 14.62% because the artificially low December no longer drags it down. February 2025's rate of 19.15% is z = 1.93 standard errors above it (it was 2.15 against the old center line). A point is a special-cause signal only beyond ±3, so every month is inside the limits: readmissions are stable, showing common-cause variation only. The chart says the committee shouldn't react to any single month. To lower the rate, change the process (discharge planning, follow-up calls) and then watch for a shift, such as 8 months in a row below the center line.
