Workbook

Sheet Start Here
B2: Lesson 2.4
B3: Math & Statistical Functions
B4: Beginner → Intermediate · about 100 minutes · Bluestone Health System (fictional)
B6: What you'll learn
B7: • | C7: Round correctly with ROUND, ROUNDUP, ROUNDDOWN, MROUND, CEILING.MATH, and FLOOR.MATH
B8: • | C8: Use INT, TRUNC, MOD, ABS, and SUMPRODUCT
B9: • | C9: Describe data with MEDIAN, MODE, STDEV, PERCENTILE, and QUARTILE — and know when the mean misleads
B10: • | C10: Rank and pick extremes with RANK.EQ, LARGE, and SMALL
B12: How to use this workbook
B13: 1. Read the guide | C13: The lesson guide (README) explains each skill with examples: https://github.com/lmansf/learn-excel/tree/main/02-formulas-functions/04-math-statistical-functions
B14: 2. Practice | C14: Go to the 'Practice' sheet. Type a formula or value into each yellow cell. For task 10, fill the yellow AgeBand column on the Stays sheet instead, and the task's gray cell on Practice reads it.
B15: 3. Check yourself | C15: The Check column shows ✔ Correct (green) or ✘ Not yet (red).
B16: 4. Bonus | C16: Finished? Try the harder 'Bonus' sheet.
B17: 5. Answers | C17: The 'Answer Key' and 'Bonus Key' sheets are hidden. Right-click any sheet tab → Unhide… → pick one → OK. (Try first!)
B18: Note | C18: The vancomycin vial rule in this lesson is a simplified teaching assumption, not pharmacy guidance.
B20: Color legend
B21: Yellow cell | C21: Your answer goes here.
B22: Gray cell | C22: Pre-filled summary formula. It reads the work you did on another sheet, so don't type over it.
B23: ✔ Correct | C23: Your answer matches the key.
B24: ✘ Not yet | C24: Not matching yet. Check the hint and try again.
B26: Sheets in this workbook
B27: Practice | C27: 13 practice tasks, each with a Check cell.
B28: Stays | C28: Data: 573 rows, in the Excel Table 'tblStays'
B29: ED | C29: Data: 785 rows, in the Excel Table 'tblED'
B30: Meds | C30: Data: 388 rows, in the Excel Table 'tblMeds'
B31: Bonus | C31: The bonus challenge (5 parts).
B32: About the data | C32: All 573 inpatient stays discharged from Bluestone Memorial Hospital in Q4 2025 (October–December), with age, length of stay, expected length of stay, and charges. All 785 emergency department visits at Bluestone Memorial in November–December 2025, with wait and length-of-stay minutes. The 388 medication orders written for that quarter's Medical-Surgical 5 East stays.
B33: Disclaimer | C33: All people, places, and numbers are synthetic and fictional. Not clinical guidance.

Sheet Practice
A1: Lesson 2.4 · Practice
A2: Tasks use three data sheets. Stays holds 573 inpatient stays (rows 2–574), ED holds 785 visits (rows 2–786), and Meds holds 388 medication orders (rows 2–389). Reference a column's data rows, like Stays!J2:J574, rather than a whole column like J:J, because the header text in row 1 breaks the row-by-row math in SUMPRODUCT. Structured references such as tblStays[TotalCharges] work too. When a task asks you to round, round with a function so the stored value matches, not just the display.
A3: Type a formula or value in each yellow cell. The Check column turns green when your answer matches. Stuck? Read the hint, then the lesson guide. Answers: right-click a sheet tab → Unhide… → 'Answer Key'.
A4: ="Score: "&COUNTIF(E6:E18,"✔*")&" of 13 auto-checked tasks correct"
A5: # | B5: Task | C5: Hint | D5: Your Answer | E5: Check
A6: 1 | B6: What is the most common ESI triage level among the ED visits? | C6: MODE.SNGL | E6: =IF(IFERROR(D6="",FALSE),"",IF(IFERROR(AND(ISNUMBER(D6),OR(ABS(D6-'Answer Key'!$C$5)<=0.0001)),FALSE),"✔ Correct","✘ Not yet"))
A7: 2 | B7: How much higher is the mean (average) TotalCharges per stay than the median TotalCharges? Enter the difference in dollars, to the cent. | C7: AVERAGE(…) − MEDIAN(…) | E7: =IF(IFERROR(D7="",FALSE),"",IF(IFERROR(AND(ISNUMBER(D7),OR(ABS(D7-'Answer Key'!$C$6)<=0.0051)),FALSE),"✔ Correct","✘ Not yet"))
A8: 3 | B8: What is the sample standard deviation of TotalCharges, rounded to the nearest $100 with ROUND? | C8: STDEV.S, then ROUND with a negative num_digits | E8: =IF(IFERROR(D8="",FALSE),"",IF(IFERROR(AND(ISNUMBER(D8),OR(ABS(D8-'Answer Key'!$C$7)<=0.0001)),FALSE),"✔ Correct","✘ Not yet"))
A9: 4 | B9: ED leaders review the three longest ED visits for boarding delays, where an admitted patient waits in the ED for an inpatient bed. They report each visit's length of stay in whole hours and count any started hour as a full hour. Find the 3rd-longest EDLOSMin on the ED sheet, convert it to hours, and round it up to a whole number of hours with ROUNDUP. | C9: LARGE(array, k) finds the visit. Divide by 60, then ROUNDUP(…, 0) | E9: =IF(IFERROR(D9="",FALSE),"",IF(IFERROR(AND(ISNUMBER(D9),OR(ABS(D9-'Answer Key'!$C$8)<=0.0001)),FALSE),"✔ Correct","✘ Not yet"))
A10: 5 | B10: The charge-capture team audits the cheapest stays, because an unusually low charge often means some charges were never posted. What is the 3rd-lowest TotalCharges? | C10: SMALL is LARGE's mirror image | E10: =IF(IFERROR(D10="",FALSE),"",IF(IFERROR(AND(ISNUMBER(D10),OR(ABS(D10-'Answer Key'!$C$9)<=0.0051)),FALSE),"✔ Correct","✘ Not yet"))
A11: 6 | B11: Encounter ENC119052 (Stays row 70) stayed 10 days. Rank its LOSDays among all 573 stays with RANK.EQ, where the longest stay is rank 1. | C11: RANK.EQ(number, ref). Leaving out order ranks the largest value as 1 | E11: =IF(IFERROR(D11="",FALSE),"",IF(IFERROR(AND(ISNUMBER(D11),OR(ABS(D11-'Answer Key'!$C$10)<=0.0001)),FALSE),"✔ Correct","✘ Not yet"))
A12: 7 | B12: Ninety percent of the patients who saw a provider waited at most how many minutes? Calculate the 90th percentile of DoorToProviderMin. (The 16 blank cells are patients who left without being seen.) | C12: PERCENTILE.INC(array, 0.9) | E12: =IF(IFERROR(D12="",FALSE),"",IF(IFERROR(AND(ISNUMBER(D12),OR(ABS(D12-'Answer Key'!$C$11)<=0.0001)),FALSE),"✔ Correct","✘ Not yet"))
A13: 8 | B13: What is the interquartile range (IQR = Q3 − Q1) of EDLOSMin, in minutes? Use QUARTILE.INC. | C13: QUARTILE.INC(array, 3) − QUARTILE.INC(array, 1) | E13: =IF(IFERROR(D13="",FALSE),"",IF(IFERROR(AND(ISNUMBER(D13),OR(ABS(D13-'Answer Key'!$C$12)<=0.0001)),FALSE),"✔ Correct","✘ Not yet"))
A14: 9 | B14: What was the total acquisition cost of the medications dispensed for the 5 East stays? Multiply each order's DosesDispensed by its UnitCost and add up all the orders, in one formula. Enter the total in dollars, to the cent. | C14: SUMPRODUCT(array1, array2) | E14: =IF(IFERROR(D14="",FALSE),"",IF(IFERROR(AND(ISNUMBER(D14),OR(ABS(D14-'Answer Key'!$C$13)<=0.0051)),FALSE),"✔ Correct","✘ Not yet"))
A15: 10 | B15: Fill the yellow AgeBand column on the Stays sheet with each stay's 10-year age band using FLOOR.MATH, so age 78 becomes 70 and age 80 becomes 80. Type the formula in K2. Stays is an Excel Table, so Excel fills the formula down the whole column for you. If it doesn't, double-click the fill handle. The gray cell counts the stays in the 80–89 band. | C15: FLOOR.MATH(number, significance) rounds down to a multiple | D15: {=IF(COUNT(Stays!$K$2:$K$574)=0,"",COUNTIF(Stays!$K$2:$K$574,80))} | E15: =IF(IFERROR(D15="",FALSE),"",IF(IFERROR(AND(ISNUMBER(D15),OR(ABS(D15-'Answer Key'!$C$14)<=0.0001)),FALSE),"✔ Correct","✘ Not yet"))
A16: 11 | B16: Order RX824601 (Meds row 255) is vancomycin 1,250 mg every 12 hours, with 24 doses dispensed. Assume the IV room mixes every dose from 500 mg single-dose vials and throws away whatever is left in an opened vial. How many vials did this order use? | C16: Work out vials per dose first: round 1,250 mg UP to a whole number of 500 mg vials with CEILING.MATH (or ROUNDUP) | E16: =IF(IFERROR(D16="",FALSE),"",IF(IFERROR(AND(ISNUMBER(D16),OR(ABS(D16-'Answer Key'!$C$15)<=0.0001)),FALSE),"✔ Correct","✘ Not yet"))
A17: 12 | B17: Case managers call a stay "on target" when its LOSDays is within 1 day of its ExpectedLOS in either direction (a difference of 1.0 day or less, longer or shorter). How many of the 573 stays were on target? Use one formula. | C17: ABS makes −0.9 and +0.9 the same distance. Count TRUE results with SUMPRODUCT(--(…)) from Lesson 2.1 | E17: =IF(IFERROR(D17="",FALSE),"",IF(IFERROR(AND(ISNUMBER(D17),OR(ABS(D17-'Answer Key'!$C$16)<=0.0001)),FALSE),"✔ Correct","✘ Not yet"))
A18: 13 | B18: The ED status board rounds each visit's length of stay to the nearest 15 minutes and shows it as hours and minutes, like "6 h 45 min". What does it show for visit ED211176 (ED row 2, EDLOSMin = 624)? Build the text with one formula that refers to the EDLOSMin cell. | C18: MROUND to 15 first. Then INT(minutes/60) gives hours and MOD(minutes,60) gives the minutes left over. Join with & | E18: =IF(IFERROR(D18="",FALSE),"",IF(IFERROR(OR(LOWER(TRIM(D18&""))=LOWER(TRIM('Answer Key'!$C$17&"")),LOWER(TRIM(D18&""))="10h 30min",LOWER(TRIM(D18&""))="10h30min",LOWER(TRIM(D18&""))="10 h 30 m",LOWER(TRIM(D18&""))="10h 30m",LOWER(TRIM(D18&""))="10h30m",LOWER(TRIM(D18&""))="10 hr 30 min",LOWER(TRIM(D18&""))="10 h 30 mins",LOWER(TRIM(D18&""))="10 hrs 30 min"),FALSE),"✔ Correct","✘ Not yet"))

Sheet Stays
A1: EncounterID | B1: Unit | C1: AdmitDate | D1: DischargeDate | E1: Age | F1: PrimaryDxCode | G1: DxDescription | H1: ExpectedLOS | I1: LOSDays | J1: TotalCharges | K1: AgeBand
A2: ENC118816 | B2: Medical-Surgical 4 West | C2: 45928 | D2: 45931 | E2: 86 | F2: A41.9 | G2: Sepsis, unspecified organism | H2: 5 | I2: 3 | J2: 32556.4
A3: ENC118667 | B3: Medical-Surgical 5 East | C3: 45922 | D3: 45931 | E3: 47 | F3: J18.9 | G3: Pneumonia, unspecified organism | H3: 3.9 | I3: 9 | J3: 37997.22
A4: ENC118807 | B4: Medical-Surgical 5 East | C4: 45928 | D4: 45931 | E4: 79 | F4: J18.9 | G4: Pneumonia, unspecified organism | H4: 3.9 | I4: 3 | J4: 17390.75
A5: ENC118810 | B5: Labor & Delivery | C5: 45928 | D5: 45932 | E5: 19 | F5: O80 | G5: Encounter for full-term uncomplicated delivery | H5: 2 | I5: 4 | J5: 22833.96
A6: ENC118634 | B6: Medical-Surgical 4 West | C6: 45921 | D6: 45932 | E6: 56 | F6: A41.9 | G6: Sepsis, unspecified organism | H6: 5 | I6: 11 | J6: 83723.83
A7: ENC118779 | B7: Medical-Surgical 5 East | C7: 45926 | D7: 45932 | E7: 79 | F7: N39.0 | G7: Urinary tract infection, site not specified | H7: 3.1 | I7: 6 | J7: 26261.44
A8: ENC118701 | B8: Medical-Surgical 4 West | C8: 45923 | D8: 45932 | E8: 69 | F8: U07.1 | G8: COVID-19 | H8: 4.4 | I8: 9 | J8: 34519.59
A9: ENC118877 | B9: Medical-Surgical 5 East | C9: 45930 | D9: 45932 | E9: 49 | F9: K35.80 | G9: Unspecified acute appendicitis | H9: 2 | I9: 2 | J9: 24246.5
A10: ENC118823 | B10: Labor & Delivery | C10: 45928 | D10: 45932 | E10: 38 | F10: O82 | G10: Encounter for cesarean delivery without indication | H10: 2.9 | I10: 4 | J10: 36519.04
A11: ENC118855 | B11: Orthopedics & Spine | C11: 45930 | D11: 45933 | E11: 56 | F11: S72.001A | G11: Fracture of unspecified part of neck of right femur, initial encounter | H11: 4.6 | I11: 3 | J11: 66398.97
A12: ENC118944 | B12: Medical-Surgical 4 West | C12: 45932 | D12: 45933 | E12: 65 | F12: N39.0 | G12: Urinary tract infection, site not specified | H12: 3.1 | I12: 1 | J12: 10798.46
A13: ENC118818 | B13: Medical-Surgical 5 East | C13: 45928 | D13: 45933 | E13: 78 | F13: L03.115 | G13: Cellulitis of right lower limb | H13: 3.4 | I13: 5 | J13: 19559.83
... A574: ENC121789 | B574: Cardiac Step-Down | C574: 46020 | D574: 46022 | E574: 62 | F574: I48.91 | G574: Unspecified atrial fibrillation | H574: 2.9 | I574: 2 | J574: 11907.29

Sheet ED
A1: EDVisitID | B1: ArrivalDateTime | C1: ArrivalMode | D1: ESILevel | E1: ChiefComplaint | F1: EDDisposition | G1: DoorToProviderMin | H1: EDLOSMin
A2: ED211176 | B2: 45962.037 | C2: Walk-In | D2: 3 | E2: Cough / Fever | F2: Admitted | G2: 23 | H2: 624
A3: ED211178 | B3: 45962.278 | C3: Walk-In | D3: 3 | E3: Cough / Trouble Breathing | F3: Discharged | G3: 28 | H3: 168
A4: ED211180 | B4: 45962.397 | C4: Ambulance | D4: 2 | E4: Weakness / Fatigue | F4: Admitted | G4: 35 | H4: 473
A5: ED211182 | B5: 45962.531 | C5: Walk-In | D5: 3 | E5: Vomiting / Dizziness | F5: Discharged | G5: 109 | H5: 307
A6: ED211184 | B6: 45962.562 | C6: Ambulance | D6: 2 | E6: Seizure | F6: Discharged | G6: 20 | H6: 182
A7: ED211185 | B7: 45962.583 | C7: Walk-In | D7: 5 | E7: Ankle Injury | F7: Discharged | G7: 54 | H7: 141
A8: ED211187 | B8: 45962.769 | C8: Walk-In | D8: 4 | E8: Dizziness | F8: Discharged | G8: 45 | H8: 111
A9: ED211188 | B9: 45963.235 | C9: Walk-In | D9: 4 | E9: Abdominal Pain | F9: Discharged | G9: 23 | H9: 95
A10: ED211190 | B10: 45963.415 | C10: Walk-In | D10: 3 | E10: Seizure | F10: Discharged | G10: 21 | H10: 191
A11: ED211192 | B11: 45963.482 | C11: Walk-In | D11: 3 | E11: Tremors / Alcohol Withdrawal | F11: Admitted | G11: 115 | H11: 500
A12: ED211195 | B12: 45963.599 | C12: Ambulance | D12: 2 | E12: Fever / Altered Mental Status | F12: Admitted | G12: 15 | H12: 402
A13: ED211196 | B13: 45963.635 | C13: Walk-In | D13: 3 | E13: Cough / Fever | F13: Discharged | G13: 130 | H13: 284
... A29: ED211217 | B29: 45964.574 | C29: Walk-In | D29: 4 | E29: Ear Pain / Fever | F29: Discharged | G29: 142 | H29: 257
A30: ED211218 | B30: 45964.601 | C30: Walk-In | D30: 4 | E30: Back Pain | F30: LWBS | H30: 141
A31: ED211219 | B31: 45964.632 | C31: Walk-In | D31: 2 | E31: Cough / Fever | F31: Admitted | G31: 59 | H31: 487
A32: ED211220 | B32: 45964.656 | C32: Ambulance | D32: 2 | E32: Weakness / Fatigue | F32: Admitted | G32: 13 | H32: 412
A33: ED211221 | B33: 45964.659 | C33: Walk-In | D33: 3 | E33: Painful Urination / Fever | F33: Observation | G33: 31 | H33: 306
A34: ED211224 | B34: 45964.798 | C34: Walk-In | D34: 4 | E34: Back Pain | F34: Discharged | G34: 36 | H34: 119
A35: ED211225 | B35: 45964.863 | C35: Walk-In | D35: 4 | E35: Painful Urination / Fever | F35: Discharged | G35: 66 | H35: 134
A36: ED211226 | B36: 45964.91 | C36: Ambulance | D36: 2 | E36: Shortness of Breath | F36: Discharged | G36: 23 | H36: 267
A37: ED211227 | B37: 45964.938 | C37: Walk-In | D37: 3 | E37: Abdominal Pain | F37: Discharged | G37: 83 | H37: 286
A38: ED211228 | B38: 45965.075 | C38: Walk-In | D38: 3 | E38: Head Injury | F38: Discharged | G38: 23 | H38: 221
A39: ED211229 | B39: 45965.12 | C39: Walk-In | D39: 4 | E39: Cough / Fever | F39: Admitted | G39: 28 | H39: 358
A40: ED211230 | B40: 45965.29 | C40: Walk-In | D40: 3 | E40: Fall | F40: Discharged | G40: 28 | H40: 253
A41: ED211231 | B41: 45965.333 | C41: Police | D41: 2 | E41: Dizziness | F41: Transferred | G41: 13 | H41: 300
A42: ED211232 | B42: 45965.342 | C42: Ambulance | D42: 3 | E42: Skin Redness / Swelling | F42: Discharged | G42: 20 | H42: 221
... A52: ED211249 | B52: 45966.345 | C52: Ambulance | D52: 3 | E52: Bloody Stool / Vomiting Blood | F52: Admitted | G52: 31 | H52: 535
A53: ED211250 | B53: 45966.415 | C53: Walk-In | D53: 4 | E53: Cough / Trouble Breathing | F53: LWBS | H53: 76
A54: ED211252 | B54: 45966.43 | C54: Walk-In | D54: 4 | E54: Chest Pain | F54: Discharged | G54: 28 | H54: 124
A55: ED211253 | B55: 45966.443 | C55: Walk-In | D55: 3 | E55: Cough / Trouble Breathing | F55: Discharged | G55: 59 | H55: 265
A56: ED211254 | B56: 45966.46 | C56: Walk-In | D56: 3 | E56: Skin Redness / Swelling | F56: Discharged | G56: 43 | H56: 243
A57: ED211255 | B57: 45966.525 | C57: Ambulance | D57: 4 | E57: Laceration | F57: Discharged | G57: 68 | H57: 137
A58: ED211256 | B58: 45966.535 | C58: Ambulance | D58: 3 | E58: Shortness of Breath | F58: Admitted | G58: 75 | H58: 284
A59: ED211260 | B59: 45966.759 | C59: Ambulance | D59: 3 | E59: Cough / Fever | F59: Discharged | G59: 27 | H59: 251
A60: ED211262 | B60: 45966.838 | C60: Ambulance | D60: 1 | E60: Shortness of Breath | F60: Admitted | G60: 4 | H60: 542
A61: ED211263 | B61: 45966.854 | C61: Walk-In | D61: 4 | E61: Dizziness | F61: Observation | G61: 47 | H61: 281
A62: ED211265 | B62: 45967.086 | C62: Walk-In | D62: 5 | E62: Ankle Injury | F62: Discharged | G62: 15 | H62: 79
A63: ED211267 | B63: 45967.43 | C63: Walk-In | D63: 3 | E63: Shortness of Breath | F63: Admitted | G63: 28 | H63: 327
A64: ED211268 | B64: 45967.467 | C64: Walk-In | D64: 3 | E64: Cough / Fever | F64: Admitted | G64: 40 | H64: 242
...

Sheet Meds
A1: MedOrderID | B1: EncounterID | C1: OrderDateTime | D1: MedicationName | E1: Dose | F1: Route | G1: Frequency | H1: DosesDispensed | I1: UnitCost
A2: RX822105 | B2: ENC118667 | C2: 45922.774 | D2: Sodium Chloride 0.9% | E2: 1000 mL | F2: IV | G2: Continuous | H2: 16 | I2: 1.75
A3: RX822104 | B3: ENC118667 | C3: 45922.794 | D3: Azithromycin | E3: 500 mg | F3: PO | G3: Daily | H3: 7 | I3: 1.1
A4: RX822106 | B4: ENC118667 | C4: 45922.848 | D4: Acetaminophen | E4: 650 mg | F4: PO | G4: Q6H PRN | H4: 15 | I4: 0.08
A5: RX822103 | B5: ENC118667 | C5: 45922.985 | D5: Ceftriaxone | E5: 1 g | F5: IV | G5: Q24H | H5: 8 | I5: 3.2
A6: RX822225 | B6: ENC118779 | C6: 45926.787 | D6: Acetaminophen | E6: 650 mg | F6: PO | G6: Q6H PRN | H6: 11 | I6: 0.08
A7: RX822224 | B7: ENC118779 | C7: 45926.902 | D7: Cephalexin | E7: 500 mg | F7: PO | G7: Q6H | H7: 19 | I7: 0.45
A8: RX822273 | B8: ENC118807 | C8: 45928.14 | D8: Azithromycin | E8: 500 mg | F8: PO | G8: Daily | H8: 4 | I8: 1.1
A9: RX822274 | B9: ENC118807 | C9: 45928.154 | D9: Acetaminophen | E9: 650 mg | F9: PO | G9: Q6H PRN | H9: 5 | I9: 0.08
A10: RX822275 | B10: ENC118807 | C10: 45928.178 | D10: Enoxaparin | E10: 40 mg | F10: SubQ | G10: Daily | H10: 3 | I10: 6.75
A11: RX822272 | B11: ENC118807 | C11: 45928.316 | D11: Ceftriaxone | E11: 1 g | F11: IV | G11: Q24H | H11: 3 | I11: 3.2
A12: RX822296 | B12: ENC118818 | C12: 45928.647 | D12: Cephalexin | E12: 500 mg | F12: PO | G12: Q6H | H12: 18 | I12: 0.45
A13: RX822297 | B13: ENC118818 | C13: 45928.738 | D13: Vancomycin | E13: 1250 mg | F13: IV | G13: Q12H | H13: 10 | I13: 9.8
... A389: RX825736 | B389: ENC121697 | C389: 46017.726 | D389: Acetaminophen | E389: 650 mg | F389: PO | G389: Q6H PRN | H389: 7 | I389: 0.08

Sheet Bonus
A1: Lesson 2.4 · Bonus: Which stays are driving the average charge?
A2: The CFO's draft board report says the average inpatient charge in Q4 was $32,042. A board member asks whether that number is typical and which stays are unusually expensive. Flag the high-charge outliers with two common rules, measure how much they matter, and find a more representative average. Use the TotalCharges column on the Stays sheet (Stays!J2:J574). Your B1 answer lands in cell D6 of this sheet, so later parts can refer to it.
A3: Type a formula or value in each yellow cell. The Check column turns green when your answer matches. Stuck? Read the hint, then the lesson guide. Answers: right-click a sheet tab → Unhide… → 'Bonus Key'.
A4: ="Score: "&COUNTIF(E6:E10,"✔*")&" of 5 auto-checked tasks correct"
A5: # | B5: Task | C5: Hint | D5: Your Answer | E5: Check
A6: B1 | B6: Calculate the upper outlier fence with the IQR rule: Q3 + 1.5 × (Q3 − Q1), using QUARTILE.INC. Enter it in dollars, to the cent. | C6: Find Q1 and Q3 with QUARTILE.INC, then combine them | E6: =IF(IFERROR(D6="",FALSE),"",IF(IFERROR(AND(ISNUMBER(D6),OR(ABS(D6-'Bonus Key'!$C$5)<=0.0051)),FALSE),"✔ Correct","✘ Not yet"))
A7: B2 | B7: How many stays have TotalCharges above the fence from B1? | C7: COUNTIF(range, ">"&cell) joins the operator to your B1 cell | E7: =IF(IFERROR(D7="",FALSE),"",IF(IFERROR(AND(ISNUMBER(D7),OR(ABS(D7-'Bonus Key'!$C$6)<=0.0001)),FALSE),"✔ Correct","✘ Not yet"))
A8: B3 | B8: What share of all Q4 TotalCharges came from the stays above the fence? Enter it as a percentage with one decimal place. | C8: (range>D6) is TRUE or FALSE for each stay. Multiply it by the charges inside SUMPRODUCT, then divide by the total | E8: =IF(IFERROR(D8="",FALSE),"",IF(IFERROR(AND(ISNUMBER(D8),OR(ABS(D8-'Bonus Key'!$C$7)<=0.00051,ABS(D8-'Bonus Key'!$C$7*100)<=0.051000000000000004)),FALSE),"✔ Correct","✘ Not yet"))
A9: B4 | B9: A second common rule flags any value more than 3 standard deviations above the mean. How many stays have TotalCharges above AVERAGE + 3 × STDEV.S? | C9: Build the threshold inside the criterion: ">"&(AVERAGE(…)+3*STDEV.S(…)) | E9: =IF(IFERROR(D9="",FALSE),"",IF(IFERROR(AND(ISNUMBER(D9),OR(ABS(D9-'Bonus Key'!$C$8)<=0.0001)),FALSE),"✔ Correct","✘ Not yet"))
A10: B5 | B10: Calculate a 10% trimmed mean of TotalCharges with TRIMMEAN, which drops about 5% of stays from each end before averaging. Enter it in dollars, to the cent. | C10: TRIMMEAN(array, percent). The percent is the TOTAL share to drop | E10: =IF(IFERROR(D10="",FALSE),"",IF(IFERROR(AND(ISNUMBER(D10),OR(ABS(D10-'Bonus Key'!$C$9)<=0.0051)),FALSE),"✔ Correct","✘ Not yet"))

Sheet Answer Key
A1: 🔑 Answer Key — Lesson 2.4
A2: Spoiler alert: try every task before reading this sheet. Column C is the value the Check column compares against. Column D is a sample solution, and column E recalculates a formula for it live, proving the answer.
A4: # | B4: Task | C4: Answer | D4: Sample solution | E4: Live result | F4: Explanation
A5: 1 | B5: What is the most common ESI triage level among the ED visits? | C5: 3 | D5: =MODE.SNGL(ED!D2:D786) | E5: {=_xlfn.MODE.SNGL(ED!D2:D786)} | F5: MODE.SNGL returns the value that occurs most often: level 3 appears 328 times out of 785. ESI levels are codes on a 1–5 scale, so their mean (3.12) isn't a real triage level. For codes and categories, the mode is the honest "typical" value. The older MODE function gives the same result.
A6: 2 | B6: How much higher is the mean (average) TotalCharges per stay than the median TotalCharges? Enter the difference in dollars, to the cent. | C6: 8076.03 | D6: =AVERAGE(Stays!J2:J574)-MEDIAN(Stays!J2:J574) | E6: {=AVERAGE(Stays!J2:J574)-MEDIAN(Stays!J2:J574)} | F6: The mean is $32,041.72 but the median is $23,965.69, so half of all stays were charged less than $23,966. In fact 375 of the 573 stays (65%) fall below the mean. A handful of very long, very expensive stays pull the mean up, while the median only cares about the middle value. When data is skewed like this, the median describes a typical stay better.
A7: 3 | B7: What is the sample standard deviation of TotalCharges, rounded to the nearest $100 with ROUND? | C7: 24100 | D7: =ROUND(STDEV.S(Stays!J2:J574),-2) | E7: {=ROUND(_xlfn.STDEV.S(Stays!J2:J574),-2)} | F7: STDEV.S returns $24,056.39. A num_digits of -2 rounds to the hundreds place, giving $24,100. STDEV.S treats the stays as a sample of an ongoing process, which is the usual choice. STDEV.P gives $24,035.39, which rounds to $24,000, so the check tells the two apart.
A8: 4 | B8: ED leaders review the three longest ED visits for boarding delays, where an admitted patient waits in the ED for an inpatient bed. They report each visit's length of stay in whole hours and count any started hour as a full hour. Find the 3rd-longest EDLOSMin on the ED sheet, convert it to hours, and round it up to a whole number of hours with ROUNDUP. | C8: 20 | D8: =ROUNDUP(LARGE(ED!H2:H786,3)/60,0) | E8: {=ROUNDUP(LARGE(ED!H2:H786,3)/60,0)} | F8: LARGE returns the k-th largest value, so LARGE(range,1) is the same as MAX. The three longest visits lasted 1,304, 1,281, and 1,169 minutes. The 3rd is 1,169 ÷ 60 = 19.48 hours, and ROUNDUP turns the started hour into a full one, giving 20. ROUND and ROUNDDOWN both give 19 here, which would under-report the visit because the rule counts every started hour. =CEILING.MATH(LARGE(…,3)/60) gives the same 20. Change k to 2 or 1 to see the other two visits.
A9: 5 | B9: The charge-capture team audits the cheapest stays, because an unusually low charge often means some charges were never posted. What is the 3rd-lowest TotalCharges? | C9: 6249.27 | D9: =SMALL(Stays!J2:J574,3) | E9: {=SMALL(Stays!J2:J574,3)} | F9: SMALL(array, k) returns the k-th smallest value, so SMALL(range,1) equals MIN. Like LARGE, it ignores blank cells and text.
A10: 6 | B10: Encounter ENC119052 (Stays row 70) stayed 10 days. Rank its LOSDays among all 573 stays with RANK.EQ, where the longest stay is rank 1. | C10: 28 | D10: =RANK.EQ(Stays!I70,Stays!I2:I574) | E10: {=_xlfn.RANK.EQ(Stays!I70,Stays!I2:I574)} | F10: 27 stays were longer than 10 days, so this one ranks 28. The other 7 stays of exactly 10 days share rank 28, and the next rank used is 36. RANK.AVG returns 31.5 instead, which is the average of positions 28–35. If you copy a RANK formula down a column, lock the ref with $ ($I$2:$I$574) so it doesn't slide.
A11: 7 | B11: Ninety percent of the patients who saw a provider waited at most how many minutes? Calculate the 90th percentile of DoorToProviderMin. (The 16 blank cells are patients who left without being seen.) | C11: 102 | D11: =PERCENTILE.INC(ED!G2:G786,0.9) | E11: {=_xlfn.PERCENTILE.INC(ED!G2:G786,0.9)} | F11: PERCENTILE.INC ignores blank cells, so it uses only the 769 visits with a provider time. The median wait was 38 minutes, yet 74 of the 769 waits (9.6%) were longer than 102 minutes. That long tail is why ED leaders track the 90th percentile alongside the median. If someone had typed 0 into the blank cells, the percentile would drop and the report would look better than reality.
A12: 8 | B12: What is the interquartile range (IQR = Q3 − Q1) of EDLOSMin, in minutes? Use QUARTILE.INC. | C12: 155 | D12: =QUARTILE.INC(ED!H2:H786,3)-QUARTILE.INC(ED!H2:H786,1) | E12: {=_xlfn.QUARTILE.INC(ED!H2:H786,3)-_xlfn.QUARTILE.INC(ED!H2:H786,1)} | F12: Q1 is 167 and Q3 is 322, so the middle half of ED visits lasted between 2 h 47 min and 5 h 22 min. The IQR ignores the extreme visits at both ends, so a few boarding patients can't stretch it. QUARTILE.EXC interpolates slightly differently, but with 785 visits it lands on the same Q1 and Q3 here.
A13: 9 | B13: What was the total acquisition cost of the medications dispensed for the 5 East stays? Multiply each order's DosesDispensed by its UnitCost and add up all the orders, in one formula. Enter the total in dollars, to the cent. | C13: 9252.38 | D13: =SUMPRODUCT(Meds!H2:H389,Meds!I2:I389) | E13: {=SUMPRODUCT(Meds!H2:H389,Meds!I2:I389)} | F13: SUMPRODUCT multiplies the two columns row by row, then adds the 388 products. It gives the same result as a helper column of =H2*I2 totaled with SUM. Multiplying two totals, as in =SUM(H…)*SUM(I…), is wrong (it gives $3,108,585.48) because it pairs every order's doses with every other order's price. Divide by SUM(Meds!H2:H389) to get the average cost per dose, $3.08.
A14: 10 | B14: Fill the yellow AgeBand column on the Stays sheet with each stay's 10-year age band using FLOOR.MATH, so age 78 becomes 70 and age 80 becomes 80. Type the formula in K2. Stays is an Excel Table, so Excel fills the formula down the whole column for you. If it doesn't, double-click the fill handle. The gray cell counts the stays in the 80–89 band. | C14: 44 | D14: =FLOOR.MATH(E2,10) | E14: {=SUMPRODUCT((Stays!E2:E574>=80)*(Stays!E2:E574<90))} | F14: FLOOR.MATH rounds down to the nearest multiple of 10, so every age from 80 to 89 lands in the 80 band. ROUND(E2,-1) would be wrong, because it sends ages 75–84 to 80 and gives 93 instead of 44. =INT(E2/10)*10, =TRUNC(E2,-1), and =ROUNDDOWN(E2,-1) all work too. In the Table you may see =FLOOR.MATH([@Age],10). The most common band is the 70s.
A15: 11 | B15: Order RX824601 (Meds row 255) is vancomycin 1,250 mg every 12 hours, with 24 doses dispensed. Assume the IV room mixes every dose from 500 mg single-dose vials and throws away whatever is left in an opened vial. How many vials did this order use? | C15: 72 | D15: =CEILING.MATH(1250,500)/500*Meds!H255 | E15: {=_xlfn.CEILING.MATH(1250,500)/500*Meds!H255} | F15: CEILING.MATH(1250,500) rounds up to 1,500 mg, which is 3 vials per dose. Two vials would hold only 1,000 mg, so ROUNDDOWN would under-dose. 3 vials × 24 doses = 72 vials. Rounding the order's total instead (CEILING.MATH(1250*24,500)/500 = 60) assumes leftover drug carries over to the next dose, which a single-dose vial doesn't allow. =ROUNDUP(1250/500,0)*Meds!H255 also works. The order wasted 6,000 mg in partly used vials.
A16: 12 | B16: Case managers call a stay "on target" when its LOSDays is within 1 day of its ExpectedLOS in either direction (a difference of 1.0 day or less, longer or shorter). How many of the 573 stays were on target? Use one formula. | C16: 264 | D16: =SUMPRODUCT(--(ABS(Stays!I2:I574-Stays!H2:H574)<=1)) | E16: {=SUMPRODUCT(--(ABS(Stays!I2:I574-Stays!H2:H574)<=1))} | F16: Subtracting the two columns gives each stay's difference from expected, which is negative when the stay was shorter than expected. ABS turns every difference into a distance, the comparison turns each distance into TRUE or FALSE, -- turns those into 1s and 0s, and SUMPRODUCT adds them. Without ABS, every stay that ended early would count as on target, and you'd get 348. A helper column of =ABS(I2-H2) counted with COUNTIF(range,"<=1") gives the same 264.
A17: 13 | B17: The ED status board rounds each visit's length of stay to the nearest 15 minutes and shows it as hours and minutes, like "6 h 45 min". What does it show for visit ED211176 (ED row 2, EDLOSMin = 624)? Build the text with one formula that refers to the EDLOSMin cell. | C17: 10 h 30 min | D17: =INT(MROUND(ED!H2,15)/60)&" h "&MOD(MROUND(ED!H2,15),60)&" min" | E17: {=INT(MROUND(ED!H2,15)/60)&" h "&MOD(MROUND(ED!H2,15),60)&" min"} | F17: MROUND(624,15) returns 630, because 624 is closer to 630 than to 615. Then INT(630/60) is 10 whole hours and MOD(630,60) is the 30 minutes left over. The & operator joins the pieces into "10 h 30 min". Without the rounding the board would show "10 h 24 min". TRUNC or ROUNDDOWN(…,0) can replace INT here because the minutes are positive.

Sheet Bonus Key
A1: 🔑 Bonus Key — Lesson 2.4
A2: Spoiler alert: try every task before reading this sheet. Column C is the value the Check column compares against. Column D is a sample solution, and column E recalculates a formula for it live, proving the answer.
A4: # | B4: Task | C4: Answer | D4: Sample solution | E4: Live result | F4: Explanation
A5: B1 | B5: Calculate the upper outlier fence with the IQR rule: Q3 + 1.5 × (Q3 − Q1), using QUARTILE.INC. Enter it in dollars, to the cent. | C5: 70379.05 | D5: =QUARTILE.INC(Stays!J2:J574,3)+1.5*(QUARTILE.INC(Stays!J2:J574,3)-QUARTILE.INC(Stays!J2:J574,1)) | E5: {=_xlfn.QUARTILE.INC(Stays!J2:J574,3)+1.5*(_xlfn.QUARTILE.INC(Stays!J2:J574,3)-_xlfn.QUARTILE.INC(Stays!J2:J574,1))} | F5: Q1 is $16,511.45 and Q3 is $38,058.49, so the IQR is $21,547.04 and the fence is $38,058.49 + 1.5 × $21,547.04 = $70,379.05. The lower fence, Q1 − 1.5 × IQR, is −$15,809.11. That's below zero, so the rule can't flag any low outliers. Right-skewed data like charges usually has outliers on the high side only.
A6: B2 | B6: How many stays have TotalCharges above the fence from B1? | C6: 50 | D6: =COUNTIF(Stays!J2:J574,">"&D6) | E6: {=COUNTIF(Stays!J2:J574,">"&(_xlfn.QUARTILE.INC(Stays!J2:J574,3)+1.5*(_xlfn.QUARTILE.INC(Stays!J2:J574,3)-_xlfn.QUARTILE.INC(Stays!J2:J574,1))))} | F6: ">"&D6 builds the criterion text ">70379.05", so COUNTIF counts charges above your fence. That's 50 stays, or 8.7% of all stays.
A7: B3 | B7: What share of all Q4 TotalCharges came from the stays above the fence? Enter it as a percentage with one decimal place. | C7: 0.25706803 | D7: =SUMPRODUCT((Stays!J2:J574>D6)*Stays!J2:J574)/SUM(Stays!J2:J574) | E7: {=SUMPRODUCT((Stays!J2:J574>(_xlfn.QUARTILE.INC(Stays!J2:J574,3)+1.5*(_xlfn.QUARTILE.INC(Stays!J2:J574,3)-_xlfn.QUARTILE.INC(Stays!J2:J574,1))))*Stays!J2:J574)/SUM(Stays!J2:J574)} | F7: (Stays!J2:J574>D6) is TRUE for an outlier and FALSE otherwise. Multiplying by the charges turns TRUE into 1 and FALSE into 0, so only the outlier charges survive, and SUMPRODUCT adds them. Just 8.7% of stays produced 25.7% of all charges. That concentration is exactly why the mean sits so far above the median. (=SUMIF(Stays!J2:J574,">"&D6)/SUM(Stays!J2:J574) from Lesson 2.5 gives the same answer.)
A8: B4 | B8: A second common rule flags any value more than 3 standard deviations above the mean. How many stays have TotalCharges above AVERAGE + 3 × STDEV.S? | C8: 13 | D8: =COUNTIF(Stays!J2:J574,">"&(AVERAGE(Stays!J2:J574)+3*STDEV.S(Stays!J2:J574))) | E8: {=COUNTIF(Stays!J2:J574,">"&(AVERAGE(Stays!J2:J574)+3*_xlfn.STDEV.S(Stays!J2:J574)))} | F8: The threshold is $32,041.72 + 3 × $24,056.39 = $104,210.89, and only 13 stays exceed it, compared with 50 under the IQR rule. The outliers themselves inflate the mean and the standard deviation, which raises the bar they have to clear. This effect is called masking. The 3-SD rule assumes roughly symmetric data. Quartiles barely move when a few extreme values change, so the IQR rule is the better screen for skewed data like charges and length of stay.
A9: B5 | B9: Calculate a 10% trimmed mean of TotalCharges with TRIMMEAN, which drops about 5% of stays from each end before averaging. Enter it in dollars, to the cent. | C9: 29241.27 | D9: =TRIMMEAN(Stays!J2:J574,0.1) | E9: {=TRIMMEAN(Stays!J2:J574,0.1)} | F9: 573 × 10% = 57.3 stays. TRIMMEAN rounds that down to an even number (56) and drops 28 from each end. The result, $29,241.27, sits between the median ($23,965.69) and the mean ($32,041.72). For the board, report the median as the typical stay and keep the mean for budgeting, because mean × number of stays = total charges. Then list the outlier stays separately so nobody mistakes them for the norm.
