Workbook

Sheet Start Here
B2: Lesson 1.1
B3: The Excel Interface & Navigation
B4: Beginner · about 70 minutes · Bluestone Health System (fictional)
B6: What you'll learn
B7: • | C7: Name the parts of the Excel window: ribbon, Quick Access Toolbar, Name Box, formula bar, grid, sheet tabs, status bar
B8: • | C8: Understand workbooks, worksheets, cells, ranges, and cell addresses
B9: • | C9: Move around large datasets fast with keyboard shortcuts and Go To
B10: • | C10: Read quick statistics from the status bar
B11: • | C11: Freeze panes, zoom, and hide/unhide rows, columns, and sheets
B13: How to use this workbook
B14: 1. Read the guide | C14: The lesson guide (README) explains each skill with examples: https://github.com/lmansf/learn-excel/tree/main/01-foundations/01-excel-interface-navigation
B15: 2. Practice | C15: Go to the 'Practice' sheet. Type a formula or value into each yellow cell.
B16: 3. Check yourself | C16: The Check column shows ✔ Correct (green) or ✘ Not yet (red).
B17: 4. Bonus | C17: Finished? Try the harder 'Bonus' sheet.
B18: 5. Answers | C18: The 'Answer Key' and 'Bonus Key' sheets are hidden. Right-click any sheet tab → Unhide… → pick one → OK. (Try first!)
B19: Note | C19: Two things are hidden on purpose so you can practice unhiding them: column I on the Patients sheet and the whole Payers sheet.
B20: Note | C20: The Patients sheet opens with nothing frozen, so the headers scroll out of view. The guide shows how to freeze them.
B22: Color legend
B23: Yellow cell | C23: Your answer goes here.
B24: ✔ Correct | C24: Your answer matches the key.
B25: ✘ Not yet | C25: Not matching yet. Check the hint and try again.
B27: Sheets in this workbook
B28: Practice | C28: 12 practice tasks, each with a Check cell.
B29: Patients | C29: Data: 500 rows, in the Excel Table 'tblPatients'
B30: Payers | C30: Data: 8 rows, in the Excel Table 'tblPayers'
B31: Bonus | C31: The bonus challenge (4 parts).
B32: About the data | C32: 500 registered patients from the Bluestone Health System patient index (every 8th record), plus a small payer list that starts out hidden.
B33: Disclaimer | C33: All people, places, and numbers are synthetic and fictional. Not clinical guidance.

Sheet Practice
A1: Lesson 1.1 · Practice
A2: Every task uses the Patients sheet (500 patients, rows 2–501) unless it says otherwise. No formulas needed: navigate, look, and type what you find. Mac users: for Ctrl+arrow shortcuts such as Ctrl+↓ and Ctrl+Shift+↓, press ⌘ instead of Ctrl.
A3: Type a formula or value in each yellow cell. The Check column turns green when your answer matches. Stuck? Read the hint, then the lesson guide. Answers: right-click a sheet tab → Unhide… → 'Answer Key'.
A4: ="Score: "&COUNTIF(E6:E17,"✔*")&" of 12 auto-checked tasks correct"
A5: # | B5: Task | C5: Hint | D5: Your Answer | E5: Check
A6: 1 | B6: On the Patients sheet, click in the Name Box (the box at the left end of the formula bar), type C347, and press Enter. What last name is in that cell? | C6: The Name Box jumps to any address you type | E6: =IF(IFERROR(D6="",FALSE),"",IF(IFERROR(OR(LOWER(TRIM(D6&""))=LOWER(TRIM('Answer Key'!$C$5&""))),FALSE),"✔ Correct","✘ Not yet"))
A7: 2 | B7: What is the address of the bottom-right cell of the patient data? From A1, press Ctrl+↓ to find the last row, go back with Ctrl+↑, then press Ctrl+→ to find the last column. Type the address as column letter + row number (like B12). | C7: Column letter from Ctrl+→, row number from Ctrl+↓. Ctrl+End confirms | E7: =IF(IFERROR(D7="",FALSE),"",IF(IFERROR(OR(LOWER(TRIM(D7&""))=LOWER(TRIM('Answer Key'!$C$6&"")),LOWER(TRIM(D7&""))="$q$501"),FALSE),"✔ Correct","✘ Not yet"))
A8: 3 | B8: Use the Name Box to go to cell A600, which is in an empty row below the data, then press Ctrl+→. Excel races across the empty row to the very last column of the worksheet. What is the address of the cell you land on? | C8: A worksheet has 16,384 columns | E8: =IF(IFERROR(D8="",FALSE),"",IF(IFERROR(OR(LOWER(TRIM(D8&""))=LOWER(TRIM('Answer Key'!$C$7&"")),LOWER(TRIM(D8&""))="$xfd$600"),FALSE),"✔ Correct","✘ Not yet"))
A9: 4 | B9: Click M1 (the PCPProviderID header) and press Ctrl+↓ once. On which row number does Excel stop? | C9: Ctrl+arrow stops at the edge of a block of filled cells | E9: =IF(IFERROR(D9="",FALSE),"",IF(IFERROR(AND(ISNUMBER(D9),OR(ABS(D9-'Answer Key'!$C$8)<=0.0001)),FALSE),"✔ Correct","✘ Not yet"))
A10: 5 | B10: Select the Email data cells J2:J501: type J2:J501 in the Name Box and press Enter. How many patients have an email address on file? Read Count on the status bar. | C10: Count = cells that aren't empty | E10: =IF(IFERROR(D10="",FALSE),"",IF(IFERROR(AND(ISNUMBER(D10),OR(ABS(D10-'Answer Key'!$C$9)<=0.0001)),FALSE),"✔ Correct","✘ Not yet"))
A11: 6 | B11: Select the WeightLb values O2:O501 with Go To: press F5 or Ctrl+G (Mac: Control+G), type O2:O501, and press Enter. What is the average weight in pounds? Round to 1 decimal place. | C11: Average is on the status bar by default | E11: =IF(IFERROR(D11="",FALSE),"",IF(IFERROR(AND(ISNUMBER(D11),OR(ABS(D11-'Answer Key'!$C$10)<=0.051)),FALSE),"✔ Correct","✘ Not yet"))
A12: 7 | B12: Turn on Minimum in the status bar: right-click the status bar and tick Minimum. Then click cell F2 (the first DOB) and press Ctrl+Shift+↓ to select every date of birth. What is the date of birth of the oldest patient? Type it as month/day/year, the way the status bar shows it. (If your computer uses day/month dates, type the month as a word instead, such as 15 Mar 1950.) | C12: The oldest patient has the earliest date, so look at Minimum | E12: =IF(IFERROR(D12="",FALSE),"",IF(IFERROR(AND(ISNUMBER(D12),INT(D12)=INT('Answer Key'!$C$11)),FALSE),"✔ Correct","✘ Not yet"))
A13: 8 | B13: How many patients live in Millbrook? On the Patients sheet, click a single cell such as A1 so Find searches the whole sheet. Then press Ctrl+F (Mac: Control+F), type Millbrook, click Find All, and read the count at the bottom of the dialog. | C13: Find All shows '… cell(s) found' | E13: =IF(IFERROR(D13="",FALSE),"",IF(IFERROR(AND(ISNUMBER(D13),OR(ABS(D13-'Answer Key'!$C$12)<=0.0001)),FALSE),"✔ Correct","✘ Not yet"))
A14: 9 | B14: Column I is hidden (the column letters jump from H to J). Unhide it, then click cell A1 and use Ctrl+F (Mac: Control+F) to find patient PT12376. What is that patient's phone number? | C14: Select the columns on both sides of the gap, right-click → Unhide | E14: =IF(IFERROR(D14="",FALSE),"",IF(IFERROR(OR(LOWER(TRIM(D14&""))=LOWER(TRIM('Answer Key'!$C$13&"")),LOWER(TRIM(D14&""))="5557408462",LOWER(TRIM(D14&""))="555-740-8462",LOWER(TRIM(D14&""))="(555)740-8462",LOWER(TRIM(D14&""))="555 740 8462"),FALSE),"✔ Correct","✘ Not yet"))
A15: 10 | B15: Patient PT13312 has a PrimaryPayerID in column L. The payer names are on the Payers sheet, which is hidden. Unhide it (right-click any sheet tab → Unhide…) and type the name of this patient's payer. | C15: Right-click a sheet tab → Unhide… | E15: =IF(IFERROR(D15="",FALSE),"",IF(IFERROR(OR(LOWER(TRIM(D15&""))=LOWER(TRIM('Answer Key'!$C$14&""))),FALSE),"✔ Correct","✘ Not yet"))
A16: 11 | B16: How many worksheets does this workbook contain in total, hidden ones included? Count the tabs you can see, then right-click a tab → Unhide… to see what's still hidden. Look, but don't unhide the answer keys yet! | C16: Visible tabs + the names listed in the Unhide dialog | E16: =IF(IFERROR(D16="",FALSE),"",IF(IFERROR(AND(ISNUMBER(D16),OR(ABS(D16-'Answer Key'!$C$15)<=0.0001)),FALSE),"✔ Correct","✘ Not yet"))
A17: 12 | B17: You want row 1 (the headers) and columns A:B (PatientID and MRN) to stay on screen while you scroll. Which cell must you select before choosing View → Freeze Panes → Freeze Panes? Type its address. | C17: Excel freezes everything above and to the left of the selected cell | E17: =IF(IFERROR(D17="",FALSE),"",IF(IFERROR(OR(LOWER(TRIM(D17&""))=LOWER(TRIM('Answer Key'!$C$16&"")),LOWER(TRIM(D17&""))="$c$2"),FALSE),"✔ Correct","✘ Not yet"))

Sheet Patients
A1: PatientID | B1: MRN | C1: LastName | D1: FirstName | E1: Sex | F1: DOB | G1: City | H1: ZIP | I1: Phone | J1: Email | K1: PreferredLanguage | L1: PrimaryPayerID | M1: PCPProviderID | N1: HeightIn | O1: WeightLb | P1: ChronicConditions | Q1: RegistrationDate
A2: PT10008 | B2: 04700089 | C2: Clark | D2: Arthur | E2: M | F2: 18921 | G2: Riverbend | H2: 45545 | I2: (555) 518-1637 | K2: Arabic | L2: PY02 | M2: PRV1139 | N2: 66.9 | O2: 187.1 | Q2: 44219
A3: PT10016 | B3: 07426502 | C3: Kennedy | D3: Danielle | E3: F | F3: 37473 | G3: Granite Springs | H3: 45750 | I3: (555) 476-8447 | J3: danielle.kennedy84@example.com | K3: English | L3: PY04 | M3: PRV1126 | N3: 63.1 | O3: 118.5 | Q3: 41955
A4: PT10024 | B4: 07685936 | C4: Sandoval | D4: Priya | E4: F | F4: 23950 | G4: Bluestone | H4: 45503 | I4: (555) 481-8733 | K4: English | L4: PY06 | M4: PRV1127 | N4: 62.9 | O4: 221.3 | P4: HTN;HF | Q4: 42105
A5: PT10032 | B5: 03929231 | C5: White | D5: Amber | E5: F | F5: 35240 | G5: Cedar Ridge | H5: 45720 | I5: (555) 556-3833 | J5: amber.white81@example.com | K5: English | L5: PY03 | M5: PRV1124 | N5: 66.4 | O5: 211.6 | Q5: 45483
A6: PT10040 | B6: 01627410 | C6: Carroll | D6: Lucia | E6: F | F6: 21777 | G6: Bluestone | H6: 45502 | I6: (555) 661-2143 | K6: English | L6: PY01 | M6: PRV1134 | N6: 65.3 | O6: 266.1 | P6: HTN | Q6: 42423
A7: PT10048 | B7: 03647016 | C7: Boyd | D7: Teresa | E7: F | F7: 45238 | G7: Ashby Falls | H7: 45610 | I7: (555) 678-0264 | K7: English | L7: PY03 | M7: PRV1104 | N7: 24.9 | O7: 17 | Q7: 45311
A8: PT10056 | B8: 05428930 | C8: Sanchez | D8: Lisa | E8: F | F8: 36674 | G8: Oak Glen | H8: 45730 | I8: (555) 200-2730 | J8: lisa.sanchez44@example.com | K8: Spanish | L8: PY07 | M8: PRV1140 | N8: 59.6 | O8: 106.3 | P8: ETOH | Q8: 41473
A9: PT10064 | B9: 08932643 | C9: Grant | D9: Natalie | E9: F | F9: 28231 | G9: Bluestone | H9: 45502 | I9: (555) 959-1391 | J9: natalie.grant52@example.com | K9: English | L9: PY06 | M9: PRV1134 | N9: 63.2 | O9: 132.7 | Q9: 45208
A10: PT10072 | B10: 08124000 | C10: Romero | D10: Alice | E10: F | F10: 45777 | G10: Bluestone | H10: 45501 | I10: (555) 625-3341 | K10: English | L10: PY05 | M10: PRV1105 | N10: 23.2 | O10: 13.8 | Q10: 45621
A11: PT10080 | B11: 08943314 | C11: Taylor | D11: Julie | E11: F | F11: 28549 | G11: Bluestone | H11: 45502 | I11: (555) 715-8462 | K11: English | L11: PY03 | M11: PRV1128 | N11: 67 | O11: 119.2 | P11: PSYCH | Q11: 42394
A12: PT10088 | B12: 07430462 | C12: Yilmaz | D12: Nicholas | E12: M | F12: 18457 | G12: Ashby Falls | H12: 45610 | I12: (555) 665-4621 | J12: nicholas.yilmaz10@example.com | K12: English | L12: PY01 | M12: PRV1124 | N12: 73.2 | O12: 169.9 | Q12: 44282
A13: PT10096 | B13: 04307890 | C13: Harris | D13: Elijah | E13: M | F13: 23365 | G13: Bluestone | H13: 45501 | I13: (555) 416-8448 | K13: English | L13: PY05 | M13: PRV1132 | N13: 76.8 | O13: 301.7 | P13: CANCER | Q13: 44421
A14: PT10104 | B14: 09055529 | C14: Pierce | D14: Samuel | E14: M | F14: 31972 | G14: Granite Springs | H14: 45750 | I14: (555) 268-4376 | J14: samuel.pierce7@example.com | K14: English | L14: PY03 | M14: PRV1139 | N14: 71.5 | O14: 233.4 | P14: DM;PSYCH | Q14: 45292
A15: PT10112 | B15: 01473420 | C15: Bailey | D15: Elizabeth | E15: F | F15: 21398 | G15: Lakeview Heights | H15: 45510 | I15: (555) 713-3477 | J15: elizabeth.bailey48@example.com | K15: Spanish | L15: PY02 | M15: PRV1131 | N15: 63.7 | O15: 182.8 | Q15: 40267
A16: PT10120 | B16: 01998299 | C16: Contreras | D16: Joseph | E16: M | F16: 23388 | G16: Granite Springs | H16: 45750 | I16: (555) 205-1626 | J16: joseph.contreras19@example.com | K16: English | L16: PY05 | M16: PRV1134 | N16: 67.9 | O16: 149.6 | P16: HTN;COPD;PSYCH | Q16: 44653
A17: PT10128 | B17: 08149461 | C17: Price | D17: Evelyn | E17: F | F17: 44118 | G17: Ashby Falls | H17: 45610 | I17: (555) 827-2489 | K17: English | L17: PY03 | M17: PRV1105 | N17: 30.8 | O17: 27.6 | Q17: 45120
A18: PT10136 | B18: 06020756 | C18: Butler | D18: Amina | E18: F | F18: 27365 | G18: Bluestone | H18: 45503 | I18: (555) 398-2220 | J18: amina.butler97@example.com | K18: English | L18: PY06 | M18: PRV1134 | N18: 62.2 | O18: 97.4 | P18: ETOH | Q18: 41098
A19: PT10144 | B19: 02454067 | C19: Jones | D19: Betty | E19: F | F19: 25267 | G19: Bluestone | H19: 45501 | I19: (555) 216-4750 | K19: English | L19: PY06 | M19: PRV1131 | N19: 62.9 | O19: 154.4 | Q19: 39510
A20: PT10152 | B20: 03219873 | C20: Alvarez | D20: Sharon | E20: F | F20: 26065 | G20: Bluestone | H20: 45501 | I20: (555) 223-5532 | K20: English | L20: PY06 | M20: PRV1131 | N20: 65.4 | O20: 205 | Q20: 44624
A21: PT10160 | B21: 04174427 | C21: Hansen | D21: Susan | E21: F | F21: 23054 | G21: Ashby Falls | H21: 45610 | I21: (555) 863-0761 | K21: English | L21: PY05 | M21: PRV1130 | N21: 64.9 | O21: 127.9 | P21: AFIB | Q21: 44610
A22: PT10168 | B22: 02322826 | C22: Petrov | D22: Mei | E22: F | F22: 33573 | G22: Bluestone | H22: 45503 | I22: (555) 527-1160 | J22: mei.petrov46@example.com | K22: English | L22: PY05 | M22: PRV1124 | N22: 65.4 | O22: 161.7 | Q22: 40687
A23: PT10176 | B23: 01358460 | C23: O'Brien | D23: Carl | E23: M | F23: 39851 | G23: Granite Springs | H23: 45750 | I23: (555) 701-8677 | J23: carl.obrien92@example.com | K23: English | L23: PY03 | M23: PRV1106 | N23: 70.3 | O23: 178.2 | Q23: 42413
A24: PT10184 | B24: 04439547 | C24: Meyer | D24: Rebecca | E24: F | F24: 32953 | G24: Bluestone | H24: 45501 | I24: (555) 869-4100 | K24: English | L24: PY04 | M24: PRV1137 | N24: 65.1 | O24: 152 | Q24: 44902
A25: PT10192 | B25: 00863078 | C25: Jackson | D25: Sharon | E25: F | F25: 30976 | G25: Bluestone | H25: 45503 | I25: (555) 466-5175 | J25: sharon.jackson13@example.com | K25: Spanish | L25: PY06 | M25: PRV1131 | N25: 67 | O25: 196.5 | P25: HTN | Q25: 41731
A26: PT10200 | B26: 04324932 | C26: Sullivan | D26: Jeremy | E26: M | F26: 30536 | G26: Millbrook | H26: 45530 | I26: (555) 431-1956 | J26: jeremy.sullivan79@example.com | K26: English | L26: PY03 | M26: PRV1126 | N26: 65.2 | O26: 169.7 | Q26: 40086
A27: PT10208 | B27: 09507441 | C27: Rivera | D27: Roy | E27: M | F27: 40681 | G27: Pine Hollow | H27: 45640 | I27: (555) 305-7867 | K27: English | L27: PY03 | M27: PRV1107 | N27: 61.1 | O27: 102.8 | P27: SEIZURE | Q27: 42787
A28: PT10216 | B28: 05508401 | C28: Mason | D28: Sophia | E28: F | F28: 45884 | G28: Bluestone | H28: 45503 | I28: (555) 291-2248 | K28: English | L28: PY03 | M28: PRV1104 | N28: 20.8 | O28: 9.9 | Q28: 45324
A29: PT10224 | B29: 00890329 | C29: Foster | D29: Alice | E29: F | F29: 32625 | G29: Bluestone | H29: 45502 | I29: (555) 702-9750 | K29: English | L29: PY04 | M29: PRV1140 | N29: 68.6 | O29: 254.6 | P29: ASTHMA | Q29: 41307
A30: PT10232 | B30: 03521479 | C30: Garza | D30: Jean | E30: F | F30: 44688 | G30: Bluestone | H30: 45501 | I30: (555) 384-4062 | K30: English | L30: PY06 | M30: PRV1107 | N30: 26.5 | O30: 15.4 | Q30: 45375
A31: PT10240 | B31: 03515282 | C31: Abdi | D31: Abigail | E31: F | F31: 42375 | G31: Bluestone | H31: 45501 | I31: (555) 964-0827 | K31: English | L31: PY03 | M31: PRV1105 | N31: 44.6 | O31: 65.1 | Q31: 44055
A32: PT10248 | B32: 00057585 | C32: Rivera | D32: Brittany | E32: F | F32: 41008 | G32: Ashby Falls | H32: 45610 | I32: (555) 251-7339 | K32: English | L32: PY04 | M32: PRV1108 | N32: 62.6 | O32: 133 | Q32: 45641
A33: PT10256 | B33: 03057839 | C33: Nguyen | D33: Brandon | E33: M | F33: 43285 | G33: Millbrook | H33: 45530 | I33: (555) 979-8588 | K33: English | L33: PY03 | M33: PRV1105 | N33: 37.3 | O33: 39.6 | Q33: 45116
A34: PT10264 | B34: 06291850 | C34: Robertson | D34: Diana | E34: F | F34: 35680 | G34: Riverbend | H34: 45545 | I34: (555) 343-4458 | K34: English | L34: PY04 | M34: PRV1137 | N34: 65 | O34: 174.4 | P34: ASTHMA | Q34: 40819
A35: PT10272 | B35: 00443312 | C35: Hoffman | D35: Judy | E35: F | F35: 18259 | G35: Bluestone | H35: 45503 | I35: (555) 795-8281 | J35: judy.hoffman41@example.com | K35: Spanish | L35: PY04 | N35: 64 | O35: 206 | P35: DM | Q35: 44219
A36: PT10280 | B36: 02758864 | C36: Lee | D36: Joan | E36: F | F36: 23266 | G36: Bluestone | H36: 45501 | I36: (555) 731-2249 | J36: joan.lee32@example.com | K36: English | L36: PY03 | M36: PRV1126 | N36: 61.3 | O36: 188.8 | P36: ETOH | Q36: 44552
A37: PT10288 | B37: 02406591 | C37: Daniels | D37: Diane | E37: F | F37: 20393 | G37: Pine Hollow | H37: 45640 | I37: (555) 820-1143 | K37: English | L37: PY01 | M37: PRV1136 | N37: 62.6 | O37: 141.3 | Q37: 41850
A38: PT10296 | B38: 06090552 | C38: Andrews | D38: Madison | E38: F | F38: 24707 | G38: Oak Glen | H38: 45730 | I38: (555) 895-9192 | K38: English | L38: PY04 | M38: PRV1128 | N38: 59.7 | O38: 93.9 | Q38: 43867
A39: PT10304 | B39: 00049359 | C39: Richards | D39: Robert | E39: M | F39: 20031 | G39: Riverbend | H39: 45545 | I39: (555) 559-8984 | J39: robert.richards78@example.com | K39: Spanish | L39: PY01 | M39: PRV1127 | N39: 69.8 | O39: 268.8 | P39: HTN | Q39: 45322
A40: PT10312 | B40: 06265337 | C40: Davis | D40: Jean | E40: F | F40: 33249 | G40: Bluestone | H40: 45502 | I40: (555) 692-3169 | K40: Spanish | L40: PY05 | M40: PRV1129 | N40: 67.4 | O40: 137.5 | Q40: 43703
...

Sheet Payers
A1: PayerID | B1: PayerName | C1: PayerType
A2: PY01 | B2: Medicare | C2: Government
A3: PY02 | B3: Silverline Medicare Advantage | C3: Medicare Advantage
A4: PY03 | B4: State Medicaid | C4: Government
A5: PY04 | B5: Keystone Health Partners | C5: Commercial
A6: PY05 | B6: Evergreen Mutual Insurance | C6: Commercial
A7: PY06 | B7: Summit Choice PPO | C7: Commercial
A8: PY07 | B8: Self-Pay | C8: Self-Pay
A9: PY08 | B9: Workers' Compensation | C9: Workers' Comp

Sheet Bonus
A1: Lesson 1.1 · Bonus: Data-quality scavenger hunt
A2: The population-health team is starting a blood-pressure outreach program and will build its mailing list from this patient index. Before the letters go out, the data steward asks you to check four facts. Set up the Patients sheet first: if you froze panes earlier, choose View → Freeze Panes → Unfreeze Panes. Then press Ctrl+Home (Mac: Control+Home), click B2, and choose View → Freeze Panes → Freeze Panes so the headers and the PatientID column stay in view. Also turn on Minimum and Maximum in the status bar. You'll look everything up on the Patients sheet and type your answers on the Bonus sheet, without a single formula.
A3: Type a formula or value in each yellow cell. The Check column turns green when your answer matches. Stuck? Read the hint, then the lesson guide. Answers: right-click a sheet tab → Unhide… → 'Bonus Key'.
A4: ="Score: "&COUNTIF(E6:E9,"✔*")&" of 4 auto-checked tasks correct"
A5: # | B5: Task | C5: Hint | D5: Your Answer | E5: Check
A6: B1 | B6: Each outreach letter is signed by the patient's primary care provider (PCP), and a blank PCPProviderID means no PCP is on file. Use Go To (F5 or Ctrl+G, Mac: Control+G) to select M2:M501. How many of the 500 patients have no PCP? | C6: The status bar counts filled cells, but you want the empty ones | E6: =IF(IFERROR(D6="",FALSE),"",IF(IFERROR(AND(ISNUMBER(D6),OR(ABS(D6-'Bonus Key'!$C$5)<=0.0001)),FALSE),"✔ Correct","✘ Not yet"))
A7: B2 | B7: The program targets every patient with hypertension, coded HTN. Click a single cell such as A1, so Find searches the whole sheet rather than the column you just selected. Press Ctrl+F (Mac: Control+F), click Options >> and make sure Match entire cell contents is OFF, then Find All for HTN. How many patients have HTN anywhere in their ChronicConditions list? | C7: Partial matches count: 'HTN;DM' contains HTN | E7: =IF(IFERROR(D7="",FALSE),"",IF(IFERROR(AND(ISNUMBER(D7),OR(ABS(D7-'Bonus Key'!$C$6)<=0.0001)),FALSE),"✔ Correct","✘ Not yet"))
A8: B3 | B8: Patients whose only condition is hypertension will get a shorter letter. Turn ON Match entire cell contents and Find All for HTN again. How many patients have hypertension as their ONLY recorded chronic condition? | C8: Match entire cell contents finds cells that are exactly HTN | E8: =IF(IFERROR(D8="",FALSE),"",IF(IFERROR(AND(ISNUMBER(D8),OR(ABS(D8-'Bonus Key'!$C$7)<=0.0001)),FALSE),"✔ Correct","✘ Not yet"))
A9: B4 | B9: Finally, the steward wants to confirm that the largest weight on file is real and not a typo. Which patient is the heaviest? Select O2:O501, read Maximum on the status bar, then use Find to locate that weight and read the PatientID in the frozen column A. Type the PatientID. | C9: Status bar Maximum, then Ctrl+F for that number | E9: =IF(IFERROR(D9="",FALSE),"",IF(IFERROR(OR(LOWER(TRIM(D9&""))=LOWER(TRIM('Bonus Key'!$C$8&""))),FALSE),"✔ Correct","✘ Not yet"))

Sheet Answer Key
A1: 🔑 Answer Key — Lesson 1.1
A2: Spoiler alert: try every task before reading this sheet. Column C is the value the Check column compares against. Column D is a sample solution, and column E recalculates a formula for it live, proving the answer.
A4: # | B4: Task | C4: Answer | D4: Sample solution | E4: Live result | F4: Explanation
A5: 1 | B5: On the Patients sheet, click in the Name Box (the box at the left end of the formula bar), type C347, and press Enter. What last name is in that cell? | C5: Coleman | D5: 1. Click the Name Box, type C347, press Enter. 2. Read the cell (or the formula bar). | E5: {=Patients!C347} | F5: The Name Box always shows the address of the active cell, and it works in reverse too: type an address, press Enter, and Excel takes you there. That's faster than scrolling 345 rows. Column C holds LastName, so C347 is the last name of the patient in row 347.
A6: 2 | B6: What is the address of the bottom-right cell of the patient data? From A1, press Ctrl+↓ to find the last row, go back with Ctrl+↑, then press Ctrl+→ to find the last column. Type the address as column letter + row number (like B12). | C6: Q501 | D6: 1. Click A1 and press Ctrl+↓: the active cell becomes A501. 2. Press Ctrl+↑ to return to A1, then Ctrl+→: the active cell becomes Q1. 3. Combine them: Q501. Press Ctrl+End (Mac: Control+End, or Control+Fn+→) to confirm. It jumps straight there. | E6: {=ADDRESS(COUNTA(Patients!A:A),COUNTA(Patients!1:1),4)} | F6: Ctrl+arrow jumps to the edge of the block of filled cells. Column A and row 1 have no gaps, so the jumps land on the true last row (501: 500 patients plus the header row) and the true last column (Q). Ctrl+End goes straight to the last used cell, Q501. The hidden column I doesn't change the answer, because hiding a column doesn't remove it.
A7: 3 | B7: Use the Name Box to go to cell A600, which is in an empty row below the data, then press Ctrl+→. Excel races across the empty row to the very last column of the worksheet. What is the address of the cell you land on? | C7: XFD600 | D7: 1. Type A600 in the Name Box and press Enter. 2. Press Ctrl+→. The Name Box shows XFD600. 3. Press Ctrl+← to come back to column A. | E7: {=ADDRESS(600,COLUMNS(Patients!1:1),4)} | F7: When the row is empty, Ctrl+→ has no data to stop at, so it goes to the edge of the sheet: column XFD, the 16,384th column. Ctrl+↓ in an empty column goes to row 1,048,576. Every modern worksheet has exactly 1,048,576 rows × 16,384 columns.
A8: 4 | B8: Click M1 (the PCPProviderID header) and press Ctrl+↓ once. On which row number does Excel stop? | C8: 34 | D8: 1. Click M1 (or type M1 in the Name Box). 2. Press Ctrl+↓. The Name Box shows M34. | E8: {=MATCH(TRUE,ISBLANK(Patients!M2:M501),0)} | F8: M35 is empty because that patient has no primary care provider on file. Ctrl+↓ stops at the last filled cell before the gap, M34, even though the data continues to row 501. Never assume Ctrl+↓ found the bottom of a column with blanks. Check the row number, or press Ctrl+↓ again to keep jumping.
A9: 5 | B9: Select the Email data cells J2:J501: type J2:J501 in the Name Box and press Enter. How many patients have an email address on file? Read Count on the status bar. | C9: 298 | D9: 1. Type J2:J501 in the Name Box and press Enter. 2. Read Count on the status bar. | E9: {=COUNTA(Patients!J2:J501)} | F9: The status bar's Count counts every non-empty cell, text included, so it counts the email addresses and skips the blanks. Typing the range in the Name Box selects exactly 500 cells. Ctrl+Shift+↓ from J2 would be a trap, because the Email column has gaps: it would select only J2:J3. In a Table you can also click any Email cell and press Ctrl+Space (Mac: Control+Space) to select just that column's data.
A10: 6 | B10: Select the WeightLb values O2:O501 with Go To: press F5 or Ctrl+G (Mac: Control+G), type O2:O501, and press Enter. What is the average weight in pounds? Round to 1 decimal place. | C10: 167.8 | D10: 1. Press F5 (or Ctrl+G), type O2:O501 in Reference, press Enter. 2. Read Average on the status bar and round it to 1 decimal place. | E10: {=ROUND(AVERAGE(Patients!O2:O501),1)} | F10: Go To selects any range you type, however large. The status bar's Average is 167.8442, which rounds to 167.8. The average is pulled down by children in the list: the lightest patient weighs 9.7 lb, which is a baby and not a typo. Always glance at Minimum and Maximum before trusting an average.
A11: 7 | B11: Turn on Minimum in the status bar: right-click the status bar and tick Minimum. Then click cell F2 (the first DOB) and press Ctrl+Shift+↓ to select every date of birth. What is the date of birth of the oldest patient? Type it as month/day/year, the way the status bar shows it. (If your computer uses day/month dates, type the month as a word instead, such as 15 Mar 1950.) | C11: 9534 | D11: 1. Right-click the status bar and tick Minimum (and Maximum while you're there). 2. Click cell F2 and press Ctrl+Shift+↓ to select F2:F501. 3. Read Minimum on the status bar. | E11: {=MIN(Patients!F2:F501)} | F11: Excel stores dates as numbers that grow by 1 each day, so the earliest date is the smallest number and Minimum finds it. The status bar shows it as a date because the cells are formatted as dates. (If you see a plain number such as 9534 instead, that's the date's serial number, and the check accepts it.) Ctrl+Shift+↓ is safe here because the DOB column has no blanks.
A12: 8 | B12: How many patients live in Millbrook? On the Patients sheet, click a single cell such as A1 so Find searches the whole sheet. Then press Ctrl+F (Mac: Control+F), type Millbrook, click Find All, and read the count at the bottom of the dialog. | C12: 31 | D12: 1. Click A1 (one cell, so Find searches the whole sheet). 2. Press Ctrl+F, type Millbrook, and click Find All. 3. Read '… cell(s) found' at the bottom of the dialog. | E12: {=COUNTIF(Patients!A1:Q501,"*Millbrook*")} | F12: Find All lists every matching cell on the sheet and counts them. That's a count of patients here only because the word Millbrook appears in the City column and nowhere else. If a search term could also appear inside other text, such as an email address, turn on Match entire cell contents under Options. Clicking a single cell first matters too. When several cells are selected, Find searches only inside the selection, so with the DOB column still selected from the previous task, Find All would report nothing.
A13: 9 | B13: Column I is hidden (the column letters jump from H to J). Unhide it, then click cell A1 and use Ctrl+F (Mac: Control+F) to find patient PT12376. What is that patient's phone number? | C13: (555) 740-8462 | D13: 1. Click the H column header, Shift+click the J header, then right-click → Unhide. 2. Click A1, press Ctrl+F, type PT12376, click Find Next, then close the dialog. 3. Read column I on row 298. | E13: {=Patients!I298} | F13: You can't click a hidden column, so you select the columns on both sides of it (H and J) and choose Unhide. Click A1 before you search, because while those three columns are selected, Find looks only inside them. The patient is on row 298. Hiding never deletes data: the phone numbers were there all along, so a hidden column is not a safe place for confidential data.
A14: 10 | B14: Patient PT13312 has a PrimaryPayerID in column L. The payer names are on the Payers sheet, which is hidden. Unhide it (right-click any sheet tab → Unhide…) and type the name of this patient's payer. | C14: Summit Choice PPO | D14: 1. On the Patients sheet, click A1, press Ctrl+F, and find PT13312: row 415, payer ID PY06. 2. Right-click any sheet tab → Unhide… → Payers → OK. 3. On the Payers sheet, PY06 is Summit Choice PPO. | E14: {=INDEX(Payers!$B$2:$B$9,MATCH(Patients!L415,Payers!$A$2:$A$9,0))} | F14: Hidden sheets don't show a tab, so the only clue is the Unhide… command becoming available. This is the same move you'll use to open the Answer Key in every lesson. Small lookup lists like this one are often hidden to keep a workbook tidy, and in Lesson 2.6 you'll learn to pull names from them automatically with a lookup formula.
A15: 11 | B15: How many worksheets does this workbook contain in total, hidden ones included? Count the tabs you can see, then right-click a tab → Unhide… to see what's still hidden. Look, but don't unhide the answer keys yet! | C15: 7 | D15: 1. Count the visible tabs: Start Here, Practice, Patients, Payers (now unhidden), Bonus. 2. Right-click a tab → Unhide…: the list shows Answer Key and Bonus Key. Click Cancel. 3. 5 + 2 = 7. | E15: {=_xlfn.SHEETS()} | F15: A workbook is the file, and each worksheet is one tab inside it. This file has 7 worksheets, and 2 of them are still hidden: the Answer Key and the Bonus Key. The total is the same whether or not you unhid Payers first, because hiding a sheet doesn't remove it.
A16: 12 | B16: You want row 1 (the headers) and columns A:B (PatientID and MRN) to stay on screen while you scroll. Which cell must you select before choosing View → Freeze Panes → Freeze Panes? Type its address. | C16: C2 | D16: 1. Click C2. 2. View → Freeze Panes → Freeze Panes. 3. Scroll down and right: row 1 and columns A:B stay put. (View → Freeze Panes → Unfreeze Panes undoes it.) | E16: — | F16: Freeze Panes freezes the rows above the active cell and the columns to its left. To keep 1 row and 2 columns, select the cell just below row 1 and just right of column B: C2. Selecting B2 would keep row 1 but only column A, and A2 would freeze only row 1, which is the same as Freeze Top Row.

Sheet Bonus Key
A1: 🔑 Bonus Key — Lesson 1.1
A2: Spoiler alert: try every task before reading this sheet. Column C is the value the Check column compares against. Column D is a sample solution, and column E recalculates a formula for it live, proving the answer.
A4: # | B4: Task | C4: Answer | D4: Sample solution | E4: Live result | F4: Explanation
A5: B1 | B5: Each outreach letter is signed by the patient's primary care provider (PCP), and a blank PCPProviderID means no PCP is on file. Use Go To (F5 or Ctrl+G, Mac: Control+G) to select M2:M501. How many of the 500 patients have no PCP? | C5: 31 | D5: 1. Press F5, type M2:M501, press Enter. 2. The status bar shows Count: 469. 3. 500 − 469 = 31. | E5: {=COUNTBLANK(Patients!M2:M501)} | F5: Count only counts non-empty cells, so it tells you how many patients do have a PCP (469). The range M2:M501 covers rows 2 to 501, which is 500 cells, so 500 − 469 leaves 31 blanks. Any of those patients who have hypertension need a PCP assigned before a letter can go out. (If you select by dragging instead, the Name Box shows the size of the selection while you drag, such as 500R x 1C.)
A6: B2 | B6: The program targets every patient with hypertension, coded HTN. Click a single cell such as A1, so Find searches the whole sheet rather than the column you just selected. Press Ctrl+F (Mac: Control+F), click Options >> and make sure Match entire cell contents is OFF, then Find All for HTN. How many patients have HTN anywhere in their ChronicConditions list? | C6: 144 | D6: 1. Click A1, then Ctrl+F → Options >> → untick Match entire cell contents. 2. Type HTN and click Find All. 3. Read the count at the bottom of the dialog. | E6: {=COUNTIF(Patients!A1:Q501,"*HTN*")} | F6: By default Find matches text anywhere inside a cell, so it finds HTN on its own and also inside lists like HTN;DM and HTN;HF. No other column contains the letters HTN, so every hit is a patient with hypertension.
A7: B3 | B7: Patients whose only condition is hypertension will get a shorter letter. Turn ON Match entire cell contents and Find All for HTN again. How many patients have hypertension as their ONLY recorded chronic condition? | C7: 48 | D7: 1. In the Find dialog, tick Match entire cell contents. 2. Find All for HTN. 3. Read the count. | E7: {=COUNTIF(Patients!A1:Q501,"HTN")} | F7: With Match entire cell contents on, a cell must equal HTN exactly, so HTN;DM no longer counts. The gap between the two answers (144 − 48 = 96) is the number of hypertensive patients with at least one other condition. When you finish this challenge, turn the option off again, because Find keeps your settings until you close Excel.
A8: B4 | B8: Finally, the steward wants to confirm that the largest weight on file is real and not a typo. Which patient is the heaviest? Select O2:O501, read Maximum on the status bar, then use Find to locate that weight and read the PatientID in the frozen column A. Type the PatientID. | C8: PT13784 | D8: 1. Select O2:O501 (Name Box or Go To) and read Maximum: 319.2. 2. With the weights still selected, press Ctrl+F → Find what: 319.2 → Find Next. (Match entire cell contents can be on or off here, because no other cell on the sheet contains 319.2.) 3. Excel selects O474. The frozen column A shows PT13784. | E8: {=INDEX(Patients!A2:A501,MATCH(MAX(Patients!O2:O501),Patients!O2:O501,0))} | F8: The status bar tells you what the largest value is but not where it is. Find tells you where, and leaving the weights selected helps, because Find then searches only inside the selection. Because panes are frozen at B2, column A stays on screen when Find scrolls over to the WeightLb column, so you can read the ID without losing your place. Teams use this check to plan bariatric beds and lift equipment, and it's also how you'd spot a typo such as 3192 lb.
