Workbook

Sheet Start Here
B2: Lesson 3.1
B3: Excel Tables, Structured References & Named Ranges
B4: Intermediate · about 105 minutes · Bluestone Health System (fictional)
B6: What you'll learn
B7: • | C7: Convert ranges to Excel Tables and name them
B8: • | C8: Write structured references like tblInventory[UnitCost] and [@QtyOnHand]
B9: • | C9: Use calculated columns, the Total Row, and slicers on Tables
B10: • | C10: Create, manage, and use named ranges and named constants
B12: How to use this workbook
B13: 1. Read the guide | C13: The lesson guide (README) explains each skill with examples: https://github.com/lmansf/learn-excel/tree/main/03-data-analysis/01-tables-named-ranges
B14: 2. Practice | C14: Go to the 'Practice' sheet. Type a formula or value into each yellow cell. For tasks 1, 3, 5, and 9, do the work on the Inventory or Settings sheet instead, and the task's gray cell on Practice reads it.
B15: 3. Check yourself | C15: The Check column shows ✔ Correct (green) or ✘ Not yet (red).
B16: 4. Bonus | C16: Finished? Try the harder 'Bonus' sheet.
B17: 5. Answers | C17: The 'Answer Key' and 'Bonus Key' sheets are hidden. Right-click any sheet tab → Unhide… → pick one → OK. (Try first!)
B18: Note | C18: The Inventory, Settings, and Vendors sheets are plain ranges on purpose. You turn them into Tables and named cells as part of the practice and the bonus.
B20: Color legend
B21: Yellow cell | C21: Your answer goes here.
B22: Gray cell | C22: Pre-filled summary formula. It reads the work you did on another sheet, so don't type over it.
B23: ✔ Correct | C23: Your answer matches the key.
B24: ✘ Not yet | C24: Not matching yet. Check the hint and try again.
B26: Sheets in this workbook
B27: Practice | C27: 12 practice tasks, each with a Check cell.
B28: Inventory | C28: Data: 257 rows
B29: Settings | C29: Data: 2 rows
B30: Bonus | C30: The bonus challenge (4 parts).
B31: Vendors | C31: Data: 7 rows
B32: About the data | C32: Supply inventory snapshot for 15 storerooms across three Bluestone hospitals (257 stock rows, as of 12/31/2025), a Settings sheet with the report date and expiry window, and Purchasing's vendor list.
B33: Disclaimer | C33: All people, places, and numbers are synthetic and fictional. Not clinical guidance.

Sheet Practice
A1: Lesson 3.1 · Practice
A2: The tasks use the Inventory sheet: supply stock in 15 storerooms across three Bluestone hospitals, in the snapshot taken on 12/31/2025. Task 9 also uses the Settings sheet. Do the tasks in order, because later tasks use the Table, columns, Total Row, and names you create in earlier ones. After task 1, write formulas with structured references such as tblInventory[QtyOnHand] instead of cell ranges.
A3: Type a formula or value in each yellow cell. For tasks 1, 3, 5, and 9, do the work on the Inventory or Settings sheet instead, and the gray cell here reads it. The Check column turns green when your answer matches. Stuck? Read the hint, then the lesson guide. Answers: right-click a sheet tab → Unhide… → 'Answer Key'.
A4: ="Score: "&COUNTIF(E6:E17,"✔*")&" of 12 auto-checked tasks correct"
A5: # | B5: Task | C5: Hint | D5: Your Answer | E5: Check
A6: 1 | B6: On the Inventory sheet, click any cell in the data and convert the range to an Excel Table with Ctrl + T (Mac: Control + T). Then rename the Table tblInventory in the Table Name box on the Table Design tab (Mac: Table tab). The gray cell finds a Table with that exact name and counts its data rows. It stays blank until the Table exists. | C6: Make sure 'My table has headers' is ticked | D6: {=IFERROR(ROWS(INDIRECT("tblInventory")),"")} | E6: =IF(IFERROR(D6="",FALSE),"",IF(IFERROR(AND(ISNUMBER(D6),OR(ABS(D6-'Answer Key'!$C$5)<=0.0001)),FALSE),"✔ Correct","✘ Not yet"))
A7: 2 | B7: How many stock rows are completely out of stock (QtyOnHand = 0)? Use a structured reference to the QtyOnHand column instead of a cell range. | C7: COUNTIF. Type tblInventory[ and pick the column from the list | E7: =IF(IFERROR(D7="",FALSE),"",IF(IFERROR(AND(ISNUMBER(D7),OR(ABS(D7-'Answer Key'!$C$6)<=0.0001)),FALSE),"✔ Correct","✘ Not yet"))
A8: 3 | B8: Fill the yellow ExtendedValue column (column R) with a calculated column: each row's QtyOnHand × UnitCost. Type the formula once in R2 and press Enter, and the Table fills every row. The gray cell totals the column: what's the value of all stock on hand across the system? | C8: Click the QtyOnHand cell in the same row while you type, and Excel writes [@QtyOnHand] | D8: {=IF(COUNT(Inventory!$R$2:$R$258)=0,"",SUM(Inventory!$R$2:$R$258))} | E8: =IF(IFERROR(D8="",FALSE),"",IF(IFERROR(AND(ISNUMBER(D8),OR(ABS(D8-'Answer Key'!$C$7)<=0.0051)),FALSE),"✔ Correct","✘ Not yet"))
A9: 4 | B9: What share of the system's total inventory value (ExtendedValue) is Orthopedic Implants stock? Divide the category's value by the total of all rows and enter it as a percentage, to 1 decimal place. | C9: SUMIFS(…)/SUM(…), both with structured references | E9: =IF(IFERROR(D9="",FALSE),"",IF(IFERROR(AND(ISNUMBER(D9),OR(ABS(D9-'Answer Key'!$C$8)<=0.00051,ABS(D9-'Answer Key'!$C$8*100)<=0.051000000000000004)),FALSE),"✔ Correct","✘ Not yet"))
A10: 5 | B10: Fill the yellow NeedsReorder column (column S) with a calculated column that returns TRUE when QtyOnHand is at or below ReorderPoint, and FALSE otherwise. The gray cell counts the TRUE rows: how many stock rows need reordering? | C10: A comparison already returns TRUE or FALSE, so you don't need IF | D10: {=IF(COUNTA(Inventory!$S$2:$S$258)=0,"",COUNTIF(Inventory!$S$2:$S$258,TRUE))} | E10: =IF(IFERROR(D10="",FALSE),"",IF(IFERROR(AND(ISNUMBER(D10),OR(ABS(D10-'Answer Key'!$C$9)<=0.0001)),FALSE),"✔ Correct","✘ Not yet"))
A11: 6 | B11: Turn on the Table's Total Row and set the LeadTimeDays total to Average. Then, in the yellow cell, type = and click that Total Row cell, so Excel writes a [#Totals] reference. What's the average vendor lead time in days, to 2 decimal places? | C11: Table Design → Total Row (Windows: Ctrl + Shift + T; Mac: Table → Total Row), then use the drop-down arrow in the Total Row cell | E11: =IF(IFERROR(D11="",FALSE),"",IF(IFERROR(AND(ISNUMBER(D11),OR(ABS(D11-'Answer Key'!$C$10)<=0.0051)),FALSE),"✔ Correct","✘ Not yet"))
A12: 7 | B12: With the Total Row still on, what does =ROWS(tblInventory[#All]) return? Predict it first, then type the formula to check. | C12: #All is everything: which rows does it include that tblInventory[QtyOnHand] doesn't? | E12: =IF(IFERROR(D12="",FALSE),"",IF(IFERROR(AND(ISNUMBER(D12),OR(ABS(D12-'Answer Key'!$C$11)<=0.0001)),FALSE),"✔ Correct","✘ Not yet"))
A13: 8 | B13: Insert slicers for Facility and Category (Table Design → Insert Slicer; Mac: Table → Insert Slicer). Select Cedar Ridge Medical Center in the Facility slicer and Surgical in the Category slicer. Set the Total Row's ExtendedValue cell to Sum. What value does it show? Type the number, then clear both slicers, because while they filter the Table the Total Row (and task 6) only summarizes the visible rows. | C13: Slicers filter the Table, and SUBTOTAL ignores rows the filter hides | E13: =IF(IFERROR(D13="",FALSE),"",IF(IFERROR(AND(ISNUMBER(D13),OR(ABS(D13-'Answer Key'!$C$12)<=0.0051)),FALSE),"✔ Correct","✘ Not yet"))
A14: 9 | B14: On the Settings sheet, select A2:B3 and use Formulas → Create from Selection (tick only Left column) to name cell B2 ReportDate and cell B3 ExpiringWindowDays. The gray cell looks up both names and adds them: what date does it show? | C14: The labels in column A become the names of the cells beside them | D14: {=IFERROR(INDIRECT("ReportDate")+INDIRECT("ExpiringWindowDays"),"")} | E14: =IF(IFERROR(D14="",FALSE),"",IF(IFERROR(AND(ISNUMBER(D14),INT(D14)=INT('Answer Key'!$C$13)),FALSE),"✔ Correct","✘ Not yet"))
A15: 10 | B15: How many stock rows expire inside the expiry window? Count rows whose ExpirationDate is later than ReportDate and no later than ReportDate + ExpiringWindowDays. Use the two names in a COUNTIFS (rows with no ExpirationDate don't count). | C15: Join an operator to a name the way you join it to a cell: ">"&ReportDate | E15: =IF(IFERROR(D15="",FALSE),"",IF(IFERROR(AND(ISNUMBER(D15),OR(ABS(D15-'Answer Key'!$C$14)<=0.0001)),FALSE),"✔ Correct","✘ Not yet"))
A16: 11 | B16: Expired stock must be pulled from the shelves and written off. What's the total ExtendedValue of rows whose ExpirationDate is before ReportDate? Enter it to the cent. | C16: SUMIFS with a "<"&ReportDate criterion | E16: =IF(IFERROR(D16="",FALSE),"",IF(IFERROR(AND(ISNUMBER(D16),OR(ABS(D16-'Answer Key'!$C$15)<=0.0051)),FALSE),"✔ Correct","✘ Not yet"))
A17: 12 | B17: Policy says every stock row must be cycle-counted at least every 30 days. Create a named constant CycleCountDays that refers to =30 with Formulas → Define Name. It doesn't live in any cell. How many rows are overdue, meaning ReportDate − LastCountDate is greater than CycleCountDays? | C17: Rearrange: overdue means LastCountDate < ReportDate − CycleCountDays | E17: =IF(IFERROR(D17="",FALSE),"",IF(IFERROR(AND(ISNUMBER(D17),OR(ABS(D17-'Answer Key'!$C$16)<=0.0001)),FALSE),"✔ Correct","✘ Not yet"))

Sheet Inventory
A1: StockID | B1: SKU | C1: ItemDescription | D1: Category | E1: Vendor | F1: UnitOfMeasure | G1: UnitCost | H1: Facility | I1: Location | J1: QtyOnHand | K1: ParLevel | L1: ReorderPoint | M1: ReorderQty | N1: LeadTimeDays | O1: LastCountDate | P1: ExpirationDate | Q1: LotNumber | R1: ExtendedValue | S1: NeedsReorder
A2: STK4001 | B2: SKU-10007 | C2: Nitrile Exam Gloves Small (Box/100) | D2: PPE | E2: Harbor Health Products | F2: Box | G2: 8.22 | H2: Cedar Ridge Medical Center | I2: Emergency Department | J2: 527 | K2: 481 | L2: 140 | M2: 341 | N2: 2 | O2: 45999
A3: STK4002 | B3: SKU-10014 | C3: Nitrile Exam Gloves Medium (Box/100) | D3: PPE | E3: Northstar Medical Supply | F3: Box | G3: 7.8 | H3: Bluestone Memorial Hospital | I3: Medical-Surgical 4 West | J3: 403 | K3: 800 | L3: 313 | M3: 487 | N3: 5 | O3: 46014
A4: STK4003 | B4: SKU-10014 | C4: Nitrile Exam Gloves Medium (Box/100) | D4: PPE | E4: Northstar Medical Supply | F4: Box | G4: 7.8 | H4: Bluestone Memorial Hospital | I4: Perioperative Services | J4: 578 | K4: 800 | L4: 225 | M4: 575 | N4: 2 | O4: 45988
A5: STK4004 | B5: SKU-10021 | C5: Nitrile Exam Gloves Large (Box/100) | D5: PPE | E5: Northstar Medical Supply | F5: Box | G5: 9.28 | H5: Bluestone Memorial Hospital | I5: Pediatrics | J5: 550 | K5: 491 | L5: 179 | M5: 312 | N5: 3 | O5: 46008
A6: STK4005 | B6: SKU-10021 | C6: Nitrile Exam Gloves Large (Box/100) | D6: PPE | E6: Northstar Medical Supply | F6: Box | G6: 9.28 | H6: Bluestone Memorial Hospital | I6: Perioperative Services | J6: 495 | K6: 460 | L6: 155 | M6: 305 | N6: 2 | O6: 45989
A7: STK4006 | B7: SKU-10021 | C7: Nitrile Exam Gloves Large (Box/100) | D7: PPE | E7: Northstar Medical Supply | F7: Box | G7: 9.28 | H7: Ashby Falls Community Hospital | I7: Medical-Surgical | J7: 324 | K7: 497 | L7: 193 | M7: 304 | N7: 10 | O7: 46014
A8: STK4007 | B8: SKU-10028 | C8: Nitrile Exam Gloves X-Large (Box/100) | D8: PPE | E8: Northstar Medical Supply | F8: Box | G8: 7.29 | H8: Cedar Ridge Medical Center | I8: Emergency Department | J8: 703 | K8: 788 | L8: 290 | M8: 498 | N8: 7 | O8: 46013
A9: STK4008 | B9: SKU-10035 | C9: Isolation Gown, Level 2 Regular | D9: PPE | E9: CareLine Distributors | F9: Case | G9: 54.86 | H9: Bluestone Memorial Hospital | I9: Labor & Delivery | J9: 0 | K9: 72 | L9: 18 | M9: 54 | N9: 3 | O9: 46020
A10: STK4009 | B10: SKU-10035 | C10: Isolation Gown, Level 2 Regular | D10: PPE | E10: CareLine Distributors | F10: Case | G10: 54.86 | H10: Ashby Falls Community Hospital | I10: Emergency Department | J10: 47 | K10: 174 | L10: 48 | M10: 126 | N10: 2 | O10: 45978
A11: STK4010 | B11: SKU-10042 | C11: Isolation Gown, Level 2 X-Large | D11: PPE | E11: CareLine Distributors | F11: Case | G11: 51.32 | H11: Bluestone Memorial Hospital | I11: Labor & Delivery | J11: 65 | K11: 55 | L11: 19 | M11: 36 | N11: 7 | O11: 45980
A12: STK4011 | B12: SKU-10042 | C12: Isolation Gown, Level 2 X-Large | D12: PPE | E12: CareLine Distributors | F12: Case | G12: 51.32 | H12: Bluestone Memorial Hospital | I12: Perioperative Services | J12: 82 | K12: 77 | L12: 26 | M12: 51 | N12: 2 | O12: 45999
A13: STK4012 | B13: SKU-10049 | C13: N95 Respirator Small (Box/20) | D13: PPE | E13: Northstar Medical Supply | F13: Box | G13: 31.56 | H13: Bluestone Memorial Hospital | I13: Orthopedics & Spine | J13: 263 | K13: 226 | L13: 86 | M13: 140 | N13: 3 | O13: 45986 | P13: 46367 | Q13: L567778
A14: STK4013 | B14: SKU-10049 | C14: N95 Respirator Small (Box/20) | D14: PPE | E14: Northstar Medical Supply | F14: Box | G14: 31.56 | H14: Bluestone Memorial Hospital | I14: Oncology | J14: 126 | K14: 225 | L14: 88 | M14: 137 | N14: 10 | O14: 45995 | P14: 46181 | Q14: L705867
A15: STK4014 | B15: SKU-10049 | C15: N95 Respirator Small (Box/20) | D15: PPE | E15: Northstar Medical Supply | F15: Box | G15: 31.56 | H15: Bluestone Memorial Hospital | I15: Laboratory | J15: 37 | K15: 150 | L15: 53 | M15: 97 | N15: 3 | O15: 45987 | P15: 46126 | Q15: L670999
A16: STK4015 | B16: SKU-10056 | C16: N95 Respirator Regular (Box/20) | D16: PPE | E16: Northstar Medical Supply | F16: Box | G16: 30.79 | H16: Bluestone Memorial Hospital | I16: Medical-Surgical 5 East | J16: 121 | K16: 148 | L16: 39 | M16: 109 | N16: 3 | O16: 46014 | P16: 46324 | Q16: L274021
A17: STK4016 | B17: SKU-10056 | C17: N95 Respirator Regular (Box/20) | D17: PPE | E17: Northstar Medical Supply | F17: Box | G17: 30.79 | H17: Bluestone Memorial Hospital | I17: Labor & Delivery | J17: 36 | K17: 117 | L17: 32 | M17: 85 | N17: 10 | O17: 45983 | P17: 46487 | Q17: L412381
A18: STK4017 | B18: SKU-10056 | C18: N95 Respirator Regular (Box/20) | D18: PPE | E18: Northstar Medical Supply | F18: Box | G18: 30.79 | H18: Bluestone Memorial Hospital | I18: Perioperative Services | J18: 71 | K18: 153 | L18: 60 | M18: 93 | N18: 3 | O18: 45989 | P18: 46118 | Q18: L805667
A19: STK4018 | B19: SKU-10063 | C19: Procedure Mask, Ear Loop (Box/50) | D19: PPE | E19: CareLine Distributors | F19: Box | G19: 5.82 | H19: Bluestone Memorial Hospital | I19: Oncology | J19: 90 | K19: 426 | L19: 155 | M19: 271 | N19: 5 | O19: 46018
A20: STK4019 | B20: SKU-10063 | C20: Procedure Mask, Ear Loop (Box/50) | D20: PPE | E20: CareLine Distributors | F20: Box | G20: 5.82 | H20: Ashby Falls Community Hospital | I20: Emergency Department | J20: 158 | K20: 430 | L20: 110 | M20: 320 | N20: 7 | O20: 46016
A21: STK4020 | B21: SKU-10063 | C21: Procedure Mask, Ear Loop (Box/50) | D21: PPE | E21: CareLine Distributors | F21: Box | G21: 5.82 | H21: Cedar Ridge Medical Center | I21: Medical-Surgical | J21: 441 | K21: 800 | L21: 310 | M21: 490 | N21: 3 | O21: 45999
A22: STK4021 | B22: SKU-10070 | C22: Face Shield, Full Length (Box/24) | D22: PPE | E22: Harbor Health Products | F22: Box | G22: 19.06 | H22: Bluestone Memorial Hospital | I22: Medical-Surgical 5 East | J22: 182 | K22: 142 | L22: 49 | M22: 93 | N22: 3 | O22: 45984
A23: STK4022 | B23: SKU-10070 | C23: Face Shield, Full Length (Box/24) | D23: PPE | E23: Harbor Health Products | F23: Box | G23: 19.06 | H23: Bluestone Memorial Hospital | I23: Labor & Delivery | J23: 337 | K23: 288 | L23: 110 | M23: 178 | N23: 5 | O23: 46004
A24: STK4023 | B24: SKU-10070 | C24: Face Shield, Full Length (Box/24) | D24: PPE | E24: Harbor Health Products | F24: Box | G24: 19.06 | H24: Bluestone Memorial Hospital | I24: Pediatrics | J24: 191 | K24: 322 | L24: 109 | M24: 213 | N24: 3 | O24: 45991
A25: STK4024 | B25: SKU-10077 | C25: Shoe Covers, Non-Skid (Case/300) | D25: PPE | E25: Keystone Lab Solutions | F25: Case | G25: 40.02 | H25: Bluestone Memorial Hospital | I25: Medical-Surgical 4 West | J25: 121 | K25: 115 | L25: 44 | M25: 71 | N25: 5 | O25: 45979
A26: STK4025 | B26: SKU-10077 | C26: Shoe Covers, Non-Skid (Case/300) | D26: PPE | E26: Keystone Lab Solutions | F26: Case | G26: 40.02 | H26: Bluestone Memorial Hospital | I26: Orthopedics & Spine | J26: 46 | K26: 93 | L26: 32 | M26: 61 | N26: 3 | O26: 46007
A27: STK4026 | B27: SKU-10077 | C27: Shoe Covers, Non-Skid (Case/300) | D27: PPE | E27: Keystone Lab Solutions | F27: Case | G27: 40.02 | H27: Bluestone Memorial Hospital | I27: Perioperative Services | J27: 213 | K27: 164 | L27: 42 | M27: 122 | N27: 5 | O27: 46009
A28: STK4027 | B28: SKU-10084 | C28: IV Catheter 14G x 1.16 in | D28: IV Supplies | E28: Pinnacle Biomedical | F28: Box | G28: 60.04 | H28: Bluestone Memorial Hospital | I28: Medical-Surgical 4 West | J28: 44 | K28: 64 | L28: 22 | M28: 42 | N28: 14 | O28: 45977 | P28: 46233 | Q28: L227031
A29: STK4028 | B29: SKU-10091 | C29: IV Catheter 16G x 1.16 in | D29: IV Supplies | E29: Pinnacle Biomedical | F29: Box | G29: 69.18 | H29: Bluestone Memorial Hospital | I29: Medical-Surgical 5 East | J29: 71 | K29: 108 | L29: 40 | M29: 68 | N29: 5 | O29: 46001 | P29: 46009 | Q29: L323955
A30: STK4029 | B30: SKU-10098 | C30: IV Catheter 18G x 1.16 in | D30: IV Supplies | E30: Pinnacle Biomedical | F30: Box | G30: 73.33 | H30: Bluestone Memorial Hospital | I30: Oncology | J30: 50 | K30: 76 | L30: 29 | M30: 47 | N30: 3 | O30: 45986 | P30: 46382 | Q30: L551785
A31: STK4030 | B31: SKU-10098 | C31: IV Catheter 18G x 1.16 in | D31: IV Supplies | E31: Pinnacle Biomedical | F31: Box | G31: 73.33 | H31: Bluestone Memorial Hospital | I31: Labor & Delivery | J31: 118 | K31: 132 | L31: 46 | M31: 86 | N31: 7 | O31: 45992 | P31: 46392 | Q31: L490763
A32: STK4031 | B32: SKU-10105 | C32: IV Catheter 20G x 1.16 in | D32: IV Supplies | E32: Pinnacle Biomedical | F32: Box | G32: 69.13 | H32: Ashby Falls Community Hospital | I32: Medical-Surgical | J32: 151 | K32: 148 | L32: 41 | M32: 107 | N32: 5 | O32: 46004 | P32: 46272 | Q32: L262859
A33: STK4032 | B33: SKU-10105 | C33: IV Catheter 20G x 1.16 in | D33: IV Supplies | E33: Pinnacle Biomedical | F33: Box | G33: 69.13 | H33: Bluestone Memorial Hospital | I33: Laboratory | J33: 104 | K33: 190 | L33: 74 | M33: 116 | N33: 5 | O33: 45995 | P33: 46258 | Q33: L416786
A34: STK4033 | B34: SKU-10112 | C34: IV Catheter 22G x 1.16 in | D34: IV Supplies | E34: Pinnacle Biomedical | F34: Box | G34: 68.17 | H34: Bluestone Memorial Hospital | I34: Oncology | J34: 7 | K34: 52 | L34: 19 | M34: 33 | N34: 7 | O34: 45994 | P34: 45957 | Q34: L236652
A35: STK4034 | B35: SKU-10112 | C35: IV Catheter 22G x 1.16 in | D35: IV Supplies | E35: Pinnacle Biomedical | F35: Box | G35: 68.17 | H35: Cedar Ridge Medical Center | I35: Medical-Surgical | J35: 15 | K35: 132 | L35: 35 | M35: 97 | N35: 5 | O35: 45991 | P35: 46468 | Q35: L564515
A36: STK4035 | B36: SKU-10119 | C36: IV Catheter 24G x 1.16 in | D36: IV Supplies | E36: Pinnacle Biomedical | F36: Box | G36: 63.47 | H36: Bluestone Memorial Hospital | I36: Orthopedics & Spine | J36: 93 | K36: 69 | L36: 19 | M36: 50 | N36: 2 | O36: 45995 | P36: 46415 | Q36: L705292
A37: STK4036 | B37: SKU-10119 | C37: IV Catheter 24G x 1.16 in | D37: IV Supplies | E37: Pinnacle Biomedical | F37: Box | G37: 63.47 | H37: Bluestone Memorial Hospital | I37: Pediatrics | J37: 33 | K37: 92 | L37: 28 | M37: 64 | N37: 3 | O37: 46015 | P37: 46464 | Q37: L791852
A38: STK4037 | B38: SKU-10119 | C38: IV Catheter 24G x 1.16 in | D38: IV Supplies | E38: Pinnacle Biomedical | F38: Box | G38: 63.47 | H38: Ashby Falls Community Hospital | I38: Emergency Department | J38: 102 | K38: 355 | L38: 94 | M38: 261 | N38: 5 | O38: 45998 | P38: 46869 | Q38: L343745
A39: STK4038 | B39: SKU-10126 | C39: Primary IV Tubing Set, 60 Drop | D39: IV Supplies | E39: Pinnacle Biomedical | F39: Case | G39: 104.04 | H39: Bluestone Memorial Hospital | I39: Pediatrics | J39: 50 | K39: 38 | L39: 12 | M39: 26 | N39: 3 | O39: 45993 | P39: 46986 | Q39: L290377
... A85: STK4084 | B85: SKU-10252 | C85: Silver Alginate Dressing 4x5 | D85: Wound Care | E85: Pinnacle Biomedical | F85: Each | G85: 13.32 | H85: Bluestone Memorial Hospital | I85: Pediatrics | J85: 99 | K85: 291 | L85: 92 | M85: 199 | N85: 3 | O85: 46005 | P85: 46854 | Q85: L691707
...

Sheet Settings
A1: Setting | B1: Value | C1: Notes
A2: ReportDate | B2: 46022 | C2: The 'as of' date of this inventory snapshot. Use it instead of TODAY() so answers never change.
A3: ExpiringWindowDays | B3: 90 | C3: Perishable stock expiring within this many days after ReportDate gets flagged for use-first.
A5: Task 9 names B2 and B3 after the labels in column A (Formulas → Create from Selection).
A6: Task 12 and the bonus add named constants (CycleCountDays, DiscountMin, DiscountPct) with Formulas → Define Name.
A7: Named constants live only in Name Manager, so you won't see them on this sheet.

Sheet Bonus
A1: Lesson 3.1 · Bonus: This week's reorder report
A2: Every Monday, Bluestone's purchasing team turns the inventory snapshot into purchase orders. Each stock row at or below its reorder point gets an order for its standard ReorderQty, and all the lines for one vendor go on a single purchase order. Build the report with Tables and names, so next week it updates itself when the new snapshot is pasted in. Finish practice tasks 1–12 first, because this uses tblInventory, NeedsReorder, and the names.
A3: Type a formula or value in each yellow cell. For B1, fill the OrderCost column on the Inventory sheet instead, and the gray cell here reads it. B2 also builds the tblVendors Table on the Vendors sheet. The Check column turns green when your answer matches. Stuck? Read the hint, then the lesson guide. Answers: right-click a sheet tab → Unhide… → 'Bonus Key'.
A4: ="Score: "&COUNTIF(E6:E9,"✔*")&" of 4 auto-checked tasks correct"
A5: # | B5: Task | C5: Hint | D5: Your Answer | E5: Check
A6: B1 | B6: Add a new column to tblInventory by typing OrderCost in cell T1, just right of the NeedsReorder header. The Table expands to include it. Make it a calculated column that returns ReorderQty × UnitCost for rows where NeedsReorder is TRUE, and 0 for every other row. The gray cell totals the column: what's the total cost of this week's orders? | C6: IF's test can be the TRUE/FALSE value in [@NeedsReorder] itself, with no comparison needed | D6: {=IF(COUNT(Inventory!$T$2:$T$258)=0,"",SUM(Inventory!$T$2:$T$258))} | E6: =IF(IFERROR(D6="",FALSE),"",IF(IFERROR(AND(ISNUMBER(D6),OR(ABS(D6-'Bonus Key'!$C$5)<=0.0051)),FALSE),"✔ Correct","✘ Not yet"))
A7: B2 | B7: On the Vendors sheet, convert the vendor list to a Table named tblVendors. Fill its yellow ReorderCost column with a calculated column that adds up tblInventory[OrderCost] for that row's vendor. Which vendor gets the largest purchase order? (Type the vendor's name, or return it with a formula.) | C7: In tblVendors, SUMIFS can add up another Table's column, with [@Vendor] as the criterion | E7: =IF(IFERROR(D7="",FALSE),"",IF(IFERROR(OR(LOWER(TRIM(D7&""))=LOWER(TRIM('Bonus Key'!$C$6&""))),FALSE),"✔ Correct","✘ Not yet"))
A8: B3 | B8: What's the value of that vendor's purchase order, to the cent? | C8: The largest value in tblVendors[ReorderCost] | E8: =IF(IFERROR(D8="",FALSE),"",IF(IFERROR(AND(ISNUMBER(D8),OR(ABS(D8-'Bonus Key'!$C$7)<=0.0051)),FALSE),"✔ Correct","✘ Not yet"))
A9: B4 | B9: The group purchasing contract gives a 2% discount on any single vendor order of $20,000 or more. Define two named constants, DiscountMin (=20000) and DiscountPct (=0.02), then calculate the total discount on this week's orders, to the cent. | C9: SUMIFS can use the same column as the sum range and the criteria range | E9: =IF(IFERROR(D9="",FALSE),"",IF(IFERROR(AND(ISNUMBER(D9),OR(ABS(D9-'Bonus Key'!$C$8)<=0.0051)),FALSE),"✔ Correct","✘ Not yet"))

Sheet Vendors
A1: Vendor | B1: AccountNo | C1: ReorderCost
A2: Apex Surgical Co. | B2: BHS-V1001
A3: CareLine Distributors | B3: BHS-V1002
A4: Harbor Health Products | B4: BHS-V1003
A5: Keystone Lab Solutions | B5: BHS-V1004
A6: Northstar Medical Supply | B6: BHS-V1005
A7: Pinnacle Biomedical | B7: BHS-V1006
A8: Summit Orthopedic Systems | B8: BHS-V1007
A10: Bonus: convert this list to a Table named tblVendors, then fill ReorderCost with a calculated column.

Sheet Answer Key
A1: 🔑 Answer Key — Lesson 3.1
A2: Spoiler alert: try every task before reading this sheet. Column C is the value the Check column compares against. Column D is a sample solution, and column E recalculates a formula for it live, proving the answer.
A4: # | B4: Task | C4: Answer | D4: Sample solution | E4: Live result | F4: Explanation
A5: 1 | B5: On the Inventory sheet, click any cell in the data and convert the range to an Excel Table with Ctrl + T (Mac: Control + T). Then rename the Table tblInventory in the Table Name box on the Table Design tab (Mac: Table tab). The gray cell finds a Table with that exact name and counts its data rows. It stays blank until the Table exists. | C5: 257 | D5: 1. Click any cell inside the data, for example A2. 2. Press Ctrl + T (Mac: Control + T), or choose Insert → Table. 3. Check that the range shows $A$1:$S$258 and that My table has headers is ticked, then click OK. 4. On the Table Design tab (Mac: Table tab), click in the Table Name box at the far left, type tblInventory, and press Enter. | E5: {=COUNTA(Inventory!$A$2:$A$258)} | F5: Ctrl + T selects the whole block of connected cells around the active cell, so you don't need to select the data first. Excel names new Tables Table1, Table2, and so on. Renaming the Table is what makes formulas readable: tblInventory[UnitCost] tells the next reader what the formula uses, while Table1[UnitCost] doesn't. The gray cell uses INDIRECT("tblInventory"), which looks the Table up by name and returns its data rows (headers and Total Row excluded).
A6: 2 | B6: How many stock rows are completely out of stock (QtyOnHand = 0)? Use a structured reference to the QtyOnHand column instead of a cell range. | C6: 9 | D6: =COUNTIF(tblInventory[QtyOnHand],0) | E6: {=COUNTIF(Inventory!$J$2:$J$258,0)} | F6: tblInventory[QtyOnHand] means "every data cell in the QtyOnHand column." It excludes the header and the Total Row, and it grows when rows are added. After you type tblInventory[, Excel lists the columns. Pick one with the arrow keys and press Tab. These rows are stockouts: a nurse who reaches for the item finds an empty bin.
A7: 3 | B7: Fill the yellow ExtendedValue column (column R) with a calculated column: each row's QtyOnHand × UnitCost. Type the formula once in R2 and press Enter, and the Table fills every row. The gray cell totals the column: what's the value of all stock on hand across the system? | C7: 1011928.9 | D7: =[@QtyOnHand]*[@UnitCost] | E7: {=SUMPRODUCT(Inventory!$J$2:$J$258,Inventory!$G$2:$G$258)} | F7: When you enter a formula in an empty Table column, Excel copies it to every row of that column. That's a calculated column. [@QtyOnHand] means "QtyOnHand in this row," so the formula reads the same on all 257 rows and says what it multiplies. The A1 version, =J2*G2, changes on every row and tells the next reader nothing about the columns it uses.
A8: 4 | B8: What share of the system's total inventory value (ExtendedValue) is Orthopedic Implants stock? Divide the category's value by the total of all rows and enter it as a percentage, to 1 decimal place. | C8: 0.14008124 | D8: =SUMIFS(tblInventory[ExtendedValue],tblInventory[Category],"Orthopedic Implants")/SUM(tblInventory[ExtendedValue]) | E8: {=SUMPRODUCT((Inventory!$D$2:$D$258="Orthopedic Implants")*Inventory!$J$2:$J$258*Inventory!$G$2:$G$258)/SUMPRODUCT(Inventory!$J$2:$J$258,Inventory!$G$2:$G$258)} | F8: Every argument in SUMIFS is a whole Table column, so the ranges are automatically the same size, which SUMIFS requires. Only 15 of the 257 rows are implants, yet they hold 14% of the value on the shelves. High-cost, low-volume items like these are the ones a supply chain team counts most carefully.
A9: 5 | B9: Fill the yellow NeedsReorder column (column S) with a calculated column that returns TRUE when QtyOnHand is at or below ReorderPoint, and FALSE otherwise. The gray cell counts the TRUE rows: how many stock rows need reordering? | C9: 41 | D9: =[@QtyOnHand]<=[@ReorderPoint] | E9: {=SUMPRODUCT(--(Inventory!$J$2:$J$258<=Inventory!$L$2:$L$258))} | F9: A comparison such as [@QtyOnHand]<=[@ReorderPoint] evaluates to TRUE or FALSE by itself (Lesson 2.1). Storing the result as a column turns a row-by-row test into something you can filter, count with COUNTIF(tblInventory[NeedsReorder],TRUE), and reuse in other formulas, as the bonus does. Use "at or below" (<=): an item sitting exactly at its reorder point is due.
A10: 6 | B10: Turn on the Table's Total Row and set the LeadTimeDays total to Average. Then, in the yellow cell, type = and click that Total Row cell, so Excel writes a [#Totals] reference. What's the average vendor lead time in days, to 2 decimal places? | C10: 5.3501946 | D10: =tblInventory[[#Totals],[LeadTimeDays]] | E10: {=AVERAGE(Inventory!$N$2:$N$258)} | F10: The Total Row's drop-down list writes =SUBTOTAL(101,[LeadTimeDays]). Function number 101 means AVERAGE of the visible rows only, ignoring rows hidden by a filter or hidden by hand (109 = SUM, 103 = COUNTA, 104 = MAX). tblInventory[[#Totals],[LeadTimeDays]] points at that total cell by name, so it still works if rows are added. If you turn the Total Row off, the reference returns #REF!.
A11: 7 | B11: With the Total Row still on, what does =ROWS(tblInventory[#All]) return? Predict it first, then type the formula to check. | C11: 259 | D11: =ROWS(tblInventory[#All]) | E11: — | F11: ROWS counts the rows a reference covers. [#All] covers the header row, the 257 data rows, and the Total Row: 1 + 257 + 1 = 259. tblInventory[#Data] (or just tblInventory) is the 257 data rows, [#Headers] is the header row alone, and [#Totals] is the Total Row alone.
A12: 8 | B12: Insert slicers for Facility and Category (Table Design → Insert Slicer; Mac: Table → Insert Slicer). Select Cedar Ridge Medical Center in the Facility slicer and Surgical in the Category slicer. Set the Total Row's ExtendedValue cell to Sum. What value does it show? Type the number, then clear both slicers, because while they filter the Table the Total Row (and task 6) only summarizes the visible rows. | C12: 47775.51 | D12: 1. Click inside the Table, then Table Design → Insert Slicer (Mac: Table → Insert Slicer). Tick Facility and Category and click OK. 2. In the Facility slicer click Cedar Ridge Medical Center. In the Category slicer click Surgical. The Table now shows 6 rows. 3. In the Total Row, click the ExtendedValue cell, open its drop-down list, and choose Sum. 4. Read the total and type it in the answer cell: 47,775.51. 5. Click the Clear Filter button (funnel with a red X) at the top right of each slicer. | E12: {=SUMPRODUCT((Inventory!$H$2:$H$258="Cedar Ridge Medical Center")*(Inventory!$D$2:$D$258="Surgical")*Inventory!$J$2:$J$258*Inventory!$G$2:$G$258)} | F12: Slicers are buttons that apply the Table's AutoFilter for you. Choices in different slicers combine with AND, so only rows that match both stay visible. The Total Row uses SUBTOTAL(109,…), which adds only the visible rows. That's why it changes as you click. You can check the number without slicers using =SUMIFS(tblInventory[ExtendedValue],tblInventory[Facility],"Cedar Ridge Medical Center",tblInventory[Category],"Surgical").
A13: 9 | B13: On the Settings sheet, select A2:B3 and use Formulas → Create from Selection (tick only Left column) to name cell B2 ReportDate and cell B3 ExpiringWindowDays. The gray cell looks up both names and adds them: what date does it show? | C13: 46112 | D13: 1. Go to the Settings sheet and select A2:B3 (labels and values together). 2. Choose Formulas → Create from Selection (Windows shortcut: Ctrl + Shift + F3). 3. Tick Left column only, untick Top row, and click OK. 4. Check the result: click B2 and the Name Box shows ReportDate. Open Formulas → Name Manager to see both names and what they refer to. | E13: {=Settings!$B$2+Settings!$B$3} | F13: Create from Selection turns each label in the left column into a name for the cell to its right: ReportDate → =Settings!$B$2 and ExpiringWindowDays → =Settings!$B$3. Names are absolute references, so they never shift when you copy a formula. 12/31/2025 + 90 days = 03/31/2026, because dates are day counts (Lesson 2.3). If the gray cell stays blank, check the spelling of each name in Name Manager.
A14: 10 | B14: How many stock rows expire inside the expiry window? Count rows whose ExpirationDate is later than ReportDate and no later than ReportDate + ExpiringWindowDays. Use the two names in a COUNTIFS (rows with no ExpirationDate don't count). | C14: 7 | D14: =COUNTIFS(tblInventory[ExpirationDate],">"&ReportDate,tblInventory[ExpirationDate],"<="&ReportDate+ExpiringWindowDays) | E14: {=COUNTIFS(Inventory!$P$2:$P$258,">"&Settings!$B$2,Inventory!$P$2:$P$258,"<="&Settings!$B$2+Settings!$B$3)} | F14: Criteria are text, so join the operator to the name with &, exactly as you would with a cell reference (Lesson 2.5). Blank ExpirationDate cells never match a date criterion, so non-perishables drop out automatically. The formula reads like the policy, and when the next snapshot arrives you only change the date in Settings!B2.
A15: 11 | B15: Expired stock must be pulled from the shelves and written off. What's the total ExtendedValue of rows whose ExpirationDate is before ReportDate? Enter it to the cent. | C15: 17115.69 | D15: =SUMIFS(tblInventory[ExtendedValue],tblInventory[ExpirationDate],"<"&ReportDate) | E15: {=SUMPRODUCT((Inventory!$P$2:$P$258<Settings!$B$2)*(Inventory!$P$2:$P$258<>"")*Inventory!$J$2:$J$258*Inventory!$G$2:$G$258)} | F15: In this snapshot, 10 rows are past their expiration date. That's a patient-safety issue as well as a cost: surveyors such as The Joint Commission look for expired supplies in clinical areas. The live formula in the key guards against blanks with <>"", but SUMIFS doesn't need that guard, because an empty cell never matches "<"&ReportDate.
A16: 12 | B16: Policy says every stock row must be cycle-counted at least every 30 days. Create a named constant CycleCountDays that refers to =30 with Formulas → Define Name. It doesn't live in any cell. How many rows are overdue, meaning ReportDate − LastCountDate is greater than CycleCountDays? | C16: 78 | D16: =COUNTIF(tblInventory[LastCountDate],"<"&ReportDate-CycleCountDays) | E16: {=COUNTIF(Inventory!$O$2:$O$258,"<"&Settings!$B$2-30)} | F16: In the New Name dialog, type CycleCountDays as the Name and =30 in Refers to. ReportDate − CycleCountDays is 12/01/2025, so any row last counted before that date is more than 30 days old. A named constant suits a policy value that shouldn't be typed over by accident. A named cell, like ReportDate, suits an input that people change often.

Sheet Bonus Key
A1: 🔑 Bonus Key — Lesson 3.1
A2: Spoiler alert: try every task before reading this sheet. Column C is the value the Check column compares against. Column D is a sample solution, and column E recalculates a formula for it live, proving the answer.
A4: # | B4: Task | C4: Answer | D4: Sample solution | E4: Live result | F4: Explanation
A5: B1 | B5: Add a new column to tblInventory by typing OrderCost in cell T1, just right of the NeedsReorder header. The Table expands to include it. Make it a calculated column that returns ReorderQty × UnitCost for rows where NeedsReorder is TRUE, and 0 for every other row. The gray cell totals the column: what's the total cost of this week's orders? | C5: 173950.91 | D5: =IF([@NeedsReorder],[@ReorderQty]*[@UnitCost],0) | E5: {=SUMPRODUCT((Inventory!$J$2:$J$258<=Inventory!$L$2:$L$258)*Inventory!$M$2:$M$258*Inventory!$G$2:$G$258)} | F5: Typing in the first empty column next to a Table adds a column to it (Excel's AutoExpansion). IF([@NeedsReorder],…) reuses the calculated column you built in task 5 instead of repeating the comparison. The 41 rows that need an order return their cost and the rest return 0, so the column total is the cost of the whole report.
A6: B2 | B6: On the Vendors sheet, convert the vendor list to a Table named tblVendors. Fill its yellow ReorderCost column with a calculated column that adds up tblInventory[OrderCost] for that row's vendor. Which vendor gets the largest purchase order? (Type the vendor's name, or return it with a formula.) | C6: Summit Orthopedic Systems | D6: =INDEX(tblVendors[Vendor],MATCH(MAX(tblVendors[ReorderCost]),tblVendors[ReorderCost],0)) | E6: — | F6: The calculated column in tblVendors is =SUMIFS(tblInventory[OrderCost],tblInventory[Vendor],[@Vendor]). It mixes whole columns from another Table with [@Vendor] from this row, which is how Tables talk to each other. INDEX/MATCH (Lesson 2.6) then returns the vendor on the row with the largest total. =XLOOKUP(MAX(tblVendors[ReorderCost]),tblVendors[ReorderCost],tblVendors[Vendor]) also works in Microsoft 365 and Excel 2021 or later. All four reorder lines for Summit Orthopedic Systems are orthopedic implants, and three of them cost more than $2,000 per unit, so a handful of lines makes the largest order.
A7: B3 | B7: What's the value of that vendor's purchase order, to the cent? | C7: 62855.33 | D7: =MAX(tblVendors[ReorderCost]) | E7: {=SUMPRODUCT((Inventory!$E$2:$E$258="Summit Orthopedic Systems")*(Inventory!$J$2:$J$258<=Inventory!$L$2:$L$258)*Inventory!$M$2:$M$258*Inventory!$G$2:$G$258)} | F7: MAX scans the ReorderCost column of tblVendors, so it returns the largest vendor total, the same row that INDEX/MATCH found in B2. That's 36% of the week's spend on a single purchase order. In practice, a buyer would confirm implant orders with the OR schedule before sending them.
A8: B4 | B8: The group purchasing contract gives a 2% discount on any single vendor order of $20,000 or more. Define two named constants, DiscountMin (=20000) and DiscountPct (=0.02), then calculate the total discount on this week's orders, to the cent. | C8: 2431.66 | D8: =SUMIFS(tblVendors[ReorderCost],tblVendors[ReorderCost],">="&DiscountMin)*DiscountPct | E8: — | F8: The criteria range and the sum range are the same column, so SUMIFS adds only the vendor totals that pass the test against DiscountMin. Orders from 3 vendors reach $20,000. Together they total $121,583.18, and 2% of that is the discount. With the thresholds in named constants, Purchasing can test a new contract (say 3% at $15,000) by editing two names in Name Manager, and every formula that uses them updates.
