Workbook

Sheet Start Here
B2: Lesson 5.3
B3: VBA: Ranges, Worksheets & Workbooks
B4: Expert · about 65 minutes · Bluestone Health System (fictional)
B6: What you'll learn
B7: • | C7: Navigate the object model: Application, Workbooks, Worksheets, Range
B8: • | C8: Find the last row and work with CurrentRegion, Offset, and Resize
B9: • | C9: Loop through sheets; add, copy, rename, and delete them
B10: • | C10: Process data fast with arrays, AutoFilter, and Sort — without Select
B12: How to use this workbook
B13: 1. Read the guide | C13: The lesson guide (README) explains each skill with examples: https://github.com/lmansf/learn-excel/tree/main/05-automation-vba/03-vba-ranges-worksheets
B14: 2. Practice | C14: Go to the 'Practice' sheet. Type your predictions for tasks 1–6 in the yellow cells. For tasks 7–12, complete and run your macros, and the gray cells fill in by themselves.
B15: 3. Check yourself | C15: The Check column shows ✔ Correct (green) or ✘ Not yet (red). Every task is checked automatically.
B16: 4. Bonus | C16: Finished? Try the harder 'Bonus' sheet.
B17: 5. Answers | C17: The 'Answer Key' and 'Bonus Key' sheets are hidden. Right-click any sheet tab → Unhide… → pick one → OK. (Try first!)
B18: Note | C18: Macros can't be saved in an .xlsx file. Before you write any code, choose File → Save As and pick 'Excel Macro-Enabled Workbook (*.xlsm)'.
B19: Note | C19: Import starter/EncounterMacros.bas and starter/Snippets.bas from the lesson folder: open the Visual Basic Editor with Alt + F11 (Mac: Developer → Visual Basic), then choose File → Import File…
B20: Note | C20: Snippets shows the code for tasks 1–6. Your macros add sheets (TypeSummary, F01–F04, 2025-01…) and write to the Output sheet. The gray cells on Practice and Bonus read those, so they stay blank until the macro has run.
B22: Color legend
B23: Yellow cell | C23: Your answer goes here.
B24: Gray cell | C24: Pre-filled summary formula — it reads the work you did on another sheet.
B25: ✔ Correct | C25: Your answer matches the key.
B26: ✘ Not yet | C26: Not matching yet — check the hint and try again.
B28: Sheets in this workbook
B29: Practice | C29: Tasks 1–12. Yellow cells take your predictions (tasks 1–6), and gray cells read what your macros create (tasks 7–12).
B30: Snippets | C30: The code for tasks 1–6. The same code is in starter/Snippets.bas.
B31: Encounters | C31: Data: 2,000 rows in columns A:K, a plain range like a raw EHR export. Task 12 fills the yellow LOSDays column (L).
B32: Facilities | C32: Data: 4 rows, an Excel Table named tblFacilities.
B33: Output | C33: The blue cells your macros write results to. The Practice and Bonus sheets read them.
B34: Bonus | C34: The bonus challenge: one inpatient packet per month.
B35: PacketTemplate | C35: The template the bonus macro copies once per month. Leave it as it is.
B36: About the data | C36: 2,000 encounters admitted in 2025 at all four Bluestone facilities (inpatient, observation, emergency, and outpatient), exported from the EHR as a plain range, plus the facility list as an Excel Table.
B37: Disclaimer | C37: All people, places, and numbers are synthetic and fictional. Not clinical guidance.

Sheet Practice
A1: Lesson 5.3 · Practice
A2: Save the workbook as .xlsm, then import starter/EncounterMacros.bas and starter/Snippets.bas (VBE → File → Import File…). Tasks 1–6 ask what the code on the Snippets sheet prints: type your prediction, then run the snippet to check it. In tasks 7–12 you complete macros, and the gray cells read the sheets and cells your macros create.
A3: Type your predictions for tasks 1–6 in the yellow cells. The gray cells for tasks 7–12 fill in when your macros run. The Check column turns green when your answer matches. Stuck? Read the hint, then the lesson guide. Answers: right-click a sheet tab → Unhide… → 'Answer Key'.
A4: ="Score: "&COUNTIF(E6:E17,"✔*")&" of 12 auto-checked tasks correct"
A5: # | B5: Task | C5: Hint | D5: Your Answer | E5: Check
A6: 1 | B6: Snippet A: what address does the Immediate window show? Type it as printed (the $ signs are optional). | C6: Offset moves the top-left corner, and Resize sets the size from that corner | E6: =IF(IFERROR(D6="",FALSE),"",IF(IFERROR(OR(LOWER(TRIM(D6&""))=LOWER(TRIM('Answer Key'!$C$5&"")),LOWER(TRIM(D6&""))="g5:g9"),FALSE),"✔ Correct","✘ Not yet"))
A7: 2 | B7: Snippet B: what address does the Immediate window show? | C7: CurrentRegion is the whole block around E50 (Go To Special → Current region shows it). The last two steps drop the header row | E7: =IF(IFERROR(D7="",FALSE),"",IF(IFERROR(OR(LOWER(TRIM(D7&""))=LOWER(TRIM('Answer Key'!$C$6&"")),LOWER(TRIM(D7&""))="$a$2:$l$2001"),FALSE),"✔ Correct","✘ Not yet"))
A8: 3 | B8: Snippet C: line 1 prints 2001, the last row of column A. What number does line 2 print (the same idiom on column F, AdmitSource)? | C8: Which encounter types leave AdmitSource blank? Look at the bottom of column F | E8: =IF(IFERROR(D8="",FALSE),"",IF(IFERROR(AND(ISNUMBER(D8),OR(ABS(D8-'Answer Key'!$C$7)<=0.0001)),FALSE),"✔ Correct","✘ Not yet"))
A9: 4 | B9: Snippet C: what number does line 3 print? | C9: End(xlDown) works like Ctrl + ↓: it stops at the last filled cell before a gap | E9: =IF(IFERROR(D9="",FALSE),"",IF(IFERROR(AND(ISNUMBER(D9),OR(ABS(D9-'Answer Key'!$C$8)<=0.0001)),FALSE),"✔ Correct","✘ Not yet"))
A10: 5 | B10: Snippet D: running SnippetD_WhichSheet stops with a run-time error. Type the error number. | C10: Which sheet does a Cells(…) with nothing in front of it belong to? | E10: =IF(IFERROR(D10="",FALSE),"",IF(IFERROR(OR(LOWER(TRIM(D10&""))=LOWER(TRIM('Answer Key'!$C$9&"")),LOWER(TRIM(D10&""))="error 1004",LOWER(TRIM(D10&""))="run-time error 1004",LOWER(TRIM(D10&""))="runtime error 1004"),FALSE),"✔ Correct","✘ Not yet"))
A11: 6 | B11: Snippet E: running SnippetE_DeleteOld stops with a run-time error. Type the error number. | C11: What does a collection do when you ask for an item it doesn't have? | E11: =IF(IFERROR(D11="",FALSE),"",IF(IFERROR(OR(LOWER(TRIM(D11&""))=LOWER(TRIM('Answer Key'!$C$10&"")),LOWER(TRIM(D11&""))="subscript out of range",LOWER(TRIM(D11&""))="error 9",LOWER(TRIM(D11&""))="run-time error 9",LOWER(TRIM(D11&""))="runtime error 9"),FALSE),"✔ Correct","✘ Not yet"))
A12: 7 | B12: Complete SheetExists and BuildTypeSummary in the starter module. BuildTypeSummary deletes any old TypeSummary sheet (with DeleteSheetIfExists, which calls your SheetExists), adds a new sheet named TypeSummary at the end of the workbook, and writes one row per EncounterType (Emergency, Inpatient, Observation, Outpatient) with the columns EncounterType (A), Encounters (B, the count), and TotalCharges (C), headers in row 1. Run it twice: the second run must not stop with an error or ask a question. The gray cell looks up the Inpatient TotalCharges on your sheet. | C12: SheetExists: For Each ws In ThisWorkbook.Worksheets … StrComp(ws.Name, sheetName, vbTextCompare) = 0 | D12: {=IF(ISREF(INDIRECT("'TypeSummary'!A1")),IFERROR(INDEX(INDIRECT("'TypeSummary'!C1:C50"),MATCH("Inpatient",INDIRECT("'TypeSummary'!A1:A50"),0)),"Inpatient row not found"),"")} | E12: =IF(IFERROR(D12="",FALSE),"",IF(IFERROR(AND(ISNUMBER(D12),OR(ABS(D12-'Answer Key'!$C$11)<=0.0051)),FALSE),"✔ Correct","✘ Not yet"))
A13: 8 | B13: Complete SplitByFacility: for each FacilityID in the Facilities table (tblFacilities), delete any old sheet with that name, add a new sheet named after the ID (F01, F02, F03, F04), AutoFilter the Encounters block on FacilityID, and copy the visible cells (header included) to A1 of the new sheet. Turn the filter off at the end. The gray cell lists the number of data rows on F01, F02, F03, and F04. | C13: block.AutoFilter Field:=4, Criteria1:=facID, then block.SpecialCells(xlCellTypeVisible).Copy | D13: {=IF(OR(ISREF(INDIRECT("'F01'!A1")),ISREF(INDIRECT("'F02'!A1")),ISREF(INDIRECT("'F03'!A1")),ISREF(INDIRECT("'F04'!A1"))),IF(ISREF(INDIRECT("'F01'!A1")),COUNTA(INDIRECT("'F01'!A:A"))-1,"missing")&" / "&IF(ISREF(INDIRECT("'F02'!A1")),COUNTA(INDIRECT("'F02'!A:A"))-1,"missing")&" / "&IF(ISREF(INDIRECT("'F03'!A1")),COUNTA(INDIRECT("'F03'!A:A"))-1,"missing")&" / "&IF(ISREF(INDIRECT("'F04'!A1")),COUNTA(INDIRECT("'F04'!A:A"))-1,"missing"),"")} | E13: =IF(IFERROR(D13="",FALSE),"",IF(IFERROR(OR(LOWER(TRIM(D13&""))=LOWER(TRIM('Answer Key'!$C$12&""))),FALSE),"✔ Correct","✘ Not yet"))
A14: 9 | B14: Complete SortAndReconcile, part 1: loop through every worksheet and, for each sheet whose name is Like "F0#", sort its block by TotalCharges (column K), largest first, with Range.Sort and a header row. Which EncounterID is now in A2 of sheet F03? (The gray cell reads F03!A2.) | C14: Test ws.Name Like "F0#" inside the loop, then sort ws.Range("A1").CurrentRegion with Key1 in column K and Order1:=xlDescending (guide section 12) | D14: {=IF(ISREF(INDIRECT("'F03'!A1")),INDIRECT("'F03'!A2")&"","")} | E14: =IF(IFERROR(D14="",FALSE),"",IF(IFERROR(OR(LOWER(TRIM(D14&""))=LOWER(TRIM('Answer Key'!$C$13&""))),FALSE),"✔ Correct","✘ Not yet"))
A15: 10 | B15: SortAndReconcile, part 2: in the same loop, add each facility sheet's data rows and TotalCharges to two running totals, then write the row total to Output!B4 and the charge total to Output!B5. What is the total charge on the facility sheets? (The gray cell reads Output!B5.) | C15: Find each sheet's last row with LastRow(ws, "A"), then WorksheetFunction.Sum the K cells | D15: {=IF(Output!B5="","",Output!B5)} | E15: =IF(IFERROR(D15="",FALSE),"",IF(IFERROR(AND(ISNUMBER(D15),OR(ABS(D15-'Answer Key'!$C$14)<=0.0051)),FALSE),"✔ Correct","✘ Not yet"))
A16: 11 | B16: Complete ExportFacility: copy sheet F02 into a new workbook (Worksheet.Copy with no arguments), save it in the same folder as this workbook as F02_encounters_2025.xlsx with SaveAs and FileFormat:=xlOpenXMLWorkbook, and close it. Then reopen the file with Workbooks.Open, add up its TotalCharges column, write the total to Output!B7 (and the file name to Output!B6), and close it without saving. The gray cell reads Output!B7. | C16: After Worksheet.Copy the new workbook is the ActiveWorkbook, so write results through ThisWorkbook | D16: {=IF(Output!B7="","",Output!B7)} | E16: =IF(IFERROR(D16="",FALSE),"",IF(IFERROR(AND(ISNUMBER(D16),OR(ABS(D16-'Answer Key'!$C$15)<=0.0051)),FALSE),"✔ Correct","✘ Not yet"))
A17: 12 | B17: Complete FillLOSDays: read AdmitDateTime and DischargeDateTime (Encounters G2:H2001) into a Variant array with one .Value2 read, calculate each row's length of stay in days with Int(discharge) - Int(admit) (the number of midnights, ignoring the times), and write all the results to the yellow LOSDays column (L) with one assignment. The gray cell adds up your column. | C17: stay = ws.Range("G2:H" & lastR).Value2, then ReDim los(1 To UBound(stay, 1), 1 To 1) | D17: {=IF(COUNT(Encounters!L2:L2001)=0,"",SUM(Encounters!L2:L2001))} | E17: =IF(IFERROR(D17="",FALSE),"",IF(IFERROR(AND(ISNUMBER(D17),OR(ABS(D17-'Answer Key'!$C$16)<=0.0001)),FALSE),"✔ Correct","✘ Not yet"))

Sheet Snippets
A1: Snippets for Practice tasks 1–6
A2: Predict what each snippet prints (or which error stops it), type your prediction on the Practice sheet, then run it from the Snippets module (starter/Snippets.bas) to check. Debug.Print writes to the Immediate window, which Ctrl + G opens (Mac: View → Immediate Window).
A4: Snippet A · Practice task 1
A5: Sub SnippetA_OffsetResize()
A6: Dim ws As Worksheet
A7: Set ws = ThisWorkbook.Worksheets("Encounters")
A8: Debug.Print ws.Range("C2").Offset(3, 4).Resize(5).Address
A9: End Sub
A11: Snippet B · Practice task 2
A12: Sub SnippetB_DataBody()
A13: Dim ws As Worksheet, block As Range
A14: Set ws = ThisWorkbook.Worksheets("Encounters")
... A43: End Sub

Sheet Encounters
A1: EncounterID | B1: PatientID | C1: EncounterType | D1: FacilityID | E1: DeptID | F1: AdmitSource | G1: AdmitDateTime | H1: DischargeDateTime | I1: PrimaryDxCode | J1: PayerID | K1: TotalCharges | L1: LOSDays
A2: ENC110713 | B2: PT13324 | C2: Inpatient | D2: F01 | E2: D110 | F2: Emergency Department | G2: 45658.092 | H2: 45661.531 | I2: J44.1 | J2: PY05 | K2: 10673.63
A3: ENC110718 | B3: PT11455 | C3: Emergency | D3: F01 | E3: D100 | G3: 45658.372 | H3: 45658.529 | I3: J44.1 | J3: PY02 | K3: 2579.55
A4: ENC110725 | B4: PT12903 | C4: Outpatient | D4: F04 | E4: D450 | G4: 45658.552 | H4: 45658.59 | I4: H66.90 | J4: PY03 | K4: 482.23
A5: ENC110731 | B5: PT13303 | C5: Outpatient | D5: F04 | E5: D420 | G5: 45658.604 | H5: 45658.635 | I5: M17.11 | J5: PY01 | K5: 471.04
A6: ENC110738 | B6: PT12632 | C6: Outpatient | D6: F04 | E6: D450 | G6: 45658.667 | H6: 45658.678 | I6: H66.90 | J6: PY05 | K6: 292.94
A7: ENC110726 | B7: PT11101 | C7: Inpatient | D7: F03 | E7: D320 | F7: Emergency Department | G7: 45658.709 | H7: 45664.475 | I7: I50.9 | J7: PY01 | K7: 37731.01
A8: ENC110744 | B8: PT10444 | C8: Inpatient | D8: F01 | E8: D111 | F8: Emergency Department | G8: 45658.881 | H8: 45660.531 | I8: K35.80 | J8: PY01 | K8: 48442.42
A9: ENC110752 | B9: PT11758 | C9: Outpatient | D9: F04 | E9: D400 | G9: 45659.375 | H9: 45659.393 | I9: J06.9 | J9: PY07 | K9: 387.65
A10: ENC110758 | B10: PT10475 | C10: Outpatient | D10: F04 | E10: D400 | G10: 45659.448 | H10: 45659.48 | I10: F41.9 | J10: PY06 | K10: 460.88
A11: ENC110765 | B11: PT12533 | C11: Outpatient | D11: F04 | E11: D400 | G11: 45659.49 | H11: 45659.503 | I11: I10 | J11: PY03 | K11: 812.85
A12: ENC110770 | B12: PT13387 | C12: Outpatient | D12: F04 | E12: D400 | G12: 45659.542 | H12: 45659.578 | I12: I10 | J12: PY03 | K12: 273.1
A13: ENC110774 | B13: PT11628 | C13: Outpatient | D13: F04 | E13: D440 | G13: 45659.573 | H13: 45659.599 | I13: E11.65 | J13: PY02 | K13: 153.45
A14: ENC110779 | B14: PT12704 | C14: Inpatient | D14: F01 | E14: D190 | F14: Direct Admit | G14: 45659.618 | H14: 45669.483 | I14: F20.9 | J14: PY06 | K14: 34645.11
A15: ENC110786 | B15: PT10725 | C15: Outpatient | D15: F04 | E15: D450 | G15: 45659.677 | H15: 45659.706 | I15: Z23 | J15: PY03 | K15: 105.41
A16: ENC110792 | B16: PT13870 | C16: Emergency | D16: F01 | E16: D100 | G16: 45659.825 | H16: 45659.992 | I16: J06.9 | J16: PY07 | K16: 4749.54
A17: ENC110797 | B17: PT13061 | C17: Emergency | D17: F01 | E17: D100 | G17: 45660.294 | H17: 45660.394 | I17: J06.9 | J17: PY03 | K17: 1031.47
A18: ENC110803 | B18: PT12309 | C18: Emergency | D18: F01 | E18: D100 | G18: 45660.359 | H18: 45660.439 | I18: S93.401A | J18: PY03 | K18: 656.08
A19: ENC110808 | B19: PT10915 | C19: Emergency | D19: F01 | E19: D100 | G19: 45660.435 | H19: 45660.526 | I19: S06.0X0A | J19: PY06 | K19: 1062.78
A20: ENC110814 | B20: PT11837 | C20: Outpatient | D20: F04 | E20: D430 | G20: 45660.5 | H20: 45660.528 | I20: C50.911 | J20: PY06 | K20: 591.64
A21: ENC110819 | B21: PT12866 | C21: Outpatient | D21: F04 | E21: D440 | G21: 45660.552 | H21: 45660.568 | I21: E11.9 | J21: PY03 | K21: 542.28
A22: ENC110826 | B22: PT13773 | C22: Outpatient | D22: F04 | E22: D400 | G22: 45660.625 | H22: 45660.648 | I22: J06.9 | J22: PY07 | K22: 594.07
A23: ENC110828 | B23: PT11762 | C23: Inpatient | D23: F01 | E23: D180 | F23: Emergency Department | G23: 45660.751 | H23: 45662.633 | I23: J21.9 | J23: PY03 | K23: 11411.42
A24: ENC110836 | B24: PT10362 | C24: Emergency | D24: F01 | E24: D100 | G24: 45660.911 | H24: 45660.976 | I24: M54.50 | J24: PY03 | K24: 1152
A25: ENC110841 | B25: PT13985 | C25: Emergency | D25: F01 | E25: D100 | G25: 45661.383 | H25: 45661.524 | I25: J44.1 | J25: PY01 | K25: 3420.72
A26: ENC110844 | B26: PT11866 | C26: Inpatient | D26: F01 | E26: D160 | F26: Emergency Department | G26: 45661.659 | H26: 45668.492 | I26: I63.9 | J26: PY06 | K26: 40611.34
A27: ENC110853 | B27: PT12533 | C27: Observation | D27: F01 | E27: D195 | F27: Emergency Department | G27: 45662.028 | H27: 45663.397 | I27: K92.2 | J27: PY03 | K27: 6111.47
A28: ENC110857 | B28: PT13653 | C28: Emergency | D28: F01 | E28: D100 | G28: 45662.426 | H28: 45662.553 | I28: F10.239 | J28: PY04 | K28: 1599.37
A29: ENC110864 | B29: PT11155 | C29: Emergency | D29: F01 | E29: D100 | G29: 45662.557 | H29: 45662.713 | I29: N39.0 | J29: PY05 | K29: 3744.39
A30: ENC110866 | B30: PT13715 | C30: Inpatient | D30: F03 | E30: D310 | F30: Emergency Department | G30: 45662.719 | H30: 45669.528 | I30: U07.1 | J30: PY02 | K30: 32912.35
A31: ENC110875 | B31: PT10538 | C31: Emergency | D31: F01 | E31: D100 | G31: 45662.983 | H31: 45663.111 | I31: J45.909 | J31: PY05 | K31: 1629.66
A32: ENC110881 | B32: PT13429 | C32: Emergency | D32: F02 | E32: D200 | G32: 45663.295 | H32: 45663.397 | I32: S06.0X0A | J32: PY04 | K32: 2378.15
A33: ENC110887 | B33: PT13959 | C33: Outpatient | D33: F04 | E33: D400 | G33: 45663.406 | H33: 45663.425 | I33: E78.5 | J33: PY02 | K33: 405.38
A34: ENC110895 | B34: PT13608 | C34: Outpatient | D34: F04 | E34: D400 | G34: 45663.49 | H34: 45663.526 | I34: G43.909 | J34: PY06 | K34: 308.42
A35: ENC110897 | B35: PT13594 | C35: Outpatient | D35: F04 | E35: D400 | G35: 45663.562 | H35: 45663.593 | I35: F32.9 | J35: PY03 | K35: 311.69
A36: ENC110903 | B36: PT12611 | C36: Outpatient | D36: F04 | E36: D400 | G36: 45663.615 | H36: 45663.631 | I36: J45.909 | J36: PY01 | K36: 468.8
A37: ENC110910 | B37: PT12915 | C37: Outpatient | D37: F04 | E37: D420 | G37: 45663.656 | H37: 45663.685 | I37: M17.11 | J37: PY04 | K37: 446.43
A38: ENC110915 | B38: PT13404 | C38: Emergency | D38: F01 | E38: D100 | G38: 45663.685 | H38: 45663.782 | I38: H66.90 | J38: PY03 | K38: 1489.5
A39: ENC110923 | B39: PT10225 | C39: Emergency | D39: F01 | E39: D100 | G39: 45663.814 | H39: 45663.903 | I39: J06.9 | J39: PY03 | K39: 724.63
A40: ENC110920 | B40: PT12633 | C40: Inpatient | D40: F01 | E40: D170 | F40: Emergency Department | G40: 45663.875 | H40: 45665.671 | I40: O80 | J40: PY05 | K40: 17934.54
...

Sheet Facilities
A1: FacilityID | B1: FacilityName | C1: City | D1: FacilityType
A2: F01 | B2: Bluestone Memorial Hospital | C2: Bluestone | D2: Tertiary Acute Care
A3: F02 | B3: Ashby Falls Community Hospital | C3: Ashby Falls | D3: Community Hospital
A4: F03 | B4: Cedar Ridge Medical Center | C4: Cedar Ridge | D4: Acute Care
A5: F04 | B5: Bluestone Outpatient Pavilion | C5: Bluestone | D5: Ambulatory Care Center

Sheet Output
A1: Output: your macros write their results here
A2: Macros write into the blue cells. The Practice and Bonus sheets read them, so keep them where they are and don't type in them by hand.
A3: Result | B3: Value | C3: Written by (task)
A4: Data rows on the facility sheets | C4: SortAndReconcile (10)
A5: TotalCharges on the facility sheets | C5: SortAndReconcile (10)
A6: Exported file name | C6: ExportFacility (11)
A7: TotalCharges read back from the exported file | C7: ExportFacility (11)
A9: Bonus: packet with the largest total charges | C9: BuildMonthlyPackets (bonus)

Sheet Bonus
A1: Lesson 5.3 · Bonus: the monthly inpatient packet
A2: Finance wants a monthly packet of inpatient encounters, one sheet per month of 2025, each built from the PacketTemplate sheet. Complete BuildMonthlyPackets so that, for each month 1 to 12, it does four things: 1. Deletes any old sheet named for the month in yyyy-mm form (for example 2025-03), copies PacketTemplate to the end of the workbook, and renames the copy to that name. 2. Writes that month's Inpatient encounters (AdmitDateTime in the month) to the packet: all 11 columns A:K, in the same order as Encounters. The template's headers are in row 6, so data starts in A7. Use arrays: read the Encounters data once, before the month loop, collect each month's rows in a second array, and write them with one assignment. 3. Sorts the packet's rows by TotalCharges, largest first. 4. Fills the header block: B2 the first day of the month, B3 the number of encounters, and B4 their total charges. After the loop, write the name of the packet sheet with the largest total charges to Output!B9 (it's formatted as Text, so Excel keeps 2025-xx as text and doesn't turn it into a date). Turn ScreenUpdating off while the macro runs, and make sure it comes back on even if something fails.
A3: There's nothing to type on this sheet: the gray cells fill in when BuildMonthlyPackets has run. The Check column turns green when your answer matches. Stuck? Read the hint, then the lesson guide. Answers: right-click a sheet tab → Unhide… → 'Bonus Key'.
A4: ="Score: "&COUNTIF(E6:E9,"✔*")&" of 4 auto-checked tasks correct"
A5: # | B5: Task | C5: Hint | D5: Your Answer | E5: Check
A6: B1 | B6: How many inpatient encounters are in the 2025-03 packet? (The gray cell counts the data rows from row 7 down.) | C6: Test src(i, 3) = "Inpatient" And src(i, 7) >= monthStart And src(i, 7) < nextMonth | D6: {=IF(ISREF(INDIRECT("'2025-03'!A1")),COUNTA(INDIRECT("'2025-03'!A7:A2000")),"")} | E6: =IF(IFERROR(D6="",FALSE),"",IF(IFERROR(AND(ISNUMBER(D6),OR(ABS(D6-'Bonus Key'!$C$5)<=0.0001)),FALSE),"✔ Correct","✘ Not yet"))
A7: B2 | B7: What total charges does the 2025-07 packet show in its header (cell B4)? | C7: Reset total = 0 at the start of every month | D7: {=IF(ISREF(INDIRECT("'2025-07'!A1")),INDIRECT("'2025-07'!B4"),"")} | E7: =IF(IFERROR(D7="",FALSE),"",IF(IFERROR(AND(ISNUMBER(D7),OR(ABS(D7-'Bonus Key'!$C$6)<=0.0051)),FALSE),"✔ Correct","✘ Not yet"))
A8: B3 | B8: What is the top charge in the 2025-11 packet (TotalCharges in K7, after sorting)? | C8: Row 5 of the template is empty, so CurrentRegion from A6 is just the table | D8: {=IF(ISREF(INDIRECT("'2025-11'!A1")),INDIRECT("'2025-11'!K7"),"")} | E8: =IF(IFERROR(D8="",FALSE),"",IF(IFERROR(AND(ISNUMBER(D8),OR(ABS(D8-'Bonus Key'!$C$7)<=0.0051)),FALSE),"✔ Correct","✘ Not yet"))
A9: B4 | B9: Which month's packet has the largest total charges? (The gray cell reads Output!B9.) | C9: The running-maximum pattern from Lesson 5.2, one level up: once per month, not once per row | D9: {=IF(Output!B9="","",Output!B9)} | E9: =IF(IFERROR(D9="",FALSE),"",IF(IFERROR(OR(LOWER(TRIM(D9&""))="2025-11",AND(ISNUMBER(D9),IFERROR(YEAR(D9)=2025,FALSE),IFERROR(MONTH(D9)=11,FALSE))),FALSE),"✔ Correct","✘ Not yet"))

Sheet Answer Key
A1: 🔑 Answer Key — Lesson 5.3
A2: Spoiler alert — try every task before reading this sheet. Column C is the value the Check column compares against. Column D is a sample solution; column E is that same formula, live, proving it works.
A4: # | B4: Task | C4: Answer | D4: Sample solution | E4: Live result | F4: Explanation
A5: 1 | B5: Snippet A: what address does the Immediate window show? Type it as printed (the $ signs are optional). | C5: $G$5:$G$9 | D5: `Range("C2").Offset(3, 4)` moves 3 rows down and 4 columns right, to **G5**. `Resize(5)` makes the range 5 rows tall from that corner and keeps its width of 1 column: **$G$5:$G$9**. | E5: — | F5: Offset never changes a range's size, and Resize never moves its top-left corner, so you can read a chain of them left to right. Leaving out Resize's second argument keeps the column count as it is. .Address returns absolute references ($G$5) unless you ask for .Address(False, False).
A6: 2 | B6: Snippet B: what address does the Immediate window show? | C6: A2:L2001 | D6: `Range("E50").CurrentRegion` grows from E50 to the whole block bounded by empty rows and columns: A1:L2001 (the LOSDays header in L1 makes the block 12 columns wide). `Offset(1)` shifts the block down one row, and `Resize(Rows.Count - 1)` trims the row that fell off the bottom: **A2:L2001**. | E6: — | F6: This data-body idiom gives you the data without its header, however many rows the export has. It works from any cell inside the block, which is why the snippet starts in E50. CurrentRegion stops at the first completely empty row and column, so a blank row in the middle of an export cuts it short.
A7: 3 | B7: Snippet C: line 1 prints 2001, the last row of column A. What number does line 2 print (the same idiom on column F, AdmitSource)? | C7: 1995 | D7: End(xlUp) from the bottom of column F stops at the last cell with something in it: row **1995**. The last 6 encounters are emergency or outpatient visits, which have no AdmitSource. | E7: {=SUMPRODUCT(MAX((Encounters!F2:F2001<>"")*ROW(Encounters!F2:F2001)))} | F7: The last-row idiom finds the last filled cell in the column you give it. AdmitSource is blank for emergency and outpatient visits, so a loop that stopped at this row would silently skip the last 6 encounters. Always use a column that is filled on every row, such as the ID column.
A8: 4 | B8: Snippet C: what number does line 3 print? | C8: 2 | D8: F1 and F2 are both filled and F3 is empty, so End(xlDown) stops at the end of that first block: row **2**. | E8: — | F8: Range("F1").End(xlDown) is the top-down version of the idiom, and it fails on the first blank cell. On a column with no gaps it gives the same answer as End(xlUp), which is why it seems to work until the day a blank appears. Start from the bottom and go up with Cells(Rows.Count, col).End(xlUp).
A9: 5 | B9: Snippet D: running SnippetD_WhichSheet stops with a run-time error. Type the error number. | C9: 1004 | D9: Run-time error **1004**: *Method 'Range' of object '_Worksheet' failed*. The two bare `Cells(...)` belong to the active sheet (Practice), and `ws.Range(...)` can't build an Encounters range from Practice cells. | E9: — | F9: In a standard module, Range and Cells with no object in front mean *the active sheet*. Qualify every one: ws.Range(ws.Cells(2, 1), ws.Cells(2, 11)), or use a With block and a leading dot: .Range(.Cells(2, 1), .Cells(2, 11)). The same macro works when Encounters happens to be active, which is what makes this bug hard to spot.
A10: 6 | B10: Snippet E: running SnippetE_DeleteOld stops with a run-time error. Type the error number. | C10: 9 | D10: Run-time error **9**: *Subscript out of range*. There is no sheet named TypeSummary_2024, so `Worksheets("TypeSummary_2024")` fails before `.Delete` even runs. | E10: — | F10: DisplayAlerts = False only silences Excel's *confirmation* prompt. It doesn't make a missing sheet exist. That's why delete-and-recreate macros check first with a function such as SheetExists. The macro also stopped before its DisplayAlerts = True line. Excel resets DisplayAlerts by itself when code finishes, but it doesn't do that for Calculation or EnableEvents, which is why restore lines belong in cleanup code that always runs (guide section 15).
A11: 7 | B11: Complete SheetExists and BuildTypeSummary in the starter module. BuildTypeSummary deletes any old TypeSummary sheet (with DeleteSheetIfExists, which calls your SheetExists), adds a new sheet named TypeSummary at the end of the workbook, and writes one row per EncounterType (Emergency, Inpatient, Observation, Outpatient) with the columns EncounterType (A), Encounters (B, the count), and TotalCharges (C), headers in row 1. Run it twice: the second run must not stop with an error or ask a question. The gray cell looks up the Inpatient TotalCharges on your sheet. | C11: 16882216 | D11: Function SheetExists(ByVal sheetName As String) As Boolean ' True if THIS workbook has a worksheet with that name (ignoring case, ' because Excel treats "typesummary" and "TypeSummary" as the same name). Dim ws As Worksheet For Each ws In ThisWorkbook.Worksheets If StrComp(ws.Name, sheetName, vbTextCompare) = 0 Then SheetExists = True Exit Function End If Next ws End Function Sub BuildTypeSummary() Dim wsEnc As Worksheet, wsSum As Worksheet Dim rngType As Range, rngCharges As Range Dim types As Variant Dim lastR As Long, i As Long Set wsEnc = ThisWorkbook.Worksheets("Encounters") lastR = LastRow(wsEnc, "A") Set rngType = wsEnc.Range("C2:C" & lastR) ' EncounterType Set rngCharges = wsEnc.Range("K2:K" & lastR) ' TotalCharges ' Delete-and-recreate: the macro can run again and again DeleteSheetIfExists "TypeSummary" Set wsSum = ThisWorkbook.Worksheets.Add(After:=ThisWorkbook.Worksheets(ThisWorkbook.Worksheets.Count)) wsSum.Name = "TypeSummary" wsSum.Range("A1:C1").Value = Array("EncounterType", "Encounters", "TotalCharges") types = Array("Emergency", "Inpatient", "Observation", "Outpatient") For i = 0 To UBound(types) ' Array() numbers its items from 0 With wsSum.Cells(i + 2, 1) ' rows 2 to 5, column A .Value = types(i) .Offset(0, 1).Value = Application.WorksheetFunction.CountIf(rngType, types(i)) .Offset(0, 2).Value = Application.WorksheetFunction.SumIf(rngType, types(i), rngCharges) End With Next i wsSum.Range("A1:C1").Font.Bold = True wsSum.Range("C2:C5").NumberFormat = "#,##0.00" wsSum.Columns("A:C").AutoFit End Sub | E11: {=SUMIFS(Encounters!K2:K2001,Encounters!C2:C2001,"Inpatient")} | F11: Delete-and-recreate makes a macro safe to rerun: without the delete, the second run stops at wsSum.Name = "TypeSummary" with run-time error 1004 (*That name is already taken*), because sheet names must be unique. Worksheets.Add returns the new sheet, so Set wsSum = … gives you a variable for it and you never need ActiveSheet. SheetExists compares with vbTextCompare because Excel sheet names ignore case. The finished sheet: Emergency 663 encounters / $1,753,021.67, Inpatient 539 encounters / $16,882,215.53, Observation 89 encounters / $702,704.46, Outpatient 709 encounters / $899,052.36. Inpatient stays are 27% of the encounters but 83% of the charges.
A12: 8 | B12: Complete SplitByFacility: for each FacilityID in the Facilities table (tblFacilities), delete any old sheet with that name, add a new sheet named after the ID (F01, F02, F03, F04), AutoFilter the Encounters block on FacilityID, and copy the visible cells (header included) to A1 of the new sheet. Turn the filter off at the end. The gray cell lists the number of data rows on F01, F02, F03, and F04. | C12: 928 / 175 / 188 / 709 | D12: Sub SplitByFacility() Dim wsEnc As Worksheet, wsNew As Worksheet Dim lo As ListObject Dim idCell As Range, block As Range Dim facID As String Set wsEnc = ThisWorkbook.Worksheets("Encounters") Set lo = ThisWorkbook.Worksheets("Facilities").ListObjects("tblFacilities") If wsEnc.AutoFilterMode Then wsEnc.AutoFilterMode = False ' start with no filter Set block = wsEnc.Range("A1").CurrentRegion ' header + every data row Application.ScreenUpdating = False On Error GoTo CleanUp ' always restore settings For Each idCell In lo.ListColumns("FacilityID").DataBodyRange facID = idCell.Value DeleteSheetIfExists facID Set wsNew = ThisWorkbook.Worksheets.Add(After:=ThisWorkbook.Worksheets(ThisWorkbook.Worksheets.Count)) wsNew.Name = facID block.AutoFilter Field:=4, Criteria1:=facID ' column D = FacilityID block.SpecialCells(xlCellTypeVisible).Copy Destination:=wsNew.Range("A1") wsNew.Range("A1").CurrentRegion.Columns.AutoFit Next idCell CleanUp: wsEnc.AutoFilterMode = False ' leave the export unfiltered Application.ScreenUpdating = True If Err.Number <> 0 Then MsgBox "SplitByFacility stopped: " & Err.Description, vbExclamation End Sub | E12: {=COUNTIF(Encounters!D2:D2001,"F01")&" / "&COUNTIF(Encounters!D2:D2001,"F02")&" / "&COUNTIF(Encounters!D2:D2001,"F03")&" / "&COUNTIF(Encounters!D2:D2001,"F04")} | F12: AutoFilter hides the rows that don't match, and SpecialCells(xlCellTypeVisible) picks only the rows still showing, so the copy brings the header and that facility's rows and nothing else. Looping over the Table's FacilityID column means a fifth facility would get its own sheet with no code change. The On Error GoTo CleanUp block turns the filter off and ScreenUpdating back on even if something fails. If a count is one too high or too low, check whether your copy included the header row, because the gray cell subtracts 1 for it.
A13: 9 | B13: Complete SortAndReconcile, part 1: loop through every worksheet and, for each sheet whose name is Like "F0#", sort its block by TotalCharges (column K), largest first, with Range.Sort and a header row. Which EncounterID is now in A2 of sheet F03? (The gray cell reads F03!A2.) | C13: ENC112749 | D13: Sub SortAndReconcile() Dim ws As Worksheet Dim lastR As Long, rowTotal As Long, sheetCount As Long Dim chargeTotal As Double For Each ws In ThisWorkbook.Worksheets If ws.Name Like "F0#" Then ' F01 to F09 (# = any one digit) ' Task 9: largest charge first. One cell is enough to name the sort column. ws.Range("A1").CurrentRegion.Sort Key1:=ws.Range("K1"), Order1:=xlDescending, Header:=xlYes ' Task 10: add this sheet to the control totals lastR = LastRow(ws, "A") rowTotal = rowTotal + (lastR - 1) ' minus the header row chargeTotal = chargeTotal + Application.WorksheetFunction.Sum(ws.Range("K2:K" & lastR)) sheetCount = sheetCount + 1 End If Next ws With ThisWorkbook.Worksheets("Output") .Range("B4").Value = rowTotal .Range("B5").Value = chargeTotal End With MsgBox sheetCount & " facility sheets: " & rowTotal & " rows, " & _ Format(chargeTotal, "#,##0.00") & " in charges.", vbInformation, "Reconcile the split" End Sub | E13: {=INDEX(Encounters!A2:A2001,MATCH(1,(Encounters!D2:D2001="F03")*(Encounters!K2:K2001=MAX(IF(Encounters!D2:D2001="F03",Encounters!K2:K2001))),0))} | F13: For Each ws In ThisWorkbook.Worksheets visits every worksheet, including the hidden key sheets, so the Like "F0#" test (# means any one digit) picks out the facility sheets. Header:=xlYes keeps row 1 in place as a header. Leave it out and Range.Sort treats row 1 as data, so an ascending sort would bury the header among the rows. ENC112749 is Cedar Ridge's most expensive 2025 encounter in the sample ($167,509.41, inpatient).
A14: 10 | B14: SortAndReconcile, part 2: in the same loop, add each facility sheet's data rows and TotalCharges to two running totals, then write the row total to Output!B4 and the charge total to Output!B5. What is the total charge on the facility sheets? (The gray cell reads Output!B5.) | C14: 20236994 | D14: The second half of the loop in task 9's macro: `rowTotal = rowTotal + (lastR - 1)` and `chargeTotal = chargeTotal + Application.WorksheetFunction.Sum(ws.Range("K2:K" & lastR))`, then both are written to Output after `Next ws`. | E14: {=SUM(Encounters!K2:K2001)} | F14: This is a reconciliation: the facility sheets together must hold exactly the 2,000 rows and $20,236,994.02 of the export (compare with =SUM(Encounters!K2:K2001)). If the totals differ, the split lost or duplicated rows, and you know before anyone reads the sheets. The same control-total habit applies to any macro that moves data around.
A15: 11 | B15: Complete ExportFacility: copy sheet F02 into a new workbook (Worksheet.Copy with no arguments), save it in the same folder as this workbook as F02_encounters_2025.xlsx with SaveAs and FileFormat:=xlOpenXMLWorkbook, and close it. Then reopen the file with Workbooks.Open, add up its TotalCharges column, write the total to Output!B7 (and the file name to Output!B6), and close it without saving. The gray cell reads Output!B7. | C15: 2357196.8 | D15: Sub ExportFacility() Const FAC_ID As String = "F02" Dim wbNew As Workbook, wbCheck As Workbook Dim filePath As String, savedName As String Dim lastR As Long Dim total As Double If Not SheetExists(FAC_ID) Then MsgBox "There's no " & FAC_ID & " sheet. Run SplitByFacility first.", vbExclamation Exit Sub End If If ThisWorkbook.Path = "" Then MsgBox "Save this workbook first, so the export has a folder to go in.", vbExclamation Exit Sub End If filePath = ThisWorkbook.Path & Application.PathSeparator & FAC_ID & "_encounters_2025.xlsx" ' 1. Copy the sheet into a brand-new workbook and save that as .xlsx ThisWorkbook.Worksheets(FAC_ID).Copy ' no Before/After: Excel makes a new workbook Set wbNew = ActiveWorkbook ' right after Copy, the new workbook is active Application.DisplayAlerts = False ' replace last run's file without asking wbNew.SaveAs Filename:=filePath, FileFormat:=xlOpenXMLWorkbook Application.DisplayAlerts = True savedName = wbNew.Name ' read it BEFORE closing wbNew.Close SaveChanges:=False ' 2. Reopen the saved file, read it, and close it again Set wbCheck = Workbooks.Open(Filename:=filePath, ReadOnly:=True) With wbCheck.Worksheets(1) lastR = .Cells(.Rows.Count, "A").End(xlUp).Row total = Application.WorksheetFunction.Sum(.Range("K2:K" & lastR)) End With wbCheck.Close SaveChanges:=False ' 3. Report in THIS workbook, whichever workbook is active now With ThisWorkbook.Worksheets("Output") .Range("B6").Value = savedName .Range("B7").Value = total End With End Sub | E15: {=SUMIFS(Encounters!K2:K2001,Encounters!D2:D2001,"F02")} | F15: Once a second workbook is open, ActiveWorkbook and ThisWorkbook are different files. ThisWorkbook is always the file that holds the code, so it's the safe way back to Output. FileFormat:=xlOpenXMLWorkbook (51) must match the .xlsx extension, or Excel refuses or saves a file that won't open. DisplayAlerts False lets a second run overwrite the old file. Opening with ReadOnly:=True and closing with SaveChanges:=False guarantees the check never changes the export.
A16: 12 | B16: Complete FillLOSDays: read AdmitDateTime and DischargeDateTime (Encounters G2:H2001) into a Variant array with one .Value2 read, calculate each row's length of stay in days with Int(discharge) - Int(admit) (the number of midnights, ignoring the times), and write all the results to the yellow LOSDays column (L) with one assignment. The gray cell adds up your column. | C16: 2580 | D16: Sub FillLOSDays() Dim ws As Worksheet Dim lastR As Long, i As Long Dim stay As Variant ' will hold an n x 2 array: admit, discharge Dim los() As Variant ' n x 1 array for the results Set ws = ThisWorkbook.Worksheets("Encounters") lastR = LastRow(ws, "A") stay = ws.Range("G2:H" & lastR).Value2 ' ONE read. Value2 gives dates as serial numbers ReDim los(1 To UBound(stay, 1), 1 To 1) For i = 1 To UBound(stay, 1) ' whole days between the two dates = midnights in the hospital los(i, 1) = Int(stay(i, 2)) - Int(stay(i, 1)) Next i ws.Range("L2").Resize(UBound(los, 1), 1).Value = los ' ONE write End Sub | E16: {=SUMPRODUCT(INT(Encounters!H2:H2001)-INT(Encounters!G2:G2001))} | F16: Every read or write of a cell crosses from VBA into Excel, and that crossing is the slow part. The array version crosses twice (one read, one write) instead of 6,000 times (4,000 reads and 2,000 writes) for 2,000 rows. A multi-cell range's .Value2 is always a 2-D array numbered from 1, even for one column, so the results array must be 2-D too: los(1 To n, 1 To 1). Value2 hands back dates as serial numbers, so Int strips the time. Inpatient stays account for 2,406 of the 2,580 days. Emergency and observation visits that crossed midnight count 1 or 2.

Sheet Bonus Key
A1: 🔑 Bonus Key — Lesson 5.3
A2: Spoiler alert — try every task before reading this sheet. Column C is the value the Check column compares against. Column D is a sample solution; column E is that same formula, live, proving it works.
A4: # | B4: Task | C4: Answer | D4: Sample solution | E4: Live result | F4: Explanation
A5: B1 | B5: How many inpatient encounters are in the 2025-03 packet? (The gray cell counts the data rows from row 7 down.) | C5: 37 | D5: Sub BuildMonthlyPackets() Const NCOLS As Long = 11 ' Encounters columns A:K Dim wsEnc As Worksheet, wsTpl As Worksheet, wsPk As Worksheet Dim src As Variant, buf() As Variant Dim lastR As Long, i As Long, j As Long, n As Long, m As Long Dim monthStart As Date, nextMonth As Date Dim sheetName As String, bestName As String Dim total As Double, bestTotal As Double Set wsEnc = ThisWorkbook.Worksheets("Encounters") Set wsTpl = ThisWorkbook.Worksheets("PacketTemplate") lastR = LastRow(wsEnc, "A") src = wsEnc.Range("A2").Resize(lastR - 1, NCOLS).Value ' read the export ONCE Application.ScreenUpdating = False On Error GoTo CleanUp For m = 1 To 12 monthStart = DateSerial(2025, m, 1) nextMonth = DateSerial(2025, m + 1, 1) ' month 13 rolls over to January 2026 sheetName = Format(monthStart, "yyyy-mm") ' 1. Collect this month's inpatient rows in a buffer as big as the export ReDim buf(1 To UBound(src, 1), 1 To NCOLS) n = 0 total = 0 For i = 1 To UBound(src, 1) If src(i, 3) = "Inpatient" And src(i, 7) >= monthStart And src(i, 7) < nextMonth Then n = n + 1 For j = 1 To NCOLS buf(n, j) = src(i, j) Next j total = total + src(i, 11) End If Next i ' 2. A fresh copy of the template, named for the month DeleteSheetIfExists sheetName wsTpl.Copy After:=ThisWorkbook.Worksheets(ThisWorkbook.Worksheets.Count) Set wsPk = ActiveSheet ' a copied sheet is always the active one wsPk.Name = sheetName ' 3. Header block, data, sort wsPk.Range("B2").Value = monthStart wsPk.Range("B3").Value = n wsPk.Range("B4").Value = total If n > 0 Then ' A range smaller than the array takes just the top-left n rows of it wsPk.Range("A7").Resize(n, NCOLS).Value = buf wsPk.Range("A6").CurrentRegion.Sort Key1:=wsPk.Range("K6"), Order1:=xlDescending, Header:=xlYes End If ' 4. Remember the biggest month so far If total > bestTotal Then bestTotal = total bestName = sheetName End If Next m ThisWorkbook.Worksheets("Output").Range("B9").Value = bestName CleanUp: Application.ScreenUpdating = True If Err.Number <> 0 Then MsgBox "BuildMonthlyPackets stopped: " & Err.Description, vbExclamation Else MsgBox "12 packets built. Largest month: " & bestName, vbInformation End If End Sub | E5: {=COUNTIFS(Encounters!C2:C2001,"Inpatient",Encounters!G2:G2001,">="&DATE(2025,3,1),Encounters!G2:G2001,"<"&DATE(2025,4,1))} | F5: Comparing against the first day of the next month with < catches every admission on the last day of the month, whatever the time. <= DateSerial(2025, 3, 31) would miss a patient admitted at 3/31 14:20, because that datetime is larger than midnight on 3/31. DateSerial(2025, m + 1, 1) works for December too: month 13 rolls over to January 2026. The ReDim buf(1 To UBound(src, 1), …) buffer is as big as the whole export, and Range("A7").Resize(n, 11).Value = buf writes only its top-left n rows.
A6: B2 | B6: What total charges does the 2025-07 packet show in its header (cell B4)? | C6: 1362384.7 | D6: Add each matching row's TotalCharges (`src(i, 11)`) to `total` inside the collecting loop, then write `wsPk.Range("B4").Value = total` after copying the template. | E6: {=SUMIFS(Encounters!K2:K2001,Encounters!C2:C2001,"Inpatient",Encounters!G2:G2001,">="&DATE(2025,7,1),Encounters!G2:G2001,"<"&DATE(2025,8,1))} | F6: If every month after January shows a bigger total than the one before, total wasn't reset inside the month loop, so each packet carries the previous months' charges. The same goes for n. Accumulators that belong to one pass of an outer loop must be reset at the top of that pass.
A7: B3 | B7: What is the top charge in the 2025-11 packet (TotalCharges in K7, after sorting)? | C7: 144338.01 | D7: Sort the block that starts at the header row: `wsPk.Range("A6").CurrentRegion.Sort Key1:=wsPk.Range("K6"), Order1:=xlDescending, Header:=xlYes`. | E7: {=MAX(IF((Encounters!C2:C2001="Inpatient")*(Encounters!G2:G2001>=DATE(2025,11,1))*(Encounters!G2:G2001<DATE(2025,12,1)),Encounters!K2:K2001))} | F7: The template leaves row 5 empty on purpose. CurrentRegion stops at an empty row, so Range("A6").CurrentRegion is the header plus the data and never includes the labels in A2:B4. Without that empty row, the region would reach up to the title and labels in rows 1–4, and the sort would shuffle them in among the encounters. ENC120639 tops the 2025-11 packet at $144,338.01.
A8: B4 | B8: Which month's packet has the largest total charges? (The gray cell reads Output!B9.) | C8: 2025-11 | D8: Track a running maximum in the month loop. After each month, `If total > bestTotal Then` store `total` in `bestTotal` and `sheetName` in `bestName`. After `Next m`, write `bestName` to Output!B9. | E8: — | F8: 2025-11: $1,925,363.45 from 53 stays. The quietest month was 2025-06 ($868,931.28, 31 stays). Output!B9 is formatted as Text because Excel may read a value like 2025-01 written into a General cell as a date (January 2025). The check accepts either form. In the solution, the On Error GoTo CleanUp line sends any error to the cleanup block, which turns ScreenUpdating back on before reporting the problem.

Sheet PacketTemplate
A1: Monthly inpatient packet | D1: Bluestone Health System · Finance
A2: Month
A3: Inpatient encounters
A4: Total charges
A6: EncounterID | B6: PatientID | C6: EncounterType | D6: FacilityID | E6: DeptID | F6: AdmitSource | G6: AdmitDateTime | H6: DischargeDateTime | I6: PrimaryDxCode | J6: PayerID | K6: TotalCharges
