Workbook

Sheet Start Here
B2: Lesson 2.6
B3: Lookups: VLOOKUP, INDEX/MATCH & XLOOKUP
B4: Beginner → Intermediate · about 125 minutes · Bluestone Health System (fictional)
B6: What you'll learn
B7: • | C7: Look up exact matches with VLOOKUP and XLOOKUP
B8: • | C8: Use approximate matches for tiers like age bands and BMI categories
B9: • | C9: Combine INDEX and MATCH for flexible and two-way lookups
B10: • | C10: Handle missing values with IFNA and XLOOKUP's if_not_found
B12: How to use this workbook
B13: 1. Read the guide | C13: The lesson guide (README) explains each skill with examples: https://github.com/lmansf/learn-excel/tree/main/02-formulas-functions/06-lookup-functions
B14: 2. Practice | C14: Go to the 'Practice' sheet. Type a formula or value into each yellow cell.
B15: 3. Check yourself | C15: The Check column shows ✔ Correct (green) or ✘ Not yet (red).
B16: 4. Bonus | C16: Finished? Try the harder 'Bonus' sheet.
B17: 5. Answers | C17: The 'Answer Key' and 'Bonus Key' sheets are hidden. Right-click any sheet tab → Unhide… → pick one → OK. (Try first!)
B18: Note | C18: Encounters is sorted by AdmitDate, oldest first. Patients holds only Dr. Nguyen's panel (185 patients), so a patient who isn't on the panel won't be found there. That's intentional (task 13).
B19: Note | C19: MRN is stored as 8-character TEXT on purpose (leading zeros matter). The green triangles in that column are Excel's 'number stored as text' warning. Leave them as they are.
B20: Note | C20: Every data sheet is an Excel Table. When you drag over a data sheet's column while typing a formula, Excel may write a Table reference such as tblPatients[LastName] instead of Patients!D2:D186. Both give the same result (Lesson 3.1 covers Tables).
B21: Note | C21: BMI = 703 × WeightLb ÷ HeightIn², rounded to 1 decimal place. Age is the patient's age in completed years on 12/31/2025.
B22: Note | C22: The Card sheet is for the bonus challenge.
B24: Color legend
B25: Yellow cell | C25: Your answer goes here.
B26: Gray cell | C26: Pre-filled summary formula. It reads the work you did on another sheet, so don't type over it.
B27: ✔ Correct | C27: Your answer matches the key.
B28: ✘ Not yet | C28: Not matching yet. Check the hint and try again.
B30: Sheets in this workbook
B31: Practice | C31: 13 practice tasks, each with a Check cell.
B32: Encounters | C32: Data: 529 rows, in the Excel Table 'tblEncounters'
B33: Patients | C33: Data: 185 rows, in the Excel Table 'tblPatients'
B34: Referrals | C34: Data: 24 rows, in the Excel Table 'tblReferrals'
B35: Providers | C35: Data: 147 rows, in the Excel Table 'tblProviders'
B36: Diagnoses | C36: Data: 51 rows, in the Excel Table 'tblDiagnoses'
B37: Payers | C37: Data: 8 rows, in the Excel Table 'tblPayers'
B38: Departments | C38: Data: 31 rows, in the Excel Table 'tblDepartments'
B39: Claims | C39: Data: 529 rows, in the Excel Table 'tblClaims'
B40: Budget | C40: Data: 31 rows, in the Excel Table 'tblBudget'
B41: BMITiers | C41: Data: 6 rows, in the Excel Table 'tblBMITiers'
B42: AgeBands | C42: Data: 6 rows, in the Excel Table 'tblAgeBands'
... B45: Disclaimer | C45: All people, places, and numbers are synthetic and fictional. Not clinical guidance.

Sheet Practice
A1: Lesson 2.6 · Practice
A2: The Encounters sheet stores IDs only, so every answer comes from looking an ID up in another sheet. Write each answer as a formula. Your answers sit on this Practice sheet, so a reference to a data cell needs its sheet name, such as Encounters!B9. Click the cell on the data sheet and Excel writes the sheet name for you. Tasks 5, 7, and 13 are different: you type the formula on a data sheet and copy it down the column, and the gray cell here reads your column. Lock the lookup table's ranges with $ (F4, Mac: ⌘ + T) so they don't slide when you copy. If Excel writes a Table reference such as tblPayers[PayerName] instead, keep it, because a Table reference never slides when you copy it down.
A3: Type a formula or value in each yellow cell. The Check column turns green when your answer matches. Stuck? Read the hint, then the lesson guide. Answers: right-click a sheet tab → Unhide… → 'Answer Key'.
A4: ="Score: "&COUNTIF(E6:E18,"✔*")&" of 13 auto-checked tasks correct"
A5: # | B5: Task | C5: Hint | D5: Your Answer | E5: Check
A6: 1 | B6: Encounter ENC110900 is on row 9 of the Encounters sheet. Use VLOOKUP with its PatientID (cell Encounters!B9) to return the patient's last name from the Patients sheet. | C6: VLOOKUP(lookup_value, table_array, col_index_num, FALSE). Count columns from PatientID (column 1) to LastName | E6: =IF(IFERROR(D6="",FALSE),"",IF(IFERROR(OR(LOWER(TRIM(D6&""))=LOWER(TRIM('Answer Key'!$C$5&""))),FALSE),"✔ Correct","✘ Not yet"))
A7: 2 | B7: Encounter ENC111256 (Encounters row 20) was billed to payer PY02. Use VLOOKUP on the Payers sheet to return the payer's PayerType. | C7: Count the columns of the Payers table to find PayerType's column number | E7: =IF(IFERROR(D7="",FALSE),"",IF(IFERROR(OR(LOWER(TRIM(D7&""))=LOWER(TRIM('Answer Key'!$C$6&""))),FALSE),"✔ Correct","✘ Not yet"))
A8: 3 | B8: Encounter ENC113996 (Encounters row 150) has primary diagnosis code E11.65. Use XLOOKUP to return its description from the Diagnoses sheet. | C8: XLOOKUP(lookup_value, lookup_array, return_array) | E8: =IF(IFERROR(D8="",FALSE),"",IF(IFERROR(OR(LOWER(TRIM(D8&""))=LOWER(TRIM('Answer Key'!$C$7&""))),FALSE),"✔ Correct","✘ Not yet"))
A9: 4 | B9: Who attended encounter ENC112339 (Encounters row 73)? Use INDEX and MATCH with its AttendingProviderID to return the provider's Specialty from the Providers sheet. | C9: INDEX(Specialty column, MATCH(id, ProviderID column, 0)) | E9: =IF(IFERROR(D9="",FALSE),"",IF(IFERROR(OR(LOWER(TRIM(D9&""))=LOWER(TRIM('Answer Key'!$C$8&""))),FALSE),"✔ Correct","✘ Not yet"))
A10: 5 | B10: Fill the yellow PayerName column on the Encounters sheet with a lookup that returns each encounter's payer name (start in K2 and copy down to row 530). The gray cell counts how many encounters your column shows as exactly "Medicare". | C10: Lock the Payers ranges with $ before you copy the formula down | D10: {=IF(COUNTA(Encounters!K2:K530)=0,"",COUNTIF(Encounters!K2:K530,"Medicare"))} | E10: =IF(IFERROR(D10="",FALSE),"",IF(IFERROR(AND(ISNUMBER(D10),OR(ABS(D10-'Answer Key'!$C$9)<=0.0001)),FALSE),"✔ Correct","✘ Not yet"))
A11: 6 | B11: Patient PT10395 is on Patients row 21, and the Age column shows 75. Use VLOOKUP with an approximate match (TRUE) on the AgeBands sheet to return the patient's age band. | C11: An approximate match returns the band whose MinAge is the largest one that is ≤ the age | E11: =IF(IFERROR(D11="",FALSE),"",IF(IFERROR(OR(LOWER(TRIM(D11&""))=LOWER(TRIM('Answer Key'!$C$10&""))),FALSE),"✔ Correct","✘ Not yet"))
A12: 7 | B12: Fill the yellow BMICategory column on the Patients sheet: look up each patient's BMI in the BMITiers table with an approximate match (start in L2 and copy down to row 186). The gray cell counts patients in any obesity class (BMI 30 or higher). | C12: VLOOKUP(…, TRUE) or XLOOKUP with match_mode -1 (exact match or next smaller item) | D12: {=IF(COUNTA(Patients!L2:L186)=0,"",COUNTIF(Patients!L2:L186,"Obesity*"))} | E12: =IF(IFERROR(D12="",FALSE),"",IF(IFERROR(AND(ISNUMBER(D12),OR(ABS(D12-'Answer Key'!$C$11)<=0.0001)),FALSE),"✔ Correct","✘ Not yet"))
A13: 8 | B13: The lab's interface file sent a result for MRN 50339. It arrived as a number, so its leading zeros were dropped, but the Patients sheet stores MRNs as 8-character text. Return the PatientID for this MRN. (PatientID is to the left of MRN, so VLOOKUP can't do it.) | C13: Rebuild the text MRN with TEXT(number,"00000000"), then use INDEX/MATCH or XLOOKUP | E13: =IF(IFERROR(D13="",FALSE),"",IF(IFERROR(OR(LOWER(TRIM(D13&""))=LOWER(TRIM('Answer Key'!$C$12&""))),FALSE),"✔ Correct","✘ Not yet"))
A14: 9 | B14: A clinic note mentions "osteoarthritis of the right knee." Use a wildcard lookup to return the DxCode whose DxDescription contains the word knee. | C14: An asterisk wildcard stands for any characters, so put one on each side of the word. XLOOKUP needs match_mode 2 | E14: =IF(IFERROR(D14="",FALSE),"",IF(IFERROR(OR(LOWER(TRIM(D14&""))=LOWER(TRIM('Answer Key'!$C$13&""))),FALSE),"✔ Correct","✘ Not yet"))
A15: 10 | B15: Two-way lookup: on the Budget sheet, what is the 2025 Pharmaceuticals budget for department D130 (Intensive Care Unit at Bluestone Memorial Hospital)? Find the row by DeptID and the column by category name. | C15: INDEX(grid, MATCH(row label…), MATCH(column header…)) | E15: =IF(IFERROR(D15="",FALSE),"",IF(IFERROR(AND(ISNUMBER(D15),OR(ABS(D15-'Answer Key'!$C$14)<=0.0001)),FALSE),"✔ Correct","✘ Not yet"))
A16: 11 | B16: What is the TOTAL 2025 expense budget (all seven categories) for department D400, Primary Care Clinic, where Dr. Nguyen practices? Use one lookup that returns the department's whole row of the grid, wrapped in SUM. | C16: XLOOKUP's return_array can be several columns wide | E16: =IF(IFERROR(D16="",FALSE),"",IF(IFERROR(AND(ISNUMBER(D16),OR(ABS(D16-'Answer Key'!$C$15)<=0.0001)),FALSE),"✔ Correct","✘ Not yet"))
A17: 12 | B17: Patient PT13163 visited more often than anyone else on the panel (11 encounters in 2025). The Encounters sheet is sorted oldest to newest. Use XLOOKUP searching from the bottom up to return the AdmitDate of this patient's most recent encounter. | C17: search_mode is XLOOKUP's 6th argument, and -1 searches last-to-first | E17: =IF(IFERROR(D17="",FALSE),"",IF(IFERROR(AND(ISNUMBER(D17),INT(D17)=INT('Answer Key'!$C$16)),FALSE),"✔ Correct","✘ Not yet"))
A18: 13 | B18: The Referrals sheet lists 24 referrals received in December. Fill its yellow PatientID column by looking up each MRN in the Patients sheet (start in G2 and copy down to row 25). Patients who aren't on the panel yet must show the text Not found instead of #N/A. The gray cell counts the Not found rows. | C18: XLOOKUP's 4th argument (if_not_found), or wrap the lookup in IFNA(…, "Not found") | D18: {=IF(COUNTA(Referrals!G2:G25)=0,"",COUNTIF(Referrals!G2:G25,"Not found"))} | E18: =IF(IFERROR(D18="",FALSE),"",IF(IFERROR(AND(ISNUMBER(D18),OR(ABS(D18-'Answer Key'!$C$17)<=0.0001)),FALSE),"✔ Correct","✘ Not yet"))

Sheet Encounters
A1: EncounterID | B1: PatientID | C1: EncounterType | D1: AdmitDate | E1: DischargeDate | F1: DeptID | G1: AttendingProviderID | H1: PrimaryDxCode | I1: PayerID | J1: TotalCharges | K1: PayerName
A2: ENC110744 | B2: PT10444 | C2: Inpatient | D2: 45658 | E2: 45660 | F2: D111 | G2: PRV1087 | H2: K35.80 | I2: PY01 | J2: 48442.42
A3: ENC110776 | B3: PT12169 | C3: Outpatient | D3: 45659 | E3: 45659 | F3: D400 | G3: PRV1137 | H3: J06.9 | I3: PY05 | J3: 304.68
A4: ENC110790 | B4: PT10695 | C4: Emergency | D4: 45659 | E4: 45659 | F4: D300 | G4: PRV1025 | H4: A08.4 | I4: PY03 | J4: 1281.12
A5: ENC110816 | B5: PT11138 | C5: Outpatient | D5: 45660 | E5: 45660 | F5: D430 | G5: PRV1114 | H5: C50.911 | I5: PY06 | J5: 413.97
A6: ENC110831 | B6: PT13484 | C6: Observation | D6: 45660 | E6: 45661 | F6: D195 | G6: PRV1042 | H6: R55 | I6: PY02 | J6: 4715.78
A7: ENC110868 | B7: PT10065 | C7: Emergency | D7: 45662 | E7: 45662 | F7: D100 | G7: PRV1009 | H7: F41.9 | I7: PY01 | J7: 1451.71
A8: ENC110893 | B8: PT10085 | C8: Outpatient | D8: 45663 | E8: 45663 | F8: D400 | G8: PRV1127 | H8: Z00.00 | I8: PY04 | J8: 276.25
A9: ENC110900 | B9: PT10264 | C9: Inpatient | D9: 45663 | E9: 45666 | F9: D170 | G9: PRV1092 | H9: O80 | I9: PY04 | J9: 13917.66
A10: ENC110954 | B10: PT13517 | C10: Inpatient | D10: 45664 | E10: 45668 | F10: D111 | G10: PRV1029 | H10: E11.65 | I10: PY03 | J10: 22267.85
A11: ENC110975 | B11: PT11701 | C11: Inpatient | D11: 45665 | E11: 45666 | F11: D110 | G11: PRV1084 | H11: K80.20 | I11: PY01 | J11: 29564.23
A12: ENC110967 | B12: PT11138 | C12: Inpatient | D12: 45665 | E12: 45668 | F12: D310 | G12: PRV1051 | H12: N39.0 | I12: PY06 | J12: 27045.66
A13: ENC110989 | B13: PT10444 | C13: Emergency | D13: 45665 | E13: 45665 | F13: D100 | G13: PRV1002 | H13: J44.1 | I13: PY01 | J13: 3793.84
... A530: ENC121856 | B530: PT10423 | C530: Outpatient | D530: 46022 | E530: 46022 | F530: D440 | G530: PRV1142 | H530: E11.9 | I530: PY02 | J530: 401.99

Sheet Patients
A1: PatientID | B1: MRN | C1: FirstName | D1: LastName | E1: Sex | F1: DOB | G1: Age | H1: HeightIn | I1: WeightLb | J1: BMI | K1: PrimaryPayerID | L1: BMICategory
A2: PT10050 | B2: 01987874 | C2: Patrick | D2: Kim | E2: M | F2: 16878 | G2: 79 | H2: 72.3 | I2: 177.1 | J2: 23.8 | K2: PY04
A3: PT10065 | B3: 01729555 | C3: James | D3: Henry | E3: M | F3: 19012 | G3: 73 | H3: 68.4 | I3: 229.9 | J3: 34.5 | K3: PY01
A4: PT10070 | B4: 00750668 | C4: Carl | D4: Elliott | E4: M | F4: 19277 | G4: 73 | H4: 68.4 | I4: 180.5 | J4: 27.1 | K4: PY02
A5: PT10073 | B5: 03449108 | C5: Isabella | D5: Cruz | E5: F | F5: 38279 | G5: 21 | H5: 67.5 | I5: 160.1 | J5: 24.7 | K5: PY01
A6: PT10084 | B6: 05752459 | C6: Stephen | D6: Ramos | E6: M | F6: 10549 | G6: 97 | H6: 69.9 | I6: 176.9 | J6: 25.5 | K6: PY02
A7: PT10085 | B7: 06705511 | C7: Andrew | D7: Hernandez | E7: M | F7: 37824 | G7: 22 | H7: 70.8 | I7: 239.3 | J7: 33.6 | K7: PY04
A8: PT10103 | B8: 01509591 | C8: Minh | D8: Snyder | E8: M | F8: 21735 | G8: 66 | H8: 68.1 | I8: 171.8 | J8: 26 | K8: PY01
A9: PT10107 | B9: 02363916 | C9: Mason | D9: Harrison | E9: M | F9: 36368 | G9: 26 | H9: 64 | I9: 157.4 | J9: 27 | K9: PY07
A10: PT10118 | B10: 00397290 | C10: Eric | D10: Peterson | E10: M | F10: 17544 | G10: 77 | H10: 67.9 | I10: 136.3 | J10: 20.8 | K10: PY04
A11: PT10130 | B11: 08690991 | C11: Maria | D11: Romero | E11: F | F11: 19237 | G11: 73 | H11: 63.7 | I11: 124.3 | J11: 21.5 | K11: PY02
A12: PT10131 | B12: 05272828 | C12: Alexander | D12: Watson | E12: M | F12: 29322 | G12: 45 | H12: 64.3 | I12: 234.2 | J12: 39.8 | K12: PY05
A13: PT10167 | B13: 01444107 | C13: Aaliyah | D13: Wood | E13: F | F13: 16950 | G13: 79 | H13: 66.7 | I13: 192.3 | J13: 30.4 | K13: PY01
... A186: PT13966 | B186: 04542733 | C186: John | D186: Herrera | E186: M | F186: 19431 | G186: 72 | H186: 73.9 | I186: 289.8 | J186: 37.3 | K186: PY02

Sheet Referrals
A1: ReferralID | B1: ReceivedDate | C1: MRN | D1: PatientName | E1: ReferredBy | F1: Reason | G1: PatientID
A2: RF-2512-01 | B2: 45992 | C2: 03449108 | D2: Cruz, Isabella | E2: Bluestone Memorial ED | F2: ED follow-up
A3: RF-2512-02 | B3: 45992 | C3: 06291850 | D3: Robertson, Diana | E3: Endocrinology & Diabetes Clinic | F3: Abnormal lab follow-up
A4: RF-2512-03 | B4: 45993 | C4: 04683061 | D4: Lindqvist, Austin | E4: Cardiology Clinic | F4: Establish primary care
A5: RF-2512-04 | B5: 45994 | C5: 09504842 | D5: Owens, Donna | E5: Ashby Falls Community Hospital | F5: Medication review
A6: RF-2512-05 | B6: 45995 | C6: 00633088 | D6: Foster, Nicholas | E6: Cedar Ridge Medical Center | F6: Diabetes management
A7: RF-2512-06 | B7: 45996 | C7: 05468100 | D7: Simmons, Billy | E7: Bluestone Memorial Hospital Medicine | F7: Post-discharge follow-up
A8: RF-2512-07 | B8: 45999 | C8: 01591310 | D8: Ellis, Lauren | E8: Bluestone Memorial ED | F8: Blood pressure check
A9: RF-2512-08 | B9: 46000 | C9: 04635403 | D9: Thompson, Charlotte | E9: Endocrinology & Diabetes Clinic | F9: ED follow-up
A10: RF-2512-09 | B10: 46001 | C10: 00746283 | D10: Andrews, Karen | E10: Cardiology Clinic | F10: Abnormal lab follow-up
A11: RF-2512-10 | B11: 46002 | C11: 04488731 | D11: Cruz, Jesse | E11: Ashby Falls Community Hospital | F11: Establish primary care
A12: RF-2512-11 | B12: 46003 | C12: 07862874 | D12: Miller, Marie | E12: Cedar Ridge Medical Center | F12: Medication review
A13: RF-2512-12 | B13: 46006 | C13: 06750184 | D13: Howard, Vincent | E13: Bluestone Memorial Hospital Medicine | F13: Diabetes management
... A25: RF-2512-24 | B25: 46022 | C25: 04718077 | D25: Munoz, Anna | E25: Bluestone Memorial Hospital Medicine | F25: Establish primary care

Sheet Providers
A1: ProviderID | B1: FirstName | C1: LastName | D1: Credential | E1: Specialty | F1: PrimaryDeptID | G1: FacilityID
A2: PRV1001 | B2: Roy | C2: Ferguson | D2: MD | E2: Emergency Medicine | F2: D100 | G2: F01
A3: PRV1002 | B3: Mia | C3: Cruz | D3: MD | E3: Emergency Medicine | F3: D100 | G3: F01
A4: PRV1003 | B4: Jordan | C4: Morris | D4: MD | E4: Emergency Medicine | F4: D100 | G4: F01
A5: PRV1004 | B5: Jesse | C5: Elliott | D5: MD | E5: Emergency Medicine | F5: D100 | G5: F01
A6: PRV1005 | B6: Christian | C6: Olson | D6: DO | E6: Emergency Medicine | F6: D100 | G6: F01
A7: PRV1006 | B7: James | C7: Kowalski | D7: MD | E7: Emergency Medicine | F7: D100 | G7: F01
A8: PRV1007 | B8: Alexander | C8: Mendoza | D8: MD | E8: Emergency Medicine | F8: D100 | G8: F01
A9: PRV1008 | B9: Jacob | C9: Sullivan | D9: DO | E9: Emergency Medicine | F9: D100 | G9: F01
A10: PRV1009 | B10: Patrick | C10: Foster | D10: DO | E10: Emergency Medicine | F10: D100 | G10: F01
A11: PRV1010 | B11: Nancy | C11: Payne | D11: MD | E11: Emergency Medicine | F11: D100 | G11: F01
A12: PRV1011 | B12: Mia | C12: Gonzales | D12: PA | E12: Emergency Medicine | F12: D100 | G12: F01
... A148: PRV1147 | B148: Natalie | C148: Wagner | D148: MD | E148: Pathology | F148: D500 | G148: F01

Sheet Diagnoses
A1: DxCode | B1: DxDescription | C1: DxCategory | D1: ChronicCondition | E1: ExpectedLOS
A2: A08.4 | B2: Viral intestinal infection, unspecified | C2: Infectious | D2: N | E2: 2.1
A3: A41.9 | B3: Sepsis, unspecified organism | C3: Infectious | D3: N | E3: 5
A4: C34.90 | B4: Malignant neoplasm of unspecified part of unspecified bronchus or lung | C4: Neoplasms | D4: Y | E4: 5
A5: C50.911 | B5: Malignant neoplasm of unspecified site of right female breast | C5: Neoplasms | D5: Y | E5: 3
A6: D70.1 | B6: Agranulocytosis secondary to cancer chemotherapy | C6: Blood | D6: N | E6: 4.5
A7: E11.65 | B7: Type 2 diabetes mellitus with hyperglycemia | C7: Endocrine | D7: Y | E7: 3
A8: E11.9 | B8: Type 2 diabetes mellitus without complications | C8: Endocrine | D8: Y
A9: E78.5 | B9: Hyperlipidemia, unspecified | C9: Endocrine | D9: Y
A10: E86.0 | B10: Dehydration | C10: Endocrine | D10: N | E10: 2.4
A11: E87.1 | B11: Hypo-osmolality and hyponatremia | C11: Endocrine | D11: N | E11: 3.2
A12: F10.239 | B12: Alcohol dependence with withdrawal, unspecified | C12: Mental & Behavioral | D12: Y | E12: 3.6
A13: F20.9 | B13: Schizophrenia, unspecified | C13: Mental & Behavioral | D13: Y | E13: 8.9
A14: F32.9 | B14: Major depressive disorder, single episode, unspecified | C14: Mental & Behavioral | D14: Y | E14: 6.8
A15: F41.9 | B15: Anxiety disorder, unspecified | C15: Mental & Behavioral | D15: Y
A16: G40.909 | B16: Epilepsy, unspecified, not intractable, without status epilepticus | C16: Nervous System | D16: Y | E16: 2.5
A17: G43.909 | B17: Migraine, unspecified, not intractable, without status migrainosus | C17: Nervous System | D17: Y
A18: H66.90 | B18: Otitis media, unspecified, unspecified ear | C18: Ear | D18: N
A19: I10 | B19: Essential (primary) hypertension | C19: Circulatory | D19: Y
A20: I21.4 | B20: Non-ST elevation (NSTEMI) myocardial infarction | C20: Circulatory | D20: N | E20: 3.4
A21: I48.91 | B21: Unspecified atrial fibrillation | C21: Circulatory | D21: Y | E21: 2.9
A22: I50.9 | B22: Heart failure, unspecified | C22: Circulatory | D22: Y | E22: 4.1
A23: I63.9 | B23: Cerebral infarction, unspecified | C23: Circulatory | D23: N | E23: 4.2
A24: J06.9 | B24: Acute upper respiratory infection, unspecified | C24: Respiratory | D24: N
A25: J18.9 | B25: Pneumonia, unspecified organism | C25: Respiratory | D25: N | E25: 3.9
A26: J21.9 | B26: Acute bronchiolitis, unspecified | C26: Respiratory | D26: N | E26: 2.4
A27: J44.1 | B27: Chronic obstructive pulmonary disease with (acute) exacerbation | C27: Respiratory | D27: Y | E27: 3.4
A28: J45.909 | B28: Unspecified asthma, uncomplicated | C28: Respiratory | D28: Y | E28: 2.1
A29: J96.01 | B29: Acute respiratory failure with hypoxia | C29: Respiratory | D29: N | E29: 4.8
A30: K35.80 | B30: Unspecified acute appendicitis | C30: Digestive | D30: N | E30: 2
A31: K56.609 | B31: Unspecified intestinal obstruction | C31: Digestive | D31: N | E31: 4.6
A32: K80.20 | B32: Calculus of gallbladder without cholecystitis without obstruction | C32: Digestive | D32: N | E32: 1.9
A33: K92.2 | B33: Gastrointestinal hemorrhage, unspecified | C33: Digestive | D33: N | E33: 3.5
A34: L03.115 | B34: Cellulitis of right lower limb | C34: Skin | D34: N | E34: 3.4
A35: M16.11 | B35: Unilateral primary osteoarthritis, right hip | C35: Musculoskeletal | D35: Y | E35: 2.1
A36: M17.11 | B36: Unilateral primary osteoarthritis, right knee | C36: Musculoskeletal | D36: Y | E36: 2
A37: M54.50 | B37: Low back pain, unspecified | C37: Musculoskeletal | D37: N
A38: N17.9 | B38: Acute kidney failure, unspecified | C38: Genitourinary | D38: N | E38: 3.9
A39: N39.0 | B39: Urinary tract infection, site not specified | C39: Genitourinary | D39: N | E39: 3.1
A40: O80 | B40: Encounter for full-term uncomplicated delivery | C40: Pregnancy | D40: N | E40: 2
...

Sheet Payers
A1: PayerID | B1: PayerName | C1: PayerType | D1: AvgAllowedPctOfCharges | E1: AvgDaysToPay | F1: TimelyFilingDays
A2: PY01 | B2: Medicare | C2: Government | D2: 0.31 | E2: 14 | F2: 365
A3: PY02 | B3: Silverline Medicare Advantage | C3: Medicare Advantage | D3: 0.33 | E3: 28 | F3: 180
A4: PY03 | B4: State Medicaid | C4: Government | D4: 0.24 | E4: 35 | F4: 365
A5: PY04 | B5: Keystone Health Partners | C5: Commercial | D5: 0.52 | E5: 24 | F5: 90
A6: PY05 | B6: Evergreen Mutual Insurance | C6: Commercial | D6: 0.48 | E6: 30 | F6: 120
A7: PY06 | B7: Summit Choice PPO | C7: Commercial | D7: 0.55 | E7: 21 | F7: 90
A8: PY07 | B8: Self-Pay | C8: Self-Pay | D8: 0.4 | E8: 60 | F8: 0
A9: PY08 | B9: Workers' Compensation | C9: Workers' Comp | D9: 0.6 | E9: 45 | F9: 180

Sheet Departments
A1: DeptID | B1: DeptName | C1: FacilityID | D1: ServiceLine | E1: UnitType | F1: StaffedBeds | G1: CostCenter
A2: D100 | B2: Emergency Department | C2: F01 | D2: Emergency | E2: Emergency | G2: 6100
A3: D110 | B3: Medical-Surgical 4 West | C3: F01 | D3: Medicine | E3: Inpatient | F3: 36 | G3: 6110
A4: D111 | B4: Medical-Surgical 5 East | C4: F01 | D4: Medicine | E4: Inpatient | F4: 32 | G4: 6111
A5: D120 | B5: Cardiac Step-Down | C5: F01 | D5: Cardiovascular | E5: Inpatient | F5: 24 | G5: 6120
A6: D130 | B6: Intensive Care Unit | C6: F01 | D6: Critical Care | E6: Critical Care | F6: 20 | G6: 6130
A7: D140 | B7: Orthopedics & Spine | C7: F01 | D7: Orthopedics | E7: Inpatient | F7: 22 | G7: 6140
A8: D150 | B8: Oncology | C8: F01 | D8: Oncology | E8: Inpatient | F8: 18 | G8: 6150
A9: D160 | B9: Neuroscience & Stroke | C9: F01 | D9: Neuroscience | E9: Inpatient | F9: 16 | G9: 6160
A10: D170 | B10: Labor & Delivery | C10: F01 | D10: Women & Children | E10: Inpatient | F10: 20 | G10: 6170
A11: D180 | B11: Pediatrics | C11: F01 | D11: Women & Children | E11: Inpatient | F11: 14 | G11: 6180
A12: D190 | B12: Behavioral Health | C12: F01 | D12: Behavioral Health | E12: Inpatient | F12: 18 | G12: 6190
A13: D195 | B13: Observation Unit | C13: F01 | D13: Medicine | E13: Observation | F13: 12 | G13: 6195
A14: D196 | B14: Perioperative Services | C14: F01 | D14: Surgery | E14: Ancillary | G14: 6196
A15: D200 | B15: Emergency Department | C15: F02 | D15: Emergency | E15: Emergency | G15: 6200
A16: D210 | B16: Medical-Surgical | C16: F02 | D16: Medicine | E16: Inpatient | F16: 28 | G16: 6210
A17: D230 | B17: Intensive Care Unit | C17: F02 | D17: Critical Care | E17: Critical Care | F17: 8 | G17: 6230
A18: D270 | B18: Labor & Delivery | C18: F02 | D18: Women & Children | E18: Inpatient | F18: 10 | G18: 6270
A19: D300 | B19: Emergency Department | C19: F03 | D19: Emergency | E19: Emergency | G19: 6300
A20: D310 | B20: Medical-Surgical | C20: F03 | D20: Medicine | E20: Inpatient | F20: 30 | G20: 6310
A21: D320 | B21: Cardiac Step-Down | C21: F03 | D21: Cardiovascular | E21: Inpatient | F21: 16 | G21: 6320
A22: D330 | B22: Intensive Care Unit | C22: F03 | D22: Critical Care | E22: Critical Care | F22: 12 | G22: 6330
A23: D340 | B23: Orthopedics | C23: F03 | D23: Orthopedics | E23: Inpatient | F23: 14 | G23: 6340
A24: D400 | B24: Primary Care Clinic | C24: F04 | D24: Ambulatory | E24: Outpatient | G24: 6400
A25: D410 | B25: Cardiology Clinic | C25: F04 | D25: Cardiovascular | E25: Outpatient | G25: 6410
A26: D420 | B26: Orthopedic Clinic | C26: F04 | D26: Orthopedics | E26: Outpatient | G26: 6420
A27: D430 | B27: Infusion & Oncology Clinic | C27: F04 | D27: Oncology | E27: Outpatient | G27: 6430
A28: D440 | B28: Endocrinology & Diabetes Clinic | C28: F04 | D28: Ambulatory | E28: Outpatient | G28: 6440
A29: D450 | B29: Pediatric Clinic | C29: F04 | D29: Women & Children | E29: Outpatient | G29: 6450
A30: D500 | B30: Laboratory | C30: F01 | D30: Ancillary | E30: Ancillary | G30: 6500
A31: D510 | B31: Radiology | C31: F01 | D31: Ancillary | E31: Ancillary | G31: 6510
A32: D520 | B32: Pharmacy | C32: F01 | D32: Ancillary | E32: Ancillary | G32: 6520

Sheet Claims
A1: ClaimID | B1: EncounterID | C1: PayerID | D1: SubmitDate | E1: BilledAmount | F1: PaidAmount | G1: ClaimStatus | H1: DenialReason
A2: CLM510744 | B2: ENC110744 | C2: PY01 | D2: 45662 | E2: 48442.42 | F2: 13955.32 | G2: Paid
A3: CLM510776 | B3: ENC110776 | C3: PY05 | D3: 45661 | E3: 304.68 | F3: 128.86 | G3: Paid
A4: CLM510790 | B4: ENC110790 | C4: PY03 | D4: 45662 | E4: 1281.12 | F4: 324.23 | G4: Paid
A5: CLM510816 | B5: ENC110816 | C5: PY06 | D5: 45664 | E5: 413.97 | F5: 191.08 | G5: Paid
A6: CLM510831 | B6: ENC110831 | C6: PY02 | D6: 45666 | E6: 4715.78 | F6: 1576.43 | G6: Paid
A7: CLM510868 | B7: ENC110868 | C7: PY01 | D7: 45667 | E7: 1451.71 | F7: 401.85 | G7: Paid
A8: CLM510893 | B8: ENC110893 | C8: PY04 | D8: 45672 | E8: 276.25 | F8: 75.93 | G8: Partially Paid | H8: Coding Error
A9: CLM510900 | B9: ENC110900 | C9: PY04 | D9: 45673 | E9: 13917.66 | F9: 7630.44 | G9: Paid
A10: CLM510954 | B10: ENC110954 | C10: PY03 | D10: 45670 | E10: 22267.85 | F10: 5119.15 | G10: Paid
A11: CLM510967 | B11: ENC110967 | C11: PY06 | D11: 45673 | E11: 27045.66 | F11: 14232.83 | G11: Paid
A12: CLM510975 | B12: ENC110975 | C12: PY01 | D12: 45672 | E12: 29564.23 | F12: 9291.38 | G12: Paid
A13: CLM510989 | B13: ENC110989 | C13: PY01 | D13: 45667 | E13: 3793.84 | F13: 1085.27 | G13: Paid
A14: CLM511004 | B14: ENC111004 | C14: PY02 | D14: 45678 | E14: 9111.8 | F14: 1433.31 | G14: Partially Paid | H14: Coding Error
A15: CLM511012 | B15: ENC111012 | C15: PY06 | D15: 45674 | E15: 19563.2 | F15: 8552.32 | G15: Paid
A16: CLM511021 | B16: ENC111021 | C16: PY04 | D16: 45671 | E16: 1433.77 | F16: 677.28 | G16: Paid
A17: CLM511059 | B17: ENC111059 | C17: PY02 | D17: 45673 | E17: 1491.72 | F17: 456.37 | G17: Paid
A18: CLM511076 | B18: ENC111076 | C18: PY01 | D18: 45679 | E18: 1231.96 | F18: 322.82 | G18: Paid
A19: CLM511248 | B19: ENC111248 | C19: PY05 | D19: 45681 | E19: 1582.78 | F19: 695.66 | G19: Paid
A20: CLM511256 | B20: ENC111256 | C20: PY02 | D20: 45682 | E20: 5112.95 | F20: 1676.22 | G20: Paid
A21: CLM511322 | B21: ENC111322 | C21: PY01 | D21: 45684 | E21: 301.2 | F21: 100.08 | G21: Paid
A22: CLM511363 | B22: ENC111363 | C22: PY07 | D22: 45679 | E22: 1251.14 | F22: 0 | G22: Pending
A23: CLM511365 | B23: ENC111365 | C23: PY01 | D23: 45688 | E23: 832.97 | F23: 217.47 | G23: Paid
A24: CLM511373 | B24: ENC111373 | C24: PY01 | D24: 45679 | E24: 3103 | F24: 796.82 | G24: Paid
A25: CLM511390 | B25: ENC111390 | C25: PY01 | D25: 45686 | E25: 14358.29 | F25: 4242.44 | G25: Paid
A26: CLM511404 | B26: ENC111404 | C26: PY02 | D26: 45683 | E26: 814.6 | F26: 264.51 | G26: Paid
... A35: CLM511630 | B35: ENC111630 | C35: PY04 | D35: 45688 | E35: 23953.88 | F35: 12380.9 | G35: Paid
A36: CLM511635 | B36: ENC111635 | C36: PY04 | D36: 45691 | E36: 3205.92 | F36: 1085.22 | G36: Partially Paid | H36: Medical Necessity
A37: CLM511645 | B37: ENC111645 | C37: PY03 | D37: 45689 | E37: 464.35 | F37: 109.16 | G37: Paid
A38: CLM511653 | B38: ENC111653 | C38: PY07 | D38: 45690 | E38: 246.09 | F38: 30.75 | G38: Partially Paid
A39: CLM511655 | B39: ENC111655 | C39: PY01 | D39: 45690 | E39: 409.24 | F39: 119.72 | G39: Paid
A40: CLM511690 | B40: ENC111690 | C40: PY01 | D40: 45687 | E40: 380.08 | F40: 100.94 | G40: Paid
A41: CLM511703 | B41: ENC111703 | C41: PY01 | D41: 45695 | E41: 127.86 | F41: 31.53 | G41: Paid
A42: CLM511708 | B42: ENC111708 | C42: PY08 | D42: 45692 | E42: 215.19 | F42: 124.12 | G42: Paid
A43: CLM511747 | B43: ENC111747 | C43: PY03 | D43: 45690 | E43: 227.45 | F43: 57.11 | G43: Paid
A44: CLM511766 | B44: ENC111766 | C44: PY02 | D44: 45694 | E44: 18554.49 | F44: 0 | G44: Appealed | H44: Authorization Required
A45: CLM511800 | B45: ENC111800 | C45: PY03 | D45: 45690 | E45: 144.72 | F45: 34.93 | G45: Paid
A46: CLM511807 | B46: ENC111807 | C46: PY06 | D46: 45691 | E46: 481.8 | F46: 0 | G46: Appealed | H46: Authorization Required
A47: CLM511831 | B47: ENC111831 | C47: PY06 | D47: 45696 | E47: 6655.98 | F47: 2610.74 | G47: Partially Paid | H47: Medical Necessity
A48: CLM511870 | B48: ENC111870 | C48: PY02 | D48: 45706 | E48: 41069.82 | F48: 14729.1 | G48: Paid
...

Sheet Budget
A1: DeptID | B1: DeptName | C1: FacilityID | D1: Salaries & Wages | E1: Employee Benefits | F1: Medical Supplies | G1: Pharmaceuticals | H1: Purchased Services | I1: Equipment & Maintenance | J1: Other Operating
A2: D100 | B2: Emergency Department | C2: F01 | D2: 9935999 | E2: 2782078 | F2: 1391039 | G2: 894238 | H2: 1192324 | I2: 496801 | J2: 298078
A3: D110 | B3: Medical-Surgical 4 West | C3: F01 | D3: 7638296 | E3: 2138725 | F3: 1155058 | G3: 894238 | H3: 335340 | I3: 204932 | J3: 156490
A4: D111 | B4: Medical-Surgical 5 East | C4: F01 | D4: 6789599 | E4: 1901087 | F4: 1026721 | G4: 794879 | H4: 298078 | I4: 182159 | J4: 139101
A5: D120 | B5: Cardiac Step-Down | C5: F01 | D5: 5092199 | E5: 1425817 | F5: 770043 | G5: 596160 | H5: 223559 | I5: 136617 | J5: 104330
A6: D130 | B6: Intensive Care Unit | C6: F01 | D6: 6830999 | E6: 1912683 | F6: 1076397 | G6: 993601 | H6: 186301 | I6: 227700 | J6: 86941
A7: D140 | B7: Orthopedics & Spine | C7: F01 | D7: 4667854 | E7: 1306994 | F7: 705874 | G7: 546477 | H7: 204932 | I7: 125231 | J7: 95630
A8: D150 | B8: Oncology | C8: F01 | D8: 3819150 | E8: 1069366 | F8: 577526 | G8: 2328748 | H8: 167666 | I8: 102469 | J8: 78248
A9: D160 | B9: Neuroscience & Stroke | C9: F01 | D9: 3394798 | E9: 950543 | F9: 513357 | G9: 397438 | H9: 149039 | I9: 91083 | J9: 69552
A10: D170 | B10: Labor & Delivery | C10: F01 | D10: 4243502 | E10: 1188182 | F10: 641701 | G10: 496801 | H10: 186301 | I10: 113849 | J10: 86941
A11: D180 | B11: Pediatrics | C11: F01 | D11: 2970453 | E11: 831728 | F11: 449188 | G11: 347761 | H11: 130412 | I11: 79697 | J11: 60860
A12: D190 | B12: Behavioral Health | C12: F01 | D12: 3819150 | E12: 1069366 | F12: 577526 | G12: 447125 | H12: 167666 | I12: 102469 | J12: 78248
A13: D195 | B13: Observation Unit | C13: F01 | D13: 2546097 | E13: 712905 | F13: 385016 | G13: 298078 | H13: 111781 | I13: 68314 | J13: 52160
... A32: D520 | B32: Pharmacy | C32: F01 | D32: 3208501 | E32: 898380 | F32: 160426 | G32: 2069999 | H32: 320847 | I32: 192510 | J32: 96253

Sheet BMITiers
A1: MinBMI | B1: Category | C1: BMIRange
A2: 0 | B2: Underweight | C2: Below 18.5
A3: 18.5 | B3: Healthy weight | C3: 18.5 to under 25
A4: 25 | B4: Overweight | C4: 25 to under 30
A5: 30 | B5: Obesity class 1 | C5: 30 to under 35
A6: 35 | B6: Obesity class 2 | C6: 35 to under 40
A7: 40 | B7: Obesity class 3 | C7: 40 and above

Sheet AgeBands
A1: MinAge | B1: AgeBand
A2: 0 | B2: 0-17
A3: 18 | B3: 18-44
A4: 45 | B4: 45-64
A5: 65 | B5: 65-74
A6: 75 | B6: 75-84
A7: 85 | B7: 85+

Sheet Bonus
A1: Lesson 2.6 · Bonus: An encounter lookup card
A2: Dr. Nguyen's care manager answers the same questions all day: who is this encounter's patient, how old were they, what were they treated for, who was the attending, who pays, and where does the claim stand? Build a reusable lookup card on the Card sheet. Each card is one column: it takes an EncounterID in row 5 and returns ten facts in rows 6 to 15. Rows 6 and 7 are helper cells (PatientID and Attending ProviderID) that the other rows reuse. Card 1 (column B) holds ENC117295. Card 2 (column C) holds ENC119O88, an ID copied from a handwritten note, and every row of Card 2 must show Not found instead of an error. Write every formula in column B, then copy B6:B15 and paste it into C6:C15. Refer to the ID as B$5, with no $ before the B, so it becomes C$5 in column C. The $ before the 5 keeps it on row 5 if you copy a formula down to start the next row. Use Copy (Ctrl + C, Mac: ⌘ + C) and Paste (Ctrl + V, Mac: ⌘ + V) rather than dragging the fill handle, because dragging to the right shifts Table references such as tblEncounters[PatientID] to the next Table column. Keep both IDs in place while you check your answers. The gray cells on the Bonus sheet read your card.
A3: Type a formula or value in each yellow cell. The Check column turns green when your answer matches. Stuck? Read the hint, then the lesson guide. Answers: right-click a sheet tab → Unhide… → 'Bonus Key'.
A4: ="Score: "&COUNTIF(E6:E10,"✔*")&" of 5 auto-checked tasks correct"
A5: # | B5: Task | C5: Hint | D5: Your Answer | E5: Check
A6: B1 | B6: Card 1 (ENC117295): what does your Patient name row (Card!B8) show? Format: First Last. | C6: Chain two lookups: first EncounterID to PatientID (row 6), then PatientID to the names. Join them with &" "& | D6: {=IF(Card!B8="","",Card!B8)} | E6: =IF(IFERROR(D6="",FALSE),"",IF(IFERROR(OR(LOWER(TRIM(D6&""))=LOWER(TRIM('Bonus Key'!$C$5&""))),FALSE),"✔ Correct","✘ Not yet"))
A7: B2 | B7: Card 1: how old was the patient, in completed years, on the encounter's AdmitDate (Card!B9)? | C7: Look up DOB and AdmitDate, then DATEDIF(…, …, "Y") from Lesson 2.3 | D7: {=IF(Card!B9="","",Card!B9)} | E7: =IF(IFERROR(D7="",FALSE),"",IF(IFERROR(AND(ISNUMBER(D7),OR(ABS(D7-'Bonus Key'!$C$6)<=0.0001)),FALSE),"✔ Correct","✘ Not yet"))
A8: B3 | B8: Card 1: what does your Attending row (Card!B12) show? Format: First Last, Credential (for example, Isabella Nguyen, MD). | C8: Use the Attending ProviderID helper in row 7, three lookups, and & to join them | D8: {=IF(Card!B12="","",Card!B12)} | E8: =IF(IFERROR(D8="",FALSE),"",IF(IFERROR(OR(LOWER(TRIM(D8&""))=LOWER(TRIM('Bonus Key'!$C$7&""))),FALSE),"✔ Correct","✘ Not yet"))
A9: B4 | B9: Card 1: what is the claim status (Card!B15)? Claims are matched by EncounterID, which is column B of the Claims sheet. | C9: XLOOKUP can search any column. VLOOKUP would need its table to start at column B | D9: {=IF(Card!B15="","",Card!B15)} | E9: =IF(IFERROR(D9="",FALSE),"",IF(IFERROR(OR(LOWER(TRIM(D9&""))=LOWER(TRIM('Bonus Key'!$C$8&""))),FALSE),"✔ Correct","✘ Not yet"))
A10: B5 | B10: Card 2 (ENC119O88): how many of the ten output rows (Card!C6:C15) show exactly Not found? All ten should. If any shows #N/A or #VALUE!, fix that row's formula in column B and copy it to column C again. | C10: Give every lookup an if_not_found, and let IF skip calculations (like DATEDIF) when the helper cell says Not found | D10: {=IF(COUNTA(Card!C6:C15)=0,"",COUNTIF(Card!C6:C15,"Not found"))} | E10: =IF(IFERROR(D10="",FALSE),"",IF(IFERROR(AND(ISNUMBER(D10),OR(ABS(D10-'Bonus Key'!$C$9)<=0.0001)),FALSE),"✔ Correct","✘ Not yet"))

Sheet Card
A1: Encounter lookup card
A2: Type one formula in each yellow cell of column B (B6:B15) and refer to the ID as B$5. Then copy B6:B15 (Ctrl + C, Mac: ⌘ + C) and paste it into C6:C15 (Ctrl + V, Mac: ⌘ + V). B$5 becomes C$5, and Copy and Paste keeps Table references such as tblEncounters[PatientID] on the same column (dragging the fill handle to the right would shift them). Every Card 2 cell must show Not found. The gray cells on the Bonus sheet check your card.
A4: Field | B4: Card 1 | C4: Card 2 | D4: Where it comes from
A5: EncounterID | B5: ENC117295 | C5: ENC119O88 | D5: Input: keep both IDs while you check the bonus
A6: PatientID | D6: Encounters (helper cell)
A7: Attending ProviderID | D7: Encounters (helper cell)
A8: Patient name (First Last) | D8: Patients, via row 6
A9: Age at admission (years) | D9: Patients DOB + Encounters AdmitDate
A10: Primary diagnosis | D10: Encounters → Diagnoses
A11: Unit (department) | D11: Encounters → Departments
A12: Attending (First Last, Credential) | D12: Providers, via row 7
A13: Attending specialty | D13: Providers, via row 7
A14: Payer | D14: Encounters → Payers
A15: Claim status | D15: Claims (search the EncounterID column)

Sheet Answer Key
A1: 🔑 Answer Key — Lesson 2.6
A2: Spoiler alert: try every task before reading this sheet. Column C is the value the Check column compares against. Column D is a sample solution, and column E recalculates a formula for it live, proving the answer.
A4: # | B4: Task | C4: Answer | D4: Sample solution | E4: Live result | F4: Explanation
A5: 1 | B5: Encounter ENC110900 is on row 9 of the Encounters sheet. Use VLOOKUP with its PatientID (cell Encounters!B9) to return the patient's last name from the Patients sheet. | C5: Robertson | D5: =VLOOKUP(Encounters!B9,Patients!$A$2:$K$186,4,FALSE) | E5: {=VLOOKUP(Encounters!B9,Patients!$A$2:$K$186,4,FALSE)} | F5: VLOOKUP searches the first column of the table (PatientID) for the ID, then returns the value from the 4th column of the same row: PatientID, MRN, FirstName, LastName. FALSE asks for an exact match, which is what you want for any ID.
A6: 2 | B6: Encounter ENC111256 (Encounters row 20) was billed to payer PY02. Use VLOOKUP on the Payers sheet to return the payer's PayerType. | C6: Medicare Advantage | D6: =VLOOKUP(Encounters!I20,Payers!$A$2:$F$9,3,FALSE) | E6: {=VLOOKUP(Encounters!I20,Payers!$A$2:$F$9,3,FALSE)} | F6: PayerType is the 3rd column of Payers (PayerID, PayerName, PayerType). The payer's name, Silverline Medicare Advantage, contains the word Medicare, but its type is Medicare Advantage, a private plan that contracts with Medicare. That difference matters for billing rules, which is why reports look up the type instead of guessing it from the name.
A7: 3 | B7: Encounter ENC113996 (Encounters row 150) has primary diagnosis code E11.65. Use XLOOKUP to return its description from the Diagnoses sheet. | C7: Type 2 diabetes mellitus with hyperglycemia | D7: =XLOOKUP(Encounters!H150,Diagnoses!$A$2:$A$52,Diagnoses!$B$2:$B$52) | E7: {=_xlfn.XLOOKUP(Encounters!H150,Diagnoses!$A$2:$A$52,Diagnoses!$B$2:$B$52)} | F7: XLOOKUP takes two separate columns, one to search and one to return, so there's no column number to count. It also defaults to an exact match, so you can't forget the FALSE that VLOOKUP needs.
A8: 4 | B8: Who attended encounter ENC112339 (Encounters row 73)? Use INDEX and MATCH with its AttendingProviderID to return the provider's Specialty from the Providers sheet. | C8: Pulmonary & Critical Care | D8: =INDEX(Providers!$E$2:$E$148,MATCH(Encounters!G73,Providers!$A$2:$A$148,0)) | E8: {=INDEX(Providers!$E$2:$E$148,MATCH(Encounters!G73,Providers!$A$2:$A$148,0))} | F8: MATCH finds the position of the ProviderID in the ProviderID column (the 0 means exact match). INDEX then returns the item at that same position in the Specialty column. Because the two columns are separate arguments, INDEX/MATCH works in every Excel version and doesn't care where the columns sit.
A9: 5 | B9: Fill the yellow PayerName column on the Encounters sheet with a lookup that returns each encounter's payer name (start in K2 and copy down to row 530). The gray cell counts how many encounters your column shows as exactly "Medicare". | C9: 120 | D9: =XLOOKUP(I2,Payers!$A$2:$A$9,Payers!$B$2:$B$9) | E9: {=COUNTIF(Encounters!$I$2:$I$530,"PY01")} | F9: This is the everyday use of a lookup: adding a readable column to an ID-only extract. The $ signs keep the Payers ranges fixed while the lookup value (I2, then I3, …) moves down a row at a time. =VLOOKUP(I2,Payers!$A$2:$F$9,2,FALSE) works just as well. COUNTIF with "Medicare" counts exact matches only, so Silverline Medicare Advantage isn't included.
A10: 6 | B10: Patient PT10395 is on Patients row 21, and the Age column shows 75. Use VLOOKUP with an approximate match (TRUE) on the AgeBands sheet to return the patient's age band. | C10: 75-84 | D10: =VLOOKUP(Patients!G21,AgeBands!$A$2:$B$7,2,TRUE) | E10: {=VLOOKUP(Patients!G21,AgeBands!$A$2:$B$7,2,TRUE)} | F10: With TRUE, VLOOKUP looks for the largest MinAge that is less than or equal to 75. MinAge 75 qualifies, and the next one (85) is too big, so the answer is the 75-84 band. A value exactly on a boundary belongs to the band that starts there. That's why a tier table lists each band's lower bound, sorted smallest to largest.
A11: 7 | B11: Fill the yellow BMICategory column on the Patients sheet: look up each patient's BMI in the BMITiers table with an approximate match (start in L2 and copy down to row 186). The gray cell counts patients in any obesity class (BMI 30 or higher). | C11: 82 | D11: =VLOOKUP(J2,BMITiers!$A$2:$B$7,2,TRUE) | E11: {=COUNTIF(Patients!$J$2:$J$186,">=30")} | F11: Each BMI falls between two lower bounds in BMITiers, and the approximate match returns the tier whose lower bound is the largest one at or below the BMI. 5 patients sit exactly on a boundary (25.0 or 30.0) and correctly land in the higher tier. The XLOOKUP version is =XLOOKUP(J2,BMITiers!$A$2:$A$7,BMITiers!$B$2:$B$7,,-1). The panel has 41 patients in class 1, 28 in class 2, and 13 in class 3.
A12: 8 | B12: The lab's interface file sent a result for MRN 50339. It arrived as a number, so its leading zeros were dropped, but the Patients sheet stores MRNs as 8-character text. Return the PatientID for this MRN. (PatientID is to the left of MRN, so VLOOKUP can't do it.) | C12: PT11047 | D12: =XLOOKUP(TEXT(50339,"00000000"),Patients!$B$2:$B$186,Patients!$A$2:$A$186) | E12: {=_xlfn.XLOOKUP(TEXT(50339,"00000000"),Patients!$B$2:$B$186,Patients!$A$2:$A$186)} | F12: Looking up the number 50339 returns #N/A, because a number never equals the text "00050339". TEXT(…,"00000000") pads it back to 8 characters as text, and then the match works. The INDEX/MATCH version is =INDEX(Patients!$A$2:$A$186,MATCH(TEXT(50339,"00000000"),Patients!$B$2:$B$186,0)). Both can return a column to the left of the one they search.
A13: 9 | B13: A clinic note mentions "osteoarthritis of the right knee." Use a wildcard lookup to return the DxCode whose DxDescription contains the word knee. | C13: M17.11 | D13: =XLOOKUP("*knee*",Diagnoses!$B$2:$B$52,Diagnoses!$A$2:$A$52,,2) | E13: {=_xlfn.XLOOKUP("*knee*",Diagnoses!$B$2:$B$52,Diagnoses!$A$2:$A$52,,2)} | F13: The asterisk stands for any number of characters, so "knee" matches "Unilateral primary osteoarthritis, right knee". XLOOKUP only uses wildcards when match_mode is 2. MATCH with match_type 0 uses them automatically: =INDEX(Diagnoses!$A$2:$A$52,MATCH("knee",Diagnoses!$B$2:$B$52,0)). If several descriptions matched, you'd get the first one.
A14: 10 | B14: Two-way lookup: on the Budget sheet, what is the 2025 Pharmaceuticals budget for department D130 (Intensive Care Unit at Bluestone Memorial Hospital)? Find the row by DeptID and the column by category name. | C14: 993601 | D14: =INDEX(Budget!$D$2:$J$32,MATCH("D130",Budget!$A$2:$A$32,0),MATCH("Pharmaceuticals",Budget!$D$1:$J$1,0)) | E14: {=INDEX(Budget!$D$2:$J$32,MATCH("D130",Budget!$A$2:$A$32,0),MATCH("Pharmaceuticals",Budget!$D$1:$J$1,0))} | F14: The first MATCH finds the department's row inside the grid and the second finds the category's column in the header row. INDEX returns the cell where they cross. The nested XLOOKUP version is =XLOOKUP("D130",Budget!$A$2:$A$32,XLOOKUP("Pharmaceuticals",Budget!$D$1:$J$1,Budget!$D$2:$J$32)): the inner XLOOKUP returns the whole Pharmaceuticals column, and the outer one picks the department's row from it. Look up by DeptID, not DeptName. Three facilities each have an "Intensive Care Unit", and a lookup on that name would return only the first one.
A15: 11 | B15: What is the TOTAL 2025 expense budget (all seven categories) for department D400, Primary Care Clinic, where Dr. Nguyen practices? Use one lookup that returns the department's whole row of the grid, wrapped in SUM. | C15: 5348882 | D15: =SUM(XLOOKUP("D400",Budget!$A$2:$A$32,Budget!$D$2:$J$32)) | E15: {=SUM(_xlfn.XLOOKUP("D400",Budget!$A$2:$A$32,Budget!$D$2:$J$32))} | F15: When return_array is seven columns wide, XLOOKUP returns all seven values from the matching row, and SUM adds them. On its own in an empty cell the same XLOOKUP would spill across seven cells. INDEX can do this too, because a column number of 0 means "the whole row": =SUM(INDEX(Budget!$D$2:$J$32,MATCH("D400",Budget!$A$2:$A$32,0),0)).
A16: 12 | B16: Patient PT13163 visited more often than anyone else on the panel (11 encounters in 2025). The Encounters sheet is sorted oldest to newest. Use XLOOKUP searching from the bottom up to return the AdmitDate of this patient's most recent encounter. | C16: 46020 | D16: =XLOOKUP("PT13163",Encounters!$B$2:$B$530,Encounters!$D$2:$D$530,,0,-1) | E16: {=_xlfn.XLOOKUP("PT13163",Encounters!$B$2:$B$530,Encounters!$D$2:$D$530,,0,-1)} | F16: A normal lookup stops at the first match, which here is the oldest encounter (01/19/2025). search_mode -1 starts at the bottom, so the first match it meets is the most recent row. If the result shows a number like 46020, format the cell as a date. =MAXIFS(…) (Lesson 2.5) gives the same date, but only the lookup can return other columns from that row, like its EncounterID or diagnosis.
A17: 13 | B17: The Referrals sheet lists 24 referrals received in December. Fill its yellow PatientID column by looking up each MRN in the Patients sheet (start in G2 and copy down to row 25). Patients who aren't on the panel yet must show the text Not found instead of #N/A. The gray cell counts the Not found rows. | C17: 7 | D17: =XLOOKUP(C2,Patients!$B$2:$B$186,Patients!$A$2:$A$186,"Not found") | E17: {=SUMPRODUCT(--ISNA(MATCH(Referrals!$C$2:$C$25,Patients!$B$2:$B$186,0)))} | F17: XLOOKUP's if_not_found argument replaces #N/A with your own text, but only when the lookup really finds nothing. The older equivalent is =IFNA(INDEX(Patients!$A$2:$A$186,MATCH(C2,Patients!$B$2:$B$186,0)),"Not found"). Prefer IFNA to IFERROR here. IFERROR would also hide a #REF! or #NAME? caused by a broken formula, and you'd never know. The 7 Not found rows are new patients for the practice to register.

Sheet Bonus Key
A1: 🔑 Bonus Key — Lesson 2.6
A2: Spoiler alert: try every task before reading this sheet. Column C is the value the Check column compares against. Column D is a sample solution, and column E recalculates a formula for it live, proving the answer.
A4: # | B4: Task | C4: Answer | D4: Sample solution | E4: Live result | F4: Explanation
A5: B1 | B5: Card 1 (ENC117295): what does your Patient name row (Card!B8) show? Format: First Last. | C5: Carlos Ortiz | D5: =IF(B6="Not found","Not found",XLOOKUP(B6,Patients!$A$2:$A$186,Patients!$C$2:$C$186)&" "&XLOOKUP(B6,Patients!$A$2:$A$186,Patients!$D$2:$D$186)) | E5: {=_xlfn.XLOOKUP(_xlfn.XLOOKUP("ENC117295",Encounters!$A$2:$A$530,Encounters!$B$2:$B$530),Patients!$A$2:$A$186,Patients!$C$2:$C$186)&" "&_xlfn.XLOOKUP(_xlfn.XLOOKUP("ENC117295",Encounters!$A$2:$A$530,Encounters!$B$2:$B$530),Patients!$A$2:$A$186,Patients!$D$2:$D$186)} | F5: Row 6 does the first hop, from EncounterID to PatientID, once, and every patient row reuses it. Chaining through a helper cell keeps each formula short and lets you check each hop on its own. The IF in front returns Not found when row 6 already says so, which keeps Card 2 clean.
A6: B2 | B6: Card 1: how old was the patient, in completed years, on the encounter's AdmitDate (Card!B9)? | C6: 78 | D6: =IF(B6="Not found","Not found",DATEDIF(XLOOKUP(B6,Patients!$A$2:$A$186,Patients!$F$2:$F$186),XLOOKUP(B$5,Encounters!$A$2:$A$530,Encounters!$D$2:$D$530),"Y")) | E6: {=DATEDIF(_xlfn.XLOOKUP(_xlfn.XLOOKUP("ENC117295",Encounters!$A$2:$A$530,Encounters!$B$2:$B$530),Patients!$A$2:$A$186,Patients!$F$2:$F$186),_xlfn.XLOOKUP("ENC117295",Encounters!$A$2:$A$530,Encounters!$D$2:$D$530),"Y")} | F6: DATEDIF with "Y" counts completed years. The patient was born on 09/18/1946 and admitted on 08/01/2025, 48 days before turning 79, so the answer is 78. YEAR(admit) − YEAR(DOB) would give 79, which is one year too old. The DOB comes from Patients (via row 6) and the AdmitDate from Encounters (via row 5), so this one formula reads two different tables.
A7: B3 | B7: Card 1: what does your Attending row (Card!B12) show? Format: First Last, Credential (for example, Isabella Nguyen, MD). | C7: Judith Cox, DO | D7: =IF(B7="Not found","Not found",XLOOKUP(B7,Providers!$A$2:$A$148,Providers!$B$2:$B$148)&" "&XLOOKUP(B7,Providers!$A$2:$A$148,Providers!$C$2:$C$148)&", "&XLOOKUP(B7,Providers!$A$2:$A$148,Providers!$D$2:$D$148)) | E7: {=_xlfn.XLOOKUP(_xlfn.XLOOKUP("ENC117295",Encounters!$A$2:$A$530,Encounters!$G$2:$G$530),Providers!$A$2:$A$148,Providers!$B$2:$B$148)&" "&_xlfn.XLOOKUP(_xlfn.XLOOKUP("ENC117295",Encounters!$A$2:$A$530,Encounters!$G$2:$G$530),Providers!$A$2:$A$148,Providers!$C$2:$C$148)&", "&_xlfn.XLOOKUP(_xlfn.XLOOKUP("ENC117295",Encounters!$A$2:$A$530,Encounters!$G$2:$G$530),Providers!$A$2:$A$148,Providers!$D$2:$D$148)} | F7: Three lookups on the same ProviderID return FirstName, LastName, and Credential, and & glues them together with a space and a comma. Showing the credential is safer than putting "Dr." in front of every name, because some attendings are nurse practitioners (NP) or physician assistants (PA). Judith Cox is a DO, a doctor of osteopathic medicine.
A8: B4 | B8: Card 1: what is the claim status (Card!B15)? Claims are matched by EncounterID, which is column B of the Claims sheet. | C8: Denied | D8: =XLOOKUP(B$5,Claims!$B$2:$B$530,Claims!$G$2:$G$530,"Not found") | E8: {=_xlfn.XLOOKUP("ENC117295",Claims!$B$2:$B$530,Claims!$G$2:$G$530)} | F8: The Claims key is ClaimID, but the card knows only the EncounterID. XLOOKUP searches the EncounterID column wherever it is. With VLOOKUP you'd start the table at column B: =VLOOKUP(B$5,Claims!$B$2:$H$530,6,FALSE). This claim was denied (Authorization Required), so it goes on the care manager's follow-up list.
A9: B5 | B9: Card 2 (ENC119O88): how many of the ten output rows (Card!C6:C15) show exactly Not found? All ten should. If any shows #N/A or #VALUE!, fix that row's formula in column B and copy it to column C again. | C9: 10 | D9: =XLOOKUP(B$5,Encounters!$A$2:$A$530,Encounters!$B$2:$B$530,"Not found") | E9: {=IF(ISNA(MATCH("ENC119O88",Encounters!$A$2:$A$530,0)),10,0)} | F9: ENC119O88 contains the letter O where the real ID ENC119088 has a zero. To Excel they're different text, so every lookup comes back empty-handed. That's the most common reason a lookup fails on data that looks right. The sample solution shown is row 6. Three techniques make the whole card fail politely: 1. Every XLOOKUP gets an if_not_found of "Not found". 2. Chained lookups pass "Not found" along. The inner XLOOKUP returns it, and the outer one can't find a DxCode called "Not found", so it returns its own "Not found". 3. Rows that join or calculate (the two name rows and the age row) test their helper cell first with IF(B6="Not found","Not found",…). Without that test, DATEDIF of the text "Not found" returns #VALUE!. A name join would show #N/A, or "Not found Not found" if each of its lookups had its own if_not_found. Your finished card should match this: | Row | Field | Card 1 (ENC117295) | Card 2 (ENC119O88) | |:-:|---|---|---| | 6 | PatientID | PT12752 | Not found | | 7 | Attending ProviderID | PRV1030 | Not found | | 8 | Patient name (First Last) | Carlos Ortiz | Not found | | 9 | Age at admission (years) | 78 | Not found | | 10 | Primary diagnosis | Chronic obstructive pulmonary disease with (acute) exacerbation | Not found | | 11 | Unit (department) | Medical-Surgical 4 West | Not found | | 12 | Attending (First Last, Credential) | Judith Cox, DO | Not found | | 13 | Attending specialty | Hospital Medicine | Not found | | 14 | Payer | Silverline Medicare Advantage | Not found | | 15 | Claim status | Denied | Not found | Every formula on the card (type them in column B, then copy them to column C): - Row 6 · PatientID: =XLOOKUP(B$5,Encounters!$A$2:$A$530,Encounters!$B$2:$B$530,"Not found") - Row 7 · Attending ProviderID: =XLOOKUP(B$5,Encounters!$A$2:$A$530,Encounters!$G$2:$G$530,"Not found") - Row 8 · Patient name (First Last): =IF(B6="Not found","Not found",XLOOKUP(B6,Patients!$A$2:$A$186,Patients!$C$2:$C$186)&" "&XLOOKUP(B6,Patients!$A$2:$A$186,Patients!$D$2:$D$186)) - Row 9 · Age at admission (years): =IF(B6="Not found","Not found",DATEDIF(XLOOKUP(B6,Patients!$A$2:$A$186,Patients!$F$2:$F$186),XLOOKUP(B$5,Encounters!$A$2:$A$530,Encounters!$D$2:$D$530),"Y")) - Row 10 · Primary diagnosis: =XLOOKUP(XLOOKUP(B$5,Encounters!$A$2:$A$530,Encounters!$H$2:$H$530,"Not found"),Diagnoses!$A$2:$A$52,Diagnoses!$B$2:$B$52,"Not found") - Row 11 · Unit (department): =XLOOKUP(XLOOKUP(B$5,Encounters!$A$2:$A$530,Encounters!$F$2:$F$530,"Not found"),Departments!$A$2:$A$32,Departments!$B$2:$B$32,"Not found") - Row 12 · Attending (First Last, Credential): =IF(B7="Not found","Not found",XLOOKUP(B7,Providers!$A$2:$A$148,Providers!$B$2:$B$148)&" "&XLOOKUP(B7,Providers!$A$2:$A$148,Providers!$C$2:$C$148)&", "&XLOOKUP(B7,Providers!$A$2:$A$148,Providers!$D$2:$D$148)) - Row 13 · Attending specialty: =XLOOKUP(B7,Providers!$A$2:$A$148,Providers!$E$2:$E$148,"Not found") - Row 14 · Payer: =XLOOKUP(XLOOKUP(B$5,Encounters!$A$2:$A$530,Encounters!$I$2:$I$530,"Not found"),Payers!$A$2:$A$9,Payers!$B$2:$B$9,"Not found") - Row 15 · Claim status: =XLOOKUP(B$5,Claims!$B$2:$B$530,Claims!$G$2:$G$530,"Not found")
