Workbook

Sheet Start Here
B2: Lesson 1.4
B3: Your First Formulas & Functions
B4: Beginner · about 45 minutes · Bluestone Health System (fictional)
B6: What you'll learn
B7: • | C7: Write formulas with operators and the correct order of operations
B8: • | C8: Use SUM, AVERAGE, MIN, MAX, COUNT, COUNTA, and COUNTBLANK
B9: • | C9: Calculate rates and percentages such as bed occupancy
B10: • | C10: Copy formulas down a column and read common errors (#DIV/0!, #NAME?, #VALUE!)
B11: • | C11: Round results with ROUND
B13: How to use this workbook
B14: 1. Read the guide | C14: The lesson guide (README) explains each skill with examples: https://github.com/lmansf/learn-excel/tree/main/01-foundations/04-basic-formulas
B15: 2. Practice | C15: Go to the 'Practice' sheet. Type a formula or value into each yellow cell.
B16: 3. Check yourself | C16: The Check column shows ✔ Correct (green) or ✘ Not yet (red). Tasks marked 'See key' are checked by comparing with the answer key.
B17: 4. Bonus | C17: Finished? Try the harder 'Bonus' sheet.
B18: 5. Answers | C18: The 'Answer Key' and 'Bonus Key' sheets are hidden. Right-click any sheet tab → Unhide… → pick one → OK. (Try first!)
B20: Color legend
B21: Yellow cell | C21: Your answer goes here.
B22: Gray cell | C22: Pre-filled summary formula — it reads the work you did on another sheet.
B23: ✔ Correct | C23: Your answer matches the key.
B24: ✘ Not yet | C24: Not matching yet — check the hint and try again.
B26: Sheets in this workbook
B27: Census | C27: Data: 90 rows — Excel Table 'tblCensus'
B28: Supplies | C28: Data: 14 rows — Excel Table 'tblSupplies'
B29: About the data | C29: Daily census for Medical-Surgical 4 West at Bluestone Memorial Hospital, Jan–Mar 2025 (90 days), plus the unit's supply room stock.
B30: Disclaimer | C30: All people, places, and numbers are synthetic and fictional. Not clinical guidance.

Sheet Practice
A1: Lesson 1.4 · Practice
A2: All tasks use the Census sheet (4 West, Q1 2025) unless they say otherwise. Use cell ranges like Census!C2:C91 — or click and drag to select them while typing a formula.
A3: Type a formula or value in each yellow cell. The Check column turns green when your answer matches. Stuck? Read the hint, then the lesson guide. Answers: right-click a sheet tab → Unhide… → 'Answer Key'.
A4: ="Score: "&COUNTIF(E6:E18,"✔*")&" of 13 auto-checked tasks correct"
A5: # | B5: Task | C5: Hint | D5: Your Answer | E5: Check
A6: 1 | B6: How many patients were admitted to 4 West during the quarter (total of the Admissions column)? | C6: SUM | E6: =IF(IFERROR(D6="",FALSE),"",IF(IFERROR(AND(ISNUMBER(D6),OR(ABS(D6-'Answer Key'!$C$5)<=0.0001)),FALSE),"✔ Correct","✘ Not yet"))
A7: 2 | B7: What was the average midnight census? (Keep full precision — the check accepts 2 decimal places.) | C7: AVERAGE | E7: =IF(IFERROR(D7="",FALSE),"",IF(IFERROR(AND(ISNUMBER(D7),OR(ABS(D7-'Answer Key'!$C$6)<=0.0051)),FALSE),"✔ Correct","✘ Not yet"))
A8: 3 | B8: What was the highest midnight census on any day? | C8: MAX | E8: =IF(IFERROR(D8="",FALSE),"",IF(IFERROR(AND(ISNUMBER(D8),OR(ABS(D8-'Answer Key'!$C$7)<=0.0001)),FALSE),"✔ Correct","✘ Not yet"))
A9: 4 | B9: What was the lowest midnight census on any day? | C9: MIN | E9: =IF(IFERROR(D9="",FALSE),"",IF(IFERROR(AND(ISNUMBER(D9),OR(ABS(D9-'Answer Key'!$C$8)<=0.0001)),FALSE),"✔ Correct","✘ Not yet"))
A10: 5 | B10: How many days of census data are there? Count the dates in the CensusDate column. | C10: COUNT counts numbers — and dates are numbers | E10: =IF(IFERROR(D10="",FALSE),"",IF(IFERROR(AND(ISNUMBER(D10),OR(ABS(D10-'Answer Key'!$C$9)<=0.0001)),FALSE),"✔ Correct","✘ Not yet"))
A11: 6 | B11: On how many days did the charge nurse write a note? | C11: COUNTA counts anything that isn't empty | E11: =IF(IFERROR(D11="",FALSE),"",IF(IFERROR(AND(ISNUMBER(D11),OR(ABS(D11-'Answer Key'!$C$10)<=0.0001)),FALSE),"✔ Correct","✘ Not yet"))
A12: 7 | B12: On how many days was the Notes cell left empty? | C12: COUNTBLANK | E12: =IF(IFERROR(D12="",FALSE),"",IF(IFERROR(AND(ISNUMBER(D12),OR(ABS(D12-'Answer Key'!$C$11)<=0.0001)),FALSE),"✔ Correct","✘ Not yet"))
A13: 8 | B13: Patient days = the sum of every day's midnight census. How many patient days did 4 West provide in Q1? | C13: It's a SUM | E13: =IF(IFERROR(D13="",FALSE),"",IF(IFERROR(AND(ISNUMBER(D13),OR(ABS(D13-'Answer Key'!$C$12)<=0.0001)),FALSE),"✔ Correct","✘ Not yet"))
A14: 9 | B14: What was the unit's occupancy rate for the whole quarter? Divide total patient days by total staffed-bed days. Enter it as a percentage. | C14: SUM(…)/SUM(…), then format as % | E14: =IF(IFERROR(D14="",FALSE),"",IF(IFERROR(AND(ISNUMBER(D14),OR(ABS(D14-'Answer Key'!$C$13)<=0.00051,ABS(D14-'Answer Key'!$C$13*100)<=0.051000000000000004)),FALSE),"✔ Correct","✘ Not yet"))
A15: 10 | B15: In the Census sheet, fill the yellow Occupancy column with a formula for each day (MidnightCensus ÷ StaffedBeds). The gray cell counts the days your column shows 100% or more. (Type it in G2, then double-click the fill handle to copy it down.) | C15: Relative references shift down as you copy | D15: {=IF(COUNT(Census!G2:G91)=0,"",COUNTIF(Census!G2:G91,">=1"))} | E15: =IF(IFERROR(D15="",FALSE),"",IF(IFERROR(AND(ISNUMBER(D15),OR(ABS(D15-'Answer Key'!$C$14)<=0.0001)),FALSE),"✔ Correct","✘ Not yet"))
A16: 11 | B16: Average length of stay (ALOS) = patient days ÷ discharges. Calculate it for the quarter, rounded to 1 decimal place with ROUND. | C16: ROUND(number, 1) | E16: =IF(IFERROR(D16="",FALSE),"",IF(IFERROR(AND(ISNUMBER(D16),OR(ABS(D16-'Answer Key'!$C$15)<=0.0001)),FALSE),"✔ Correct","✘ Not yet"))
A17: 12 | B17: Without typing it into Excel first, what does =(30-6)/4+2^3 return? Then type it to confirm. | C17: Parentheses → exponents → × ÷ → + − | E17: =IF(IFERROR(D17="",FALSE),"",IF(IFERROR(AND(ISNUMBER(D17),OR(ABS(D17-'Answer Key'!$C$16)<=0.0051)),FALSE),"✔ Correct","✘ Not yet"))
A18: 13 | B18: Switch to the Supplies sheet. Fill the yellow StockValue column with UnitCost × QtyOnHand for every item. The gray cell totals your column — what is the total value of 4 West's supply room? | C18: Multiply with *; copy down | D18: {=IF(COUNT(Supplies!G2:G15)=0,"",SUM(Supplies!G2:G15))} | E18: =IF(IFERROR(D18="",FALSE),"",IF(IFERROR(AND(ISNUMBER(D18),OR(ABS(D18-'Answer Key'!$C$17)<=0.0051)),FALSE),"✔ Correct","✘ Not yet"))

Sheet Census
A1: CensusDate | B1: StaffedBeds | C1: Admissions | D1: Discharges | E1: MidnightCensus | F1: Notes | G1: Occupancy
A2: 45658 | B2: 36 | C2: 6 | D2: 7 | E2: 33
A3: 45659 | B3: 36 | C3: 14 | D3: 12 | E3: 35
A4: 45660 | B4: 36 | C4: 8 | D4: 10 | E4: 33
A5: 45661 | B5: 36 | C5: 5 | D5: 7 | E5: 31
A6: 45662 | B6: 36 | C6: 3 | D6: 2 | E6: 32 | F6: 1 RN call-off; covered by float pool
A7: 45663 | B7: 36 | C7: 8 | D7: 7 | E7: 33
A8: 45664 | B8: 36 | C8: 12 | D8: 10 | E8: 35
A9: 45665 | B9: 36 | C9: 4 | D9: 4 | E9: 35 | F9: Isolation room deep-clean
A10: 45666 | B10: 36 | C10: 15 | D10: 15 | E10: 35
A11: 45667 | B11: 36 | C11: 10 | D11: 10 | E11: 35
A12: 45668 | B12: 36 | C12: 10 | D12: 10 | E12: 35
A13: 45669 | B13: 36 | C13: 8 | D13: 8 | E13: 35
A14: 45670 | B14: 36 | C14: 17 | D14: 17 | E14: 35
A15: 45671 | B15: 36 | C15: 12 | D15: 12 | E15: 35 | F15: 1 RN call-off; covered by float pool
A16: 45672 | B16: 36 | C16: 5 | D16: 4 | E16: 36 | F16: Unit full: diverting new admits to 5 East
A17: 45673 | B17: 36 | C17: 10 | D17: 11 | E17: 35
A18: 45674 | B18: 36 | C18: 10 | D18: 12 | E18: 33
A19: 45675 | B19: 36 | C19: 7 | D19: 7 | E19: 33
A20: 45676 | B20: 36 | C20: 10 | D20: 9 | E20: 34
A21: 45677 | B21: 36 | C21: 6 | D21: 7 | E21: 33
A22: 45678 | B22: 36 | C22: 7 | D22: 5 | E22: 35 | F22: Isolation room deep-clean
A23: 45679 | B23: 36 | C23: 12 | D23: 12 | E23: 35
A24: 45680 | B24: 36 | C24: 1 | D24: 2 | E24: 34 | F24: 1 RN call-off; covered by float pool
A25: 45681 | B25: 36 | C25: 11 | D25: 10 | E25: 35
A26: 45682 | B26: 36 | C26: 2 | D26: 3 | E26: 34
A27: 45683 | B27: 36 | C27: 7 | D27: 8 | E27: 33
A28: 45684 | B28: 36 | C28: 9 | D28: 6 | E28: 36 | F28: Unit full: diverting new admits to 5 East
A29: 45685 | B29: 36 | C29: 7 | D29: 8 | E29: 35
A30: 45686 | B30: 36 | C30: 10 | D30: 12 | E30: 33
A31: 45687 | B31: 36 | C31: 7 | D31: 6 | E31: 34
A32: 45688 | B32: 36 | C32: 10 | D32: 11 | E32: 33
A33: 45689 | B33: 36 | C33: 6 | D33: 6 | E33: 33 | F33: 1 RN call-off; covered by float pool
A34: 45690 | B34: 36 | C34: 8 | D34: 8 | E34: 33
A35: 45691 | B35: 36 | C35: 7 | D35: 6 | E35: 34 | F35: Isolation room deep-clean
A36: 45692 | B36: 36 | C36: 5 | D36: 6 | E36: 33
A37: 45693 | B37: 36 | C37: 5 | D37: 5 | E37: 33
A38: 45694 | B38: 36 | C38: 8 | D38: 8 | E38: 33
A39: 45695 | B39: 36 | C39: 10 | D39: 10 | E39: 33
A40: 45696 | B40: 36 | C40: 8 | D40: 9 | E40: 32
...

Sheet Supplies
A1: SKU | B1: ItemDescription | C1: Category | D1: UnitOfMeasure | E1: UnitCost | F1: QtyOnHand | G1: StockValue
A2: SKU-10014 | B2: Nitrile Exam Gloves Medium (Box/100) | C2: PPE | D2: Box | E2: 7.8 | F2: 403
A3: SKU-10077 | B3: Shoe Covers, Non-Skid (Case/300) | C3: PPE | D3: Case | E3: 40.02 | F3: 121
A4: SKU-10084 | B4: IV Catheter 14G x 1.16 in | C4: IV Supplies | D4: Box | E4: 60.04 | F4: 44
A5: SKU-10147 | B5: Saline Flush Syringe 3 mL (Box/30) | C5: IV Supplies | D5: Box | E5: 8.76 | F5: 0
A6: SKU-10175 | B6: IV Extension Set 7 in | C6: IV Supplies | D6: Each | E6: 2.06 | F6: 268
A7: SKU-10224 | B7: Transparent Film Dressing 2.4x2.8 | C7: Wound Care | D7: Each | E7: 0.79 | F7: 977
A8: SKU-10287 | B8: Nasal Cannula, Pediatric | C8: Respiratory | D8: Each | E8: 0.91 | F8: 809
A9: SKU-10301 | B9: Non-Rebreather Mask, Adult | C9: Respiratory | D9: Each | E9: 2.29 | F9: 947
A10: SKU-10308 | B10: Non-Rebreather Mask, Pediatric | C10: Respiratory | D10: Each | E10: 2.16 | F10: 586
A11: SKU-10315 | B11: Nebulizer Kit with Mouthpiece | C11: Respiratory | D11: Each | E11: 3.11 | F11: 1026
A12: SKU-10350 | B12: Endotracheal Tube 6.5 mm Cuffed | C12: Respiratory | D12: Each | E12: 7.47 | F12: 0
A13: SKU-10735 | B13: Patient Gown, Standard | C13: Linens | D13: Dozen | E13: 39.37 | F13: 171
... A15: SKU-10840 | B15: Hand Sanitizer Foam 1000 mL | C15: Patient Care | D15: Each | E15: 9.56 | F15: 303

Sheet Bonus
A1: Lesson 1.4 · Bonus: Does 4 West need more beds?
A2: The Chief Nursing Officer says February felt 'impossibly full' on 4 West and asks whether the unit needs more staffed beds. Hospitals often plan beds so average occupancy is about 85% — enough slack to absorb surges. February is rows 33–60 of the Census sheet.
A3: Type a formula or value in each yellow cell. The Check column turns green when your answer matches. Stuck? Read the hint, then the lesson guide. Answers: right-click a sheet tab → Unhide… → 'Bonus Key'.
A4: ="Score: "&COUNTIF(E6:E9,"✔*")&" of 4 auto-checked tasks correct"
A5: # | B5: Task | C5: Hint | D5: Your Answer | E5: Check
A6: B1 | B6: What was February's average daily census (ADC)? Use only the February rows. | C6: AVERAGE over rows 33–60 | E6: =IF(IFERROR(D6="",FALSE),"",IF(IFERROR(AND(ISNUMBER(D6),OR(ABS(D6-'Bonus Key'!$C$5)<=0.0051)),FALSE),"✔ Correct","✘ Not yet"))
A7: B2 | B7: How many beds would 4 West have needed in February for that ADC to equal 85% occupancy? (ADC ÷ 0.85, keep the decimals.) | C7: If ADC is 85% of the beds, beds = ADC ÷ 0.85 | E7: =IF(IFERROR(D7="",FALSE),"",IF(IFERROR(AND(ISNUMBER(D7),OR(ABS(D7-'Bonus Key'!$C$6)<=0.0051)),FALSE),"✔ Correct","✘ Not yet"))
A8: B3 | B8: You can't open part of a bed. How many EXTRA beds (beyond today's 36) should the unit open? Round up to a whole bed. | C8: ROUNDUP works like ROUND but always rounds up: ROUNDUP(number, 0) | E8: =IF(IFERROR(D8="",FALSE),"",IF(IFERROR(AND(ISNUMBER(D8),OR(ABS(D8-'Bonus Key'!$C$7)<=0.0001)),FALSE),"✔ Correct","✘ Not yet"))
A9: B4 | B9: Sanity check: on how many February days did the midnight census exceed 85% of 36 beds (i.e. more than 30.6 patients)? | C9: COUNTIF(range, ">30.6") — a preview of Lesson 2.5 | E9: =IF(IFERROR(D9="",FALSE),"",IF(IFERROR(AND(ISNUMBER(D9),OR(ABS(D9-'Bonus Key'!$C$8)<=0.0001)),FALSE),"✔ Correct","✘ Not yet"))

Sheet Answer Key
A1: 🔑 Answer Key — Lesson 1.4
A2: Spoiler alert — try every task before reading this sheet. Column C is the value the Check column compares against. Column D is a sample solution; column E is that same formula, live, proving it works.
A4: # | B4: Task | C4: Answer | D4: Sample solution | E4: Live result | F4: Explanation
A5: 1 | B5: How many patients were admitted to 4 West during the quarter (total of the Admissions column)? | C5: 699 | D5: =SUM(Census!C2:C91) | E5: {=SUM(Census!C2:C91)} | F5: SUM adds every number in the range. Typing =SUM( and then dragging over the column fills in the range for you.
A6: 2 | B6: What was the average midnight census? (Keep full precision — the check accepts 2 decimal places.) | C6: 32.855556 | D6: =AVERAGE(Census!E2:E91) | E6: {=AVERAGE(Census!E2:E91)} | F6: AVERAGE = SUM ÷ COUNT of the numbers in the range. This is the unit's *average daily census* (ADC).
A7: 3 | B7: What was the highest midnight census on any day? | C7: 37 | D7: =MAX(Census!E2:E91) | E7: {=MAX(Census!E2:E91)}
A8: 4 | B8: What was the lowest midnight census on any day? | C8: 28 | D8: =MIN(Census!E2:E91) | E8: {=MIN(Census!E2:E91)}
A9: 5 | B9: How many days of census data are there? Count the dates in the CensusDate column. | C9: 90 | D9: =COUNT(Census!A2:A91) | E9: {=COUNT(Census!A2:A91)} | F9: Excel stores dates as numbers (serial numbers), so COUNT includes them. COUNT ignores text and blanks.
A10: 6 | B10: On how many days did the charge nurse write a note? | C10: 21 | D10: =COUNTA(Census!F2:F91) | E10: {=COUNTA(Census!F2:F91)} | F10: COUNTA counts every non-empty cell, including text. COUNT would return 0 here because the notes are text.
A11: 7 | B11: On how many days was the Notes cell left empty? | C11: 69 | D11: =COUNTBLANK(Census!F2:F91) | E11: {=COUNTBLANK(Census!F2:F91)} | F11: COUNTA + COUNTBLANK always equals the number of cells in the range (here 90).
A12: 8 | B12: Patient days = the sum of every day's midnight census. How many patient days did 4 West provide in Q1? | C12: 2957 | D12: =SUM(Census!E2:E91) | E12: {=SUM(Census!E2:E91)} | F12: Each patient in a bed at midnight counts as one patient day. Patient days drive staffing and cost per day.
A13: 9 | B13: What was the unit's occupancy rate for the whole quarter? Divide total patient days by total staffed-bed days. Enter it as a percentage. | C13: 0.91265432 | D13: =SUM(Census!E2:E91)/SUM(Census!B2:B91) | E13: {=SUM(Census!E2:E91)/SUM(Census!B2:B91)} | F13: A rate for a whole period should be total numerator ÷ total denominator. Format the cell as a percentage (Ctrl+Shift+%) to see 91.3% instead of 0.9126…
A14: 10 | B14: In the Census sheet, fill the yellow Occupancy column with a formula for each day (MidnightCensus ÷ StaffedBeds). The gray cell counts the days your column shows 100% or more. (Type it in G2, then double-click the fill handle to copy it down.) | C14: 6 | D14: =E2/B2 | E14: {=SUMPRODUCT(--(Census!E2:E91>=Census!B2:B91))} | F14: Type =E2/B2 in the first Occupancy cell and copy it down; each row's formula points to its own row (=E3/B3, =E4/B4 …). Because the data is an Excel Table, typing the formula in one cell may fill the whole column automatically — and you may see it written as =[@MidnightCensus]/[@StaffedBeds]. Both are correct.
A15: 11 | B15: Average length of stay (ALOS) = patient days ÷ discharges. Calculate it for the quarter, rounded to 1 decimal place with ROUND. | C15: 4.2 | D15: =ROUND(SUM(Census!E2:E91)/SUM(Census!D2:D91),1) | E15: {=ROUND(SUM(Census!E2:E91)/SUM(Census!D2:D91),1)} | F15: ROUND changes the stored value, not just how it looks. The check here is strict: an unrounded value won't match.
A16: 12 | B16: Without typing it into Excel first, what does =(30-6)/4+2^3 return? Then type it to confirm. | C16: 14 | D16: =(30-6)/4+2^3 | E16: {=(30-6)/4+2^3} | F16: (30−6)=24 first (parentheses), then 2^3=8 (exponent), then 24/4=6 (division), then 6+8=14.
A17: 13 | B17: Switch to the Supplies sheet. Fill the yellow StockValue column with UnitCost × QtyOnHand for every item. The gray cell totals your column — what is the total value of 4 West's supply room? | C17: 31730.68 | D17: =E2*F2 | E17: {=SUMPRODUCT(Supplies!E2:E15,Supplies!F2:F15)} | F17: One formula, copied down, gives each item's value; then SUM the column. (The live formula in the key uses SUMPRODUCT, which multiplies and adds in one step — you'll meet it in Lesson 2.4.)

Sheet Bonus Key
A1: 🔑 Bonus Key — Lesson 1.4
A2: Spoiler alert — try every task before reading this sheet. Column C is the value the Check column compares against. Column D is a sample solution; column E is that same formula, live, proving it works.
A4: # | B4: Task | C4: Answer | D4: Sample solution | E4: Live result | F4: Explanation
A5: B1 | B5: What was February's average daily census (ADC)? Use only the February rows. | C5: 32.821429 | D5: =AVERAGE(Census!E33:E60) | E5: {=AVERAGE(Census!E33:E60)} | F5: Select only the February rows. Selecting the whole column would give the quarterly ADC instead.
A6: B2 | B6: How many beds would 4 West have needed in February for that ADC to equal 85% occupancy? (ADC ÷ 0.85, keep the decimals.) | C6: 38.613445 | D6: =AVERAGE(Census!E33:E60)/0.85 | E6: {=AVERAGE(Census!E33:E60)/0.85}
A7: B3 | B7: You can't open part of a bed. How many EXTRA beds (beyond today's 36) should the unit open? Round up to a whole bed. | C7: 3 | D7: =ROUNDUP(AVERAGE(Census!E33:E60)/0.85-Census!B33,0) | E7: {=ROUNDUP(AVERAGE(Census!E33:E60)/0.85-Census!B33,0)} | F7: Beds needed (≈38.6) minus the 36 staffed beds ≈ 2.6, rounded up to 3. ROUND would have given 3 here as well, but only ROUNDUP guarantees you never under-build: 2.1 extra beds still means opening 3.
A8: B4 | B8: Sanity check: on how many February days did the midnight census exceed 85% of 36 beds (i.e. more than 30.6 patients)? | C8: 25 | D8: =COUNTIF(Census!E33:E60,">"&0.85*36) | E8: {=COUNTIF(Census!E33:E60,">"&0.85*36)} | F8: COUNTIF counts cells that meet a condition. You'll master it in Lesson 2.5 — here it confirms that almost every February day ran above the 85% planning target.
