Workbook

Sheet Start Here
B2: Lesson 3.3
B3: Cleaning Messy Data
B4: Intermediate · about 145 minutes · Bluestone Health System (fictional)
B6: What you'll learn
B7: • | C7: Spot common data problems: stray spaces, inconsistent case and categories, text dates, duplicates
B8: • | C8: Fix them with TRIM, PROPER, SUBSTITUTE, VALUE, DATEVALUE, and lookup mapping tables
B9: • | C9: Use Text to Columns, Flash Fill, Remove Duplicates, and Go To Special
B10: • | C10: Document a repeatable cleaning process
B12: How to use this workbook
B13: 1. Read the guide | C13: The lesson guide (README) explains each skill with examples: https://github.com/lmansf/learn-excel/tree/main/03-data-analysis/03-data-cleaning
B14: 2. Practice | C14: Go to the 'Practice' sheet. Type your answers to tasks 1 and 3 in its yellow cells. For tasks 2 and 4–12, do the work on the sheet the task names (Clean, CensusExport, LabFeed, or CleaningLog), and the task's gray cell on Practice reads it.
B15: 3. Check yourself | C15: The Check column shows ✔ Correct (green) or ✘ Not yet (red).
B16: 4. Bonus | C16: Finished? Try the harder 'Bonus' sheet.
B17: 5. Answers | C17: The 'Answer Key' and 'Bonus Key' sheets are hidden. Right-click any sheet tab → Unhide… → pick one → OK. (Try first!)
B18: Note | C18: Clean's last two yellow columns (RegisteredClean and Keep) belong to the Bonus.
B19: Note | C19: Task 3 deletes rows, so do it on a copy of Raw (right-click the Raw tab → Move or Copy → Create a copy). Tasks 4 and 9 change the CensusExport and LabFeed sheets in place. If something goes wrong, press Ctrl + Z (Mac: ⌘ + Z) or download a fresh workbook.
B20: Note | C20: Version notes: XLOOKUP needs Microsoft 365 or Excel 2021+ (use VLOOKUP with FALSE in older versions). MAXIFS needs Excel 2019+. Flash Fill needs Excel 2013+ on Windows, or Excel 2019 / Microsoft 365 on a Mac.
B22: Color legend
B23: Yellow cell | C23: Your answer goes here.
B24: Gray cell | C24: Pre-filled summary formula. It reads the work you did on another sheet, so don't type over it.
B25: ✔ Correct | C25: Your answer matches the key.
B26: ✘ Not yet | C26: Not matching yet. Check the hint and try again.
B28: Sheets in this workbook
B29: Practice | C29: 12 practice tasks, each with a Check cell.
B30: Raw | C30: Data: 650 rows. The registration export exactly as received. Read it, but never edit it.
B31: Clean | C31: Data: 650 rows, in the Excel Table 'tblClean'. Your working copy of Raw. Fill its yellow columns: K–Q in the practice tasks, and R–S in the bonus.
B32: PayerMap | C32: Data: 19 rows, in the Excel Table 'tblPayerMap'. The mapping table that turns each insurance spelling into a PayerID (task 8).
B33: CensusExport | C33: Data: 49 rows. A one-week bed-board census export with blank Facility and Unit cells to fill (task 4).
B34: LabFeed | C34: Data: 116 rows. A pipe-delimited lab interface feed to split with Text to Columns (task 9).
B35: CleaningLog | C35: Data: 9 rows, in the Excel Table 'tblLog'. Your cleaning log. Fill in its yellow cells as you go. Task 12 checks step 2's RowsChanged cell.
B36: Bonus | C36: The bonus challenge (5 parts).
B37: About the data | C37: A 650-row patient registration export from Bluestone's legacy registration system (names, DOBs, phones, insurance, and MRNs typed every which way, plus duplicates), a payer mapping table, a one-week bed-board census export, and a 116-line lab interface feed from Cedar Ridge Medical Center.
B38: Disclaimer | C38: All people, places, and numbers are synthetic and fictional. Not clinical guidance.

Sheet Practice
A1: Lesson 3.3 · Practice
A2: Raw is the untouched export: never edit it. Clean is your working copy of the same 650 rows, with yellow columns to fill. For a column task, type the formula in row 2 of the yellow column. Clean is an Excel Table, so the formula fills down by itself. A gray cell here then checks the whole column. Other tasks use the CensusExport, LabFeed, and CleaningLog sheets.
A3: For tasks 1 and 3, type a formula or value in the yellow cell. For the other tasks, do the work on the sheet the task names, and the gray cell here reads it. The Check column turns green when your answer matches. Stuck? Read the hint, then the lesson guide. Answers: right-click a sheet tab → Unhide… → 'Answer Key'.
A4: ="Score: "&COUNTIF(E6:E17,"✔*")&" of 12 auto-checked tasks correct"
A5: # | B5: Task | C5: Hint | D5: Your Answer | E5: Check
A6: 1 | B6: Profile first. On the Raw sheet, how many PatientName values contain extra spaces (leading, trailing, or doubled)? Compare each name's length with the length of its TRIMmed version. | C6: LEN(x)<>LEN(TRIM(x)) is TRUE when TRIM would remove something. SUMPRODUCT(--(…)) counts the TRUEs | E6: =IF(IFERROR(D6="",FALSE),"",IF(IFERROR(AND(ISNUMBER(D6),OR(ABS(D6-'Answer Key'!$C$5)<=0.0001)),FALSE),"✔ Correct","✘ Not yet"))
A7: 2 | B7: On the Clean sheet, fill the yellow SexClean column (M) with a single capital letter, F or M. The raw Sex column has 10 spellings, including Female, MALE, lowercase f, and values with a stray space. The gray cell counts cells that are exactly F (case-sensitive). | C7: TRIM first, then take the first letter, then capitalize it | D7: {=IF(COUNTA(Clean!M2:M651)=0,"",SUMPRODUCT(--EXACT(Clean!M2:M651,"F")))} | E7: =IF(IFERROR(D7="",FALSE),"",IF(IFERROR(AND(ISNUMBER(D7),OR(ABS(D7-'Answer Key'!$C$6)<=0.0001)),FALSE),"✔ Correct","✘ Not yet"))
A8: 3 | B8: Make a copy of the Raw sheet (right-click its tab → Move or Copy… → tick Create a copy). On the copy, run Data → Remove Duplicates on all the data (A1:J651) with every column ticked except RecordID (each row has its own RecordID, so leaving it ticked finds nothing). How many duplicate rows does Excel remove? | C8: Untick RecordID in the Remove Duplicates dialog. Excel's message tells you the count | E8: =IF(IFERROR(D8="",FALSE),"",IF(IFERROR(AND(ISNUMBER(D8),OR(ABS(D8-'Answer Key'!$C$7)<=0.0001)),FALSE),"✔ Correct","✘ Not yet"))
A9: 4 | B9: Switch to CensusExport, a bed-board report that prints each Facility and Unit only on the first row of its block. Fill every blank cell in A2:B50 with the value above it: select that range, use Go To Special → Blanks, type = and press the Up arrow, then press Ctrl + Enter (Mac: ⌘ + Return). The gray cell stays blank until every gap is filled, then totals the week's midnight census for the Intensive Care Unit at Cedar Ridge Medical Center (ICU patient days). | C9: Go To Special selects only the blanks, and Ctrl + Enter fills them all with one relative formula | D9: {=IF(COUNTBLANK(CensusExport!A2:B50)>0,"",SUMIFS(CensusExport!E2:E50,CensusExport!A2:A50,"Cedar Ridge Medical Center",CensusExport!B2:B50,"Intensive Care Unit"))} | E9: =IF(IFERROR(D9="",FALSE),"",IF(IFERROR(AND(ISNUMBER(D9),OR(ABS(D9-'Answer Key'!$C$8)<=0.0001)),FALSE),"✔ Correct","✘ Not yet"))
A10: 5 | B10: Back on Clean, use Flash Fill to fill the yellow ZIP5 column (O) with the 5-digit ZIP from CityStateZip. 101 rows carry a ZIP+4 such as 45501-8106, and those must become 45501. Type three examples yourself: rows 2 and 3, plus the first ZIP+4 row (row 11). Then select the first empty cell and press Ctrl + E (Mac: Data → Flash Fill). The gray cell counts the distinct ZIP codes in your column. | C10: Give Flash Fill an example from each layout, especially a ZIP+4 row | D10: {=IF(COUNTA(Clean!O2:O651)=0,"",SUMPRODUCT((Clean!O2:O651<>"")/COUNTIF(Clean!O2:O651,Clean!O2:O651&"")))} | E10: =IF(IFERROR(D10="",FALSE),"",IF(IFERROR(AND(ISNUMBER(D10),OR(ABS(D10-'Answer Key'!$C$9)<=0.0001)),FALSE),"✔ Correct","✘ Not yet"))
A11: 6 | B11: Fill the yellow PhoneClean column (N) with each phone as exactly 10 digits and nothing else, or an empty result when Phone is blank. Phones arrive as (555) 476-7432, 555-722-8468, 555.468.7891, 5553869767, and +1 555 597 3811. The gray cell counts rows that end up with exactly 10 digits. | C11: Nest one SUBSTITUTE per unwanted character, then keep the RIGHT 10 characters | D11: {=IF(COUNTA(Clean!N2:N651)=0,"",SUMPRODUCT((LEN(Clean!N2:N651)=10)*ISNUMBER(--Clean!N2:N651)))} | E11: =IF(IFERROR(D11="",FALSE),"",IF(IFERROR(AND(ISNUMBER(D11),OR(ABS(D11-'Answer Key'!$C$10)<=0.0001)),FALSE),"✔ Correct","✘ Not yet"))
A12: 7 | B12: Fill the yellow MRNClean column (Q) with every MRN as 8-digit text: 05927600, not MRN-05927600, and 01955231, not 1955231. The gray cell first checks that every value is 8 characters long, then counts the distinct MRNs, which is the number of real patients in the file. | C12: Remove the prefix with SUBSTITUTE, make it a number with VALUE, then pad it back with TEXT(…,"00000000") | D12: {=IF(COUNTA(Clean!Q2:Q651)=0,"",IF(SUMPRODUCT(--(LEN(Clean!Q2:Q651)<>8))>0,"MRN not 8 chars",SUMPRODUCT((Clean!Q2:Q651<>"")/COUNTIF(Clean!Q2:Q651,Clean!Q2:Q651&""))))} | E12: =IF(IFERROR(D12="",FALSE),"",IF(IFERROR(AND(ISNUMBER(D12),OR(ABS(D12-'Answer Key'!$C$11)<=0.0001)),FALSE),"✔ Correct","✘ Not yet"))
A13: 8 | B13: Fill the yellow PayerID column (P) by looking up each Insurance value in the PayerMap table, so all 30 spellings become one of seven PayerIDs. Some values carry a trailing space. Return UNMAPPED for anything missing from the map. The gray cell shows a warning if any row is unmapped. Otherwise it counts PY02 (Silverline Medicare Advantage) rows. | C13: XLOOKUP the TRIMmed Insurance value in tblPayerMap, and use XLOOKUP's if_not_found argument for UNMAPPED | D13: {=IF(COUNTA(Clean!P2:P651)=0,"",IF(COUNTIF(Clean!P2:P651,"PY*")<ROWS(Clean!P2:P651),"Unmapped rows",COUNTIF(Clean!P2:P651,"PY02")))} | E13: =IF(IFERROR(D13="",FALSE),"",IF(IFERROR(AND(ISNUMBER(D13),OR(ABS(D13-'Answer Key'!$C$12)<=0.0001)),FALSE),"✔ Correct","✘ Not yet"))
A14: 9 | B14: Switch to LabFeed: 116 STAT results from a lab interface, each crammed into one cell as MRN|TestCode|Result|Units|CollectedDateTime. Split A1:A117 into five columns with Data → Text to Columns (Delimited, Other: |). In step 3 of the wizard, set the MRN column's format to Text so its leading zeros survive. The gray cell checks the MRNs, then shows the average potassium (TestCode K) result in mmol/L. | C14: Text to Columns step 3: click the first column in the preview, then choose Text | D14: {=IF(COUNTA(LabFeed!C2:C117)=0,"",IF(SUMPRODUCT(--(LEN(LabFeed!A2:A117)<>8))>0,"MRN lost zeros",AVERAGEIF(LabFeed!B2:B117,"K",LabFeed!C2:C117)))} | E14: =IF(IFERROR(D14="",FALSE),"",IF(IFERROR(AND(ISNUMBER(D14),OR(ABS(D14-'Answer Key'!$C$13)<=0.0051)),FALSE),"✔ Correct","✘ Not yet"))
A15: 10 | B15: Fill the yellow NameClean column (K) with every name as First Last in Proper Case, with single spaces. For example, "Haddad, Jonathan" becomes Jonathan Haddad, " Alexander , Gary " becomes Gary Alexander, and "Amber White" stays Amber White. 92 rows are already First Last (no comma). The gray cell warns if any name still has extra spaces or is ALL CAPS or all lowercase. Otherwise it counts distinct names. | C15: IF(ISNUMBER(FIND(",",B2)), flip the two parts, just TRIM), then wrap everything in PROPER | D15: {=IF(COUNTA(Clean!K2:K651)=0,"",IF(SUMPRODUCT(EXACT(Clean!K2:K651,UPPER(Clean!K2:K651))+EXACT(Clean!K2:K651,LOWER(Clean!K2:K651))+NOT(EXACT(Clean!K2:K651,TRIM(Clean!K2:K651))))>0,"Fix spaces/case",SUMPRODUCT((Clean!K2:K651<>"")/COUNTIF(Clean!K2:K651,Clean!K2:K651&""))))} | E15: =IF(IFERROR(D15="",FALSE),"",IF(IFERROR(AND(ISNUMBER(D15),OR(ABS(D15-'Answer Key'!$C$14)<=0.0001)),FALSE),"✔ Correct","✘ Not yet"))
A16: 11 | B16: Fill the yellow DOBClean column (L) with real dates. DOB is text in five layouts: 2002-03-31, 03-Apr-1957, 08/06/1989, 3/22/1961, and 01.11.2003. The export is from a U.S. system, so the slash and dot layouts are month first. The gray cell checks that every row is a real date, then counts DOBs that fall on the 13th or later of their month (a quick test that month and day weren't swapped). | C16: DATEVALUE can't read 01.11.2003 until the dots become slashes. For a version that works with any regional setting, build DATE(year, month, day) from the pieces | D16: {=IF(COUNTA(Clean!L2:L651)=0,"",IF(COUNT(Clean!L2:L651)<ROWS(Clean!L2:L651),"Not all dates yet",SUMPRODUCT(--(DAY(Clean!L2:L651)>12))))} | E16: =IF(IFERROR(D16="",FALSE),"",IF(IFERROR(AND(ISNUMBER(D16),OR(ABS(D16-'Answer Key'!$C$15)<=0.0001)),FALSE),"✔ Correct","✘ Not yet"))
A17: 12 | B17: Document your work. On the CleaningLog sheet, put a formula in the yellow RowsChanged cell for step 2 (E3) that counts how many rows your SexClean column actually changed: rows where the raw Sex value is not exactly the same as SexClean (case-sensitive). The gray cell here reads your log entry. | C17: EXACT compares case-sensitively, NOT flips TRUE and FALSE, and SUMPRODUCT(--…) counts the TRUEs | D17: {=IF(CleaningLog!E3="","",CleaningLog!E3)} | E17: =IF(IFERROR(D17="",FALSE),"",IF(IFERROR(AND(ISNUMBER(D17),OR(ABS(D17-'Answer Key'!$C$16)<=0.0001)),FALSE),"✔ Correct","✘ Not yet"))

Sheet Raw
A1: RecordID | B1: PatientName | C1: DOB | D1: Sex | E1: Phone | F1: Email | G1: CityStateZip | H1: Insurance | I1: MRN | J1: RegisteredOn
A2: R1001 | B2: Haddad, Jonathan | C2: 2002-03-31 | D2: M | E2: 555.468.7891 | F2: jonathan.haddad30@example.com | G2: Bluestone OH 45501 | H2: Medicaid | I2: 04979796 | J2: 2015-11-06 18:33:00
A3: R1002 | B3: Powell, Wei | C3: 03-Apr-1957 | D3: M | E3: (555) 476-7432 | G3: CEDAR RIDGE, OH 45720 | H3: Medicare | I3: 01261473 | J3: 2023-05-03 16:02:00
A4: R1003 | B4: Campbell, Virginia | C4: 08/06/1989 | D4: Female | E4: (555) 455-0735 | F4: virginia.campbell86@example.com | G4: Riverbend, OH 45545 | H4: Summit Choice | I4: 09849286 | J4: 2008-02-22 14:10:00
A5: R1004 | B5: MURRAY, MARGARET | C5: 28-Dec-1993 | D5: F | E5: (555) 841-8432 | G5: Bluestone, OH 45501 | H5: evergreen mutual insurance | I5: MRN-05927600 | J5: 05/30/2022 05:42 PM
A6: R1005 | B6: ELLIS, JOSEPH | C6: 1960-07-05 | D6: M | E6: (555) 914-3619 | G6: LAKEVIEW HEIGHTS, OH 45510 | H6: Medicare | I6: 07075701 | J6: 01/16/2024 06:58 PM
A7: R1006 | B7: BOYD, DOUGLAS | C7: 02/18/1928 | D7: Male | E7: 555-722-8468 | G7: Granite Springs OH 45750 | H7: Silverline Medicare Advantage | I7: 09093811 | J7: 01/05/2025 04:03 PM
A8: R1007 | B8: perry, janet | C8: 05/18/1950 | D8: F | E8: 555-261-7228 | F8: none | G8: Granite Springs, OH 45750 | H8: Silverline Medicare Advantage | I8: 05265401 | J8: 09/21/2022 07:12 AM
A9: R1008 | B9: Hunter, Austin | C9: 09/16/1957 | D9: MALE | E9: (555) 570-6678 | F9: austin.hunter80@example.com | G9: BLUESTONE, OH 45502 | H9: SILVERLINE MEDICARE ADV. | I9: 04897542 | J9: 2018-03-02 10:39:00
A10: R1009 | B10: Alexander , Gary | C10: 11/25/1948 | D10: MALE | E10: 555-509-5785 | G10: Bluestone, OH 45501 | H10: Silverline Medicare Advantage | I10: 05801986 | J10: 05/18/2013 12:46 PM
A11: R1010 | B11: Watson , Amy | C11: 12/25/1980 | D11: F | E11: (555) 815-2249 | G11: Bluestone, OH 45501-8106 | H11: STATE MEDICAID | I11: 1955231 | J11: 08/04/2018 10:40 AM
A12: R1011 | B12: Ferguson , Carolyn | C12: 14-Jan-2019 | D12: F | F12: N/A | G12: Oak Glen OH 45730 | H12: KEYSTONE HEALTH PARTNERS | I12: MRN-06388981 | J12: 11/03/2020 05:27 PM
A13: R1012 | B13: Gomez, Walter | C13: 12/16/1958 | D13: M | E13: (555) 402-9498 | F13: none | G13: ASHBY FALLS, OH 45610 | H13: Silverline MA | I13: 07279550 | J13: 2015-10-23 18:30:00
A14: R1013 | B14: Diaz, Angela | C14: 05/25/1951 | D14: FEMALE | E14: 555-751-0512 | F14: angela.diaz23@example.com | G14: Millbrook, OH 45530 | H14: SILVERLINE MEDICARE ADV. | I14: 01452965 | J14: 2019-03-19 09:47:00
A15: R1014 | B15: O'Brien, Virginia | C15: 1940-10-20 | D15: f | E15: (555) 972-5277 | F15: virginia.obrien12@example.com | G15: Bluestone, OH 45501-2106 | H15: Medicare | I15: 02003462 | J15: 2023-02-28 11:19:00
A16: R1015 | B16: Stone, Frank | C16: 11/10/1960 | D16: M | E16: (555) 392-9849 | F16: frank.stone92@example.com | G16: Fairhaven, OH 45620 | H16: Medicare Part A | I16: 488484 | J16: 2019-08-28 16:52:00
A17: R1016 | B17: Ryan, Theresa | C17: 06/15/1967 | D17: F | F17: THERESA.RYAN88@EXAMPLE.COM | G17: ASHBY FALLS, OH 45610 | H17: KEYSTONE HEALTH PARTNERS | I17: 5293385 | J17: 2017-09-20 09:54:00
A18: R1017 | B18: Amber White | C18: 1996-06-24 | D18: FEMALE | E18: (555) 556-3833 | F18: amber.white81@example.com | G18: Cedar Ridge OH 45720 | H18: Medicaid | I18: 03929231 | J18: 2024-07-10 16:38:00
A19: R1018 | B19: Janet Carter | C19: 06/22/2023 | D19: Female | E19: 555-742-3815 | F19: N/A | G19: ASHBY FALLS, OH 45610 | H19: medicaid | I19: 08514640 | J19: 06/09/2024 11:20 AM
A20: R1019 | B20: OSEI, ROY | C20: 3/22/1961 | D20: M | E20: +1 555 597 3811 | F20: roy.osei61@example.com | G20: BLUESTONE, OH 45503 | H20: EVERGREEN MUTUAL INS | I20: 04811155 | J20: 2009-01-12 13:09:00
A21: R1020 | B21: jimenez, bobby | C21: 1988-10-28 | D21: M | E21: 555.252.4718 | G21: Millbrook, OH 45530-1433 | H21: Summit Choice | I21: 5841378 | J21: 08/07/2020 12:17 PM
A22: R1021 | B22: O'Brien, Madison | C22: 2014-06-11 | D22: Female | E22: (555) 285-4455 | G22: Bluestone, OH 45502 | H22: Medicaid | I22: 8523812 | J22: 03/28/2023 09:50 AM
A23: R1022 | B23: Ray, Michael | C23: 10-Oct-2011 | D23: M | E23: (555) 856-4092 | F23: none | G23: Cedar Ridge, OH 45720 | H23: Medicaid | I23: 09317927 | J23: 09/28/2015 08:50 AM
A24: R1023 | B24: Robinson, Angela | C24: 12-Jan-2018 | D24: F | E24: 555-580-6711 | F24: none | G24: Bluestone OH 45502 | H24: STATE MEDICAID | I24: 00757638 | J24: 2022-05-01 12:49:00
A25: R1024 | B25: Vargas, Betty | C25: 03/24/1996 | D25: F | E25: 5553869767 | F25: none | G25: BLUESTONE, OH 45503 | H25: STATE MEDICAID | I25: 09463107 | J25: 2020-05-07 14:43:00
A26: R1025 | B26: Harris, Doris | C26: 1976-12-28 | D26: F | E26: 555.521.8783 | F26: doris.harris90@example.com | G26: Bluestone, OH 45503 | H26: self-pay | I26: 06545996 | J26: 07/02/2020 11:15 AM
A27: R1026 | B27: SPENCER, GERALD | C27: 06/30/1981 | D27: m | E27: (555) 805-6914 | F27: gerald.spencer79@example.com | G27: Ashby Falls, OH 45610-7699 | H27: KEYSTONE HEALTH PARTNERS | I27: 02651075 | J27: 03/24/2009 04:56 PM
A28: R1027 | B28: Paul Simmons | C28: 01/05/1984 | D28: M | E28: (555) 611-9026 | F28: PAUL.SIMMONS91@EXAMPLE.COM | G28: LAKEVIEW HEIGHTS, OH 45510 | H28: Keystone Health Partners | I28: 08817764 | J28: 01/16/2018 05:15 PM
A29: R1028 | B29: SOTO, DORIS | C29: 05/07/1975 | D29: f | E29: 555-686-8252 | F29: doris.soto85@example.com | G29: Ashby Falls, OH 45610 | H29: EVERGREEN MUTUAL INS | I29: 03295027 | J29: 2024-01-22 07:05:00
A30: R1029 | B30: Wei Burns | C30: 01.11.2003 | D30: M | E30: (555) 817-3440 | F30: wei.burns45@example.com | G30: Granite Springs, OH 45750 | H30: Keystone Health Partners | I30: 07405722 | J30: 10/02/2012 01:48 PM
A31: R1030 | B31: SANTOS, CARLOS | C31: 22-Dec-1952 | D31: M | E31: 5552389242 | F31: carlos.santos91@example.com | G31: Bluestone, OH 45502 | H31: Silverline Medicare Advantage | I31: 01786386 | J31: 2021-10-28 10:01:00
A32: R1031 | B32: Ellis , Jean | C32: 1970-09-14 | D32: F | E32: (555) 401-2840 | G32: Bluestone, OH 45502 | H32: Summit PPO | I32: 04736523 | J32: 2017-10-03 17:58:00
A33: R1032 | B33: Freeman, Matthew | C33: 11.06.1975 | D33: MALE | E33: 555-733-5390 | G33: Ashby Falls, OH 45610 | H33: Self Pay | I33: 1143993 | J33: 2013-02-15 10:17:00
A34: R1033 | B34: Baker , Ava | C34: 06/12/2025 | D34: Female | G34: Pine Hollow, OH 45640 | H34: self-pay | I34: 09501885 | J34: 03/15/2024 03:24 PM
A35: R1034 | B35: meyer, nancy | C35: 1931-11-19 | D35: F | E35: 555-971-3628 | F35: nancy.meyer26@example.com | G35: Bluestone, OH 45503 | H35: Silverline MA | I35: 06141853 | J35: 05/01/2017 03:37 PM
A36: R1035 | B36: GARZA, DONNA | C36: 04/11/2020 | D36: f | E36: (555) 233-5856 | F36: none | G36: Cedar Ridge, OH 45720 | H36: Summit Choice PPO | I36: 07765833 | J36: 06/27/2023 09:25 AM
A37: R1036 | B37: Abdi, Gregory | C37: 8/1/1945 | D37: M | E37: 555.221.2464 | G37: Lakeview Heights, OH 45510 | H37: MEDICARE | I37: 08665573 | J37: 2019-12-05 15:17:00
A38: R1037 | B38: Cooper, Nancy | C38: 12-Jun-1948 | D38: Female | E38: 555.847.4160 | G38: Bluestone, OH 45501 | H38: Silverline MA | I38: 01374637 | J38: 2008-11-15 15:26:00
A39: R1038 | B39: Weaver, Justin | C39: 12-Jun-1990 | D39: M | E39: (555) 328-2250 | F39: justin.weaver6@example.com | G39: Bluestone, OH 45503-2144 | H39: State Medicaid | I39: 06122876 | J39: 2013-08-30 10:22:00
A40: R1039 | B40: GARCIA, PAMELA | C40: 1962-02-11 | D40: F | E40: 555-239-0126 | F40: pamela.garcia63@example.com | G40: Bluestone, OH 45501-5610 | H40: EVERGREEN MUTUAL INS | I40: 5952813 | J40: 2018-02-20 07:23:00
...

Sheet Clean
A1: RecordID | B1: PatientName | C1: DOB | D1: Sex | E1: Phone | F1: Email | G1: CityStateZip | H1: Insurance | I1: MRN | J1: RegisteredOn | K1: NameClean | L1: DOBClean | M1: SexClean | N1: PhoneClean | O1: ZIP5 | P1: PayerID | Q1: MRNClean | R1: RegisteredClean | S1: Keep
A2: R1001 | B2: Haddad, Jonathan | C2: 2002-03-31 | D2: M | E2: 555.468.7891 | F2: jonathan.haddad30@example.com | G2: Bluestone OH 45501 | H2: Medicaid | I2: 04979796 | J2: 2015-11-06 18:33:00
A3: R1002 | B3: Powell, Wei | C3: 03-Apr-1957 | D3: M | E3: (555) 476-7432 | G3: CEDAR RIDGE, OH 45720 | H3: Medicare | I3: 01261473 | J3: 2023-05-03 16:02:00
A4: R1003 | B4: Campbell, Virginia | C4: 08/06/1989 | D4: Female | E4: (555) 455-0735 | F4: virginia.campbell86@example.com | G4: Riverbend, OH 45545 | H4: Summit Choice | I4: 09849286 | J4: 2008-02-22 14:10:00
A5: R1004 | B5: MURRAY, MARGARET | C5: 28-Dec-1993 | D5: F | E5: (555) 841-8432 | G5: Bluestone, OH 45501 | H5: evergreen mutual insurance | I5: MRN-05927600 | J5: 05/30/2022 05:42 PM
A6: R1005 | B6: ELLIS, JOSEPH | C6: 1960-07-05 | D6: M | E6: (555) 914-3619 | G6: LAKEVIEW HEIGHTS, OH 45510 | H6: Medicare | I6: 07075701 | J6: 01/16/2024 06:58 PM
A7: R1006 | B7: BOYD, DOUGLAS | C7: 02/18/1928 | D7: Male | E7: 555-722-8468 | G7: Granite Springs OH 45750 | H7: Silverline Medicare Advantage | I7: 09093811 | J7: 01/05/2025 04:03 PM
A8: R1007 | B8: perry, janet | C8: 05/18/1950 | D8: F | E8: 555-261-7228 | F8: none | G8: Granite Springs, OH 45750 | H8: Silverline Medicare Advantage | I8: 05265401 | J8: 09/21/2022 07:12 AM
A9: R1008 | B9: Hunter, Austin | C9: 09/16/1957 | D9: MALE | E9: (555) 570-6678 | F9: austin.hunter80@example.com | G9: BLUESTONE, OH 45502 | H9: SILVERLINE MEDICARE ADV. | I9: 04897542 | J9: 2018-03-02 10:39:00
A10: R1009 | B10: Alexander , Gary | C10: 11/25/1948 | D10: MALE | E10: 555-509-5785 | G10: Bluestone, OH 45501 | H10: Silverline Medicare Advantage | I10: 05801986 | J10: 05/18/2013 12:46 PM
A11: R1010 | B11: Watson , Amy | C11: 12/25/1980 | D11: F | E11: (555) 815-2249 | G11: Bluestone, OH 45501-8106 | H11: STATE MEDICAID | I11: 1955231 | J11: 08/04/2018 10:40 AM
A12: R1011 | B12: Ferguson , Carolyn | C12: 14-Jan-2019 | D12: F | F12: N/A | G12: Oak Glen OH 45730 | H12: KEYSTONE HEALTH PARTNERS | I12: MRN-06388981 | J12: 11/03/2020 05:27 PM
A13: R1012 | B13: Gomez, Walter | C13: 12/16/1958 | D13: M | E13: (555) 402-9498 | F13: none | G13: ASHBY FALLS, OH 45610 | H13: Silverline MA | I13: 07279550 | J13: 2015-10-23 18:30:00
A14: R1013 | B14: Diaz, Angela | C14: 05/25/1951 | D14: FEMALE | E14: 555-751-0512 | F14: angela.diaz23@example.com | G14: Millbrook, OH 45530 | H14: SILVERLINE MEDICARE ADV. | I14: 01452965 | J14: 2019-03-19 09:47:00
A15: R1014 | B15: O'Brien, Virginia | C15: 1940-10-20 | D15: f | E15: (555) 972-5277 | F15: virginia.obrien12@example.com | G15: Bluestone, OH 45501-2106 | H15: Medicare | I15: 02003462 | J15: 2023-02-28 11:19:00
A16: R1015 | B16: Stone, Frank | C16: 11/10/1960 | D16: M | E16: (555) 392-9849 | F16: frank.stone92@example.com | G16: Fairhaven, OH 45620 | H16: Medicare Part A | I16: 488484 | J16: 2019-08-28 16:52:00
A17: R1016 | B17: Ryan, Theresa | C17: 06/15/1967 | D17: F | F17: THERESA.RYAN88@EXAMPLE.COM | G17: ASHBY FALLS, OH 45610 | H17: KEYSTONE HEALTH PARTNERS | I17: 5293385 | J17: 2017-09-20 09:54:00
A18: R1017 | B18: Amber White | C18: 1996-06-24 | D18: FEMALE | E18: (555) 556-3833 | F18: amber.white81@example.com | G18: Cedar Ridge OH 45720 | H18: Medicaid | I18: 03929231 | J18: 2024-07-10 16:38:00
A19: R1018 | B19: Janet Carter | C19: 06/22/2023 | D19: Female | E19: 555-742-3815 | F19: N/A | G19: ASHBY FALLS, OH 45610 | H19: medicaid | I19: 08514640 | J19: 06/09/2024 11:20 AM
A20: R1019 | B20: OSEI, ROY | C20: 3/22/1961 | D20: M | E20: +1 555 597 3811 | F20: roy.osei61@example.com | G20: BLUESTONE, OH 45503 | H20: EVERGREEN MUTUAL INS | I20: 04811155 | J20: 2009-01-12 13:09:00
A21: R1020 | B21: jimenez, bobby | C21: 1988-10-28 | D21: M | E21: 555.252.4718 | G21: Millbrook, OH 45530-1433 | H21: Summit Choice | I21: 5841378 | J21: 08/07/2020 12:17 PM
A22: R1021 | B22: O'Brien, Madison | C22: 2014-06-11 | D22: Female | E22: (555) 285-4455 | G22: Bluestone, OH 45502 | H22: Medicaid | I22: 8523812 | J22: 03/28/2023 09:50 AM
A23: R1022 | B23: Ray, Michael | C23: 10-Oct-2011 | D23: M | E23: (555) 856-4092 | F23: none | G23: Cedar Ridge, OH 45720 | H23: Medicaid | I23: 09317927 | J23: 09/28/2015 08:50 AM
A24: R1023 | B24: Robinson, Angela | C24: 12-Jan-2018 | D24: F | E24: 555-580-6711 | F24: none | G24: Bluestone OH 45502 | H24: STATE MEDICAID | I24: 00757638 | J24: 2022-05-01 12:49:00
A25: R1024 | B25: Vargas, Betty | C25: 03/24/1996 | D25: F | E25: 5553869767 | F25: none | G25: BLUESTONE, OH 45503 | H25: STATE MEDICAID | I25: 09463107 | J25: 2020-05-07 14:43:00
A26: R1025 | B26: Harris, Doris | C26: 1976-12-28 | D26: F | E26: 555.521.8783 | F26: doris.harris90@example.com | G26: Bluestone, OH 45503 | H26: self-pay | I26: 06545996 | J26: 07/02/2020 11:15 AM
A27: R1026 | B27: SPENCER, GERALD | C27: 06/30/1981 | D27: m | E27: (555) 805-6914 | F27: gerald.spencer79@example.com | G27: Ashby Falls, OH 45610-7699 | H27: KEYSTONE HEALTH PARTNERS | I27: 02651075 | J27: 03/24/2009 04:56 PM
A28: R1027 | B28: Paul Simmons | C28: 01/05/1984 | D28: M | E28: (555) 611-9026 | F28: PAUL.SIMMONS91@EXAMPLE.COM | G28: LAKEVIEW HEIGHTS, OH 45510 | H28: Keystone Health Partners | I28: 08817764 | J28: 01/16/2018 05:15 PM
A29: R1028 | B29: SOTO, DORIS | C29: 05/07/1975 | D29: f | E29: 555-686-8252 | F29: doris.soto85@example.com | G29: Ashby Falls, OH 45610 | H29: EVERGREEN MUTUAL INS | I29: 03295027 | J29: 2024-01-22 07:05:00
A30: R1029 | B30: Wei Burns | C30: 01.11.2003 | D30: M | E30: (555) 817-3440 | F30: wei.burns45@example.com | G30: Granite Springs, OH 45750 | H30: Keystone Health Partners | I30: 07405722 | J30: 10/02/2012 01:48 PM
A31: R1030 | B31: SANTOS, CARLOS | C31: 22-Dec-1952 | D31: M | E31: 5552389242 | F31: carlos.santos91@example.com | G31: Bluestone, OH 45502 | H31: Silverline Medicare Advantage | I31: 01786386 | J31: 2021-10-28 10:01:00
A32: R1031 | B32: Ellis , Jean | C32: 1970-09-14 | D32: F | E32: (555) 401-2840 | G32: Bluestone, OH 45502 | H32: Summit PPO | I32: 04736523 | J32: 2017-10-03 17:58:00
A33: R1032 | B33: Freeman, Matthew | C33: 11.06.1975 | D33: MALE | E33: 555-733-5390 | G33: Ashby Falls, OH 45610 | H33: Self Pay | I33: 1143993 | J33: 2013-02-15 10:17:00
A34: R1033 | B34: Baker , Ava | C34: 06/12/2025 | D34: Female | G34: Pine Hollow, OH 45640 | H34: self-pay | I34: 09501885 | J34: 03/15/2024 03:24 PM
A35: R1034 | B35: meyer, nancy | C35: 1931-11-19 | D35: F | E35: 555-971-3628 | F35: nancy.meyer26@example.com | G35: Bluestone, OH 45503 | H35: Silverline MA | I35: 06141853 | J35: 05/01/2017 03:37 PM
A36: R1035 | B36: GARZA, DONNA | C36: 04/11/2020 | D36: f | E36: (555) 233-5856 | F36: none | G36: Cedar Ridge, OH 45720 | H36: Summit Choice PPO | I36: 07765833 | J36: 06/27/2023 09:25 AM
A37: R1036 | B37: Abdi, Gregory | C37: 8/1/1945 | D37: M | E37: 555.221.2464 | G37: Lakeview Heights, OH 45510 | H37: MEDICARE | I37: 08665573 | J37: 2019-12-05 15:17:00
A38: R1037 | B38: Cooper, Nancy | C38: 12-Jun-1948 | D38: Female | E38: 555.847.4160 | G38: Bluestone, OH 45501 | H38: Silverline MA | I38: 01374637 | J38: 2008-11-15 15:26:00
A39: R1038 | B39: Weaver, Justin | C39: 12-Jun-1990 | D39: M | E39: (555) 328-2250 | F39: justin.weaver6@example.com | G39: Bluestone, OH 45503-2144 | H39: State Medicaid | I39: 06122876 | J39: 2013-08-30 10:22:00
A40: R1039 | B40: GARCIA, PAMELA | C40: 1962-02-11 | D40: F | E40: 555-239-0126 | F40: pamela.garcia63@example.com | G40: Bluestone, OH 45501-5610 | H40: EVERGREEN MUTUAL INS | I40: 5952813 | J40: 2018-02-20 07:23:00
...

Sheet PayerMap
A1: Variant | B1: PayerID | C1: StandardName | D1: Note
A2: MEDICARE | B2: PY01 | C2: Medicare
A3: MEDICARE PART A | B3: PY01 | C3: Medicare
A4: SILVERLINE MA | B4: PY02 | C4: Silverline Medicare Advantage
A5: SILVERLINE MEDICARE ADV. | B5: PY02 | C5: Silverline Medicare Advantage
A6: SILVERLINE MEDICARE ADVANTAGE | B6: PY02 | C6: Silverline Medicare Advantage
A7: MEDICAID | B7: PY03 | C7: State Medicaid
A8: STATE MEDICAID | B8: PY03 | C8: State Medicaid
A9: KEYSTONE | B9: PY04 | C9: Keystone Health Partners
A10: KEYSTONE HEALTH PARTNERS | B10: PY04 | C10: Keystone Health Partners
A11: KEYSTONE HEALTH PTNRS | B11: PY04 | C11: Keystone Health Partners
A12: EVERGREEN MUTUAL | B12: PY05 | C12: Evergreen Mutual Insurance
A13: EVERGREEN MUTUAL INS | B13: PY05 | C13: Evergreen Mutual Insurance
... A19: SELF-PAY | B19: PY07 | C19: Self-Pay
A20: UNINSURED | B20: PY07 | C20: Self-Pay | D20: Business rule: no coverage on file = Self-Pay
A22: Variants are trimmed and in capitals. XLOOKUP and VLOOKUP ignore case, so one row per spelling is enough.

Sheet CensusExport
A1: Facility | B1: Unit | C1: CensusDate | D1: StaffedBeds | E1: MidnightCensus | G1: Bed-board export: Facility and Unit print only on the first row of each block.
A2: Bluestone Memorial Hospital | B2: Cardiac Step-Down | C2: 46006 | D2: 24 | E2: 21 | G2: Practice task 4: fill the blanks in A2:B50 with Go To Special → Blanks.
C3: 46007 | D3: 24 | E3: 21
C4: 46008 | D4: 24 | E4: 20
C5: 46009 | D5: 24 | E5: 20
C6: 46010 | D6: 24 | E6: 20
C7: 46011 | D7: 24 | E7: 19
C8: 46012 | D8: 24 | E8: 19
B9: Intensive Care Unit | C9: 46006 | D9: 20 | E9: 16
C10: 46007 | D10: 20 | E10: 17
C11: 46008 | D11: 20 | E11: 18
C12: 46009 | D12: 20 | E12: 18
C13: 46010 | D13: 20 | E13: 19
C14: 46011 | D14: 20 | E14: 20
C15: 46012 | D15: 20 | E15: 20
A16: Ashby Falls Community Hospital | B16: Intensive Care Unit | C16: 46006 | D16: 8 | E16: 7
C17: 46007 | D17: 8 | E17: 7
C18: 46008 | D18: 8 | E18: 7
C19: 46009 | D19: 8 | E19: 7
C20: 46010 | D20: 8 | E20: 7
C21: 46011 | D21: 8 | E21: 7
C22: 46012 | D22: 8 | E22: 7
B23: Medical-Surgical | C23: 46006 | D23: 28 | E23: 28
C24: 46007 | D24: 28 | E24: 28
C25: 46008 | D25: 28 | E25: 29
C26: 46009 | D26: 28 | E26: 27
C27: 46010 | D27: 28 | E27: 28
C28: 46011 | D28: 28 | E28: 26
C29: 46012 | D29: 28 | E29: 25
A30: Cedar Ridge Medical Center | B30: Cardiac Step-Down | C30: 46006 | D30: 16 | E30: 15
C31: 46007 | D31: 16 | E31: 15
C32: 46008 | D32: 16 | E32: 15
C33: 46009 | D33: 16 | E33: 15
C34: 46010 | D34: 16 | E34: 15
C35: 46011 | D35: 16 | E35: 14
C36: 46012 | D36: 16 | E36: 12
B37: Intensive Care Unit | C37: 46006 | D37: 12 | E37: 11
C38: 46007 | D38: 12 | E38: 10
C39: 46008 | D39: 12 | E39: 10
C40: 46009 | D40: 12 | E40: 10
...

Sheet LabFeed
A1: MRN|TestCode|Result|Units|CollectedDateTime | H1: Lab interface feed: one result per line, fields separated by | (vertical bar).
A2: 07539656|NA|138|mmol/L|12/01/2025 14:58 | H2: Practice task 9: split column A with Data → Text to Columns. Keep MRN as Text.
A3: 07539656|K|4.6|mmol/L|12/01/2025 14:58
A4: 07539656|GLU|149|mg/dL|12/01/2025 15:18
A5: 08012025|GLU|121|mg/dL|12/02/2025 02:02
A6: 08094078|K|5.3|mmol/L|12/02/2025 11:14
A7: 02838787|GLU|72|mg/dL|12/03/2025 01:37
A8: 00723214|K|4.2|mmol/L|12/03/2025 15:25
A9: 00723214|CREAT|1.05|mg/dL|12/03/2025 15:41
A10: 06224529|GLU|119|mg/dL|12/03/2025 15:54
A11: 06224529|CREAT|1.3|mg/dL|12/03/2025 15:54
A12: 00723214|NA|137|mmol/L|12/03/2025 16:05
A13: 06439191|CREAT|1.13|mg/dL|12/04/2025 08:31
A14: 06439191|GLU|112|mg/dL|12/04/2025 08:55
... A117: 03705464|GLU|233|mg/dL|12/30/2025 19:35

Sheet CleaningLog
A1: Step | B1: Column | C1: ProblemFound | D1: FixApplied | E1: RowsChanged | F1: Notes
A2: 1 | B2: (all) | C2: Export must stay exactly as received, for audit and re-runs | D2: Raw copied to Clean. Every fix is a formula in a new yellow column | E2: 0 | F2: Never type over Raw
A3: 2 | B3: Sex | C3: 10 spellings of 2 values: F, f, ' F', Female, FEMALE, M, m, 'M ', Male, MALE | F3: Practice tasks 2 and 12
A4: 3 | B4: PatientName | C4: Two layouts (Last, First and First Last), stray spaces, ALL CAPS and lowercase
A5: 4 | B5: Phone | C5: Six layouts, some with a +1 country code, and some blanks
A6: 5 | B6: MRN | C6: Leading zeros lost on some rows, and an MRN- prefix on others
A7: 6 | B7: DOB | C7: Dates stored as text in five layouts
A8: 7 | B8: Insurance | C8: Many spellings of 7 payers, some with trailing spaces
A9: 8 | B9: CityStateZip | C9: ZIP+4 mixed with 5-digit ZIPs
A10: 9 | B10: (rows) | C10: Exact copies and re-registrations of the same patient
A12: Fill in FixApplied and RowsChanged as you finish each practice task. Practice task 12 checks the RowsChanged cell for step 2.

Sheet Bonus
A1: Lesson 3.3 · Bonus: Build the master patient list for the EHR migration
A2: Bluestone is moving to a new EHR, and the vendor needs a master patient load file with exactly one row per patient. The rule from Patient Access is: keep each patient's most recent registration (latest RegisteredOn). Fill the Clean sheet's last two yellow columns (RegisteredClean and Keep), using your MRNClean and PhoneClean columns from the practice tasks. RegisteredOn has two layouts: 2015-11-06 18:33:00 (24-hour clock) and 05/30/2022 05:42 PM (12-hour clock). If you want helper columns, put them on the Clean sheet in column V or further right, outside the Table.
A3: For B1 and B2, fill the yellow RegisteredClean and Keep columns on the Clean sheet, and the gray cell here reads them. For B3–B5, type a formula or value in the yellow cell. The Check column turns green when your answer matches. Stuck? Read the hint, then the lesson guide. Answers: right-click a sheet tab → Unhide… → 'Bonus Key'.
A4: ="Score: "&COUNTIF(E6:E10,"✔*")&" of 5 auto-checked tasks correct"
A5: # | B5: Task | C5: Hint | D5: Your Answer | E5: Check
A6: B1 | B6: Fill the yellow RegisteredClean column (R) with real date-times. Make sure 05:42 PM becomes 17:42. The gray cell checks every row, then counts registrations made at 5:00 PM or later (the evening Patient Access shift). | C6: In both layouts the time starts at character 12, and TIMEVALUE understands both 18:33:00 and 05:42 PM. Build the date part with DATE, then add the time to it | D6: {=IF(COUNTA(Clean!R2:R651)=0,"",IF(COUNT(Clean!R2:R651)<ROWS(Clean!R2:R651),"Not all date-times yet",SUMPRODUCT(--(HOUR(Clean!R2:R651)>=17))))} | E6: =IF(IFERROR(D6="",FALSE),"",IF(IFERROR(AND(ISNUMBER(D6),OR(ABS(D6-'Bonus Key'!$C$5)<=0.0001)),FALSE),"✔ Correct","✘ Not yet"))
A7: B2 | B7: Fill the yellow Keep column (S) with TRUE on exactly one row per patient (MRNClean): the row with that patient's latest RegisteredClean. If the latest time appears on two identical rows, keep only the first of them. Every other row is FALSE. The gray cell counts the TRUEs. | C7: MAXIFS (Lesson 2.5) finds the patient's latest time. A COUNTIFS over an expanding range ($Q$2:Q2) breaks ties | D7: {=IF(COUNTA(Clean!S2:S651)=0,"",COUNTIF(Clean!S2:S651,TRUE))} | E7: =IF(IFERROR(D7="",FALSE),"",IF(IFERROR(AND(ISNUMBER(D7),OR(ABS(D7-'Bonus Key'!$C$6)<=0.0001)),FALSE),"✔ Correct","✘ Not yet"))
A8: B3 | B8: Which RegisteredOn did you keep for MRN 01276260? Enter it as a date and time. | C8: MAXIFS with two conditions: MRNClean is this MRN, and Keep is TRUE. Or filter Clean on those two columns and read RegisteredClean | E8: =IF(IFERROR(D8="",FALSE),"",IF(IFERROR(AND(ISNUMBER(D8),ABS(D8-'Bonus Key'!$C$7)<=0.0006944454444444445),FALSE),"✔ Correct","✘ Not yet"))
A9: B4 | B9: Remove Duplicates always keeps the first row it meets. For how many patients is the row you kept NOT that patient's first row in the file? These are the patients that Remove Duplicates on MRNClean would have gotten wrong. | C9: A row is a patient's first occurrence when MATCH(its MRN, the MRN column, 0) returns its own position. Or add a helper column with =COUNTIF($Q$2:Q2,Q2)=1 | E9: =IF(IFERROR(D9="",FALSE),"",IF(IFERROR(AND(ISNUMBER(D9),OR(ABS(D9-'Bonus Key'!$C$8)<=0.0001)),FALSE),"✔ Correct","✘ Not yet"))
A10: B5 | B10: The rule "keep the latest row" decides which registration survives into the master list, and it can throw away good data. How many kept rows have an empty PhoneClean even though another registration for the same patient has a phone number? | C10: For each row, COUNTIFS(MRN column, this MRN, PhoneClean column, "?*") counts that patient's rows that have a phone | E10: =IF(IFERROR(D10="",FALSE),"",IF(IFERROR(AND(ISNUMBER(D10),OR(ABS(D10-'Bonus Key'!$C$9)<=0.0001)),FALSE),"✔ Correct","✘ Not yet"))

Sheet Answer Key
A1: 🔑 Answer Key — Lesson 3.3
A2: Spoiler alert: try every task before reading this sheet. Column C is the value the Check column compares against. Column D is a sample solution, and column E recalculates a formula for it live, proving the answer.
A4: # | B4: Task | C4: Answer | D4: Sample solution | E4: Live result | F4: Explanation
A5: 1 | B5: Profile first. On the Raw sheet, how many PatientName values contain extra spaces (leading, trailing, or doubled)? Compare each name's length with the length of its TRIMmed version. | C5: 69 | D5: =SUMPRODUCT(--(LEN(Raw!B2:B651)<>LEN(TRIM(Raw!B2:B651)))) | E5: {=SUMPRODUCT(--(LEN(Raw!B2:B651)<>LEN(TRIM(Raw!B2:B651))))} | F5: TRIM removes leading and trailing spaces and shrinks inner runs to one space, so any name it shortens had extra spaces. Comparing lengths tests all 650 rows at once: the comparison gives TRUE/FALSE for each row, the double minus turns those into 1/0, and SUMPRODUCT adds them. You can't see a trailing space by looking at a cell, so a count like this is how you find out a problem exists before you fix it. In Microsoft 365 or Excel 2021+, =SUM(--(LEN(…)<>LEN(TRIM(…)))) works too.
A6: 2 | B6: On the Clean sheet, fill the yellow SexClean column (M) with a single capital letter, F or M. The raw Sex column has 10 spellings, including Female, MALE, lowercase f, and values with a stray space. The gray cell counts cells that are exactly F (case-sensitive). | C6: 335 | D6: =UPPER(LEFT(TRIM(D2),1)) | E6: {=SUMPRODUCT(--EXACT(UPPER(LEFT(TRIM(Raw!D2:D651),1)),"F"))} | F6: Every spelling starts with the right letter once the stray space is gone, so the fix is TRIM, then LEFT(…,1), then UPPER. The order matters: LEFT(" F",1) is a space. The check uses EXACT because COUNTIF ignores case and would count a lowercase f as F. This shortcut works only because each value is identified by its first letter. Medicare and Medicaid share a first letter, so Insurance needs a mapping table instead (task 8).
A7: 3 | B7: Make a copy of the Raw sheet (right-click its tab → Move or Copy… → tick Create a copy). On the copy, run Data → Remove Duplicates on all the data (A1:J651) with every column ticked except RecordID (each row has its own RecordID, so leaving it ticked finds nothing). How many duplicate rows does Excel remove? | C7: 40 | D7: 1. Right-click the Raw tab → Move or Copy… → tick Create a copy → OK. Work on Raw (2). 2. Click any cell in the data, then Data → Remove Duplicates. 3. Keep My data has headers ticked. Untick RecordID and leave the other nine columns ticked. Click OK. 4. Excel reports 40 duplicate values found and removed; 610 unique values remain. Formula check without deleting anything (Microsoft 365 or Excel 2021+): =ROWS(Raw!B2:J651)-ROWS(UNIQUE(Raw!B2:J651)) | E7: {=ROWS(Raw!B2:J651)-ROWS(_xlfn.UNIQUE(Raw!B2:J651))} | F7: Remove Duplicates only removes rows that match in every ticked column, so it finds the 40 rows that were exported twice, character for character. That is not all of them, as task 7 will show when you count the real patients. Many more rows are re-registrations typed differently. For example, row 18 ("Amber White", (555) 556-3833) and row 410 ("WHITE, AMBER", 5555563833) are the same patient, but Remove Duplicates sees two different rows. Standardize first, then remove duplicates on the cleaned key column. UNIQUE on all nine columns counts the same thing without deleting anything. Both ignore case.
A8: 4 | B8: Switch to CensusExport, a bed-board report that prints each Facility and Unit only on the first row of its block. Fill every blank cell in A2:B50 with the value above it: select that range, use Go To Special → Blanks, type = and press the Up arrow, then press Ctrl + Enter (Mac: ⌘ + Return). The gray cell stays blank until every gap is filled, then totals the week's midnight census for the Intensive Care Unit at Cedar Ridge Medical Center (ICU patient days). | C8: 71 | D8: 1. Select A2:B50 on CensusExport (not the whole columns, and not the header row). 2. Home → Find & Select → Go To Special… (or press F5, Mac: Control + G, then Special…). Choose Blanks → OK. Only the empty cells stay selected. 3. Without clicking anywhere, type = and press ↑. The active cell is the first blank, A3, so the formula reads =A2. 4. Press Ctrl + Enter (Mac: ⌘ + Return) to put that formula in every selected blank. Each copy points to the cell above itself. 5. Turn the formulas into values: select A2:B50, copy, then Paste Special → Values. Check with =SUMIFS(CensusExport!E2:E50,CensusExport!A2:A50,"Cedar Ridge Medical Center",CensusExport!B2:B50,"Intensive Care Unit") | E8: — | F8: After Go To Special, Excel has selected only the 88 empty cells, and the formula you type goes into all of them at once. Because the reference is relative, each blank points to the cell directly above it, and that cell either holds the label or points further up. The unit name "Intensive Care Unit" appears at all three hospitals, so the SUMIFS needs both columns filled. With the blanks left in, it returns 0: no Cedar Ridge ICU row carries both labels, because the facility name was printed only once, on the facility's first unit. Paste the result as values before you sort, because a formula that points "one row up" points somewhere else after a sort.
A9: 5 | B9: Back on Clean, use Flash Fill to fill the yellow ZIP5 column (O) with the 5-digit ZIP from CityStateZip. 101 rows carry a ZIP+4 such as 45501-8106, and those must become 45501. Type three examples yourself: rows 2 and 3, plus the first ZIP+4 row (row 11). Then select the first empty cell and press Ctrl + E (Mac: Data → Flash Fill). The gray cell counts the distinct ZIP codes in your column. | C9: 12 | D9: 1. In O2 type 45501 (from Bluestone OH 45501), and in O3 type 45720 (from CEDAR RIDGE, OH 45720). 2. In the first ZIP+4 row, O11 (Bluestone, OH 45501-8106), type 45501. 3. Select O4, the first empty cell, and press Ctrl + E (or Data → Flash Fill). 4. Check the result: =SUMPRODUCT(--(LEN(Clean!O2:O651)<>5)) should return 0. If some rows are wrong, press Ctrl + Z (Mac: ⌘ + Z), type the correct ZIP on one of the wrong rows as an extra example, and run Flash Fill again. Formula alternative (Microsoft 365 or Excel 2024): =LEFT(TEXTAFTER(G2," ",-1),5) | E9: {=ROWS(_xlfn.UNIQUE(MID(Raw!G2:G651,FIND(" OH ",Raw!G2:G651)+4,5)))} | F9: Flash Fill looks for a rule that explains every example you typed. Two plain ZIPs fit several rules (the first number, the last number, the last five characters), and on 45501-8106 those give different answers. The ZIP+4 example leaves only "the first number". If the +4 survives, the distinct count jumps to 108. Flash Fill writes typed-in values, not formulas, so it won't update when next month's export arrives. The Lesson 2.2 bonus did the same job with TEXTAFTER. The formula is the repeatable choice, and Flash Fill is the fast one for a one-off.
A10: 6 | B10: Fill the yellow PhoneClean column (N) with each phone as exactly 10 digits and nothing else, or an empty result when Phone is blank. Phones arrive as (555) 476-7432, 555-722-8468, 555.468.7891, 5553869767, and +1 555 597 3811. The gray cell counts rows that end up with exactly 10 digits. | C10: 620 | D10: =RIGHT(SUBSTITUTE(SUBSTITUTE(SUBSTITUTE(SUBSTITUTE(SUBSTITUTE(E2,"(",""),")",""),"-",""),".","")," ",""),10) | E10: {=SUMPRODUCT((LEN(RIGHT(SUBSTITUTE(SUBSTITUTE(SUBSTITUTE(SUBSTITUTE(SUBSTITUTE(Raw!E2:E651,"(",""),")",""),"-",""),".","")," ",""),10))=10)*ISNUMBER(--RIGHT(SUBSTITUTE(SUBSTITUTE(SUBSTITUTE(SUBSTITUTE(SUBSTITUTE(Raw!E2:E651,"(",""),")",""),"-",""),".","")," ",""),10)))} | F10: Each SUBSTITUTE deletes one kind of character: parentheses, dashes, dots, and spaces. That leaves 5554767432 for most rows, but +15555973811 for the 40 numbers with a country code, so RIGHT(…,10) keeps the last ten digits, which is always the U.S. number. A blank phone needs no special handling, because SUBSTITUTE and RIGHT on an empty cell return an empty result. The 30 blanks are why the count is 620, not 650. Keep phones as text, because they are identifiers, not quantities. In Microsoft 365, =RIGHT(REGEXREPLACE(E2,"[^0-9]",""),10) removes every non-digit in one step.
A11: 7 | B11: Fill the yellow MRNClean column (Q) with every MRN as 8-digit text: 05927600, not MRN-05927600, and 01955231, not 1955231. The gray cell first checks that every value is 8 characters long, then counts the distinct MRNs, which is the number of real patients in the file. | C11: 560 | D11: =TEXT(VALUE(SUBSTITUTE(I2,"MRN-","")),"00000000") | E11: {=ROWS(_xlfn.UNIQUE(TEXT(VALUE(SUBSTITUTE(Raw!I2:I651,"MRN-","")),"00000000")))} | F11: Two problems hide in this column. 86 rows carry an MRN- prefix, which SUBSTITUTE removes. 141 rows lost their leading zeros somewhere upstream, because a system treated the MRN as a number. VALUE turns the remaining text into a number, and TEXT(…,"00000000") writes it back as text with exactly 8 digits, adding the zeros it needs. =RIGHT("0000000"&SUBSTITUTE(I2,"MRN-",""),8) does the same without VALUE. The result: 650 rows but only 560 patients, so 90 rows are duplicates.
A12: 8 | B12: Fill the yellow PayerID column (P) by looking up each Insurance value in the PayerMap table, so all 30 spellings become one of seven PayerIDs. Some values carry a trailing space. Return UNMAPPED for anything missing from the map. The gray cell shows a warning if any row is unmapped. Otherwise it counts PY02 (Silverline Medicare Advantage) rows. | C12: 68 | D12: =XLOOKUP(TRIM(H2),tblPayerMap[Variant],tblPayerMap[PayerID],"UNMAPPED") | E12: {=SUMPRODUCT(--(_xlfn.XLOOKUP(TRIM(Raw!H2:H651),PayerMap!$A$2:$A$20,PayerMap!$B$2:$B$20,"UNMAPPED")="PY02"))} | F12: A mapping table turns a messy category into a standard code with one lookup, and it documents your decisions where everyone can see them, such as the rule that Uninsured means PY07 (Self-Pay). XLOOKUP ignores case, so the map needs only one row per spelling, not one per capitalization. It does not ignore spaces, so TRIM comes first. Without TRIM, the 12 rows typed "Silverline Medicare Advantage " with a trailing space come back UNMAPPED. The "UNMAPPED" result makes new spellings easy to find next month: filter for it, add the spelling as a new row of the map, and every formula picks it up. The Table references (tblPayerMap[Variant]) grow with the map. A fixed range such as PayerMap!$A$2:$A$20 works today but would miss a row added below it. Without XLOOKUP, use =IFNA(VLOOKUP(TRIM(H2),tblPayerMap,2,FALSE),"UNMAPPED").
A13: 9 | B13: Switch to LabFeed: 116 STAT results from a lab interface, each crammed into one cell as MRN|TestCode|Result|Units|CollectedDateTime. Split A1:A117 into five columns with Data → Text to Columns (Delimited, Other: |). In step 3 of the wizard, set the MRN column's format to Text so its leading zeros survive. The gray cell checks the MRNs, then shows the average potassium (TestCode K) result in mmol/L. | C13: 4.18125 | D13: 1. On LabFeed, select A1:A117 (header included). 2. Data → Text to Columns. Choose Delimited → Next. 3. Untick Tab, tick Other, and type a vertical bar | in the box. The preview splits into five columns. Click Next. 4. Click the MRN column in the preview and choose Text as its column data format. Optionally click the last column and choose Date: MDY. Click Finish. Check with =AVERAGEIF(LabFeed!B2:B117,"K",LabFeed!C2:C117) | E13: {=AVERAGE(IF(MID(LabFeed!A2:A117,FIND("|",LabFeed!A2:A117)+1,FIND("|",LabFeed!A2:A117,FIND("|",LabFeed!A2:A117)+1)-FIND("|",LabFeed!A2:A117)-1)="K",--MID(LabFeed!A2:A117,FIND("|",LabFeed!A2:A117,FIND("|",LabFeed!A2:A117)+1)+1,FIND("|",LabFeed!A2:A117,FIND("|",LabFeed!A2:A117,FIND("|",LabFeed!A2:A117)+1)+1)-FIND("|",LabFeed!A2:A117,FIND("|",LabFeed!A2:A117)+1)-1)))} | F13: Text to Columns splits each cell at every |, and step 3 decides what each piece becomes. Under General, Excel turns 07539656 (row 2) into the number 7539656. All 116 MRNs in this feed start with 0, so every one would break and stop matching the registration file. Choosing Text keeps the digits exactly as sent. The results (for example 138 and 4.6 in rows 2 and 3) should stay General so they become real numbers you can average. If you get it wrong, press Ctrl + Z (Mac: ⌘ + Z) to undo the split and run it again.
A14: 10 | B14: Fill the yellow NameClean column (K) with every name as First Last in Proper Case, with single spaces. For example, "Haddad, Jonathan" becomes Jonathan Haddad, " Alexander , Gary " becomes Gary Alexander, and "Amber White" stays Amber White. 92 rows are already First Last (no comma). The gray cell warns if any name still has extra spaces or is ALL CAPS or all lowercase. Otherwise it counts distinct names. | C14: 557 | D14: =PROPER(IF(ISNUMBER(FIND(",",B2)),TRIM(MID(B2,FIND(",",B2)+1,LEN(B2)))&" "&TRIM(LEFT(B2,FIND(",",B2)-1)),TRIM(B2))) | E14: — | F14: FIND(",",B2) returns a position when there is a comma and #VALUE! when there isn't, so ISNUMBER(FIND(…)) tells the two layouts apart. For Last, First rows, MID takes everything after the comma (the first name) and LEFT takes everything before it (the last name). TRIM each piece before joining, because the spaces sit around the comma. PROPER on the outside fixes the case of both layouts at once. Two checks on the result. First, the flip matters: =PROPER(TRIM(B2)) alone gives 578 distinct names, and deleting the comma without flipping still gives 569, because the same patient then appears as both "Amber White" (row 18) and "White Amber" (row 410). Second, the count is 557, not 560, because 3 names belong to two different patients (Justin Lewis, Lisa Morris, Mei Myers). That's why you deduplicate on MRN, never on name. PROPER also turns McDonald into Mcdonald, so fix known exceptions by hand and note them in the cleaning log.
A15: 11 | B15: Fill the yellow DOBClean column (L) with real dates. DOB is text in five layouts: 2002-03-31, 03-Apr-1957, 08/06/1989, 3/22/1961, and 01.11.2003. The export is from a U.S. system, so the slash and dot layouts are month first. The gray cell checks that every row is a real date, then counts DOBs that fall on the 13th or later of their month (a quick test that month and day weren't swapped). | C15: 397 | D15: =IF(MID(C2,5,1)="-",DATE(LEFT(C2,4),MID(C2,6,2),RIGHT(C2,2)),IF(MID(C2,3,1)="-",DATE(RIGHT(C2,4),(SEARCH(MID(C2,4,3),"JanFebMarAprMayJunJulAugSepOctNovDec")+2)/3,LEFT(C2,2)),DATE(RIGHT(C2,4),LEFT(C2,FIND("/",SUBSTITUTE(C2,".","/"))-1),MID(C2,FIND("/",SUBSTITUTE(C2,".","/"))+1,LEN(C2)-FIND("/",SUBSTITUTE(C2,".","/"))-5)))) | E15: {=SUMPRODUCT(--(DAY(IF(MID(Raw!C2:C651,5,1)="-",DATE(LEFT(Raw!C2:C651,4),MID(Raw!C2:C651,6,2),RIGHT(Raw!C2:C651,2)),IF(MID(Raw!C2:C651,3,1)="-",DATE(RIGHT(Raw!C2:C651,4),(SEARCH(MID(Raw!C2:C651,4,3),"JanFebMarAprMayJunJulAugSepOctNovDec")+2)/3,LEFT(Raw!C2:C651,2)),DATE(RIGHT(Raw!C2:C651,4),LEFT(Raw!C2:C651,FIND("/",SUBSTITUTE(Raw!C2:C651,".","/"))-1),MID(Raw!C2:C651,FIND("/",SUBSTITUTE(Raw!C2:C651,".","/"))+1,LEN(Raw!C2:C651)-FIND("/",SUBSTITUTE(Raw!C2:C651,".","/"))-5)))))>12))} | F15: This solution works on any computer: it reads the layout and builds DATE(year, month, day) from the pieces. ISO dates have a dash in position 5. In 03-Apr-1957 the dash is in position 3, and the month comes from where Apr sits in "JanFebMarAprMayJunJulAugSepOctNovDec" (position 10, and (10+2)/3 = 4). Everything else is month/day/year with a / or . after the month. If your Windows or Mac region is United States, the much shorter =DATEVALUE(SUBSTITUTE(C2,".","/")) gives identical results, because U.S. settings read the ISO and 03-Apr-1957 layouts and read slashes month first. In a day-first region it reads 08/06/1989 as 8 June and fails on 3/22/1961, and in a language whose month names differ from English it can fail on 03-Apr-1957 too. The day-13 test catches a swap: a month number is never above 12, so if the slash and dot rows had month and day swapped, none of them could show a day above 12 and the count would fall to 145 instead of 397.
A16: 12 | B16: Document your work. On the CleaningLog sheet, put a formula in the yellow RowsChanged cell for step 2 (E3) that counts how many rows your SexClean column actually changed: rows where the raw Sex value is not exactly the same as SexClean (case-sensitive). The gray cell here reads your log entry. | C16: 424 | D16: =SUMPRODUCT(--NOT(EXACT(Clean!D2:D651,Clean!M2:M651))) | E16: {=SUMPRODUCT(--NOT(EXACT(Raw!D2:D651,UPPER(LEFT(TRIM(Raw!D2:D651),1)))))} | F16: A cleaning log records what you changed and how much, so the next person (or you, next month) can repeat it and audit it. "Rows changed" is the most useful number in it: here 424 of 650 rows changed and 226 were already F or M. EXACT matters again, because with = the values "f" and "F" count as equal and those rows would look unchanged. A count that is suspiciously high or low is often the first sign that a cleaning formula is wrong.

Sheet Bonus Key
A1: 🔑 Bonus Key — Lesson 3.3
A2: Spoiler alert: try every task before reading this sheet. Column C is the value the Check column compares against. Column D is a sample solution, and column E recalculates a formula for it live, proving the answer.
A4: # | B4: Task | C4: Answer | D4: Sample solution | E4: Live result | F4: Explanation
A5: B1 | B5: Fill the yellow RegisteredClean column (R) with real date-times. Make sure 05:42 PM becomes 17:42. The gray cell checks every row, then counts registrations made at 5:00 PM or later (the evening Patient Access shift). | C5: 118 | D5: =IF(MID(J2,5,1)="-",DATE(LEFT(J2,4),MID(J2,6,2),MID(J2,9,2)),DATE(MID(J2,7,4),LEFT(J2,2),MID(J2,4,2)))+TIMEVALUE(MID(J2,12,8)) | E5: {=SUMPRODUCT(--(HOUR(IF(MID(Raw!J2:J651,5,1)="-",DATE(LEFT(Raw!J2:J651,4),MID(Raw!J2:J651,6,2),MID(Raw!J2:J651,9,2)),DATE(MID(Raw!J2:J651,7,4),LEFT(Raw!J2:J651,2),MID(Raw!J2:J651,4,2)))+TIMEVALUE(MID(Raw!J2:J651,12,8)))>=17))} | F5: Both layouts put the time at character 12, so TIMEVALUE(MID(J2,12,8)) reads "18:33:00" and "05:42 PM" alike, and AM/PM is handled for you. The date part differs, so the IF builds it with DATE from the right pieces. In the ISO layout the day is MID(J2,9,2), not RIGHT(J2,2), because the time follows it. A date-time is just date + time (a whole number plus a fraction of a day). If PM were ignored, the evening count would drop to 76. With U.S. regional settings, =--J2 (or =VALUE(J2)) converts both layouts in one step.
A6: B2 | B6: Fill the yellow Keep column (S) with TRUE on exactly one row per patient (MRNClean): the row with that patient's latest RegisteredClean. If the latest time appears on two identical rows, keep only the first of them. Every other row is FALSE. The gray cell counts the TRUEs. | C6: 560 | D6: =AND(R2=MAXIFS($R$2:$R$651,$Q$2:$Q$651,Q2),COUNTIFS($Q$2:Q2,Q2,$R$2:R2,R2)=1) | E6: {=ROWS(_xlfn.UNIQUE(TEXT(VALUE(SUBSTITUTE(Raw!I2:I651,"MRN-","")),"00000000")))} | F6: The first test, RegisteredClean = MAXIFS(all RegisteredClean, all MRNClean, this MRN), is TRUE on the patient's latest row. Exact copies share that time, so the second test counts how many rows so far (the expanding range $Q$2:Q2 grows as the formula goes down) have this MRN and this time. It equals 1 only on the first of them. The total must equal the 560 distinct MRNs from practice task 7, which is a good cross-check. Avoid comparing date-times with ">"&R2 inside COUNTIFS, because that turns the time into text with 15 digits and can miss by a rounding error.
A7: B3 | B7: Which RegisteredOn did you keep for MRN 01276260? Enter it as a date and time. | C7: 43820.588 | D7: =MAXIFS(Clean!R2:R651,Clean!Q2:Q651,"01276260",Clean!S2:S651,TRUE) | E7: {=MAX(IF(TEXT(VALUE(SUBSTITUTE(Raw!I2:I651,"MRN-","")),"00000000")="01276260",IF(MID(Raw!J2:J651,5,1)="-",DATE(LEFT(Raw!J2:J651,4),MID(Raw!J2:J651,6,2),MID(Raw!J2:J651,9,2)),DATE(MID(Raw!J2:J651,7,4),LEFT(Raw!J2:J651,2),MID(Raw!J2:J651,4,2)))+TIMEVALUE(MID(Raw!J2:J651,12,8))))} | F7: This patient has three rows. Two of them say 1276260 (the MRN lost its leading zero) with the time 08:22, and the third says 01276260 with 12/21/2019 02:06 PM. You only find all three after cleaning the MRN, and you only pick the right one if 02:06 PM became 14:06: read as 02:06 AM it would look older than 08:22.
A8: B4 | B8: Remove Duplicates always keeps the first row it meets. For how many patients is the row you kept NOT that patient's first row in the file? These are the patients that Remove Duplicates on MRNClean would have gotten wrong. | C8: 27 | D8: =SUMPRODUCT(Clean!S2:S651*(MATCH(Clean!Q2:Q651,Clean!Q2:Q651,0)<>ROW(Clean!Q2:Q651)-1)) | E8: — | F8: MATCH(MRN, MRN column, 0) returns the position of the first row with that MRN. ROW(…)-1 is each row's own position in the column (row 2 is position 1). Where they differ, the row is a repeat. Multiplying by Keep counts kept rows that are repeats. For these 27 patients a newer registration sits further down the file. To make Remove Duplicates keep the newest row, sort by RegisteredClean (newest to oldest) first, then remove duplicates on MRNClean: the first row it meets is then the newest.
A9: B5 | B9: The rule "keep the latest row" decides which registration survives into the master list, and it can throw away good data. How many kept rows have an empty PhoneClean even though another registration for the same patient has a phone number? | C9: 2 | D9: =SUMPRODUCT(Clean!S2:S651*(Clean!N2:N651="")*(COUNTIFS(Clean!Q2:Q651,Clean!Q2:Q651,Clean!N2:N651,"?*")>0)) | E9: — | F9: When its criteria argument is a range instead of a single value, COUNTIFS returns one count per row: how many rows share this row's MRN and have a phone. The criteria "?*" means at least one character, which works because PhoneClean is text. Multiply by Keep and by an empty PhoneClean to find the 2 patients who would arrive in the new EHR with no phone, although an older registration has one. Real master patient index (MPI) loads prevent this with survivorship rules, which decide field by field which value survives. A common rule takes each field from the most recent row that has it filled in, instead of taking every field from the most recent row.
