Workbook

Sheet Start Here
B2: Lesson 2.3
B3: Dates & Times
B4: Beginner → Intermediate · about 55 minutes · Bluestone Health System (fictional)
B6: What you'll learn
B7: • | C7: Understand date serial numbers and times as fractions of a day
B8: • | C8: Build and take apart dates with DATE, YEAR, MONTH, DAY, WEEKDAY, EOMONTH, and EDATE
B9: • | C9: Calculate ages, lengths of stay, and turnaround times (DATEDIF, YEARFRAC, NETWORKDAYS, WORKDAY)
B10: • | C10: Do time math for ED waits and overnight shifts (MOD, [h]:mm)
B12: How to use this workbook
B13: 1. Read the guide | C13: The lesson guide (README) explains each skill with examples: https://github.com/lmansf/learn-excel/tree/main/02-formulas-functions/03-date-time-functions
B14: 2. Practice | C14: Go to the 'Practice' sheet. Type a formula or value into each yellow cell.
B15: 3. Check yourself | C15: The Check column shows ✔ Correct (green) or ✘ Not yet (red). Tasks marked 'See key' are checked by comparing with the answer key.
B16: 4. Bonus | C16: Finished? Try the harder 'Bonus' sheet.
B17: 5. Answers | C17: The 'Answer Key' and 'Bonus Key' sheets are hidden. Right-click any sheet tab → Unhide… → pick one → OK. (Try first!)
B18: Note | C18: Settings!B2 holds the report date (12/31/2025). Use it wherever a task says "as of" or "today". TODAY() would give a different answer every day you open the file.
B19: Note | C19: The two-midnight rule in the bonus is simplified for teaching date math. It is not billing or clinical guidance.
B21: Color legend
B22: Yellow cell | C22: Your answer goes here.
B23: Gray cell | C23: Pre-filled summary formula — it reads the work you did on another sheet.
B24: ✔ Correct | C24: Your answer matches the key.
B25: ✘ Not yet | C25: Not matching yet — check the hint and try again.
B27: Sheets in this workbook
B28: Stays | C28: Data: 369 rows — Excel Table 'tblStays'
B29: Claims | C29: Data: 369 rows — Excel Table 'tblClaims'
B30: ED | C30: Data: 226 rows — Excel Table 'tblED'
B31: Shifts | C31: Data: 185 rows — Excel Table 'tblShifts'
B32: Holidays | C32: Data: 18 rows — Excel Table 'tblHolidays'
B33: Settings | C33: Data: 1 rows
B34: About the data | C34: All 369 inpatient stays admitted at Ashby Falls Community Hospital in 2025 (with each patient's date of birth and, for ED admissions, the ED arrival time), the insurance claim for each stay, and the hospital's 226 emergency department visits in Q4 2025. The workbook also has one pay week (December 14–20, 2025) of worked shifts on Medical-Surgical 4 West at Bluestone Memorial Hospital and the business office's 2025–2026 holiday calendar.
B35: Disclaimer | C35: All people, places, and numbers are synthetic and fictional. Not clinical guidance.

Sheet Practice
A1: Lesson 2.3 · Practice
A2: Tasks 1–7 use the Stays sheet, 8–11 the Claims sheet, 12 the ED sheet, and 13 the Shifts sheet. Settings!B2 holds the report date (12/31/2025) and the Holidays sheet lists the business office's holidays. When a formula on this sheet points at a data sheet, include the sheet name, as in Stays!G2:G370, or click the cells on that sheet and Excel adds the name for you. (Selecting a whole Table column may write tblStays[AdmitDateTime] instead, which works the same.) Several tasks ask you to fill a yellow column on a data sheet: type the formula in the first data row and the Table fills the rest (if it doesn't, double-click the fill handle). The gray cell on this sheet then summarizes your column.
A3: Type a formula or value in each yellow cell. The Check column turns green when your answer matches. Stuck? Read the hint, then the lesson guide. Answers: right-click a sheet tab → Unhide… → 'Answer Key'.
A4: ="Score: "&COUNTIF(E6:E18,"✔*")&" of 13 auto-checked tasks correct"
A5: # | B5: Task | C5: Hint | D5: Your Answer | E5: Check
A6: 1 | B6: Stays!G2 shows the first admission of 2025: 01/01/2025 21:09. What number does Excel actually store in that cell? Enter a formula that refers to the cell. The answer cell is already formatted to show 5 decimal places, so you'll see the stored number instead of a date. | C6: A date-time is one number: whole days since 1900, plus a fraction of a day | E6: =IF(IFERROR(D6="",FALSE),"",IF(IFERROR(AND(ISNUMBER(D6),OR(ABS(D6-'Answer Key'!$C$5)<=0.0001)),FALSE),"✔ Correct","✘ Not yet"))
A7: 2 | B7: The patient in Stays row 15 (encounter ENC110973) was 64 at admission. On what date does the patient turn 65, the usual age of Medicare eligibility? Use the DOB in that row. | C7: EDATE moves a date by whole months. How many months are in 65 years? | E7: =IF(IFERROR(D7="",FALSE),"",IF(IFERROR(AND(ISNUMBER(D7),INT(D7)=INT('Answer Key'!$C$6)),FALSE),"✔ Correct","✘ Not yet"))
A8: 3 | B8: Fill the yellow AgeAtAdmit column on the Stays sheet with each patient's age in completed years on the admit date. Start in I2. The gray cell averages your column. What was the average age at admission? | C8: DATEDIF(start_date, end_date, "Y") counts completed years. Type it in full, because Excel won't suggest it | D8: {=IF(COUNT('Stays'!$I$2:$I$370)=0,"",AVERAGE('Stays'!$I$2:$I$370))} | E8: =IF(IFERROR(D8="",FALSE),"",IF(IFERROR(AND(ISNUMBER(D8),OR(ABS(D8-'Answer Key'!$C$7)<=0.0001)),FALSE),"✔ Correct","✘ Not yet"))
A9: 4 | B9: The youngest patient (Stays row 42, encounter ENC112029) was an infant. Calculate the exact age in years at admission with YEARFRAC, using basis 1 (actual/actual). Round to 2 decimal places. | C9: YEARFRAC(start_date, end_date, basis). Don't skip the third argument | E9: =IF(IFERROR(D9="",FALSE),"",IF(IFERROR(AND(ISNUMBER(D9),OR(ABS(D9-'Answer Key'!$C$8)<=0.0051)),FALSE),"✔ Correct","✘ Not yet"))
A10: 5 | B10: How many stays were admitted on a weekend (Saturday or Sunday)? Use the AdmitDateTime column. | C10: WEEKDAY with return_type 2 numbers Monday as 1 and Sunday as 7 | E10: =IF(IFERROR(D10="",FALSE),"",IF(IFERROR(AND(ISNUMBER(D10),OR(ABS(D10-'Answer Key'!$C$9)<=0.0001)),FALSE),"✔ Correct","✘ Not yet"))
A11: 6 | B11: How many stays were admitted in April 2025? Compare AdmitDateTime with dates you build with DATE. | C11: On or after April 1, and before May 1 | E11: =IF(IFERROR(D11="",FALSE),"",IF(IFERROR(AND(ISNUMBER(D11),OR(ABS(D11-'Answer Key'!$C$10)<=0.0001)),FALSE),"✔ Correct","✘ Not yet"))
A12: 7 | B12: Fill the yellow LOSDays column with each stay's length of stay in days, including the fraction of a day (DischargeDateTime minus AdmitDateTime). Start in J2. The gray cell averages your column. What was the average length of stay? | C12: Later date-time minus earlier date-time gives days | D12: {=IF(COUNT('Stays'!$J$2:$J$370)=0,"",AVERAGE('Stays'!$J$2:$J$370))} | E12: =IF(IFERROR(D12="",FALSE),"",IF(IFERROR(AND(ISNUMBER(D12),OR(ABS(D12-'Answer Key'!$C$11)<=0.0051)),FALSE),"✔ Correct","✘ Not yet"))
A13: 8 | B13: Ashby Falls' billing standard says a claim must be submitted by the last day of the month after the month of service. What is the deadline for claim CLM511227 (Claims row 29, ServiceDate 01/30/2025)? | C13: EOMONTH(start_date, months) returns the last day of a month | E13: =IF(IFERROR(D13="",FALSE),"",IF(IFERROR(AND(ISNUMBER(D13),INT(D13)=INT('Answer Key'!$C$12)),FALSE),"✔ Correct","✘ Not yet"))
A14: 9 | B14: Fill the yellow DaysToPay column on the Claims sheet with the calendar days from SubmitDate to PaidDate. 94 claims have no PaidDate yet, so make those rows return "" (empty text). Start in H2. The gray cell averages your column. What is the average days to pay? | C14: Test for a blank PaidDate with IF before you subtract | D14: {=IF(COUNT('Claims'!$H$2:$H$370)=0,"",AVERAGE('Claims'!$H$2:$H$370))} | E14: =IF(IFERROR(D14="",FALSE),"",IF(IFERROR(AND(ISNUMBER(D14),OR(ABS(D14-'Answer Key'!$C$13)<=0.0051)),FALSE),"✔ Correct","✘ Not yet"))
A15: 10 | B15: Claim CLM520056 (Claims row 307) is still Pending. As of the report date in Settings!B2, how many business days has it been waiting? Count from its SubmitDate through the report date, both days included, skipping weekends and the dates on the Holidays sheet. | C15: NETWORKDAYS(start_date, end_date, holidays) | E15: =IF(IFERROR(D15="",FALSE),"",IF(IFERROR(AND(ISNUMBER(D15),OR(ABS(D15-'Answer Key'!$C$14)<=0.0001)),FALSE),"✔ Correct","✘ Not yet"))
A16: 11 | B16: Claim CLM517132 (Claims row 207) was only partially paid by Evergreen Mutual Insurance, and the payment posted on its PaidDate. Bluestone Health's policy gives the appeals team 10 business days to send an underpayment appeal, so the deadline is the 10th business day after the PaidDate (the PaidDate itself doesn't count). Weekends and the dates on the Holidays sheet aren't business days. What is the deadline? | C16: WORKDAY(start_date, days, holidays) returns a date | E16: =IF(IFERROR(D16="",FALSE),"",IF(IFERROR(AND(ISNUMBER(D16),INT(D16)=INT('Answer Key'!$C$15)),FALSE),"✔ Correct","✘ Not yet"))
A17: 12 | B17: Fill the yellow DoorToProviderMin column on the ED sheet with the minutes from ArrivalDateTime to ProviderSeenDateTime. 9 patients left without being seen and have no ProviderSeenDateTime, so make those rows return "". Start in H2. The gray cell averages your column. What is the average door-to-provider time in minutes? | C17: A difference of date-times is in days. A day has 24 × 60 = 1,440 minutes | D17: {=IF(COUNT('ED'!$H$2:$H$227)=0,"",AVERAGE('ED'!$H$2:$H$227))} | E17: =IF(IFERROR(D17="",FALSE),"",IF(IFERROR(AND(ISNUMBER(D17),OR(ABS(D17-'Answer Key'!$C$16)<=0.0051)),FALSE),"✔ Correct","✘ Not yet"))
A18: 13 | B18: The Shifts sheet's ClockIn and ClockOut columns hold clock times only, with no dates, and 69 shifts end after midnight. Fill the yellow PaidTime column with each shift's paid time: clock-out minus clock-in, corrected for shifts that cross midnight, minus a 30-minute unpaid meal break. Keep each result as a time value (don't multiply by 24). Start in H2. The gray cell totals your column in [h]:mm format. What is the total paid time for the week? | C18: MOD(…, 1) turns a negative time difference into the right positive one. Half an hour is a time value, not 0.5 | D18: {=IF(COUNT('Shifts'!$H$2:$H$186)=0,"",SUM('Shifts'!$H$2:$H$186))} | E18: =IF(IFERROR(D18="",FALSE),"",IF(IFERROR(AND(ISNUMBER(D18),ABS(D18-'Answer Key'!$C$17)<=0.0006944454444444445),FALSE),"✔ Correct","✘ Not yet"))

Sheet Stays
A1: EncounterID | B1: PatientID | C1: Unit | D1: AdmitSource | E1: DOB | F1: EDArrivalDateTime | G1: AdmitDateTime | H1: DischargeDateTime | I1: AgeAtAdmit | J1: LOSDays | K1: Midnights | L1: BenchMidnights | M1: AdmitDay
A2: ENC110742 | B2: PT13915 | C2: Medical-Surgical | D2: Emergency Department | E2: 16097 | F2: 45658.724 | G2: 45658.881 | H2: 45661.641
A3: ENC110747 | B3: PT11596 | C3: Intensive Care Unit | D3: Emergency Department | E3: 23743 | F3: 45658.946 | G3: 45659.077 | H3: 45667.605
A4: ENC110780 | B4: PT11758 | C4: Medical-Surgical | D4: Emergency Department | E4: 23604 | F4: 45659.619 | G4: 45659.728 | H4: 45663.576
A5: ENC110817 | B5: PT12776 | C5: Medical-Surgical | D5: Emergency Department | E5: 17411 | F5: 45660.535 | G5: 45660.654 | H5: 45666.699
A6: ENC110839 | B6: PT13879 | C6: Labor & Delivery | D6: Emergency Department | E6: 37458 | F6: 45661.136 | G6: 45661.29 | H6: 45662.744
A7: ENC110865 | B7: PT13499 | C7: Medical-Surgical | D7: Emergency Department | E7: 14846 | F7: 45662.574 | G7: 45662.722 | H7: 45667.606
A8: ENC110873 | B8: PT10377 | C8: Labor & Delivery | D8: Direct Admit | E8: 33650 | G8: 45662.844 | H8: 45665.531
A9: ENC110876 | B9: PT12963 | C9: Medical-Surgical | D9: Direct Admit | E9: 12453 | G9: 45663.006 | H9: 45669.469
A10: ENC110882 | B10: PT13910 | C10: Medical-Surgical | D10: Emergency Department | E10: 26674 | F10: 45663.329 | G10: 45663.41 | H10: 45668.64
A11: ENC110924 | B11: PT11972 | C11: Medical-Surgical | D11: Emergency Department | E11: 21123 | F11: 45663.869 | G11: 45664.005 | H11: 45666.544
A12: ENC110927 | B12: PT12927 | C12: Medical-Surgical | D12: Emergency Department | E12: 20933 | F12: 45664.327 | G12: 45664.437 | H12: 45666.664
A13: ENC110953 | B13: PT10534 | C13: Medical-Surgical | D13: Direct Admit | E13: 27763 | G13: 45664.718 | H13: 45668.54
A14: ENC110963 | B14: PT10543 | C14: Labor & Delivery | D14: Emergency Department | E14: 31489 | F14: 45665.046 | G14: 45665.134 | H14: 45668.569
A15: ENC110973 | B15: PT11382 | C15: Medical-Surgical | D15: Transfer | E15: 21994 | G15: 45665.43 | H15: 45669.549
A16: ENC111125 | B16: PT10795 | C16: Medical-Surgical | D16: Direct Admit | E16: 22428 | G16: 45669.66 | H16: 45672.557
A17: ENC111127 | B17: PT10722 | C17: Medical-Surgical | D17: Direct Admit | E17: 29109 | G17: 45669.719 | H17: 45671.581
A18: ENC111120 | B18: PT10900 | C18: Medical-Surgical | D18: Emergency Department | E18: 19534 | F18: 45669.556 | G18: 45669.729 | H18: 45673.511
A19: ENC111170 | B19: PT13907 | C19: Medical-Surgical | D19: Emergency Department | E19: 23924 | F19: 45670.585 | G19: 45670.728 | H19: 45674.668
A20: ENC111191 | B20: PT11514 | C20: Medical-Surgical | D20: Emergency Department | E20: 11881 | F20: 45671.312 | G20: 45671.401 | H20: 45674.651
A21: ENC111227 | B21: PT11854 | C21: Intensive Care Unit | D21: Emergency Department | E21: 13207 | F21: 45672.335 | G21: 45672.418 | H21: 45687.614
A22: ENC111247 | B22: PT10889 | C22: Medical-Surgical | D22: Direct Admit | E22: 25440 | G22: 45672.671 | H22: 45674.825
A23: ENC111321 | B23: PT13041 | C23: Medical-Surgical | D23: Emergency Department | E23: 14226 | F23: 45674.649 | G23: 45674.761 | H23: 45679.665
A24: ENC111328 | B24: PT10739 | C24: Medical-Surgical | D24: Emergency Department | E24: 28168 | F24: 45674.833 | G24: 45674.935 | H24: 45677.43
A25: ENC111388 | B25: PT13563 | C25: Labor & Delivery | D25: Direct Admit | E25: 29947 | G25: 45677.552 | H25: 45680.499
A26: ENC111402 | B26: PT11952 | C26: Intensive Care Unit | D26: Emergency Department | E26: 18313 | F26: 45677.67 | G26: 45677.754 | H26: 45689.581
A27: ENC111416 | B27: PT12298 | C27: Labor & Delivery | D27: Direct Admit | E27: 37351 | G27: 45678.215 | H27: 45681.663
A28: ENC111423 | B28: PT13669 | C28: Medical-Surgical | D28: Emergency Department | E28: 15741 | F28: 45678.433 | G28: 45678.576 | H28: 45683.442
A29: ENC111451 | B29: PT10429 | C29: Medical-Surgical | D29: Emergency Department | E29: 18106 | F29: 45678.683 | G29: 45678.781 | H29: 45681.519
A30: ENC111544 | B30: PT10648 | C30: Medical-Surgical | D30: Emergency Department | E30: 28247 | F30: 45681.219 | G30: 45681.371 | H30: 45682.442
A31: ENC111674 | B31: PT13157 | C31: Medical-Surgical | D31: Transfer | E31: 44652 | G31: 45684.678 | H31: 45687.697
A32: ENC111680 | B32: PT10169 | C32: Medical-Surgical | D32: Emergency Department | E32: 20924 | F32: 45684.81 | G32: 45685.065 | H32: 45687.483
A33: ENC111694 | B33: PT10676 | C33: Medical-Surgical | D33: Emergency Department | E33: 20178 | F33: 45685.49 | G33: 45685.688 | H33: 45689.56
A34: ENC111762 | B34: PT13140 | C34: Medical-Surgical | D34: Emergency Department | E34: 32871 | F34: 45686.698 | G34: 45686.801 | H34: 45697.65
A35: ENC111791 | B35: PT13976 | C35: Medical-Surgical | D35: Emergency Department | E35: 20850 | F35: 45687.494 | G35: 45687.61 | H35: 45690.456
A36: ENC111842 | B36: PT12776 | C36: Medical-Surgical | D36: Emergency Department | E36: 17411 | F36: 45688.619 | G36: 45688.702 | H36: 45691.573
A37: ENC111871 | B37: PT11207 | C37: Medical-Surgical | D37: Emergency Department | E37: 15124 | F37: 45690.091 | G37: 45690.259 | H37: 45695.543
A38: ENC111876 | B38: PT10316 | C38: Medical-Surgical | D38: Emergency Department | E38: 20021 | F38: 45690.41 | G38: 45690.537 | H38: 45692.542
A39: ENC111923 | B39: PT10193 | C39: Labor & Delivery | D39: Direct Admit | E39: 38230 | G39: 45691.626 | H39: 45692.705
A40: ENC111934 | B40: PT10048 | C40: Medical-Surgical | D40: Emergency Department | E40: 45238 | F40: 45691.906 | G40: 45691.985 | H40: 45696.573
...

Sheet Claims
A1: ClaimID | B1: EncounterID | C1: PayerName | D1: ClaimStatus | E1: ServiceDate | F1: SubmitDate | G1: PaidDate | H1: DaysToPay
A2: CLM510742 | B2: ENC110742 | C2: Silverline Medicare Advantage | D2: Paid | E2: 45661 | F2: 45662 | G2: 45695
A3: CLM510839 | B3: ENC110839 | C3: Self-Pay | D3: Pending | E3: 45662 | F3: 45666
A4: CLM510780 | B4: ENC110780 | C4: Self-Pay | D4: Pending | E4: 45663 | F4: 45667
A5: CLM510873 | B5: ENC110873 | C5: State Medicaid | D5: Paid | E5: 45665 | F5: 45668 | G5: 45698
A6: CLM510817 | B6: ENC110817 | C6: Silverline Medicare Advantage | D6: Paid | E6: 45666 | F6: 45670 | G6: 45703
A7: CLM510924 | B7: ENC110924 | C7: Medicare | D7: Paid | E7: 45666 | F7: 45668 | G7: 45676
A8: CLM510927 | B8: ENC110927 | C8: Medicare | D8: Paid | E8: 45666 | F8: 45673 | G8: 45684
A9: CLM510747 | B9: ENC110747 | C9: Keystone Health Partners | D9: Paid | E9: 45667 | F9: 45672 | G9: 45693
A10: CLM510865 | B10: ENC110865 | C10: Medicare | D10: Paid | E10: 45667 | F10: 45676 | G10: 45705
A11: CLM510882 | B11: ENC110882 | C11: Keystone Health Partners | D11: Paid | E11: 45668 | F11: 45675 | G11: 45692
A12: CLM510953 | B12: ENC110953 | C12: Evergreen Mutual Insurance | D12: Partially Paid | E12: 45668 | F12: 45680 | G12: 45708
A13: CLM510963 | B13: ENC110963 | C13: Summit Choice PPO | D13: Paid | E13: 45668 | F13: 45682 | G13: 45701
A14: CLM510876 | B14: ENC110876 | C14: Medicare | D14: Paid | E14: 45669 | F14: 45673 | G14: 45688
A15: CLM510973 | B15: ENC110973 | C15: Medicare | D15: Paid | E15: 45669 | F15: 45677 | G15: 45697
A16: CLM511127 | B16: ENC111127 | C16: Keystone Health Partners | D16: Paid | E16: 45671 | F16: 45673 | G16: 45695
... A19: CLM511170 | B19: ENC111170 | C19: State Medicaid | D19: Paid | E19: 45674 | F19: 45679 | G19: 45708
A20: CLM511191 | B20: ENC111191 | C20: Medicare | D20: Denied | E20: 45674 | F20: 45679
A21: CLM511247 | B21: ENC111247 | C21: Summit Choice PPO | D21: Paid | E21: 45674 | F21: 45676 | G21: 45697
A22: CLM511328 | B22: ENC111328 | C22: State Medicaid | D22: Partially Paid | E22: 45677 | F22: 45687 | G22: 45725
A23: CLM511321 | B23: ENC111321 | C23: Medicare | D23: Paid | E23: 45679 | F23: 45680 | G23: 45694
A24: CLM511388 | B24: ENC111388 | C24: Medicare | D24: Paid | E24: 45680 | F24: 45686 | G24: 45699
A25: CLM511416 | B25: ENC111416 | C25: State Medicaid | D25: Paid | E25: 45681 | F25: 45684 | G25: 45727
A26: CLM511451 | B26: ENC111451 | C26: Silverline Medicare Advantage | D26: Paid | E26: 45681 | F26: 45690 | G26: 45717
A27: CLM511544 | B27: ENC111544 | C27: Self-Pay | D27: Partially Paid | E27: 45682 | F27: 45686 | G27: 45748
A28: CLM511423 | B28: ENC111423 | C28: Silverline Medicare Advantage | D28: Denied | E28: 45683 | F28: 45687
A29: CLM511227 | B29: ENC111227 | C29: Medicare | D29: Paid | E29: 45687 | F29: 45702 | G29: 45711
A30: CLM511674 | B30: ENC111674 | C30: Keystone Health Partners | D30: Paid | E30: 45687 | F30: 45697 | G30: 45727
A31: CLM511680 | B31: ENC111680 | C31: Medicare | D31: Paid | E31: 45687 | F31: 45690 | G31: 45710
A32: CLM511402 | B32: ENC111402 | C32: Silverline Medicare Advantage | D32: Paid | E32: 45689 | F32: 45691 | G32: 45716
A33: CLM511694 | B33: ENC111694 | C33: Medicare | D33: Paid | E33: 45689 | F33: 45697 | G33: 45708
A34: CLM511791 | B34: ENC111791 | C34: Medicare | D34: Paid | E34: 45690 | F34: 45698 | G34: 45715
A35: CLM511842 | B35: ENC111842 | C35: Silverline Medicare Advantage | D35: Paid | E35: 45691 | F35: 45694 | G35: 45724
A36: CLM511876 | B36: ENC111876 | C36: Silverline Medicare Advantage | D36: Denied | E36: 45692 | F36: 45694
A37: CLM511923 | B37: ENC111923 | C37: Self-Pay | D37: Pending | E37: 45692 | F37: 45695
A38: CLM511871 | B38: ENC111871 | C38: Medicare | D38: Paid | E38: 45695 | F38: 45698 | G38: 45710
A39: CLM511934 | B39: ENC111934 | C39: State Medicaid | D39: Paid | E39: 45696 | F39: 45700 | G39: 45731
A40: CLM512029 | B40: ENC112029 | C40: Keystone Health Partners | D40: Paid | E40: 45696 | F40: 45702 | G40: 45737
A41: CLM511762 | B41: ENC111762 | C41: Keystone Health Partners | D41: Paid | E41: 45697 | F41: 45701 | G41: 45719
A42: CLM512082 | B42: ENC112082 | C42: Silverline Medicare Advantage | D42: Appealed | E42: 45697 | F42: 45701
...

Sheet ED
A1: EDVisitID | B1: ESILevel | C1: ArrivalDateTime | D1: TriageDateTime | E1: ProviderSeenDateTime | F1: DepartureDateTime | G1: EDDisposition | H1: DoorToProviderMin
A2: ED210677 | B2: 3 | C2: 45931.786 | D2: 45931.792 | E2: 45931.811 | F2: 45931.967 | G2: Admitted
A3: ED210681 | B3: 3 | C3: 45932.338 | D3: 45932.34 | E3: 45932.362 | F3: 45932.606 | G3: Admitted
A4: ED210691 | B4: 4 | C4: 45932.853 | D4: 45932.858 | E4: 45932.879 | F4: 45932.938 | G4: Discharged
A5: ED210696 | B5: 2 | C5: 45933.245 | D5: 45933.249 | E5: 45933.253 | F5: 45933.478 | G5: Observation
A6: ED210702 | B6: 2 | C6: 45933.506 | D6: 45933.517 | E6: 45933.518 | F6: 45933.704 | G6: Admitted
A7: ED210706 | B7: 3 | C7: 45933.614 | D7: 45933.625 | E7: 45933.638 | F7: 45933.726 | G7: Discharged
A8: ED210707 | B8: 4 | C8: 45933.699 | D8: 45933.704 | E8: 45933.715 | F8: 45933.835 | G8: Admitted
A9: ED210713 | B9: 2 | C9: 45934.122 | D9: 45934.127 | E9: 45934.128 | F9: 45934.31 | G9: Admitted
A10: ED210746 | B10: 2 | C10: 45936.228 | D10: 45936.233 | E10: 45936.24 | F10: 45936.39 | G10: Admitted
A11: ED210753 | B11: 2 | C11: 45936.516 | D11: 45936.519 | E11: 45936.547 | F11: 45936.674 | G11: Discharged
A12: ED210759 | B12: 2 | C12: 45936.639 | D12: 45936.642 | E12: 45936.653 | F12: 45936.885 | G12: Admitted
A13: ED210775 | B13: 3 | C13: 45937.655 | D13: 45937.667 | E13: 45937.667 | F13: 45938.036 | G13: Observation
... A24: ED210825 | B24: 1 | C24: 45940.688 | D24: 45940.688 | E24: 45940.689 | F24: 45940.834 | G24: Admitted
A25: ED210849 | B25: 4 | C25: 45942.408 | D25: 45942.409 | F25: 45942.486 | G25: LWBS
A26: ED210861 | B26: 4 | C26: 45943.309 | D26: 45943.317 | E26: 45943.322 | F26: 45943.393 | G26: Observation
A27: ED210862 | B27: 2 | C27: 45943.516 | D27: 45943.517 | E27: 45943.551 | F27: 45943.785 | G27: Admitted
A28: ED210865 | B28: 4 | C28: 45943.671 | D28: 45943.678 | E28: 45943.756 | F28: 45943.81 | G28: Discharged
A29: ED210876 | B29: 4 | C29: 45944.26 | D29: 45944.271 | E29: 45944.277 | F29: 45944.312 | G29: Discharged
A30: ED210877 | B30: 3 | C30: 45944.37 | D30: 45944.373 | E30: 45944.389 | F30: 45944.466 | G30: Discharged
A31: ED210884 | B31: 3 | C31: 45944.662 | D31: 45944.664 | E31: 45944.694 | F31: 45944.85 | G31: Discharged
A32: ED210894 | B32: 5 | C32: 45945.1 | D32: 45945.106 | E32: 45945.136 | F32: 45945.174 | G32: Discharged
A33: ED210933 | B33: 3 | C33: 45947.616 | D33: 45947.618 | E33: 45947.651 | F33: 45947.816 | G33: Discharged
A34: ED210943 | B34: 2 | C34: 45948.003 | D34: 45948.01 | E34: 45948.011 | F34: 45948.616 | G34: Admitted
A35: ED210956 | B35: 2 | C35: 45949.226 | D35: 45949.235 | E35: 45949.235 | F35: 45949.439 | G35: Observation
A36: ED210957 | B36: 4 | C36: 45949.245 | D36: 45949.258 | E36: 45949.262 | F36: 45949.439 | G36: Admitted
A37: ED210959 | B37: 4 | C37: 45949.51 | D37: 45949.513 | E37: 45949.583 | F37: 45949.619 | G37: Discharged
A38: ED210960 | B38: 4 | C38: 45949.557 | D38: 45949.565 | F38: 45949.66 | G38: LWBS
A39: ED210974 | B39: 4 | C39: 45950.526 | D39: 45950.528 | E39: 45950.594 | F39: 45950.628 | G39: Left AMA
A40: ED211006 | B40: 2 | C40: 45952.792 | D40: 45952.8 | E40: 45952.801 | F40: 45953.061 | G40: Admitted
A41: ED211012 | B41: 2 | C41: 45953.2 | D41: 45953.204 | E41: 45953.205 | F41: 45953.347 | G41: Admitted
A42: ED211013 | B42: 2 | C42: 45953.415 | D42: 45953.421 | E42: 45953.424 | F42: 45953.611 | G42: Admitted
A43: ED211038 | B43: 2 | C43: 45954.588 | D43: 45954.59 | E43: 45954.6 | F43: 45954.75 | G43: Admitted
A44: ED211039 | B44: 2 | C44: 45954.594 | D44: 45954.599 | E44: 45954.606 | F44: 45954.84 | G44: Observation
A45: ED211046 | B45: 2 | C45: 45955.465 | D45: 45955.469 | E45: 45955.476 | F45: 45956.394 | G45: Admitted
A46: ED211048 | B46: 3 | C46: 45955.567 | D46: 45955.572 | E46: 45955.596 | F46: 45955.724 | G46: Admitted
A47: ED211056 | B47: 2 | C47: 45956.574 | D47: 45956.579 | E47: 45956.59 | F47: 45956.778 | G47: Admitted
A48: ED211086 | B48: 4 | C48: 45957.806 | D48: 45957.81 | E48: 45957.858 | F48: 45957.928 | G48: Admitted
A49: ED211089 | B49: 3 | C49: 45957.928 | D49: 45957.931 | E49: 45957.95 | F49: 45958.181 | G49: Admitted
A50: ED211093 | B50: 2 | C50: 45958.405 | D50: 45958.41 | E50: 45958.412 | F50: 45958.654 | G50: Admitted
...

Sheet Shifts
A1: ShiftID | B1: EmployeeID | C1: JobTitle | D1: ShiftDate | E1: ShiftType | F1: ClockIn | G1: ClockOut | H1: PaidTime
A2: SH915361 | B2: EMP2060 | C2: Registered Nurse | D2: 46005 | E2: Day 12h | F2: 0.28958333 | G2: 0.81458333
A3: SH915362 | B3: EMP2070 | C3: Registered Nurse | D3: 46005 | E3: Day 12h | F3: 0.28263889 | G3: 0.81944444
A4: SH915363 | B4: EMP2073 | C4: Registered Nurse | D4: 46005 | E4: Day 12h | F4: 0.28819444 | G4: 0.81388889
A5: SH915364 | B5: EMP2074 | C5: Registered Nurse | D5: 46005 | E5: Day 12h | F5: 0.28958333 | G5: 0.81944444
A6: SH915365 | B6: EMP2075 | C6: Registered Nurse | D6: 46005 | E6: Day 12h | F6: 0.29236111 | G6: 0.81805556
A7: SH915366 | B7: EMP2086 | C7: Registered Nurse | D7: 46005 | E7: Day 12h | F7: 0.28125 | G7: 0.81388889
A8: SH915367 | B8: EMP2087 | C8: Registered Nurse | D8: 46005 | E8: Day 12h | F8: 0.28888889 | G8: 0.81597222
A9: SH915368 | B9: EMP2089 | C9: Registered Nurse | D9: 46005 | E9: Day 12h | F9: 0.2875 | G9: 0.80972222
A10: SH915369 | B10: EMP2096 | C10: Registered Nurse | D10: 46005 | E10: Day 12h | F10: 0.28888889 | G10: 0.81736111
A11: SH915370 | B11: EMP2101 | C11: Registered Nurse | D11: 46005 | E11: Day 12h | F11: 0.29097222 | G11: 0.82083333
A12: SH915371 | B12: EMP2112 | C12: Certified Nursing Assistant | D12: 46005 | E12: Day 12h | F12: 0.28472222 | G12: 0.88125
A13: SH915372 | B13: EMP2114 | C13: Certified Nursing Assistant | D13: 46005 | E13: Day 12h | F13: 0.28958333 | G13: 0.81388889
... A186: SH916782 | B186: EMP2115 | C186: Certified Nursing Assistant | D186: 46011 | E186: Night 12h | F186: 0.7875 | G186: 0.32291667

Sheet Holidays
A1: Date | B1: Holiday | C1: Day
A2: 45658 | B2: New Year's Day | C2: Wed
A3: 45677 | B3: Martin Luther King Jr. Day | C3: Mon
A4: 45803 | B4: Memorial Day | C4: Mon
A5: 45827 | B5: Juneteenth | C5: Thu
A6: 45842 | B6: Independence Day | C6: Fri
A7: 45901 | B7: Labor Day | C7: Mon
A8: 45988 | B8: Thanksgiving Day | C8: Thu
A9: 45989 | B9: Day after Thanksgiving | C9: Fri
A10: 46016 | B10: Christmas Day | C10: Thu
A11: 46023 | B11: New Year's Day | C11: Thu
A12: 46041 | B12: Martin Luther King Jr. Day | C12: Mon
A13: 46167 | B13: Memorial Day | C13: Mon
... A19: 46381 | B19: Christmas Day | C19: Fri

Sheet Settings
A1: Setting | B1: Value | C1: Notes
A2: ReportDate | B2: 46022 | C2: The course's 'today'. Use this cell instead of TODAY() so your answers never change.

Sheet Bonus
A1: Lesson 2.3 · Bonus: The two-midnight check
A2: Ashby Falls' utilization review nurse is preparing for a Medicare audit. Under the CMS two-midnight benchmark, an inpatient admission is generally expected to span at least two midnights of hospital care. This bonus uses a simplified, educational version (not billing guidance): count the midnights between two date-times by comparing their dates, not the hours between them. The nurse also wants to know whether the day of the week a patient is admitted affects how long they stay. Fill the yellow Midnights, BenchMidnights, and AdmitDay columns on the Stays sheet as you go. B2, B4, and B5 also use your LOSDays column from task 7.
A3: Type a formula or value in each yellow cell. The Check column turns green when your answer matches. Stuck? Read the hint, then the lesson guide. Answers: right-click a sheet tab → Unhide… → 'Bonus Key'.
A4: ="Score: "&COUNTIF(E6:E10,"✔*")&" of 5 auto-checked tasks correct"
A5: # | B5: Task | C5: Hint | D5: Your Answer | E5: Check
A6: B1 | B6: Fill the Midnights column with the number of midnights each stay crossed between AdmitDateTime and DischargeDateTime. Start in K2. The gray cell counts your rows with 2 or more. How many stays crossed at least two midnights? | C6: INT strips the time from a date-time. Subtract the two dates | D6: {=IF(COUNT('Stays'!$K$2:$K$370)=0,"",COUNTIF('Stays'!$K$2:$K$370,">=2"))} | E6: =IF(IFERROR(D6="",FALSE),"",IF(IFERROR(AND(ISNUMBER(D6),OR(ABS(D6-'Bonus Key'!$C$5)<=0.0001)),FALSE),"✔ Correct","✘ Not yet"))
A7: B2 | B7: How many stays crossed two or more midnights even though they lasted LESS than 48 hours? | C7: Two conditions on two of your columns: multiply the TRUE/FALSE lists. 48 hours is 2 days | E7: =IF(IFERROR(D7="",FALSE),"",IF(IFERROR(AND(ISNUMBER(D7),OR(ABS(D7-'Bonus Key'!$C$6)<=0.0001)),FALSE),"✔ Correct","✘ Not yet"))
A8: B3 | B8: CMS starts the benchmark clock when hospital care begins, which for ED admissions is the ED arrival, not the inpatient admit order. Fill the BenchMidnights column: midnights from EDArrivalDateTime to DischargeDateTime, or from AdmitDateTime when EDArrivalDateTime is blank. Start in L2. The gray cell counts your rows with 2 or more. How many stays meet the benchmark when ED time counts? | C8: Use IF to pick the clock start for each row, then count midnights the same way as in B1 | D8: {=IF(COUNT('Stays'!$L$2:$L$370)=0,"",COUNTIF('Stays'!$L$2:$L$370,">=2"))} | E8: =IF(IFERROR(D8="",FALSE),"",IF(IFERROR(AND(ISNUMBER(D8),OR(ABS(D8-'Bonus Key'!$C$7)<=0.0001)),FALSE),"✔ Correct","✘ Not yet"))
A9: B4 | B9: Fill the AdmitDay column with the weekday name of each AdmitDateTime (Monday, Tuesday, …). Start in M2. What was the average length of stay, in HOURS, for patients admitted on a Friday? Use your LOSDays column and round to 1 decimal place. | C9: TEXT(date, "dddd") gives the weekday name. AVERAGEIF (a preview of Lesson 2.5) or AVERAGE(IF(…)) averages the Friday rows | E9: =IF(IFERROR(D9="",FALSE),"",IF(IFERROR(AND(ISNUMBER(D9),OR(ABS(D9-'Bonus Key'!$C$8)<=0.051)),FALSE),"✔ Correct","✘ Not yet"))
A10: B5 | B10: Which weekday of admission has the LONGEST average length of stay? Type the weekday name. | C10: Build a small seven-row table of averages, one per weekday | E10: =IF(IFERROR(D10="",FALSE),"",IF(IFERROR(OR(LOWER(TRIM(D10&""))=LOWER(TRIM('Bonus Key'!$C$9&"")),LOWER(TRIM(D10&""))="thu"),FALSE),"✔ Correct","✘ Not yet"))

Sheet Answer Key
A1: 🔑 Answer Key — Lesson 2.3
A2: Spoiler alert — try every task before reading this sheet. Column C is the value the Check column compares against. Column D is a sample solution; column E is that same formula, live, proving it works.
A4: # | B4: Task | C4: Answer | D4: Sample solution | E4: Live result | F4: Explanation
A5: 1 | B5: Stays!G2 shows the first admission of 2025: 01/01/2025 21:09. What number does Excel actually store in that cell? Enter a formula that refers to the cell. The answer cell is already formatted to show 5 decimal places, so you'll see the stored number instead of a date. | C5: 45658.881 | D5: =Stays!G2 | E5: {=Stays!G2} | F5: The whole part, 45,658, is the date serial number: January 1, 2025 is day 45,658 counting from January 1, 1900. The decimal part, 0.88125, is the time as a fraction of a 24-hour day: 21:09 is 1,269 minutes ÷ 1,440 minutes per day. You can also see the number by giving the cell the General format with Ctrl + Shift + ~ (Mac: Control + Shift + ~). Because dates and times are numbers, you can add, subtract, and compare them.
A6: 2 | B6: The patient in Stays row 15 (encounter ENC110973) was 64 at admission. On what date does the patient turn 65, the usual age of Medicare eligibility? Use the DOB in that row. | C6: 45735 | D6: =EDATE(Stays!E15,65*12) | E6: {=EDATE(Stays!E15,65*12)} | F6: EDATE moves a date forward (or back) by whole months and keeps the day number, so 65 × 12 = 780 months after the DOB is the 65th birthday. =DATE(YEAR(Stays!E15)+65,MONTH(Stays!E15),DAY(Stays!E15)) gives the same date. It takes the date apart with YEAR, MONTH, and DAY, adds 65 to the year, and builds it again with DATE. Adding 65 × 365 days would land 16 days early, because it ignores the 16 leap days in between.
A7: 3 | B7: Fill the yellow AgeAtAdmit column on the Stays sheet with each patient's age in completed years on the admit date. Start in I2. The gray cell averages your column. What was the average age at admission? | C7: 58.124661 | D7: =DATEDIF(E2,G2,"Y") | E7: {=SUMPRODUCT(YEAR(Stays!G2:G370)-YEAR(Stays!E2:E370)-((MONTH(Stays!G2:G370)*100+DAY(Stays!G2:G370))<(MONTH(Stays!E2:E370)*100+DAY(Stays!E2:E370))))/COUNT(Stays!E2:E370)} | F7: DATEDIF counts whole birthdays passed, which is how age is stated on a chart. Shortcuts like =INT((G2-E2)/365) drift by a day for every leap year lived, and in this data they make 14 patients a year too old. Excel doesn't list DATEDIF in AutoComplete or Insert Function, so type it in full. The start date must come first, or DATEDIF returns #NUM!. 159 of the 369 patients were 65 or older at admission.
A8: 4 | B8: The youngest patient (Stays row 42, encounter ENC112029) was an infant. Calculate the exact age in years at admission with YEARFRAC, using basis 1 (actual/actual). Round to 2 decimal places. | C8: 0.7 | D8: =ROUND(YEARFRAC(Stays!E42,Stays!G42,1),2) | E8: {=ROUND(YEARFRAC(Stays!E42,Stays!G42,1),2)} | F8: YEARFRAC returns the fraction of a year between two dates: 0.6959 here. Basis 1 counts the real days (254 of them) and divides by the real length of the year. Without the basis argument YEARFRAC uses basis 0 (the 30/360 banking convention, where every month has 30 days) and returns 0.6889, which rounds to 0.69. Use basis 1 for ages. For infants, clinicians usually state age in months instead: =DATEDIF(Stays!E42,Stays!G42,"M") returns 8.
A9: 5 | B9: How many stays were admitted on a weekend (Saturday or Sunday)? Use the AdmitDateTime column. | C9: 95 | D9: =SUMPRODUCT(--(WEEKDAY(Stays!G2:G370,2)>5)) | E9: {=SUMPRODUCT(--(WEEKDAY(Stays!G2:G370,2)>5))} | F9: WEEKDAY(date,2) returns 1 for Monday through 7 for Sunday, so Saturday and Sunday are exactly the values above 5. Comparing the whole column gives a list of TRUE/FALSE values, -- turns them into 1s and 0s, and SUMPRODUCT adds them (Lesson 2.1). With the default return_type 1 (Sunday = 1, Saturday = 7) you'd need two tests: =SUMPRODUCT((WEEKDAY(Stays!G2:G370)=1)+(WEEKDAY(Stays!G2:G370)=7)).
A10: 6 | B10: How many stays were admitted in April 2025? Compare AdmitDateTime with dates you build with DATE. | C10: 27 | D10: =SUMPRODUCT((Stays!G2:G370>=DATE(2025,4,1))*(Stays!G2:G370<DATE(2025,5,1))) | E10: {=SUMPRODUCT((Stays!G2:G370>=DATE(2025,4,1))*(Stays!G2:G370<DATE(2025,5,1)))} | F10: DATE(2025,4,1) builds the serial number for April 1, and multiplying the two TRUE/FALSE lists keeps only rows that pass both tests (AND logic). The upper bound is before May 1, not on or before April 30. AdmitDateTime includes a time, so 04/30/2025 19:59 is *greater* than DATE(2025,4,30), which means midnight. <=DATE(2025,4,30) would miss the 3 admissions on April 30 and return 24. =SUMPRODUCT((MONTH(Stays!G2:G370)=4)*(YEAR(Stays!G2:G370)=2025)) also works.
A11: 7 | B11: Fill the yellow LOSDays column with each stay's length of stay in days, including the fraction of a day (DischargeDateTime minus AdmitDateTime). Start in J2. The gray cell averages your column. What was the average length of stay? | C11: 4.5442299 | D11: =H2-G2 | E11: {=(SUM(Stays!H2:H370)-SUM(Stays!G2:G370))/COUNT(Stays!G2:G370)} | F11: Subtracting two date-times gives the elapsed days, with the hours as a decimal: 2.50 is two and a half days. The LOSDays column is already formatted as a number. In a General cell, Excel may copy the date format from the cells you referenced and show 4.5 days as 01/04/1900 12:00, so change the format to Number when that happens. Multiply by 24 to get hours. The live formula in the key uses a shortcut: the sum of the differences equals the difference of the sums.
A12: 8 | B12: Ashby Falls' billing standard says a claim must be submitted by the last day of the month after the month of service. What is the deadline for claim CLM511227 (Claims row 29, ServiceDate 01/30/2025)? | C12: 45716 | D12: =EOMONTH(Claims!E29,1) | E12: {=EOMONTH(Claims!E29,1)} | F12: EOMONTH(date,0) is the last day of the date's own month, and EOMONTH(date,1) is the last day of the next month. It handles 28-, 29-, 30-, and 31-day months for you. Adding 30 days instead would give 03/01/2025, which is in the wrong month. =EOMONTH(date,-1)+1 gives the first day of the date's month, another pattern you'll use often.
A13: 9 | B13: Fill the yellow DaysToPay column on the Claims sheet with the calendar days from SubmitDate to PaidDate. 94 claims have no PaidDate yet, so make those rows return "" (empty text). Start in H2. The gray cell averages your column. What is the average days to pay? | C13: 27.621818 | D13: =IF(G2="","",G2-F2) | E13: {=SUMPRODUCT((Claims!G2:G370<>"")*(Claims!G2:G370-Claims!F2:F370))/COUNT(Claims!G2:G370)} | F13: An empty PaidDate counts as 0 in arithmetic, so a bare =G2-F2 returns minus the submit date's serial number for every unpaid claim (−45,666 for the first one), which wrecks the average. The IF returns empty text for those rows, and AVERAGE ignores text. =IF(G2="","",DAYS(G2,F2)) gives the same result. Notice that DAYS takes the end date first, and that it needs the same blank guard.
A14: 10 | B14: Claim CLM520056 (Claims row 307) is still Pending. As of the report date in Settings!B2, how many business days has it been waiting? Count from its SubmitDate through the report date, both days included, skipping weekends and the dates on the Holidays sheet. | C14: 28 | D14: =NETWORKDAYS(Claims!F307,Settings!$B$2,Holidays!$A$2:$A$19) | E14: {=NETWORKDAYS(Claims!F307,Settings!$B$2,Holidays!$A$2:$A$19)} | F14: NETWORKDAYS counts Monday-to-Friday dates from the start date through the end date, including both, and skips any date in the holidays range. Without the holiday list the answer would be 31. The three missing days are Thanksgiving, the day after, and Christmas. The $ signs lock the Settings and Holidays references, so you can copy the formula down a column without them moving.
A15: 11 | B15: Claim CLM517132 (Claims row 207) was only partially paid by Evergreen Mutual Insurance, and the payment posted on its PaidDate. Bluestone Health's policy gives the appeals team 10 business days to send an underpayment appeal, so the deadline is the 10th business day after the PaidDate (the PaidDate itself doesn't count). Weekends and the dates on the Holidays sheet aren't business days. What is the deadline? | C15: 45994 | D15: =WORKDAY(Claims!G207,10,Holidays!$A$2:$A$19) | E15: {=WORKDAY(Claims!G207,10,Holidays!$A$2:$A$19)} | F15: WORKDAY steps forward the given number of business days, never counting the start date itself, and skips weekends and holidays. This window crosses 2 holidays (Thanksgiving Day, Day after Thanksgiving). Without the holiday list WORKDAY would return 12/01/2025, 2 days too early. WORKDAY returns a serial number, so if you see a number like 46000 instead of a date, give the cell a Date format. NETWORKDAYS measures a span you already have, and WORKDAY finds the date at the end of a span.
A16: 12 | B16: Fill the yellow DoorToProviderMin column on the ED sheet with the minutes from ArrivalDateTime to ProviderSeenDateTime. 9 patients left without being seen and have no ProviderSeenDateTime, so make those rows return "". Start in H2. The gray cell averages your column. What is the average door-to-provider time in minutes? | C16: 49.147465 | D16: =IF(E2="","",(E2-C2)*1440) | E16: {=SUMPRODUCT((ED!E2:E227<>"")*(ED!E2:E227-ED!C2:C227))*1440/COUNT(ED!E2:E227)} | F16: Subtracting gives a fraction of a day (0.0347 is 50 minutes), and multiplying by 1,440 converts days to minutes. Because these columns hold the full date *and* time, visit ED211281 (arrived 23:51, seen at 00:03 the next morning) still gives a positive 12 minutes, with no special handling. The IF keeps LWBS visits out of the average instead of counting them as huge negative waits.
A17: 13 | B17: The Shifts sheet's ClockIn and ClockOut columns hold clock times only, with no dates, and 69 shifts end after midnight. Fill the yellow PaidTime column with each shift's paid time: clock-out minus clock-in, corrected for shifts that cross midnight, minus a 30-minute unpaid meal break. Keep each result as a time value (don't multiply by 24). Start in H2. The gray cell totals your column in [h]:mm format. What is the total paid time for the week? | C17: 92.241667 | D17: =MOD(G2-F2,1)-TIME(0,30,0) | E17: {=SUMPRODUCT(MOD(Shifts!G2:G186-Shifts!F2:F186,1))-COUNT(Shifts!F2:F186)*TIME(0,30,0)} | F17: Shift SH915484 clocked in at 18:48 and out at 08:20. 08:20 − 18:48 is negative (−0.4361 of a day). MOD(…, 1) adds one whole day to a negative result and leaves positive results alone, so the shift becomes 13:32. Subtract the meal break as a time, TIME(0,30,0) or "0:30" or 30/1440. Subtracting 0.5 would remove half a *day*. The total is 2,213.8 hours, so it needs [h]:mm. Plain h:mm would wrap past every 24 hours and show only the leftover hours. Without MOD the week totals 557.8 hours, because every overnight shift comes out negative. The PaidTime column is formatted h:mm, so a shift that comes out negative shows ######## instead of a time.

Sheet Bonus Key
A1: 🔑 Bonus Key — Lesson 2.3
A2: Spoiler alert — try every task before reading this sheet. Column C is the value the Check column compares against. Column D is a sample solution; column E is that same formula, live, proving it works.
A4: # | B4: Task | C4: Answer | D4: Sample solution | E4: Live result | F4: Explanation
A5: B1 | B5: Fill the Midnights column with the number of midnights each stay crossed between AdmitDateTime and DischargeDateTime. Start in K2. The gray cell counts your rows with 2 or more. How many stays crossed at least two midnights? | C5: 356 | D5: =INT(H2)-INT(G2) | E5: {=SUMPRODUCT(--((INT(Stays!H2:H370)-INT(Stays!G2:G370))>=2))} | F5: INT(date-time) drops the decimal part, leaving the date at midnight. The difference between two dates is the number of midnights crossed: admitted Monday 23:00 and discharged Wednesday 01:00 is 2 midnights in only 26 hours. Rounding LOSDays doesn't work: that stay's LOSDays is 1.08, which rounds to 1. 13 stays fall short of the benchmark.
A6: B2 | B6: How many stays crossed two or more midnights even though they lasted LESS than 48 hours? | C6: 28 | D6: =SUMPRODUCT((Stays!K2:K370>=2)*(Stays!J2:J370<2)) | E6: {=SUMPRODUCT(((INT(Stays!H2:H370)-INT(Stays!G2:G370))>=2)*((Stays!H2:H370-Stays!G2:G370)<2))} | F6: LOSDays measures elapsed time, and 2 days is 48 hours. Midnights measures calendar dates. A patient admitted late in the evening crosses a midnight within minutes, so a stay of 30 hours can span 2 midnights. That's why a two-midnight review can't use "LOS ≥ 2 days" as a shortcut.
A7: B3 | B7: CMS starts the benchmark clock when hospital care begins, which for ED admissions is the ED arrival, not the inpatient admit order. Fill the BenchMidnights column: midnights from EDArrivalDateTime to DischargeDateTime, or from AdmitDateTime when EDArrivalDateTime is blank. Start in L2. The gray cell counts your rows with 2 or more. How many stays meet the benchmark when ED time counts? | C7: 357 | D7: =INT(H2)-INT(IF(F2="",G2,F2)) | E7: {=SUMPRODUCT(--((INT(Stays!H2:H370)-(INT(Stays!G2:G370)*(Stays!F2:F370="")+INT(Stays!F2:F370)*(Stays!F2:F370<>"")))>=2))} | F7: The IF picks the start of care for each row, and INT turns it into a date. 23 ED patients arrived before midnight and were admitted after it, so each gains a midnight. Only 1 of them moves from below the benchmark to meeting it. The rest already had 2 or more. =INT(H2)-INT(MIN(F2:G2)) is a shorter trick that works because MIN ignores the blank cell, but the IF says what you mean.
A8: B4 | B8: Fill the AdmitDay column with the weekday name of each AdmitDateTime (Monday, Tuesday, …). Start in M2. What was the average length of stay, in HOURS, for patients admitted on a Friday? Use your LOSDays column and round to 1 decimal place. | C8: 108.3 | D8: =ROUND(AVERAGEIF(Stays!M2:M370,"Friday",Stays!J2:J370)*24,1) | E8: {=ROUND(SUMPRODUCT((WEEKDAY(Stays!G2:G370,2)=5)*(Stays!H2:H370-Stays!G2:G370))*24/SUMPRODUCT(--(WEEKDAY(Stays!G2:G370,2)=5)),1)} | F8: Fill AdmitDay with =TEXT(G2,"dddd"), which returns full weekday names. AVERAGEIF averages the LOSDays values on rows where AdmitDay is "Friday", and × 24 converts days to hours. The array formula from Lesson 2.1, =ROUND(AVERAGE(IF(Stays!M2:M370="Friday",Stays!J2:J370))*24,1), also works. Microsoft 365 and Excel 2021 calculate it automatically, and Excel 2019 and earlier need Ctrl + Shift + Enter (Mac: ⌘ + Shift + Return). TEXT returns weekday names in your Office language, so a German Excel shows "Freitag".
A9: B5 | B9: Which weekday of admission has the LONGEST average length of stay? Type the weekday name. | C9: Thursday | D9: 1. On the Bonus sheet, type Monday in G2 and drag the fill handle down to G8. AutoFill (Lesson 1.2) completes the week through Sunday. 2. In H2, enter `=AVERAGEIF(Stays!$M$2:$M$370,G2,Stays!$J$2:$J$370)*24` and fill it down to H8. 3. Find the largest average by eye, or let Excel find it: `=INDEX(G2:G8,MATCH(MAX(H2:H8),H2:H8,0))` (INDEX and MATCH are covered in Lesson 2.6). | E9: — | F9: Thursday admissions stay longest, at 121.8 hours on average, against 113.1 for Monday, the runner-up, and 98.8 for Sunday. A weekly pattern like this often points to weekend gaps in services: a patient admitted late in the week may wait through the weekend for a test, a procedure, or a discharge placement.
