Workbook

Sheet Start Here
B2: Lesson 4.2
B3: Advanced Formulas: LET, LAMBDA & Array Logic
B4: Advanced · about 65 minutes · Bluestone Health System (fictional)
B6: What you'll learn
B7: • | C7: Write multi-condition array logic with SUMPRODUCT and boolean math
B8: • | C8: Make complex formulas readable and fast with LET
B9: • | C9: Create reusable custom functions with LAMBDA and the Name Manager
B10: • | C10: Use MAP, REDUCE, SCAN, BYROW, and audit formulas with Evaluate Formula
B12: How to use this workbook
B13: 1. Read the guide | C13: The lesson guide (README) explains each skill with examples: https://github.com/lmansf/learn-excel/tree/main/04-advanced-analysis/02-advanced-formulas-let-lambda
B14: 2. Practice | C14: Go to the 'Practice' sheet. Type a formula or value into each yellow cell.
B15: 3. Check yourself | C15: The Check column shows ✔ Correct (green) or ✘ Not yet (red). Tasks marked 'See key' are checked by comparing with the answer key.
B16: 4. Bonus | C16: Finished? Try the harder 'Bonus' sheet.
B17: 5. Answers | C17: The 'Answer Key' and 'Bonus Key' sheets are hidden. Right-click any sheet tab → Unhide… → pick one → OK. (Try first!)
B18: Note | C18: Tasks that use LAMBDA, MAP, BYROW, SCAN, or REDUCE need Microsoft 365 or Excel 2024. In older versions they show #NAME?, so read those solutions in the lesson README instead. LET, XLOOKUP, and FILTER need Excel 2021 or later.
B19: Note | C19: Answer cells must hold ONE value. Wrap array results in SUM, MAX, or INDEX, and use the Sandbox sheet to watch arrays spill.
B20: Note | C20: The Stays sheet has 5,586 rows, and some of these formulas compare every row with every other row. Excel may pause for a second or two while it recalculates.
B21: Note | C21: Two extra sheets: 'Audit' holds a colleague's broken formula for Task 13, and 'Sandbox' is blank space for watching array formulas spill.
B23: Color legend
B24: Yellow cell | C24: Your answer goes here.
B25: Gray cell | C25: Pre-filled summary formula — it reads the work you did on another sheet.
B26: ✔ Correct | C26: Your answer matches the key.
B27: ✘ Not yet | C27: Not matching yet — check the hint and try again.
B29: Sheets in this workbook
B30: Stays | C30: Data: 5,586 rows — Excel Table 'tblStays'
B31: Diagnoses | C31: Data: 51 rows — Excel Table 'tblDx'
B32: Labs | C32: Data: 1,018 rows — Excel Table 'tblLabs'
B33: Census | C33: Data: 731 rows — Excel Table 'tblCensus'
B34: About the data | C34: All 5,586 inpatient stays at Bluestone's three hospitals, Jan 2024–Dec 2025 (with the Readmit30 flag removed so you can rebuild it), the diagnosis lookup with benchmark LOS, 1,018 lab results from Ashby Falls stays discharged Jul–Dec 2025, and the Bluestone Memorial ICU's daily census for 2024–2025.
B35: Disclaimer | C35: All people, places, and numbers are synthetic and fictional. Not clinical guidance.

Sheet Practice
A1: Lesson 4.2 · Practice
A2: Every task works on the Excel Tables in this workbook. Table references such as tblStays[FacilityID] are the easiest to read, and A1 ranges such as Stays!$C$2:$C$5587 work too. LOS days = discharge date − admit date (midnights), with a minimum of 1 day. Each answer cell must return ONE value, so try array formulas on the Sandbox sheet first.
A3: Type a formula or value in each yellow cell. The Check column turns green when your answer matches. Stuck? Read the hint, then the lesson guide. Answers: right-click a sheet tab → Unhide… → 'Answer Key'.
A4: ="Score: "&COUNTIF(E6:E18,"✔*")&" of 13 auto-checked tasks correct"
A5: # | B5: Task | C5: Hint | D5: Your Answer | E5: Check
A6: 1 | B6: How many inpatient stays were admitted on a Saturday or Sunday in 2025? Use AdmitDateTime for both the weekday and the year. | C6: WEEKDAY(date, 2) numbers Monday as 1 and Sunday as 7. Multiply two TRUE/FALSE arrays inside SUMPRODUCT. | E6: =IF(IFERROR(D6="",FALSE),"",IF(IFERROR(AND(ISNUMBER(D6),OR(ABS(D6-'Answer Key'!$C$5)<=0.0001)),FALSE),"✔ Correct","✘ Not yet"))
A7: 2 | B7: Case management reviews every 2025 discharge that had LOS days of 7 or more OR went to a Skilled Nursing Facility. What were the total charges (TotalCharges) of the stays on that review list? Count each stay once, and enter dollars and cents. | C7: Adding two conditions gives OR logic, but a stay that meets both scores 2. Wrap the OR in (…>0). | E7: =IF(IFERROR(D7="",FALSE),"",IF(IFERROR(AND(ISNUMBER(D7),OR(ABS(D7-'Answer Key'!$C$6)<=0.0051)),FALSE),"✔ Correct","✘ Not yet"))
A8: 3 | B8: The Labs sheet is sorted from oldest to newest CollectedDateTime. What was patient PT11882's most recent creatinine (TestCode CREAT) result? | C8: XLOOKUP can look for 1 in an array of 1s and 0s that you build from two conditions. Its 6th argument chooses the search direction. | E8: =IF(IFERROR(D8="",FALSE),"",IF(IFERROR(AND(ISNUMBER(D8),OR(ABS(D8-'Answer Key'!$C$7)<=0.0051)),FALSE),"✔ Correct","✘ Not yet"))
A9: 4 | B9: Use FREQUENCY with the bins {1,2,3,5,7,14} on the LOS days of every stay discharged in 2025. FREQUENCY returns 7 counts. Enter the 7th: the number of 2025 discharges with LOS days greater than 14. | C9: FILTER the LOS values to 2025 first, then pick one count out of FREQUENCY's result with INDEX. | E9: =IF(IFERROR(D9="",FALSE),"",IF(IFERROR(AND(ISNUMBER(D9),OR(ABS(D9-'Answer Key'!$C$8)<=0.0001)),FALSE),"✔ Correct","✘ Not yet"))
A10: 5 | B10: On the Stays sheet, fill the yellow Readmit30 column: 1 if the same patient has another stay whose AdmitDateTime is after this stay's DischargeDateTime and whose admit DATE is 0–30 days after this stay's discharge DATE, otherwise 0. The gray cell totals your column. How many stays were followed by a 30-day readmission? | C10: COUNTIFS over the whole table, using this row's PatientID and DischargeDateTime as criteria. Compare dates with INT(). | D10: {=IF(COUNT(Stays!$I$2:$I$5587)=0,"",SUM(Stays!$I$2:$I$5587))} | E10: =IF(IFERROR(D10="",FALSE),"",IF(IFERROR(AND(ISNUMBER(D10),OR(ABS(D10-'Answer Key'!$C$9)<=0.0001)),FALSE),"✔ Correct","✘ Not yet"))
A11: 6 | B11: Write ONE LET formula that names the admit and discharge columns, computes LOS days (minimum 1), and returns the average LOS days for sepsis stays (PrimaryDxCode A41.9) at Bluestone Memorial (F01) discharged in 2025. Round to 2 decimal places with ROUND. | C11: Name each step (nights, then los, then a 1/0 keep array). A conditional average is SUM(los*keep)/SUM(keep). | E11: =IF(IFERROR(D11="",FALSE),"",IF(IFERROR(AND(ISNUMBER(D11),OR(ABS(D11-'Answer Key'!$C$10)<=0.0051)),FALSE),"✔ Correct","✘ Not yet"))
A12: 7 | B12: The LOS index (observed ÷ expected) compares actual LOS days with the benchmark ExpectedLOS of each stay's diagnosis (Diagnoses sheet). Calculate it for Cedar Ridge (F03) stays discharged in 2025: total LOS days ÷ total ExpectedLOS. Keep full precision (the check accepts 2 decimal places). | C12: Inside LET, XLOOKUP the whole PrimaryDxCode column. You get one ExpectedLOS for every stay. | E12: =IF(IFERROR(D12="",FALSE),"",IF(IFERROR(AND(ISNUMBER(D12),OR(ABS(D12-'Answer Key'!$C$11)<=0.0051)),FALSE),"✔ Correct","✘ Not yet"))
A13: 8 | B13: Create a named function LOSDAYS(admit, discharge) in the Name Manager that returns LOS days (discharge date − admit date, minimum 1). Then call it on whole columns. What is the total of LOS days for Ashby Falls (F02) stays discharged in 2025? | C13: Formulas → Name Manager → New. Test the LAMBDA in a cell first, for example =LAMBDA(…)(Stays!E2,Stays!F2). | E13: =IF(IFERROR(D13="",FALSE),"",IF(IFERROR(AND(ISNUMBER(D13),OR(ABS(D13-'Answer Key'!$C$12)<=0.0001)),FALSE),"✔ Correct","✘ Not yet"))
A14: 9 | B14: Utilization review audits inpatient stays that spanned fewer than 2 midnights (discharge date − admit date < 2). Using MAP with a LAMBDA that uses AND, count Bluestone Memorial (F01) stays discharged in 2025 that spanned fewer than 2 midnights. | C14: MAP can take several same-size arrays and passes one value from each to your LAMBDA. Wrap the result in SUM. | E14: =IF(IFERROR(D14="",FALSE),"",IF(IFERROR(AND(ISNUMBER(D14),OR(ABS(D14-'Answer Key'!$C$13)<=0.0001)),FALSE),"✔ Correct","✘ Not yet"))
A15: 10 | B15: On the Labs sheet, count the results outside their reference range (ResultValue below RefLow or above RefHigh). Use BYROW over the three adjacent columns ResultValue:RefHigh with a LAMBDA that uses OR. | C15: Inside BYROW, the LAMBDA gets one row of 3 cells: INDEX(r,1) is the value, INDEX(r,2) the low, INDEX(r,3) the high. | E15: =IF(IFERROR(D15="",FALSE),"",IF(IFERROR(AND(ISNUMBER(D15),OR(ABS(D15-'Answer Key'!$C$14)<=0.0001)),FALSE),"✔ Correct","✘ Not yet"))
A16: 11 | B16: The Census sheet holds the Bluestone Memorial ICU's daily census for 2024–2025. A day is 'strained' when MidnightCensus ÷ StaffedBeds is 90% or more. Using SCAN, find the longest run of consecutive strained days. | C16: Keep a running count that adds 1 on a strained day and resets to 0 otherwise. Then take the MAX. | E16: =IF(IFERROR(D16="",FALSE),"",IF(IFERROR(AND(ISNUMBER(D16),OR(ABS(D16-'Answer Key'!$C$15)<=0.0001)),FALSE),"✔ Correct","✘ Not yet"))
A17: 12 | B17: The four HRRP conditions in the data are AMI (I21.4), heart failure (I50.9), pneumonia (J18.9), and COPD (J44.1). Using REDUCE to loop over the array {"I21.4","I50.9","J18.9","J44.1"}, count Bluestone Memorial (F01) stays discharged in 2025 with any of these primary diagnoses. | C17: REDUCE(0, codes, LAMBDA(total, dxcode, total + …)) starts at 0 and adds one COUNTIFS per code. | E17: =IF(IFERROR(D17="",FALSE),"",IF(IFERROR(AND(ISNUMBER(D17),OR(ABS(D17-'Answer Key'!$C$16)<=0.0001)),FALSE),"✔ Correct","✘ Not yet"))
A18: 13 | B18: The Audit sheet has a colleague's formula that should count Ashby Falls (F02) stays discharged in 2025 to Home Health, but it returns 0. Step through it with Evaluate Formula (Windows; on a Mac, test its pieces on the Sandbox sheet), fix the bug, and enter the correct count. | C18: Watch what YEAR returns and what it is compared with. | E18: =IF(IFERROR(D18="",FALSE),"",IF(IFERROR(AND(ISNUMBER(D18),OR(ABS(D18-'Answer Key'!$C$17)<=0.0001)),FALSE),"✔ Correct","✘ Not yet"))

Sheet Stays
A1: EncounterID | B1: PatientID | C1: FacilityID | D1: PrimaryDxCode | E1: AdmitDateTime | F1: DischargeDateTime | G1: DischargeDisposition | H1: TotalCharges | I1: Readmit30
A2: ENC100001 | B2: PT10493 | C2: F01 | D2: I48.91 | E2: 45292.255 | F2: 45295.613 | G2: Home Health | H2: 20407.87
A3: ENC100035 | B3: PT13560 | C3: F03 | D3: I50.9 | E3: 45292.733 | F3: 45302.65 | G3: Home/Self-Care | H3: 41025.96
A4: ENC100022 | B4: PT12529 | C4: F02 | D4: K56.609 | E4: 45292.741 | F4: 45296.554 | G4: Home/Self-Care | H4: 43373.46
A5: ENC100034 | B5: PT10353 | C5: F01 | D5: I50.9 | E5: 45292.771 | F5: 45296.723 | G5: Home/Self-Care | H5: 23951.11
A6: ENC100037 | B6: PT13215 | C6: F03 | D6: I48.91 | E6: 45293.022 | F6: 45295.606 | G6: Home/Self-Care | H6: 32715.76
A7: ENC100048 | B7: PT10002 | C7: F01 | D7: C34.90 | E7: 45293.537 | F7: 45299.464 | G7: Home/Self-Care | H7: 25775.67
A8: ENC100050 | B8: PT11897 | C8: F01 | D8: J44.1 | E8: 45293.624 | F8: 45297.7 | G8: Skilled Nursing Facility | H8: 11403.22
A9: ENC100056 | B9: PT13204 | C9: F01 | D9: F20.9 | E9: 45293.672 | F9: 45300.767 | G9: Home/Self-Care | H9: 22661.44
A10: ENC100057 | B10: PT13103 | C10: F01 | D10: A41.9 | E10: 45293.683 | F10: 45297.501 | G10: Home/Self-Care | H10: 41363.48
A11: ENC100061 | B11: PT10526 | C11: F01 | D11: E11.65 | E11: 45293.844 | F11: 45296.651 | G11: Home Health | H11: 18033.95
A12: ENC100069 | B12: PT13448 | C12: F01 | D12: I21.4 | E12: 45294.001 | F12: 45295.515 | G12: Home/Self-Care | H12: 71638.89
A13: ENC100073 | B13: PT10558 | C13: F02 | D13: J18.9 | E13: 45294.021 | F13: 45296.557 | G13: Expired | H13: 14849.03
... A5587: ENC121789 | B5587: PT11738 | C5587: F01 | D5587: I48.91 | E5587: 46020.962 | F5587: 46022.633 | G5587: Home/Self-Care | H5587: 11907.29

Sheet Diagnoses
A1: DxCode | B1: DxDescription | C1: DxCategory | D1: ExpectedLOS
A2: A08.4 | B2: Viral intestinal infection, unspecified | C2: Infectious | D2: 2.1
A3: A41.9 | B3: Sepsis, unspecified organism | C3: Infectious | D3: 5
A4: C34.90 | B4: Malignant neoplasm of unspecified part of unspecified bronchus or lung | C4: Neoplasms | D4: 5
A5: C50.911 | B5: Malignant neoplasm of unspecified site of right female breast | C5: Neoplasms | D5: 3
A6: D70.1 | B6: Agranulocytosis secondary to cancer chemotherapy | C6: Blood | D6: 4.5
A7: E11.65 | B7: Type 2 diabetes mellitus with hyperglycemia | C7: Endocrine | D7: 3
A8: E11.9 | B8: Type 2 diabetes mellitus without complications | C8: Endocrine
A9: E78.5 | B9: Hyperlipidemia, unspecified | C9: Endocrine
A10: E86.0 | B10: Dehydration | C10: Endocrine | D10: 2.4
A11: E87.1 | B11: Hypo-osmolality and hyponatremia | C11: Endocrine | D11: 3.2
A12: F10.239 | B12: Alcohol dependence with withdrawal, unspecified | C12: Mental & Behavioral | D12: 3.6
A13: F20.9 | B13: Schizophrenia, unspecified | C13: Mental & Behavioral | D13: 8.9
A14: F32.9 | B14: Major depressive disorder, single episode, unspecified | C14: Mental & Behavioral | D14: 6.8
A15: F41.9 | B15: Anxiety disorder, unspecified | C15: Mental & Behavioral
A16: G40.909 | B16: Epilepsy, unspecified, not intractable, without status epilepticus | C16: Nervous System | D16: 2.5
A17: G43.909 | B17: Migraine, unspecified, not intractable, without status migrainosus | C17: Nervous System
A18: H66.90 | B18: Otitis media, unspecified, unspecified ear | C18: Ear
A19: I10 | B19: Essential (primary) hypertension | C19: Circulatory
A20: I21.4 | B20: Non-ST elevation (NSTEMI) myocardial infarction | C20: Circulatory | D20: 3.4
A21: I48.91 | B21: Unspecified atrial fibrillation | C21: Circulatory | D21: 2.9
A22: I50.9 | B22: Heart failure, unspecified | C22: Circulatory | D22: 4.1
A23: I63.9 | B23: Cerebral infarction, unspecified | C23: Circulatory | D23: 4.2
A24: J06.9 | B24: Acute upper respiratory infection, unspecified | C24: Respiratory
A25: J18.9 | B25: Pneumonia, unspecified organism | C25: Respiratory | D25: 3.9
A26: J21.9 | B26: Acute bronchiolitis, unspecified | C26: Respiratory | D26: 2.4
A27: J44.1 | B27: Chronic obstructive pulmonary disease with (acute) exacerbation | C27: Respiratory | D27: 3.4
A28: J45.909 | B28: Unspecified asthma, uncomplicated | C28: Respiratory | D28: 2.1
A29: J96.01 | B29: Acute respiratory failure with hypoxia | C29: Respiratory | D29: 4.8
A30: K35.80 | B30: Unspecified acute appendicitis | C30: Digestive | D30: 2
A31: K56.609 | B31: Unspecified intestinal obstruction | C31: Digestive | D31: 4.6
A32: K80.20 | B32: Calculus of gallbladder without cholecystitis without obstruction | C32: Digestive | D32: 1.9
A33: K92.2 | B33: Gastrointestinal hemorrhage, unspecified | C33: Digestive | D33: 3.5
A34: L03.115 | B34: Cellulitis of right lower limb | C34: Skin | D34: 3.4
A35: M16.11 | B35: Unilateral primary osteoarthritis, right hip | C35: Musculoskeletal | D35: 2.1
A36: M17.11 | B36: Unilateral primary osteoarthritis, right knee | C36: Musculoskeletal | D36: 2
A37: M54.50 | B37: Low back pain, unspecified | C37: Musculoskeletal
A38: N17.9 | B38: Acute kidney failure, unspecified | C38: Genitourinary | D38: 3.9
A39: N39.0 | B39: Urinary tract infection, site not specified | C39: Genitourinary | D39: 3.1
A40: O80 | B40: Encounter for full-term uncomplicated delivery | C40: Pregnancy | D40: 2
...

Sheet Labs
A1: LabResultID | B1: EncounterID | C1: PatientID | D1: TestCode | E1: TestName | F1: ResultValue | G1: RefLow | H1: RefHigh | I1: Units | J1: Priority | K1: CollectedDateTime | L1: ResultedDateTime
A2: LAB738455 | B2: ENC116230 | C2: PT10861 | D2: GLU | E2: Glucose | F2: 159 | G2: 70 | H2: 99 | I2: mg/dL | J2: STAT | K2: 45832.831 | L2: 45832.864
A3: LAB738457 | B3: ENC116230 | C3: PT10861 | D3: WBC | E3: White Blood Cell Count | F3: 4.9 | G3: 4.5 | H3: 11 | I3: K/uL | J3: STAT | K3: 45832.852 | L3: 45832.89
A4: LAB738456 | B4: ENC116230 | C4: PT10861 | D4: CREAT | E4: Creatinine | F4: 1.02 | G4: 0.6 | H4: 1.3 | I4: mg/dL | J4: Routine | K4: 45832.858 | L4: 45833.186
A5: LAB738458 | B5: ENC116230 | C5: PT10861 | D5: HGB | E5: Hemoglobin | F5: 4.6 | G5: 12 | H5: 17.5 | I5: g/dL | J5: STAT | K5: 45832.863 | L5: 45832.898
A6: LAB738459 | B6: ENC116230 | C6: PT10861 | D6: INR | E6: Prothrombin Time INR | F6: 0.8 | G6: 0.8 | H6: 1.2 | I6: ratio | J6: Routine | K6: 45832.865 | L6: 45833.394
A7: LAB738587 | B7: ENC116296 | C7: PT13863 | D7: K | E7: Potassium | F7: 4.8 | G7: 3.5 | H7: 5.1 | I7: mmol/L | J7: STAT | K7: 45834.794 | L7: 45834.831
A8: LAB738582 | B8: ENC116296 | C8: PT13863 | D8: GLU | E8: Glucose | F8: 131 | G8: 70 | H8: 99 | I8: mg/dL | J8: Routine | K8: 45834.813 | L8: 45834.908
A9: LAB738583 | B9: ENC116296 | C9: PT13863 | D9: CREAT | E9: Creatinine | F9: 1.69 | G9: 0.6 | H9: 1.3 | I9: mg/dL | J9: STAT | K9: 45834.815 | L9: 45834.857
A10: LAB738586 | B10: ENC116296 | C10: PT13863 | D10: NA | E10: Sodium | F10: 139 | G10: 136 | H10: 145 | I10: mmol/L | J10: Routine | K10: 45834.828 | L10: 45834.951
A11: LAB738588 | B11: ENC116296 | C11: PT13863 | D11: LACT | E11: Lactate | F11: 7.4 | G11: 0.5 | H11: 2 | I11: mmol/L | J11: STAT | K11: 45834.831 | L11: 45834.859
A12: LAB738584 | B12: ENC116296 | C12: PT13863 | D12: WBC | E12: White Blood Cell Count | F12: 18.6 | G12: 4.5 | H12: 11 | I12: K/uL | J12: STAT | K12: 45834.84 | L12: 45834.881
A13: LAB738585 | B13: ENC116296 | C13: PT13863 | D13: HGB | E13: Hemoglobin | F13: 13.6 | G13: 12 | H13: 17.5 | I13: g/dL | J13: STAT | K13: 45834.847 | L13: 45834.881
... A1019: LAB751340 | B1019: ENC121728 | C1019: PT12266 | D1019: WBC | E1019: White Blood Cell Count | F1019: 10.4 | G1019: 4.5 | H1019: 11 | I1019: K/uL | J1019: Routine | K1019: 46018.542 | L1019: 46018.726

Sheet Census
A1: CensusDate | B1: StaffedBeds | C1: Admissions | D1: Discharges | E1: MidnightCensus
A2: 45292 | B2: 20 | C2: 7 | D2: 6 | E2: 17
A3: 45293 | B3: 20 | C3: 6 | D3: 5 | E3: 18
A4: 45294 | B4: 20 | C4: 4 | D4: 3 | E4: 19
A5: 45295 | B5: 20 | C5: 6 | D5: 5 | E5: 20
A6: 45296 | B6: 20 | C6: 8 | D6: 9 | E6: 19
A7: 45297 | B7: 20 | C7: 8 | D7: 9 | E7: 18
A8: 45298 | B8: 20 | C8: 6 | D8: 5 | E8: 19
A9: 45299 | B9: 20 | C9: 4 | D9: 3 | E9: 20
A10: 45300 | B10: 20 | C10: 5 | D10: 5 | E10: 20
A11: 45301 | B11: 20 | C11: 4 | D11: 4 | E11: 20
A12: 45302 | B12: 20 | C12: 7 | D12: 8 | E12: 19
A13: 45303 | B13: 20 | C13: 9 | D13: 9 | E13: 19
... A732: 46022 | B732: 20 | C732: 9 | D732: 9 | E732: 18

Sheet Audit
A1: Audit: a formula that needs fixing
A3: Request | B3: Count the Ashby Falls (F02) inpatient stays discharged in 2025 that went to Home Health.
A4: Colleague's note | B4: "My formula returns 0, but I know Ashby Falls sends patients home with home health every week. Can you find the bug?"
A6: The formula | B6: {=SUMPRODUCT((tblStays[FacilityID]="F02")*(YEAR(tblStays[DischargeDateTime])="2025")*(tblStays[DischargeDisposition]="Home Health"))}
A7: Formula text | B7: =SUMPRODUCT((tblStays[FacilityID]="F02")*(YEAR(tblStays[DischargeDateTime])="2025")*(tblStays[DischargeDisposition]="Home Health"))
A9: How to audit | B9: 1. Select B6, then choose Formulas → Evaluate Formula (Formula Auditing group). Evaluate Formula is in Excel for Windows only.
B10: 2. Click Evaluate repeatedly. Watch the underlined part of the formula turn into its result.
B11: 3. Stop when an array turns all FALSE. Which comparison did that?
B12: 4. Fix the formula in B6 and check that the result is believable.
B13: 5. Enter the corrected count in the matching task on the Practice sheet.
B14: On a Mac (no Evaluate Formula)? Type one piece, such as =YEAR(tblStays[DischargeDateTime]), into a cell on the Sandbox sheet and let it spill. Then try the comparison from the formula on its own.

Sheet Sandbox
A1: Sandbox: try array formulas here
A2: Answer cells on the Practice and Bonus sheets must return ONE value, so build and inspect your array formulas here first.
A3: Type a formula in A10 (or any cell with empty cells below it) and watch it spill. Examples to try:
A4: =INT(tblStays[DischargeDateTime])-INT(tblStays[AdmitDateTime]) (LOS nights for every stay)
A5: =SCAN(0, tblCensus[Admissions], LAMBDA(total, x, total + x)) (running total of ICU admissions)
A6: When the spill looks right, wrap it in SUM, MAX, or INDEX and copy the formula to the Practice sheet.
A9: Your workspace ↓

Sheet Bonus
A1: Lesson 4.2 · Bonus: CMS-style readmission rates in one formula
A2: Bluestone's quality committee wants 30-day all-cause readmission rates by hospital, built with CMS-style rules (simplified: CMS also risk-adjusts its rates and ignores planned readmissions). Index stays are inpatient stays discharged from 01/01/2025 through 11/30/2025, so every stay has a full 30 days of follow-up in the data. Exclude stays that ended in death (Expired), a transfer (Transfer to Another Hospital), or a discharge against medical advice (Left AMA). A readmission is any later inpatient admission of the same patient, at any Bluestone hospital, with an admit date 0–30 days after the index discharge date (the Task 5 rule). Rate = index stays followed by a readmission ÷ index stays. Build each answer as one LET formula over tblStays.
A3: Type a formula or value in each yellow cell. The Check column turns green when your answer matches. Stuck? Read the hint, then the lesson guide. Answers: right-click a sheet tab → Unhide… → 'Bonus Key'.
A4: ="Score: "&COUNTIF(E6:E10,"✔*")&" of 5 auto-checked tasks correct"
A5: # | B5: Task | C5: Hint | D5: Your Answer | E5: Check
A6: B1 | B6: How many index stays are there system-wide? | C6: ISNA(MATCH(disposition, {list}, 0)) is TRUE when a disposition is NOT on the list. | E6: =IF(IFERROR(D6="",FALSE),"",IF(IFERROR(AND(ISNUMBER(D6),OR(ABS(D6-'Bonus Key'!$C$5)<=0.0001)),FALSE),"✔ Correct","✘ Not yet"))
A7: B2 | B7: Write one LET formula that returns the readmission rate for Bluestone Memorial (F01). Enter it as a percentage (1 decimal place is enough). | C7: Name readmit (the Task 5 test for every row at once), eligible, and keep, then divide SUM(keep*readmit) by SUM(keep). | E7: =IF(IFERROR(D7="",FALSE),"",IF(IFERROR(AND(ISNUMBER(D7),OR(ABS(D7-'Bonus Key'!$C$6)<=0.00051,ABS(D7-'Bonus Key'!$C$6*100)<=0.051000000000000004)),FALSE),"✔ Correct","✘ Not yet"))
A8: B3 | B8: Which hospital has the highest rate? Enter its FacilityID. | C8: Wrap your B2 formula in LAMBDA(facility, …), save it as READMITRATE, and MAP it over {"F01";"F02";"F03"}. Or edit the facility ID three times. | E8: =IF(IFERROR(D8="",FALSE),"",IF(IFERROR(OR(LOWER(TRIM(D8&""))=LOWER(TRIM('Bonus Key'!$C$7&"")),LOWER(TRIM(D8&""))="ashby falls community hospital"),FALSE),"✔ Correct","✘ Not yet"))
A9: B4 | B9: What is that hospital's rate? Enter it as a percentage (1 decimal place is enough). | C9: Reuse B2 with the other facility ID, or call your READMITRATE function. | E9: =IF(IFERROR(D9="",FALSE),"",IF(IFERROR(AND(ISNUMBER(D9),OR(ABS(D9-'Bonus Key'!$C$8)<=0.00051,ABS(D9-'Bonus Key'!$C$8*100)<=0.051000000000000004)),FALSE),"✔ Correct","✘ Not yet"))
A10: B5 | B10: CMS also publishes readmission rates by condition. What is the system-wide rate for index stays whose primary diagnosis is one of the four HRRP conditions from Task 12? Enter it as a percentage (1 decimal place is enough). | C10: Swap the facility test for a diagnosis-list test: ISNUMBER(MATCH(dx, {list}, 0)). | E10: =IF(IFERROR(D10="",FALSE),"",IF(IFERROR(AND(ISNUMBER(D10),OR(ABS(D10-'Bonus Key'!$C$9)<=0.00051,ABS(D10-'Bonus Key'!$C$9*100)<=0.051000000000000004)),FALSE),"✔ Correct","✘ Not yet"))

Sheet Answer Key
A1: 🔑 Answer Key — Lesson 4.2
A2: Spoiler alert — try every task before reading this sheet. Column C is the value the Check column compares against. Column D is a sample solution; column E is that same formula, live, proving it works.
A4: # | B4: Task | C4: Answer | D4: Sample solution | E4: Live result | F4: Explanation
A5: 1 | B5: How many inpatient stays were admitted on a Saturday or Sunday in 2025? Use AdmitDateTime for both the weekday and the year. | C5: 668 | D5: =SUMPRODUCT((WEEKDAY(tblStays[AdmitDateTime],2)>5)*(YEAR(tblStays[AdmitDateTime])=2025)) | E5: {=SUMPRODUCT((WEEKDAY(tblStays[AdmitDateTime],2)>5)*(YEAR(tblStays[AdmitDateTime])=2025))} | F5: Each comparison returns an array of 5,586 TRUE/FALSE values. Multiplying the two arrays turns TRUE into 1 and FALSE into 0, so a row is 1 only when both conditions hold (AND logic). SUMPRODUCT adds the 1s. COUNTIFS could handle the year with two date criteria, but it can't apply WEEKDAY to the range first, so the weekend test needs either a helper column or array logic.
A6: 2 | B6: Case management reviews every 2025 discharge that had LOS days of 7 or more OR went to a Skilled Nursing Facility. What were the total charges (TotalCharges) of the stays on that review list? Count each stay once, and enter dollars and cents. | C6: 40025644 | D6: =SUMPRODUCT((((INT(tblStays[DischargeDateTime])-INT(tblStays[AdmitDateTime])>=7)+(tblStays[DischargeDisposition]="Skilled Nursing Facility"))>0)*(YEAR(tblStays[DischargeDateTime])=2025),tblStays[TotalCharges]) | E6: {=SUMPRODUCT((((INT(tblStays[DischargeDateTime])-INT(tblStays[AdmitDateTime])>=7)+(tblStays[DischargeDisposition]="Skilled Nursing Facility"))>0)*(YEAR(tblStays[DischargeDateTime])=2025),tblStays[TotalCharges])} | F6: (A)+(B) is 0, 1, or 2. The 49 long SNF stays score 2, so multiplying by charges without the >0 test counts their charges twice and gives $42,880,891.91. ((A)+(B))>0 turns the sum back into TRUE/FALSE, so every stay counts once. LOS days of 7 or more only depends on the midnight count, so INT(dis)-INT(adm)>=7 is enough here (the 1-day minimum only changes 0-night stays).
A7: 3 | B7: The Labs sheet is sorted from oldest to newest CollectedDateTime. What was patient PT11882's most recent creatinine (TestCode CREAT) result? | C7: 3.9 | D7: =XLOOKUP(1,(tblLabs[PatientID]="PT11882")*(tblLabs[TestCode]="CREAT"),tblLabs[ResultValue],"Not found",0,-1) | E7: {=_xlfn.XLOOKUP(1,(tblLabs[PatientID]="PT11882")*(tblLabs[TestCode]="CREAT"),tblLabs[ResultValue],"Not found",0,-1)} | F7: Multiplying the two conditions builds an array that is 1 only on this patient's creatinine rows. XLOOKUP finds the value 1 in that array. search_mode -1 searches from the bottom up, and because the sheet is sorted oldest to newest, the bottom match is the latest result. A top-down search returns the first result (2.75), which is how creatinine looked months earlier. Rising creatinine can signal kidney injury.
A8: 4 | B8: Use FREQUENCY with the bins {1,2,3,5,7,14} on the LOS days of every stay discharged in 2025. FREQUENCY returns 7 counts. Enter the 7th: the number of 2025 discharges with LOS days greater than 14. | C8: 33 | D8: =INDEX(FREQUENCY(FILTER(INT(tblStays[DischargeDateTime])-INT(tblStays[AdmitDateTime]),YEAR(tblStays[DischargeDateTime])=2025),{1,2,3,5,7,14}),7) | E8: {=INDEX(FREQUENCY(_xlfn._xlws.FILTER(INT(tblStays[DischargeDateTime])-INT(tblStays[AdmitDateTime]),YEAR(tblStays[DischargeDateTime])=2025),{1,2,3,5,7,14}),7)} | F8: FREQUENCY counts values ≤ 1, then >1 to 2, >2 to 3, >3 to 5, >5 to 7, >7 to 14, and finally everything above the last bin. That extra overflow count is why 6 bins return 7 numbers. INDEX(…, 7) returns just the overflow count, so the answer cell holds one value. The solution skips the 1-day minimum because a 0-night stay lands in the ≤ 1 bin either way, so applying it gives the same counts. FREQUENCY(IF(YEAR(dis)=2025, INT(dis)-INT(adm)), bins) also works, because FREQUENCY ignores the FALSE values that IF returns for other years.
A9: 5 | B9: On the Stays sheet, fill the yellow Readmit30 column: 1 if the same patient has another stay whose AdmitDateTime is after this stay's DischargeDateTime and whose admit DATE is 0–30 days after this stay's discharge DATE, otherwise 0. The gray cell totals your column. How many stays were followed by a 30-day readmission? | C9: 800 | D9: =IF(COUNTIFS(tblStays[PatientID],[@PatientID],tblStays[AdmitDateTime],">"&[@DischargeDateTime],tblStays[AdmitDateTime],"<"&(INT([@DischargeDateTime])+31))>0,1,0) | E9: {=SUM(--(COUNTIFS(tblStays[PatientID],tblStays[PatientID],tblStays[AdmitDateTime],">"&tblStays[DischargeDateTime],tblStays[AdmitDateTime],"<"&(INT(tblStays[DischargeDateTime])+31))>0))} | F9: For each row, COUNTIFS counts the stays that have the same PatientID, an AdmitDateTime after this discharge, and an AdmitDateTime earlier than INT(discharge)+31, which is midnight at the start of the 31st day after the discharge date. That last test is the same as an admit DATE no more than 30 days later. Any count above 0 means a readmission. In A1 style the first row is =IF(COUNTIFS($B$2:$B$5587,B2,$E$2:$E$5587,">"&F2,$E$2:$E$5587,"<"&(INT(F2)+31))>0,1,0). Your total should be 800, the same as the official Readmit30 = Y count in the full dataset. A window measured to the minute (admit ≤ discharge + 30) finds only 793 because it misses readmissions on day 30 that happen later in the day than the discharge did. The key's live formula does all rows in one cell by giving COUNTIFS whole columns as criteria.
A10: 6 | B10: Write ONE LET formula that names the admit and discharge columns, computes LOS days (minimum 1), and returns the average LOS days for sepsis stays (PrimaryDxCode A41.9) at Bluestone Memorial (F01) discharged in 2025. Round to 2 decimal places with ROUND. | C10: 7.19 | D10: =LET( adm, tblStays[AdmitDateTime], dis, tblStays[DischargeDateTime], nights, INT(dis)-INT(adm), los, IF(nights<1, 1, nights), keep, (tblStays[FacilityID]="F01")*(tblStays[PrimaryDxCode]="A41.9")*(YEAR(dis)=2025), ROUND(SUM(los*keep)/SUM(keep), 2) ) | E10: {=_xlfn.LET( _xlpm.adm, tblStays[AdmitDateTime], _xlpm.dis, tblStays[DischargeDateTime], _xlpm.nights, INT(_xlpm.dis)-INT(_xlpm.adm), _xlpm.los, IF(_xlpm.nights<1, 1, _xlpm.nights), _xlpm.keep, (tblStays[FacilityID]="F01")*(tblStays[PrimaryDxCode]="A41.9")*(YEAR(_xlpm.dis)=2025), ROUND(SUM(_xlpm.los*_xlpm.keep)/SUM(_xlpm.keep), 2) )} | F10: Each name is calculated once and reused, so INT(dis)-INT(adm) isn't repeated. los*keep zeroes out the rows you don't want, and SUM(keep) counts the rows you do (167 stays), which gives a conditional average without a helper column. AVERAGE(FILTER(los, keep)) is an equally good last step.
A11: 7 | B11: The LOS index (observed ÷ expected) compares actual LOS days with the benchmark ExpectedLOS of each stay's diagnosis (Diagnoses sheet). Calculate it for Cedar Ridge (F03) stays discharged in 2025: total LOS days ÷ total ExpectedLOS. Keep full precision (the check accepts 2 decimal places). | C11: 1.245149 | D11: =LET( adm, tblStays[AdmitDateTime], dis, tblStays[DischargeDateTime], nights, INT(dis)-INT(adm), los, IF(nights<1, 1, nights), explos, XLOOKUP(tblStays[PrimaryDxCode], tblDx[DxCode], tblDx[ExpectedLOS]), keep, (tblStays[FacilityID]="F03")*(YEAR(dis)=2025), SUM(los*keep)/SUM(explos*keep) ) | E11: {=_xlfn.LET( _xlpm.adm, tblStays[AdmitDateTime], _xlpm.dis, tblStays[DischargeDateTime], _xlpm.nights, INT(_xlpm.dis)-INT(_xlpm.adm), _xlpm.los, IF(_xlpm.nights<1, 1, _xlpm.nights), _xlpm.explos, _xlfn.XLOOKUP(tblStays[PrimaryDxCode], tblDx[DxCode], tblDx[ExpectedLOS]), _xlpm.keep, (tblStays[FacilityID]="F03")*(YEAR(_xlpm.dis)=2025), SUM(_xlpm.los*_xlpm.keep)/SUM(_xlpm.explos*_xlpm.keep) )} | F11: Given a whole column as its lookup value, XLOOKUP returns one benchmark per stay. Naming that array explos keeps the final line readable: observed days ÷ expected days for the kept rows. An index above 1.00 means patients stayed longer than the benchmark. Don't average the per-stay ratios. A ratio of totals weights long and short stays correctly.
A12: 8 | B12: Create a named function LOSDAYS(admit, discharge) in the Name Manager that returns LOS days (discharge date − admit date, minimum 1). Then call it on whole columns. What is the total of LOS days for Ashby Falls (F02) stays discharged in 2025? | C12: 1694 | D12: =SUM(LOSDAYS(tblStays[AdmitDateTime],tblStays[DischargeDateTime])*(tblStays[FacilityID]="F02")*(YEAR(tblStays[DischargeDateTime])=2025)) | E12: — | F12: Define LOSDAYS as =LAMBDA(admit, discharge, LET(nights, INT(discharge)-INT(admit), IF(nights<1, 1, nights))). Called with two whole columns, it returns 5,586 LOS values, and the two conditions keep the 374 F02 stays from 2025. Use IF for the minimum, not MAX. MAX(1, INT(discharge)-INT(admit)) collapses the whole column into one number (the longest stay, 34 days), and the total becomes 12,716.
A13: 9 | B13: Utilization review audits inpatient stays that spanned fewer than 2 midnights (discharge date − admit date < 2). Using MAP with a LAMBDA that uses AND, count Bluestone Memorial (F01) stays discharged in 2025 that spanned fewer than 2 midnights. | C13: 118 | D13: =SUM(MAP(tblStays[FacilityID], tblStays[AdmitDateTime], tblStays[DischargeDateTime], LAMBDA(fac, adm, dis, IF(AND(fac="F01", YEAR(dis)=2025, INT(dis)-INT(adm)<2), 1, 0)))) | E13: — | F13: MAP calls the LAMBDA once per stay, so fac, adm, and dis are single values and AND works. Outside MAP, AND(...) on whole columns would return one TRUE/FALSE for all 5,586 rows. The boolean-math version =SUMPRODUCT((tblStays[FacilityID]="F01")*(YEAR(tblStays[DischargeDateTime])=2025)*(INT(tblStays[DischargeDateTime])-INT(tblStays[AdmitDateTime])<2)) gives the same count. MAP is worth it when the per-row logic reads better with AND, OR, or MAX.
A14: 10 | B14: On the Labs sheet, count the results outside their reference range (ResultValue below RefLow or above RefHigh). Use BYROW over the three adjacent columns ResultValue:RefHigh with a LAMBDA that uses OR. | C14: 365 | D14: =SUM(BYROW(tblLabs[[ResultValue]:[RefHigh]], LAMBDA(r, IF(OR(INDEX(r,1)<INDEX(r,2), INDEX(r,1)>INDEX(r,3)), 1, 0)))) | E14: — | F14: BYROW hands the LAMBDA one 1×3 row at a time, so OR tests just that row and returns one TRUE/FALSE. BYROW stacks the results into a column of 1s and 0s for SUM. tblLabs[[ResultValue]:[RefHigh]] is the structured reference for the three adjacent columns. Cross-check: the lab's own abnormal flags (not included here) mark the same 365 results.
A15: 11 | B15: The Census sheet holds the Bluestone Memorial ICU's daily census for 2024–2025. A day is 'strained' when MidnightCensus ÷ StaffedBeds is 90% or more. Using SCAN, find the longest run of consecutive strained days. | C15: 15 | D15: =MAX(SCAN(0, tblCensus[MidnightCensus]/tblCensus[StaffedBeds]>=0.9, LAMBDA(run, strained, IF(strained, run+1, 0)))) | E15: — | F15: SCAN walks down the 731 TRUE/FALSE values and keeps a running number (the accumulator run). On a strained day it adds 1, and on any other day it resets to 0. The result is one running count per day, so its MAX is the longest streak. A streak depends on the previous row's result, which SUMPRODUCT and COUNTIFS can't express without a helper column.
A16: 12 | B16: The four HRRP conditions in the data are AMI (I21.4), heart failure (I50.9), pneumonia (J18.9), and COPD (J44.1). Using REDUCE to loop over the array {"I21.4","I50.9","J18.9","J44.1"}, count Bluestone Memorial (F01) stays discharged in 2025 with any of these primary diagnoses. | C16: 561 | D16: =REDUCE(0, {"I21.4","I50.9","J18.9","J44.1"}, LAMBDA(total, dxcode, total + COUNTIFS(tblStays[PrimaryDxCode], dxcode, tblStays[FacilityID], "F01", tblStays[DischargeDateTime], ">="&DATE(2025,1,1), tblStays[DischargeDateTime], "<"&DATE(2026,1,1)))) | E16: — | F16: REDUCE starts the accumulator total at 0, then calls the LAMBDA once per code, adding that code's COUNTIFS each time. It returns only the final total. The codes can't overlap (a stay has one primary diagnosis), so adding is safe. SUM(COUNTIFS(…, {codes}, …)) gives the same answer. REDUCE earns its keep when each step needs more logic than one function call.
A17: 13 | B17: The Audit sheet has a colleague's formula that should count Ashby Falls (F02) stays discharged in 2025 to Home Health, but it returns 0. Step through it with Evaluate Formula (Windows; on a Mac, test its pieces on the Sandbox sheet), fix the bug, and enter the correct count. | C17: 48 | D17: =SUMPRODUCT((tblStays[FacilityID]="F02")*(YEAR(tblStays[DischargeDateTime])=2025)*(tblStays[DischargeDisposition]="Home Health")) | E17: {=SUMPRODUCT((tblStays[FacilityID]="F02")*(YEAR(tblStays[DischargeDateTime])=2025)*(tblStays[DischargeDisposition]="Home Health"))} | F17: YEAR returns the number 2025, but the formula compares it with the text "2025". In Excel a number never equals text, so that array is all FALSE and every product is 0. Evaluate Formula shows the YEAR step as numbers and the comparison as all FALSE (on a Mac, =YEAR(tblStays[DischargeDateTime])="2025" on the Sandbox sheet spills a column of FALSE). COUNTIFS would have accepted "2025" because it converts criteria strings, and that habit is how this bug usually gets in.

Sheet Bonus Key
A1: 🔑 Bonus Key — Lesson 4.2
A2: Spoiler alert — try every task before reading this sheet. Column C is the value the Check column compares against. Column D is a sample solution; column E is that same formula, live, proving it works.
A4: # | B4: Task | C4: Answer | D4: Sample solution | E4: Live result | F4: Explanation
A5: B1 | B5: How many index stays are there system-wide? | C5: 2452 | D5: =LET( dis, tblStays[DischargeDateTime], eligible, (dis>=DATE(2025,1,1))*(dis<DATE(2025,12,1)) *ISNA(MATCH(tblStays[DischargeDisposition], {"Expired","Transfer to Another Hospital","Left AMA"}, 0)), SUM(eligible) ) | E5: {=_xlfn.LET( _xlpm.dis, tblStays[DischargeDateTime], _xlpm.eligible, (_xlpm.dis>=DATE(2025,1,1))*(_xlpm.dis<DATE(2025,12,1)) *ISNA(MATCH(tblStays[DischargeDisposition], {"Expired","Transfer to Another Hospital","Left AMA"}, 0)), SUM(_xlpm.eligible) )} | F5: MATCH returns #N/A for every disposition that isn't one of the three exclusions, so ISNA turns "not excluded" into TRUE. The two date tests keep discharges from 01/01/2025 up to (not including) 12/01/2025. Without the exclusions there would be 2,595 stays in the window.
A6: B2 | B6: Write one LET formula that returns the readmission rate for Bluestone Memorial (F01). Enter it as a percentage (1 decimal place is enough). | C6: 0.1582774 | D6: =LET( adm, tblStays[AdmitDateTime], dis, tblStays[DischargeDateTime], readmit, COUNTIFS(tblStays[PatientID], tblStays[PatientID], adm, ">"&dis, adm, "<"&(INT(dis)+31))>0, eligible, (dis>=DATE(2025,1,1))*(dis<DATE(2025,12,1)) *ISNA(MATCH(tblStays[DischargeDisposition], {"Expired","Transfer to Another Hospital","Left AMA"}, 0)), keep, eligible*(tblStays[FacilityID]="F01"), SUM(keep*readmit)/SUM(keep) ) | E6: {=_xlfn.LET( _xlpm.adm, tblStays[AdmitDateTime], _xlpm.dis, tblStays[DischargeDateTime], _xlpm.readmit, COUNTIFS(tblStays[PatientID], tblStays[PatientID], _xlpm.adm, ">"&_xlpm.dis, _xlpm.adm, "<"&(INT(_xlpm.dis)+31))>0, _xlpm.eligible, (_xlpm.dis>=DATE(2025,1,1))*(_xlpm.dis<DATE(2025,12,1)) *ISNA(MATCH(tblStays[DischargeDisposition], {"Expired","Transfer to Another Hospital","Left AMA"}, 0)), _xlpm.keep, _xlpm.eligible*(tblStays[FacilityID]="F01"), SUM(_xlpm.keep*_xlpm.readmit)/SUM(_xlpm.keep) )} | F6: readmit hands COUNTIFS whole columns as criteria, so it returns one count per stay (5,586 of them), and >0 turns those counts into TRUE/FALSE. LET calculates that expensive array once. keep narrows the index stays to F01 (1,788 stays). If you finished Task 5, SUM(keep*tblStays[Readmit30])/SUM(keep) is a shorter last step that reuses your column. The self-contained version keeps working even if someone deletes that column.
A7: B3 | B7: Which hospital has the highest rate? Enter its FacilityID. | C7: F02 | D7: =LET( facs, {"F01";"F02";"F03"}, rates, MAP(facs, LAMBDA(f, READMITRATE(f))), XLOOKUP(MAX(rates), rates, facs) ) | E7: — | F7: Define READMITRATE in the Name Manager as your B2 formula wrapped in =LAMBDA(facility, LET(…)), with "F01" replaced by facility. MAP passes each ID in turn to LAMBDA(f, READMITRATE(f)), and XLOOKUP returns the ID next to the largest rate. The rates are F01 15.8%, F02 18.6%, F03 16.5%. Ashby Falls Community Hospital has the highest rate even though it's the smallest hospital, which is why rates, not counts, are compared.
A8: B4 | B8: What is that hospital's rate? Enter it as a percentage (1 decimal place is enough). | C8: 0.18604651 | D8: =LET( adm, tblStays[AdmitDateTime], dis, tblStays[DischargeDateTime], readmit, COUNTIFS(tblStays[PatientID], tblStays[PatientID], adm, ">"&dis, adm, "<"&(INT(dis)+31))>0, eligible, (dis>=DATE(2025,1,1))*(dis<DATE(2025,12,1)) *ISNA(MATCH(tblStays[DischargeDisposition], {"Expired","Transfer to Another Hospital","Left AMA"}, 0)), keep, eligible*(tblStays[FacilityID]="F02"), SUM(keep*readmit)/SUM(keep) ) | E8: {=_xlfn.LET( _xlpm.adm, tblStays[AdmitDateTime], _xlpm.dis, tblStays[DischargeDateTime], _xlpm.readmit, COUNTIFS(tblStays[PatientID], tblStays[PatientID], _xlpm.adm, ">"&_xlpm.dis, _xlpm.adm, "<"&(INT(_xlpm.dis)+31))>0, _xlpm.eligible, (_xlpm.dis>=DATE(2025,1,1))*(_xlpm.dis<DATE(2025,12,1)) *ISNA(MATCH(tblStays[DischargeDisposition], {"Expired","Transfer to Another Hospital","Left AMA"}, 0)), _xlpm.keep, _xlpm.eligible*(tblStays[FacilityID]="F02"), SUM(_xlpm.keep*_xlpm.readmit)/SUM(_xlpm.keep) )} | F8: Same formula as B2 with "F02". With the named LAMBDA it is simply =READMITRATE("F02"). Turning a long LET into a LAMBDA means one tested definition serves every hospital, so a fix to the rule only has to be made once.
A9: B5 | B9: CMS also publishes readmission rates by condition. What is the system-wide rate for index stays whose primary diagnosis is one of the four HRRP conditions from Task 12? Enter it as a percentage (1 decimal place is enough). | C9: 0.20674487 | D9: =LET( adm, tblStays[AdmitDateTime], dis, tblStays[DischargeDateTime], readmit, COUNTIFS(tblStays[PatientID], tblStays[PatientID], adm, ">"&dis, adm, "<"&(INT(dis)+31))>0, eligible, (dis>=DATE(2025,1,1))*(dis<DATE(2025,12,1)) *ISNA(MATCH(tblStays[DischargeDisposition], {"Expired","Transfer to Another Hospital","Left AMA"}, 0)), keep, eligible*ISNUMBER(MATCH(tblStays[PrimaryDxCode], {"I21.4","I50.9","J18.9","J44.1"}, 0)), SUM(keep*readmit)/SUM(keep) ) | E9: {=_xlfn.LET( _xlpm.adm, tblStays[AdmitDateTime], _xlpm.dis, tblStays[DischargeDateTime], _xlpm.readmit, COUNTIFS(tblStays[PatientID], tblStays[PatientID], _xlpm.adm, ">"&_xlpm.dis, _xlpm.adm, "<"&(INT(_xlpm.dis)+31))>0, _xlpm.eligible, (_xlpm.dis>=DATE(2025,1,1))*(_xlpm.dis<DATE(2025,12,1)) *ISNA(MATCH(tblStays[DischargeDisposition], {"Expired","Transfer to Another Hospital","Left AMA"}, 0)), _xlpm.keep, _xlpm.eligible*ISNUMBER(MATCH(tblStays[PrimaryDxCode], {"I21.4","I50.9","J18.9","J44.1"}, 0)), SUM(_xlpm.keep*_xlpm.readmit)/SUM(_xlpm.keep) )} | F9: ISNUMBER(MATCH(…)) is the mirror image of the exclusion test: TRUE when the diagnosis IS on the list. The 682 HRRP index stays are readmitted more often than index stays overall (16.3%), which is why CMS targets these conditions.
