Workbook

Sheet Start Here
B2: Lesson 3.5
B3: Charts & Data Visualization
B4: Intermediate · about 55 minutes · Bluestone Health System (fictional)
B6: What you'll learn
B7: • | C7: Choose the right chart for comparisons, trends, parts of a whole, distributions, and relationships
B8: • | C8: Build and format column, line, bar, scatter, histogram, combo, and Pareto charts
B9: • | C9: Add trendlines, dynamic titles, and sparklines
B10: • | C10: Design clear, accessible charts that tell one story
B12: How to use this workbook
B13: 1. Read the guide | C13: The lesson guide (README) explains each skill with examples: https://github.com/lmansf/learn-excel/tree/main/03-data-analysis/05-charts-visualization
B14: 2. Practice | C14: Go to the 'Practice' sheet. Type a formula or value into each yellow cell.
B15: 3. Check yourself | C15: The Check column shows ✔ Correct (green) or ✘ Not yet (red).
B16: 4. Bonus | C16: Finished? Try the harder 'Bonus' sheet.
B17: 5. Answers | C17: The 'Answer Key' and 'Bonus Key' sheets are hidden. Right-click any sheet tab → Unhide… → pick one → OK. (Try first!)
B18: Note | C18: Build every chart next to its table. Each data sheet has empty columns on the right for that.
B19: Note | C19: The Makeover sheet holds a deliberately misleading chart for Task 4. Fix it in place.
B20: Note | C20: The hidden 'Chart Key' sheet shows a reference version of every chart. Unhide it the same way as the Answer Key. It draws the histogram, Pareto, and waterfall the classic way (column charts with helper data), so they look slightly different from Excel 2016's built-in versions.
B21: Note | C21: Histogram, Pareto, and waterfall charts need Excel 2016 or later (Windows or Mac) or Microsoft 365.
B22: Note | C22: On the Stays sheet, LOSDays is the exact length of stay (discharge time minus admit time, in days, rounded to 1 decimal place), so it can differ slightly from the count of midnights used in Lesson 3.4.
B24: Color legend
B25: Yellow cell | C25: Your answer goes here.
B26: Gray cell | C26: Pre-filled summary formula. It reads the work you did on another sheet, so don't type over it.
B27: ✔ Correct | C27: Your answer matches the key.
B28: ✘ Not yet | C28: Not matching yet. Check the hint and try again.
B30: Sheets in this workbook
B31: ED_Hourly | C31: Data: 24 rows, in the Excel Table 'tblEDHourly'
B32: ED_Monthly | C32: Data: 24 rows, in the Excel Table 'tblEDMonthly'
B33: Readmits | C33: Data: 8 rows, in the Excel Table 'tblReadmits'
B34: PayerMix | C34: Data: 5 rows, in the Excel Table 'tblPayerMix'
B35: Stays | C35: Data: 300 rows, in the Excel Table 'tblStays'
B36: Denials | C36: Data: 7 rows, in the Excel Table 'tblDenials'
B37: Budget | C37: Data: 10 rows, in the Excel Table 'tblBudget'
B38: About the data | C38: Bluestone Health System, pre-summarized for charting: monthly ED visits by hospital with counts of patients who left without being seen (LWBS), Jan 2024 – Dec 2025, 2025 ED arrivals and average door-to-provider minutes by hour of day, 2025 readmission rates by service line, 2025 payer mix, a sample of 300 of the 2,859 inpatient stays that began in 2025, 2025 claim denials by reason, and 4 West's FY2025 budget-to-actual margin bridge.
B39: Disclaimer | C39: All people, places, and numbers are synthetic and fictional. Not clinical guidance.

Sheet Practice
A1: Lesson 3.5 · Practice
A2: Each task names the sheet to work on. Build each chart on the same sheet as its data, to the right of the table, then type the number or name your chart shows into the yellow cell. The Check column can't see your chart, so every task asks a question the finished chart answers. The hidden Chart Key sheet shows a reference version of each chart. The yellow LWBSRate and CumulativePct columns are for the Bonus.
A3: Type a formula or value in each yellow cell. The Check column turns green when your answer matches. Stuck? Read the hint, then the lesson guide. Answers: right-click a sheet tab → Unhide… → 'Answer Key'.
A4: ="Score: "&COUNTIF(E6:E18,"✔*")&" of 13 auto-checked tasks correct"
A5: # | B5: Task | C5: Hint | D5: Your Answer | E5: Check
A6: 1 | B6: On ED_Hourly, select A1:B25 (ArrivalHour and Arrivals) and insert a clustered column chart. Which hour of the day had the most ED arrivals in 2025? Type the hour as a number from 0 to 23 (for example, 9 for the 09:00 hour). | C6: Insert → Insert Column or Bar Chart → Clustered Column. Hover over the tallest column | E6: =IF(IFERROR(D6="",FALSE),"",IF(IFERROR(AND(ISNUMBER(D6),OR(ABS(D6-'Answer Key'!$C$5)<=0.0001,ABS(D6-0.6666666666666666)<=0.0001)),FALSE),"✔ Correct","✘ Not yet"))
A7: 2 | B7: On ED_Monthly, select A1:D25 (Month and the three hospitals) and insert a line chart. In which month did Cedar Ridge have its most ED visits? Type the month and year (for example, Jun 2025). | C7: Insert → Insert Line or Area Chart → Line. Hover over the highest point of the Cedar Ridge line | E7: =IF(IFERROR(D7="",FALSE),"",IF(IFERROR(AND(ISNUMBER(D7),INT(D7)=INT('Answer Key'!$C$6)),FALSE),"✔ Correct","✘ Not yet"))
A8: 3 | B8: On Readmits, sort the table by ReadmitRate from largest to smallest. Then select ServiceLine and ReadmitRate (A1:A9, then Ctrl+click D1:D9, or ⌘+click on a Mac) and insert a clustered bar chart. Before you change anything else, which service line's bar is at the TOP of the chart? (Afterwards, fix the order so the highest rate is on top.) | C8: Read the chart, not the table. Guide section 6 explains the bar order and how to fix it | E8: =IF(IFERROR(D8="",FALSE),"",IF(IFERROR(OR(LOWER(TRIM(D8&""))=LOWER(TRIM('Answer Key'!$C$7&"")),LOWER(TRIM(D8&""))="women and children"),FALSE),"✔ Correct","✘ Not yet"))
A9: 4 | B9: The Makeover sheet has a colleague's column chart of the same readmission rates. Its vertical axis starts at 5%, not 0%. Measured from that axis, how many times taller is the Cardiovascular bar than the Women & Children bar? Round to 1 decimal place. Then fix the chart in place, using the checklist in Guide section 16, and add alt text. | C9: A bar's drawn height is its value minus the axis minimum (5%) | E9: =IF(IFERROR(D9="",FALSE),"",IF(IFERROR(AND(ISNUMBER(D9),OR(ABS(D9-'Answer Key'!$C$8)<=0.051)),FALSE),"✔ Correct","✘ Not yet"))
A10: 5 | B10: On PayerMix, insert a pie chart of 2025 encounters by PayerType. Add data labels that show the Percentage (not the Value), formatted with 1 decimal place. What does the Commercial label show? | C10: Format Data Labels → Label Options: tick Percentage, untick Value. Then Number → Percentage, 1 decimal | E10: =IF(IFERROR(D10="",FALSE),"",IF(IFERROR(AND(ISNUMBER(D10),OR(ABS(D10-'Answer Key'!$C$9)<=0.00051,ABS(D10-'Answer Key'!$C$9*100)<=0.051000000000000004)),FALSE),"✔ Correct","✘ Not yet"))
A11: 6 | B11: On Stays, insert a histogram of LOSDays (all 300 stays). Format the horizontal axis with Bin width 1, Overflow bin 10, and Underflow bin 1. How many stays fall in the overflow bin (longer than 10 days)? | C11: Select D1:D301, then Insert → Insert Statistic Chart → Histogram. Double-click the horizontal axis | E11: =IF(IFERROR(D11="",FALSE),"",IF(IFERROR(AND(ISNUMBER(D11),OR(ABS(D11-'Answer Key'!$C$10)<=0.0001)),FALSE),"✔ Correct","✘ Not yet"))
A12: 7 | B12: On Stays, select D1:E301 (LOSDays and TotalCharges) and insert an XY scatter chart, so LOSDays is on the horizontal axis. Add a linear trendline and display its equation. By how many dollars do charges rise for each extra day in the hospital? Confirm with SLOPE and round to the nearest dollar. | C12: Insert → Insert Scatter (X, Y) or Bubble Chart → Scatter. Right-click a point → Add Trendline, then tick Display Equation on chart. SLOPE takes the Y range first | E12: =IF(IFERROR(D12="",FALSE),"",IF(IFERROR(AND(ISNUMBER(D12),OR(ABS(D12-'Answer Key'!$C$11)<=0.5)),FALSE),"✔ Correct","✘ Not yet"))
A13: 8 | B13: Make a second scatter chart on Stays with AgeAtAdmit on the horizontal axis and LOSDays on the vertical axis (C1:D301). Add a linear trendline and display the R-squared value. What is R²? Confirm with RSQ and enter it to 4 decimal places. | C13: RSQ(known_y's, known_x's) | E13: =IF(IFERROR(D13="",FALSE),"",IF(IFERROR(AND(ISNUMBER(D13),OR(ABS(D13-'Answer Key'!$C$12)<=6e-05)),FALSE),"✔ Correct","✘ Not yet"))
A14: 9 | B14: Back on ED_Hourly, select A1:C25 and insert a combo chart with Arrivals as clustered columns and AvgDoorToProviderMin as a line on the secondary axis. Which arrival hour has the longest average wait to see a provider? Type the hour as a number from 0 to 23. | C14: Insert → Insert Combo Chart → Clustered Column – Line on Secondary Axis | E14: =IF(IFERROR(D14="",FALSE),"",IF(IFERROR(AND(ISNUMBER(D14),OR(ABS(D14-'Answer Key'!$C$13)<=0.0001,ABS(D14-0.5416666666666666)<=0.0001)),FALSE),"✔ Correct","✘ Not yet"))
A15: 10 | B15: On Denials, select A1:B8 (DenialReason and Claims) and insert a Pareto chart. What cumulative percentage does the line reach at the second bar (the top two reasons together)? Enter it as a percentage to 1 decimal place. | C15: Insert → Insert Statistic Chart → Pareto. Confirm with LARGE and SUM | E15: =IF(IFERROR(D15="",FALSE),"",IF(IFERROR(AND(ISNUMBER(D15),OR(ABS(D15-'Answer Key'!$C$14)<=0.00051,ABS(D15-'Answer Key'!$C$14*100)<=0.051000000000000004)),FALSE),"✔ Correct","✘ Not yet"))
A16: 11 | B16: On Budget, select A4:B14 and insert a waterfall chart. Set the first and last bars as totals. Which step is the largest drop (the longest downward bar)? Type the Step name as it appears in the table. | C16: Insert → Insert Waterfall, Funnel, Stock, Surface, or Radar Chart → Waterfall. Right-click a bar → Set as Total | E16: =IF(IFERROR(D16="",FALSE),"",IF(IFERROR(OR(LOWER(TRIM(D16&""))=LOWER(TRIM('Answer Key'!$C$15&"")),LOWER(TRIM(D16&""))="revenue",LOWER(TRIM(D16&""))="net patient service revenue",LOWER(TRIM(D16&""))="net revenue",LOWER(TRIM(D16&""))="patient revenue"),FALSE),"✔ Correct","✘ Not yet"))
A17: 12 | B17: On ED_Monthly, insert line sparklines in the yellow cells B27:D27 (Data Range B2:D25), one per hospital. Turn on First Point and Last Point markers. For how many of the three hospitals is the last point (Dec 2025) higher than the first point (Jan 2024)? | C17: Insert → Sparklines → Line. Then the Sparkline tab → Show → First Point, Last Point | E17: =IF(IFERROR(D17="",FALSE),"",IF(IFERROR(AND(ISNUMBER(D17),OR(ABS(D17-'Answer Key'!$C$16)<=0.0001)),FALSE),"✔ Correct","✘ Not yet"))
A18: 13 | B18: Write a formula in the yellow cell that builds this chart title from tblEDMonthly: ED visits by facility, [first month] to [last month] ([total visits] visits). Show each month as a three-letter month and year, and the total with a thousands separator. Example of the pattern: ED visits by facility, Mar 2023 to Feb 2024 (9,876 visits). Then link the title of your Task 2 line chart to this cell. | C18: TEXT(MIN(…),"mmm yyyy") and TEXT(SUM(…),"#,##0"), joined with & | E18: =IF(IFERROR(D18="",FALSE),"",IF(IFERROR(OR(LOWER(TRIM(D18&""))=LOWER(TRIM('Answer Key'!$C$17&"")),LOWER(TRIM(D18&""))="ed visits by facility, january 2024 to december 2025 (12,292 visits)",LOWER(TRIM(D18&""))="ed visits by facility, jan 2024 to dec 2025 (12292 visits)"),FALSE),"✔ Correct","✘ Not yet"))

Sheet ED_Hourly
A1: ArrivalHour | B1: Arrivals | C1: AvgDoorToProviderMin
A2: 00:00 | B2: 154 | C2: 35.4
A3: 01:00 | B3: 112 | C3: 36.6
A4: 02:00 | B4: 102 | C4: 30.3
A5: 03:00 | B5: 102 | C5: 28.2
A6: 04:00 | B6: 77 | C6: 27.8
A7: 05:00 | B7: 107 | C7: 28.1
A8: 06:00 | B8: 111 | C8: 33.9
A9: 07:00 | B9: 180 | C9: 41.5
A10: 08:00 | B10: 257 | C10: 38.7
A11: 09:00 | B11: 313 | C11: 45.9
A12: 10:00 | B12: 392 | C12: 50.6
A13: 11:00 | B13: 391 | C13: 53.4
... A25: 23:00 | B25: 168 | C25: 34.4

Sheet ED_Monthly
A1: Month | B1: Bluestone Memorial | C1: Ashby Falls | D1: Cedar Ridge | E1: Total | F1: LWBS | G1: LWBSRate
A2: 45292 | B2: 405 | C2: 85 | D2: 90 | E2: 580 | F2: 15
A3: 45323 | B3: 408 | C3: 85 | D3: 93 | E3: 586 | F3: 21
A4: 45352 | B4: 411 | C4: 69 | D4: 99 | E4: 579 | F4: 14
A5: 45383 | B5: 340 | C5: 56 | D5: 70 | E5: 466 | F5: 10
A6: 45413 | B6: 338 | C6: 73 | D6: 66 | E6: 477 | F6: 9
A7: 45444 | B7: 300 | C7: 55 | D7: 67 | E7: 422 | F7: 3
A8: 45474 | B8: 321 | C8: 52 | D8: 71 | E8: 444 | F8: 7
A9: 45505 | B9: 318 | C9: 71 | D9: 80 | E9: 469 | F9: 9
A10: 45536 | B10: 287 | C10: 56 | D10: 60 | E10: 403 | F10: 15
A11: 45566 | B11: 333 | C11: 64 | D11: 69 | E11: 466 | F11: 8
A12: 45597 | B12: 413 | C12: 63 | D12: 86 | E12: 562 | F12: 8
A13: 45627 | B13: 435 | C13: 106 | D13: 80 | E13: 621 | F13: 18
... A25: 45992 | B25: 423 | C25: 79 | D25: 93 | E25: 595 | F25: 19
A27: Trend
A28: Task 12: put line sparklines in the yellow cells B27:D27.

Sheet Readmits
A1: ServiceLine | B1: IndexStays | C1: Readmissions | D1: ReadmitRate
A2: Behavioral Health | B2: 123 | C2: 14 | D2: 0.11382114
A3: Cardiovascular | B3: 354 | C3: 65 | D3: 0.18361582
A4: Critical Care | B4: 184 | C4: 33 | D4: 0.17934783
A5: Medicine | B5: 1562 | C5: 252 | D5: 0.16133163
A6: Neuroscience | B6: 136 | C6: 21 | D6: 0.15441176
A7: Oncology | B7: 85 | C7: 8 | D7: 0.094117647
A8: Orthopedics | B8: 149 | C8: 14 | D8: 0.093959732
A9: Women & Children | B9: 266 | C9: 17 | D9: 0.063909774

Sheet Makeover
A1: Chart makeover (Task 4)
A2: A colleague made this chart of 2025 readmission rates from the Readmits sheet. It has several design problems. Answer Task 4, then fix the chart in place.

Sheet PayerMix
A1: PayerType | B1: Encounters
A2: Government | B2: 4620
A3: Commercial | B3: 4198
A4: Medicare Advantage | B4: 1681
A5: Self-Pay | B5: 589
A6: Workers' Comp | B6: 57

Sheet Stays
A1: EncounterID | B1: ServiceLine | C1: AgeAtAdmit | D1: LOSDays | E1: TotalCharges
A2: ENC110713 | B2: Medicine | C2: 45 | D2: 3.4 | E2: 10673.63
A3: ENC110742 | B3: Medicine | C3: 80 | D3: 2.8 | E3: 15321.28
A4: ENC110788 | B4: Medicine | C4: 34 | D4: 3.6 | E4: 23338.39
A5: ENC110846 | B5: Medicine | C5: 53 | D5: 3.8 | E5: 16258.28
A6: ENC110878 | B6: Women & Children | C6: 33 | D6: 2.3 | E6: 19402.63
A7: ENC110922 | B7: Medicine | C7: 69 | D7: 2.7 | E7: 8674.56
A8: ENC110959 | B8: Women & Children | C8: 2 | D8: 3.8 | E8: 13197.21
A9: ENC110984 | B9: Medicine | C9: 77 | D9: 3 | E9: 10520.63
A10: ENC111057 | B10: Medicine | C10: 91 | D10: 4 | E10: 12776.77
A11: ENC111089 | B11: Orthopedics | C11: 55 | D11: 5.3 | E11: 69733.36
A12: ENC111117 | B12: Cardiovascular | C12: 77 | D12: 5.8 | E12: 30667.36
A13: ENC111138 | B13: Medicine | C13: 78 | D13: 11.4 | E13: 48028.29
... A301: ENC121728 | B301: Women & Children | C301: 36 | D301: 2.1 | E301: 26424.65

Sheet Denials
A1: DenialReason | B1: Claims | C1: DeniedCharges | D1: CumulativePct
A2: Authorization Required | B2: 395 | C2: 5015271.9
A3: Coding Error | B3: 200 | C3: 2354746.6
A4: Duplicate Claim | B4: 35 | C4: 295135.49
A5: Eligibility / Coverage | B5: 125 | C5: 1260363.8
A6: Medical Necessity | B6: 243 | C6: 3239702.7
A7: Missing Documentation | B7: 97 | C7: 1360498.8
A8: Timely Filing | B8: 47 | C8: 380612.26

Sheet Budget
A1: Medical-Surgical 4 West (Bluestone Memorial) · FY2025 operating margin, budget to actual
A2: Positive amounts are favorable: revenue above budget, or an expense category that came in under budget. Negative amounts are unfavorable.
A4: Step | B4: Amount
A5: Budgeted operating margin | B5: 751385
A6: Net patient revenue | B6: -366593
A7: Salaries & wages | B7: 284237
A8: Employee benefits | B8: -1188
A9: Medical supplies | B9: 90127
A10: Pharmaceuticals | B10: 7363
A11: Purchased services | B11: -19608
A12: Equipment & maintenance | B12: -5765
A13: Other operating | B13: -4548
A14: Actual operating margin | B14: 735410

Sheet Bonus
A1: Lesson 3.5 · Bonus: Charts for the operations review
A2: Two directors bring questions to Bluestone's monthly operations review. The ED medical director believes patients leave without being seen (LWBS) mainly in busy months, and the ED's target is an LWBS rate of 2% or less. The revenue-cycle director wants to know which denial reasons to work first, ranked by dollars at risk (DeniedCharges) rather than by claim counts. Build a combo chart and a scatter chart for the first question and a Pareto chart for the second, then check the numbers behind them.
A3: Type a formula or value in each yellow cell. The Check column turns green when your answer matches. Stuck? Read the hint, then the lesson guide. Answers: right-click a sheet tab → Unhide… → 'Bonus Key'.
A4: ="Score: "&COUNTIF(E6:E10,"✔*")&" of 5 auto-checked tasks correct"
A5: # | B5: Task | C5: Hint | D5: Your Answer | E5: Check
A6: B1 | B6: On ED_Monthly, fill the yellow LWBSRate column with LWBS ÷ Total for each month. The column is already formatted as a percentage. The gray cell counts the months above the 2% target. How many of the 24 months missed the target? | C6: Write one formula in G2 with [@Column] references (Lesson 3.1). The Table fills the other 23 rows | D6: {=IF(COUNT(ED_Monthly!$G$2:$G$25)=0,"",COUNTIF(ED_Monthly!$G$2:$G$25,">0.02"))} | E6: =IF(IFERROR(D6="",FALSE),"",IF(IFERROR(AND(ISNUMBER(D6),OR(ABS(D6-'Bonus Key'!$C$5)<=0.0001)),FALSE),"✔ Correct","✘ Not yet"))
A7: B2 | B7: Build a combo chart on ED_Monthly with Total as clustered columns and LWBSRate as a line on the secondary axis (select Month, then Ctrl+click or ⌘+click Total and LWBSRate). Which month had the highest LWBS rate? Type the month and year. | C7: Select A1:A25, Ctrl+click E1:E25 and G1:G25, then Insert → Insert Combo Chart | E7: =IF(IFERROR(D7="",FALSE),"",IF(IFERROR(AND(ISNUMBER(D7),INT(D7)=INT('Bonus Key'!$C$6)),FALSE),"✔ Correct","✘ Not yet"))
A8: B3 | B8: Test the director's theory with a scatter chart of Total (horizontal axis) against LWBSRate (vertical axis), with a linear trendline and its R². What is R²? Enter it to 3 decimal places. | C8: Select E1:E25, Ctrl+click G1:G25, then Insert → Scatter. RSQ(known_y's, known_x's) confirms it | E8: =IF(IFERROR(D8="",FALSE),"",IF(IFERROR(AND(ISNUMBER(D8),OR(ABS(D8-'Bonus Key'!$C$7)<=0.0006)),FALSE),"✔ Correct","✘ Not yet"))
A9: B4 | B9: On Denials, build a Pareto chart by DeniedCharges by hand: sort the table by DeniedCharges (largest first), fill CumulativePct with each row's running share of total DeniedCharges, then insert a combo chart with DeniedCharges as columns and CumulativePct as a line on the secondary axis (fix that axis at 0% to 100%). How many reasons does it take to reach at least 80% of denied charges? | C9: Follow 'A Pareto by hand' in Guide section 12. DeniedCharges is column C. Sort before you chart | E9: =IF(IFERROR(D9="",FALSE),"",IF(IFERROR(AND(ISNUMBER(D9),OR(ABS(D9-'Bonus Key'!$C$8)<=0.0001)),FALSE),"✔ Correct","✘ Not yet"))
A10: B5 | B10: Compare this Pareto with the one you built by claim count in Task 10. Exactly one reason ranks higher by denied charges than by number of claims. Which one? Type it as it appears in the table. | C10: Compare the order of the bars in the two Pareto charts | E10: =IF(IFERROR(D10="",FALSE),"",IF(IFERROR(OR(LOWER(TRIM(D10&""))=LOWER(TRIM('Bonus Key'!$C$9&""))),FALSE),"✔ Correct","✘ Not yet"))

Sheet Answer Key
A1: 🔑 Answer Key — Lesson 3.5
A2: Spoiler alert: try every task before reading this sheet. Column C is the value the Check column compares against. Column D is a sample solution, and column E recalculates a formula for it live, proving the answer.
A4: # | B4: Task | C4: Answer | D4: Sample solution | E4: Live result | F4: Explanation
A5: 1 | B5: On ED_Hourly, select A1:B25 (ArrivalHour and Arrivals) and insert a clustered column chart. Which hour of the day had the most ED arrivals in 2025? Type the hour as a number from 0 to 23 (for example, 9 for the 09:00 hour). | C5: 16 | D5: 1. On ED_Hourly, select A1:B25: the ArrivalHour labels and the Arrivals numbers, headers included. 2. Choose Insert → Insert Column or Bar Chart → 2-D Column → Clustered Column. On Windows you can also press Alt + F1, which inserts the default chart type (clustered column unless someone changed it). 3. Drag the chart to the right of the table. Hover over the tallest column: the tooltip reads Series "Arrivals" Point "16:00" Value: 408. | E5: {=VALUE(LEFT(_xlfn.XLOOKUP(MAX(tblEDHourly[Arrivals]),tblEDHourly[Arrivals],tblEDHourly[ArrivalHour]),2))} | F5: The 16:00 hour had 408 arrivals, just ahead of 12:00 with 404. The quietest hour was 04:00 with 77. A column chart suits this question because it compares one number across categories, and the eye compares column heights quickly. ArrivalHour holds text labels such as 16:00, so Excel uses it as the category axis automatically. If the hours were numbers, Excel would plot them as a second series of short columns. Cross-check with a formula: =VALUE(LEFT(XLOOKUP(MAX(tblEDHourly[Arrivals]),tblEDHourly[Arrivals],tblEDHourly[ArrivalHour]),2))
A6: 2 | B6: On ED_Monthly, select A1:D25 (Month and the three hospitals) and insert a line chart. In which month did Cedar Ridge have its most ED visits? Type the month and year (for example, Jun 2025). | C6: 45352 | D6: 1. On ED_Monthly, select A1:D25. 2. Choose Insert → Insert Line or Area Chart → 2-D Line → Line (or Line with Markers). Excel recognizes the Month column as dates and builds a date axis, one point per month. 3. Hover over the highest point of the Cedar Ridge line, or click the line once and read the values in the tooltips. | E6: {=_xlfn.XLOOKUP(MAX(tblEDMonthly[Cedar Ridge]),tblEDMonthly[Cedar Ridge],tblEDMonthly[Month])} | F6: Cedar Ridge peaked at 99 visits in Mar 2024. A line chart is the standard choice for a trend over time because the slope between points shows the change. Notice how flat the Cedar Ridge and Ashby Falls lines look: Bluestone Memorial (peak 473 in Jan 2025) sets the scale, so the smaller hospitals' swings shrink. When a small series matters, give it its own chart. Cross-check with a formula: =XLOOKUP(MAX(tblEDMonthly[Cedar Ridge]),tblEDMonthly[Cedar Ridge],tblEDMonthly[Month])
A7: 3 | B7: On Readmits, sort the table by ReadmitRate from largest to smallest. Then select ServiceLine and ReadmitRate (A1:A9, then Ctrl+click D1:D9, or ⌘+click on a Mac) and insert a clustered bar chart. Before you change anything else, which service line's bar is at the TOP of the chart? (Afterwards, fix the order so the highest rate is on top.) | C7: Women & Children | D7: 1. Click any ReadmitRate cell and choose Data → Sort Largest to Smallest (Mac: Data → Sort, or the column's filter button). 2. Select A1:A9, hold Ctrl (Mac: ⌘), and select D1:D9. 3. Choose Insert → Insert Column or Bar Chart → 2-D Bar → Clustered Bar. 4. Read the top bar: it's Women & Children, the lowest rate. 5. To fix the order, double-click the vertical (category) axis to open Format Axis, then under Axis Options tick Categories in reverse order. Set Horizontal axis crosses to At maximum category so the value axis stays at the bottom. | E7: {=_xlfn.XLOOKUP(MIN(tblReadmits[ReadmitRate]),tblReadmits[ReadmitRate],tblReadmits[ServiceLine])} | F7: A bar chart plots the first category next to the origin, which is the bottom of a bar chart. So a table sorted from highest to lowest produces a chart with the highest bar at the bottom and the lowest (Women & Children, 6.4%) at the top, which is upside down for a ranking. Categories in reverse order flips it without re-sorting the data. Bars suit this data better than columns because the service-line names are long and read easily on the left. Cross-check with a formula: =XLOOKUP(MIN(tblReadmits[ReadmitRate]),tblReadmits[ReadmitRate],tblReadmits[ServiceLine])
A8: 4 | B8: The Makeover sheet has a colleague's column chart of the same readmission rates. Its vertical axis starts at 5%, not 0%. Measured from that axis, how many times taller is the Cardiovascular bar than the Women & Children bar? Round to 1 decimal place. Then fix the chart in place, using the checklist in Guide section 16, and add alt text. | C8: 9.6 | D8: 1. Each bar is drawn up from the axis minimum, so its height is its rate minus 5%. 2. (0.1836 − 0.05) ÷ (0.0639 − 0.05) = 9.6. 3. Fix the chart: double-click the vertical axis, and in Format Axis → Axis Options → Bounds set Minimum to 0 (or click Reset so Excel chooses 0). Turn off Vary colors by point (Format Data Series → Fill & Line → Fill), delete the legend, add data labels, and give the chart a title that states the finding. 4. Right-click the chart → Edit Alt Text and describe it, for example: Column chart of 2025 30-day readmission rates by service line. Cardiovascular is highest at 18.4% and Women & Children lowest at 6.4%. | E8: {=(MAX(tblReadmits[ReadmitRate])-0.05)/(MIN(tblReadmits[ReadmitRate])-0.05)} | F8: The real ratio is 18.4% ÷ 6.4% = 2.9, but the truncated chart draws the Cardiovascular bar 9.6 times as tall. A bar's length is how readers judge its value, so every bar and column chart needs a value axis that starts at zero. Line charts are different: their message is in the slope, so a line chart's axis may start above zero as long as it's labeled. The other problems on the Makeover chart (rainbow colors and a legend that repeats the axis labels) add color without adding information. Cross-check with a formula: =(MAX(tblReadmits[ReadmitRate])-0.05)/(MIN(tblReadmits[ReadmitRate])-0.05)
A9: 5 | B9: On PayerMix, insert a pie chart of 2025 encounters by PayerType. Add data labels that show the Percentage (not the Value), formatted with 1 decimal place. What does the Commercial label show? | C9: 0.37667115 | D9: 1. Click any cell in tblPayerMix and choose Insert → Insert Pie or Doughnut Chart → 2-D Pie. 2. Add labels: click the Chart Elements button (+) → Data Labels → More Options… (Mac: Chart Design → Add Chart Element → Data Labels → More Data Label Options). 3. In Label Options, tick Percentage and Category Name and untick Value. Under Number, choose Percentage with 1 decimal place. 4. Read the Commercial slice. | E9: {=_xlfn.XLOOKUP("Commercial",tblPayerMix[PayerType],tblPayerMix[Encounters])/SUM(tblPayerMix[Encounters])} | F9: Excel computes each slice's percentage itself: 4,198 ÷ 11,145 = 37.7%. The default label format has no decimals, so it would round to 38%. A pie works here because there are only five parts of one whole and two of them dominate. Workers' Comp (0.5%) is barely a sliver, which is the usual limit of a pie: with more or smaller slices, a sorted bar chart compares parts far more accurately. Cross-check with a formula: =XLOOKUP("Commercial",tblPayerMix[PayerType],tblPayerMix[Encounters])/SUM(tblPayerMix[Encounters])
A10: 6 | B10: On Stays, insert a histogram of LOSDays (all 300 stays). Format the horizontal axis with Bin width 1, Overflow bin 10, and Underflow bin 1. How many stays fall in the overflow bin (longer than 10 days)? | C10: 9 | D10: 1. On Stays, select D1:D301 (the LOSDays column with its header). 2. Choose Insert → Insert Statistic Chart → Histogram. On a Mac, the same Statistic Chart button is on the Insert tab. 3. Double-click the horizontal axis. Under Axis Options → Bins, choose Bin width 1, tick Overflow bin and type 10, and tick Underflow bin and type 1. 4. Hover over the last column, labeled >10. | E10: {=COUNTIF(tblStays[LOSDays],">10")} | F10: A histogram answers "how are the values distributed?" by counting values in equal-width bins. Here the tallest bin is (3, 4] days with 75 stays, and the long right tail ends in the >10 overflow bin with 9 stays. That skew is why the median length of stay (3.90 days) sits below the mean (4.59 days). The few long stays pull the mean up but barely move the median. A bin label such as (3, 4] means "more than 3, up to and including 4". The overflow and underflow bins stop a few extreme stays from stretching the axis. Cross-check with a formula: =COUNTIF(tblStays[LOSDays],">10")
A11: 7 | B11: On Stays, select D1:E301 (LOSDays and TotalCharges) and insert an XY scatter chart, so LOSDays is on the horizontal axis. Add a linear trendline and display its equation. By how many dollars do charges rise for each extra day in the hospital? Confirm with SLOPE and round to the nearest dollar. | C11: 4921.9599 | D11: 1. Select D1:E301. The left column (LOSDays) becomes X, the right one (TotalCharges) becomes Y. 2. Choose Insert → Insert Scatter (X, Y) or Bubble Chart → Scatter. 3. Right-click any point → Add Trendline…. In Format Trendline, keep Linear and tick Display Equation on chart and Display R-squared value on chart. 4. The equation reads about y = 4922x + 9225. The slope is the number in front of x. 5. Confirm in the yellow cell: =SLOPE(Stays!E2:E301,Stays!D2:D301). | E11: {=SLOPE(tblStays[TotalCharges],tblStays[LOSDays])} | F11: A linear trendline is the least-squares line through the points, the same line that SLOPE and INTERCEPT calculate. Its slope says that each extra day adds about $4,922 in charges on average. R² is 0.31, so length of stay explains about 31% of the variation in charges. The rest comes from what happened during the stay, such as surgery, ICU days, and imaging. SLOPE takes the Y range first, which is easy to get backwards. Cross-check with a formula: =SLOPE(tblStays[TotalCharges],tblStays[LOSDays])
A12: 8 | B12: Make a second scatter chart on Stays with AgeAtAdmit on the horizontal axis and LOSDays on the vertical axis (C1:D301). Add a linear trendline and display the R-squared value. What is R²? Confirm with RSQ and enter it to 4 decimal places. | C12: 0.018515007 | D12: 1. Select C1:D301 and choose Insert → Insert Scatter (X, Y) or Bubble Chart → Scatter. 2. Right-click a point → Add Trendline… → Linear, and tick Display R-squared value on chart. 3. The label reads R² = 0.0185. 4. Confirm in the yellow cell: =RSQ(Stays!D2:D301,Stays!C2:C301). | E12: {=RSQ(tblStays[LOSDays],tblStays[AgeAtAdmit])} | F12: R² = 0.0185 means age explains under 2% of the variation in length of stay. The trendline still slopes upward (about 0.017 days per year of age, or 0.17 days per decade), but the points scatter widely around it. Always show R² next to a trendline, because a line can be drawn through any cloud of points, related or not. Even a high R² shows association, not cause. Cross-check with a formula: =RSQ(tblStays[LOSDays],tblStays[AgeAtAdmit])
A13: 9 | B13: Back on ED_Hourly, select A1:C25 and insert a combo chart with Arrivals as clustered columns and AvgDoorToProviderMin as a line on the secondary axis. Which arrival hour has the longest average wait to see a provider? Type the hour as a number from 0 to 23. | C13: 13 | D13: 1. Select A1:C25 on ED_Hourly. 2. Choose Insert → Insert Combo Chart → Clustered Column – Line on Secondary Axis. (Or insert any chart, then Chart Design → Change Chart Type → Combo, set AvgDoorToProviderMin to Line and tick its Secondary Axis box.) 3. Add axis titles with Chart Elements (+) → Axis Titles (Mac: Chart Design → Add Chart Element → Axis Titles): Arrivals on the left and Avg minutes to provider on the right. 4. Hover over the highest point of the line. | E13: {=VALUE(LEFT(_xlfn.XLOOKUP(MAX(tblEDHourly[AvgDoorToProviderMin]),tblEDHourly[AvgDoorToProviderMin],tblEDHourly[ArrivalHour]),2))} | F13: Arrivals peak at 16:00, and the average wait peaks at 13:00 (57.1 minutes, against 27.8 at 04:00). The two series use different units (visits and minutes) and very different sizes, so the line needs its own axis. Otherwise it would be squashed flat. The two shapes match closely (correlation 0.96), so waits rise and fall with arrivals. That suggests staffing doesn't keep pace in the busy hours, but the chart alone can't prove the cause. Always title both axes on a dual-axis chart so nobody reads minutes off the arrivals scale. Cross-check with a formula: =VALUE(LEFT(XLOOKUP(MAX(tblEDHourly[AvgDoorToProviderMin]),tblEDHourly[AvgDoorToProviderMin],tblEDHourly[ArrivalHour]),2))
A14: 10 | B14: On Denials, select A1:B8 (DenialReason and Claims) and insert a Pareto chart. What cumulative percentage does the line reach at the second bar (the top two reasons together)? Enter it as a percentage to 1 decimal place. | C14: 0.558669 | D14: 1. Select A1:B8 on Denials. 2. Choose Insert → Insert Statistic Chart → Pareto. Excel sorts the reasons from most to fewest claims and adds a cumulative-percentage line on a secondary axis that runs to 100%. 3. Hover over the line at the second bar. 4. To get the exact value, type =(LARGE(Denials!B2:B8,1)+LARGE(Denials!B2:B8,2))/SUM(Denials!B2:B8) and format it as a percentage with 1 decimal place. | E14: {=SUM(LARGE(tblDenials[Claims],{1,2}))/SUM(tblDenials[Claims])} | F14: Authorization Required (395 claims) and Medical Necessity (243) make up 638 of 1,142 denied claims. A Pareto chart ranks causes so a team can see the "vital few" worth fixing first. Here the first two reasons cover 55.9% of denials and the first four cover 84.3%. The built-in Pareto sorts the data for you, so the table itself can stay in any order. LARGE(range,1) and LARGE(range,2) return the largest and second-largest claim counts, which are the first two bars. The shorter cross-check formula that follows hands LARGE the array constant {1,2} (Lesson 2.5) so it returns both at once, and SUM adds them. Cross-check with a formula: =SUM(LARGE(tblDenials[Claims],{1,2}))/SUM(tblDenials[Claims])
A15: 11 | B15: On Budget, select A4:B14 and insert a waterfall chart. Set the first and last bars as totals. Which step is the largest drop (the longest downward bar)? Type the Step name as it appears in the table. | C15: Net patient revenue | D15: 1. Select A4:B14 on Budget. 2. Choose Insert → Insert Waterfall, Funnel, Stock, Surface, or Radar Chart → Waterfall (Mac: Insert → Waterfall). 3. Click the first bar once to select the series and once more to select only that bar. Right-click it → Set as Total. Do the same for the last bar. 4. Find the longest bar in the Decrease color (the legend shows which color that is). Hover over it to read its Step name. | E15: {=_xlfn.XLOOKUP(MIN(tblBudget[Amount]),tblBudget[Amount],tblBudget[Step])} | F15: A waterfall shows how a starting total becomes an ending total through a series of increases and decreases. 4 West budgeted a margin of $751,385 and earned $735,410. Revenue came in $366,593 under budget, the biggest drop, and salaries & wages saved $284,237, the biggest rise, so expense control offset most of the revenue shortfall. Without Set as Total, Excel treats the last row as one more increase and floats it on top of the running total. Cross-check with a formula: =XLOOKUP(MIN(tblBudget[Amount]),tblBudget[Amount],tblBudget[Step])
A16: 12 | B16: On ED_Monthly, insert line sparklines in the yellow cells B27:D27 (Data Range B2:D25), one per hospital. Turn on First Point and Last Point markers. For how many of the three hospitals is the last point (Dec 2025) higher than the first point (Jan 2024)? | C16: 2 | D16: 1. Select B27:D27 on ED_Monthly. 2. Choose Insert → Sparklines → Line. In Data Range type B2:D25. Location Range already shows $B$27:$D$27. Click OK. Excel draws one sparkline per column. 3. On the Sparkline tab, tick First Point and Last Point (and High Point if you like). 4. Compare each sparkline's two end markers. To check, compare row 25 with row 2. | E16: {=SUMPRODUCT(--(ED_Monthly!$B$25:$D$25>ED_Monthly!$B$2:$D$2))} | F16: Bluestone Memorial and Cedar Ridge ended higher than they started. Ashby Falls ended lower (85 visits in Jan 2024, 79 in Dec 2025). A sparkline is a word-sized chart in a cell, so it shows each series' shape next to the numbers. By default every sparkline gets its own vertical scale, which is right for comparing a series with itself but wrong for comparing hospitals. When heights should be comparable, open Sparkline → Axis and set both the minimum and the maximum to Same for All Sparklines. Cross-check with a formula: =SUMPRODUCT(--(ED_Monthly!$B$25:$D$25>ED_Monthly!$B$2:$D$2))
A17: 13 | B17: Write a formula in the yellow cell that builds this chart title from tblEDMonthly: ED visits by facility, [first month] to [last month] ([total visits] visits). Show each month as a three-letter month and year, and the total with a thousands separator. Example of the pattern: ED visits by facility, Mar 2023 to Feb 2024 (9,876 visits). Then link the title of your Task 2 line chart to this cell. | C17: ED visits by facility, Jan 2024 to Dec 2025 (12,292 visits) | D17: ="ED visits by facility, "&TEXT(MIN(tblEDMonthly[Month]),"mmm yyyy")&" to "&TEXT(MAX(tblEDMonthly[Month]),"mmm yyyy")&" ("&TEXT(SUM(tblEDMonthly[Total]),"#,##0")&" visits)" | E17: {="ED visits by facility, "&TEXT(MIN(tblEDMonthly[Month]),"mmm yyyy")&" to "&TEXT(MAX(tblEDMonthly[Month]),"mmm yyyy")&" ("&TEXT(SUM(tblEDMonthly[Total]),"#,##0")&" visits)"} | F17: Build the title in a cell, because a chart title can show text or one cell reference, but not a formula. To link it, click the chart title on ED_Monthly, type = in the formula bar, click the Practice sheet tab, click this yellow cell, and press Enter. The formula bar then shows a reference such as =Practice!$D$18. TEXT turns the dates and the total into formatted text. Without it, & would join the raw serial number 45292 instead of Jan 2024. Because the formula uses tblEDMonthly, adding January 2026 as a new row updates the chart and its title together.

Sheet Bonus Key
A1: 🔑 Bonus Key — Lesson 3.5
A2: Spoiler alert: try every task before reading this sheet. Column C is the value the Check column compares against. Column D is a sample solution, and column E recalculates a formula for it live, proving the answer.
A4: # | B4: Task | C4: Answer | D4: Sample solution | E4: Live result | F4: Explanation
A5: B1 | B5: On ED_Monthly, fill the yellow LWBSRate column with LWBS ÷ Total for each month. The column is already formatted as a percentage. The gray cell counts the months above the 2% target. How many of the 24 months missed the target? | C5: 8 | D5: =[@LWBS]/[@Total] | E5: {=SUMPRODUCT(--(tblEDMonthly[LWBS]/tblEDMonthly[Total]>0.02))} | F5: Type the formula in G2 (=F2/E2 works too). [@LWBS] means "the LWBS value in this row", and the Table fills the column for you. Rates make months comparable even though volume swings by 228 visits between the busiest and quietest months. The gray cell runs COUNTIF(G2:G25,">0.02") on your column, and 8 of the 24 months were above 2%.
A6: B2 | B6: Build a combo chart on ED_Monthly with Total as clustered columns and LWBSRate as a line on the secondary axis (select Month, then Ctrl+click or ⌘+click Total and LWBSRate). Which month had the highest LWBS rate? Type the month and year. | C6: 45536 | D6: 1. Select A1:A25, then hold Ctrl (Mac: ⌘) and select E1:E25 and G1:G25. 2. Choose Insert → Insert Combo Chart → Clustered Column – Line on Secondary Axis. 3. Title both axes (ED visits and LWBS rate). If the secondary axis shows too many decimals, set its number format to a percentage with 1 decimal place (Format Axis → Number). 4. Hover over the highest point of the line. | E6: {=_xlfn.XLOOKUP(MAX(tblEDMonthly[LWBS]/tblEDMonthly[Total]),tblEDMonthly[LWBS]/tblEDMonthly[Total],tblEDMonthly[Month])} | F6: Sep 2024 had 15 LWBS out of 403 visits (3.72%), yet it was the quietest month of the two years. The busiest month, Jan 2025 (631 visits), had an LWBS rate of only 1.74%. On the combo chart, the line's peaks don't line up with the tallest columns, which is the first hint that volume isn't the whole story. Cross-check with a formula: =XLOOKUP(MAX(tblEDMonthly[LWBS]/tblEDMonthly[Total]),tblEDMonthly[LWBS]/tblEDMonthly[Total],tblEDMonthly[Month])
A7: B3 | B7: Test the director's theory with a scatter chart of Total (horizontal axis) against LWBSRate (vertical axis), with a linear trendline and its R². What is R²? Enter it to 3 decimal places. | C7: 0.12095476 | D7: 1. Select E1:E25, then Ctrl+click (Mac: ⌘+click) G1:G25. The left column (Total) becomes X. 2. Choose Insert → Insert Scatter (X, Y) or Bubble Chart → Scatter. 3. Right-click a point → Add Trendline… → Linear, tick Display R-squared value on chart. 4. Confirm: =RSQ(ED_Monthly!G2:G25,ED_Monthly!E2:E25). | E7: {=RSQ(tblEDMonthly[LWBS]/tblEDMonthly[Total],tblEDMonthly[Total])} | F7: R² = 0.121. The trendline slopes upward (about 0.43 percentage points of LWBS per 100 extra visits), so busier months do run slightly higher, but volume explains only about 12% of the month-to-month variation. The director should look at staffing, boarding, and triage flow as well. Twenty-four points is a small sample, so treat any pattern as a lead to investigate rather than proof. Cross-check with a formula: =RSQ(tblEDMonthly[LWBS]/tblEDMonthly[Total],tblEDMonthly[Total])
A8: B4 | B8: On Denials, build a Pareto chart by DeniedCharges by hand: sort the table by DeniedCharges (largest first), fill CumulativePct with each row's running share of total DeniedCharges, then insert a combo chart with DeniedCharges as columns and CumulativePct as a line on the secondary axis (fix that axis at 0% to 100%). How many reasons does it take to reach at least 80% of denied charges? | C8: 4 | D8: 1. Click a DeniedCharges cell → Data → Sort Largest to Smallest. 2. In D2 type =SUM($C$2:C2)/SUM($C$2:$C$8) and press Enter. The Table fills it down, and the column is already formatted as a percentage. 3. Select A1:A8, then Ctrl+click (Mac: ⌘+click) C1:D8, and choose Insert → Insert Combo Chart → Clustered Column – Line on Secondary Axis. 4. Double-click the secondary axis and set Minimum 0 and Maximum 1. Optionally set the column Gap Width to about 10%. 5. Find the first bar where the line reaches 80%. | E8: {=SUMPRODUCT(--(SUMIF(tblDenials[DeniedCharges],">="&tblDenials[DeniedCharges])<0.8*SUM(tblDenials[DeniedCharges])))+1} | F8: Cumulative shares by dollars: Authorization Required 36.1%, Medical Necessity 59.4%, Coding Error 76.3%, Missing Documentation 86.1%, Eligibility / Coverage 95.1%, Timely Filing 97.9%, Duplicate Claim 100.0%. The line first passes 80% at reason 4, so 4 of the 7 reasons hold 86.1% of the $13,906,332 at risk. The mixed reference $C$2:C2 keeps its start fixed while its end moves down one row at a time (Lesson 1.5). Building a Pareto by hand takes longer than the built-in chart, but it works in every Excel version and lets you add an 80% reference line or label the cut-off. Cross-check (counts the reasons whose running share is still below 80%, then adds one): =SUMPRODUCT(--(SUMIF(tblDenials[DeniedCharges],">="&tblDenials[DeniedCharges])<0.8*SUM(tblDenials[DeniedCharges])))+1
A9: B5 | B9: Compare this Pareto with the one you built by claim count in Task 10. Exactly one reason ranks higher by denied charges than by number of claims. Which one? Type it as it appears in the table. | C9: Missing Documentation | D9: Read the bar order in both charts. By claims, Missing Documentation is number 5, and by denied charges it's number 4, so it swaps places with Eligibility / Coverage. | E9: {=INDEX(tblDenials[DenialReason],MATCH(1,--(COUNTIF(tblDenials[DeniedCharges],">"&tblDenials[DeniedCharges])<COUNTIF(tblDenials[Claims],">"&tblDenials[Claims])),0))} | F9: Missing Documentation denials are fewer (97 claims against 125 for Eligibility / Coverage) but larger: about $14,026 per claim against $10,083. That's why the director asked for dollars. A count Pareto ranks the work queue by volume, and a dollar Pareto ranks it by money at risk. Put the two charts side by side, at the same size, so the committee sees the swap at a glance. Cross-check (COUNTIF(range,">"&range) gives each reason's rank minus 1, so MATCH finds the reason whose dollar rank beats its claim rank. In Excel 2019 or earlier, confirm it with Ctrl + Shift + Enter): =INDEX(tblDenials[DenialReason],MATCH(1,--(COUNTIF(tblDenials[DeniedCharges],">"&tblDenials[DeniedCharges])<COUNTIF(tblDenials[Claims],">"&tblDenials[Claims])),0))

Sheet Chart Key
A1: 🔑 Chart Key — Lesson 3.5
A2: Reference versions of every chart in the lesson. Helper tables on the left feed the charts that need sorted or pre-binned data. Your colors, sizes, and fonts can differ, so compare the shapes and the numbers.
A4: Task 1 · Column chart: 2025 ED arrivals by hour of day
A5: Data
A6: ED_Hourly!A1:B25
A24: Tasks 2 & 13 · Line chart: monthly ED visits by hospital (title linked to Task 13's cell)
A25: Data | B25: Title text
A26: ED_Monthly!A1:D25 | B26: ED visits by facility, Jan 2024 to Dec 2025 (12,292 visits)
A44: Task 3 · Bar chart: readmission rate by service line (sorted, categories reversed)
A45: ServiceLine | B45: ReadmitRate
A46: Cardiovascular | B46: 0.18361582
A47: Critical Care | B47: 0.17934783
A48: Medicine | B48: 0.16133163
A49: Neuroscience | B49: 0.15441176
A50: Behavioral Health | B50: 0.11382114
A51: Oncology | B51: 0.094117647
A52: Orthopedics | B52: 0.093959732
A53: Women & Children | B53: 0.063909774
A64: Task 4 · Makeover fixed: axis from 0%, one color, labels instead of a legend
A65: ServiceLine | B65: ReadmitRate
A66: Cardiovascular | B66: 0.18361582
A67: Critical Care | B67: 0.17934783
A68: Medicine | B68: 0.16133163
A69: Neuroscience | B69: 0.15441176
A70: Behavioral Health | B70: 0.11382114
A71: Oncology | B71: 0.094117647
A72: Orthopedics | B72: 0.093959732
A73: Women & Children | B73: 0.063909774
A84: Task 5 · Pie chart: 2025 encounters by payer type (Percentage labels, 1 decimal)
A85: Data
A86: PayerMix!A1:B6
A104: Task 6 · Histogram of LOSDays: bin width 1, underflow 1, overflow 10 (classic column version)
A105: Bin (days) | B105: Stays
A106: ≤1 | B106: 1
A107: (1, 2] | B107: 27
A108: (2, 3] | B108: 57
A109: (3, 4] | B109: 75
A110: (4, 5] | B110: 47
A111: (5, 6] | B111: 29
A112: (6, 7] | B112: 26
...
