Workbook

Sheet Start Here
B2: Lesson 4.1
B3: Dynamic Arrays: FILTER, SORT, UNIQUE & More
B4: Advanced · about 60 minutes · Bluestone Health System (fictional)
B6: What you'll learn
B7: • | C7: Understand spilling, the # spill reference, and #SPILL! errors
B8: • | C8: Extract lists with UNIQUE, FILTER, SORT, and SORTBY
B9: • | C9: Generate sequences with SEQUENCE and reshape with TAKE, DROP, CHOOSECOLS, VSTACK, and HSTACK
B10: • | C10: Combine functions into one-formula reports
B12: How to use this workbook
B13: 1. Read the guide | C13: The lesson guide (README) explains each skill with examples: https://github.com/lmansf/learn-excel/tree/main/04-advanced-analysis/01-dynamic-arrays
B14: 2. Practice | C14: Go to the 'Practice' sheet. Type a formula or value into each yellow cell.
B15: 3. Check yourself | C15: The Check column shows ✔ Correct (green) or ✘ Not yet (red). Tasks marked 'See key' are checked by comparing with the answer key.
B16: 4. Bonus | C16: Finished? Try the harder 'Bonus' sheet.
B17: 5. Answers | C17: The 'Answer Key' and 'Bonus Key' sheets are hidden. Right-click any sheet tab → Unhide… → pick one → OK. (Try first!)
B18: Note | C18: Spill formulas go on the Workspace sheet. Type each one in its yellow anchor cell and leave the cells below and to the right empty so the results have room to spill.
B19: Note | C19: Needs Microsoft 365 or Excel 2024 (VSTACK, HSTACK, TAKE, DROP, CHOOSECOLS). FILTER, SORT, SORTBY, UNIQUE, SEQUENCE, and XLOOKUP also work in Excel 2021.
B21: Color legend
B22: Yellow cell | C22: Your answer goes here.
B23: Gray cell | C23: Pre-filled summary formula — it reads the work you did on another sheet.
B24: ✔ Correct | C24: Your answer matches the key.
B25: ✘ Not yet | C25: Not matching yet — check the hint and try again.
B27: Sheets in this workbook
B28: Practice | C28: 13 tasks. Each yellow answer cell needs a formula that returns ONE value. Gray cells read the spills you build on the Workspace sheet (tasks 1, 2, 12, and 13).
B29: Workspace | C29: Yellow anchor cells for the spill tasks (1, 2, 12, and 13) and the bonus leaderboard, plus a gray Guide examples area (columns S–W) for trying the guide's formulas.
B30: Encounters | C30: Data: 2,000 rows in the Excel Table 'tblEncounters' (16 columns).
B31: Providers | C31: Data: 147 rows in the Excel Table 'tblProviders'.
B32: Departments | C32: Data: 31 rows in the Excel Table 'tblDepartments'.
B33: Bonus | C33: 4 harder questions about a one-formula unit leaderboard that you build in Workspace!N6.
B34: About the data | C34: 2,000 encounters sampled from Bluestone Health System's 2025 activity at all four facilities, with facility, department, attending, diagnosis category, and payer names already joined in. Also includes the provider roster (147) and the department list (31, with StaffedBeds 0 for departments that have no inpatient beds).
B35: Disclaimer | C35: All people, places, and numbers are synthetic and fictional. Not clinical guidance.

Sheet Practice
A1: Lesson 4.1 · Practice
A2: Tasks 1, 2, 12, and 13 are spill exercises: build them in the yellow anchor cells on the Workspace sheet, and the gray cells here read your results. Every other answer cell needs a formula that returns ONE value, so wrap spilling functions in ROWS, SUM, AVERAGE, INDEX, or TAKE(…,1). Refer to the data with structured references such as tblEncounters[TotalCharges].
A3: Type a formula or value in each yellow cell. The Check column turns green when your answer matches. Stuck? Read the hint, then the lesson guide. Answers: right-click a sheet tab → Unhide… → 'Answer Key'.
A4: ="Score: "&COUNTIF(E6:E18,"✔*")&" of 13 auto-checked tasks correct"
A5: # | B5: Task | C5: Hint | D5: Your Answer | E5: Check
A6: 1 | B6: Go to the Workspace sheet. In the yellow cell B6, enter one formula that spills the list of distinct payer names from the Payer column of tblEncounters. The gray cell counts the names in your list. | C6: UNIQUE of one Table column | D6: {=IF(ISBLANK(Workspace!B6),"",IF(ISERROR(Workspace!B6),"Workspace!B6 shows an error. Fix it there.",COUNTA(Workspace!B6:B60)))} | E6: =IF(IFERROR(D6="",FALSE),"",IF(IFERROR(AND(ISNUMBER(D6),OR(ABS(D6-'Answer Key'!$C$5)<=0.0001)),FALSE),"✔ Correct","✘ Not yet"))
A7: 2 | B7: In Workspace!D6, enter one formula that spills the distinct ServiceLine values from tblEncounters sorted A to Z. When you press Enter, D6 shows #SPILL!. Find out why and fix the problem without moving your formula. The gray cell then summarizes your list. | C7: SORT(UNIQUE(…)). Then click the warning icon next to the error | D7: {=IF(ISBLANK(Workspace!D6),"",IFERROR(COUNTA(Workspace!D6:D60)&" service lines · first: "&Workspace!D6&" · last: "&INDEX(Workspace!D6:D60,COUNTA(Workspace!D6:D60)),"Workspace!D6 shows an error. Fix it there."))} | E7: =IF(IFERROR(D7="",FALSE),"",IF(IFERROR(OR(LOWER(TRIM(D7&""))=LOWER(TRIM('Answer Key'!$C$6&""))),FALSE),"✔ Correct","✘ Not yet"))
A8: 3 | B8: Department names repeat across hospitals (each hospital has its own 'Emergency Department'). How many distinct Facility + Department combinations (units) appear in tblEncounters? | C8: UNIQUE over two adjacent columns, then count the rows | E8: =IF(IFERROR(D8="",FALSE),"",IF(IFERROR(AND(ISNUMBER(D8),OR(ABS(D8-'Answer Key'!$C$7)<=0.0001)),FALSE),"✔ Correct","✘ Not yet"))
A9: 4 | B9: How many patients (PatientID) have exactly one encounter in this extract? | C9: UNIQUE has an optional third argument | E9: =IF(IFERROR(D9="",FALSE),"",IF(IFERROR(AND(ISNUMBER(D9),OR(ABS(D9-'Answer Key'!$C$8)<=0.0001)),FALSE),"✔ Correct","✘ Not yet"))
A10: 5 | B10: This one uses tblDepartments (on the Departments sheet), but the formula still goes in the yellow cell here. Using FILTER, how many departments have UnitType "Inpatient" and 20 or more StaffedBeds? | C10: Multiply the two conditions with *, then count the rows FILTER returns | E10: =IF(IFERROR(D10="",FALSE),"",IF(IFERROR(AND(ISNUMBER(D10),OR(ABS(D10-'Answer Key'!$C$9)<=0.0001)),FALSE),"✔ Correct","✘ Not yet"))
A11: 6 | B11: How many different attending providers (Attending) treated Emergency encounters? | C11: FILTER first, then UNIQUE, then count | E11: =IF(IFERROR(D11="",FALSE),"",IF(IFERROR(AND(ISNUMBER(D11),OR(ABS(D11-'Answer Key'!$C$10)<=0.0001)),FALSE),"✔ Correct","✘ Not yet"))
A12: 7 | B12: Flu-season review: what were the total charges of Emergency encounters admitted in January or February 2025 whose DxCategory is Respiratory or Infectious? Enter dollars and cents. | C12: AND with *, OR with +. Wrap the OR part in its own parentheses | E12: =IF(IFERROR(D12="",FALSE),"",IF(IFERROR(AND(ISNUMBER(D12),OR(ABS(D12-'Answer Key'!$C$11)<=0.0051)),FALSE),"✔ Correct","✘ Not yet"))
A13: 8 | B13: What is the combined TotalCharges of the five most expensive Emergency encounters? Enter dollars and cents. | C13: SORT the ED charges largest first, TAKE the first 5, then add them | E13: =IF(IFERROR(D13="",FALSE),"",IF(IFERROR(AND(ISNUMBER(D13),OR(ABS(D13-'Answer Key'!$C$12)<=0.0051)),FALSE),"✔ Correct","✘ Not yet"))
A14: 9 | B14: Outliers distort averages. What is the average TotalCharges of Inpatient encounters after dropping the 10 most expensive stays? Enter dollars and cents. | C14: Sort largest first, then DROP the first 10 rows | E14: =IF(IFERROR(D14="",FALSE),"",IF(IFERROR(AND(ISNUMBER(D14),OR(ABS(D14-'Answer Key'!$C$13)<=0.0051)),FALSE),"✔ Correct","✘ Not yet"))
A15: 10 | B15: Which attending provider's encounters add up to the highest TotalCharges? Enter the name exactly as it appears (Last, First). | C15: SORTBY the UNIQUE names by a SUMIFS that uses those same names as its criteria | E15: =IF(IFERROR(D15="",FALSE),"",IF(IFERROR(OR(LOWER(TRIM(D15&""))=LOWER(TRIM('Answer Key'!$C$14&""))),FALSE),"✔ Correct","✘ Not yet"))
A16: 11 | B16: Look up the specialty of the attending on every Inpatient encounter (tblProviders has a Specialty for each Provider name). How many distinct specialties appear? | C16: XLOOKUP accepts a whole array of lookup values | E16: =IF(IFERROR(D16="",FALSE),"",IF(IFERROR(AND(ISNUMBER(D16),OR(ABS(D16-'Answer Key'!$C$15)<=0.0001)),FALSE),"✔ Correct","✘ Not yet"))
A17: 12 | B17: On the Workspace sheet, make F6 spill the first day of each month of 2025 (01/01/2025 through 12/01/2025) using SEQUENCE. Column F is formatted to show them as Jan 2025, Feb 2025, and so on. Then, in G6, write ONE COUNTIFS formula that refers to your month list with the spill operator (F6#) and spills the number of encounters admitted in each month. The gray cell checks both columns. | C17: DATE accepts an array of months. Count AdmitDate ≥ each month start and < the next month's start | D17: {=IF(ISBLANK(Workspace!F6),"",IF(OR(ISERROR(Workspace!F6),ISERROR(Workspace!G6)),"Workspace!F6 or G6 shows an error. Fix it there.",COUNT(Workspace!F6:F60)&" months · "&SUM(Workspace!G6:G60)&" encounters"))} | E17: =IF(IFERROR(D17="",FALSE),"",IF(IFERROR(OR(LOWER(TRIM(D17&""))=LOWER(TRIM('Answer Key'!$C$16&""))),FALSE),"✔ Correct","✘ Not yet"))
A18: 13 | B18: Build a long-stay worklist in Workspace!I6 with ONE formula: a header row (EncounterID, Department, LOSDays, TotalCharges) on top of every Cedar Ridge Medical Center encounter with LOSDays of 7 or more, showing only those four columns, sorted by LOSDays from longest to shortest. | C18: VSTACK(header, SORT(CHOOSECOLS(FILTER(tblEncounters, …), …), …)) | D18: {=IF(ISBLANK(Workspace!I6),"",IF(ISERROR(Workspace!I6),"Workspace!I6 shows an error. Fix it there.",(COUNTA(Workspace!I6:I60)-1)&" stays · longest: "&Workspace!I7&" ("&Workspace!K7&" d) · shortest: "&INDEX(Workspace!I6:I60,COUNTA(Workspace!I6:I60))&" ("&INDEX(Workspace!K6:K60,COUNTA(Workspace!I6:I60))&" d)"))} | E18: =IF(IFERROR(D18="",FALSE),"",IF(IFERROR(OR(LOWER(TRIM(D18&""))=LOWER(TRIM('Answer Key'!$C$17&""))),FALSE),"✔ Correct","✘ Not yet"))

Sheet Workspace
A1: Workspace: spill your dynamic-array formulas here
A2: Type each formula in its yellow anchor cell and press Enter. Leave the cells below and to the right empty so the results can spill. The gray cells on the Practice sheet read these results. Columns S–W are a scratch area for trying the guide's examples.
B4: Task 1 · UNIQUE | D4: Task 2 · SORT + UNIQUE | F4: Task 12 · SEQUENCE | I4: Task 13 · Long-stay worklist | N4: Bonus · Unit leaderboard | S4: Guide examples (not graded)
B5: Distinct payers ↓ | D5: Service lines, A→Z ↓ | F5: Month starts ↓ | G5: Encounters ↓ | I5: Header row, then data ↓ (4 columns) | N5: Header row, then data ↓ (4 columns) | S5: Try the lesson guide's formulas here ↓ (S6, U6, W6)
D11: draft

Sheet Encounters
A1: EncounterID | B1: PatientID | C1: AdmitDate | D1: DischargeDate | E1: LOSDays | F1: EncounterType | G1: Facility | H1: Department | I1: ServiceLine | J1: Attending | K1: DxCode | L1: DxCategory | M1: Payer | N1: PayerType | O1: TotalCharges | P1: Readmit30
A2: ENC110714 | B2: PT10258 | C2: 45658 | D2: 45662 | E2: 4 | F2: Inpatient | G2: Bluestone Memorial Hospital | H2: Medical-Surgical 5 East | I2: Medicine | J2: Simpson, Kelly | K2: J44.1 | L2: Respiratory | M2: Silverline Medicare Advantage | N2: Medicare Advantage | O2: 23167.91 | P2: N
A3: ENC110718 | B3: PT11455 | C3: 45658 | D3: 45658 | E3: 0 | F3: Emergency | G3: Bluestone Memorial Hospital | H3: Emergency Department | I3: Emergency | J3: Olson, Christian | K3: J44.1 | L3: Respiratory | M3: Silverline Medicare Advantage | N3: Medicare Advantage | O3: 2579.55
A4: ENC110733 | B4: PT13219 | C4: 45658 | D4: 45658 | E4: 0 | F4: Outpatient | G4: Bluestone Outpatient Pavilion | H4: Primary Care Clinic | I4: Ambulatory | J4: Santos, Edward | K4: I10 | L4: Circulatory | M4: Silverline Medicare Advantage | N4: Medicare Advantage | O4: 191.04
A5: ENC110740 | B5: PT10753 | C5: 45658 | D5: 45658 | E5: 0 | F5: Outpatient | G5: Bluestone Outpatient Pavilion | H5: Primary Care Clinic | I5: Ambulatory | J5: Chen, Mei | K5: M54.50 | L5: Musculoskeletal | M5: Keystone Health Partners | N5: Commercial | O5: 157.43
A6: ENC110744 | B6: PT10444 | C6: 45658 | D6: 45660 | E6: 2 | F6: Inpatient | G6: Bluestone Memorial Hospital | H6: Medical-Surgical 5 East | I6: Medicine | J6: Kim, Jeffrey | K6: K35.80 | L6: Digestive | M6: Medicare | N6: Government | O6: 48442.42 | P6: N
A7: ENC110762 | B7: PT10906 | C7: 45659 | D7: 45659 | E7: 0 | F7: Outpatient | G7: Bluestone Outpatient Pavilion | H7: Endocrinology & Diabetes Clinic | I7: Ambulatory | J7: Woods, Larry | K7: E11.65 | L7: Endocrine | M7: Keystone Health Partners | N7: Commercial | O7: 420.49
A8: ENC110763 | B8: PT12818 | C8: 45659 | D8: 45659 | E8: 0 | F8: Outpatient | G8: Bluestone Outpatient Pavilion | H8: Primary Care Clinic | I8: Ambulatory | J8: Arnold, Catherine | K8: E78.5 | L8: Endocrine | M8: Silverline Medicare Advantage | N8: Medicare Advantage | O8: 466.73
A9: ENC110769 | B9: PT12522 | C9: 45659 | D9: 45659 | E9: 0 | F9: Emergency | G9: Ashby Falls Community Hospital | H9: Emergency Department | I9: Emergency | J9: Richardson, Mei | K9: J45.909 | L9: Respiratory | M9: Self-Pay | N9: Self-Pay | O9: 1127.43
A10: ENC110776 | B10: PT12169 | C10: 45659 | D10: 45659 | E10: 0 | F10: Outpatient | G10: Bluestone Outpatient Pavilion | H10: Primary Care Clinic | I10: Ambulatory | J10: Nguyen, Isabella | K10: J06.9 | L10: Respiratory | M10: Evergreen Mutual Insurance | N10: Commercial | O10: 304.68
A11: ENC110786 | B11: PT10725 | C11: 45659 | D11: 45659 | E11: 0 | F11: Outpatient | G11: Bluestone Outpatient Pavilion | H11: Pediatric Clinic | I11: Women & Children | J11: Brown, Stephanie | K11: Z23 | L11: Factors Influencing Health | M11: State Medicaid | N11: Government | O11: 105.41
A12: ENC110790 | B12: PT10695 | C12: 45659 | D12: 45659 | E12: 0 | F12: Emergency | G12: Cedar Ridge Medical Center | H12: Emergency Department | I12: Emergency | J12: Warren, Victoria | K12: A08.4 | L12: Infectious | M12: State Medicaid | N12: Government | O12: 1281.12
A13: ENC110791 | B13: PT10220 | C13: 45659 | D13: 45661 | E13: 2 | F13: Inpatient | G13: Bluestone Memorial Hospital | H13: Cardiac Step-Down | I13: Cardiovascular | J13: Taylor, Jonathan | K13: I48.91 | L13: Circulatory | M13: Self-Pay | N13: Self-Pay | O13: 13130.81 | P13: N
A14: ENC110809 | B14: PT12897 | C14: 45660 | D14: 45660 | E14: 0 | F14: Emergency | G14: Bluestone Memorial Hospital | H14: Emergency Department | I14: Emergency | J14: Payne, Nancy | K14: J06.9 | L14: Respiratory | M14: Medicare | N14: Government | O14: 626.62
A15: ENC110812 | B15: PT13751 | C15: 45660 | D15: 45660 | E15: 0 | F15: Outpatient | G15: Bluestone Outpatient Pavilion | H15: Primary Care Clinic | I15: Ambulatory | J15: Black, Kelly | K15: J06.9 | L15: Respiratory | M15: Silverline Medicare Advantage | N15: Medicare Advantage | O15: 354.41
A16: ENC110802 | B16: PT11756 | C16: 45660 | D16: 45665 | E16: 5 | F16: Inpatient | G16: Bluestone Memorial Hospital | H16: Neuroscience & Stroke | I16: Neuroscience | J16: Stone, Frank | K16: I63.9 | L16: Circulatory | M16: Keystone Health Partners | N16: Commercial | O16: 29599.26 | P16: N
A17: ENC110824 | B17: PT12546 | C17: 45660 | D17: 45660 | E17: 0 | F17: Emergency | G17: Bluestone Memorial Hospital | H17: Emergency Department | I17: Emergency | J17: Ferguson, Roy | K17: A08.4 | L17: Infectious | M17: Keystone Health Partners | N17: Commercial | O17: 1382.13
A18: ENC110834 | B18: PT11715 | C18: 45660 | D18: 45661 | E18: 1 | F18: Emergency | G18: Bluestone Memorial Hospital | H18: Emergency Department | I18: Emergency | J18: Ferguson, Roy | K18: G40.909 | L18: Nervous System | M18: Keystone Health Partners | N18: Commercial | O18: 2932.16
A19: ENC110836 | B19: PT10362 | C19: 45660 | D19: 45660 | E19: 0 | F19: Emergency | G19: Bluestone Memorial Hospital | H19: Emergency Department | I19: Emergency | J19: Mendoza, Alexander | K19: M54.50 | L19: Musculoskeletal | M19: State Medicaid | N19: Government | O19: 1152
A20: ENC110833 | B20: PT12745 | C20: 45660 | D20: 45665 | E20: 5 | F20: Inpatient | G20: Bluestone Memorial Hospital | H20: Medical-Surgical 4 West | I20: Medicine | J20: Cox, Judith | K20: J96.01 | L20: Respiratory | M20: Medicare | N20: Government | O20: 48858.56 | P20: N
A21: ENC110848 | B21: PT12991 | C21: 45661 | D21: 45668 | E21: 7 | F21: Inpatient | G21: Bluestone Memorial Hospital | H21: Intensive Care Unit | I21: Critical Care | J21: Allen, Grace | K21: A41.9 | L21: Infectious | M21: Medicare | N21: Government | O21: 67153.41 | P21: N
A22: ENC110849 | B22: PT11023 | C22: 45661 | D22: 45662 | E22: 1 | F22: Observation | G22: Ashby Falls Community Hospital | H22: Medical-Surgical | I22: Medicine | J22: Carroll, Philip | K22: J44.1 | L22: Respiratory | M22: Medicare | N22: Government | O22: 4865.67
A23: ENC110859 | B23: PT11553 | C23: 45662 | D23: 45662 | E23: 0 | F23: Emergency | G23: Bluestone Memorial Hospital | H23: Emergency Department | I23: Emergency | J23: Foster, Patrick | K23: A08.4 | L23: Infectious | M23: Evergreen Mutual Insurance | N23: Commercial | O23: 2845.54
A24: ENC110860 | B24: PT11095 | C24: 45662 | D24: 45662 | E24: 0 | F24: Emergency | G24: Bluestone Memorial Hospital | H24: Emergency Department | I24: Emergency | J24: Elliott, Jesse | K24: J44.1 | L24: Respiratory | M24: Summit Choice PPO | N24: Commercial | O24: 2419.78
A25: ENC110865 | B25: PT13499 | C25: 45662 | D25: 45667 | E25: 5 | F25: Inpatient | G25: Ashby Falls Community Hospital | H25: Medical-Surgical | I25: Medicine | J25: Murray, Stephanie | K25: I50.9 | L25: Circulatory | M25: Medicare | N25: Government | O25: 38855.89 | P25: N
A26: ENC110871 | B26: PT13276 | C26: 45662 | D26: 45662 | E26: 0 | F26: Emergency | G26: Bluestone Memorial Hospital | H26: Emergency Department | I26: Emergency | J26: Mendoza, Alexander | K26: J21.9 | L26: Respiratory | M26: Keystone Health Partners | N26: Commercial | O26: 5712.21
A27: ENC110875 | B27: PT10538 | C27: 45662 | D27: 45663 | E27: 1 | F27: Emergency | G27: Bluestone Memorial Hospital | H27: Emergency Department | I27: Emergency | J27: Ferguson, Roy | K27: J45.909 | L27: Respiratory | M27: Evergreen Mutual Insurance | N27: Commercial | O27: 1629.66
A28: ENC110891 | B28: PT11812 | C28: 45663 | D28: 45668 | E28: 5 | F28: Inpatient | G28: Bluestone Memorial Hospital | H28: Oncology | I28: Oncology | J28: Gray, Fatima | K28: C34.90 | L28: Neoplasms | M28: Silverline Medicare Advantage | N28: Medicare Advantage | O28: 23337.44 | P28: N
A29: ENC110907 | B29: PT13678 | C29: 45663 | D29: 45663 | E29: 0 | F29: Outpatient | G29: Bluestone Outpatient Pavilion | H29: Primary Care Clinic | I29: Ambulatory | J29: Torres, Rebecca | K29: I10 | L29: Circulatory | M29: Silverline Medicare Advantage | N29: Medicare Advantage | O29: 440.68
A30: ENC110912 | B30: PT12444 | C30: 45663 | D30: 45663 | E30: 0 | F30: Emergency | G30: Bluestone Memorial Hospital | H30: Emergency Department | I30: Emergency | J30: Morris, Jordan | K30: R07.9 | L30: Symptoms & Signs | M30: Keystone Health Partners | N30: Commercial | O30: 2542.05
A31: ENC110913 | B31: PT13044 | C31: 45663 | D31: 45663 | E31: 0 | F31: Emergency | G31: Bluestone Memorial Hospital | H31: Emergency Department | I31: Emergency | J31: Cruz, Mia | K31: J06.9 | L31: Respiratory | M31: State Medicaid | N31: Government | O31: 1570.3
A32: ENC110930 | B32: PT13132 | C32: 45664 | D32: 45664 | E32: 0 | F32: Outpatient | G32: Bluestone Outpatient Pavilion | H32: Endocrinology & Diabetes Clinic | I32: Ambulatory | J32: Woods, Larry | K32: E11.65 | L32: Endocrine | M32: Keystone Health Partners | N32: Commercial | O32: 353.05
A33: ENC110931 | B33: PT11689 | C33: 45664 | D33: 45664 | E33: 0 | F33: Outpatient | G33: Bluestone Outpatient Pavilion | H33: Primary Care Clinic | I33: Ambulatory | J33: Santos, Edward | K33: J06.9 | L33: Respiratory | M33: Medicare | N33: Government | O33: 160.68
A34: ENC110934 | B34: PT12854 | C34: 45664 | D34: 45664 | E34: 0 | F34: Outpatient | G34: Bluestone Outpatient Pavilion | H34: Infusion & Oncology Clinic | I34: Oncology | J34: Robinson, Bradley | K34: Z51.11 | L34: Factors Influencing Health | M34: Silverline Medicare Advantage | N34: Medicare Advantage | O34: 5105.42
A35: ENC110939 | B35: PT13437 | C35: 45664 | D35: 45664 | E35: 0 | F35: Emergency | G35: Bluestone Memorial Hospital | H35: Emergency Department | I35: Emergency | J35: Olson, Christian | K35: J45.909 | L35: Respiratory | M35: Evergreen Mutual Insurance | N35: Commercial | O35: 599.01
A36: ENC110946 | B36: PT13320 | C36: 45664 | D36: 45664 | E36: 0 | F36: Outpatient | G36: Bluestone Outpatient Pavilion | H36: Primary Care Clinic | I36: Ambulatory | J36: Black, Nancy | K36: E78.5 | L36: Endocrine | M36: Silverline Medicare Advantage | N36: Medicare Advantage | O36: 232.12
A37: ENC110949 | B37: PT11320 | C37: 45664 | D37: 45664 | E37: 0 | F37: Outpatient | G37: Bluestone Outpatient Pavilion | H37: Infusion & Oncology Clinic | I37: Oncology | J37: Cooper, Logan | K37: Z51.11 | L37: Factors Influencing Health | M37: Medicare | N37: Government | O37: 11341.4
A38: ENC110953 | B38: PT10534 | C38: 45664 | D38: 45668 | E38: 4 | F38: Inpatient | G38: Ashby Falls Community Hospital | H38: Medical-Surgical | I38: Medicine | J38: Murray, Stephanie | K38: L03.115 | L38: Skin | M38: Evergreen Mutual Insurance | N38: Commercial | O38: 16335.56 | P38: N
A39: ENC110956 | B39: PT13707 | C39: 45664 | D39: 45664 | E39: 0 | F39: Emergency | G39: Bluestone Memorial Hospital | H39: Emergency Department | I39: Emergency | J39: Sullivan, Jacob | K39: J45.909 | L39: Respiratory | M39: State Medicaid | N39: Government | O39: 8267.81
A40: ENC110961 | B40: PT11125 | C40: 45664 | D40: 45664 | E40: 0 | F40: Emergency | G40: Bluestone Memorial Hospital | H40: Emergency Department | I40: Emergency | J40: Mendoza, Alexander | K40: J06.9 | L40: Respiratory | M40: Silverline Medicare Advantage | N40: Medicare Advantage | O40: 1141.91
...

Sheet Providers
A1: ProviderID | B1: Provider | C1: Credential | D1: Specialty | E1: Facility | F1: Department | G1: HireDate | H1: FTE
A2: PRV1001 | B2: Ferguson, Roy | C2: MD | D2: Emergency Medicine | E2: Bluestone Memorial Hospital | F2: Emergency Department | G2: 40803 | H2: 1
A3: PRV1002 | B3: Cruz, Mia | C3: MD | D3: Emergency Medicine | E3: Bluestone Memorial Hospital | F3: Emergency Department | G3: 39297 | H3: 0.9
A4: PRV1003 | B4: Morris, Jordan | C4: MD | D4: Emergency Medicine | E4: Bluestone Memorial Hospital | F4: Emergency Department | G4: 38529 | H4: 1
A5: PRV1004 | B5: Elliott, Jesse | C5: MD | D5: Emergency Medicine | E5: Bluestone Memorial Hospital | F5: Emergency Department | G5: 41165 | H5: 1
A6: PRV1005 | B6: Olson, Christian | C6: DO | D6: Emergency Medicine | E6: Bluestone Memorial Hospital | F6: Emergency Department | G6: 39554 | H6: 1
A7: PRV1006 | B7: Kowalski, James | C7: MD | D7: Emergency Medicine | E7: Bluestone Memorial Hospital | F7: Emergency Department | G7: 37283 | H7: 1
A8: PRV1007 | B8: Mendoza, Alexander | C8: MD | D8: Emergency Medicine | E8: Bluestone Memorial Hospital | F8: Emergency Department | G8: 44233 | H8: 1
A9: PRV1008 | B9: Sullivan, Jacob | C9: DO | D9: Emergency Medicine | E9: Bluestone Memorial Hospital | F9: Emergency Department | G9: 36898 | H9: 0.9
A10: PRV1009 | B10: Foster, Patrick | C10: DO | D10: Emergency Medicine | E10: Bluestone Memorial Hospital | F10: Emergency Department | G10: 39506 | H10: 1
A11: PRV1010 | B11: Payne, Nancy | C11: MD | D11: Emergency Medicine | E11: Bluestone Memorial Hospital | F11: Emergency Department | G11: 43123 | H11: 1
A12: PRV1011 | B12: Gonzales, Mia | C12: PA | D12: Emergency Medicine | E12: Bluestone Memorial Hospital | F12: Emergency Department | G12: 40177 | H12: 1
A13: PRV1012 | B13: Vasquez, Bruce | C13: NP | D13: Emergency Medicine | E13: Bluestone Memorial Hospital | F13: Emergency Department | G13: 45137 | H13: 0.5
... A148: PRV1147 | B148: Wagner, Natalie | C148: MD | D148: Pathology | E148: Bluestone Memorial Hospital | F148: Laboratory | G148: 40655 | H148: 1

Sheet Departments
A1: DeptID | B1: Department | C1: Facility | D1: ServiceLine | E1: UnitType | F1: StaffedBeds
A2: D100 | B2: Emergency Department | C2: Bluestone Memorial Hospital | D2: Emergency | E2: Emergency | F2: 0
A3: D110 | B3: Medical-Surgical 4 West | C3: Bluestone Memorial Hospital | D3: Medicine | E3: Inpatient | F3: 36
A4: D111 | B4: Medical-Surgical 5 East | C4: Bluestone Memorial Hospital | D4: Medicine | E4: Inpatient | F4: 32
A5: D120 | B5: Cardiac Step-Down | C5: Bluestone Memorial Hospital | D5: Cardiovascular | E5: Inpatient | F5: 24
A6: D130 | B6: Intensive Care Unit | C6: Bluestone Memorial Hospital | D6: Critical Care | E6: Critical Care | F6: 20
A7: D140 | B7: Orthopedics & Spine | C7: Bluestone Memorial Hospital | D7: Orthopedics | E7: Inpatient | F7: 22
A8: D150 | B8: Oncology | C8: Bluestone Memorial Hospital | D8: Oncology | E8: Inpatient | F8: 18
A9: D160 | B9: Neuroscience & Stroke | C9: Bluestone Memorial Hospital | D9: Neuroscience | E9: Inpatient | F9: 16
A10: D170 | B10: Labor & Delivery | C10: Bluestone Memorial Hospital | D10: Women & Children | E10: Inpatient | F10: 20
A11: D180 | B11: Pediatrics | C11: Bluestone Memorial Hospital | D11: Women & Children | E11: Inpatient | F11: 14
A12: D190 | B12: Behavioral Health | C12: Bluestone Memorial Hospital | D12: Behavioral Health | E12: Inpatient | F12: 18
A13: D195 | B13: Observation Unit | C13: Bluestone Memorial Hospital | D13: Medicine | E13: Observation | F13: 12
... A32: D520 | B32: Pharmacy | C32: Bluestone Memorial Hospital | D32: Ancillary | E32: Ancillary | F32: 0

Sheet Bonus
A1: Lesson 4.1 · Bonus: A one-formula unit leaderboard
A2: The CFO wants a 'unit leaderboard' she can refresh every month: every unit (Facility + Department) with at least 50 encounters in the extract, with four columns (Facility, Department, Encounters, AvgCharge), where Encounters is the unit's number of encounters and AvgCharge is the average TotalCharges of those encounters. Sort it by AvgCharge from highest to lowest and put a header row on top. Build it in Workspace!N6 as ONE formula. Section 12 of the lesson guide shows how to lift COUNTIFS and AVERAGEIFS over a two-column list, and LET (previewed there) keeps the formula readable. Then answer the questions below with formulas that refer to your leaderboard through N6#.
A3: Type a formula or value in each yellow cell. The Check column turns green when your answer matches. Stuck? Read the hint, then the lesson guide. Answers: right-click a sheet tab → Unhide… → 'Bonus Key'.
A4: ="Score: "&COUNTIF(E6:E9,"✔*")&" of 4 auto-checked tasks correct"
A5: # | B5: Task | C5: Hint | D5: Your Answer | E5: Check
A6: B1 | B6: How many units qualify for the leaderboard? Count data rows only, not the header. | C6: ROWS of the spill, minus the header row | E6: =IF(IFERROR(D6="",FALSE),"",IF(IFERROR(AND(ISNUMBER(D6),OR(ABS(D6-'Bonus Key'!$C$5)<=0.0001)),FALSE),"✔ Correct","✘ Not yet"))
A7: B2 | B7: Which Department tops the leaderboard? | C7: Row 2 of the spill is the first data row | E7: =IF(IFERROR(D7="",FALSE),"",IF(IFERROR(OR(LOWER(TRIM(D7&""))=LOWER(TRIM('Bonus Key'!$C$6&""))),FALSE),"✔ Correct","✘ Not yet"))
A8: B3 | B8: What is the top unit's average charge? Enter dollars and cents. | C8: Same row, fourth column | E8: =IF(IFERROR(D8="",FALSE),"",IF(IFERROR(AND(ISNUMBER(D8),OR(ABS(D8-'Bonus Key'!$C$7)<=0.0051)),FALSE),"✔ Correct","✘ Not yet"))
A9: B4 | B9: What share of all TotalCharges in tblEncounters comes from the units on the leaderboard? Each unit's total is Encounters × AvgCharge. Enter it as a percentage. | C9: DROP the header row, multiply column 3 by column 4, add up, then divide by all charges | E9: =IF(IFERROR(D9="",FALSE),"",IF(IFERROR(AND(ISNUMBER(D9),OR(ABS(D9-'Bonus Key'!$C$8)<=0.00051,ABS(D9-'Bonus Key'!$C$8*100)<=0.051000000000000004)),FALSE),"✔ Correct","✘ Not yet"))

Sheet Answer Key
A1: 🔑 Answer Key — Lesson 4.1
A2: Spoiler alert — try every task before reading this sheet. Column C is the value the Check column compares against. Column D is a sample solution; column E is that same formula, live, proving it works.
A4: # | B4: Task | C4: Answer | D4: Sample solution | E4: Live result | F4: Explanation
A5: 1 | B5: Go to the Workspace sheet. In the yellow cell B6, enter one formula that spills the list of distinct payer names from the Payer column of tblEncounters. The gray cell counts the names in your list. | C5: 8 | D5: =UNIQUE(tblEncounters[Payer]) | E5: {=ROWS(_xlfn.UNIQUE(tblEncounters[Payer]))} | F5: UNIQUE returns each payer once, in the order it first appears in the table. Only B6 holds the formula, and the other names spill into B7, B8, and so on. Click one of them and the formula bar shows the formula grayed out, and a blue border outlines the whole spill range.
A6: 2 | B6: In Workspace!D6, enter one formula that spills the distinct ServiceLine values from tblEncounters sorted A to Z. When you press Enter, D6 shows #SPILL!. Find out why and fix the problem without moving your formula. The gray cell then summarizes your list. | C6: 10 service lines · first: Ambulatory · last: Women & Children | D6: =SORT(UNIQUE(tblEncounters[ServiceLine])) | E6: {=ROWS(_xlfn.UNIQUE(tblEncounters[ServiceLine]))&" service lines · first: "&INDEX(_xlfn._xlws.SORT(_xlfn.UNIQUE(tblEncounters[ServiceLine])),1)&" · last: "&INDEX(_xlfn._xlws.SORT(_xlfn.UNIQUE(tblEncounters[ServiceLine]),,-1),1)} | F6: A leftover note ('draft') sits in D11, inside the range the list needs. Excel never overwrites data, so it shows #SPILL! in the anchor instead. Click the warning icon, choose Select Obstructing Cells, press Delete, and the list spills at once. SORT puts the UNIQUE results in A to Z order. UNIQUE(SORT(…)) gives the same list.
A7: 3 | B7: Department names repeat across hospitals (each hospital has its own 'Emergency Department'). How many distinct Facility + Department combinations (units) appear in tblEncounters? | C7: 27 | D7: =ROWS(UNIQUE(tblEncounters[[Facility]:[Department]])) | E7: {=ROWS(_xlfn.UNIQUE(tblEncounters[[Facility]:[Department]]))} | F7: Given two columns, UNIQUE compares whole rows, so 'Bluestone Memorial Hospital | Emergency Department' and 'Cedar Ridge Medical Center | Emergency Department' are different units. =ROWS(UNIQUE(tblEncounters[Department])) returns only 20, because it merges the same name across hospitals. ROWS counts the rows of the spilled result and returns one number, so it fits in an answer cell. For columns that aren't next to each other, use UNIQUE(HSTACK(col1, col2)).
A8: 4 | B8: How many patients (PatientID) have exactly one encounter in this extract? | C8: 1186 | D8: =ROWS(UNIQUE(tblEncounters[PatientID],,TRUE)) | E8: {=ROWS(_xlfn.UNIQUE(tblEncounters[PatientID],,TRUE))} | F8: The third argument, exactly_once, set to TRUE keeps only values that occur once. The two commas skip the second argument (by_col). Compare =ROWS(UNIQUE(tblEncounters[PatientID])), which counts every distinct patient (1,549). The difference, 363 patients, came back at least twice.
A9: 5 | B9: This one uses tblDepartments (on the Departments sheet), but the formula still goes in the yellow cell here. Using FILTER, how many departments have UnitType "Inpatient" and 20 or more StaffedBeds? | C9: 7 | D9: =ROWS(FILTER(tblDepartments[Department],(tblDepartments[UnitType]="Inpatient")*(tblDepartments[StaffedBeds]>=20))) | E9: {=ROWS(_xlfn._xlws.FILTER(tblDepartments[Department],(tblDepartments[UnitType]="Inpatient")*(tblDepartments[StaffedBeds]>=20)))} | F9: Each condition returns TRUE or FALSE for all 31 rows. Multiplying them turns TRUE/FALSE into 1/0, so only rows where both are 1 pass the filter (AND logic). Bluestone Memorial Hospital's Intensive Care Unit has 20 beds but doesn't count, because its UnitType is 'Critical Care'. COUNTIFS gives the same number here. FILTER is worth learning because the same include argument can also return the rows themselves.
A10: 6 | B10: How many different attending providers (Attending) treated Emergency encounters? | C10: 28 | D10: =ROWS(UNIQUE(FILTER(tblEncounters[Attending],tblEncounters[EncounterType]="Emergency"))) | E10: {=ROWS(_xlfn.UNIQUE(_xlfn._xlws.FILTER(tblEncounters[Attending],tblEncounters[EncounterType]="Emergency")))} | F10: Read it from the inside out. FILTER keeps the Attending names of Emergency encounters (with repeats), UNIQUE removes the repeats, and ROWS counts what's left. Nesting functions this way is the core dynamic-array habit.
A11: 7 | B11: Flu-season review: what were the total charges of Emergency encounters admitted in January or February 2025 whose DxCategory is Respiratory or Infectious? Enter dollars and cents. | C11: 184214.42 | D11: =SUM(FILTER(tblEncounters[TotalCharges],(tblEncounters[EncounterType]="Emergency")*(tblEncounters[AdmitDate]<DATE(2025,3,1))*((tblEncounters[DxCategory]="Respiratory")+(tblEncounters[DxCategory]="Infectious")))) | E11: {=SUM(_xlfn._xlws.FILTER(tblEncounters[TotalCharges],(tblEncounters[EncounterType]="Emergency")*(tblEncounters[AdmitDate]<DATE(2025,3,1))*((tblEncounters[DxCategory]="Respiratory")+(tblEncounters[DxCategory]="Infectious"))))} | F11: Three conditions are multiplied (AND), and the last one is itself an OR built by adding two tests. The extra parentheses around the OR matter: without them, multiplication happens first and the formula would add every Infectious encounter of the year regardless of type or date. 64 encounters match. Because the data covers 2025 only, AdmitDate < 3/1/2025 is enough for 'January or February'.
A12: 8 | B12: What is the combined TotalCharges of the five most expensive Emergency encounters? Enter dollars and cents. | C12: 42030.97 | D12: =SUM(TAKE(SORT(FILTER(tblEncounters[TotalCharges],tblEncounters[EncounterType]="Emergency"),,-1),5)) | E12: {=SUM(_xlfn.TAKE(_xlfn._xlws.SORT(_xlfn._xlws.FILTER(tblEncounters[TotalCharges],tblEncounters[EncounterType]="Emergency"),,-1),5))} | F12: SORT(…,,-1) sorts descending (the empty second argument keeps the default sort column). TAKE(array, 5) keeps the first five rows, and SUM collapses them to one number. =SUM(LARGE(FILTER(…),{1,2,3,4,5})) works too, but TAKE scales better: change 5 to 50 and nothing else changes.
A13: 9 | B13: Outliers distort averages. What is the average TotalCharges of Inpatient encounters after dropping the 10 most expensive stays? Enter dollars and cents. | C13: 31772.46 | D13: =AVERAGE(DROP(SORT(FILTER(tblEncounters[TotalCharges],tblEncounters[EncounterType]="Inpatient"),,-1),10)) | E13: {=AVERAGE(_xlfn.DROP(_xlfn._xlws.SORT(_xlfn._xlws.FILTER(tblEncounters[TotalCharges],tblEncounters[EncounterType]="Inpatient"),,-1),10))} | F13: DROP is the mirror image of TAKE: it removes rows from the start (or, with a negative number, from the end). The full inpatient average is 33,987.43, so ten very expensive stays move the mean by about $2,215. TRIMMEAN (Lesson 2.4) trims a percentage from both ends, while DROP lets you decide exactly what to remove.
A14: 10 | B14: Which attending provider's encounters add up to the highest TotalCharges? Enter the name exactly as it appears (Last, First). | C14: Taylor, Jonathan | D14: =TAKE(SORTBY(UNIQUE(tblEncounters[Attending]),SUMIFS(tblEncounters[TotalCharges],tblEncounters[Attending],UNIQUE(tblEncounters[Attending])),-1),1) | E14: {=_xlfn.TAKE(_xlfn.SORTBY(_xlfn.UNIQUE(tblEncounters[Attending]),SUMIFS(tblEncounters[TotalCharges],tblEncounters[Attending],_xlfn.UNIQUE(tblEncounters[Attending])),-1),1)} | F14: SUMIFS normally takes one criterion. Hand it the whole UNIQUE list and it returns one total per name (142 totals). SORTBY then orders the names by those totals, even though the totals never appear in the result, and TAKE(…,1) keeps the top name. The runner-up, Hawkins, Bruce, is only $3,146 behind.
A15: 11 | B15: Look up the specialty of the attending on every Inpatient encounter (tblProviders has a Specialty for each Provider name). How many distinct specialties appear? | C15: 10 | D15: =ROWS(UNIQUE(XLOOKUP(FILTER(tblEncounters[Attending],tblEncounters[EncounterType]="Inpatient"),tblProviders[Provider],tblProviders[Specialty]))) | E15: {=ROWS(_xlfn.UNIQUE(INDEX(tblProviders[Specialty],_xlfn.XMATCH(_xlfn._xlws.FILTER(tblEncounters[Attending],tblEncounters[EncounterType]="Inpatient"),tblProviders[Provider]))))} | F15: FILTER returns 529 attending names, one per inpatient stay. XLOOKUP looks up each of them and returns an array of the same size, so you get one specialty per stay. UNIQUE and ROWS then count the distinct specialties. In Excel 2019 and earlier you'd need a helper column for this.
A16: 12 | B16: On the Workspace sheet, make F6 spill the first day of each month of 2025 (01/01/2025 through 12/01/2025) using SEQUENCE. Column F is formatted to show them as Jan 2025, Feb 2025, and so on. Then, in G6, write ONE COUNTIFS formula that refers to your month list with the spill operator (F6#) and spills the number of encounters admitted in each month. The gray cell checks both columns. | C16: 12 months · 2000 encounters | D16: 1. In F6: =DATE(2025,SEQUENCE(12),1) 2. In G6: =COUNTIFS(tblEncounters[AdmitDate],">="&F6#,tblEncounters[AdmitDate],"<"&DATE(YEAR(F6#),MONTH(F6#)+1,1)) | E16: {=_xlfn.LET(_xlpm.starts,DATE(2025,_xlfn.SEQUENCE(12),1),_xlpm.counts,COUNTIFS(tblEncounters[AdmitDate],">="&_xlpm.starts,tblEncounters[AdmitDate],"<"&DATE(YEAR(_xlpm.starts),MONTH(_xlpm.starts)+1,1)),ROWS(_xlpm.starts)&" months · "&SUM(_xlpm.counts)&" encounters")} | F16: SEQUENCE(12) spills 1 to 12, and DATE turns each number into that month's first day. In G6, F6# means 'the whole spill that starts in F6', so COUNTIFS receives 12 start dates and returns 12 counts. The upper bound DATE(YEAR(F6#),MONTH(F6#)+1,1) is the next month's first day (month 13 rolls into January 2026). If you change SEQUENCE(12) in F6 to SEQUENCE(24), G6 grows to 24 counts automatically. December is the busiest month (221 encounters).
A17: 13 | B17: Build a long-stay worklist in Workspace!I6 with ONE formula: a header row (EncounterID, Department, LOSDays, TotalCharges) on top of every Cedar Ridge Medical Center encounter with LOSDays of 7 or more, showing only those four columns, sorted by LOSDays from longest to shortest. | C17: 9 stays · longest: ENC117529 (19 d) · shortest: ENC118758 (7 d) | D17: =VSTACK({"EncounterID","Department","LOSDays","TotalCharges"},SORT(CHOOSECOLS(FILTER(tblEncounters,(tblEncounters[Facility]="Cedar Ridge Medical Center")*(tblEncounters[LOSDays]>=7)),1,8,5,15),3,-1)) | E17: {=_xlfn.LET(_xlpm.keep,(tblEncounters[Facility]="Cedar Ridge Medical Center")*(tblEncounters[LOSDays]>=7),_xlpm.ids,_xlfn._xlws.FILTER(tblEncounters[EncounterID],_xlpm.keep),_xlpm.days,_xlfn._xlws.FILTER(tblEncounters[LOSDays],_xlpm.keep),_xlpm.srt,_xlfn.SORTBY(_xlfn.HSTACK(_xlpm.ids,_xlpm.days),_xlpm.days,-1),_xlpm.nrows,ROWS(_xlpm.srt),_xlpm.nrows&" stays · longest: "&INDEX(_xlpm.srt,1,1)&" ("&INDEX(_xlpm.srt,1,2)&" d) · shortest: "&INDEX(_xlpm.srt,_xlpm.nrows,1)&" ("&INDEX(_xlpm.srt,_xlpm.nrows,2)&" d)")} | F17: Build it from the inside out. FILTER(tblEncounters, …) returns all 16 columns of the matching rows. CHOOSECOLS keeps columns 1, 8, 5, and 15 in the order you list them. SORT(…, 3, -1) sorts by the third of those columns (LOSDays), largest first. VSTACK puts the header row, an array constant in braces, on top. Two stays tie at 14 days. To break ties by charges, use SORT(…, {3,4}, {-1,-1}).

Sheet Bonus Key
A1: 🔑 Bonus Key — Lesson 4.1
A2: Spoiler alert — try every task before reading this sheet. Column C is the value the Check column compares against. Column D is a sample solution; column E is that same formula, live, proving it works.
A4: # | B4: Task | C4: Answer | D4: Sample solution | E4: Live result | F4: Explanation
A5: B1 | B5: How many units qualify for the leaderboard? Count data rows only, not the header. | C5: 13 | D5: 1. In Workspace!N6: =LET(units, UNIQUE(tblEncounters[[Facility]:[Department]]), fac, CHOOSECOLS(units, 1), dept, CHOOSECOLS(units, 2), n, COUNTIFS(tblEncounters[Facility], fac, tblEncounters[Department], dept), avg, AVERAGEIFS(tblEncounters[TotalCharges], tblEncounters[Facility], fac, tblEncounters[Department], dept), VSTACK({"Facility","Department","Encounters","AvgCharge"}, SORT(FILTER(HSTACK(units, n, avg), n >= 50), 4, -1))) 2. In the answer cell: =ROWS(Workspace!N6#)-1 | E5: {=ROWS(_xlfn.LET(_xlpm.units,_xlfn.UNIQUE(tblEncounters[[Facility]:[Department]]),_xlpm.fac,_xlfn.CHOOSECOLS(_xlpm.units,1),_xlpm.dept,_xlfn.CHOOSECOLS(_xlpm.units,2),_xlpm.n,COUNTIFS(tblEncounters[Facility],_xlpm.fac,tblEncounters[Department],_xlpm.dept),_xlpm.avg,AVERAGEIFS(tblEncounters[TotalCharges],tblEncounters[Facility],_xlpm.fac,tblEncounters[Department],_xlpm.dept),_xlfn.VSTACK({"Facility","Department","Encounters","AvgCharge"},_xlfn._xlws.SORT(_xlfn._xlws.FILTER(_xlfn.HSTACK(_xlpm.units,_xlpm.n,_xlpm.avg),_xlpm.n>=50),4,-1))))-1} | F5: UNIQUE over Facility:Department lists every unit once. CHOOSECOLS splits that two-column list so COUNTIFS and AVERAGEIFS can use each column as a criteria array, and each returns one value per unit. HSTACK glues the four columns together, FILTER keeps units with n ≥ 50, SORT orders by column 4 descending, and VSTACK adds the header. LET names each piece once, so UNIQUE runs once. Without LET, the same UNIQUE(…) would have to be repeated in every part of the formula that needs it.
A6: B2 | B6: Which Department tops the leaderboard? | C6: Cardiac Step-Down | D6: =INDEX(Workspace!N6#,2,2) | E6: {=INDEX(_xlfn.LET(_xlpm.units,_xlfn.UNIQUE(tblEncounters[[Facility]:[Department]]),_xlpm.fac,_xlfn.CHOOSECOLS(_xlpm.units,1),_xlpm.dept,_xlfn.CHOOSECOLS(_xlpm.units,2),_xlpm.n,COUNTIFS(tblEncounters[Facility],_xlpm.fac,tblEncounters[Department],_xlpm.dept),_xlpm.avg,AVERAGEIFS(tblEncounters[TotalCharges],tblEncounters[Facility],_xlpm.fac,tblEncounters[Department],_xlpm.dept),_xlfn.VSTACK({"Facility","Department","Encounters","AvgCharge"},_xlfn._xlws.SORT(_xlfn._xlws.FILTER(_xlfn.HSTACK(_xlpm.units,_xlpm.n,_xlpm.avg),_xlpm.n>=50),4,-1))),2,2)} | F6: INDEX works on a spill like on any range: row 2 (row 1 is the header), column 2. The top unit is Cardiac Step-Down at Bluestone Memorial Hospital. Inpatient units dominate the top of the board because a stay costs far more than a clinic visit.
A7: B3 | B7: What is the top unit's average charge? Enter dollars and cents. | C7: 39862.22 | D7: =INDEX(Workspace!N6#,2,4) | E7: {=INDEX(_xlfn.LET(_xlpm.units,_xlfn.UNIQUE(tblEncounters[[Facility]:[Department]]),_xlpm.fac,_xlfn.CHOOSECOLS(_xlpm.units,1),_xlpm.dept,_xlfn.CHOOSECOLS(_xlpm.units,2),_xlpm.n,COUNTIFS(tblEncounters[Facility],_xlpm.fac,tblEncounters[Department],_xlpm.dept),_xlpm.avg,AVERAGEIFS(tblEncounters[TotalCharges],tblEncounters[Facility],_xlpm.fac,tblEncounters[Department],_xlpm.dept),_xlfn.VSTACK({"Facility","Department","Encounters","AvgCharge"},_xlfn._xlws.SORT(_xlfn._xlws.FILTER(_xlfn.HSTACK(_xlpm.units,_xlpm.n,_xlpm.avg),_xlpm.n>=50),4,-1))),2,4)} | F7: Column 4 of the leaderboard is AvgCharge. A Cardiac Step-Down stay averages $39,862, about 15 times the average Bluestone Memorial emergency visit. If your answer has many decimals, that's fine: the check accepts the unrounded value.
A8: B4 | B8: What share of all TotalCharges in tblEncounters comes from the units on the leaderboard? Each unit's total is Encounters × AvgCharge. Enter it as a percentage. | C8: 0.62383032 | D8: =SUM(CHOOSECOLS(DROP(Workspace!N6#,1),3)*CHOOSECOLS(DROP(Workspace!N6#,1),4))/SUM(tblEncounters[TotalCharges]) | E8: {=SUM(_xlfn.CHOOSECOLS(_xlfn.DROP(_xlfn.LET(_xlpm.units,_xlfn.UNIQUE(tblEncounters[[Facility]:[Department]]),_xlpm.fac,_xlfn.CHOOSECOLS(_xlpm.units,1),_xlpm.dept,_xlfn.CHOOSECOLS(_xlpm.units,2),_xlpm.n,COUNTIFS(tblEncounters[Facility],_xlpm.fac,tblEncounters[Department],_xlpm.dept),_xlpm.avg,AVERAGEIFS(tblEncounters[TotalCharges],tblEncounters[Facility],_xlpm.fac,tblEncounters[Department],_xlpm.dept),_xlfn.VSTACK({"Facility","Department","Encounters","AvgCharge"},_xlfn._xlws.SORT(_xlfn._xlws.FILTER(_xlfn.HSTACK(_xlpm.units,_xlpm.n,_xlpm.avg),_xlpm.n>=50),4,-1))),1),3)*_xlfn.CHOOSECOLS(_xlfn.DROP(_xlfn.LET(_xlpm.units,_xlfn.UNIQUE(tblEncounters[[Facility]:[Department]]),_xlpm.fac,_xlfn.CHOOSECOLS(_xlpm.units,1),_xlpm.dept,_xlfn.CHOOSECOLS(_xlpm.units,2),_xlpm.n,COUNTIFS(tblEncounters[Facility],_xlpm.fac,tblEncounters[Department],_xlpm.dept),_xlpm.avg,AVERAGEIFS(tblEncounters[TotalCharges],tblEncounters[Facility],_xlpm.fac,tblEncounters[Department],_xlpm.dept),_xlfn.VSTACK({"Facility","Department","Encounters","AvgCharge"},_xlfn._xlws.SORT(_xlfn._xlws.FILTER(_xlfn.HSTACK(_xlpm.units,_xlpm.n,_xlpm.avg),_xlpm.n>=50),4,-1))),1),4))/SUM(tblEncounters[TotalCharges])} | F8: DROP(N6#,1) removes the header so only numbers remain. CHOOSECOLS pulls out the Encounters and AvgCharge columns. Multiplying them row by row rebuilds each unit's total charges, and SUM adds them. The 13 busiest units bring in 62.4% of all charges. The other 14 units see fewer patients, but most of them are ICUs and inpatient floors with high charges per stay, so together they still account for the remaining 37.6%.
