Workbook

Sheet Start Here
B2: Lesson 2.2
B3: Text Functions
B4: Beginner → Intermediate · about 50 minutes · Bluestone Health System (fictional)
B6: What you'll learn
B7: • | C7: Extract parts of text with LEFT, RIGHT, MID, FIND, and SEARCH
B8: • | C8: Clean and standardize text with TRIM, CLEAN, UPPER, LOWER, PROPER, and SUBSTITUTE
B9: • | C9: Join text with &, CONCAT, and TEXTJOIN; format numbers as text with TEXT
B10: • | C10: Use modern TEXTBEFORE, TEXTAFTER, and TEXTSPLIT (Microsoft 365)
B12: How to use this workbook
B13: 1. Read the guide | C13: The lesson guide (README) explains each skill with examples: https://github.com/lmansf/learn-excel/tree/main/02-formulas-functions/02-text-functions
B14: 2. Practice | C14: Go to the 'Practice' sheet. Type a formula or value into each yellow cell.
B15: 3. Check yourself | C15: The Check column shows ✔ Correct (green) or ✘ Not yet (red). Tasks marked 'See key' are checked by comparing with the answer key.
B16: 4. Bonus | C16: Finished? Try the harder 'Bonus' sheet.
B17: 5. Answers | C17: The 'Answer Key' and 'Bonus Key' sheets are hidden. Right-click any sheet tab → Unhide… → pick one → OK. (Try first!)
B18: Note | C18: Tasks 9 and 10 and bonus parts B1–B3 use TEXTBEFORE, TEXTAFTER, or TEXTSPLIT, which need Microsoft 365, Excel for the web, or Excel 2024. In older versions those functions show #NAME?, so use the classic LEFT, MID, and FIND methods from the guide instead.
B19: Note | C19: Tasks 2, 8, 11, and 12 ask you to fill a yellow column on a data sheet. The data sheets are Excel Tables, so a formula typed in the first row usually fills the whole column automatically.
B21: Color legend
B22: Yellow cell | C22: Your answer goes here.
B23: Gray cell | C23: Pre-filled summary formula — it reads the work you did on another sheet.
B24: ✔ Correct | C24: Your answer matches the key.
B25: ✘ Not yet | C25: Not matching yet — check the hint and try again.
B27: Sheets in this workbook
B28: Patients | C28: Data: 400 rows — Excel Table 'tblPatients'
B29: Encounters | C29: Data: 283 rows — Excel Table 'tblEncounters'
B30: Providers | C30: Data: 147 rows — Excel Table 'tblProviders'
B31: Registrations | C31: Data: 650 rows — Excel Table 'tblRegistrations'
B32: About the data | C32: 400 patients from Bluestone's registration system (names, MRNs, phones, emails, chronic-condition flags), their 283 encounters in Q4 2025, the 147-provider roster, and a 650-row legacy registration export with messy addresses.
B33: Disclaimer | C33: All people, places, and numbers are synthetic and fictional. Not clinical guidance.

Sheet Practice
A1: Lesson 2.2 · Practice
A2: Tasks use the Patients, Encounters, and Providers sheets. When a task names one patient, it also gives the row, so you can point your formula at that row's cells (for example Patients!C25). Column tasks ask you to fill a yellow column on a data sheet; a gray cell here then summarizes your column.
A3: Type a formula or value in each yellow cell. The Check column turns green when your answer matches. Stuck? Read the hint, then the lesson guide. Answers: right-click a sheet tab → Unhide… → 'Answer Key'.
A4: ="Score: "&COUNTIF(E6:E18,"✔*")&" of 13 auto-checked tasks correct"
A5: # | B5: Task | C5: Hint | D5: Your Answer | E5: Check
A6: 1 | B6: Front-desk staff confirm a caller's identity with the last 4 digits of their phone number. Return the last 4 digits of patient PT10015's phone (row 16 of the Patients sheet). | C6: RIGHT(text, num_chars) | E6: =IF(IFERROR(D6="",FALSE),"",IF(IFERROR(OR(LOWER(TRIM(D6&""))=LOWER(TRIM('Answer Key'!$C$5&""))),FALSE),"✔ Correct","✘ Not yet"))
A7: 2 | B7: On the Encounters sheet, fill the yellow DxCategory column with the ICD-10 category of each PrimaryDxCode (its first 3 characters). The gray cell counts encounters in category E11 (type 2 diabetes). Type your formula in G2, then copy it down. | C7: LEFT(text, num_chars) | D7: {=IF(COUNTA(Encounters!G2:G284)=0,"",COUNTIF(Encounters!G2:G284,"E11"))} | E7: =IF(IFERROR(D7="",FALSE),"",IF(IFERROR(AND(ISNUMBER(D7),OR(ABS(D7-'Answer Key'!$C$6)<=0.0001)),FALSE),"✔ Correct","✘ Not yet"))
A8: 3 | B8: Extract the last name of patient PT10031 (row 32 of the Patients sheet, "PETROV, Ana"): everything before the comma. | C8: FIND gives the comma's position; LEFT takes everything before it | E8: =IF(IFERROR(D8="",FALSE),"",IF(IFERROR(OR(LOWER(TRIM(D8&""))=LOWER(TRIM('Answer Key'!$C$7&""))),FALSE),"✔ Correct","✘ Not yet"))
A9: 4 | B9: The appointment-reminder system needs phone numbers as 10 digits with no punctuation. Convert patient PT10058's phone (row 59, "(555) 529-7071") to digits only. | C9: Nest one SUBSTITUTE per character you want to remove | E9: =IF(IFERROR(D9="",FALSE),"",IF(IFERROR(OR(LOWER(TRIM(D9&""))=LOWER(TRIM('Answer Key'!$C$8&""))),FALSE),"✔ Correct","✘ Not yet"))
A10: 5 | B10: Patient PT10002's MRN (row 3) shows 897724 because the export stored it as a number and dropped the leading zeros. Return it as the 8-character text MRN printed on wristbands. | C10: TEXT(value, format_text) with a format of eight 0s | E10: =IF(IFERROR(D10="",FALSE),"",IF(IFERROR(OR(LOWER(TRIM(D10&""))=LOWER(TRIM('Answer Key'!$C$9&""))),FALSE),"✔ Correct","✘ Not yet"))
A11: 6 | B11: Monthly quality reports label encounters by month. Return the admit month of encounter ENC120217 (row 128 of the Encounters sheet) as text in the form Mon-YYYY, for example Jan-2026. | C11: TEXT with a date format code | E11: =IF(IFERROR(D11="",FALSE),"",IF(IFERROR(OR(LOWER(TRIM(D11&""))=LOWER(TRIM('Answer Key'!$C$10&""))),FALSE),"✔ Correct","✘ Not yet"))
A12: 7 | B12: Build the ID-badge label for provider PRV1054 (row 55 of the Providers sheet) in the form Dr. First Last, Credential. For example, provider PRV1001's label is Dr. Roy Ferguson, MD. | C12: Join pieces with &; spaces and punctuation go inside quotes | E12: =IF(IFERROR(D12="",FALSE),"",IF(IFERROR(OR(LOWER(TRIM(D12&""))=LOWER(TRIM('Answer Key'!$C$11&""))),FALSE),"✔ Correct","✘ Not yet"))
A13: 8 | B13: On the Patients sheet, fill the yellow HasDM column with TRUE when the patient's ChronicConditions list includes DM (diabetes) and FALSE otherwise. Blank lists should give FALSE. The gray cell counts the TRUEs. | C13: SEARCH returns a position or #VALUE!; ISNUMBER turns that into TRUE/FALSE | D13: {=IF(COUNTA(Patients!I2:I401)=0,"",COUNTIF(Patients!I2:I401,TRUE))} | E13: =IF(IFERROR(D13="",FALSE),"",IF(IFERROR(AND(ISNUMBER(D13),OR(ABS(D13-'Answer Key'!$C$12)<=0.0001)),FALSE),"✔ Correct","✘ Not yet"))
A14: 9 | B14: The patient portal username is the part of the email address before the @. Return the username for patient PT10123 (row 124). | C14: TEXTBEFORE (Microsoft 365), or LEFT + FIND | E14: =IF(IFERROR(D14="",FALSE),"",IF(IFERROR(OR(LOWER(TRIM(D14&""))=LOWER(TRIM('Answer Key'!$C$13&""))),FALSE),"✔ Correct","✘ Not yet"))
A15: 10 | B15: How many chronic conditions does patient PT10101 (row 102) have? Split the semicolon-separated ChronicConditions list with TEXTSPLIT and count the pieces. | C15: COUNTA(TEXTSPLIT(…)) returns one number instead of a spill | E15: =IF(IFERROR(D15="",FALSE),"",IF(IFERROR(AND(ISNUMBER(D15),OR(ABS(D15-'Answer Key'!$C$14)<=0.0001)),FALSE),"✔ Correct","✘ Not yet"))
A16: 11 | B16: On the Patients sheet, fill the yellow ContactLine column with the phone and email joined by " | " (space, vertical bar, space), for example (555) 875-0698 | edward.abbott94@example.com. When there's no email, show just the phone, with no dangling separator. The gray cell counts lines that contain a |. | C16: TEXTJOIN(delimiter, ignore_empty, …) | D16: {=IF(COUNTA(Patients!H2:H401)=0,"",COUNTIF(Patients!H2:H401,"*|*"))} | E16: =IF(IFERROR(D16="",FALSE),"",IF(IFERROR(AND(ISNUMBER(D16),OR(ABS(D16-'Answer Key'!$C$15)<=0.0001)),FALSE),"✔ Correct","✘ Not yet"))
A17: 12 | B17: On the Patients sheet, fill the yellow FirstName column with each patient's first name: everything after the comma in PatientName, with no extra spaces. Watch out: some names have doubled, leading, or trailing spaces, and 28 were pasted from the patient portal with non-breaking spaces (UNICHAR(160)). Case doesn't matter here. The gray cell adds up the lengths of all your first names, so any leftover space changes the total. | C17: TRIM can't remove a non-breaking space; SUBSTITUTE it with a normal space first | D17: {=IF(COUNTA(Patients!G2:G401)=0,"",SUMPRODUCT(LEN(Patients!G2:G401)))} | E17: =IF(IFERROR(D17="",FALSE),"",IF(IFERROR(AND(ISNUMBER(D17),OR(ABS(D17-'Answer Key'!$C$16)<=0.0001)),FALSE),"✔ Correct","✘ Not yet"))
A18: 13 | B18: Patient PT10325's name was typed as "o'brien,hannah " (row 326, with two trailing spaces). Return a clean display name in the form First Last, in Proper Case. This check is case-sensitive. | C18: Extract both parts, join them with " ", then wrap everything in PROPER | E18: =IF(IFERROR(D18="",FALSE),"",IF(IFERROR(EXACT(D18,'Answer Key'!$C$17),FALSE),"✔ Correct","✘ Not yet"))

Sheet Patients
A1: PatientID | B1: MRN | C1: PatientName | D1: Phone | E1: Email | F1: ChronicConditions | G1: FirstName | H1: ContactLine | I1: HasDM | J1: ConditionCount
A2: PT10001 | B2: 8293181 | C2: ABBOTT, Edward | D2: (555) 875-0698 | E2: edward.abbott94@example.com | F2: HTN;DM
A3: PT10002 | B3: 897724 | C3: Peterson, Brenda | D3: (555) 373-1790 | F3: HTN;DM
A4: PT10003 | B4: 9970254 | C4: CRUZ, CHRISTIAN | D4: (555) 853-8470 | E4: christian.cruz12@example.com | F4: HTN;HF
A5: PT10004 | B5: 7139825 | C5: hamilton, george | D5: (555) 327-5166 | E5: george.hamilton90@example.com
A6: PT10005 | B6: 2312589 | C6: Romero, Albert | D6: (555) 963-5969 | F6: HTN
A7: PT10006 | B7: 5707071 | C7: YILMAZ, Alexis | D7: (555) 779-1083
A8: PT10007 | B8: 3029934 | C8: Chavez, Carol | D8: (555) 981-0131 | E8: carol.chavez85@example.com | F8: HTN
A9: PT10008 | B9: 4700089 | C9: CLARK,ARTHUR | D9: (555) 518-1637
A10: PT10009 | B10: 6171140 | C10: miller, wei | D10: (555) 729-4132 | F10: ETOH
A11: PT10010 | B11: 158711 | C11: Hill, Gloria | D11: (555) 300-6504
A12: PT10011 | B12: 9871480 | C12: SULLIVAN, Russell | D12: (555) 470-5202 | E12: russell.sullivan51@example.com | F12: HTN;CKD;OA
A13: PT10012 | B13: 7078263 | C13: Cruz, Theresa | D13: (555) 393-0161 | E13: theresa.cruz77@example.com
A14: PT10013 | B14: 324447 | C14: ANDREWS, BRIAN | D14: (555) 585-0021 | E14: brian.andrews93@example.com | F14: HTN
A15: PT10014 | B15: 2589502 | C15: hudson, walter | D15: (555) 916-0820
A16: PT10015 | B16: 2570260 | C16: Walker, Judith | D16: (555) 404-7258 | E16: judith.walker43@example.com
A17: PT10016 | B17: 7426502 | C17: KENNEDY, Danielle | D17: (555) 476-8447 | E17: danielle.kennedy84@example.com
A18: PT10017 | B18: 965645 | C18: Ramos, Albert | D18: (555) 288-5776
A19: PT10018 | B19: 2774533 | C19: HANSEN, NICHOLAS | D19: (555) 864-8575 | E19: nicholas.hansen3@example.com
A20: PT10019 | B20: 4236785 | C20: clark,steven | D20: (555) 871-3637 | F20: ASTHMA
A21: PT10020 | B21: 326186 | C21: Freeman, Wayne | D21: (555) 449-3334
A22: PT10021 | B22: 9635756 | C22: ALEXANDER, Emily | D22: (555) 721-2029 | E22: emily.alexander38@example.com | F22: OA
A23: PT10022 | B23: 4683061 | C23: Lindqvist, Austin | D23: (555) 592-9434 | E23: austin.lindqvist96@example.com
A24: PT10023 | B24: 9440135 | C24: WRIGHT, ALEXIS | D24: (555) 445-0654 | E24: alexis.wright39@example.com
A25: PT10024 | B25: 7685936 | C25: sandoval, priya | D25: (555) 481-8733 | F25: HTN;HF
A26: PT10025 | B26: 2854098 | C26: Cox, Ana | D26: (555) 408-1898 | E26: ana.cox52@example.com
A27: PT10026 | B27: 6109281 | C27: PETERS, Janice | D27: (555) 294-0043 | E27: janice.peters55@example.com
A28: PT10027 | B28: 4383389 | C28: Green, Andrea | D28: (555) 463-4236 | E28: andrea.green40@example.com | F28: ASTHMA
A29: PT10028 | B29: 6030962 | C29: MUNOZ, RYAN | D29: (555) 824-9974
A30: PT10029 | B30: 2482556 | C30: kim, omar | D30: (555) 755-9188 | E30: omar.kim28@example.com
A31: PT10030 | B31: 9030950 | C31: Thomas,Sarah | D31: (555) 549-4055 | F31: HTN;DM;OA
A32: PT10031 | B32: 5797014 | C32: PETROV, Ana | D32: (555) 516-8754 | E32: ana.petrov28@example.com | F32: HTN;PSYCH
A33: PT10032 | B33: 3929231 | C33: White, Amber | D33: (555) 556-3833 | E33: amber.white81@example.com
A34: PT10033 | B34: 6040014 | C34: WRIGHT, BRADLEY | D34: (555) 941-0190 | F34: ASTHMA
A35: PT10034 | B35: 1542628 | C35: stephens, ruth | D35: (555) 950-5408 | E35: ruth.stephens42@example.com | F35: HTN;SEIZURE
A36: PT10035 | B36: 9174321 | C36: Bailey, Doris | D36: (555) 226-8764 | F36: ASTHMA
A37: PT10036 | B37: 3624414 | C37: FOSTER, Mia | D37: (555) 382-8064 | E37: mia.foster11@example.com
A38: PT10037 | B38: 1744632 | C38: Hayes, Joseph | D38: (555) 738-5381 | E38: joseph.hayes58@example.com | F38: HTN;COPD
A39: PT10038 | B39: 7466388 | C39: O'BRIEN, TERRY | D39: (555) 220-7977 | E39: terry.obrien54@example.com
A40: PT10039 | B40: 6071518 | C40: cunningham, emma | D40: (555) 497-6103
...

Sheet Encounters
A1: EncounterID | B1: PatientID | C1: EncounterType | D1: AdmitDate | E1: PrimaryDxCode | F1: DxDescription | G1: DxCategory
A2: ENC118912 | B2: PT10335 | C2: Observation | D2: 45931 | E2: R07.9 | F2: Chest pain, unspecified
A3: ENC118915 | B3: PT10196 | C3: Inpatient | D3: 45931 | E3: J44.1 | F3: Chronic obstructive pulmonary disease with (acute) exacerbation
A4: ENC118935 | B4: PT10147 | C4: Outpatient | D4: 45932 | E4: H66.90 | F4: Otitis media, unspecified, unspecified ear
A5: ENC118945 | B5: PT10171 | C5: Emergency | D5: 45932 | E5: S93.401A | F5: Sprain of unspecified ligament of right ankle, initial encounter
A6: ENC118991 | B6: PT10119 | C6: Inpatient | D6: 45934 | E6: I63.9 | F6: Cerebral infarction, unspecified
A7: ENC118999 | B7: PT10095 | C7: Emergency | D7: 45934 | E7: M54.50 | F7: Low back pain, unspecified
A8: ENC119011 | B8: PT10367 | C8: Emergency | D8: 45935 | E8: I10 | F8: Essential (primary) hypertension
A9: ENC119023 | B9: PT10002 | C9: Outpatient | D9: 45936 | E9: C50.911 | F9: Malignant neoplasm of unspecified site of right female breast
A10: ENC119025 | B10: PT10142 | C10: Emergency | D10: 45936 | E10: L03.115 | F10: Cellulitis of right lower limb
A11: ENC119038 | B11: PT10239 | C11: Outpatient | D11: 45936 | E11: I10 | F11: Essential (primary) hypertension
A12: ENC119053 | B12: PT10307 | C12: Emergency | D12: 45936 | E12: F32.9 | F12: Major depressive disorder, single episode, unspecified
A13: ENC119059 | B13: PT10291 | C13: Emergency | D13: 45937 | E13: J06.9 | F13: Acute upper respiratory infection, unspecified
... A284: ENC121857 | B284: PT10119 | C284: Emergency | D284: 46022 | E284: N39.0 | F284: Urinary tract infection, site not specified

Sheet Providers
A1: ProviderID | B1: FirstName | C1: LastName | D1: Credential | E1: Specialty
A2: PRV1001 | B2: Roy | C2: Ferguson | D2: MD | E2: Emergency Medicine
A3: PRV1002 | B3: Mia | C3: Cruz | D3: MD | E3: Emergency Medicine
A4: PRV1003 | B4: Jordan | C4: Morris | D4: MD | E4: Emergency Medicine
A5: PRV1004 | B5: Jesse | C5: Elliott | D5: MD | E5: Emergency Medicine
A6: PRV1005 | B6: Christian | C6: Olson | D6: DO | E6: Emergency Medicine
A7: PRV1006 | B7: James | C7: Kowalski | D7: MD | E7: Emergency Medicine
A8: PRV1007 | B8: Alexander | C8: Mendoza | D8: MD | E8: Emergency Medicine
A9: PRV1008 | B9: Jacob | C9: Sullivan | D9: DO | E9: Emergency Medicine
A10: PRV1009 | B10: Patrick | C10: Foster | D10: DO | E10: Emergency Medicine
A11: PRV1010 | B11: Nancy | C11: Payne | D11: MD | E11: Emergency Medicine
A12: PRV1011 | B12: Mia | C12: Gonzales | D12: PA | E12: Emergency Medicine
... A148: PRV1147 | B148: Natalie | C148: Wagner | D148: MD | E148: Pathology

Sheet Bonus
A1: Lesson 2.2 · Bonus: Mailing list for the new diabetes education clinic
A2: Bluestone is opening a diabetes education clinic in Cedar Ridge. Marketing wants a clean mailing list from the legacy registration export (the Registrations sheet), and care management wants to know how many current patients are 'complex' (three or more chronic conditions). The export crams city, state, and ZIP into one CityStateZip column in several styles: Cedar Ridge, OH 45720 · CEDAR RIDGE, OH 45720 · Cedar Ridge OH 45720 (no comma) · Cedar Ridge, OH 45720-1280 (ZIP+4). Some city names are two words. (The export also has duplicate records. Removing those is a Lesson 3.3 job, so leave them in.)
A3: Type a formula or value in each yellow cell. The Check column turns green when your answer matches. Stuck? Read the hint, then the lesson guide. Answers: right-click a sheet tab → Unhide… → 'Bonus Key'.
A4: ="Score: "&COUNTIF(E6:E10,"✔*")&" of 5 auto-checked tasks correct"
A5: # | B5: Task | C5: Hint | D5: Your Answer | E5: Check
A6: B1 | B6: On the Registrations sheet, fill the yellow City column with just the city name in Proper Case, with no comma, state, or ZIP (for example Lakeview Heights). The gray cell counts rows whose City is exactly Lakeview Heights (case-sensitive). That town appears in every messy style, so it's a good test. | C6: The city is everything before the second-to-last space. TEXTBEFORE accepts a negative instance_num | D6: {=IF(COUNTA(Registrations!D2:D651)=0,"",SUMPRODUCT(--EXACT(Registrations!D2:D651,"Lakeview Heights")))} | E6: =IF(IFERROR(D6="",FALSE),"",IF(IFERROR(AND(ISNUMBER(D6),OR(ABS(D6-'Bonus Key'!$C$5)<=0.0001)),FALSE),"✔ Correct","✘ Not yet"))
A7: B2 | B7: Fill the yellow ZIP5 column with the 5-digit ZIP code as text. ZIP+4 codes like 45720-1280 must become 45720. The gray cell counts rows in ZIP 45501 (downtown Bluestone). | C7: The ZIP is the last word; keep only its first 5 characters | D7: {=IF(COUNTA(Registrations!E2:E651)=0,"",COUNTIF(Registrations!E2:E651,"45501"))} | E7: =IF(IFERROR(D7="",FALSE),"",IF(IFERROR(AND(ISNUMBER(D7),OR(ABS(D7-'Bonus Key'!$C$6)<=0.0001)),FALSE),"✔ Correct","✘ Not yet"))
A8: B3 | B8: Write one formula that turns record R1002's CityStateZip (row 3, "CEDAR RIDGE, OH 45720") into the mailing-label line City, ST 12345: city in Proper Case, a comma and a space, the 2-letter state in capitals, a space, and the 5-digit ZIP. This check is case-sensitive. | C8: Build city, state, and ZIP separately, then join them with &. Which piece needs PROPER? | E8: =IF(IFERROR(D8="",FALSE),"",IF(IFERROR(EXACT(D8,'Bonus Key'!$C$7),FALSE),"✔ Correct","✘ Not yet"))
A9: B4 | B9: Back on the Patients sheet, fill the yellow ConditionCount column with the number of chronic conditions each patient has: 0 when ChronicConditions is blank, 1 for HTN, 2 for HTN;DM, and so on. The gray cell counts 'complex' patients with 3 or more conditions. | C9: Items = semicolons + 1. How many semicolons? Compare LEN before and after removing them | D9: {=IF(COUNTA(Patients!J2:J401)=0,"",COUNTIF(Patients!J2:J401,">=3"))} | E9: =IF(IFERROR(D9="",FALSE),"",IF(IFERROR(AND(ISNUMBER(D9),OR(ABS(D9-'Bonus Key'!$C$8)<=0.0001)),FALSE),"✔ Correct","✘ Not yet"))
A10: B5 | B10: What is the average number of chronic conditions per patient across all 400 patients, including those with none? Use your ConditionCount column. (The check accepts 2 decimal places.) | C10: AVERAGE of the column you just filled | E10: =IF(IFERROR(D10="",FALSE),"",IF(IFERROR(AND(ISNUMBER(D10),OR(ABS(D10-'Bonus Key'!$C$9)<=0.0051)),FALSE),"✔ Correct","✘ Not yet"))

Sheet Registrations
A1: RecordID | B1: PatientName | C1: CityStateZip | D1: City | E1: ZIP5
A2: R1001 | B2: Haddad, Jonathan | C2: Bluestone OH 45501
A3: R1002 | B3: Powell, Wei | C3: CEDAR RIDGE, OH 45720
A4: R1003 | B4: Campbell, Virginia | C4: Riverbend, OH 45545
A5: R1004 | B5: MURRAY, MARGARET | C5: Bluestone, OH 45501
A6: R1005 | B6: ELLIS, JOSEPH | C6: LAKEVIEW HEIGHTS, OH 45510
A7: R1006 | B7: BOYD, DOUGLAS | C7: Granite Springs OH 45750
A8: R1007 | B8: perry, janet | C8: Granite Springs, OH 45750
A9: R1008 | B9: Hunter, Austin | C9: BLUESTONE, OH 45502
A10: R1009 | B10: Alexander , Gary | C10: Bluestone, OH 45501
A11: R1010 | B11: Watson , Amy | C11: Bluestone, OH 45501-8106
A12: R1011 | B12: Ferguson , Carolyn | C12: Oak Glen OH 45730
A13: R1012 | B13: Gomez, Walter | C13: ASHBY FALLS, OH 45610
... A651: R1650 | B651: JONES, MARY | C651: BLUESTONE, OH 45502

Sheet Answer Key
A1: 🔑 Answer Key — Lesson 2.2
A2: Spoiler alert — try every task before reading this sheet. Column C is the value the Check column compares against. Column D is a sample solution; column E is that same formula, live, proving it works.
A4: # | B4: Task | C4: Answer | D4: Sample solution | E4: Live result | F4: Explanation
A5: 1 | B5: Front-desk staff confirm a caller's identity with the last 4 digits of their phone number. Return the last 4 digits of patient PT10015's phone (row 16 of the Patients sheet). | C5: 7258 | D5: =RIGHT(Patients!D16,4) | E5: {=RIGHT(Patients!D16,4)} | F5: RIGHT returns characters from the end of the text. The phone is stored as text in a fixed (555) 123-4567 layout, so its last 4 characters are always the last 4 digits. The result is text: a phone ending in 0698 would correctly keep its leading 0.
A6: 2 | B6: On the Encounters sheet, fill the yellow DxCategory column with the ICD-10 category of each PrimaryDxCode (its first 3 characters). The gray cell counts encounters in category E11 (type 2 diabetes). Type your formula in G2, then copy it down. | C6: 15 | D6: =LEFT(E2,3) | E6: {=SUMPRODUCT(--(LEFT(Encounters!E2:E284,3)="E11"))} | F6: An ICD-10 code's first three characters are its category, so LEFT(code,3) groups E11.65 and E11.9 together as E11. Codes have different lengths (I10, E11.65, S72.001A), but the category is always the first 3 characters, which is why LEFT works with a fixed count here.
A7: 3 | B7: Extract the last name of patient PT10031 (row 32 of the Patients sheet, "PETROV, Ana"): everything before the comma. | C7: PETROV | D7: =LEFT(Patients!C32,FIND(",",Patients!C32)-1) | E7: {=LEFT(Patients!C32,FIND(",",Patients!C32)-1)} | F7: FIND(",",…) returns the comma's position (7). The last name is the 6 characters before it, so subtract 1. In Microsoft 365 you can also write =TEXTBEFORE(Patients!C32,",").
A8: 4 | B8: The appointment-reminder system needs phone numbers as 10 digits with no punctuation. Convert patient PT10058's phone (row 59, "(555) 529-7071") to digits only. | C8: 5555297071 | D8: =SUBSTITUTE(SUBSTITUTE(SUBSTITUTE(SUBSTITUTE(Patients!D59,"(",""),")","")," ",""),"-","") | E8: {=SUBSTITUTE(SUBSTITUTE(SUBSTITUTE(SUBSTITUTE(Patients!D59,"(",""),")","")," ",""),"-","")} | F8: Each SUBSTITUTE replaces one character with nothing (""). Nesting them removes the parentheses, the space, and the dash in one formula. Work from the inside out: the innermost SUBSTITUTE runs first and passes its result to the next one. The result is text, which is what you want for phone numbers.
A9: 5 | B9: Patient PT10002's MRN (row 3) shows 897724 because the export stored it as a number and dropped the leading zeros. Return it as the 8-character text MRN printed on wristbands. | C9: 00897724 | D9: =TEXT(Patients!B3,"00000000") | E9: {=TEXT(Patients!B3,"00000000")} | F9: In a format code, each 0 is a required digit, so "00000000" pads the number with leading zeros to 8 digits. The result "00897724" is text, so the zeros are part of the value: they survive joining with & and match MRNs stored as text in other systems. A custom number format (Lesson 1.3) only changes how the cell looks, so ="MRN "&Patients!B3 would still give MRN 897724.
A10: 6 | B10: Monthly quality reports label encounters by month. Return the admit month of encounter ENC120217 (row 128 of the Encounters sheet) as text in the form Mon-YYYY, for example Jan-2026. | C10: Nov-2025 | D10: =TEXT(Encounters!D128,"mmm-yyyy") | E10: {=TEXT(Encounters!D128,"mmm-yyyy")} | F10: In a date format code, mmm is the short month name and yyyy is the 4-digit year. The dash is copied as-is. Without TEXT, a date joined to text shows its serial number: ="Admitted "&Encounters!D128 gives Admitted 45975, because a date is stored as a number.
A11: 7 | B11: Build the ID-badge label for provider PRV1054 (row 55 of the Providers sheet) in the form Dr. First Last, Credential. For example, provider PRV1001's label is Dr. Roy Ferguson, MD. | C11: Dr. Jonathan Taylor, MD | D11: ="Dr. "&Providers!B55&" "&Providers!C55&", "&Providers!D55 | E11: {="Dr. "&Providers!B55&" "&Providers!C55&", "&Providers!D55} | F11: The & operator joins text. Literal text, including every space, the period after Dr, and the comma, goes inside double quotes. =CONCAT("Dr. ",Providers!B55," ",Providers!C55,", ",Providers!D55) gives the same result.
A12: 8 | B12: On the Patients sheet, fill the yellow HasDM column with TRUE when the patient's ChronicConditions list includes DM (diabetes) and FALSE otherwise. Blank lists should give FALSE. The gray cell counts the TRUEs. | C12: 52 | D12: =ISNUMBER(SEARCH("DM",F2)) | E12: {=SUMPRODUCT(--ISNUMBER(SEARCH("DM",Patients!F2:F401)))} | F12: SEARCH returns the position where DM starts, or #VALUE! when it isn't there (including in blank cells). ISNUMBER converts any position to TRUE and the error to FALSE. SEARCH ignores case, so it would also find dm. If a code could hide inside a longer code, search for ";DM;" inside ";"&F2&";" instead.
A13: 9 | B13: The patient portal username is the part of the email address before the @. Return the username for patient PT10123 (row 124). | C13: sara.scott36 | D13: =TEXTBEFORE(Patients!E124,"@") | E13: {=_xlfn.TEXTBEFORE(Patients!E124,"@")} | F13: TEXTBEFORE returns everything before the first @. The classic version, which works in every Excel, is =LEFT(Patients!E124,FIND("@",Patients!E124)-1).
A14: 10 | B14: How many chronic conditions does patient PT10101 (row 102) have? Split the semicolon-separated ChronicConditions list with TEXTSPLIT and count the pieces. | C14: 4 | D14: =COUNTA(TEXTSPLIT(Patients!F102,";")) | E14: {=COUNTA(_xlfn.TEXTSPLIT(Patients!F102,";"))} | F14: TEXTSPLIT spills one condition per cell to the right. Wrapping it in COUNTA counts the pieces and returns a single number, so nothing spills into the Check column. Without TEXTSPLIT, count the semicolons and add 1: =LEN(Patients!F102)-LEN(SUBSTITUTE(Patients!F102,";",""))+1.
A15: 11 | B15: On the Patients sheet, fill the yellow ContactLine column with the phone and email joined by " | " (space, vertical bar, space), for example (555) 875-0698 | edward.abbott94@example.com. When there's no email, show just the phone, with no dangling separator. The gray cell counts lines that contain a |. | C15: 229 | D15: =TEXTJOIN(" | ",TRUE,D2,E2) | E15: {=COUNTA(Patients!E2:E401)} | F15: TEXTJOIN puts the delimiter between items. With ignore_empty set to TRUE, it skips the blank email, so those rows show only the phone. With FALSE, or with D2&" | "&E2, every row gets a separator and the blank rows end in a dangling " | ".
A16: 12 | B16: On the Patients sheet, fill the yellow FirstName column with each patient's first name: everything after the comma in PatientName, with no extra spaces. Watch out: some names have doubled, leading, or trailing spaces, and 28 were pasted from the patient portal with non-breaking spaces (UNICHAR(160)). Case doesn't matter here. The gray cell adds up the lengths of all your first names, so any leftover space changes the total. | C16: 2324 | D16: =TRIM(MID(SUBSTITUTE(C2,UNICHAR(160)," "),FIND(",",C2)+1,LEN(C2))) | E16: {=SUMPRODUCT(LEN(TRIM(MID(SUBSTITUTE(Patients!C2:C401,_xlfn.UNICHAR(160)," "),FIND(",",Patients!C2:C401)+1,LEN(Patients!C2:C401)))))} | F16: Work from the inside out. SUBSTITUTE turns each non-breaking space into an ordinary space, MID takes everything after the comma (LEN is simply a length that's long enough), and TRIM removes the leading, trailing, and doubled spaces. Without the SUBSTITUTE, the 28 portal rows keep an invisible character and the total comes out 28 too high. On Windows, CHAR(160) is the same character as UNICHAR(160). A Microsoft 365 version is =TRIM(SUBSTITUTE(TEXTAFTER(C2,","),UNICHAR(160)," ")).
A17: 13 | B17: Patient PT10325's name was typed as "o'brien,hannah " (row 326, with two trailing spaces). Return a clean display name in the form First Last, in Proper Case. This check is case-sensitive. | C17: Hannah O'Brien | D17: =PROPER(TRIM(MID(Patients!C326,FIND(",",Patients!C326)+1,LEN(Patients!C326)))&" "&LEFT(Patients!C326,FIND(",",Patients!C326)-1)) | E17: — | F17: MID + FIND takes the first name and TRIM drops the trailing spaces. LEFT + FIND takes the last name. Join them with a space and wrap the whole thing in PROPER, which capitalizes the first letter of each word and every letter that follows a non-letter. That's why the B after the apostrophe in O'Brien comes out right. In Microsoft 365: =PROPER(TRIM(TEXTAFTER(Patients!C326,","))&" "&TEXTBEFORE(Patients!C326,",")).

Sheet Bonus Key
A1: 🔑 Bonus Key — Lesson 2.2
A2: Spoiler alert — try every task before reading this sheet. Column C is the value the Check column compares against. Column D is a sample solution; column E is that same formula, live, proving it works.
A4: # | B4: Task | C4: Answer | D4: Sample solution | E4: Live result | F4: Explanation
A5: B1 | B5: On the Registrations sheet, fill the yellow City column with just the city name in Proper Case, with no comma, state, or ZIP (for example Lakeview Heights). The gray cell counts rows whose City is exactly Lakeview Heights (case-sensitive). That town appears in every messy style, so it's a good test. | C5: 51 | D5: =PROPER(TRIM(SUBSTITUTE(TEXTBEFORE(C2," ",-2),",",""))) | E5: {=COUNTIF(Registrations!C2:C651,"Lakeview Heights*")} | F5: The commas are unreliable, but the spaces are not: the last two spaces always separate the city, the state, and the ZIP. TEXTBEFORE(C2," ",-2) counts spaces from the end, so it returns everything before the second-to-last space ("Cedar Ridge," or "CEDAR RIDGE"). SUBSTITUTE removes a comma if there is one, TRIM tidies up, and PROPER fixes the case. A FIND(",") approach fails with #VALUE! on the rows that have no comma. Without Microsoft 365, the classic trick is =PROPER(SUBSTITUTE(LEFT(C2,LEN(C2)-LEN(TRIM(RIGHT(SUBSTITUTE(C2," ",REPT(" ",100)),100)))-4),",","")): the TRIM(RIGHT(SUBSTITUTE(…))) part pulls out the last word (the ZIP), and LEFT keeps everything except the ZIP and the 4 characters of " OH ".
A6: B2 | B6: Fill the yellow ZIP5 column with the 5-digit ZIP code as text. ZIP+4 codes like 45720-1280 must become 45720. The gray cell counts rows in ZIP 45501 (downtown Bluestone). | C6: 113 | D6: =LEFT(TEXTAFTER(C2," ",-1),5) | E6: {=COUNTIF(Registrations!C2:C651,"* 45501*")} | F6: TEXTAFTER(C2," ",-1) returns everything after the last space: the whole ZIP or ZIP+4. LEFT(…,5) keeps the first five digits. RIGHT(C2,5) looks tempting but returns "-1280" for 45720-1280. 23 of the 113 rows in 45501 have a ZIP+4. Keep ZIPs as text: a ZIP like 02134 would lose its leading zero as a number. Classic version: =LEFT(TRIM(RIGHT(SUBSTITUTE(C2," ",REPT(" ",100)),100)),5). SUBSTITUTE swaps every space for 100 spaces, RIGHT(…,100) then grabs a chunk that holds only the last word plus padding, and TRIM strips the padding.
A7: B3 | B7: Write one formula that turns record R1002's CityStateZip (row 3, "CEDAR RIDGE, OH 45720") into the mailing-label line City, ST 12345: city in Proper Case, a comma and a space, the 2-letter state in capitals, a space, and the 5-digit ZIP. This check is case-sensitive. | C7: Cedar Ridge, OH 45720 | D7: =PROPER(TRIM(SUBSTITUTE(TEXTBEFORE(Registrations!C3," ",-2),",","")))&", "&UPPER(TEXTBEFORE(TEXTAFTER(Registrations!C3," ",-2)," "))&" "&LEFT(TEXTAFTER(Registrations!C3," ",-1),5) | E7: — | F7: The state is the word between the last two spaces: TEXTAFTER(…," ",-2) gives "OH 45720", and TEXTBEFORE(…," ") keeps "OH". Apply PROPER to the city only. Wrapping the whole line in PROPER is the classic mistake: it turns OH into Oh. If you finished B1 and B2, =Registrations!D3&", OH "&Registrations!E3 also works, but extracting the state keeps the formula correct for out-of-state patients.
A8: B4 | B8: Back on the Patients sheet, fill the yellow ConditionCount column with the number of chronic conditions each patient has: 0 when ChronicConditions is blank, 1 for HTN, 2 for HTN;DM, and so on. The gray cell counts 'complex' patients with 3 or more conditions. | C8: 35 | D8: =IF(F2="",0,LEN(F2)-LEN(SUBSTITUTE(F2,";",""))+1) | E8: {=SUMPRODUCT((Patients!F2:F401<>"")*((LEN(Patients!F2:F401)-LEN(SUBSTITUTE(Patients!F2:F401,";",""))+1)>=3))} | F8: LEN(F2)-LEN(SUBSTITUTE(F2,";","")) is the number of semicolons, because removing them shortens the text by exactly that many characters. A list always has one more item than separators, so add 1. The IF handles blank lists: without it, a blank cell has 0 semicolons and would count as 1 condition. COUNTA(TEXTSPLIT(F2,";")) has the same problem on blank cells, so it needs the same IF.
A9: B5 | B9: What is the average number of chronic conditions per patient across all 400 patients, including those with none? Use your ConditionCount column. (The check accepts 2 decimal places.) | C9: 0.875 | D9: =AVERAGE(Patients!J2:J401) | E9: {=SUMPRODUCT((Patients!F2:F401<>"")*(LEN(Patients!F2:F401)-LEN(SUBSTITUTE(Patients!F2:F401,";",""))+1))/ROWS(Patients!F2:F401)} | F9: If your average comes out as 1.33, your column counts the 181 blank lists as 1 condition each. That mistake doesn't change B4's count, because those rows stay below 3, but it inflates the average. Testing a formula on the edge cases (blank, one item, many items) catches errors like this.
