Workbook
Name ClinicDays: Model!$B$7
Name VisitsPerDay: Model!$B$8
Name MedicaidShare: Model!$B$16
Name CommercialShare: Model!$B$17
Name CommercialRate: Model!$C$17
Name BillingFeePct: Model!$B$36
Name VisitsPerMonth: Model!$B$42
Name AvgReimbursement: Model!$B$43
Name NetRevenue: Model!$B$44
Name TotalExpenses: Model!$B$56
Name OperatingIncome: Model!$B$59
Name OperatingMargin: Model!$B$60

Sheet Start Here
B2: Lesson 3.6
B3: What-If Analysis: Goal Seek, Scenarios, Data Tables & Solver
B4: Intermediate · about 125 minutes · Bluestone Health System (fictional)
B6: What you'll learn
B7: • | C7: Structure a model with separate inputs, calculations, and outputs
B8: • | C8: Find break-even points with Goal Seek
B9: • | C9: Compare cases with Scenario Manager and sensitivity Data Tables
B10: • | C10: Optimize a staffing mix with Solver
B12: How to use this workbook
B13: 1. Read the guide | C13: The lesson guide (README) explains each skill with examples: https://github.com/lmansf/learn-excel/tree/main/03-data-analysis/06-what-if-analysis
B14: 2. Practice | C14: Go to the 'Practice' sheet. Type a formula or value into each yellow cell.
B15: 3. Check yourself | C15: The Check column shows ✔ Correct (green) or ✘ Not yet (red).
B16: 4. Bonus | C16: Finished? Try the harder 'Bonus' sheet.
B17: 5. Answers | C17: The 'Answer Key' and 'Bonus Key' sheets are hidden. Right-click any sheet tab → Unhide… → pick one → OK. (Try first!)
B18: Note | C18: Model is the clinic's monthly profit and loss (P&L) model, laid out as INPUTS (blue numbers), CALCULATIONS (black formulas), and OUTPUTS. You complete two yellow output cells and build two Data Tables in the Sensitivity area (columns F–K).
B19: Note | C19: Staffing is a Solver worksheet. The green cells are the decision variables that Solver changes. Sources lists where every data-derived input came from.
B20: Note | C20: Goal Seek and Scenario Manager's Show button change the Model's input cells. Put the base case back after each run so the other tasks stay correct. Solver only changes the Staffing sheet, which doesn't feed the Model.
B21: Note | C21: Solver is a free add-in that ships with Excel. Turn it on once: File → Options → Add-ins → Manage: Excel Add-ins → Go → tick Solver Add-in (Mac: Tools → Excel Add-ins).
B23: Color legend
B24: Yellow cell | C24: Your answer goes here.
B25: Gray cell | C25: Pre-filled summary formula. It reads the work you did on another sheet, so don't type over it.
B26: ✔ Correct | C26: Your answer matches the key.
B27: ✘ Not yet | C27: Not matching yet. Check the hint and try again.
B29: Sheets in this workbook
B30: Practice | C30: 13 practice tasks, each with a Check cell.
B31: Sources | C31: Data: 21 rows, in the Excel Table 'tblSources'
B32: Bonus | C32: The bonus challenge (4 parts).
B33: About the data | C33: A monthly operating model for Bluestone's Primary Care Clinic (D400, Bluestone Outpatient Pavilion). Payer mix and reimbursement come from the clinic's 2,079 claims with 2025 service dates, wage rates from Bluestone HR records, and benefits, supply, and fixed costs from the clinic's 2025 budget actuals.
B34: Disclaimer | C34: All people, places, and numbers are synthetic and fictional. Not clinical guidance.

Sheet Practice
A1: Lesson 3.6 · Practice
A2: Every task uses the Model and Staffing sheets. Tasks 1 and 2 read your Model live, so their checks stay green only while the Model holds its base-case inputs (200 visits per day, Commercial $142, and so on). The same is true of any answer you type as a link to a Model cell, such as =Model!H11. After each Goal Seek run, click Cancel in the Goal Seek Status box so the Model keeps those inputs. The Staffing sheet doesn't feed the Model, so you can keep Solver's solutions there.
A3: Type a formula or value in each yellow cell. The Check column turns green when your answer matches. Stuck? Read the hint, then the lesson guide. Answers: right-click a sheet tab → Unhide… → 'Answer Key'.
A4: ="Score: "&COUNTIF(E6:E18,"✔*")&" of 13 auto-checked tasks correct"
A5: # | B5: Task | C5: Hint | D5: Your Answer | E5: Check
A6: 1 | B6: On the Model sheet, complete the yellow Operating income cell (B59): net patient revenue minus total operating expenses. The gray cell here reads your formula. What is the clinic's base-case operating income per month? | C6: An output should only point at calculation cells | D6: {=IF(Model!B59="","",Model!B59)} | E6: =IF(IFERROR(D6="",FALSE),"",IF(IFERROR(AND(ISNUMBER(D6),OR(ABS(D6-'Answer Key'!$C$5)<=0.0051)),FALSE),"✔ Correct","✘ Not yet"))
A7: 2 | B7: Complete the yellow Operating margin cell (B60): operating income as a share of net patient revenue. What is the base-case operating margin? The cell is already formatted as a percentage. | C7: Margin = income ÷ revenue | D7: {=IF(Model!B60="","",Model!B60)} | E7: =IF(IFERROR(D7="",FALSE),"",IF(IFERROR(AND(ISNUMBER(D7),OR(ABS(D7-'Answer Key'!$C$6)<=0.00051,ABS(D7-'Answer Key'!$C$6*100)<=0.051000000000000004)),FALSE),"✔ Correct","✘ Not yet"))
A8: 3 | B8: Audit the model. One formula in the CALCULATIONS section (rows 42–56) has a number typed into it instead of a reference to its input cell. Type that cell's address (for example B99). Then fix the formula so it points to the input. Task 10 depends on the fix. | C8: Show Formulas, or Trace Dependents on each input | E8: =IF(IFERROR(D8="",FALSE),"",IF(IFERROR(OR(LOWER(TRIM(D8&""))=LOWER(TRIM('Answer Key'!$C$7&"")),LOWER(TRIM(D8&""))="$b$52",LOWER(TRIM(D8&""))="model!b52",LOWER(TRIM(D8&""))="model!$b$52"),FALSE),"✔ Correct","✘ Not yet"))
A9: 4 | B9: On the Model sheet, use Goal Seek to find the break-even volume: set Operating income (B59) to 0 by changing Visits per day (B8). How many visits per day does the clinic need? Round to 1 decimal place, then click Cancel to restore 200. | C9: Data → What-If Analysis → Goal Seek | E9: =IF(IFERROR(D9="",FALSE),"",IF(IFERROR(AND(ISNUMBER(D9),OR(ABS(D9-'Answer Key'!$C$8)<=0.051)),FALSE),"✔ Correct","✘ Not yet"))
A10: 5 | B10: The CFO is renegotiating commercial contracts. On the Model sheet, use Goal Seek to set Operating margin (B60) to 5% (type 0.05) by changing the Commercial $ per visit (C17). What commercial reimbursement per visit is needed? Round to the nearest dollar, then click Cancel to restore $142. | C10: The Set cell must contain a formula, so use the margin cell | E10: =IF(IFERROR(D10="",FALSE),"",IF(IFERROR(AND(ISNUMBER(D10),OR(ABS(D10-'Answer Key'!$C$9)<=0.8)),FALSE),"✔ Correct","✘ Not yet"))
A11: 6 | B11: Build the one-variable Data Table in Model!F8:H17: put =B59 in G8 and =B60 in H8, select F8:H17, and use Column input cell B8. What operating margin does your table show at 190 visits per day? Enter it as a percentage to 1 decimal place. | C11: The visits run down a column, so use the Column input cell | E11: =IF(IFERROR(D11="",FALSE),"",IF(IFERROR(AND(ISNUMBER(D11),OR(ABS(D11-'Answer Key'!$C$10)<=0.00051,ABS(D11-'Answer Key'!$C$10*100)<=0.051000000000000004)),FALSE),"✔ Correct","✘ Not yet"))
A12: 7 | B12: Look down the Operating income column of your one-variable table. What is the lowest visits-per-day value in the table at which the clinic makes a profit (operating income above 0)? | C12: Read the table, or let MINIFS find it | E12: =IF(IFERROR(D12="",FALSE),"",IF(IFERROR(AND(ISNUMBER(D12),OR(ABS(D12-'Answer Key'!$C$11)<=0.0001)),FALSE),"✔ Correct","✘ Not yet"))
A13: 8 | B13: Build the two-variable Data Table: put =B59 in the corner cell F22, select F22:K31, and use Row input cell C17 (commercial $ across row 22) and Column input cell B8 (visits per day down column F). What operating income does the table show at 210 visits per day and $160 per commercial visit? Round to the nearest dollar. | C13: Row input = the input whose values run across the top row | E13: =IF(IFERROR(D13="",FALSE),"",IF(IFERROR(AND(ISNUMBER(D13),OR(ABS(D13-'Answer Key'!$C$12)<=0.51)),FALSE),"✔ Correct","✘ Not yet"))
A14: 9 | B14: How many of the 45 combinations in your two-variable table (G23:K31) are profitable (operating income above 0)? Use a formula. | C14: COUNTIF with ">0" | E14: =IF(IFERROR(D14="",FALSE),"",IF(IFERROR(AND(ISNUMBER(D14),OR(ABS(D14-'Answer Key'!$C$13)<=0.0001)),FALSE),"✔ Correct","✘ Not yet"))
A15: 10 | B15: Open Scenario Manager on the Model and add three scenarios that change B8, B16, B17 and B36. Base plan: visits per day 200, Medicaid share 14.9%, Commercial share 37.6%, billing fee 4.0%. Downside: visits per day 190, Medicaid share 17.9%, Commercial share 34.6%, billing fee 5.0%. Upside: visits per day 206, Medicaid share 12.9%, Commercial share 39.6%, billing fee 3.5%. Create a Scenario Summary with result cells B59 and B60. What is operating income in the Downside scenario? Round to the nearest dollar. | C15: Data → What-If Analysis → Scenario Manager | E15: =IF(IFERROR(D15="",FALSE),"",IF(IFERROR(AND(ISNUMBER(D15),OR(ABS(D15-'Answer Key'!$C$14)<=0.51)),FALSE),"✔ Correct","✘ Not yet"))
A16: 11 | B16: From the same Scenario Summary, what operating margin does the Upside scenario produce? Enter it as a percentage to 1 decimal place. | C16: Same summary, different column | E16: =IF(IFERROR(D16="",FALSE),"",IF(IFERROR(AND(ISNUMBER(D16),OR(ABS(D16-'Answer Key'!$C$15)<=0.00051,ABS(D16-'Answer Key'!$C$15*100)<=0.051000000000000004)),FALSE),"✔ Correct","✘ Not yet"))
A17: 12 | B17: On the Staffing sheet, use Solver to minimize the monthly staff cost (B31) by changing the RN, LPN, and CNA FTEs (B18:B20), subject to the three constraints in rows 25–27 (leave out the CNA cap in row 28). Keep Make Unconstrained Variables Non-Negative ticked and choose Simplex LP. What is the minimum monthly cost? Round to the nearest dollar, and type the number rather than a link to B31, because the bonus runs Solver on this sheet again. | C17: Data → Solver (enable the Solver add-in first) | E17: =IF(IFERROR(D17="",FALSE),"",IF(IFERROR(AND(ISNUMBER(D17),OR(ABS(D17-'Answer Key'!$C$16)<=0.51)),FALSE),"✔ Correct","✘ Not yet"))
A18: 13 | B18: Run Solver again (same setup) and select Sensitivity under Reports before you click OK. On the Sensitivity Report sheet, what is the Shadow Price of the Total support hours constraint (Staffing!B25)? Enter it in dollars to 2 decimal places. | C18: Shadow price = cost change per one-unit increase in the constraint's right-hand side | E18: =IF(IFERROR(D18="",FALSE),"",IF(IFERROR(AND(ISNUMBER(D18),OR(ABS(D18-'Answer Key'!$C$17)<=0.011)),FALSE),"✔ Correct","✘ Not yet"))

Sheet Model
A1: Primary Care Clinic (D400) · Monthly Operating Model
A2: Bluestone Outpatient Pavilion · FY2026 plan · $ per month unless stated
A3: Blue = input (change these) · Black = formula (don't type over) · Yellow = you complete it.
A4: Named cells (Formulas → Name Manager): ClinicDays, VisitsPerDay, MedicaidShare, CommercialShare, CommercialRate, BillingFeePct, VisitsPerMonth, AvgReimbursement, NetRevenue, TotalExpenses, OperatingIncome, OperatingMargin.
A5: INPUTS | F5: SENSITIVITY AREA (Data Tables)
A6: Volume & capacity | B6: Value | C6: Unit | D6: Source / note | F6: One-variable Data Table · Column input cell: B8
A7: Clinic days per month | B7: 21 | C7: days | D7: Weekdays the clinic is open, less holidays (plan) | F7: Visits per day | G7: Operating income | H7: Operating margin
A8: Visits per day | B8: 200 | C8: visits | D8: FY2026 plan | I8: ← type =B59 and =B60 here (task 6)
A9: Physician FTEs (MD/DO) | B9: 7 | C9: FTE | D9: Current staffing | F9: 180
A10: APP FTEs (NP/PA) | B10: 3 | C10: FTE | D10: Current staffing | F10: 185
A11: Visits per physician per day | B11: 22 | C11: visits | D11: Scheduling template | F11: 190
A12: Visits per APP per day | B12: 18 | C12: visits | D12: Scheduling template | F12: 195
A13: Payer mix & reimbursement | B13: Share of visits | C13: $ per visit | D13: Source / note | F13: 200
A14: Medicare | B14: 0.251 | C14: 87 | D14: 2025 D400 claims (Sources) | F14: 205
A15: Medicare Advantage | B15: 0.166 | C15: 88 | D15: 2025 D400 claims (Sources) | F15: 210
A16: Medicaid | B16: 0.149 | C16: 66 | D16: 2025 D400 claims (Sources) | F16: 215
A17: Commercial (incl. Workers' Comp) | B17: 0.376 | C17: 142 | D17: 2025 D400 claims (Sources) | F17: 220
A18: Self-Pay | B18: 0.058 | C18: 120 | D18: 2025 D400 claims (Sources) | F18: Select F8:H17 → Data → What-If Analysis → Data Table → Column input cell B8. The gray cells fill in.
A19: Payer mix total (check) | B19: =SUM(B14:B18) | C19: =IF(ROUND(B19,6)=1,"✔ totals 100%","✘ must total 100%")
A20: Staffing & pay | B20: Value | C20: Unit | D20: Source / note | F20: Two-variable Data Table · Row input cell: C17 · Column input cell: B8
A21: RN FTEs | B21: 5 | C21: FTE | D21: Current staffing | F21: ↓ Visits per day | G21: Commercial $ per visit →
A22: LPN FTEs | B22: 3 | C22: FTE | D22: Current staffing | G22: 130 | H22: 140 | I22: 150 | J22: 160 | K22: 170
A23: CNA FTEs | B23: 8 | C23: FTE | D23: Current staffing | F23: 180
A24: Front desk & admin FTEs | B24: 8 | C24: FTE | D24: Current staffing | F24: 185
A25: Paid hours per FTE per month | B25: 168 | C25: hours | D25: Full-time paid hours per month (plan) | F25: 190
A26: Physician salary per FTE | B26: 22000 | C26: $/month | D26: FY2026 compensation plan | F26: 195
A27: APP salary per FTE | B27: 10800 | C27: $/month | D27: FY2026 compensation plan | F27: 200
A28: RN hourly rate | B28: 42.73 | C28: $/hour | D28: Median of active RNs (Sources) | F28: 205
A29: LPN hourly rate | B29: 27.73 | C29: $/hour | D29: Median of active LPNs (Sources) | F29: 210
A30: CNA hourly rate | B30: 19.74 | C30: $/hour | D30: Median of active CNAs (Sources) | F30: 215
A31: Front desk hourly rate | B31: 18.86 | C31: $/hour | D31: Median of active unit secretaries (Sources) | F31: 220
A32: Benefits load (% of wages) | B32: 0.267 | D32: 2025 D400 benefits ÷ wages (Sources) | F32: Type =B59 in the yellow corner F22, select F22:K31 → Data Table → Row input cell C17, Column input cell B8.
A33: Other costs | B33: Value | C33: Unit | D33: Source / note
A34: Medical supplies per visit | B34: 4.39 | C34: $/visit | D34: 2025 D400 actuals (Sources)
A35: Vaccines & injectables per visit | B35: 1.27 | C35: $/visit | D35: 2025 D400 actuals (Sources)
A36: Billing & collections fee | B36: 0.04 | C36: of revenue | D36: Revenue-cycle vendor contract
A37: Facility & equipment | B37: 11500 | C37: $/month | D37: Fixed. 2025 D400 actuals (Sources)
A38: IT, EHR & purchased services | B38: 24200 | C38: $/month | D38: Fixed. 2025 D400 actuals (Sources)
A39: Other operating | B39: 14000 | C39: $/month | D39: Fixed. 2025 D400 actuals (Sources)
A41: CALCULATIONS (one formula per row · no typed-in numbers)
...

Sheet Staffing
A1: Clinical Support Staffing Plan · Solver worksheet
A2: Choose RN, LPN, and CNA FTEs that cover the clinic's workload at the lowest monthly cost. Blue = input · Green text = linked from the Model · Green cells = decision variables that Solver changes.
A5: INPUTS
A6: Visits per day to staff for | B6: 200 | C6: visits | D6: Model base case. The bonus changes it.
A7: Clinic days per month | B7: =Model!B7 | C7: days | D7: From the Model
A8: Visits per month | B8: =B6*B7 | C8: visits
A9: Support hours needed per visit (RN + LPN + CNA) | B9: 0.6 | C9: hours | D9: Rooming, vitals, injections, care coordination (time study)
A10: Licensed hours needed per visit (RN + LPN only) | B10: 0.28 | C10: hours | D10: Triage calls, medications, patient teaching
A11: Minimum RN share of licensed FTEs | B11: 0.6 | D11: Clinic policy
A12: CNA cap | B12: 6 | C12: FTEs | D12: Approved CNA positions (bonus only)
A13: Paid hours per FTE per month | B13: =Model!B25 | C13: hours | D13: From the Model
A14: Benefits load | B14: =Model!B32 | D14: From the Model
A16: DECISION VARIABLES (Solver changes the green cells)
A17: Role | B17: FTEs | C17: Hourly rate | D17: Cost per FTE per month | E17: Monthly cost
A18: Registered Nurse (RN) | B18: 5 | C18: =Model!B28 | D18: =C18*$B$13*(1+$B$14) | E18: =B18*D18
A19: Licensed Practical Nurse (LPN) | B19: 3 | C19: =Model!B29 | D19: =C19*$B$13*(1+$B$14) | E19: =B19*D19
A20: Certified Nursing Assistant (CNA) | B20: 8 | C20: =Model!B30 | D20: =C20*$B$13*(1+$B$14) | E20: =B20*D20
A21: Total | B21: =SUM(B18:B20) | E21: =SUM(E18:E20)
A23: CONSTRAINTS (each row: Provided sign Required)
A24: Constraint | B24: Provided | C24: Sign | D24: Required | E24: Status
A25: Total support hours | B25: =B21*B13 | C25: ≥ | D25: =B8*B9 | E25: =IF(B25>=D25-0.001,"OK","Short")
A26: Licensed hours (RN + LPN) | B26: =(B18+B19)*B13 | C26: ≥ | D26: =B8*B10 | E26: =IF(B26>=D26-0.001,"OK","Short")
A27: RN rule: RN FTEs − 60% × (RN + LPN FTEs) | B27: =B18-B11*(B18+B19) | C27: ≥ | D27: 0 | E27: =IF(B27>=D27-0.001,"OK","Short")
A28: CNA FTEs (bonus only) | B28: =B20 | C28: ≤ | D28: =B12 | E28: =IF(B28<=D28+0.001,"OK","Over cap (bonus only)")
A30: OBJECTIVE
A31: Monthly clinical support staff cost (minimize) | B31: =E21

Sheet Sources
A1: Input | B1: Model cell | C1: Value used | D1: How it was derived | E1: Source data
A2: Medicare: share of visits | B2: B14 | C2: 25.1% | D2: 523 of 2,079 D400 claims with 2025 service dates (25.16%); rounded to 0.1 point so the five shares total exactly 100% | E2: claims.csv + encounters.csv (DeptID D400)
A3: Medicare Advantage: share of visits | B3: B15 | C3: 16.6% | D3: 345 of 2,079 D400 claims with 2025 service dates (16.59%); rounded to 0.1 point so the five shares total exactly 100% | E3: claims.csv + encounters.csv (DeptID D400)
A4: Medicaid: share of visits | B4: B16 | C4: 14.9% | D4: 310 of 2,079 D400 claims with 2025 service dates (14.91%); rounded to 0.1 point so the five shares total exactly 100% | E4: claims.csv + encounters.csv (DeptID D400)
A5: Commercial (incl. Workers' Comp): share of visits | B5: B17 | C5: 37.6% | D5: 781 of 2,079 D400 claims with 2025 service dates (37.57%); rounded to 0.1 point so the five shares total exactly 100% | E5: claims.csv + encounters.csv (DeptID D400)
A6: Self-Pay: share of visits | B6: B18 | C6: 5.8% | D6: 120 of 2,079 D400 claims with 2025 service dates (5.77%); rounded to 0.1 point so the five shares total exactly 100% | E6: claims.csv + encounters.csv (DeptID D400)
A7: Medicare: $ per visit | B7: C14 | C7: $87 | D7: Average AllowedAmount per 2025 D400 claim = $86.83 (denied and appealed claims carry an AllowedAmount of $0 and count as $0), rounded to the dollar | E7: claims.csv
A8: Medicare Advantage: $ per visit | B8: C15 | C8: $88 | D8: Average AllowedAmount per 2025 D400 claim = $87.88 (denied and appealed claims carry an AllowedAmount of $0 and count as $0), rounded to the dollar | E8: claims.csv
A9: Medicaid: $ per visit | B9: C16 | C9: $66 | D9: Average AllowedAmount per 2025 D400 claim = $66.09 (denied and appealed claims carry an AllowedAmount of $0 and count as $0), rounded to the dollar | E9: claims.csv
A10: Commercial (incl. Workers' Comp): $ per visit | B10: C17 | C10: $142 | D10: Average AllowedAmount per 2025 D400 claim = $141.57 (denied and appealed claims carry an AllowedAmount of $0 and count as $0), rounded to the dollar | E10: claims.csv
A11: Self-Pay: $ per visit | B11: C18 | C11: $120 | D11: Average AllowedAmount per 2025 D400 claim = $120.13 (denied and appealed claims carry an AllowedAmount of $0 and count as $0), rounded to the dollar | E11: claims.csv
A12: RN hourly rate | B12: B28 | C12: $42.73 | D12: Median HourlyRate of the 331 active employees with JobTitle = Registered Nurse | E12: employees.csv
... A22: Everything else on the Model | B22: — | C22: — | D22: Planning assumptions for FY2026: clinic days, visits per day, provider and staff FTEs, provider salaries, visits per provider per day, paid hours per FTE, and the billing fee. Staffing hours per visit are on the Staffing sheet. | E22: Plan (not from data)

Sheet Bonus
A1: Lesson 3.6 · Bonus: Staff the 2026 growth plan
A2: Bluestone wants the Primary Care Clinic to grow to 220 visits per day in 2026 by adding a fourth advanced practice provider (APP: a nurse practitioner or physician assistant). Capacity rises from 208 to 226 visits per day. HR hires whole people, so every role needs a whole number of 1.0-FTE staff. Only 6 CNA positions are approved (Staffing!B12). Find the cheapest staffing plan, then test the full plan in the Model's P&L.
A3: Type a formula or value in each yellow cell. The Check column turns green when your answer matches. Stuck? Read the hint, then the lesson guide. Answers: right-click a sheet tab → Unhide… → 'Bonus Key'.
A4: ="Score: "&COUNTIF(E6:E9,"✔*")&" of 4 auto-checked tasks correct"
A5: # | B5: Task | C5: Hint | D5: Your Answer | E5: Check
A6: B1 | B6: On the Staffing sheet, change B6 to 220. Re-run Solver with two more constraints: B18:B20 = int (integer) and B28 <= D28 (the CNA cap). In Solver Options, set Integer Optimality (%) to 0. What is the minimum monthly staff cost? Round to the nearest dollar. | C6: In Add Constraint, pick int from the middle list. Integer Optimality is on the All Methods tab of Options | E6: =IF(IFERROR(D6="",FALSE),"",IF(IFERROR(AND(ISNUMBER(D6),OR(ABS(D6-'Bonus Key'!$C$5)<=0.51)),FALSE),"✔ Correct","✘ Not yet"))
A7: B2 | B7: How many RNs does that plan hire? | C7: Read Staffing!B18. The RN rule in row 27 should still say OK | E7: =IF(IFERROR(D7="",FALSE),"",IF(IFERROR(AND(ISNUMBER(D7),OR(ABS(D7-'Bonus Key'!$C$6)<=0.0001)),FALSE),"✔ Correct","✘ Not yet"))
A8: B3 | B8: How many LPNs does that plan hire? | C8: Is rounding the fractional answer up the same thing? | E8: =IF(IFERROR(D8="",FALSE),"",IF(IFERROR(AND(ISNUMBER(D8),OR(ABS(D8-'Bonus Key'!$C$7)<=0.0001)),FALSE),"✔ Correct","✘ Not yet"))
A9: B4 | B9: Test the plan in the P&L. On the Model, first select the Base plan scenario and click Show, so the payer mix and billing fee are back at their base values. Then add two more scenarios that change B8, B10, and B21:B23 (visits per day, APP FTEs, and RN, LPN, and CNA FTEs, in that order): Today (200, 3, 5, 3, 8) and Growth 2026 (220, 4, and the RN, LPN, and CNA counts in Staffing!B18:B20). What operating income does Growth 2026 produce? Round to the nearest dollar. | C9: A scenario changes only its own cells. Every other input keeps the value it has when you click Show | E9: =IF(IFERROR(D9="",FALSE),"",IF(IFERROR(AND(ISNUMBER(D9),OR(ABS(D9-'Bonus Key'!$C$8)<=0.51)),FALSE),"✔ Correct","✘ Not yet"))

Sheet Answer Key
A1: 🔑 Answer Key — Lesson 3.6
A2: Spoiler alert: try every task before reading this sheet. Column C is the value the Check column compares against. Column D is a sample solution, and column E recalculates a formula for it live, proving the answer.
A4: # | B4: Task | C4: Answer | D4: Sample solution | E4: Live result | F4: Explanation
A5: 1 | B5: On the Model sheet, complete the yellow Operating income cell (B59): net patient revenue minus total operating expenses. The gray cell here reads your formula. What is the clinic's base-case operating income per month? | C5: -8618.72 | D5: =B44-B56 | E5: {=Model!B44-Model!B56} | F5: Operating income is revenue minus expenses, and both already exist as calculation rows (B44 and B56). Because those cells are named, =NetRevenue-TotalExpenses works too and reads better. The clinic loses about $8,619 a month in the base case. That's common for hospital-owned primary care, which is why the rest of the lesson asks what it would take to break even.
A6: 2 | B6: Complete the yellow Operating margin cell (B60): operating income as a share of net patient revenue. What is the base-case operating margin? The cell is already formatted as a percentage. | C6: -0.01924464 | D6: =B59/B44 | E6: {=(Model!B44-Model!B56)/Model!B44} | F6: Margin divides operating income by revenue (=OperatingIncome/NetRevenue). A margin lets you compare a small clinic with a large hospital, which a dollar figure can't. Goal Seek will aim at this cell in task 5.
A7: 3 | B7: Audit the model. One formula in the CALCULATIONS section (rows 42–56) has a number typed into it instead of a reference to its input cell. Type that cell's address (for example B99). Then fix the formula so it points to the input. Task 10 depends on the fix. | C7: B52 | D7: 1. On the Model sheet, choose Formulas → Show Formulas (or press the Show Formulas shortcut from section 2), and read down rows 42–56. 2. B52 reads =NetRevenue*0.04. The 4% is typed in, although the fee has its own input cell, B36. 3. Change B52 to =NetRevenue*BillingFeePct (or =B44*B36), then turn Show Formulas off again to see values. | E7: — | F7: Today both versions return the same number, so nothing looks wrong. The trouble starts when someone changes the fee input in B36: the model ignores it. Another way to catch this is Formulas → Trace Dependents on B36. Excel draws no arrows and tells you no formula refers to the active cell, because no formula reads that input.
A8: 4 | B8: On the Model sheet, use Goal Seek to find the break-even volume: set Operating income (B59) to 0 by changing Visits per day (B8). How many visits per day does the clinic need? Round to 1 decimal place, then click Cancel to restore 200. | C8: 204.2 | D8: 1. On the Model sheet, choose Data → What-If Analysis → Goal Seek. 2. Set cell: B59 · To value: 0 · By changing cell: B8. 3. Click OK. B8 shows 204.2 (the cell holds 204.2440…). Note it, then click Cancel. | E8: {=ROUND(Model!B8-(Model!B44-Model!B56)/((Model!B43*(1-Model!B52/Model!B44)-Model!B34-Model!B35)*Model!B7),1)} | F8: Each extra visit per day adds one visit on each of the 21 clinic days. Each of those visits brings in $96.71 after the billing fee, supplies, and vaccines (its contribution margin). Fixed costs are $414,783 a month, so break-even = $414,783 ÷ ($96.71 × 21) ≈ 204.2. That is 98% of the clinic's 208-visit daily capacity, so volume alone is a fragile fix. The live result in the key does this algebra, and Goal Seek reaches the same answer by trial and error.
A9: 5 | B9: The CFO is renegotiating commercial contracts. On the Model sheet, use Goal Seek to set Operating margin (B60) to 5% (type 0.05) by changing the Commercial $ per visit (C17). What commercial reimbursement per visit is needed? Round to the nearest dollar, then click Cancel to restore $142. | C9: 163.58 | D9: 1. On the Model sheet, choose Data → What-If Analysis → Goal Seek. 2. Set cell: B60 · To value: 0.05 · By changing cell: C17. 3. Click OK, read C17, and click Cancel. | E9: {=Model!C17+((Model!B56-Model!B52)/(1-Model!B52/Model!B44-0.05)/Model!B42-Model!B43)/Model!B17} | F9: Commercial plans would have to pay about $164 instead of $142, an increase of 15%. Only 37.6% of visits are commercial, so each extra commercial dollar moves the average reimbursement by just 37.6 cents. Margin is a ratio, so Goal Seek has to iterate here, and it stops when the margin is within its tolerance of 5%. That's why the check accepts a small range around the exact value.
A10: 6 | B10: Build the one-variable Data Table in Model!F8:H17: put =B59 in G8 and =B60 in H8, select F8:H17, and use Column input cell B8. What operating margin does your table show at 190 visits per day? Enter it as a percentage to 1 decimal place. | C10: -0.067990134 | D10: =Model!H11 | E10: — | F10: The visits per day values run down a column (F9:F17), so B8 is the column input cell and the row input box stays empty. For each value, Excel puts it in B8, recalculates the model, and writes the results of the formulas in row 8 into that row of the table. You can type the number or point at H11.
A11: 7 | B11: Look down the Operating income column of your one-variable table. What is the lowest visits-per-day value in the table at which the clinic makes a profit (operating income above 0)? | C11: 205 | D11: =MINIFS(Model!F9:F17,Model!G9:G17,">0") | E11: — | F11: The table jumps in steps of 5, so it brackets the break-even point instead of finding it: 200 visits loses money and 205 makes money, which agrees with Goal Seek's 204.2. Use a Data Table to see the whole curve, and Goal Seek to pin down the exact crossing. MINIFS needs Excel 2019 or later. In older versions, read the value off the table and type it.
A12: 8 | B12: Build the two-variable Data Table: put =B59 in the corner cell F22, select F22:K31, and use Row input cell C17 (commercial $ across row 22) and Column input cell B8 (visits per day down column F). What operating income does the table show at 210 visits per day and $160 per commercial visit? Round to the nearest dollar. | C12: 40342 | D12: =Model!J29 | E12: — | F12: A two-variable table has exactly one formula, in its top-left corner. Excel substitutes each top-row value into the row input cell (C17) and each left-column value into the column input cell (B8), and fills every intersection. If you swap the two input cells, the table still fills without any warning, but with wrong numbers. So check one cell by hand. The base case is 200 visits at $142 (−$8,619), so the cell at 200 visits and $140 should be about $3,032 lower, because the clinic's 1,579 commercial visits a month each pay $2 less, minus the 4% fee on those dollars. With swapped input cells that cell would show 140 visits a day at $200, a far bigger loss.
A13: 9 | B13: How many of the 45 combinations in your two-variable table (G23:K31) are profitable (operating income above 0)? Use a formula. | C13: 24 | D13: =COUNTIF(Model!G23:K31,">0") | E13: — | F13: Ordinary formulas can read a Data Table's results, so you can count them, chart them, or add conditional formatting. The profitable combinations sit in the bottom-right of the table, where volume and rate are both high. Reading down each column shows the trade-off the CFO cares about: at $130 per commercial visit the clinic first makes money at 215 visits a day, but at $170 it does at 185. A better contract lowers the volume the clinic needs to break even.
A14: 10 | B14: Open Scenario Manager on the Model and add three scenarios that change B8, B16, B17 and B36. Base plan: visits per day 200, Medicaid share 14.9%, Commercial share 37.6%, billing fee 4.0%. Downside: visits per day 190, Medicaid share 17.9%, Commercial share 34.6%, billing fee 5.0%. Upside: visits per day 206, Medicaid share 12.9%, Commercial share 39.6%, billing fee 3.5%. Create a Scenario Summary with result cells B59 and B60. What is operating income in the Downside scenario? Round to the nearest dollar. | C14: -41824 | D14: 1. Select B8, then Ctrl-click (Mac: ⌘-click) B16:B17 and B36. 2. Data → What-If Analysis → Scenario Manager → Add…. Name it Base plan and click OK. The values box shows the current values, so click OK again. 3. Click Add… again for Downside and Upside. Type the values in the order B8, B16, B17, B36 (decimals like 0.179 for 17.9%). 4. Click Summary…, choose Scenario summary, set Result cells to B59,B60, and click OK. Read the Downside column on the new Scenario Summary sheet. | E14: — | F14: Fewer visits, a shift from commercial to Medicaid, and a higher vendor fee all hit income at once. If you skipped the fix in task 3, the model ignores the 5% fee and you'd see −$37,660 instead. That's exactly the kind of silent error a hard-coded number causes. The summary sheet is a snapshot. It doesn't update when the model changes, so create it again after any edit.
A15: 11 | B15: From the same Scenario Summary, what operating margin does the Upside scenario produce? Enter it as a percentage to 1 decimal place. | C15: 0.026114614 | D15: Read the Upside column of the OperatingMargin row on the Scenario Summary sheet. | E15: — | F15: The Upside case brings the clinic to roughly 2.6%. It takes three things at once: 6 more visits a day, 2 points of payer mix shifted from Medicaid to Commercial, and a cheaper vendor contract (3.5%). Because B59 and B60 are named, the summary labels those rows OperatingIncome and OperatingMargin instead of $B$59 and $B$60.
A16: 12 | B16: On the Staffing sheet, use Solver to minimize the monthly staff cost (B31) by changing the RN, LPN, and CNA FTEs (B18:B20), subject to the three constraints in rows 25–27 (leave out the CNA cap in row 28). Keep Make Unconstrained Variables Non-Negative ticked and choose Simplex LP. What is the minimum monthly cost? Round to the nearest dollar, and type the number rather than a link to B31, because the bonus runs Solver on this sheet again. | C16: 88342 | D16: 1. On the Staffing sheet, choose Data → Solver. 2. Set Objective: $B$31 · To: Min · By Changing Variable Cells: $B$18:$B$20. 3. Click Add and enter $B$25:$B$27 >= $D$25:$D$27, then click OK. 4. Leave Make Unconstrained Variables Non-Negative ticked, choose Simplex LP, and click Solve. 5. Choose Keep Solver Solution, click OK, and type the value of B31, rounded to the dollar, in the answer cell. | E16: {=Staffing!B8*Staffing!B10/Staffing!B13*(Staffing!B11*Staffing!D18+(1-Staffing!B11)*Staffing!D19)+Staffing!B8*(Staffing!B9-Staffing!B10)/Staffing!B13*Staffing!D20} | F16: Solver chooses 4.2 RN, 2.8 LPN and 8.0 CNA FTEs. This answer makes sense: CNAs are the cheapest staff, so they cover every hour that doesn't need a licensed nurse. The licensed hours are then split at exactly the 60% RN minimum, because LPNs cost less than RNs. Today's 5/3/8 staffing costs $96,798, so the plan saves about $8,457 a month. The key's live result rebuilds this optimum with algebra from the Staffing sheet's own cells.
A17: 13 | B17: Run Solver again (same setup) and select Sensitivity under Reports before you click OK. On the Sensitivity Report sheet, what is the Shadow Price of the Total support hours constraint (Staffing!B25)? Enter it in dollars to 2 decimal places. | C17: 25.01 | D17: 1. Data → Solver, same parameters as task 12, Solve. 2. In Solver Results, select Sensitivity under Reports, then click OK. 3. On the new Sensitivity Report 1 sheet, find the row for $B$25 under Constraints and read Shadow Price. | E17: {=ROUND(Model!B30*(1+Model!B32),2)} | F17: Requiring one more support hour raises the minimum cost by $25.01. That's one CNA hour at $19.74 plus 26.7% benefits, because the cheapest way to cover an hour that doesn't need a licensed nurse is a CNA hour. The live result in the key repeats that arithmetic. The licensed-hours constraint (B26) has a shadow price of only $21.53, even though licensed nurses cost more. An extra licensed hour costs 0.6 RN hours plus 0.4 LPN hours, but licensed hours also count toward the total, so it replaces a CNA hour that's no longer needed.

Sheet Bonus Key
A1: 🔑 Bonus Key — Lesson 3.6
A2: Spoiler alert: try every task before reading this sheet. Column C is the value the Check column compares against, and column D shows a sample solution (steps or code).
A4: # | B4: Task | C4: Answer | D4: Sample solution | E4: Live result | F4: Explanation
A5: B1 | B5: On the Staffing sheet, change B6 to 220. Re-run Solver with two more constraints: B18:B20 = int (integer) and B28 <= D28 (the CNA cap). In Solver Options, set Integer Optimality (%) to 0. What is the minimum monthly staff cost? Round to the nearest dollar. | C5: 112488 | D5: 1. Type 220 in Staffing!B6. 2. Data → Solver. Keep the objective, variable cells, and the three constraints from task 12. 3. Add $B$18:$B$20 int and Add $B$28 <= $D$28. 4. Options → All Methods tab → Integer Optimality (%) = 0 → OK. Check that Ignore Integer Constraints is not ticked. 5. Solve, keep the solution, and read B31. | E5: — | F5: With fractions allowed, the cheapest plan costs $107,302 (6.3 RN, 4.2 LPN, 6.0 CNA). Requiring whole people raises that to $112,488, so hiring whole people costs $5,186 a month more. Solver handles integer constraints by branch and bound, solving many LPs with tighter and tighter bounds. Its default Integer Optimality of 1% lets it stop at any plan within 1% of the best possible, so set it to 0 when the exact answer matters.
A6: B2 | B6: How many RNs does that plan hire? | C6: 7 | D6: Read Staffing!B18 after Solver finishes. | E6: — | F6: 7 RNs out of 11 licensed staff is 63.6%, which meets the 60% rule.
A7: B3 | B7: How many LPNs does that plan hire? | C7: 4 | D7: Read Staffing!B19 after Solver finishes. | E7: — | F7: The fractional plan needs 10.5 licensed FTEs, and 11 whole people already cover that. A tempting shortcut is to round each fractional value up, which gives 7 RN, 5 LPN and 6 CNA. That plan hires one licensed person too many and costs $5,902 a month more. It also breaks the RN rule, because 7 of 12 licensed staff is only 58.3%. Rounding each variable separately can't see how the constraints interact, but Solver's integer search can.
A8: B4 | B8: Test the plan in the P&L. On the Model, first select the Base plan scenario and click Show, so the payer mix and billing fee are back at their base values. Then add two more scenarios that change B8, B10, and B21:B23 (visits per day, APP FTEs, and RN, LPN, and CNA FTEs, in that order): Today (200, 3, 5, 3, 8) and Growth 2026 (220, 4, and the RN, LPN, and CNA counts in Staffing!B18:B20). What operating income does Growth 2026 produce? Round to the nearest dollar. | C8: 2624 | D8: 1. On the Model, open Scenario Manager, select Base plan, and click Show. Close the dialog. 2. Select B8, B10, and B21:B23 (Ctrl-click, or ⌘-click on a Mac). 3. Scenario Manager → Add… Today: 200, 3, 5, 3, 8. 4. Add… Growth 2026: 220, 4, 7, 4, 6. 5. Summary… with result cells B59,B60, or select Growth 2026, click Show, read B59, then Show Today to restore the base case. | E8: — | F8: The growth plan turns a −$8,619 monthly loss into $2,624 (0.5% margin). The new APP costs $10,800 plus benefits, and the larger staff costs $15,690 more a month than today's. The extra 420 visits a month each contribute $96.71, which covers both. Growth 2026 changes only its five cells, so it inherits the payer mix and billing fee already on the Model. If Upside was the last scenario you showed, Growth 2026 would quietly use Upside's mix and fee, which is why you show Base plan first. Using scenarios instead of overwriting inputs also means one click (Show Today) puts the base case back for every other task.
