Workbook
Name SelFacility: Dashboard!$C$4
Name SelMonth: Dashboard!$C$5

Sheet Start Here
B2: Lesson 4.6
B3: Building Interactive Dashboards
B4: Advanced · about 70 minutes · Bluestone Health System (fictional)
B6: What you'll learn
B7: • | C7: Plan a dashboard around audience, questions, and KPIs
B8: • | C8: Build KPI cards and selector-driven formulas
B9: • | C9: Connect slicers to multiple PivotTables and drive charts from selections
B10: • | C10: Polish layout, interactivity, and performance
B12: How to use this workbook
B13: 1. Read the guide | C13: The lesson guide (README) explains each skill with examples: https://github.com/lmansf/learn-excel/tree/main/04-advanced-analysis/06-dashboards
B14: 2. Practice | C14: Go to the 'Practice' sheet. Type a formula or value into each yellow cell.
B15: 3. Check yourself | C15: The Check column shows ✔ Correct (green) or ✘ Not yet (red). Tasks marked 'See key' are checked by comparing with the answer key.
B16: 4. Bonus | C16: Finished? Try the harder 'Bonus' sheet.
B17: 5. Answers | C17: The 'Answer Key' and 'Bonus Key' sheets are hidden. Right-click any sheet tab → Unhide… → pick one → OK. (Try first!)
B18: Note | C18: The Dashboard sheet's yellow selectors are named SelFacility (Dashboard!C4) and SelMonth (Dashboard!C5). They start at Cedar Ridge Medical Center and Nov 2025. Tasks 1–9 and 11 are checked against that selection, so set it back if you've been exploring.
B19: Note | C19: Needs Microsoft 365 or Excel 2021+ for XLOOKUP, LET, and FILTER. The guide shows alternatives for older versions. Form Controls (task 10) need Excel for Windows or Mac, not Excel for the web.
B20: Note | C20: Dashboard Key (hidden) is a finished reference dashboard set to the bonus selection. It's protected without a password so its selectors are the only cells you can change. Review → Unprotect Sheet lets you edit it.
B21: Note | C21: KPI_Monthly leaves readmission, survey, and claims numbers blank for December 2025 on purpose: those numbers aren't final yet.
B23: Color legend
B24: Yellow cell | C24: Your answer goes here.
B25: Gray cell | C25: Pre-filled summary formula — it reads the work you did on another sheet.
B26: ✔ Correct | C26: Your answer matches the key.
B27: ✘ Not yet | C27: Not matching yet — check the hint and try again.
B29: Sheets in this workbook
B30: KPI_Monthly | C30: Data: 72 rows — Excel Table 'tblKPI'
B31: EDWaits | C31: Data: 12,055 rows — Excel Table 'tblEDWaits'
B32: Targets | C32: Data: 7 rows — Excel Table 'tblTargets'
B33: About the data | C33: Monthly KPIs for Bluestone Health's three hospitals, Jan 2024 – Dec 2025 (72 hospital-months), every ED visit's door-to-provider time, and a KPI dictionary with targets and owners.
B34: Disclaimer | C34: All people, places, and numbers are synthetic and fictional. Not clinical guidance.

Sheet Practice
A1: Lesson 4.6 · Practice
A2: The yellow selectors on the Dashboard sheet are named SelFacility (Dashboard!C4) and SelMonth (Dashboard!C5). They start at Cedar Ridge Medical Center and Nov 2025. Write every formula with SelFacility and SelMonth, never typed-in names or dates, and keep that selection while you check your answers. (Change it afterwards and watch your formulas follow.) Tasks 1–9 go in the yellow cells below. Tasks 10–13 have you build on other sheets.
A3: Type a formula or value in each yellow cell. The Check column turns green when your answer matches. Stuck? Read the hint, then the lesson guide. Answers: right-click a sheet tab → Unhide… → 'Answer Key'.
A4: ="Score: "&COUNTIF(E6:E18,"✔*")&" of 13 auto-checked tasks correct"
A5: # | B5: Task | C5: Hint | D5: Your Answer | E5: Check
A6: 1 | B6: Write a formula that returns the number of ED visits for the selected facility and month (the EDVisits column of tblKPI). | C6: SUMIFS with two criteria: Facility = SelFacility and Month = SelMonth | E6: =IF(IFERROR(D6="",FALSE),"",IF(IFERROR(AND(ISNUMBER(D6),OR(ABS(D6-'Answer Key'!$C$5)<=0.0001)),FALSE),"✔ Correct","✘ Not yet"))
A7: 2 | B7: Return the LWBS % (left without being seen) for the selection. Build it from its components, LWBS ÷ EDVisits, instead of reading the LWBSRate column. Enter it as a percentage. | C7: One SUMIFS for the numerator divided by one SUMIFS for the denominator | E7: =IF(IFERROR(D7="",FALSE),"",IF(IFERROR(AND(ISNUMBER(D7),OR(ABS(D7-'Answer Key'!$C$6)<=0.00051,ABS(D7-'Answer Key'!$C$6*100)<=0.051000000000000004)),FALSE),"✔ Correct","✘ Not yet"))
A8: 3 | B8: LWBS variance to target: the selected LWBS % minus the LWBS % target from tblTargets. Look the target up with a formula instead of typing 2%. Enter the result as a percentage. A positive result means the hospital is above (worse than) this lower-is-better target. | C8: XLOOKUP("LWBS %", tblTargets[KPI], tblTargets[Target]) | E8: =IF(IFERROR(D8="",FALSE),"",IF(IFERROR(AND(ISNUMBER(D8),OR(ABS(D8-'Answer Key'!$C$7)<=0.00051,ABS(D8-'Answer Key'!$C$7*100)<=0.051000000000000004)),FALSE),"✔ Correct","✘ Not yet"))
A9: 4 | B9: ED visits change versus the same month last year: this year ÷ last year − 1. Find last year's month with EDATE so the formula works for any selected month. Enter it as a percentage. | C9: EDATE(SelMonth,-12) is the same month one year earlier | E9: =IF(IFERROR(D9="",FALSE),"",IF(IFERROR(AND(ISNUMBER(D9),OR(ABS(D9-'Answer Key'!$C$8)<=0.00051,ABS(D9-'Answer Key'!$C$8*100)<=0.051000000000000004)),FALSE),"✔ Correct","✘ Not yet"))
A10: 5 | B10: Occupancy trend arrow. Compare the selected month's occupancy (PatientDays ÷ BedDays) with the previous month's. Return ▲ with UNICHAR(9650) if it rose, ▼ with UNICHAR(9660) if it fell, or ▬ with UNICHAR(9644) if it didn't change. | C10: LET(cur, …, prev, …, IF(cur>prev, UNICHAR(9650), …)). EDATE(SelMonth,-1) is the previous month | E10: =IF(IFERROR(D10="",FALSE),"",IF(IFERROR(OR(LOWER(TRIM(D10&""))=LOWER(TRIM('Answer Key'!$C$9&""))),FALSE),"✔ Correct","✘ Not yet"))
A11: 6 | B11: Status cell for median door-to-provider: return the text On target or Off target for the selection. Read the target and the Direction of "Median door-to-provider" from tblTargets, so the same pattern works for any KPI. A median isn't additive, so look up the hospital's MedianDTP value instead of adding it up. | C11: LET + XLOOKUP(1, (tblKPI[Facility]=SelFacility)*(tblKPI[Month]=SelMonth), tblKPI[MedianDTP]); then IF on the direction | E11: =IF(IFERROR(D11="",FALSE),"",IF(IFERROR(OR(LOWER(TRIM(D11&""))=LOWER(TRIM('Answer Key'!$C$10&""))),FALSE),"✔ Correct","✘ Not yet"))
A12: 7 | B12: System-wide LWBS % for the selected month: all three hospitals combined, ignoring the facility selector. Divide total LWBS by total ED visits instead of averaging the three hospitals' rates. Enter it as a percentage. | C12: Drop the Facility criterion from both SUMIFS | E12: =IF(IFERROR(D12="",FALSE),"",IF(IFERROR(AND(ISNUMBER(D12),OR(ABS(D12-'Answer Key'!$C$11)<=0.00051,ABS(D12-'Answer Key'!$C$11*100)<=0.051000000000000004)),FALSE),"✔ Correct","✘ Not yet"))
A13: 8 | B13: System-wide median door-to-provider, in minutes, for the selected month. Medians can't be added or averaged across hospitals, so compute it from the visit-level table: the MEDIAN of DoorToProviderMin for every tblEDWaits visit whose ArrivalDateTime falls in the selected month. Keep one decimal place. | C13: MEDIAN(FILTER(…)) with ArrivalDateTime >= SelMonth and < EDATE(SelMonth,1) | E13: =IF(IFERROR(D13="",FALSE),"",IF(IFERROR(AND(ISNUMBER(D13),OR(ABS(D13-'Answer Key'!$C$12)<=0.0051)),FALSE),"✔ Correct","✘ Not yet"))
A14: 9 | B14: Rolling 3-month ED visits for the selected facility: the selected month plus the two months before it (Sep–Nov 2025 for the default selection). Use one SUMIFS with a date window, not OFFSET. | C14: Two criteria on the Month column: ">="&EDATE(SelMonth,-2) and "<="&SelMonth | E14: =IF(IFERROR(D14="",FALSE),"",IF(IFERROR(AND(ISNUMBER(D14),OR(ABS(D14-'Answer Key'!$C$13)<=0.0001)),FALSE),"✔ Correct","✘ Not yet"))
A15: 10 | B15: Insert a Form Controls combo box on the Dashboard. In Format Control, set its Input range to Lists!$A$2:$A$5 and its Cell link to Calc!$C$12. Then choose Ashby Falls Community Hospital in the combo box. The gray cell shows the number your combo box writes to the cell link. | C15: Developer → Insert → Combo Box (Form Control), then right-click it → Format Control → Control tab | D15: {=IF(Calc!C12="","",Calc!C12)} | E15: =IF(IFERROR(D15="",FALSE),"",IF(IFERROR(AND(ISNUMBER(D15),OR(ABS(D15-'Answer Key'!$C$14)<=0.0001)),FALSE),"✔ Correct","✘ Not yet"))
A16: 11 | B16: On the Calc sheet, fill the yellow 12-month trend block. In B17:B28, return the 12 months ending at SelMonth, oldest first (use EDATE). In C17:C28, return ED visits for SelFacility in each of those months. Then select B16:C28, insert a line chart, and move it to the Dashboard. The gray cell totals your block: the trailing-12-month ED visits. | C16: EDATE(SelMonth,-11) is the oldest month. A counter such as ROWS(B$17:B17) lets one formula step forward as you copy it down | D16: {=IF(COUNT(Calc!$C$17:$C$28)=0,"",SUM(Calc!$C$17:$C$28))} | E16: =IF(IFERROR(D16="",FALSE),"",IF(IFERROR(AND(ISNUMBER(D16),OR(ABS(D16-'Answer Key'!$C$15)<=0.0001)),FALSE),"✔ Correct","✘ Not yet"))
A17: 12 | B17: Insert a new sheet named Pivots. Build PivotTable 1 from tblKPI with Month in Rows and Sum of EDVisits in Values. Insert a Facility slicer and a Month timeline for it. Select Ashby Falls Community Hospital in the slicer, and select 2025 Q3 in the timeline (switch it to QUARTERS). What is PivotTable 1's grand total? | C17: PivotTable Analyze → Insert Slicer, and PivotTable Analyze → Insert Timeline | E17: =IF(IFERROR(D17="",FALSE),"",IF(IFERROR(AND(ISNUMBER(D17),OR(ABS(D17-'Answer Key'!$C$16)<=0.0001)),FALSE),"✔ Correct","✘ Not yet"))
A18: 13 | B18: On the Pivots sheet, build PivotTable 2 from tblKPI with Facility in Rows, plus Sum of LWBS and Sum of EDVisits in Values. Connect the slicer and the timeline to it (Report Connections). Then add a calculated field LWBSPct = LWBS / EDVisits. With Ashby Falls and 2025 Q3 still selected, what LWBS % does PivotTable 2 show? Enter it as a percentage. | C18: Select the slicer → Slicer → Report Connections. Then PivotTable Analyze → Fields, Items & Sets → Calculated Field | E18: =IF(IFERROR(D18="",FALSE),"",IF(IFERROR(AND(ISNUMBER(D18),OR(ABS(D18-'Answer Key'!$C$17)<=0.00051,ABS(D18-'Answer Key'!$C$17*100)<=0.051000000000000004)),FALSE),"✔ Correct","✘ Not yet"))

Sheet Dashboard
B1: Hospital Operations Dashboard · practice canvas
B2: Change the yellow selectors. Every number on this sheet, and your Practice formulas, should follow them.
B4: Facility (named SelFacility) | C4: Cedar Ridge Medical Center
B5: Month (named SelMonth) | C5: 45962
B7: INPATIENT DISCHARGES · example card | E7: ← A finished card. Click each cell and read its formula in the formula bar.
B8: =SUMIFS(tblKPI[IPDischarges],tblKPI[Facility],SelFacility,tblKPI[Month],SelMonth) | E8: Big number: SUMIFS on the selectors. Context: the same month last year (EDATE(SelMonth,-12)).
B9: Same month last year | C9: =SUMIFS(tblKPI[IPDischarges],tblKPI[Facility],SelFacility,tblKPI[Month],EDATE(SelMonth,-12)) | E9: The ▲/▼ comes from a custom number format, "▲ "0.0%;"▼ "0.0%;"▬ "0.0%, so the cell is still a number.
B10: Change vs last year | C10: =IFERROR(B8/C9-1,"n/a") | E10: It isn't colored: more discharges are neither good nor bad, so color would mislead.
B13: ▸ Task 10: put your combo box here.
B15: ▸ Task 11: paste your 12-month trend chart here (it reads Calc!B16:C28).

Sheet Calc
B1: Calc · the model layer
B2: Formulas here turn the selectors into the numbers the Dashboard shows. Viewers never need to see this sheet, so a finished dashboard usually hides it.
B4: Selection (read from the Dashboard)
B5: Facility | C5: =SelFacility
B6: Month | C6: =SelMonth
B7: Prior month | C7: =EDATE(SelMonth,-1)
B8: Same month last year | C8: =EDATE(SelMonth,-12)
B9: Facility criterion for SUMIFS | C9: =IF(SelFacility="All facilities","*",SelFacility) | E9: Turns "All facilities" into the wildcard *, which SUMIFS matches to every hospital.
B11: Form control (task 10)
B12: Combo box cell link | E12: Your combo box writes the position of the chosen item here (1 = first item in the list).
B13: Facility picked in the combo box | C13: =IF(C12="","",INDEX(Lists!$A$2:$A$5,C12)) | E13: INDEX turns the position back into the facility name.
B15: 12-month trend for the chart (task 11)
C16: ED visits | E16: B16 stays blank on purpose: with an empty corner cell, Excel uses column B as the chart's axis.
E17: B: the 12 months ending at SelMonth, oldest first. C: ED visits for SelFacility in each month.

Sheet KPI_Monthly
A1: KPI_Monthly · one row per hospital per month, January 2024 – December 2025
A2: Count and day columns are additive: SUMIFS them across hospitals and months. Rate and median columns are not: rebuild a rate from its two components, and compute a roll-up median from EDWaits.
A3: Readmission, survey, and claims columns are blank for December 2025 because those numbers aren't final yet (the 30-day window is still open, surveys are still arriving, and most claims are pending).
A5: Month | B5: Facility | C5: EDVisits | D5: LWBS | E5: LWBSRate | F5: MedianDTP | G5: IPDischarges | H5: LOSDays | I5: ALOS | J5: IndexStays | K5: Readmits | L5: ReadmitRate | M5: PatientDays | N5: BedDays | O5: Occupancy | P5: Surveys | Q5: TopBox | R5: TopBoxRate | S5: ClaimsAdjudicated | T5: ClaimsDenied | U5: DenialRate
A6: 45292 | B6: Bluestone Memorial Hospital | C6: 405 | D6: 12 | E6: 0.02962963 | F6: 37 | G6: 172 | H6: 748.77 | I6: 4.353314 | J6: 168 | K6: 19 | L6: 0.11309524 | M6: 5661 | N6: 6820 | O6: 0.83005865 | P6: 47 | Q6: 18 | R6: 0.38297872 | S6: 448 | T6: 54 | U6: 0.12053571
A7: 45292 | B7: Ashby Falls Community Hospital | C7: 85 | D7: 2 | E7: 0.023529412 | F7: 45 | G7: 26 | H7: 107.21 | I7: 4.1234615 | J7: 25 | K7: 2 | L7: 0.08 | M7: 1224 | N7: 1426 | O7: 0.85834502 | P7: 12 | Q7: 4 | R7: 0.33333333 | S7: 91 | T7: 13 | U7: 0.14285714
A8: 45292 | B8: Cedar Ridge Medical Center | C8: 90 | D8: 1 | E8: 0.011111111 | F8: 45 | G8: 35 | H8: 164.75 | I8: 4.7071429 | J8: 33 | K8: 4 | L8: 0.12121212 | M8: 1920 | N8: 2232 | O8: 0.86021505 | P8: 12 | Q8: 6 | R8: 0.5 | S8: 94 | T8: 9 | U8: 0.095744681
A9: 45323 | B9: Bluestone Memorial Hospital | C9: 408 | D9: 16 | E9: 0.039215686 | F9: 42.5 | G9: 149 | H9: 676.82 | I9: 4.5424161 | J9: 145 | K9: 22 | L9: 0.15172414 | M9: 5244 | N9: 6380 | O9: 0.82194357 | P9: 58 | Q9: 25 | R9: 0.43103448 | S9: 442 | T9: 46 | U9: 0.1040724
A10: 45323 | B10: Ashby Falls Community Hospital | C10: 85 | D10: 0 | E10: 0 | F10: 47 | G10: 38 | H10: 213.03 | I10: 5.6060526 | J10: 37 | K10: 6 | L10: 0.16216216 | M10: 1055 | N10: 1334 | O10: 0.79085457 | P10: 11 | Q10: 5 | R10: 0.45454545 | S10: 94 | T10: 9 | U10: 0.095744681
A11: 45323 | B11: Cedar Ridge Medical Center | C11: 93 | D11: 5 | E11: 0.053763441 | F11: 41.5 | G11: 41 | H11: 182.26 | I11: 4.4453659 | J11: 40 | K11: 9 | L11: 0.225 | M11: 1806 | N11: 2088 | O11: 0.86494253 | P11: 17 | Q11: 10 | R11: 0.58823529 | S11: 101 | T11: 12 | U11: 0.11881188
A12: 45352 | B12: Bluestone Memorial Hospital | C12: 411 | D12: 9 | E12: 0.02189781 | F12: 37 | G12: 198 | H12: 896.17 | I12: 4.5261111 | J12: 196 | K12: 25 | L12: 0.12755102 | M12: 5498 | N12: 6820 | O12: 0.80615836 | P12: 76 | Q12: 26 | R12: 0.34210526 | S12: 479 | T12: 49 | U12: 0.10229645
A13: 45352 | B13: Ashby Falls Community Hospital | C13: 69 | D13: 1 | E13: 0.014492754 | F13: 38.5 | G13: 25 | H13: 91.48 | I13: 3.6592 | J13: 25 | K13: 2 | L13: 0.08 | M13: 1083 | N13: 1426 | O13: 0.75946704 | P13: 13 | Q13: 4 | R13: 0.30769231 | S13: 72 | T13: 7 | U13: 0.097222222
A14: 45352 | B14: Cedar Ridge Medical Center | C14: 99 | D14: 4 | E14: 0.04040404 | F14: 37 | G14: 33 | H14: 131.54 | I14: 3.9860606 | J14: 32 | K14: 6 | L14: 0.1875 | M14: 1785 | N14: 2232 | O14: 0.79973118 | P14: 15 | Q14: 8 | R14: 0.53333333 | S14: 111 | T14: 14 | U14: 0.12612613
A15: 45383 | B15: Bluestone Memorial Hospital | C15: 340 | D15: 8 | E15: 0.023529412 | F15: 40 | G15: 143 | H15: 652.34 | I15: 4.5618182 | J15: 140 | K15: 18 | L15: 0.12857143 | M15: 5150 | N15: 6600 | O15: 0.78030303 | P15: 47 | Q15: 21 | R15: 0.44680851 | S15: 372 | T15: 38 | U15: 0.10215054
A16: 45383 | B16: Ashby Falls Community Hospital | C16: 56 | D16: 0 | E16: 0 | F16: 39.5 | G16: 23 | H16: 112.97 | I16: 4.9117391 | J16: 23 | K16: 1 | L16: 0.043478261 | M16: 1026 | N16: 1380 | O16: 0.74347826 | P16: 10 | Q16: 5 | R16: 0.5 | S16: 66 | T16: 11 | U16: 0.16666667
A17: 45383 | B17: Cedar Ridge Medical Center | C17: 70 | D17: 2 | E17: 0.028571429 | F17: 42 | G17: 34 | H17: 156.03 | I17: 4.5891176 | J17: 33 | K17: 3 | L17: 0.090909091 | M17: 1681 | N17: 2160 | O17: 0.77824074 | P17: 17 | Q17: 9 | R17: 0.52941176 | S17: 79 | T17: 8 | U17: 0.10126582
... A74: 45962 | B74: Cedar Ridge Medical Center | C74: 80 | D74: 3 | E74: 0.0375 | F74: 31 | G74: 30 | H74: 117.45 | I74: 3.915 | J74: 30 | K74: 3 | L74: 0.1 | M74: 1829 | N74: 2160 | O74: 0.84675926 | P74: 12 | Q74: 8 | R74: 0.66666667 | S74: 73 | T74: 13 | U74: 0.17808219
A75: 45992 | B75: Bluestone Memorial Hospital | C75: 423 | D75: 11 | E75: 0.026004728 | F75: 43.5 | G75: 232 | H75: 1123.56 | I75: 4.842931 | M75: 5762 | N75: 6820 | O75: 0.84486804
A76: 45992 | B76: Ashby Falls Community Hospital | C76: 79 | D76: 7 | E76: 0.088607595 | F76: 46 | G76: 44 | H76: 209.96 | I76: 4.7718182 | M76: 1184 | N76: 1426 | O76: 0.83029453
A77: 45992 | B77: Cedar Ridge Medical Center | C77: 93 | D77: 1 | E77: 0.010752688 | F77: 44 | G77: 34 | H77: 161.29 | I77: 4.7438235 | M77: 1913 | N77: 2232 | O77: 0.85707885

Sheet EDWaits
A1: EDWaits · every 2024–2025 ED visit that was seen by a provider
A2: DoorToProviderMin = minutes from arrival to first provider contact. Visits that left without being seen (LWBS) have no provider time, so they aren't listed. Use this table for medians across hospitals or months.
A4: EDVisitID | B4: ArrivalDateTime | C4: Facility | D4: DoorToProviderMin
A5: ED200001 | B5: 45292.082 | C5: Bluestone Memorial Hospital | D5: 16
A6: ED200002 | B6: 45292.122 | C6: Bluestone Memorial Hospital | D6: 95
A7: ED200003 | B7: 45292.167 | C7: Bluestone Memorial Hospital | D7: 21
A8: ED200004 | B8: 45292.349 | C8: Bluestone Memorial Hospital | D8: 48
A9: ED200005 | B9: 45292.419 | C9: Bluestone Memorial Hospital | D9: 26
A10: ED200006 | B10: 45292.435 | C10: Bluestone Memorial Hospital | D10: 25
A11: ED200008 | B11: 45292.471 | C11: Cedar Ridge Medical Center | D11: 52
A12: ED200009 | B12: 45292.476 | C12: Bluestone Memorial Hospital | D12: 68
A13: ED200010 | B13: 45292.565 | C13: Bluestone Memorial Hospital | D13: 54
A14: ED200011 | B14: 45292.586 | C14: Bluestone Memorial Hospital | D14: 18
A15: ED200012 | B15: 45292.603 | C15: Ashby Falls Community Hospital | D15: 96
A16: ED200013 | B16: 45292.615 | C16: Cedar Ridge Medical Center | D16: 47
... A12059: ED212292 | B12059: 46022.747 | C12059: Bluestone Memorial Hospital | D12059: 133

Sheet Targets
A1: Targets · the KPI dictionary: what each KPI answers, how it's calculated, which way is good, the target, and who owns it
A2: On target means at or below a 'Lower is better' target, or at or above a 'Higher is better' target.
A3: KPI | B3: Unit | C3: Question | D3: Definition | E3: Direction | F3: Target | G3: Owner
A4: LWBS % | B4: % | C4: Are ED patients leaving before a provider sees them? | D4: LWBS ÷ EDVisits. ED arrivals by arrival month. | E4: Lower is better | F4: 0.02 | G4: ED Medical Director
A5: Median door-to-provider | B5: minutes | C5: How long do ED patients wait to see a provider? | D5: Median minutes from arrival to first provider contact, over patients seen by a provider. Medians can't be added or averaged across hospitals: compute roll-ups from EDWaits. | E5: Lower is better | F5: 30 | G5: ED Nurse Director
A6: ALOS | B6: days | C6: Are inpatients staying longer than they need to? | D6: LOSDays ÷ IPDischarges. Inpatient stays by discharge month. | E6: Lower is better | F6: 4.5 | G6: Director of Case Management
A7: 30-day readmission rate | B7: % | C7: Are discharged patients coming back within 30 days? | D7: Readmits ÷ IndexStays. Inpatient discharges by month, excluding deaths. Blank for Dec 2025 (window still open). | E7: Lower is better | F7: 0.15 | G7: Chief Quality Officer
A8: Occupancy % | B8: % | C8: Will we have a bed for the next admission? | D8: PatientDays ÷ BedDays over inpatient and critical care units. Above the ceiling leaves too little surge room. | E8: Lower is better | F8: 0.85 | G8: Chief Nursing Officer
A9: HCAHPS top-box % | B9: % | C9: Would patients rate their stay 9 or 10 out of 10? | D9: TopBox ÷ Surveys. Surveys by discharge month. Blank for Dec 2025 (most surveys not returned yet). | E9: Higher is better | F9: 0.5 | G9: Director of Patient Experience
A10: Denial rate | B10: % | C10: Are payers refusing our claims? | D10: ClaimsDenied ÷ ClaimsAdjudicated (Denied or Appealed ÷ every claim except Pending), by service month. Blank for Dec 2025 (most claims still pending). | E10: Lower is better | F10: 0.1 | G10: Revenue Cycle Director

Sheet Lists
A1: Facility list | C1: Month list | E1: Dropdown sources. The Dashboard's selectors use Data Validation lists that point here:
A2: All facilities | C2: 45292 | E2: Facility: =Lists!$A$2:$A$5 Month: =Lists!$C$2:$C$25
A3: Bluestone Memorial Hospital | C3: 45323 | E3: The month cells hold real dates (the first of each month) formatted as mmm yyyy, so the dropdown shows 'Nov 2025' but the selector stores a date that SUMIFS can match.
A4: Ashby Falls Community Hospital | C4: 45352
A5: Cedar Ridge Medical Center | C5: 45383
C6: 45413
C7: 45444
C8: 45474
C9: 45505
C10: 45536
C11: 45566
C12: 45597
C13: 45627
C14: 45658
C15: 45689
C16: 45717
C17: 45748
... C25: 45992

Sheet Board
B1: Board dashboard (bonus)
B2: Build the one-page board dashboard here. The Bonus sheet has the full spec. A layout that works:
B3: Rows 1–2: title and a dynamic subtitle (facility · month). Rows 4–5: the two dropdowns (name them BoardFacility and BoardMonth).
B4: Rows 7–17: two rows of four cards. Rows 19–33: the trend chart. Columns N onward: your model cells (helpers, the KPI table, the 12-month block).
B5: Delete these notes when you're done, then hide gridlines and headings, unlock the dropdowns, protect the sheet, and set it to print on one landscape page.

Sheet Bonus
A1: Lesson 4.6 · Bonus: The board's one-page operations dashboard
A2: Each month the COO presents one page to the board's Quality & Operations Committee. It must answer three questions at a glance: Are we on target? Where are we missing? Which way are things heading? Build it on the Board sheet to this spec: 1. Facility and Month dropdowns fed by the Lists sheet, named BoardFacility and BoardMonth. Facility must allow All facilities. 2. One card for each of the seven KPIs in tblTargets, showing the value, the target, a status colored by conditional formatting, and an arrow versus the same month last year. Every card must work for All facilities, so rebuild rates from their components and compute the median door-to-provider from tblEDWaits. 3. A scorecard line that counts the KPIs on target, such as '6 of 7 KPIs on target'. 4. A 12-month LWBS % trend block and a line chart that follow both dropdowns. 5. Polish: gridlines and headings off, only the two dropdowns unlocked, the sheet protected, and one landscape page when printed. The hidden Dashboard Key sheet is a finished reference build. Compare your numbers with it when you're done.
A3: Type a formula or value in each yellow cell. The Check column turns green when your answer matches. Stuck? Read the hint, then the lesson guide. Answers: right-click a sheet tab → Unhide… → 'Bonus Key'.
A4: ="Score: "&COUNTIF(E6:E9,"✔*")&" of 4 auto-checked tasks correct"
A5: # | B5: Task | C5: Hint | D5: Your Answer | E5: Check
A6: B1 | B6: Set your Board dashboard to All facilities and Oct 2025. What is the system-wide 30-day readmission rate? Enter it as a percentage. | C6: Swap "All facilities" for the asterisk wildcard in the Facility criterion | E6: =IF(IFERROR(D6="",FALSE),"",IF(IFERROR(AND(ISNUMBER(D6),OR(ABS(D6-'Bonus Key'!$C$5)<=0.00051,ABS(D6-'Bonus Key'!$C$5*100)<=0.051000000000000004)),FALSE),"✔ Correct","✘ Not yet"))
A7: B2 | B7: With All facilities and Oct 2025 still selected, how many of the seven KPIs are on target? Use the Targets sheet's rule: on target means at or below a lower-is-better target, or at or above a higher-is-better one, so a value exactly equal to its target counts as on target. | C7: Give each card a status cell that returns 1 or 0, then SUM them. Remember which KPIs are higher-is-better | E7: =IF(IFERROR(D7="",FALSE),"",IF(IFERROR(AND(ISNUMBER(D7),OR(ABS(D7-'Bonus Key'!$C$6)<=0.0001)),FALSE),"✔ Correct","✘ Not yet"))
A8: B3 | B8: Keep Oct 2025 and switch the Facility dropdown to each hospital in turn. Which hospital has the fewest KPIs on target? | C8: Your scorecard line answers this. Change only the Facility dropdown | E8: =IF(IFERROR(D8="",FALSE),"",IF(IFERROR(OR(LOWER(TRIM(D8&""))=LOWER(TRIM('Bonus Key'!$C$7&"")),LOWER(TRIM(D8&""))="bluestone memorial"),FALSE),"✔ Correct","✘ Not yet"))
A9: B4 | B9: Back on All facilities and Oct 2025, your 12-month LWBS % trend runs Nov 2024–Oct 2025. In which month was the system-wide LWBS % highest? Enter the first day of that month as a date. | C9: INDEX(months, MATCH(MAX(rates), rates, 0)) on your trend block, or just read the chart's peak | E9: =IF(IFERROR(D9="",FALSE),"",IF(IFERROR(AND(ISNUMBER(D9),INT(D9)=INT('Bonus Key'!$C$8)),FALSE),"✔ Correct","✘ Not yet"))

Sheet Answer Key
A1: 🔑 Answer Key — Lesson 4.6
A2: Spoiler alert — try every task before reading this sheet. Column C is the value the Check column compares against. Column D is a sample solution; column E is that same formula, live, proving it works.
A4: # | B4: Task | C4: Answer | D4: Sample solution | E4: Live result | F4: Explanation
A5: 1 | B5: Write a formula that returns the number of ED visits for the selected facility and month (the EDVisits column of tblKPI). | C5: 80 | D5: =SUMIFS(tblKPI[EDVisits],tblKPI[Facility],SelFacility,tblKPI[Month],SelMonth) | E5: {=SUMIFS(tblKPI[EDVisits],tblKPI[Facility],SelFacility,tblKPI[Month],SelMonth)} | F5: tblKPI has exactly one row per hospital per month, so SUMIFS with both criteria returns that row's value. SUMIFS is the workhorse of selector-driven dashboards. It never returns #N/A, it adds up correctly when a criterion matches several rows (a quarter, or every hospital), and it recalculates the moment a selector changes. Because the criteria are the named cells, choosing a different facility on the Dashboard updates this number without anyone touching the formula.
A6: 2 | B6: Return the LWBS % (left without being seen) for the selection. Build it from its components, LWBS ÷ EDVisits, instead of reading the LWBSRate column. Enter it as a percentage. | C6: 0.0375 | D6: =SUMIFS(tblKPI[LWBS],tblKPI[Facility],SelFacility,tblKPI[Month],SelMonth)/SUMIFS(tblKPI[EDVisits],tblKPI[Facility],SelFacility,tblKPI[Month],SelMonth) | E6: {=SUMIFS(tblKPI[LWBS],tblKPI[Facility],SelFacility,tblKPI[Month],SelMonth)/SUMIFS(tblKPI[EDVisits],tblKPI[Facility],SelFacility,tblKPI[Month],SelMonth)} | F6: 3 of 80 patients left before a provider saw them. For one hospital-month this matches the LWBSRate column. The components version is still the better habit, because the same formula keeps working when the selection covers several rows (a quarter, or all hospitals). There, SUMIFS on LWBSRate would add percentages together, which is meaningless.
A7: 3 | B7: LWBS variance to target: the selected LWBS % minus the LWBS % target from tblTargets. Look the target up with a formula instead of typing 2%. Enter the result as a percentage. A positive result means the hospital is above (worse than) this lower-is-better target. | C7: 0.0175 | D7: =SUMIFS(tblKPI[LWBS],tblKPI[Facility],SelFacility,tblKPI[Month],SelMonth)/SUMIFS(tblKPI[EDVisits],tblKPI[Facility],SelFacility,tblKPI[Month],SelMonth)-XLOOKUP("LWBS %",tblTargets[KPI],tblTargets[Target]) | E7: {=SUMIFS(tblKPI[LWBS],tblKPI[Facility],SelFacility,tblKPI[Month],SelMonth)/SUMIFS(tblKPI[EDVisits],tblKPI[Facility],SelFacility,tblKPI[Month],SelMonth)-_xlfn.XLOOKUP("LWBS %",tblTargets[KPI],tblTargets[Target])} | F7: 3.75% − 2.00% = +1.75%. Strictly, that's +1.75 percentage points: the gap between two rates. (The relative variance, actual ÷ target − 1, would be +87.5%.) Keeping targets in a table and looking them up means one edit to tblTargets updates every card that uses the target. On a real card this cell would subtract the target cell from the value cell.
A8: 4 | B8: ED visits change versus the same month last year: this year ÷ last year − 1. Find last year's month with EDATE so the formula works for any selected month. Enter it as a percentage. | C8: -0.069767442 | D8: =SUMIFS(tblKPI[EDVisits],tblKPI[Facility],SelFacility,tblKPI[Month],SelMonth)/SUMIFS(tblKPI[EDVisits],tblKPI[Facility],SelFacility,tblKPI[Month],EDATE(SelMonth,-12))-1 | E8: {=SUMIFS(tblKPI[EDVisits],tblKPI[Facility],SelFacility,tblKPI[Month],SelMonth)/SUMIFS(tblKPI[EDVisits],tblKPI[Facility],SelFacility,tblKPI[Month],EDATE(SelMonth,-12))-1} | F8: 80 visits this year against 86 in Nov 2024. Comparing with the same month last year removes seasonality, which a month-over-month change can't do: an ED's November differs from its October for seasonal reasons alone. EDATE moves a date by whole months and keeps it on the first of the month, so it matches the Month column for every selection. Subtracting 365 days happens to work for Nov 2025, but it lands a day late whenever a February 29 falls in between: 1/1/2025 − 365 days is 1/2/2024, which matches no row, while EDATE returns 1/1/2024.
A9: 5 | B9: Occupancy trend arrow. Compare the selected month's occupancy (PatientDays ÷ BedDays) with the previous month's. Return ▲ with UNICHAR(9650) if it rose, ▼ with UNICHAR(9660) if it fell, or ▬ with UNICHAR(9644) if it didn't change. | C9: ▲ | D9: =LET(cur,SUMIFS(tblKPI[PatientDays],tblKPI[Facility],SelFacility,tblKPI[Month],SelMonth)/SUMIFS(tblKPI[BedDays],tblKPI[Facility],SelFacility,tblKPI[Month],SelMonth),prev,SUMIFS(tblKPI[PatientDays],tblKPI[Facility],SelFacility,tblKPI[Month],EDATE(SelMonth,-1))/SUMIFS(tblKPI[BedDays],tblKPI[Facility],SelFacility,tblKPI[Month],EDATE(SelMonth,-1)),IF(cur>prev,UNICHAR(9650),IF(cur<prev,UNICHAR(9660),UNICHAR(9644)))) | E9: {=_xlfn.LET(_xlpm.cur,SUMIFS(tblKPI[PatientDays],tblKPI[Facility],SelFacility,tblKPI[Month],SelMonth)/SUMIFS(tblKPI[BedDays],tblKPI[Facility],SelFacility,tblKPI[Month],SelMonth),_xlpm.prev,SUMIFS(tblKPI[PatientDays],tblKPI[Facility],SelFacility,tblKPI[Month],EDATE(SelMonth,-1))/SUMIFS(tblKPI[BedDays],tblKPI[Facility],SelFacility,tblKPI[Month],EDATE(SelMonth,-1)),IF(_xlpm.cur>_xlpm.prev,_xlfn.UNICHAR(9650),IF(_xlpm.cur<_xlpm.prev,_xlfn.UNICHAR(9660),_xlfn.UNICHAR(9644))))} | F9: Occupancy went from 81.5% in Oct 2025 to 84.7%. LET names the two rates once, so the IF reads like a sentence instead of repeating four SUMIFS. A formula-made arrow is ordinary text, so you can color it with conditional formatting. On a dashboard, rising occupancy deserves amber or red as it approaches the ceiling, even though the arrow itself only says which way it moved.
A10: 6 | B10: Status cell for median door-to-provider: return the text On target or Off target for the selection. Read the target and the Direction of "Median door-to-provider" from tblTargets, so the same pattern works for any KPI. A median isn't additive, so look up the hospital's MedianDTP value instead of adding it up. | C10: Off target | D10: =LET(val,XLOOKUP(1,(tblKPI[Facility]=SelFacility)*(tblKPI[Month]=SelMonth),tblKPI[MedianDTP]),tgt,XLOOKUP("Median door-to-provider",tblTargets[KPI],tblTargets[Target]),dir,XLOOKUP("Median door-to-provider",tblTargets[KPI],tblTargets[Direction]),IF(IF(dir="Lower is better",val<=tgt,val>=tgt),"On target","Off target")) | E10: {=_xlfn.LET(_xlpm.val,_xlfn.XLOOKUP(1,(tblKPI[Facility]=SelFacility)*(tblKPI[Month]=SelMonth),tblKPI[MedianDTP]),_xlpm.tgt,_xlfn.XLOOKUP("Median door-to-provider",tblTargets[KPI],tblTargets[Target]),_xlpm.dir,_xlfn.XLOOKUP("Median door-to-provider",tblTargets[KPI],tblTargets[Direction]),IF(IF(_xlpm.dir="Lower is better",_xlpm.val<=_xlpm.tgt,_xlpm.val>=_xlpm.tgt),"On target","Off target"))} | F10: The median is 31.0 minutes against a target of 30 or less, so it's off target, even if only barely. XLOOKUP(1, (condition)*(condition), …) finds the one row where both conditions are TRUE (TRUE×TRUE = 1). The inner IF flips the comparison by direction: lower-is-better KPIs pass at or below the target, and higher-is-better KPIs pass at or above it. Binary statuses hide near misses like this one, which is why many dashboards add an amber band (for example, within 10% of target).
A11: 7 | B11: System-wide LWBS % for the selected month: all three hospitals combined, ignoring the facility selector. Divide total LWBS by total ED visits instead of averaging the three hospitals' rates. Enter it as a percentage. | C11: 0.01532567 | D11: =SUMIFS(tblKPI[LWBS],tblKPI[Month],SelMonth)/SUMIFS(tblKPI[EDVisits],tblKPI[Month],SelMonth) | E11: {=SUMIFS(tblKPI[LWBS],tblKPI[Month],SelMonth)/SUMIFS(tblKPI[EDVisits],tblKPI[Month],SelMonth)} | F11: 8 ÷ 522 = 1.53%. Averaging the three hospital rates gives 1.71%, because a simple average gives the small hospitals the same weight as Bluestone Memorial, which sees several times as many patients. Rates roll up as total numerator ÷ total denominator. That's why tblKPI stores the components.
A12: 8 | B12: System-wide median door-to-provider, in minutes, for the selected month. Medians can't be added or averaged across hospitals, so compute it from the visit-level table: the MEDIAN of DoorToProviderMin for every tblEDWaits visit whose ArrivalDateTime falls in the selected month. Keep one decimal place. | C12: 33.5 | D12: =MEDIAN(FILTER(tblEDWaits[DoorToProviderMin],(tblEDWaits[ArrivalDateTime]>=SelMonth)*(tblEDWaits[ArrivalDateTime]<EDATE(SelMonth,1)))) | E12: {=MEDIAN(_xlfn._xlws.FILTER(tblEDWaits[DoorToProviderMin],(tblEDWaits[ArrivalDateTime]>=SelMonth)*(tblEDWaits[ArrivalDateTime]<EDATE(SelMonth,1))))} | F12: The true system median is 33.5 minutes. Averaging the three hospital medians gives 34.5, which is not the median of anything. A median depends on every individual value, so it can only be computed from the detail rows. The date test uses a half-open window (>= first day, < first day of next month), which catches every arrival time on the last day of the month. In Excel 2019 or earlier, use =AGGREGATE(17,6,values/(condition),2) instead, where function 17 is QUARTILE.INC and quartile 2 is the median.
A13: 9 | B13: Rolling 3-month ED visits for the selected facility: the selected month plus the two months before it (Sep–Nov 2025 for the default selection). Use one SUMIFS with a date window, not OFFSET. | C13: 221 | D13: =SUMIFS(tblKPI[EDVisits],tblKPI[Facility],SelFacility,tblKPI[Month],">="&EDATE(SelMonth,-2),tblKPI[Month],"<="&SelMonth) | E13: {=SUMIFS(tblKPI[EDVisits],tblKPI[Facility],SelFacility,tblKPI[Month],">="&EDATE(SelMonth,-2),tblKPI[Month],"<="&SelMonth)} | F13: Joining an operator to a date (">="&EDATE(SelMonth,-2)) turns the date into criteria text that SUMIFS understands. A common older pattern is SUM(OFFSET(…)). OFFSET is volatile, so Excel recalculates it after every edit anywhere in the workbook, and dozens of them make a dashboard sluggish. SUMIFS recalculates only when its inputs change, and it doesn't depend on the table being sorted.
A14: 10 | B14: Insert a Form Controls combo box on the Dashboard. In Format Control, set its Input range to Lists!$A$2:$A$5 and its Cell link to Calc!$C$12. Then choose Ashby Falls Community Hospital in the combo box. The gray cell shows the number your combo box writes to the cell link. | C14: 3 | D14: 1. Show the Developer tab if you haven't (see the guide). 2. Developer → Insert → Combo Box (Form Control) (Mac: Developer → Combo Box), then drag a box onto the Dashboard. 3. Right-click the combo box → Format Control → Control tab. Input range: Lists!$A$2:$A$5. Cell link: Calc!$C$12. Drop down lines: 4. Click OK. 4. Click a cell to deselect the control, then choose Ashby Falls Community Hospital. Calc!C13 turns the number back into a name: =INDEX(Lists!$A$2:$A$5,Calc!C12). | E14: {=MATCH("Ashby Falls Community Hospital",Lists!$A$2:$A$5,0)} | F14: A combo box writes the position of the chosen item, not its text: Ashby Falls Community Hospital is item 3 of the input range. INDEX(list, position) converts it back, which Calc!C13 does. To make the combo box drive the whole dashboard, point your formulas (or the SelFacility name) at that INDEX cell. A combo box floats above the grid, so it can't be typed over by accident, but it doesn't work in Excel for the web, and the position-number link breaks if someone re-sorts the list.
A15: 11 | B15: On the Calc sheet, fill the yellow 12-month trend block. In B17:B28, return the 12 months ending at SelMonth, oldest first (use EDATE). In C17:C28, return ED visits for SelFacility in each of those months. Then select B16:C28, insert a line chart, and move it to the Dashboard. The gray cell totals your block: the trailing-12-month ED visits. | C15: 924 | D15: 1. In Calc!B17 type =EDATE(SelMonth,ROWS(B$17:B17)-12) and copy it down to B28. The first row gives EDATE(SelMonth,-11) and the last gives SelMonth itself. 2. In C17 type =SUMIFS(tblKPI[EDVisits],tblKPI[Facility],SelFacility,tblKPI[Month],B17) and copy it down. 3. Select B16:C28 → Insert → Charts → Line. The corner cell B16 is blank on purpose, so Excel uses the months as the axis. 4. Cut the chart (Ctrl + X, Mac: ⌘ + X), click a cell on the Dashboard, and paste. The chart keeps pointing at Calc. 5. Change the selectors on the Dashboard and watch the line redraw. | E15: {=SUMIFS(tblKPI[EDVisits],tblKPI[Facility],SelFacility,tblKPI[Month],">="&EDATE(SelMonth,-11),tblKPI[Month],"<="&SelMonth)} | F15: The chart's series points at formula cells, and those cells point at the selectors, so one dropdown redraws the chart. The block for Cedar Ridge Medical Center runs Dec 2024–Nov 2025 and peaks at 87 visits in Feb 2025. In Microsoft 365 you can instead spill the months with =EDATE(SelMonth,SEQUENCE(12,1,-11)). A chart built from a spill keeps a fixed range, so if a spill can change size, chart it through a defined name that refers to it (for example =Calc!$B$17#). If you pick an early month, the window reaches back before January 2024 and SUMIFS returns 0. Wrapping it as IF(COUNTIFS(…)=0,NA(),SUMIFS(…)) makes the line chart leave a gap instead of plunging to zero.
A16: 12 | B16: Insert a new sheet named Pivots. Build PivotTable 1 from tblKPI with Month in Rows and Sum of EDVisits in Values. Insert a Facility slicer and a Month timeline for it. Select Ashby Falls Community Hospital in the slicer, and select 2025 Q3 in the timeline (switch it to QUARTERS). What is PivotTable 1's grand total? | C16: 185 | D16: 1. Click in tblKPI → Insert → PivotTable → New Worksheet → OK. Rename the sheet Pivots. 2. Drag Month to Rows and EDVisits to Values (Sum of EDVisits). Excel may group the dates into Years and Quarters. That's fine. 3. PivotTable Analyze → Insert Slicer → tick Facility → OK. Click Ashby Falls Community Hospital. 4. PivotTable Analyze → Insert Timeline → tick Month → OK. Set the time level to QUARTERS and click 2025 Q3. 5. Read the Grand Total. Formula twin: =SUMIFS(tblKPI[EDVisits],tblKPI[Facility],"Ashby Falls Community Hospital",tblKPI[Month],">="&DATE(2025,7,1),tblKPI[Month],"<="&DATE(2025,9,1)) | E16: {=SUMIFS(tblKPI[EDVisits],tblKPI[Facility],"Ashby Falls Community Hospital",tblKPI[Month],">="&DATE(2025,7,1),tblKPI[Month],"<="&DATE(2025,9,1))} | F16: A slicer is a selector made of buttons, and a timeline is a selector for dates. Both filter the pivot they were inserted from. Visible selections are what make pivots dashboard-friendly: a Filters-area dropdown hides what's selected, but a slicer shows it. The formula twin proves the number: ED visits at Ashby Falls in July, August, and September 2025.
A17: 13 | B17: On the Pivots sheet, build PivotTable 2 from tblKPI with Facility in Rows, plus Sum of LWBS and Sum of EDVisits in Values. Connect the slicer and the timeline to it (Report Connections). Then add a calculated field LWBSPct = LWBS / EDVisits. With Ashby Falls and 2025 Q3 still selected, what LWBS % does PivotTable 2 show? Enter it as a percentage. | C17: 0.016216216 | D17: 1. Click in tblKPI → Insert → PivotTable → Existing Worksheet, pick a cell on Pivots a few columns right of PivotTable 1 → OK. 2. Drag Facility to Rows, then LWBS and EDVisits to Values. 3. Select the Facility slicer → Slicer → Report Connections → tick both PivotTables → OK. Do the same for the timeline (Timeline → Report Connections). PivotTable 2 now shows only Ashby Falls, Q3 2025. 4. Click in PivotTable 2 → PivotTable Analyze → Fields, Items & Sets → Calculated Field. Name: LWBSPct. Formula: =LWBS/EDVisits → Add → OK. Format it as a percentage. Formula twin: =SUMIFS(tblKPI[LWBS],tblKPI[Facility],"Ashby Falls Community Hospital",tblKPI[Month],">="&DATE(2025,7,1),tblKPI[Month],"<="&DATE(2025,9,1))/SUMIFS(tblKPI[EDVisits],tblKPI[Facility],"Ashby Falls Community Hospital",tblKPI[Month],">="&DATE(2025,7,1),tblKPI[Month],"<="&DATE(2025,9,1)) | E17: {=SUMIFS(tblKPI[LWBS],tblKPI[Facility],"Ashby Falls Community Hospital",tblKPI[Month],">="&DATE(2025,7,1),tblKPI[Month],"<="&DATE(2025,9,1))/SUMIFS(tblKPI[EDVisits],tblKPI[Facility],"Ashby Falls Community Hospital",tblKPI[Month],">="&DATE(2025,7,1),tblKPI[Month],"<="&DATE(2025,9,1))} | F17: Report Connections is what lets one slicer filter several pivots. If you skipped it, PivotTable 2 would still show every hospital and month. A pivot calculated field sums each field first and then divides, so LWBSPct is total LWBS ÷ total visits for the quarter. That's exactly the right rate here: 1.62%. Averaging the three monthly rates would give 1.54%. Both pivots must come from the same source (tblKPI) to share a slicer.

Sheet Bonus Key
A1: 🔑 Bonus Key — Lesson 4.6
A2: Spoiler alert — try every task before reading this sheet. Column C is the value the Check column compares against. Column D is a sample solution; column E is that same formula, live, proving it works.
A4: # | B4: Task | C4: Answer | D4: Sample solution | E4: Live result | F4: Explanation
A5: B1 | B5: Set your Board dashboard to All facilities and Oct 2025. What is the system-wide 30-day readmission rate? Enter it as a percentage. | C5: 0.18957346 | D5: 1. Make a helper cell named FacCrit: =IF(BoardFacility="All facilities","*",BoardFacility). 2. The readmission card's value: =SUMIFS(tblKPI[Readmits],tblKPI[Facility],FacCrit,tblKPI[Month],BoardMonth)/SUMIFS(tblKPI[IndexStays],tblKPI[Facility],FacCrit,tblKPI[Month],BoardMonth) | E5: {=SUMIFS(tblKPI[Readmits],tblKPI[Facility],"*",tblKPI[Month],DATE(2025,10,1))/SUMIFS(tblKPI[IndexStays],tblKPI[Facility],"*",tblKPI[Month],DATE(2025,10,1))} | F5: 40 readmissions ÷ 211 index stays = 18.96%. No row in tblKPI says "All facilities", so SUMIFS with that text returns 0. The wildcard * matches any text, so the same SUMIFS adds all three hospitals. Every additive component works this way, and every rate is then rebuilt as total ÷ total.
A6: B2 | B6: With All facilities and Oct 2025 still selected, how many of the seven KPIs are on target? Use the Targets sheet's rule: on target means at or below a lower-is-better target, or at or above a higher-is-better one, so a value exactly equal to its target counts as on target. | C6: 3 | D6: Give each card a numeric status cell, for example for LWBS: =IF(ISNUMBER(val),--IF(dir="Lower is better",val<=tgt,val>=tgt),"") Then the scorecard is =SUM(statuses)&" of "&COUNT(statuses)&" KPIs on target". The system values for this month: | KPI | Value | Target | Status | |---|---|---|---| | LWBS % | 1.4% | ≤ 2.0% | ✔ On target | | Median door-to-provider | 38.0 min | ≤ 30.0 min | ✘ Off target | | ALOS | 4.54 days | ≤ 4.50 days | ✘ Off target | | 30-day readmission rate | 19.0% | ≤ 15.0% | ✘ Off target | | Occupancy % | 79.1% | ≤ 85.0% | ✔ On target | | HCAHPS top-box % | 50.0% | ≥ 50.0% | ✔ On target | | Denial rate | 14.3% | ≤ 10.0% | ✘ Off target | | E6: {=_xlfn.LET(_xlpm.m,DATE(2025,10,1),_xlpm.lwbs,SUMIFS(tblKPI[LWBS],tblKPI[Month],_xlpm.m)/SUMIFS(tblKPI[EDVisits],tblKPI[Month],_xlpm.m),_xlpm.dtp,MEDIAN(_xlfn._xlws.FILTER(tblEDWaits[DoorToProviderMin],(tblEDWaits[ArrivalDateTime]>=_xlpm.m)*(tblEDWaits[ArrivalDateTime]<EDATE(_xlpm.m,1)))),_xlpm.alos,SUMIFS(tblKPI[LOSDays],tblKPI[Month],_xlpm.m)/SUMIFS(tblKPI[IPDischarges],tblKPI[Month],_xlpm.m),_xlpm.readm,SUMIFS(tblKPI[Readmits],tblKPI[Month],_xlpm.m)/SUMIFS(tblKPI[IndexStays],tblKPI[Month],_xlpm.m),_xlpm.occ,SUMIFS(tblKPI[PatientDays],tblKPI[Month],_xlpm.m)/SUMIFS(tblKPI[BedDays],tblKPI[Month],_xlpm.m),_xlpm.tbox,SUMIFS(tblKPI[TopBox],tblKPI[Month],_xlpm.m)/SUMIFS(tblKPI[Surveys],tblKPI[Month],_xlpm.m),_xlpm.den,SUMIFS(tblKPI[ClaimsDenied],tblKPI[Month],_xlpm.m)/SUMIFS(tblKPI[ClaimsAdjudicated],tblKPI[Month],_xlpm.m),_xlpm.tg,tblTargets[Target],(_xlpm.lwbs<=INDEX(_xlpm.tg,1))+(_xlpm.dtp<=INDEX(_xlpm.tg,2))+(_xlpm.alos<=INDEX(_xlpm.tg,3))+(_xlpm.readm<=INDEX(_xlpm.tg,4))+(_xlpm.occ<=INDEX(_xlpm.tg,5))+(_xlpm.tbox>=INDEX(_xlpm.tg,6))+(_xlpm.den<=INDEX(_xlpm.tg,7)))} | F6: 3 of 7. The median door-to-provider must come from tblEDWaits, because the three hospital medians can't be combined. HCAHPS top-box is the one higher-is-better KPI, and this month it lands at exactly 50.0%: on target with >=, off target with >. Decide ties in the KPI dictionary, not in each formula. Status cells that return 1 or 0 (not text) make the scorecard a plain SUM and make conditional formatting rules simple.
A7: B3 | B7: Keep Oct 2025 and switch the Facility dropdown to each hospital in turn. Which hospital has the fewest KPIs on target? | C7: Bluestone Memorial Hospital | D7: Read the scorecard line after each switch: | Hospital | On target | |---|---| | Bluestone Memorial Hospital | 2 of 7 | | Ashby Falls Community Hospital | 5 of 7 | | Cedar Ridge Medical Center | 4 of 7 | The Dashboard Key's model area has this comparison table (columns N–V), with =INDEX(N42:N44,MATCH(MIN(V42:V44),V42:V44,0)) picking the lowest. | E7: {='Dashboard Key'!$O$46} | F7: Bluestone Memorial Hospital meets 2 of 7 targets in Oct 2025. A selector-driven dashboard answers "which hospital?" in a few clicks without a separate report per hospital. The large hospital being furthest off target is also why the system-wide scorecard lands where it does: its volumes dominate every total ÷ total rate.
A8: B4 | B8: Back on All facilities and Oct 2025, your 12-month LWBS % trend runs Nov 2024–Oct 2025. In which month was the system-wide LWBS % highest? Enter the first day of that month as a date. | C8: 45627 | D8: Trend block on the Board sheet (12 rows): month =EDATE(BoardMonth,ROWS(first:current)-12), and the rate: =IFERROR(SUMIFS(tblKPI[LWBS],tblKPI[Facility],FacCrit,tblKPI[Month],month) /SUMIFS(tblKPI[EDVisits],tblKPI[Facility],FacCrit,tblKPI[Month],month),NA()) Then =INDEX(months,MATCH(AGGREGATE(4,6,rates),rates,0)). AGGREGATE(4,6,…) is MAX that skips error values, so the #N/A gaps of an early month can't break it. | E8: {='Dashboard Key'!$O$36} | F8: December 2024 peaks at 2.90%, against a target of 2%. Every other month in the window is lower. A target line on the chart (a second series that repeats the target in every row) makes the misses visible at a glance, and the dynamic title tells the reader which facility and months they're looking at.

Sheet Dashboard Key
B1: Bluestone Health · Hospital Operations Dashboard | N1: MODEL · on a real dashboard this lives on its own (hidden) Calc sheet
B2: {="Selection: "&$C$4&" · "&TEXT($C$5,"mmmm yyyy")&" · reference build for the Lesson 4.6 bonus"}
N3: Facility criterion | O3: {=IF($C$4="All facilities","*",$C$4)}
B4: Facility | C4: All facilities | H4: {=$O$18&" of "&$P$18&" KPIs on target"} | N4: Month | O4: {=$C$5}
B5: Month | C5: 45931 | N5: Same month last year | O5: {=EDATE($O$4,-12)}
N6: Month end (exclusive) | O6: {=EDATE($O$4,1)}
B7: ED VISITS | E7: LWBS % | H7: MEDIAN DOOR-TO-PROVIDER | K7: ALOS | N7: Last year's month end (exclusive) | O7: {=EDATE($O$5,1)}
B8: {=$O$10} | E8: {=$O$11} | H8: {=$O$12} | K8: {=$O$13}
B9: Target | C9: — | E9: Target | F9: {=IF($R$11="Lower is better","≤ ","≥ ")&TEXT($Q$11,"0.0%")&""} | H9: Target | I9: {=IF($R$12="Lower is better","≤ ","≥ ")&TEXT($Q$12,"0")&" min"} | K9: Target | L9: {=IF($R$13="Lower is better","≤ ","≥ ")&TEXT($Q$13,"0.0")&" days"} | N9: KPI | O9: This month | P9: Last year | Q9: Target | R9: Direction | S9: On target (1/0)
B10: Status | C10: — | E10: Status | F10: {=IF(ISNUMBER($S$11),IF($S$11=1,"✔ On target","✘ Off target"),"n/a")} | H10: Status | I10: {=IF(ISNUMBER($S$12),IF($S$12=1,"✔ On target","✘ Off target"),"n/a")} | K10: Status | L10: {=IF(ISNUMBER($S$13),IF($S$13=1,"✔ On target","✘ Off target"),"n/a")} | N10: ED visits | O10: {=SUMIFS(tblKPI[EDVisits],tblKPI[Facility],$O$3,tblKPI[Month],$O$4)} | P10: {=SUMIFS(tblKPI[EDVisits],tblKPI[Facility],$O$3,tblKPI[Month],$O$5)}
B11: vs last year | C11: {=IF(AND(AND(ISNUMBER($O$10),ISNUMBER($P$10)),$P$10<>0),IF($O$10>$P$10,_xlfn.UNICHAR(9650),IF($O$10<$P$10,_xlfn.UNICHAR(9660),_xlfn.UNICHAR(9644)))&" "&TEXT(ABS($O$10/$P$10-1),"0.0%"),"n/a")} | E11: vs last year | F11: {=IF(AND(ISNUMBER($O$11),ISNUMBER($P$11)),IF($O$11>$P$11,_xlfn.UNICHAR(9650),IF($O$11<$P$11,_xlfn.UNICHAR(9660),_xlfn.UNICHAR(9644)))&" "&TEXT(ABS($O$11-$P$11)*100,"0.0")&" pts","n/a")} | H11: vs last year | I11: {=IF(AND(ISNUMBER($O$12),ISNUMBER($P$12)),IF($O$12>$P$12,_xlfn.UNICHAR(9650),IF($O$12<$P$12,_xlfn.UNICHAR(9660),_xlfn.UNICHAR(9644)))&" "&TEXT(ABS($O$12-$P$12),"0.0")&" min","n/a")} | K11: vs last year | L11: {=IF(AND(ISNUMBER($O$13),ISNUMBER($P$13)),IF($O$13>$P$13,_xlfn.UNICHAR(9650),IF($O$13<$P$13,_xlfn.UNICHAR(9660),_xlfn.UNICHAR(9644)))&" "&TEXT(ABS($O$13-$P$13),"0.00")&" days","n/a")} | N11: LWBS % | O11: {=IFERROR(SUMIFS(tblKPI[LWBS],tblKPI[Facility],$O$3,tblKPI[Month],$O$4)/SUMIFS(tblKPI[EDVisits],tblKPI[Facility],$O$3,tblKPI[Month],$O$4),"n/a")} | P11: {=IFERROR(SUMIFS(tblKPI[LWBS],tblKPI[Facility],$O$3,tblKPI[Month],$O$5)/SUMIFS(tblKPI[EDVisits],tblKPI[Facility],$O$3,tblKPI[Month],$O$5),"n/a")} | Q11: {=_xlfn.XLOOKUP($N11,tblTargets[KPI],tblTargets[Target])} | R11: {=_xlfn.XLOOKUP($N11,tblTargets[KPI],tblTargets[Direction])} | S11: {=IF(ISNUMBER(O11),--IF(R11="Lower is better",O11<=Q11,O11>=Q11),"")}
N12: Median door-to-provider | O12: {=IFERROR(MEDIAN(_xlfn._xlws.FILTER(tblEDWaits[DoorToProviderMin],(tblEDWaits[ArrivalDateTime]>=$O$4)*(tblEDWaits[ArrivalDateTime]<$O$6)*((tblEDWaits[Facility]=$C$4)+($C$4="All facilities")))),"n/a")} | P12: {=IFERROR(MEDIAN(_xlfn._xlws.FILTER(tblEDWaits[DoorToProviderMin],(tblEDWaits[ArrivalDateTime]>=$O$5)*(tblEDWaits[ArrivalDateTime]<$O$7)*((tblEDWaits[Facility]=$C$4)+($C$4="All facilities")))),"n/a")} | Q12: {=_xlfn.XLOOKUP($N12,tblTargets[KPI],tblTargets[Target])} | R12: {=_xlfn.XLOOKUP($N12,tblTargets[KPI],tblTargets[Direction])} | S12: {=IF(ISNUMBER(O12),--IF(R12="Lower is better",O12<=Q12,O12>=Q12),"")}
B13: 30-DAY READMISSION RATE | E13: OCCUPANCY % | H13: HCAHPS TOP-BOX % | K13: DENIAL RATE | N13: ALOS | O13: {=IFERROR(SUMIFS(tblKPI[LOSDays],tblKPI[Facility],$O$3,tblKPI[Month],$O$4)/SUMIFS(tblKPI[IPDischarges],tblKPI[Facility],$O$3,tblKPI[Month],$O$4),"n/a")} | P13: {=IFERROR(SUMIFS(tblKPI[LOSDays],tblKPI[Facility],$O$3,tblKPI[Month],$O$5)/SUMIFS(tblKPI[IPDischarges],tblKPI[Facility],$O$3,tblKPI[Month],$O$5),"n/a")} | Q13: {=_xlfn.XLOOKUP($N13,tblTargets[KPI],tblTargets[Target])} | R13: {=_xlfn.XLOOKUP($N13,tblTargets[KPI],tblTargets[Direction])} | S13: {=IF(ISNUMBER(O13),--IF(R13="Lower is better",O13<=Q13,O13>=Q13),"")}
B14: {=$O$14} | E14: {=$O$15} | H14: {=$O$16} | K14: {=$O$17} | N14: 30-day readmission rate | O14: {=IFERROR(SUMIFS(tblKPI[Readmits],tblKPI[Facility],$O$3,tblKPI[Month],$O$4)/SUMIFS(tblKPI[IndexStays],tblKPI[Facility],$O$3,tblKPI[Month],$O$4),"n/a")} | P14: {=IFERROR(SUMIFS(tblKPI[Readmits],tblKPI[Facility],$O$3,tblKPI[Month],$O$5)/SUMIFS(tblKPI[IndexStays],tblKPI[Facility],$O$3,tblKPI[Month],$O$5),"n/a")} | Q14: {=_xlfn.XLOOKUP($N14,tblTargets[KPI],tblTargets[Target])} | R14: {=_xlfn.XLOOKUP($N14,tblTargets[KPI],tblTargets[Direction])} | S14: {=IF(ISNUMBER(O14),--IF(R14="Lower is better",O14<=Q14,O14>=Q14),"")}
B15: Target | C15: {=IF($R$14="Lower is better","≤ ","≥ ")&TEXT($Q$14,"0.0%")&""} | E15: Target | F15: {=IF($R$15="Lower is better","≤ ","≥ ")&TEXT($Q$15,"0.0%")&""} | H15: Target | I15: {=IF($R$16="Lower is better","≤ ","≥ ")&TEXT($Q$16,"0.0%")&""} | K15: Target | L15: {=IF($R$17="Lower is better","≤ ","≥ ")&TEXT($Q$17,"0.0%")&""} | N15: Occupancy % | O15: {=IFERROR(SUMIFS(tblKPI[PatientDays],tblKPI[Facility],$O$3,tblKPI[Month],$O$4)/SUMIFS(tblKPI[BedDays],tblKPI[Facility],$O$3,tblKPI[Month],$O$4),"n/a")} | P15: {=IFERROR(SUMIFS(tblKPI[PatientDays],tblKPI[Facility],$O$3,tblKPI[Month],$O$5)/SUMIFS(tblKPI[BedDays],tblKPI[Facility],$O$3,tblKPI[Month],$O$5),"n/a")} | Q15: {=_xlfn.XLOOKUP($N15,tblTargets[KPI],tblTargets[Target])} | R15: {=_xlfn.XLOOKUP($N15,tblTargets[KPI],tblTargets[Direction])} | S15: {=IF(ISNUMBER(O15),--IF(R15="Lower is better",O15<=Q15,O15>=Q15),"")}
B16: Status | C16: {=IF(ISNUMBER($S$14),IF($S$14=1,"✔ On target","✘ Off target"),"n/a")} | E16: Status | F16: {=IF(ISNUMBER($S$15),IF($S$15=1,"✔ On target","✘ Off target"),"n/a")} | H16: Status | I16: {=IF(ISNUMBER($S$16),IF($S$16=1,"✔ On target","✘ Off target"),"n/a")} | K16: Status | L16: {=IF(ISNUMBER($S$17),IF($S$17=1,"✔ On target","✘ Off target"),"n/a")} | N16: HCAHPS top-box % | O16: {=IFERROR(SUMIFS(tblKPI[TopBox],tblKPI[Facility],$O$3,tblKPI[Month],$O$4)/SUMIFS(tblKPI[Surveys],tblKPI[Facility],$O$3,tblKPI[Month],$O$4),"n/a")} | P16: {=IFERROR(SUMIFS(tblKPI[TopBox],tblKPI[Facility],$O$3,tblKPI[Month],$O$5)/SUMIFS(tblKPI[Surveys],tblKPI[Facility],$O$3,tblKPI[Month],$O$5),"n/a")} | Q16: {=_xlfn.XLOOKUP($N16,tblTargets[KPI],tblTargets[Target])} | R16: {=_xlfn.XLOOKUP($N16,tblTargets[KPI],tblTargets[Direction])} | S16: {=IF(ISNUMBER(O16),--IF(R16="Lower is better",O16<=Q16,O16>=Q16),"")}
B17: vs last year | C17: {=IF(AND(ISNUMBER($O$14),ISNUMBER($P$14)),IF($O$14>$P$14,_xlfn.UNICHAR(9650),IF($O$14<$P$14,_xlfn.UNICHAR(9660),_xlfn.UNICHAR(9644)))&" "&TEXT(ABS($O$14-$P$14)*100,"0.0")&" pts","n/a")} | E17: vs last year | F17: {=IF(AND(ISNUMBER($O$15),ISNUMBER($P$15)),IF($O$15>$P$15,_xlfn.UNICHAR(9650),IF($O$15<$P$15,_xlfn.UNICHAR(9660),_xlfn.UNICHAR(9644)))&" "&TEXT(ABS($O$15-$P$15)*100,"0.0")&" pts","n/a")} | H17: vs last year | I17: {=IF(AND(ISNUMBER($O$16),ISNUMBER($P$16)),IF($O$16>$P$16,_xlfn.UNICHAR(9650),IF($O$16<$P$16,_xlfn.UNICHAR(9660),_xlfn.UNICHAR(9644)))&" "&TEXT(ABS($O$16-$P$16)*100,"0.0")&" pts","n/a")} | K17: vs last year | L17: {=IF(AND(ISNUMBER($O$17),ISNUMBER($P$17)),IF($O$17>$P$17,_xlfn.UNICHAR(9650),IF($O$17<$P$17,_xlfn.UNICHAR(9660),_xlfn.UNICHAR(9644)))&" "&TEXT(ABS($O$17-$P$17)*100,"0.0")&" pts","n/a")} | N17: Denial rate | O17: {=IFERROR(SUMIFS(tblKPI[ClaimsDenied],tblKPI[Facility],$O$3,tblKPI[Month],$O$4)/SUMIFS(tblKPI[ClaimsAdjudicated],tblKPI[Facility],$O$3,tblKPI[Month],$O$4),"n/a")} | P17: {=IFERROR(SUMIFS(tblKPI[ClaimsDenied],tblKPI[Facility],$O$3,tblKPI[Month],$O$5)/SUMIFS(tblKPI[ClaimsAdjudicated],tblKPI[Facility],$O$3,tblKPI[Month],$O$5),"n/a")} | Q17: {=_xlfn.XLOOKUP($N17,tblTargets[KPI],tblTargets[Target])} | R17: {=_xlfn.XLOOKUP($N17,tblTargets[KPI],tblTargets[Direction])} | S17: {=IF(ISNUMBER(O17),--IF(R17="Lower is better",O17<=Q17,O17>=Q17),"")}
N18: KPIs on target (of those with data) | O18: {=SUM(S11:S17)} | P18: {=COUNT(S11:S17)}
N19: Chart title: ED visits | O19: {="ED visits, 12 months to "&TEXT($O$4,"mmm yyyy")&" · "&$C$4}
N20: Chart title: LWBS % | O20: {="LWBS % vs target, 12 months to "&TEXT($O$4,"mmm yyyy")&" · "&$C$4}
N21: 12-month trend (selected facility)
N22: Month | O22: ED visits | P22: LWBS % | Q22: LWBS target
N23: {=EDATE($O$4,ROWS(N$23:N23)-12)} | O23: {=IF(COUNTIFS(tblKPI[Facility],$O$3,tblKPI[Month],N23)=0,NA(),SUMIFS(tblKPI[EDVisits],tblKPI[Facility],$O$3,tblKPI[Month],N23))} | P23: {=IFERROR(SUMIFS(tblKPI[LWBS],tblKPI[Facility],$O$3,tblKPI[Month],N23)/SUMIFS(tblKPI[EDVisits],tblKPI[Facility],$O$3,tblKPI[Month],N23),NA())} | Q23: {=$Q$11}
N24: {=EDATE($O$4,ROWS(N$23:N24)-12)} | O24: {=IF(COUNTIFS(tblKPI[Facility],$O$3,tblKPI[Month],N24)=0,NA(),SUMIFS(tblKPI[EDVisits],tblKPI[Facility],$O$3,tblKPI[Month],N24))} | P24: {=IFERROR(SUMIFS(tblKPI[LWBS],tblKPI[Facility],$O$3,tblKPI[Month],N24)/SUMIFS(tblKPI[EDVisits],tblKPI[Facility],$O$3,tblKPI[Month],N24),NA())} | Q24: {=$Q$11}
N25: {=EDATE($O$4,ROWS(N$23:N25)-12)} | O25: {=IF(COUNTIFS(tblKPI[Facility],$O$3,tblKPI[Month],N25)=0,NA(),SUMIFS(tblKPI[EDVisits],tblKPI[Facility],$O$3,tblKPI[Month],N25))} | P25: {=IFERROR(SUMIFS(tblKPI[LWBS],tblKPI[Facility],$O$3,tblKPI[Month],N25)/SUMIFS(tblKPI[EDVisits],tblKPI[Facility],$O$3,tblKPI[Month],N25),NA())} | Q25: {=$Q$11}
N26: {=EDATE($O$4,ROWS(N$23:N26)-12)} | O26: {=IF(COUNTIFS(tblKPI[Facility],$O$3,tblKPI[Month],N26)=0,NA(),SUMIFS(tblKPI[EDVisits],tblKPI[Facility],$O$3,tblKPI[Month],N26))} | P26: {=IFERROR(SUMIFS(tblKPI[LWBS],tblKPI[Facility],$O$3,tblKPI[Month],N26)/SUMIFS(tblKPI[EDVisits],tblKPI[Facility],$O$3,tblKPI[Month],N26),NA())} | Q26: {=$Q$11}
N27: {=EDATE($O$4,ROWS(N$23:N27)-12)} | O27: {=IF(COUNTIFS(tblKPI[Facility],$O$3,tblKPI[Month],N27)=0,NA(),SUMIFS(tblKPI[EDVisits],tblKPI[Facility],$O$3,tblKPI[Month],N27))} | P27: {=IFERROR(SUMIFS(tblKPI[LWBS],tblKPI[Facility],$O$3,tblKPI[Month],N27)/SUMIFS(tblKPI[EDVisits],tblKPI[Facility],$O$3,tblKPI[Month],N27),NA())} | Q27: {=$Q$11}
N28: {=EDATE($O$4,ROWS(N$23:N28)-12)} | O28: {=IF(COUNTIFS(tblKPI[Facility],$O$3,tblKPI[Month],N28)=0,NA(),SUMIFS(tblKPI[EDVisits],tblKPI[Facility],$O$3,tblKPI[Month],N28))} | P28: {=IFERROR(SUMIFS(tblKPI[LWBS],tblKPI[Facility],$O$3,tblKPI[Month],N28)/SUMIFS(tblKPI[EDVisits],tblKPI[Facility],$O$3,tblKPI[Month],N28),NA())} | Q28: {=$Q$11}
N29: {=EDATE($O$4,ROWS(N$23:N29)-12)} | O29: {=IF(COUNTIFS(tblKPI[Facility],$O$3,tblKPI[Month],N29)=0,NA(),SUMIFS(tblKPI[EDVisits],tblKPI[Facility],$O$3,tblKPI[Month],N29))} | P29: {=IFERROR(SUMIFS(tblKPI[LWBS],tblKPI[Facility],$O$3,tblKPI[Month],N29)/SUMIFS(tblKPI[EDVisits],tblKPI[Facility],$O$3,tblKPI[Month],N29),NA())} | Q29: {=$Q$11}
N30: {=EDATE($O$4,ROWS(N$23:N30)-12)} | O30: {=IF(COUNTIFS(tblKPI[Facility],$O$3,tblKPI[Month],N30)=0,NA(),SUMIFS(tblKPI[EDVisits],tblKPI[Facility],$O$3,tblKPI[Month],N30))} | P30: {=IFERROR(SUMIFS(tblKPI[LWBS],tblKPI[Facility],$O$3,tblKPI[Month],N30)/SUMIFS(tblKPI[EDVisits],tblKPI[Facility],$O$3,tblKPI[Month],N30),NA())} | Q30: {=$Q$11}
N31: {=EDATE($O$4,ROWS(N$23:N31)-12)} | O31: {=IF(COUNTIFS(tblKPI[Facility],$O$3,tblKPI[Month],N31)=0,NA(),SUMIFS(tblKPI[EDVisits],tblKPI[Facility],$O$3,tblKPI[Month],N31))} | P31: {=IFERROR(SUMIFS(tblKPI[LWBS],tblKPI[Facility],$O$3,tblKPI[Month],N31)/SUMIFS(tblKPI[EDVisits],tblKPI[Facility],$O$3,tblKPI[Month],N31),NA())} | Q31: {=$Q$11}
N32: {=EDATE($O$4,ROWS(N$23:N32)-12)} | O32: {=IF(COUNTIFS(tblKPI[Facility],$O$3,tblKPI[Month],N32)=0,NA(),SUMIFS(tblKPI[EDVisits],tblKPI[Facility],$O$3,tblKPI[Month],N32))} | P32: {=IFERROR(SUMIFS(tblKPI[LWBS],tblKPI[Facility],$O$3,tblKPI[Month],N32)/SUMIFS(tblKPI[EDVisits],tblKPI[Facility],$O$3,tblKPI[Month],N32),NA())} | Q32: {=$Q$11}
N33: {=EDATE($O$4,ROWS(N$23:N33)-12)} | O33: {=IF(COUNTIFS(tblKPI[Facility],$O$3,tblKPI[Month],N33)=0,NA(),SUMIFS(tblKPI[EDVisits],tblKPI[Facility],$O$3,tblKPI[Month],N33))} | P33: {=IFERROR(SUMIFS(tblKPI[LWBS],tblKPI[Facility],$O$3,tblKPI[Month],N33)/SUMIFS(tblKPI[EDVisits],tblKPI[Facility],$O$3,tblKPI[Month],N33),NA())} | Q33: {=$Q$11}
