Workbook

Sheet Start Here
B2: Lesson 5.4
B3: VBA: Custom Functions, Dictionaries & Error Handling
B4: Expert · about 65 minutes · Bluestone Health System (fictional)
B6: What you'll learn
B7: • | C7: Write user-defined functions (UDFs) you can call from cells
B8: • | C8: Pass arguments ByVal/ByRef, use Optional arguments, and return errors with CVErr
B9: • | C9: Count and group with Collections and Scripting.Dictionary
B10: • | C10: Handle errors gracefully with On Error, the Err object, and cleanup code
B12: How to use this workbook
B13: 1. Read the guide | C13: The lesson guide (README) explains each skill with examples: https://github.com/lmansf/learn-excel/tree/main/05-automation-vba/04-vba-functions-error-handling
B14: 2. Practice | C14: Go to the 'Practice' sheet. Type a formula or value into each yellow cell.
B15: 3. Check yourself | C15: The Check column shows ✔ Correct (green) or ✘ Not yet (red). Tasks marked 'See key' are checked by comparing with the answer key.
B16: 4. Bonus | C16: Finished? Try the harder 'Bonus' sheet.
B17: 5. Answers | C17: The 'Answer Key' and 'Bonus Key' sheets are hidden. Right-click any sheet tab → Unhide… → pick one → OK. (Try first!)
B18: Note | C18: Macros can't be saved in an .xlsx file. Before you write any code, choose File → Save As and pick 'Excel Macro-Enabled Workbook (*.xlsm)'.
B19: Note | C19: Download the four .bas files in the lesson's starter/ folder (on GitHub, open each file and click Download raw file). Open the Visual Basic Editor with Alt + F11 (Mac: Option + F11), then choose File → Import File… for each one. HealthUDFs.bas is for tasks 1–6, ClaimDictionaries.bas for tasks 8–10, Snippets.bas for tasks 7 and 11–13, and PayerSummary.bas for the bonus.
B20: Note | C20: Scripting.Dictionary works only in Excel for Windows. On a Mac, use the Collection techniques from the guide. The solutions/ folder has Mac versions of every macro.
B21: Note | C21: The Output sheet is where your macros write their results. The Snippets sheet shows the code for the predict-the-output tasks. The bonus macro creates a PayerSummary sheet.
B23: Color legend
B24: Yellow cell | C24: Your answer goes here.
B25: Gray cell | C25: Pre-filled summary formula — it reads the work you did on another sheet.
B26: ✔ Correct | C26: Your answer matches the key.
B27: ✘ Not yet | C27: Not matching yet — check the hint and try again.
B29: Sheets in this workbook
B30: Patients | C30: Data: 591 rows — Excel Table 'tblPatients'
B31: Encounters | C31: Data: 505 rows — Excel Table 'tblEncounters'
B32: Claims | C32: Data: 1,093 rows — Excel Table 'tblClaims'
B33: Payers | C33: Data: 8 rows — Excel Table 'tblPayers'
B34: About the data | C34: Cedar Ridge Medical Center, 2025: adult patients with height and weight, inpatient and observation stays, every claim with its payer and status, and the 8 payers. A few rows contain deliberate data-entry errors for your code to catch.
B35: Disclaimer | C35: All people, places, and numbers are synthetic and fictional. Not clinical guidance.

Sheet Practice
A1: Lesson 5.4 · Practice
A2: Save the workbook as .xlsm and import the starter modules first (see the Start Here sheet). In tasks 1–6 you write user-defined functions and use them in cells: tasks 1 and 6 in the yellow cell, and tasks 2–5 in yellow columns on the data sheets, which the gray cells summarize. Tasks 7 and 11–13 ask you to predict what a snippet on the Snippets sheet does. In tasks 8–10 you run macros, and the gray cells read what they wrote to the Output sheet.
A3: Type a formula or value in each yellow cell. The Check column turns green when your answer matches. Stuck? Read the hint, then the lesson guide. Answers: right-click a sheet tab → Unhide… → 'Answer Key'.
A4: ="Score: "&COUNTIF(E6:E18,"✔*")&" of 13 auto-checked tasks correct"
A5: # | B5: Task | C5: Hint | D5: Your Answer | E5: Check
A6: 1 | B6: Write BMI(weightLb, heightIn) in a standard module (start from starter/HealthUDFs.bas). BMI = 703 × weight in pounds ÷ (height in inches)². It must return #VALUE! for a blank or text input and #NUM! for a zero or negative one. In the yellow cell, call it for the first patient on the Patients sheet (row 2, PT10002). Keep full precision. The check accepts 2 decimal places. | C6: Assign the result to the function's own name. Return errors with CVErr | E6: =IF(IFERROR(D6="",FALSE),"",IF(IFERROR(AND(ISNUMBER(D6),OR(ABS(D6-'Answer Key'!$C$5)<=0.0051)),FALSE),"✔ Correct","✘ Not yet"))
A7: 2 | B7: Fill the yellow BMI column on the Patients sheet with your BMI function for every patient. Don't round inside the function: the column's number format already shows 1 decimal place. The gray cell counts the patients whose unrounded BMI is 30 or more (the usual adult obesity threshold). | C7: Type it once in the first BMI cell. The Table fills the rest | D7: {=IF(COUNT('Patients'!$H$2:$H$592)=0,"",COUNTIF('Patients'!$H$2:$H$592,">=30"))} | E7: =IF(IFERROR(D7="",FALSE),"",IF(IFERROR(AND(ISNUMBER(D7),OR(ABS(D7-'Answer Key'!$C$6)<=0.0001)),FALSE),"✔ Correct","✘ Not yet"))
A8: 3 | B8: Write AGEAT(dob, [asOf]): a person's age in completed years on the asOf date, or on today's date when asOf is left out (use IsMissing). Then fill the yellow AgeAtAdmit column on the Encounters sheet with each patient's age on the admission date. The gray cell averages your column, and the check compares that average to 2 decimal places. | C8: Optional asOf As Variant + IsMissing. Then check whether this year's birthday has happened | D8: {=IF(COUNT('Encounters'!$G$2:$G$506)=0,"",AVERAGE('Encounters'!$G$2:$G$506))} | E8: =IF(IFERROR(D8="",FALSE),"",IF(IFERROR(AND(ISNUMBER(D8),OR(ABS(D8-'Answer Key'!$C$7)<=0.0051)),FALSE),"✔ Correct","✘ Not yet"))
A9: 4 | B9: Write LOSDAYS(admitDateTime, dischargeDateTime): the number of midnights between admission and discharge, or #VALUE! when an input isn't a date or the discharge date-time is earlier than the admission date-time. Fill the yellow LOSDays column on the Encounters sheet. The gray cell adds up your column and skips error cells. What is the total? | C9: CVErr(xlErrValue) for bad rows. DateDiff("d", …) counts midnights | D9: {=IF(COUNT('Encounters'!$H$2:$H$506)+SUMPRODUCT(--ISERROR('Encounters'!$H$2:$H$506))=0,"",_xlfn.AGGREGATE(9,6,'Encounters'!$H$2:$H$506))} | E9: =IF(IFERROR(D9="",FALSE),"",IF(IFERROR(AND(ISNUMBER(D9),OR(ABS(D9-'Answer Key'!$C$8)<=0.0001)),FALSE),"✔ Correct","✘ Not yet"))
A10: 5 | B10: How many rows does your LOSDays column flag with #VALUE!? The gray cell counts them. (Each one is a data-entry error to send back to Health Information Management.) | C10: Filter the LOSDays column to see the error rows | D10: {=IF(COUNT('Encounters'!$H$2:$H$506)+SUMPRODUCT(--ISERROR('Encounters'!$H$2:$H$506))=0,"",COUNTIF('Encounters'!$H$2:$H$506,"#VALUE!"))} | E10: =IF(IFERROR(D10="",FALSE),"",IF(IFERROR(AND(ISNUMBER(D10),OR(ABS(D10-'Answer Key'!$C$9)<=0.0001)),FALSE),"✔ Correct","✘ Not yet"))
A11: 6 | B11: Write DENIALRATE(statusRange, [statusToCount]): the share of non-blank cells in statusRange whose text equals statusToCount (ignoring case). statusToCount is Optional and defaults to "Denied". Return #DIV/0! if the range has no non-blank cells. In the yellow cell, call DENIALRATE on the ClaimStatus column of the Claims sheet and leave out the second argument. The cell is already formatted as a percentage. | C11: Optional statusToCount As String = "Denied", then For Each cell In statusRange.Cells | E11: =IF(IFERROR(D11="",FALSE),"",IF(IFERROR(AND(ISNUMBER(D11),OR(ABS(D11-'Answer Key'!$C$10)<=0.00051,ABS(D11-'Answer Key'!$C$10*100)<=0.051000000000000004)),FALSE),"✔ Correct","✘ Not yet"))
A12: 7 | B12: Snippet A on the Snippets sheet passes a $100 charge to AddFeeByVal and AddFeeByRef. What number does Debug.Print charge show? Predict first, then run it to check. | C12: ByRef shares the caller's variable. What do parentheses around an argument do? | E12: =IF(IFERROR(D12="",FALSE),"",IF(IFERROR(AND(ISNUMBER(D12),OR(ABS(D12-'Answer Key'!$C$11)<=0.0001)),FALSE),"✔ Correct","✘ Not yet"))
A13: 8 | B13: Complete CountDenialReasons in starter/ClaimDictionaries.bas: add every non-blank DenialReason on the Claims sheet to a Collection, using the reason itself as the key, so each reason is kept once. The macro writes the Collection's Count to Output!B4, and the gray cell reads it. | C13: col.Add Item:=reason, Key:=reason raises an error for a key it already has | D13: {=IF(Output!B4="","",Output!B4)} | E13: =IF(IFERROR(D13="",FALSE),"",IF(IFERROR(AND(ISNUMBER(D13),OR(ABS(D13-'Answer Key'!$C$12)<=0.0001)),FALSE),"✔ Correct","✘ Not yet"))
A14: 9 | B14: Complete CountDistinctPatients: add every PatientID on the Claims sheet to a Scripting.Dictionary (Mac: a Collection) once, then write the number of keys to Output!B5. How many different patients had a claim? | C14: CreateObject("Scripting.Dictionary"), then .Exists and .Add | D14: {=IF(Output!B5="","",Output!B5)} | E14: =IF(IFERROR(D14="",FALSE),"",IF(IFERROR(AND(ISNUMBER(D14),OR(ABS(D14-'Answer Key'!$C$13)<=0.0001)),FALSE),"✔ Correct","✘ Not yet"))
A15: 10 | B15: Complete TopDeniedPayer: build one dictionary that maps PayerID → PayerName (from the Payers sheet) and another that counts the claims with ClaimStatus "Denied" for each PayerID (Mac: a Collection for the names, and SlotFor plus an array for the counts). Write the PayerName with the most denied claims to Output!B6 and its count to Output!B7. The gray cell reads B6. | C15: d(key) = d(key) + 1 counts. Then loop over .Keys to find the largest | D15: {=IF(Output!B6="","",Output!B6)} | E15: =IF(IFERROR(D15="",FALSE),"",IF(IFERROR(OR(LOWER(TRIM(D15&""))=LOWER(TRIM('Answer Key'!$C$14&"")),LOWER(TRIM(D15&""))="py02"),FALSE),"✔ Correct","✘ Not yet"))
A16: 11 | B16: Snippet B reads five blood-glucose readings typed as text and adds them up, with an error handler that skips bad entries. What total does the last line print? Predict first, then run it to check. | C16: Resume Next continues after the line that failed | E16: =IF(IFERROR(D16="",FALSE),"",IF(IFERROR(AND(ISNUMBER(D16),OR(ABS(D16-'Answer Key'!$C$15)<=0.0001)),FALSE),"✔ Correct","✘ Not yet"))
A17: 12 | B17: Snippet C reads the same five values with On Error Resume Next instead of a handler. What total does it print? Predict first, then run it to check. | C17: When an assignment fails, what's left in the variable? | E17: =IF(IFERROR(D17="",FALSE),"",IF(IFERROR(AND(ISNUMBER(D17),OR(ABS(D17-'Answer Key'!$C$16)<=0.0001)),FALSE),"✔ Correct","✘ Not yet"))
A18: 13 | B18: Snippet D looks up a payer ID that doesn't exist (PY09), first with Application.Match and then with Application.WorksheetFunction.Match. The first prints a message. The second stops the macro with a run-time error. Type the error number. Predict first, then run it to check. | C18: The 'application-defined or object-defined' error number | E18: =IF(IFERROR(D18="",FALSE),"",IF(IFERROR(AND(ISNUMBER(D18),OR(ABS(D18-'Answer Key'!$C$17)<=0.0001)),FALSE),"✔ Correct","✘ Not yet"))

Sheet Patients
A1: PatientID | B1: FirstName | C1: LastName | D1: Sex | E1: DOB | F1: HeightIn | G1: WeightLb | H1: BMI
A2: PT10002 | B2: Brenda | C2: Peterson | D2: F | E2: 15760 | F2: 61.8 | G2: 180.4
A3: PT10005 | B3: Albert | C3: Romero | D3: M | E3: 10553 | F3: 70.4 | G3: 197.9
A4: PT10009 | B4: Wei | C4: Miller | D4: M | E4: 28636 | F4: 71.9 | G4: 228.9
A5: PT10010 | B5: Gloria | C5: Hill | D5: F | E5: 36352 | F5: 61.4 | G5: 197.4
A6: PT10011 | B6: Russell | C6: Sullivan | D6: M | E6: 17141 | F6: 73.6 | G6: 227.5
A7: PT10013 | B7: Brian | C7: Andrews | D7: M | E7: 18491 | F7: 70.7 | G7: 195.9
A8: PT10016 | B8: Danielle | C8: Kennedy | D8: F | E8: 37473 | F8: 63.1 | G8: 118.5
A9: PT10025 | B9: Ana | C9: Cox | D9: F | E9: 24896 | F9: 67.4 | G9: 204.9
A10: PT10031 | B10: Ana | C10: Petrov | D10: F | E10: 17581 | F10: 63.6 | G10: 167.8
A11: PT10032 | B11: Amber | C11: White | D11: F | E11: 35240 | F11: 66.4 | G11: 211.6
A12: PT10034 | B12: Ruth | C12: Stephens | D12: F | E12: 15426 | F12: 62.1 | G12: 120.4
A13: PT10037 | B13: Joseph | C13: Hayes | D13: M | E13: 11310 | F13: 67.1 | G13: 213.7
... A592: PT13991 | B592: Brittany | C592: Nakamura | D592: F | E592: 18890 | F592: 61 | G592: 169.7

Sheet Encounters
A1: EncounterID | B1: PatientID | C1: EncounterType | D1: DOB | E1: AdmitDateTime | F1: DischargeDateTime | G1: AgeAtAdmit | H1: LOSDays
A2: ENC110726 | B2: PT11101 | C2: Inpatient | D2: 19202 | E2: 45658.709 | F2: 45664.475
A3: ENC110756 | B3: PT12695 | C3: Inpatient | D3: 23663 | E3: 45659.547 | F3: 45662.672
A4: ENC110775 | B4: PT11545 | C4: Inpatient | D4: 9771 | E4: 45659.581 | F4: 45665.547
A5: ENC110850 | B5: PT13346 | C5: Observation | D5: 26418 | E5: 45661.76 | F5: 45662.747
A6: ENC110863 | B6: PT11889 | C6: Inpatient | D6: 23094 | E6: 45662.667 | F6: 45665.721
A7: ENC110866 | B7: PT13715 | C7: Inpatient | D7: 18388 | E7: 45662.719 | F7: 45669.528
A8: ENC110874 | B8: PT11204 | C8: Inpatient | D8: 17845 | E8: 45663.049 | F8: 45669.44
A9: ENC110922 | B9: PT10855 | C9: Inpatient | D9: 20312 | E9: 45663.838 | F9: 45666.548
A10: ENC110952 | B10: PT11420 | C10: Inpatient | D10: 10276 | E10: 45664.697 | F10: 45669.561
A11: ENC110967 | B11: PT11138 | C11: Inpatient | D11: 22399 | E11: 45665.533 | F11: 45668.497
A12: ENC111042 | B12: PT11114 | C12: Observation | D12: 27199 | E12: 45667.089 | F12: 45667.958
A13: ENC111045 | B13: PT10715 | C13: Inpatient | D13: 24490 | E13: 45667.349 | F13: 45674.822
... A506: ENC121742 | B506: PT12485 | C506: Observation | D506: 30424 | E506: 46019.497 | F506: 46020.358

Sheet Claims
A1: ClaimID | B1: PatientID | C1: PayerID | D1: ServiceDate | E1: BilledAmount | F1: AllowedAmount | G1: PaidAmount | H1: ClaimStatus | I1: DenialReason
A2: CLM510373 | B2: PT11301 | C2: PY04 | D2: 45664 | E2: 60997.07 | F2: 30654.9 | G2: 27159.4 | H2: Paid
A3: CLM510507 | B3: PT13958 | C3: PY05 | D3: 45660 | E3: 68643.68 | F3: 31462.37 | G3: 30017.6 | H3: Paid
A4: CLM510592 | B4: PT11141 | C4: PY02 | D4: 45660 | E4: 42255.73 | F4: 13047.25 | G4: 12315.71 | H4: Paid
A5: CLM510608 | B5: PT10550 | C5: PY01 | D5: 45660 | E5: 73228.36 | F5: 22265.26 | G5: 20075.87 | H5: Paid
A6: CLM510628 | B6: PT10644 | C6: PY01 | D6: 45662 | E6: 54996.54 | F6: 17120.19 | G6: 11110.26 | H6: Partially Paid | I6: Medical Necessity
A7: CLM510648 | B7: PT12641 | C7: PY04 | D7: 45660 | E7: 39934.8 | F7: 21363.41 | G7: 20073.51 | H7: Paid
A8: CLM510665 | B8: PT13985 | C8: PY01 | D8: 45660 | E8: 31966.98 | F8: 9267.73 | G8: 8183.77 | H8: Paid
A9: CLM510690 | B9: PT12910 | C9: PY05 | D9: 45660 | E9: 7588.98 | F9: 3711.94 | G9: 3173.06 | H9: Paid
A10: CLM510705 | B10: PT12494 | C10: PY03 | D10: 45661 | E10: 29625.63 | F10: 6212.61 | G10: 6212.61 | H10: Paid
A11: CLM510707 | B11: PT13218 | C11: PY06 | D11: 45664 | E11: 33984.5 | F11: 18709.86 | G11: 17246.29 | H11: Paid
A12: CLM510712 | B12: PT11367 | C12: PY04 | D12: 45658 | E12: 3571.22 | F12: 1956.39 | G12: 1682.98 | H12: Paid
A13: CLM510715 | B13: PT13365 | C13: PY03 | D13: 45658 | E13: 1557.95 | F13: 386.99 | G13: 386.99 | H13: Paid
A14: CLM510726 | B14: PT11101 | C14: PY01 | D14: 45664 | E14: 37731.01 | F14: 10734.46 | G14: 9887.43 | H14: Paid
A15: CLM510748 | B15: PT10252 | C15: PY05 | D15: 45659 | E15: 1740.98 | F15: 788.08 | G15: 692.75 | H15: Paid
A16: CLM510756 | B16: PT12695 | C16: PY04 | D16: 45662 | E16: 10621.58 | F16: 5352.73 | G16: 4693.62 | H16: Paid
A17: CLM510775 | B17: PT11545 | C17: PY01 | D17: 45665 | E17: 70175.49 | F17: 21426.85 | G17: 17319.22 | H17: Paid
A18: CLM510790 | B18: PT10695 | C18: PY03 | D18: 45659 | E18: 1281.12 | F18: 324.23 | G18: 324.23 | H18: Paid
... A23: CLM510874 | B23: PT11204 | C23: PY02 | D23: 45669 | E23: 29103.37 | F23: 8708.13 | G23: 8423.6 | H23: Paid
A24: CLM510885 | B24: PT10002 | C24: PY01 | D24: 45663 | E24: 3559.37 | F24: 1106.04 | G24: 756.22 | H24: Partially Paid | I24: Medical Necessity
A25: CLM510922 | B25: PT10855 | C25: PY01 | D25: 45666 | E25: 8674.56 | F25: 2879.25 | G25: 2617.71 | H25: Paid
A26: CLM510937 | B26: PT12542 | C26: PY01 | D26: 45664 | E26: 6122.44 | F26: 1914.16 | G26: 1777.85 | H26: Paid
A27: CLM510945 | B27: PT11582 | C27: PY02 | D27: 45664 | E27: 3493.47 | F27: 1093.58 | G27: 1082.74 | H27: Paid
A28: CLM510952 | B28: PT11420 | C28: PY02 | D28: 45669 | E28: 64067.75 | F28: 20016.48 | G28: 18893.1 | H28: Paid
A29: CLM510967 | B29: PT11138 | C29: PY06 | D29: 45668 | E29: 27045.66 | F29: 16252.36 | G29: 14232.83 | H29: Paid
A30: CLM511001 | B30: PT13009 | C30: PY04 | D30: 45666 | E30: 730.2 | F30: 413.15 | G30: 324.17 | H30: Paid
A31: CLM511003 | B31: PT11104 | C31: PY01 | D31: 45666 | E31: 1280.28 | F31: 0 | G31: 0 | H31: Appealed | I31: Medical Necessity
A32: CLM511042 | B32: PT11114 | C32: PY06 | D32: 45667 | E32: 9442.74 | F32: 4609.8 | G32: 4190.63 | H32: Paid
A33: CLM511045 | B33: PT10715 | C33: PY03 | D33: 45674 | E33: 80694.99 | F33: 19601.32 | G33: 19601.32 | H33: Paid
A34: CLM511056 | B34: PT13877 | C34: PY02 | D34: 45667 | E34: 1585.21 | F34: 469.21 | G34: 420.39 | H34: Paid
A35: CLM511063 | B35: PT10750 | C35: PY01 | D35: 45667 | E35: 1073.62 | F35: 322 | G35: 282.17 | H35: Paid
A36: CLM511064 | B36: PT10668 | C36: PY02 | D36: 45667 | E36: 623.05 | F36: 189.49 | G36: 185.51 | H36: Paid
A37: CLM511079 | B37: PT12060 | C37: PY06 | D37: 45675 | E37: 89500.47 | F37: 45787.79 | G37: 38103.02 | H37: Paid
A38: CLM511094 | B38: PT12193 | C38: PY01 | D38: 45670 | E38: 9169.12 | F38: 2826.7 | G38: 2521.59 | H38: Paid
A39: CLM511101 | B39: PT12264 | C39: PY01 | D39: 45671 | E39: 16418.17 | F39: 4712.25 | G39: 4441.08 | H39: Paid
A40: CLM511109 | B40: PT11371 | C40: PY01 | D40: 45675 | E40: 25943.27 | F40: 7926.9 | G40: 6751.23 | H40: Paid
A41: CLM511111 | B41: PT13426 | C41: PY03 | D41: 45669 | E41: 1475.58 | F41: 355.34 | G41: 355.34 | H41: Paid
A42: CLM511113 | B42: PT10076 | C42: PY02 | D42: 45669 | E42: 2095.02 | F42: 657.88 | G42: 608.01 | H42: Paid
A43: CLM511114 | B43: PT11101 | C43: PY01 | D43: 45676 | E43: 39804.2 | F43: 11344.04 | G43: 10414.01 | H43: Paid
... A56: CLM511251 | B56: PT12893 | C56: PY04 | D56: 45673 | E56: 8410.08 | F56: 4469.94 | G56: 3891.44 | H56: Paid
...

Sheet Payers
A1: PayerID | B1: PayerName | C1: PayerType
A2: PY01 | B2: Medicare | C2: Government
A3: PY02 | B3: Silverline Medicare Advantage | C3: Medicare Advantage
A4: PY03 | B4: State Medicaid | C4: Government
A5: PY04 | B5: Keystone Health Partners | C5: Commercial
A6: PY05 | B6: Evergreen Mutual Insurance | C6: Commercial
A7: PY06 | B7: Summit Choice PPO | C7: Commercial
A8: PY07 | B8: Self-Pay | C8: Self-Pay
A9: PY08 | B9: Workers' Compensation | C9: Workers' Comp

Sheet Output
A1: Output: your macros write their results here
A2: Don't type in column B. Run the macro named in column C and it fills the green cell. The gray cells on the Practice sheet read these cells.
A3: Result | B3: Value | C3: Written by (task)
A4: Number of different denial reasons (blanks ignored) | C4: CountDenialReasons (task 8)
A5: Number of different patients on the Claims sheet | C5: CountDistinctPatients (task 9)
A6: Payer with the most Denied claims (PayerName) | C6: TopDeniedPayer (task 10)
A7: …its number of Denied claims | C7: TopDeniedPayer (task 10)

Sheet Snippets
A1: Snippets for the predict-the-output tasks
A2: Read the code and type your prediction on the Practice sheet first. Then import starter/Snippets.bas, click inside the Sub, and press F5 to run it (Mac: Run → Run Sub/UserForm). Debug.Print writes to the Immediate window: press Ctrl + G on Windows, or choose View → Immediate Window on a Mac. Snippet D stops with a run-time error on purpose: note the number, then click End.
A4: Snippet A (task 7): ByVal vs ByRef. Run: SnippetA
A5: Sub AddFeeByVal(ByVal amount As Double)
A6: amount = amount + 25
A7: End Sub
A9: Sub AddFeeByRef(ByRef amount As Double)
A10: amount = amount + 25
A11: End Sub
A13: Sub SnippetA()
A14: Dim charge As Double
A15: charge = 100
... A64: End Sub

Sheet Bonus
A1: Lesson 5.4 · Bonus: a one-click payer scorecard
A2: Cedar Ridge's revenue-cycle director wants a payer scorecard she can rebuild with one click every month. Write BuildPayerSummary (start from starter/PayerSummary.bas) so that it does five things: 1. If the Claims or Payers sheet is missing, it shows a friendly message and stops without a run-time error. 2. It reads the Claims table into an array and uses a Scripting.Dictionary keyed by PayerID (Mac: a Collection plus arrays) to work out four numbers for each payer: Claims (number of rows), Billed (sum of BilledAmount), Paid (sum of PaidAmount), and Denied (rows with ClaimStatus "Denied"). 3. It skips, and counts, every row whose BilledAmount or PaidAmount is not a number. A blank cell is not a number, and a skipped row is left out of every column. 4. It writes a sheet named PayerSummary, clearing it first if it already exists. Row 1 holds the headers PayerID, PayerName, Claims, Billed, Paid, Denied, DenialRate (Denied ÷ Claims). Below it go one row per payer, sorted by Billed from largest to smallest, and then a TOTAL row: the word TOTAL in column A, the totals in C:F, and the overall rate in G. Two rows below TOTAL, column A holds the text Rows skipped and column B holds the count. 5. It restores ScreenUpdating and Calculation even when an error stops the macro.
A3: Type a formula or value in each yellow cell. The Check column turns green when your answer matches. Stuck? Read the hint, then the lesson guide. Answers: right-click a sheet tab → Unhide… → 'Bonus Key'.
A4: ="Score: "&COUNTIF(E6:E10,"✔*")&" of 4 auto-checked tasks correct"
A5: # | B5: Task | C5: Hint | D5: Your Answer | E5: Check
A6: B1 | B6: Run BuildPayerSummary. Which payer has the third-highest billed charges? (It's the PayerName in cell B4 of PayerSummary, and the gray cell reads it.) | C6: Range.Sort with Key1:=the Billed header cell, Order1:=xlDescending, Header:=xlYes | D6: {=IFERROR(IF(INDIRECT("'PayerSummary'!B4")="","",INDIRECT("'PayerSummary'!B4")),"")} | E6: =IF(IFERROR(D6="",FALSE),"",IF(IFERROR(OR(LOWER(TRIM(D6&""))=LOWER(TRIM('Bonus Key'!$C$5&"")),LOWER(TRIM(D6&""))="py04"),FALSE),"✔ Correct","✘ Not yet"))
A7: B2 | B7: What DenialRate does your PayerSummary show for Silverline Medicare Advantage? (The gray cell finds Silverline's row on PayerSummary and reads column G.) | C7: The array-in-a-dictionary pattern: copy it out, change it, put it back | D7: {=IFERROR(INDEX(INDIRECT("'PayerSummary'!G1:G40"),MATCH("Silverline Medicare Advantage",INDIRECT("'PayerSummary'!B1:B40"),0)),"")} | E7: =IF(IFERROR(D7="",FALSE),"",IF(IFERROR(AND(ISNUMBER(D7),OR(ABS(D7-'Bonus Key'!$C$6)<=0.00051,ABS(D7-'Bonus Key'!$C$6*100)<=0.051000000000000004)),FALSE),"✔ Correct","✘ Not yet"))
A8: B3 | B8: What total Paid does the TOTAL row of PayerSummary show? (The gray cell reads column E of the TOTAL row, and the check compares it to the cent.) | C8: Accumulate the totals in the same loop that fills the output array | D8: {=IFERROR(INDEX(INDIRECT("'PayerSummary'!E1:E40"),MATCH("TOTAL",INDIRECT("'PayerSummary'!A1:A40"),0)),"")} | E8: =IF(IFERROR(D8="",FALSE),"",IF(IFERROR(AND(ISNUMBER(D8),OR(ABS(D8-'Bonus Key'!$C$7)<=0.0051)),FALSE),"✔ Correct","✘ Not yet"))
A9: B4 | B9: How many claim rows did your macro skip because BilledAmount or PaidAmount was not a number? (The gray cell reads the number next to 'Rows skipped'.) | C9: A blank cell read into an array is Empty, and VarType(Empty) is vbEmpty | D9: {=IFERROR(INDEX(INDIRECT("'PayerSummary'!B1:B40"),MATCH("Rows skipped",INDIRECT("'PayerSummary'!A1:A40"),0)),"")} | E9: =IF(IFERROR(D9="",FALSE),"",IF(IFERROR(AND(ISNUMBER(D9),OR(ABS(D9-'Bonus Key'!$C$8)<=0.0001)),FALSE),"✔ Correct","✘ Not yet"))
A10: B5 | B10: Test the error handling. (1) Rename the Claims sheet to Claims_old and run BuildPayerSummary: you should get your friendly message, not a run-time error. (2) Rename it back. (3) Temporarily change the header text in the Claims sheet's BilledAmount cell (E1) to Billed and run the macro again: the Fail handler should report the missing column, and Formulas → Calculation Options should still show Automatic afterwards. (4) Put the header back and run the macro once more. | C10: Check before you change settings, and clean up in one place | E10: See key

Sheet Answer Key
A1: 🔑 Answer Key — Lesson 5.4
A2: Spoiler alert — try every task before reading this sheet. Column C is the value the Check column compares against. Column D is a sample solution; column E is that same formula, live, proving it works.
A4: # | B4: Task | C4: Answer | D4: Sample solution | E4: Live result | F4: Explanation
A5: 1 | B5: Write BMI(weightLb, heightIn) in a standard module (start from starter/HealthUDFs.bas). BMI = 703 × weight in pounds ÷ (height in inches)². It must return #VALUE! for a blank or text input and #NUM! for a zero or negative one. In the yellow cell, call it for the first patient on the Patients sheet (row 2, PT10002). Keep full precision. The check accepts 2 decimal places. | C5: 33.205873 | D5: ' In the yellow cell: =BMI(Patients!G2,Patients!F2) ' Tasks 1-2: body-mass index = 703 x weight (lb) / height (in) ^ 2 Public Function BMI(weightLb As Variant, heightIn As Variant) As Variant Dim w As Variant, h As Variant w = ArgValue(weightLb) h = ArgValue(heightIn) If Not IsNumberValue(w) Or Not IsNumberValue(h) Then BMI = CVErr(xlErrValue) ' blank or text input: #VALUE! ElseIf w <= 0 Or h <= 0 Then BMI = CVErr(xlErrNum) ' impossible measurement: #NUM! Else BMI = 703 * w / h ^ 2 End If End Function | E5: {=703*Patients!G2/Patients!F2^2} | F5: A Function hands back a value by assigning it to its own name (BMI = …). Because it's Public and sits in a standard module, Excel lists it with the built-in functions, so =BMI( works in any cell. The return type is Variant so the same function can return a number or an error value made by CVErr. The two helpers come from the starter module: ArgValue turns a cell reference into its value, and IsNumberValue rejects blanks and text. Brenda Peterson weighs 180.4 lb at 61.8 in, so BMI = 703 × 180.4 ÷ 61.8² ≈ 33.21. If the cell shows #NAME?, the function isn't in a standard module of *this* workbook, or macros are disabled.
A6: 2 | B6: Fill the yellow BMI column on the Patients sheet with your BMI function for every patient. Don't round inside the function: the column's number format already shows 1 decimal place. The gray cell counts the patients whose unrounded BMI is 30 or more (the usual adult obesity threshold). | C6: 258 | D6: =BMI([@WeightLb],[@HeightIn]) | E6: {=SUMPRODUCT(--(703*'Patients'!$G$2:$G$592/'Patients'!$F$2:$F$592^2>=30))} | F6: Type the formula in H2 (or =BMI(G2,F2), which does the same). A UDF behaves like any other function: write it once in the first row and the Excel Table copies it down as a calculated column, so each of the 591 rows recalculates whenever its height or weight changes. That's the payoff of a UDF over a macro, because a macro would write values once and go stale. The key's live formula does the same math with SUMPRODUCT, which shows a UDF is a convenience: anything it does with simple arithmetic you could also do with a formula.
A7: 3 | B7: Write AGEAT(dob, [asOf]): a person's age in completed years on the asOf date, or on today's date when asOf is left out (use IsMissing). Then fill the yellow AgeAtAdmit column on the Encounters sheet with each patient's age on the admission date. The gray cell averages your column, and the check compares that average to 2 decimal places. | C7: 60.077228 | D7: ' In the AgeAtAdmit column (G2): =AGEAT([@DOB],[@AdmitDateTime]) ' Task 3: age in completed years on asOf. Leave asOf out to use today's date. Public Function AGEAT(dob As Variant, Optional asOf As Variant) As Variant Dim birthValue As Variant, refValue As Variant Dim birth As Date, refDate As Date, years As Long birthValue = ArgValue(dob) If IsMissing(asOf) Then refValue = Date ' second argument left out: today Application.Volatile ' today changes, so recalculate every time Else refValue = ArgValue(asOf) End If If Not IsNumberValue(birthValue) Or Not IsNumberValue(refValue) Then AGEAT = CVErr(xlErrValue) Exit Function End If birth = CDate(birthValue) refDate = CDate(refValue) If refDate < birth Then AGEAT = CVErr(xlErrNum) ' asOf is before the date of birth Exit Function End If years = Year(refDate) - Year(birth) ' Birthday still to come in the asOf year? Then the person is a year younger. If DateSerial(Year(refDate), Month(birth), Day(birth)) > refDate Then years = years - 1 AGEAT = years End Function | E7: {=SUMPRODUCT(YEAR('Encounters'!$E$2:$E$506)-YEAR('Encounters'!$D$2:$D$506)-(MONTH('Encounters'!$E$2:$E$506)*100+DAY('Encounters'!$E$2:$E$506)<MONTH('Encounters'!$D$2:$D$506)*100+DAY('Encounters'!$D$2:$D$506)))/ROWS('Encounters'!$D$2:$D$506)} | F7: IsMissing works only on an Optional Variant argument, which is why asOf is declared As Variant. The tricky part is the birthday: Year(asOf) - Year(dob) counts calendar years, so it's one too high whenever the birthday falls later in the year than the admission. DateSerial(Year(asOf), Month(dob), Day(dob)) builds this year's birthday. If that's after asOf, subtract 1. DateDiff("yyyy", dob, asOf) has the same flaw because it counts year boundaries, not birthdays. On this data it is wrong for 272 of 505 stays and gives an average of 60.62 instead of 60.08.
A8: 4 | B8: Write LOSDAYS(admitDateTime, dischargeDateTime): the number of midnights between admission and discharge, or #VALUE! when an input isn't a date or the discharge date-time is earlier than the admission date-time. Fill the yellow LOSDays column on the Encounters sheet. The gray cell adds up your column and skips error cells. What is the total? | C8: 1926 | D8: ' In the LOSDays column (H2): =LOSDAYS([@AdmitDateTime],[@DischargeDateTime]) ' Tasks 4-5: length of stay = midnights between admission and discharge. ' #VALUE! when an input isn't a date or the discharge is before the admission. Public Function LOSDAYS(admitDateTime As Variant, dischargeDateTime As Variant) As Variant Dim a As Variant, d As Variant a = ArgValue(admitDateTime) d = ArgValue(dischargeDateTime) If Not IsNumberValue(a) Or Not IsNumberValue(d) Then LOSDAYS = CVErr(xlErrValue) ElseIf CDate(d) < CDate(a) Then LOSDAYS = CVErr(xlErrValue) ' discharge before admission: a data-entry error Else LOSDAYS = DateDiff("d", CDate(a), CDate(d)) ' "d" counts the midnights crossed End If End Function | E8: {=SUMPRODUCT(('Encounters'!$F$2:$F$506>='Encounters'!$E$2:$E$506)*(INT('Encounters'!$F$2:$F$506)-INT('Encounters'!$E$2:$E$506)))} | F8: DateDiff("d", admit, discharge) counts the calendar-day boundaries crossed, so a patient admitted at 23:00 and discharged at 01:00 the next morning has a stay of 1 midnight, which is how inpatient days are counted. Returning CVErr(xlErrValue) makes the bad rows impossible to miss, and it keeps them out of totals: the gray cell uses AGGREGATE(9,6,…) (9 = SUM, 6 = ignore error values). If you had returned 0 or a negative number instead, it would have silently dragged the total down.
A9: 5 | B9: How many rows does your LOSDays column flag with #VALUE!? The gray cell counts them. (Each one is a data-entry error to send back to Health Information Management.) | C9: 4 | D9: =COUNTIF(tblEncounters[LOSDays],"#VALUE!") | E9: {=SUMPRODUCT(--('Encounters'!$F$2:$F$506<'Encounters'!$E$2:$E$506))} | F9: Nothing new to type here: the gray cell already holds this formula. COUNTIF can count one specific error value when you give the error's text as the criteria. Three discharges were keyed with the year 2024, and one same-day stay has its discharge time keyed 12 hours early (an AM/PM slip). Compare full date-times, not just dates: a check like DateValue(d) < DateValue(a) finds only 3 of the 4 problems, because the AM/PM slip has the right date. The check counts #VALUE! only, so a function that returns #N/A or #NUM! for these rows shows ✘.
A10: 6 | B10: Write DENIALRATE(statusRange, [statusToCount]): the share of non-blank cells in statusRange whose text equals statusToCount (ignoring case). statusToCount is Optional and defaults to "Denied". Return #DIV/0! if the range has no non-blank cells. In the yellow cell, call DENIALRATE on the ClaimStatus column of the Claims sheet and leave out the second argument. The cell is already formatted as a percentage. | C10: 0.076852699 | D10: ' In the yellow cell: =DENIALRATE(tblClaims[ClaimStatus]) ' (or =DENIALRATE(Claims!H2:H1094)) ' Task 6: share of non-blank cells in statusRange that equal statusToCount. Public Function DENIALRATE(statusRange As Range, Optional statusToCount As String = "Denied") As Variant Dim cell As Range, total As Long, hits As Long For Each cell In statusRange.Cells If Not IsEmpty(cell.Value) And Not IsError(cell.Value) Then total = total + 1 If StrComp(Trim$(CStr(cell.Value)), statusToCount, vbTextCompare) = 0 Then hits = hits + 1 End If Next cell If total = 0 Then DENIALRATE = CVErr(xlErrDiv0) ' nothing to divide by: #DIV/0! Else DENIALRATE = hits / total End If End Function | E10: {=COUNTIF('Claims'!$H$2:$H$1094,"Denied")/COUNTA('Claims'!$H$2:$H$1094)} | F10: A typed Optional argument gets its default in the declaration (= "Denied"), so you don't need IsMissing. Declaring statusRange As Range lets you loop over its cells, and it means Excel returns #VALUE! by itself if someone passes a plain number. 84 of 1,093 claims are Denied. Because statusToCount is a parameter, the same function answers other questions too: =DENIALRATE(tblClaims[ClaimStatus],"Pending") gives the pending rate. The key's live cell uses COUNTIF/COUNTA because your UDF isn't in the downloaded .xlsx.
A11: 7 | B11: Snippet A on the Snippets sheet passes a $100 charge to AddFeeByVal and AddFeeByRef. What number does Debug.Print charge show? Predict first, then run it to check. | C11: 125 | D11: Trace it: `AddFeeByVal charge` adds 25 to a **copy** (charge stays 100). `AddFeeByRef charge` adds 25 to the caller's variable itself (125). `AddFeeByRef (charge)` looks the same, but the parentheses turn `charge` into an expression, so VBA passes a temporary copy and charge stays **125**. | E11: — | F11: VBA passes arguments ByRef by default, so a procedure can change the caller's variable. Write ByVal when a procedure must not do that. The parentheses trap catches experienced developers: when you call a Sub without Call, wrapping one argument in parentheses evaluates it first and passes the result, which silently turns ByRef into ByVal. Call Subs without parentheses, or use Call AddFeeByRef(charge).
A12: 8 | B12: Complete CountDenialReasons in starter/ClaimDictionaries.bas: add every non-blank DenialReason on the Claims sheet to a Collection, using the reason itself as the key, so each reason is kept once. The macro writes the Collection's Count to Output!B4, and the gray cell reads it. | C12: 7 | D12: ' Task 8: how many different denial reasons? A Collection refuses a duplicate ' key, so adding every reason with Key:=reason keeps exactly one of each. Public Sub CountDenialReasons() Dim ws As Worksheet, claims As Variant Dim reasonCol As Long, r As Long, reason As String Dim reasons As Collection Set ws = ThisWorkbook.Worksheets("Claims") claims = ws.Range("A1").CurrentRegion.Value ' header + data in one 2-D array reasonCol = HeaderColumn(ws, "DenialReason") Set reasons = New Collection For r = 2 To UBound(claims, 1) reason = Trim$(CStr(claims(r, reasonCol))) ' a blank cell becomes "" If Len(reason) > 0 Then AddIfNew reasons, reason Next r ThisWorkbook.Worksheets("Output").Range("B4").Value = reasons.Count End Sub ' Adds keyText to a Collection once. Returns False if it was already there. Private Function AddIfNew(col As Collection, ByVal keyText As String) As Boolean On Error Resume Next col.Add Item:=keyText, Key:=keyText ' error 457 if the key already exists AddIfNew = (Err.Number = 0) On Error GoTo 0 End Function | E12: {=ROWS(_xlfn.UNIQUE(_xlfn._xlws.FILTER('Claims'!$I$2:$I$1094,'Claims'!$I$2:$I$1094<>"")))} | F12: A Collection key must be unique, so adding a duplicate key raises run-time error 457. AddIfNew traps that error with On Error Resume Next, reads Err.Number, and switches trapping off again straight away with On Error GoTo 0. The 7 reasons are: Authorization Required, Coding Error, Duplicate Claim, Eligibility / Coverage, Medical Necessity, Missing Documentation, Timely Filing. Skipping blanks matters: most claims have no denial reason, and counting the empty string as a reason would give 8.
A13: 9 | B13: Complete CountDistinctPatients: add every PatientID on the Claims sheet to a Scripting.Dictionary (Mac: a Collection) once, then write the number of keys to Output!B5. How many different patients had a claim? | C13: 631 | D13: ' Task 9: how many different patients have a claim? Dictionary keys are unique. Public Sub CountDistinctPatients() Dim ws As Worksheet, claims As Variant Dim patientCol As Long, r As Long Dim patients As Object ' late-bound Scripting.Dictionary Set ws = ThisWorkbook.Worksheets("Claims") claims = ws.Range("A1").CurrentRegion.Value patientCol = HeaderColumn(ws, "PatientID") Set patients = CreateObject("Scripting.Dictionary") For r = 2 To UBound(claims, 1) If Not patients.Exists(claims(r, patientCol)) Then patients.Add claims(r, patientCol), 1 End If Next r ThisWorkbook.Worksheets("Output").Range("B5").Value = patients.Count End Sub | E13: {=ROWS(_xlfn.UNIQUE('Claims'!$B$2:$B$1094))} | F13: .Exists asks whether a key is already in the dictionary, so each PatientID is added once and .Count is the number of different patients. 1,093 claims come from 631 patients because 265 patients had more than one claim. Dim patients As Object with CreateObject is late binding: it needs no reference to the Scripting Runtime library, so the file works on any Windows PC. In Microsoft 365 the key's =ROWS(UNIQUE(…)) gives the same answer, but the dictionary pattern scales to jobs a formula can't do, like the bonus.
A14: 10 | B14: Complete TopDeniedPayer: build one dictionary that maps PayerID → PayerName (from the Payers sheet) and another that counts the claims with ClaimStatus "Denied" for each PayerID (Mac: a Collection for the names, and SlotFor plus an array for the counts). Write the PayerName with the most denied claims to Output!B6 and its count to Output!B7. The gray cell reads B6. | C14: Silverline Medicare Advantage | D14: ' Task 10: which payer has the most Denied claims? Two dictionaries: ' one to look up payer names, one to count. Public Sub TopDeniedPayer() Dim wsClaims As Worksheet, claims As Variant, payers As Variant Dim payerCol As Long, statusCol As Long, r As Long Dim payerNames As Object, deniedCount As Object Dim payerID As Variant, bestID As String, bestCount As Long ' 1. Lookup dictionary: PayerID -> PayerName Set payerNames = CreateObject("Scripting.Dictionary") payers = ThisWorkbook.Worksheets("Payers").Range("A1").CurrentRegion.Value For r = 2 To UBound(payers, 1) payerNames(payers(r, 1)) = payers(r, 2) ' assigning to a new key adds it Next r ' 2. Counting dictionary: PayerID -> number of Denied claims Set wsClaims = ThisWorkbook.Worksheets("Claims") claims = wsClaims.Range("A1").CurrentRegion.Value payerCol = HeaderColumn(wsClaims, "PayerID") statusCol = HeaderColumn(wsClaims, "ClaimStatus") Set deniedCount = CreateObject("Scripting.Dictionary") For r = 2 To UBound(claims, 1) If claims(r, statusCol) = "Denied" Then ' Reading a key that isn't there returns Empty (and adds it); Empty + 1 = 1 deniedCount(claims(r, payerCol)) = deniedCount(claims(r, payerCol)) + 1 End If Next r ' 3. Keep the largest count (on a tie, the payer seen first wins) For Each payerID In deniedCount.Keys If deniedCount(payerID) > bestCount Then bestCount = deniedCount(payerID) bestID = payerID End If Next payerID With ThisWorkbook.Worksheets("Output") .Range("B6").Value = payerNames(bestID) .Range("B7").Value = bestCount End With End Sub | E14: {=INDEX('Payers'!$B$2:$B$9,MATCH(MAX(COUNTIFS('Claims'!$C$2:$C$1094,'Payers'!$A$2:$A$9,'Claims'!$H$2:$H$1094,"Denied")),COUNTIFS('Claims'!$C$2:$C$1094,'Payers'!$A$2:$A$9,'Claims'!$H$2:$H$1094,"Denied"),0))} | F14: deniedCount(id) = deniedCount(id) + 1 is the counting pattern: reading a key that isn't there yet returns Empty (and quietly adds the key), and Empty + 1 = 1. Then one loop over .Keys keeps the largest count. The lookup dictionary replaces a VLOOKUP inside the loop. Note that the payer with the most claims overall is Medicare (270 claims), but the most *denials* come from Silverline Medicare Advantage: 22 of its 180 claims.
A15: 11 | B15: Snippet B reads five blood-glucose readings typed as text and adds them up, with an error handler that skips bad entries. What total does the last line print? Predict first, then run it to check. | C15: 303 | D15: CLng fails (run-time error 13, Type mismatch) on "abc" and on the empty string. Each time, VBA jumps to BadReading, prints a line, and `Resume Next` continues with the statement **after** the one that failed, which is `Next i`. So the bad items add nothing: 120 + 95 + 88 = **303**. | E15: — | F15: On Error GoTo label sends any run-time error to the handler, and the Exit Sub before the label keeps normal runs out of it. Inside the handler, Err.Number says what went wrong (13 = Type mismatch). Resume Next skips the failing statement, Resume retries it (an endless loop here, because "abc" never becomes a number), and Resume SomeLabel continues at a label.
A16: 12 | B16: Snippet C reads the same five values with On Error Resume Next instead of a handler. What total does it print? Predict first, then run it to check. | C16: 518 | D16: When `CLng("abc")` fails, the assignment never happens, so `reading` still holds 120 from the line before, and it's added again. The same thing happens for "" (reading is still 95). 120 + 120 + 95 + 95 + 88 = **518**. | E16: — | F16: On Error Resume Next doesn't fix an error. It hides it. The variable keeps its previous value and the code carries on with wrong data: here 215 phantom units of glucose. Keep Resume Next to the one line you expect might fail, check Err.Number right after it, and switch back with On Error GoTo 0. AddIfNew in task 8 follows that pattern.
A17: 13 | B17: Snippet D looks up a payer ID that doesn't exist (PY09), first with Application.Match and then with Application.WorksheetFunction.Match. The first prints a message. The second stops the macro with a run-time error. Type the error number. Predict first, then run it to check. | C17: 1004 | D17: `Application.Match` returns the error **value** Error 2042 (#N/A), which `IsError` detects, so the code prints "Application.Match: not found". `WorksheetFunction.Match` raises a run-time **error** instead: **1004**, *Unable to get the Match property of the WorksheetFunction class*. | E17: — | F17: Both call Excel's MATCH, but they report failure differently. Use Application.Match (result in a Variant, then IsError) when "not found" is a normal outcome, as in the HeaderColumn helper. WorksheetFunction.Match only makes sense when a miss is a real error that your handler should catch. The same split applies to VLOOKUP, INDEX, and the other lookup functions.

Sheet Bonus Key
A1: 🔑 Bonus Key — Lesson 5.4
A2: Spoiler alert — try every task before reading this sheet. Column C is the value the Check column compares against. Column D is a sample solution; column E is that same formula, live, proving it works.
A4: # | B4: Task | C4: Answer | D4: Sample solution | E4: Live result | F4: Explanation
A5: B1 | B5: Run BuildPayerSummary. Which payer has the third-highest billed charges? (It's the PayerName in cell B4 of PayerSummary, and the gray cell reads it.) | C5: Keystone Health Partners | D5: Public Sub BuildPayerSummary() Dim wsClaims As Worksheet, wsOut As Worksheet Dim claims As Variant, payers As Variant, outData() As Variant Dim payerNames As Object, stats As Object Dim colPayer As Long, colBilled As Long, colPaid As Long, colStatus As Long Dim r As Long, n As Long, totalRow As Long, skipped As Long Dim payerID As Variant, s As Variant Dim totClaims As Long, totDenied As Long, totBilled As Double, totPaid As Double Dim prevCalc As Long ' 1. Check first: a friendly message beats a crash If Not SheetExists("Claims") Or Not SheetExists("Payers") Then MsgBox "BuildPayerSummary needs a sheet named 'Claims' and a sheet named 'Payers'." & vbNewLine & _ "One of them is missing or has been renamed. Fix that, then run the macro again.", _ vbExclamation, "Payer summary" Exit Sub End If ' 2. From here on, any run-time error jumps to Fail, which restores Excel's settings prevCalc = Application.Calculation On Error GoTo Fail Application.ScreenUpdating = False Application.Calculation = xlCalculationManual Set wsClaims = ThisWorkbook.Worksheets("Claims") claims = wsClaims.Range("A1").CurrentRegion.Value2 ' Value2: plain numbers, no Currency/Date types colPayer = HeaderColumn(wsClaims, "PayerID") colBilled = HeaderColumn(wsClaims, "BilledAmount") colPaid = HeaderColumn(wsClaims, "PaidAmount") colStatus = HeaderColumn(wsClaims, "ClaimStatus") payers = ThisWorkbook.Worksheets("Payers").Range("A1").CurrentRegion.Value2 ' 3. Lookup dictionary: PayerID -> PayerName Set payerNames = CreateObject("Scripting.Dictionary") For r = 2 To UBound(payers, 1) payerNames(payers(r, 1)) = payers(r, 2) Next r ' 4. One pass over the claims: PayerID -> Array(claims, billed, paid, denied) Set stats = CreateObject("Scripting.Dictionary") For r = 2 To UBound(claims, 1) If IsNumberValue(claims(r, colBilled)) And IsNumberValue(claims(r, colPaid)) Then payerID = claims(r, colPayer) If Not stats.Exists(payerID) Then stats.Add payerID, Array(0, 0, 0, 0) s = stats(payerID) ' copy the array out of the dictionary... s(0) = s(0) + 1 s(1) = s(1) + claims(r, colBilled) s(2) = s(2) + claims(r, colPaid) If claims(r, colStatus) = "Denied" Then s(3) = s(3) + 1 stats(payerID) = s ' ...and put it back: stats(payerID)(0) = 1 would not stick Else skipped = skipped + 1 ' blank or text amount End If Next r n = stats.Count If n = 0 Then Err.Raise vbObjectError + 514, "BuildPayerSummary", "No claim rows with numeric amounts were found." ' 5. Header + one row per payer, built in memory, plus the running totals ReDim outData(1 To n + 1, 1 To 7) outData(1, 1) = "PayerID": outData(1, 2) = "PayerName": outData(1, 3) = "Claims" outData(1, 4) = "Billed": outData(1, 5) = "Paid": outData(1, 6) = "Denied": outData(1, 7) = "DenialRate" r = 1 For Each payerID In stats.Keys r = r + 1 s = stats(payerID) outData(r, 1) = payerID If payerNames.Exists(payerID) Then outData(r, 2) = payerNames(payerID) Else outData(r, 2) = "(unknown payer)" End If outData(r, 3) = s(0): outData(r, 4) = s(1): outData(r, 5) = s(2): outData(r, 6) = s(3) outData(r, 7) = s(3) / s(0) totClaims = totClaims + s(0): totBilled = totBilled + s(1) totPaid = totPaid + s(2): totDenied = totDenied + s(3) Next payerID ' 6. A fresh output sheet: clear it if it exists, add it if it doesn't If SheetExists(OUT_SHEET) Then Set wsOut = ThisWorkbook.Worksheets(OUT_SHEET) wsOut.Cells.Clear Else Set wsOut = ThisWorkbook.Worksheets.Add(After:=ThisWorkbook.Worksheets("Payers")) wsOut.Name = OUT_SHEET End If ' 7. Write the block in one go, sort the payer rows by Billed (largest ' first), then add the TOTAL row and the skipped-rows line With wsOut .Range("A1").Resize(n + 1, 7).Value = outData .Range("A1").Resize(n + 1, 7).Sort Key1:=.Range("D1"), Order1:=xlDescending, Header:=xlYes totalRow = n + 2 .Cells(totalRow, 1).Value = "TOTAL" .Cells(totalRow, 3).Value = totClaims .Cells(totalRow, 4).Value = totBilled .Cells(totalRow, 5).Value = totPaid .Cells(totalRow, 6).Value = totDenied .Cells(totalRow, 7).Value = totDenied / totClaims .Cells(totalRow + 2, 1).Value = "Rows skipped" .Cells(totalRow + 2, 2).Value = skipped .Range("D:E").NumberFormat = "#,##0.00" .Range("G:G").NumberFormat = "0.0%" .Rows(1).Font.Bold = True .Rows(totalRow).Font.Bold = True .Columns("A:G").AutoFit End With CleanExit: On Error Resume Next ' cleanup must never raise an error of its own Application.Calculation = prevCalc Application.ScreenUpdating = True Exit Sub Fail: MsgBox "BuildPayerSummary stopped: " & Err.Description & " (error " & Err.Number & ")", _ vbCritical, "Payer summary" Resume CleanExit End Sub ' --------------------------------------------------------------------- ' Helpers ' --------------------------------------------------------------------- ' True if this workbook has a sheet with that name. Private Function SheetExists(ByVal sheetName As String) As Boolean Dim ws As Worksheet On Error Resume Next Set ws = ThisWorkbook.Worksheets(sheetName) ' error 9 if there is no such sheet On Error GoTo 0 SheetExists = Not ws Is Nothing End Function ' Column number of a header in row 1. Raises a clear error if it is missing. Private Function HeaderColumn(ws As Worksheet, ByVal headerText As String) As Long Dim pos As Variant pos = Application.Match(headerText, ws.Rows(1), 0) If IsError(pos) Then Err.Raise vbObjectError + 513, "HeaderColumn", _ "Column '" & headerText & "' was not found on sheet '" & ws.Name & "'." End If HeaderColumn = CLng(pos) End Function ' True for real numbers (a blank cell or text is not a number). Private Function IsNumberValue(v As Variant) As Boolean Select Case VarType(v) Case vbInteger, vbLong, vbSingle, vbDouble, vbCurrency, vbDecimal, vbByte IsNumberValue = True Case Else IsNumberValue = False End Select End Function | E5: {=INDEX(_xlfn.SORTBY('Payers'!$B$2:$B$9,SUMIFS('Claims'!$E$2:$E$1094,'Claims'!$C$2:$C$1094,'Payers'!$A$2:$A$9),-1),3)} | F5: The dictionary loop collects the totals in whatever order payers first appear. Sorting the written block, header excluded, puts the biggest payers on top: Medicare, Silverline Medicare Advantage, Keystone Health Partners. Third place is close (Keystone Health Partners billed 2,552,628.44 against 2,544,075.24 for State Medicaid), so an unsorted or wrongly sorted table shows ✘. The macro writes the whole block with one .Value = outData assignment, which is much faster than writing cell by cell. Mac: the Collection version is in solutions/PayerSummaryMac_Solution.bas.
A6: B2 | B6: What DenialRate does your PayerSummary show for Silverline Medicare Advantage? (The gray cell finds Silverline's row on PayerSummary and reads column G.) | C6: 0.11299435 | D6: Read it from PayerSummary column G. Formula cross-check (blank and text amounts excluded): `=COUNTIFS(tblClaims[PayerID],"PY02",tblClaims[ClaimStatus],"Denied",tblClaims[BilledAmount],">=0")/COUNTIFS(tblClaims[PayerID],"PY02",tblClaims[BilledAmount],">=0")` | E6: {=COUNTIFS('Claims'!$C$2:$C$1094,"PY02",'Claims'!$H$2:$H$1094,"Denied",'Claims'!$E$2:$E$1094,">=0")/COUNTIFS('Claims'!$C$2:$C$1094,"PY02",'Claims'!$E$2:$E$1094,">=0")} | F6: Silverline has 20 denied claims out of 177 kept rows. One Silverline denial has a blank BilledAmount. IsNumeric(Empty) returns True, so a macro that tests amounts with IsNumeric keeps that row and reports 11.8% instead of 11.3%. Test the type with VarType instead, as IsNumberValue does. Also watch the array trap: stats(id)(0) = stats(id)(0) + 1 changes a temporary copy and the dictionary never sees it. Copy the array out, change it, and assign it back.
A7: B3 | B7: What total Paid does the TOTAL row of PayerSummary show? (The gray cell reads column E of the TOTAL row, and the check compares it to the cent.) | C7: 4440116.7 | D7: Read it from the TOTAL row, column E. Formula cross-check: `=SUMIFS(tblClaims[PaidAmount],tblClaims[BilledAmount],">=0")` | E7: {=SUMIFS('Claims'!$G$2:$G$1094,'Claims'!$E$2:$E$1094,">=0")} | F7: The macro adds each payer's figures to running totals while it builds the output array, then writes the TOTAL row after sorting, so the sort can't move it. It covers 1,088 claims and $16,722,301.02 billed. Writing the TOTAL row before sorting is a classic bug: Range.Sort would treat it as a payer and sort it to the top.
A8: B4 | B8: How many claim rows did your macro skip because BilledAmount or PaidAmount was not a number? (The gray cell reads the number next to 'Rows skipped'.) | C8: 5 | D8: Read it from the cell next to *Rows skipped*. Formula cross-check: `=ROWS(tblClaims[BilledAmount])-COUNT(tblClaims[BilledAmount])` | E8: {=ROWS('Claims'!$E$2:$E$1094)-COUNT('Claims'!$E$2:$E$1094)} | F8: Filter the Claims sheet's BilledAmount column to find them: two are blank and three hold text (N/A, VOID). Without the check, s(1) + "N/A" raises run-time error 13 (Type mismatch), the handler stops the macro, and nobody gets a scorecard. Counting and reporting skipped rows is better than silently dropping them, because the director can see that 5 claims need fixing at the source.
A9: B5 | B9: Test the error handling. (1) Rename the Claims sheet to Claims_old and run BuildPayerSummary: you should get your friendly message, not a run-time error. (2) Rename it back. (3) Temporarily change the header text in the Claims sheet's BilledAmount cell (E1) to Billed and run the macro again: the Fail handler should report the missing column, and Formulas → Calculation Options should still show Automatic afterwards. (4) Put the header back and run the macro once more. | D9: 1. With Claims renamed, `SheetExists("Claims")` is False, so the macro shows the friendly MsgBox and exits **before** it changes any setting. 2. With the header renamed, `HeaderColumn` raises error vbObjectError + 513. HeaderColumn has no handler of its own, so the error travels up to BuildPayerSummary's `Fail` handler, which shows *Column 'BilledAmount' was not found on sheet 'Claims'*. Then `Resume CleanExit` restores Calculation and ScreenUpdating. 3. If Calculation Options shows Manual after the error, your error path skipped the cleanup block. Set it back with **Formulas → Calculation Options → Automatic**, then route the handler through `Resume CleanExit`. (Excel usually switches ScreenUpdating back on by itself when a macro ends, but the calculation mode stays manual for every open workbook until someone changes it.) | E9: — | F9: Good error handling has two layers. Validate the things you can predict (a missing sheet) and explain them in plain language. Trap everything else in one handler that tells the user what happened and always runs the cleanup code. Because errors travel up the call stack until they meet a handler, the custom error raised in a helper function is reported by the main macro's handler.
