Workbook
Name ReportDate: Lists!$N$2
Name ExpiringWindowDays: Lists!$N$3

Sheet Start Here
B2: Lesson 3.2
B3: Data Validation & Conditional Formatting
B4: Intermediate · about 55 minutes · Bluestone Health System (fictional)
B6: What you'll learn
B7: • | C7: Restrict entries with list, number, date, length, and custom-formula validation
B8: • | C8: Build dependent drop-down lists
B9: • | C9: Highlight what matters with conditional formatting rules, data bars, color scales, and icon sets
B10: • | C10: Write formula-based rules that format entire rows
B12: How to use this workbook
B13: 1. Read the guide | C13: The lesson guide (README) explains each skill with examples: https://github.com/lmansf/learn-excel/tree/main/03-data-analysis/02-data-validation-conditional-formatting
B14: 2. Practice | C14: Go to the 'Practice' sheet. Type a formula or value into each yellow cell.
B15: 3. Check yourself | C15: The Check column shows ✔ Correct (green) or ✘ Not yet (red). Tasks marked 'See key' are checked by comparing with the answer key.
B16: 4. Bonus | C16: Finished? Try the harder 'Bonus' sheet.
B17: 5. Answers | C17: The 'Answer Key' and 'Bonus Key' sheets are hidden. Right-click any sheet tab → Unhide… → pick one → OK. (Try first!)
B18: Note | C18: Part A of the practice uses IntakeLog and Lists. Part B uses Labs, Supplies, and Census. The bonus uses Huddle and NovCensus.
B19: Note | C19: ReportDate (12/31/2025) and ExpiringWindowDays (90) are named cells on the Lists sheet. Use the names in your rules.
B20: Note | C20: Circle Invalid Data circles disappear when you save or close the file. They are a checking tool, not formatting.
B22: Color legend
B23: Yellow cell | C23: Your answer goes here.
B24: Gray cell | C24: Pre-filled summary formula — it reads the work you did on another sheet.
B25: ✔ Correct | C25: Your answer matches the key.
B26: ✘ Not yet | C26: Not matching yet — check the hint and try again.
B28: Sheets in this workbook
B29: IntakeLog | C29: Data: 50 rows — Excel Table 'tblIntake'
B30: Labs | C30: Data: 321 rows — Excel Table 'tblLabs'
B31: Supplies | C31: Data: 257 rows — Excel Table 'tblSupplies'
B32: Census | C32: Data: 61 rows — Excel Table 'tblCensus'
B33: NovCensus | C33: Data: 450 rows — Excel Table 'tblNovCensus'
B34: About the data | C34: A December 2025 Patient Access intake log with entry errors, STAT lab results from the three ICUs (Jul–Dec 2025), the system supply inventory (12/31/2025 snapshot), and Medical-Surgical 5 East's daily census (Nov–Dec 2025). The bonus adds a bed-huddle board for every inpatient unit.
B35: Disclaimer | C35: All people, places, and numbers are synthetic and fictional. Not clinical guidance.

Sheet Practice
A1: Lesson 3.2 · Practice
A2: Part A (tasks 1–6) uses the IntakeLog and Lists sheets. Add each validation rule, then click the arrow on Data → Data Validation → Circle Invalid Data and count the red circles. Part B (tasks 7–13) uses the Labs, Supplies, and Census sheets. Create each conditional formatting rule, then answer the question about what it highlights. Type the number you count, or write a formula that calculates it.
A3: Type a formula or value in each yellow cell. The Check column turns green when your answer matches. Stuck? Read the hint, then the lesson guide. Answers: right-click a sheet tab → Unhide… → 'Answer Key'.
A4: ="Score: "&COUNTIF(E6:E18,"✔*")&" of 13 auto-checked tasks correct"
A5: # | B5: Task | C5: Hint | D5: Your Answer | E5: Check
A6: 1 | B6: IntakeLog, Payer column (F2:F51): add a List validation whose Source is the payer list on the Lists sheet (Lists!$A$2:$A$9). Then circle invalid data. How many Payer cells are circled? | C6: Data → Data Validation → Allow: List | E6: =IF(IFERROR(D6="",FALSE),"",IF(IFERROR(AND(ISNUMBER(D6),OR(ABS(D6-'Answer Key'!$C$5)<=0.0001)),FALSE),"✔ Correct","✘ Not yet"))
A7: 2 | B7: IntakeLog, VisitDate (B2:B51): the log covers December 2025 only. Allow a Date between 12/01/2025 and 12/31/2025 (type =DATE(2025,12,1) and =DATE(2025,12,31) in the boxes so it works in any regional setting). How many VisitDate cells are circled? | C7: Allow: Date, Data: between | E7: =IF(IFERROR(D7="",FALSE),"",IF(IFERROR(AND(ISNUMBER(D7),OR(ABS(D7-'Answer Key'!$C$6)<=0.0001)),FALSE),"✔ Correct","✘ Not yet"))
A8: 3 | B8: IntakeLog, CopayAmt (G2:G51): allow a Decimal between 0 and 100. On the Input Message tab, add the title Copay and the message "Enter the amount collected, $0 to $100." Leave the Error Alert style as Stop. How many CopayAmt cells are circled? | C8: Allow: Decimal. Between includes both limits | E8: =IF(IFERROR(D8="",FALSE),"",IF(IFERROR(AND(ISNUMBER(D8),OR(ABS(D8-'Answer Key'!$C$7)<=0.0001)),FALSE),"✔ Correct","✘ Not yet"))
A9: 4 | B9: IntakeLog, ZIP (E2:E51): allow Text length equal to 5. How many ZIP cells are circled? | C9: Allow: Text length, Data: equal to | E9: =IF(IFERROR(D9="",FALSE),"",IF(IFERROR(AND(ISNUMBER(D9),OR(ABS(D9-'Answer Key'!$C$8)<=0.0001)),FALSE),"✔ Correct","✘ Not yet"))
A10: 5 | B10: IntakeLog, MRN (C2:C51): an MRN must be exactly 8 characters, and all of them digits. Select the column with C2 as the active cell and add a Custom validation rule that is TRUE only for a valid MRN. How many MRN cells are circled? | C10: Combine a LEN test with an ISNUMBER(--C2) test inside AND, written for the active cell C2 | E10: =IF(IFERROR(D10="",FALSE),"",IF(IFERROR(AND(ISNUMBER(D10),OR(ABS(D10-'Answer Key'!$C$9)<=0.0001)),FALSE),"✔ Correct","✘ Not yet"))
A11: 6 | B11: Dependent drop-down: on the Lists sheet, name each department column after its facility (Formulas → Create from Selection → Top row, one column at a time: E1:E16, F1:F5, G1:G6, H1:H7). Give IntakeLog Facility (H2:H51) a List validation from Lists!$C$2:$C$5. Then give Department (I2:I51) a List validation whose Source is =INDIRECT(SUBSTITUTE($H2," ","_")). How many Department cells are circled? | C11: Names can't contain spaces, so Create from Selection uses underscores | E11: =IF(IFERROR(D11="",FALSE),"",IF(IFERROR(AND(ISNUMBER(D11),OR(ABS(D11-'Answer Key'!$C$10)<=0.0001)),FALSE),"✔ Correct","✘ Not yet"))
A12: 7 | B12: Labs sheet: the lab interface re-sent some results, so a few LabResultIDs appear more than once. Select A2:A322 and apply Highlight Cells Rules → Duplicate Values. How many cells are highlighted? | C12: Home → Conditional Formatting → Highlight Cells Rules | E12: =IF(IFERROR(D12="",FALSE),"",IF(IFERROR(AND(ISNUMBER(D12),OR(ABS(D12-'Answer Key'!$C$11)<=0.0001)),FALSE),"✔ Correct","✘ Not yet"))
A13: 8 | B13: Labs, TATMin (L2:L322): turnaround minutes from specimen collection to result. Apply Top/Bottom Rules → Top 10 Items. What is the smallest TAT that your rule highlights? | C13: Ties with the 10th value are highlighted too. LARGE gives the k-th largest | E13: =IF(IFERROR(D13="",FALSE),"",IF(IFERROR(AND(ISNUMBER(D13),OR(ABS(D13-'Answer Key'!$C$12)<=0.0001)),FALSE),"✔ Correct","✘ Not yet"))
A14: 9 | B14: Supplies, PctOfPar (K2:K258) = QtyOnHand ÷ ParLevel. Add Data Bars, then edit the rule so Minimum is Number 0 and Maximum is Number 1. A full bar now means "stocked to par." How many items show a completely full bar? | C14: Values at or above the Maximum get a full bar | E14: =IF(IFERROR(D14="",FALSE),"",IF(IFERROR(AND(ISNUMBER(D14),OR(ABS(D14-'Answer Key'!$C$13)<=0.0001)),FALSE),"✔ Correct","✘ Not yet"))
A15: 10 | B15: Census sheet (Medical-Surgical 5 East, Nov–Dec 2025): apply the Red - Yellow - Green Color Scale to Occupancy (F2:F62) so the fullest days are red. In Manage Rules → Edit Rule you'll see the midpoint is the 50th percentile. Which occupancy gets the pure yellow midpoint color? Enter it as a percentage to 1 decimal place. | C15: The 50th percentile has a more common name | E15: =IF(IFERROR(D15="",FALSE),"",IF(IFERROR(AND(ISNUMBER(D15),OR(ABS(D15-'Answer Key'!$C$14)<=0.00051,ABS(D15-'Answer Key'!$C$14*100)<=0.051000000000000004)),FALSE),"✔ Correct","✘ Not yet"))
A16: 11 | B16: Labs, TATMin: apply Icon Sets → 3 Traffic Lights (Unrimmed). Edit the rule: click Reverse Icon Order, set both Types to Number, and make red show when the value is >= 60 and yellow when it is >= 45 (green below 45). How many cells show a yellow light? | C16: Each icon's test is ">=". The default Type is Percent, not Number | E16: =IF(IFERROR(D16="",FALSE),"",IF(IFERROR(AND(ISNUMBER(D16),OR(ABS(D16-'Answer Key'!$C$15)<=0.0001)),FALSE),"✔ Correct","✘ Not yet"))
A17: 12 | B17: Labs: highlight the entire row of every critical result (AbnormalFlag HH or LL). Select A2:L322 with A2 active, choose New Rule → "Use a formula to determine which cells to format," and set a red fill. How many rows are highlighted? | C17: Lock the column with $, not the row | E17: =IF(IFERROR(D17="",FALSE),"",IF(IFERROR(AND(ISNUMBER(D17),OR(ABS(D17-'Answer Key'!$C$16)<=0.0001)),FALSE),"✔ Correct","✘ Not yet"))
A18: 13 | B18: Supplies: add two formula rules to A2:M258. Rule 1 (red fill): the item has expired, meaning ExpirationDate is not blank and is on or before ReportDate. Rule 2 (amber fill): ExpirationDate is not blank and is on or before ReportDate + ExpiringWindowDays. ReportDate (12/31/2025) and ExpiringWindowDays (90) are named cells on the Lists sheet. Excel puts each new rule at the top of the list, so open Manage Rules and move the red rule above the amber rule. How many rows are amber? | C18: A blank cell counts as 0, which is "on or before" any date. The rule higher in Manage Rules wins the fill | E18: =IF(IFERROR(D18="",FALSE),"",IF(IFERROR(AND(ISNUMBER(D18),OR(ABS(D18-'Answer Key'!$C$17)<=0.0001)),FALSE),"✔ Correct","✘ Not yet"))

Sheet IntakeLog
A1: IntakeID | B1: VisitDate | C1: MRN | D1: PatientName | E1: ZIP | F1: Payer | G1: CopayAmt | H1: Facility | I1: Department
A2: INT-25001 | B2: 45992 | C2: 05061485 | D2: Long, Dylan | E2: 45503 | F2: Keystone Health Partners | G2: 0 | H2: Bluestone Memorial Hospital | I2: Observation Unit
A3: INT-25002 | B3: 45992 | C3: 02801066 | D3: Long, Jordan | E3: 45503 | F3: State Medicaid | G3: 3 | H3: Bluestone Outpatient Pavilion | I3: Primary Care Clinic
A4: INT-25003 | B4: 45992 | C4: 01695337 | D4: Ruiz, Lawrence | E4: 45720 | F4: Keystone Health Partners | G4: 100 | H4: Bluestone Memorial Hospital | I4: Emergency Department
A5: INT-25004 | B5: 45993 | C5: 06836490 | D5: Ryan, Susan | E5: 4553 | F5: Keystone Health Partners | G5: 25 | H5: Bluestone Outpatient Pavilion | I5: Pediatric Clinic
A6: INT-25005 | B6: 45993 | C6: 02286683 | D6: Reed, Gerald | E6: 45501 | F6: Medicare | G6: 0 | H6: Bluestone Memorial Hospital | I6: Medical-Surgical 5 East
A7: INT-25006 | B7: 45994 | C7: 6320677 | D7: Ramirez, Cynthia | E7: 45720 | F7: Keystone Health Partners | G7: 25 | H7: Bluestone Outpatient Pavilion | I7: Primary Care Clinic
A8: INT-25007 | B8: 45994 | C8: 0256901 | D8: Dixon, Joseph | E8: 45501 | F8: Summit Choice PPO | G8: 100 | H8: Bluestone Memorial Hospital | I8: Emergency Department
A9: INT-25008 | B9: 12/32/2025 | C9: 02244142 | D9: Campbell, Julia | E9: 45503 | F9: Medicare | G9: 0 | H9: Bluestone Outpatient Pavilion | I9: Primary Care Clinic
A10: INT-25009 | B10: 45995 | C10: 01102944 | D10: Simmons, Larry | E10: 45503 | F10: Keystone Health Partners | G10: 0 | H10: Bluestone Memorial Hospital | I10: Pediatric Clinic
A11: INT-25010 | B11: 45996 | C11: 07480467 | D11: Diaz, James | E11: 45610 | F11: Keystone Health Partners | G11: 25 | H11: Bluestone Outpatient Pavilion | I11: Primary Care Clinic
A12: INT-25011 | B12: 45996 | C12: 02715043 | D12: Lane, Martha | E12: 45502 | F12: Evergreen Mutual Insurance | G12: -20 | H12: Bluestone Memorial Hospital | I12: Labor & Delivery
A13: INT-25012 | B13: 45997 | C13: O9127341 | D13: Ferguson, James | E13: 45501 | F13: Evergreen Mutual Insurance | G13: 100 | H13: Bluestone Memorial Hospital | I13: Emergency Department
A14: INT-25013 | B14: 45999 | C14: 09104274 | D14: Phillips, Douglas | E14: 45530 | F14: Medicare | G14: 0 | H14: Bluestone Memorial Hospital | I14: Emergency Department
A15: INT-25014 | B15: 45999 | C15: 02175923 | D15: Hughes, Patricia | E15: 45530 | F15: Keystone Health Partners | G15: 100 | H15: Bluestone Memorial Hospital | I15: Emergency Department
A16: INT-25015 | B16: 45999 | C16: 07505638 | D16: Harris, Rachel | E16: 45502 | F16: Medicare | G16: 0 | H16: Bluestone Memorial Hospital | I16: Emergency Department
A17: INT-25016 | B17: 46000 | C17: 08005967 | D17: Castillo, Christine | E17: 45502 | F17: Evergreen Mutual Insurance | G17: 25 | H17: Bluestone Outpatient Pavilion | I17: Primary Care Clinic
A18: INT-25017 | B18: 46000 | C18: 02918568 | D18: Abbott, Harper | E18: 45502 | F18: Silverline Medicare Advantage | G18: 75 | H18: Bluestone Memorial Hospital | I18: Emergency Department
A19: INT-25018 | B19: 46001 | C19: 027762471 | D19: Fisher, Wayne | E19: 45501 | F19: Medicaid | G19: 3 | H19: Bluestone Outpatient Pavilion | I19: Primary Care Clinic
A20: INT-25019 | B20: 46001 | C20: 05931696 | D20: Osei, Austin | E20: 45502 | F20: BCBS of Ohio | G20: 100 | H20: Bluestone Memorial Hospital | I20: Emergency Department
A21: INT-25020 | B21: 46367 | C21: 08580997 | D21: Gonzalez, Megan | E21: 45620 | F21: Medicare | G21: 0 | H21: Ashby Falls Community Hospital | I21: Cardiac Step-Down
A22: INT-25021 | B22: 46002 | C22: 09236613 | D22: Medina, Stephanie | E22: 45610 | F22: Medicare | G22: 0 | H22: Bluestone Memorial Hospital | I22: Cardiac Step-Down
A23: INT-25022 | B23: 46003 | C23: 04153642 | D23: Mendez, Frances | E23: 45502 | F23: Medicare | G23: 0 | H23: Bluestone Outpatient Pavilion | I23: Endocrinology & Diabetes Clinic
A24: INT-25023 | B24: 46004 | C24: 05651364 | D24: Pena, Aaron | E24: 45501 | F24: Self Pay | G24: 0 | H24: Bluestone Memorial Hospital | I24: Emergency Department
A25: INT-25024 | B25: 46005 | C25: 04969153 | D25: Porter, Grace | E25: 45503 | F25: Medicare | G25: 0 | H25: Bluestone Memorial Hospital | I25: Medical-Surgical 4 West
A26: INT-25025 | B26: 46006 | C26: 05629462 | D26: Ryan, Aaron | E26: 45730-1234 | F26: Silverline Medicare Advantage | G26: 75 | H26: Bluestone Memorial Hospital | I26: Emergency Department
A27: INT-25026 | B27: 46006 | C27: 03615457 | D27: Soto, Melissa | E27: 45510 | F27: Self-Pay | G27: 50 | H27: Bluestone Outpatient Pavilion | I27: Primary Care Clinic
A28: INT-25027 | B28: 46007 | C28: 06617891 | D28: McDonald, George | E28: 45503 | F28: Self-Pay | G28: 0 | H28: Bluestone Memorial Hospital | I28: Emergency Department
A29: INT-25028 | B29: 46007 | C29: 05292215 | D29: Edwards, Betty | E29: 45502 | F29: Keystone Health Partners | G29: 2500 | H29: Bluestone Memorial Hospital | I29: Emergency Department
... A34: INT-25033 | B34: 46010 | C34: 08517291 | D34: Ramos, Christina | E34: 45502 | F34: Medicare | G34: 0 | H34: Bluestone Memorial Hospital | I34: Cardiac Step-Down
A35: INT-25034 | B35: 19/12/2025 | C35: 04319243 | D35: Bryant, Janice | E35: 45750 | F35: State Medicaid | G35: 0 | H35: Cedar Ridge Medical Center | I35: Labor & Delivery
A36: INT-25035 | B36: 46011 | C36: 01509848 | D36: Diaz, Ann | E36: 45503 | F36: State Medicaid | G36: 0 | H36: Bluestone Memorial Hospital | I36: Emergency Department
A37: INT-25036 | B37: 46012 | C37: 07144087 | D37: Henry, Jesse | E37: 45501 | F37: Summit Choice | G37: 0 | H37: Bluestone Memorial Hospital | I37: Cardiac Step-Down
A38: INT-25037 | B38: 46013 | C38: 06280086 | D38: Parker, Catherine | E38: 45530 | F38: Medicare | G38: 0 | H38: Bluestone Memorial Hospital | I38: Medical-Surgical 4 West
A39: INT-25038 | B39: 46013 | C39: 00337216 | D39: Rivera, Jerry | E39: 45610 | F39: Silverline Medicare Advantage | G39: 20 | H39: Bluestone Outpatient Pavilion | I39: Primary Care Clinic
A40: INT-25039 | B40: 46014 | C40: 04207464 | D40: Sandoval, Virginia | E40: 45510 | F40: State Medicaid | G40: 350 | H40: Bluestone Outpatient Pavilion | I40: Infusion & Oncology Clinic
A41: INT-25040 | B41: 46014 | C41: 03461854 | D41: Ruiz, Kyle | E41: 45545 | F41: Medicare | G41: 0 | H41: Bluestone Memorial Hospital | I41: Medical-Surgical 5 East
A42: INT-25041 | B42: 46015 | C42: 01912897 | D42: Ross, Daniel | E42: 455302 | F42: Evergreen Mutual Insurance | G42: 40 | H42: Bluestone Outpatient Pavilion | I42: Infusion & Oncology Clinic
A43: INT-25042 | B43: 46015 | C43: 07958044 | D43: Holmes, Jessica | E43: 45720 | F43: Evergreen Mutual Insurance | G43: 0 | H43: Cedar Ridge Medical Center | I43: Medical-Surgical
A44: INT-25043 | B44: 46016 | C44: 06817727 | D44: Smith, Dorothy | E44: 45610 | F44: Evergreen Mutual Insurance | G44: 40 | H44: Bluestone Outpatient Pavilion | I44: Infusion & Oncology Clinic
...

Sheet Lists
A1: Payers | C1: Facilities | E1: Bluestone Memorial Hospital | F1: Ashby Falls Community Hospital | G1: Cedar Ridge Medical Center | H1: Bluestone Outpatient Pavilion | J1: Facility | K1: Department | M1: Setting | N1: Value
A2: Medicare | C2: Bluestone Memorial Hospital | E2: Emergency Department | F2: Emergency Department | G2: Emergency Department | H2: Primary Care Clinic | J2: Bluestone Memorial Hospital | K2: Emergency Department | M2: ReportDate | N2: 46022
A3: Silverline Medicare Advantage | C3: Ashby Falls Community Hospital | E3: Medical-Surgical 4 West | F3: Medical-Surgical | G3: Medical-Surgical | H3: Cardiology Clinic | J3: Bluestone Memorial Hospital | K3: Medical-Surgical 4 West | M3: ExpiringWindowDays | N3: 90
A4: State Medicaid | C4: Cedar Ridge Medical Center | E4: Medical-Surgical 5 East | F4: Intensive Care Unit | G4: Cardiac Step-Down | H4: Orthopedic Clinic | J4: Bluestone Memorial Hospital | K4: Medical-Surgical 5 East
A5: Keystone Health Partners | C5: Bluestone Outpatient Pavilion | E5: Cardiac Step-Down | F5: Labor & Delivery | G5: Intensive Care Unit | H5: Infusion & Oncology Clinic | J5: Bluestone Memorial Hospital | K5: Cardiac Step-Down | M5: Named cells: ReportDate = Lists!$N$2, ExpiringWindowDays = Lists!$N$3
A6: Evergreen Mutual Insurance | E6: Intensive Care Unit | G6: Orthopedics | H6: Endocrinology & Diabetes Clinic | J6: Bluestone Memorial Hospital | K6: Intensive Care Unit
A7: Summit Choice PPO | E7: Orthopedics & Spine | H7: Pediatric Clinic | J7: Bluestone Memorial Hospital | K7: Orthopedics & Spine
A8: Self-Pay | E8: Oncology | J8: Bluestone Memorial Hospital | K8: Oncology
A9: Workers' Compensation | E9: Neuroscience & Stroke | J9: Bluestone Memorial Hospital | K9: Neuroscience & Stroke
E10: Labor & Delivery | J10: Bluestone Memorial Hospital | K10: Labor & Delivery
E11: Pediatrics | J11: Bluestone Memorial Hospital | K11: Pediatrics
E12: Behavioral Health | J12: Bluestone Memorial Hospital | K12: Behavioral Health
E13: Observation Unit | J13: Bluestone Memorial Hospital | K13: Observation Unit
E14: Perioperative Services | J14: Bluestone Memorial Hospital | K14: Perioperative Services
E15: Laboratory | J15: Bluestone Memorial Hospital | K15: Laboratory
E16: Radiology | J16: Bluestone Memorial Hospital | K16: Radiology
J17: Ashby Falls Community Hospital | K17: Emergency Department
J18: Ashby Falls Community Hospital | K18: Medical-Surgical
E19: Departments by facility, one column per facility. Task 6: name each column with Formulas → Create from Selection (Top row). | J19: Ashby Falls Community Hospital | K19: Intensive Care Unit
J20: Ashby Falls Community Hospital | K20: Labor & Delivery
J21: Cedar Ridge Medical Center | K21: Emergency Department
J22: Cedar Ridge Medical Center | K22: Medical-Surgical
J23: Cedar Ridge Medical Center | K23: Cardiac Step-Down
J24: Cedar Ridge Medical Center | K24: Intensive Care Unit
J25: Cedar Ridge Medical Center | K25: Orthopedics
J26: Bluestone Outpatient Pavilion | K26: Primary Care Clinic
J27: Bluestone Outpatient Pavilion | K27: Cardiology Clinic
J28: Bluestone Outpatient Pavilion | K28: Orthopedic Clinic
J29: Bluestone Outpatient Pavilion | K29: Infusion & Oncology Clinic
J30: Bluestone Outpatient Pavilion | K30: Endocrinology & Diabetes Clinic
J31: Bluestone Outpatient Pavilion | K31: Pediatric Clinic
J34: The same pairs in long form (used by the answer key's check formula).

Sheet Labs
A1: LabResultID | B1: CollectedDateTime | C1: Facility | D1: PatientID | E1: TestCode | F1: TestName | G1: ResultValue | H1: Units | I1: RefLow | J1: RefHigh | K1: AbnormalFlag | L1: TATMin
A2: LAB739331 | B2: 45847.093 | C2: Bluestone Memorial Hospital | D2: PT11014 | E2: GLU | F2: Glucose | G2: 149 | H2: mg/dL | I2: 70 | J2: 99 | K2: H | L2: 72
A3: LAB739334 | B3: 45847.103 | C3: Bluestone Memorial Hospital | D3: PT11014 | E3: HGB | F3: Hemoglobin | G3: 12.6 | H3: g/dL | I3: 12 | J3: 17.5 | K3: N | L3: 67
A4: LAB739332 | B4: 45847.109 | C4: Bluestone Memorial Hospital | D4: PT11014 | E4: CREAT | F4: Creatinine | G4: 1.82 | H4: mg/dL | I4: 0.6 | J4: 1.3 | K4: H | L4: 63
A5: LAB739335 | B5: 45847.119 | C5: Bluestone Memorial Hospital | D5: PT11014 | E5: LACT | F5: Lactate | G5: 4.4 | H5: mmol/L | I5: 0.5 | J5: 2 | K5: HH | L5: 72
A6: LAB739448 | B6: 45848.251 | C6: Cedar Ridge Medical Center | D6: PT13245 | E6: LACT | F6: Lactate | G6: 3.1 | H6: mmol/L | I6: 0.5 | J6: 2 | K6: H | L6: 34
A7: LAB739447 | B7: 45848.265 | C7: Cedar Ridge Medical Center | D7: PT13245 | E7: K | F7: Potassium | G7: 3.9 | H7: mmol/L | I7: 3.5 | J7: 5.1 | K7: N | L7: 28
A8: LAB739555 | B8: 45849.847 | C8: Bluestone Memorial Hospital | D8: PT12532 | E8: CREAT | F8: Creatinine | G8: 0.97 | H8: mg/dL | I8: 0.6 | J8: 1.3 | K8: N | L8: 45
A9: LAB739560 | B9: 45849.852 | C9: Bluestone Memorial Hospital | D9: PT12532 | E9: LACT | F9: Lactate | G9: 2.3 | H9: mmol/L | I9: 0.5 | J9: 2 | K9: H | L9: 68
A10: LAB739558 | B10: 45849.865 | C10: Bluestone Memorial Hospital | D10: PT12532 | E10: BUN | F10: Blood Urea Nitrogen | G10: 16 | H10: mg/dL | I10: 7 | J10: 20 | K10: N | L10: 40
A11: LAB739556 | B11: 45849.878 | C11: Bluestone Memorial Hospital | D11: PT12532 | E11: WBC | F11: White Blood Cell Count | G11: 3.7 | H11: K/uL | I11: 4.5 | J11: 11 | K11: L | L11: 32
A12: LAB739557 | B12: 45849.883 | C12: Bluestone Memorial Hospital | D12: PT12532 | E12: HGB | F12: Hemoglobin | G12: 13.6 | H12: g/dL | I12: 12 | J12: 17.5 | K12: N | L12: 43
A13: LAB739744 | B13: 45852.894 | C13: Ashby Falls Community Hospital | D13: PT11927 | E13: NA | F13: Sodium | G13: 139 | H13: mmol/L | I13: 136 | J13: 145 | K13: N | L13: 26
... A322: LAB750340 | B322: 46006.591 | C322: Ashby Falls Community Hospital | D322: PT12685 | E322: LACT | F322: Lactate | G322: 2.1 | H322: mmol/L | I322: 0.5 | J322: 2 | K322: H | L322: 49

Sheet Supplies
A1: StockID | B1: SKU | C1: ItemDescription | D1: Category | E1: Facility | F1: Location | G1: UnitOfMeasure | H1: QtyOnHand | I1: ParLevel | J1: ReorderPoint | K1: PctOfPar | L1: ExpirationDate | M1: LotNumber
A2: STK4001 | B2: SKU-10007 | C2: Nitrile Exam Gloves Small (Box/100) | D2: PPE | E2: Cedar Ridge Medical Center | F2: Emergency Department | G2: Box | H2: 527 | I2: 481 | J2: 140 | K2: 1.0956341
A3: STK4002 | B3: SKU-10014 | C3: Nitrile Exam Gloves Medium (Box/100) | D3: PPE | E3: Bluestone Memorial Hospital | F3: Medical-Surgical 4 West | G3: Box | H3: 403 | I3: 800 | J3: 313 | K3: 0.50375
A4: STK4003 | B4: SKU-10014 | C4: Nitrile Exam Gloves Medium (Box/100) | D4: PPE | E4: Bluestone Memorial Hospital | F4: Perioperative Services | G4: Box | H4: 578 | I4: 800 | J4: 225 | K4: 0.7225
A5: STK4004 | B5: SKU-10021 | C5: Nitrile Exam Gloves Large (Box/100) | D5: PPE | E5: Bluestone Memorial Hospital | F5: Pediatrics | G5: Box | H5: 550 | I5: 491 | J5: 179 | K5: 1.1201629
A6: STK4005 | B6: SKU-10021 | C6: Nitrile Exam Gloves Large (Box/100) | D6: PPE | E6: Bluestone Memorial Hospital | F6: Perioperative Services | G6: Box | H6: 495 | I6: 460 | J6: 155 | K6: 1.076087
A7: STK4006 | B7: SKU-10021 | C7: Nitrile Exam Gloves Large (Box/100) | D7: PPE | E7: Ashby Falls Community Hospital | F7: Medical-Surgical | G7: Box | H7: 324 | I7: 497 | J7: 193 | K7: 0.65191147
A8: STK4007 | B8: SKU-10028 | C8: Nitrile Exam Gloves X-Large (Box/100) | D8: PPE | E8: Cedar Ridge Medical Center | F8: Emergency Department | G8: Box | H8: 703 | I8: 788 | J8: 290 | K8: 0.89213198
A9: STK4008 | B9: SKU-10035 | C9: Isolation Gown, Level 2 Regular | D9: PPE | E9: Bluestone Memorial Hospital | F9: Labor & Delivery | G9: Case | H9: 0 | I9: 72 | J9: 18 | K9: 0
A10: STK4009 | B10: SKU-10035 | C10: Isolation Gown, Level 2 Regular | D10: PPE | E10: Ashby Falls Community Hospital | F10: Emergency Department | G10: Case | H10: 47 | I10: 174 | J10: 48 | K10: 0.27011494
A11: STK4010 | B11: SKU-10042 | C11: Isolation Gown, Level 2 X-Large | D11: PPE | E11: Bluestone Memorial Hospital | F11: Labor & Delivery | G11: Case | H11: 65 | I11: 55 | J11: 19 | K11: 1.1818182
A12: STK4011 | B12: SKU-10042 | C12: Isolation Gown, Level 2 X-Large | D12: PPE | E12: Bluestone Memorial Hospital | F12: Perioperative Services | G12: Case | H12: 82 | I12: 77 | J12: 26 | K12: 1.0649351
A13: STK4012 | B13: SKU-10049 | C13: N95 Respirator Small (Box/20) | D13: PPE | E13: Bluestone Memorial Hospital | F13: Orthopedics & Spine | G13: Box | H13: 263 | I13: 226 | J13: 86 | K13: 1.1637168 | L13: 46367 | M13: L567778
A14: STK4013 | B14: SKU-10049 | C14: N95 Respirator Small (Box/20) | D14: PPE | E14: Bluestone Memorial Hospital | F14: Oncology | G14: Box | H14: 126 | I14: 225 | J14: 88 | K14: 0.56 | L14: 46181 | M14: L705867
A15: STK4014 | B15: SKU-10049 | C15: N95 Respirator Small (Box/20) | D15: PPE | E15: Bluestone Memorial Hospital | F15: Laboratory | G15: Box | H15: 37 | I15: 150 | J15: 53 | K15: 0.24666667 | L15: 46126 | M15: L670999
A16: STK4015 | B16: SKU-10056 | C16: N95 Respirator Regular (Box/20) | D16: PPE | E16: Bluestone Memorial Hospital | F16: Medical-Surgical 5 East | G16: Box | H16: 121 | I16: 148 | J16: 39 | K16: 0.81756757 | L16: 46324 | M16: L274021
A17: STK4016 | B17: SKU-10056 | C17: N95 Respirator Regular (Box/20) | D17: PPE | E17: Bluestone Memorial Hospital | F17: Labor & Delivery | G17: Box | H17: 36 | I17: 117 | J17: 32 | K17: 0.30769231 | L17: 46487 | M17: L412381
A18: STK4017 | B18: SKU-10056 | C18: N95 Respirator Regular (Box/20) | D18: PPE | E18: Bluestone Memorial Hospital | F18: Perioperative Services | G18: Box | H18: 71 | I18: 153 | J18: 60 | K18: 0.46405229 | L18: 46118 | M18: L805667
A19: STK4018 | B19: SKU-10063 | C19: Procedure Mask, Ear Loop (Box/50) | D19: PPE | E19: Bluestone Memorial Hospital | F19: Oncology | G19: Box | H19: 90 | I19: 426 | J19: 155 | K19: 0.21126761
A20: STK4019 | B20: SKU-10063 | C20: Procedure Mask, Ear Loop (Box/50) | D20: PPE | E20: Ashby Falls Community Hospital | F20: Emergency Department | G20: Box | H20: 158 | I20: 430 | J20: 110 | K20: 0.36744186
A21: STK4020 | B21: SKU-10063 | C21: Procedure Mask, Ear Loop (Box/50) | D21: PPE | E21: Cedar Ridge Medical Center | F21: Medical-Surgical | G21: Box | H21: 441 | I21: 800 | J21: 310 | K21: 0.55125
A22: STK4021 | B22: SKU-10070 | C22: Face Shield, Full Length (Box/24) | D22: PPE | E22: Bluestone Memorial Hospital | F22: Medical-Surgical 5 East | G22: Box | H22: 182 | I22: 142 | J22: 49 | K22: 1.2816901
A23: STK4022 | B23: SKU-10070 | C23: Face Shield, Full Length (Box/24) | D23: PPE | E23: Bluestone Memorial Hospital | F23: Labor & Delivery | G23: Box | H23: 337 | I23: 288 | J23: 110 | K23: 1.1701389
A24: STK4023 | B24: SKU-10070 | C24: Face Shield, Full Length (Box/24) | D24: PPE | E24: Bluestone Memorial Hospital | F24: Pediatrics | G24: Box | H24: 191 | I24: 322 | J24: 109 | K24: 0.5931677
A25: STK4024 | B25: SKU-10077 | C25: Shoe Covers, Non-Skid (Case/300) | D25: PPE | E25: Bluestone Memorial Hospital | F25: Medical-Surgical 4 West | G25: Case | H25: 121 | I25: 115 | J25: 44 | K25: 1.0521739
A26: STK4025 | B26: SKU-10077 | C26: Shoe Covers, Non-Skid (Case/300) | D26: PPE | E26: Bluestone Memorial Hospital | F26: Orthopedics & Spine | G26: Case | H26: 46 | I26: 93 | J26: 32 | K26: 0.49462366
A27: STK4026 | B27: SKU-10077 | C27: Shoe Covers, Non-Skid (Case/300) | D27: PPE | E27: Bluestone Memorial Hospital | F27: Perioperative Services | G27: Case | H27: 213 | I27: 164 | J27: 42 | K27: 1.2987805
A28: STK4027 | B28: SKU-10084 | C28: IV Catheter 14G x 1.16 in | D28: IV Supplies | E28: Bluestone Memorial Hospital | F28: Medical-Surgical 4 West | G28: Box | H28: 44 | I28: 64 | J28: 22 | K28: 0.6875 | L28: 46233 | M28: L227031
A29: STK4028 | B29: SKU-10091 | C29: IV Catheter 16G x 1.16 in | D29: IV Supplies | E29: Bluestone Memorial Hospital | F29: Medical-Surgical 5 East | G29: Box | H29: 71 | I29: 108 | J29: 40 | K29: 0.65740741 | L29: 46009 | M29: L323955
A30: STK4029 | B30: SKU-10098 | C30: IV Catheter 18G x 1.16 in | D30: IV Supplies | E30: Bluestone Memorial Hospital | F30: Oncology | G30: Box | H30: 50 | I30: 76 | J30: 29 | K30: 0.65789474 | L30: 46382 | M30: L551785
A31: STK4030 | B31: SKU-10098 | C31: IV Catheter 18G x 1.16 in | D31: IV Supplies | E31: Bluestone Memorial Hospital | F31: Labor & Delivery | G31: Box | H31: 118 | I31: 132 | J31: 46 | K31: 0.89393939 | L31: 46392 | M31: L490763
A32: STK4031 | B32: SKU-10105 | C32: IV Catheter 20G x 1.16 in | D32: IV Supplies | E32: Ashby Falls Community Hospital | F32: Medical-Surgical | G32: Box | H32: 151 | I32: 148 | J32: 41 | K32: 1.0202703 | L32: 46272 | M32: L262859
A33: STK4032 | B33: SKU-10105 | C33: IV Catheter 20G x 1.16 in | D33: IV Supplies | E33: Bluestone Memorial Hospital | F33: Laboratory | G33: Box | H33: 104 | I33: 190 | J33: 74 | K33: 0.54736842 | L33: 46258 | M33: L416786
A34: STK4033 | B34: SKU-10112 | C34: IV Catheter 22G x 1.16 in | D34: IV Supplies | E34: Bluestone Memorial Hospital | F34: Oncology | G34: Box | H34: 7 | I34: 52 | J34: 19 | K34: 0.13461538 | L34: 45957 | M34: L236652
A35: STK4034 | B35: SKU-10112 | C35: IV Catheter 22G x 1.16 in | D35: IV Supplies | E35: Cedar Ridge Medical Center | F35: Medical-Surgical | G35: Box | H35: 15 | I35: 132 | J35: 35 | K35: 0.11363636 | L35: 46468 | M35: L564515
A36: STK4035 | B36: SKU-10119 | C36: IV Catheter 24G x 1.16 in | D36: IV Supplies | E36: Bluestone Memorial Hospital | F36: Orthopedics & Spine | G36: Box | H36: 93 | I36: 69 | J36: 19 | K36: 1.3478261 | L36: 46415 | M36: L705292
A37: STK4036 | B37: SKU-10119 | C37: IV Catheter 24G x 1.16 in | D37: IV Supplies | E37: Bluestone Memorial Hospital | F37: Pediatrics | G37: Box | H37: 33 | I37: 92 | J37: 28 | K37: 0.35869565 | L37: 46464 | M37: L791852
A38: STK4037 | B38: SKU-10119 | C38: IV Catheter 24G x 1.16 in | D38: IV Supplies | E38: Ashby Falls Community Hospital | F38: Emergency Department | G38: Box | H38: 102 | I38: 355 | J38: 94 | K38: 0.28732394 | L38: 46869 | M38: L343745
A39: STK4038 | B39: SKU-10126 | C39: Primary IV Tubing Set, 60 Drop | D39: IV Supplies | E39: Bluestone Memorial Hospital | F39: Pediatrics | G39: Case | H39: 50 | I39: 38 | J39: 12 | K39: 1.3157895 | L39: 46986 | M39: L290377
... A85: STK4084 | B85: SKU-10252 | C85: Silver Alginate Dressing 4x5 | D85: Wound Care | E85: Bluestone Memorial Hospital | F85: Pediatrics | G85: Each | H85: 99 | I85: 291 | J85: 92 | K85: 0.34020619 | L85: 46854 | M85: L691707
...

Sheet Census
A1: CensusDate | B1: StaffedBeds | C1: Admissions | D1: Discharges | E1: MidnightCensus | F1: Occupancy
A2: 45962 | B2: 32 | C2: 4 | D2: 3 | E2: 27 | F2: 0.84375
A3: 45963 | B3: 32 | C3: 8 | D3: 8 | E3: 27 | F3: 0.84375
A4: 45964 | B4: 32 | C4: 1 | D4: 0 | E4: 28 | F4: 0.875
A5: 45965 | B5: 32 | C5: 5 | D5: 5 | E5: 28 | F5: 0.875
A6: 45966 | B6: 32 | C6: 5 | D6: 4 | E6: 29 | F6: 0.90625
A7: 45967 | B7: 32 | C7: 9 | D7: 9 | E7: 29 | F7: 0.90625
A8: 45968 | B8: 32 | C8: 8 | D8: 8 | E8: 29 | F8: 0.90625
A9: 45969 | B9: 32 | C9: 4 | D9: 5 | E9: 28 | F9: 0.875
A10: 45970 | B10: 32 | C10: 2 | D10: 2 | E10: 28 | F10: 0.875
A11: 45971 | B11: 32 | C11: 10 | D11: 8 | E11: 30 | F11: 0.9375
A12: 45972 | B12: 32 | C12: 11 | D12: 11 | E12: 30 | F12: 0.9375
A13: 45973 | B13: 32 | C13: 6 | D13: 5 | E13: 31 | F13: 0.96875
... A62: 46022 | B62: 32 | C62: 3 | D62: 3 | E62: 29 | F62: 0.90625

Sheet Bonus
A1: Lesson 3.2 · Bonus: The 7 a.m. bed huddle board
A2: It's 7 a.m. on Wednesday, November 26, 2025, the day before Thanksgiving. The house supervisor runs the system bed huddle from the Huddle sheet: one row per inpatient unit, with the midnight census for 11/24 and 11/25, the overnight change, and occupancy. Make the board readable at a glance, then build the unit selector that drives the gray unit card (B6:B9). The card reads the NovCensus sheet (every unit, Nov 1–25). The board's data is in rows 12–29.
A3: Type a formula or value in each yellow cell. The Check column turns green when your answer matches. Stuck? Read the hint, then the lesson guide. Answers: right-click a sheet tab → Unhide… → 'Bonus Key'.
A4: ="Score: "&COUNTIF(E6:E9,"✔*")&" of 4 auto-checked tasks correct"
A5: # | B5: Task | C5: Hint | D5: Your Answer | E5: Check
A6: B1 | B6: Apply a 3-color scale to Occupancy (G12:G29): Minimum = Lowest Value (green), Midpoint = Number 0.85 (yellow, the planning target), Maximum = Highest Value (red). How many units are shaded on the red side of yellow (occupancy above 85%)? | C6: New Rule → Format all cells based on their values → 3-Color Scale | E6: =IF(IFERROR(D6="",FALSE),"",IF(IFERROR(AND(ISNUMBER(D6),OR(ABS(D6-'Bonus Key'!$C$5)<=0.0001)),FALSE),"✔ Correct","✘ Not yet"))
A7: B2 | B7: Apply Icon Sets → 3 Arrows (Colored) to Change (F12:F29). Edit the rule so both Types are Number: up arrow when the value is >= 1, sideways arrow when it is >= 0, down arrow otherwise. How many units show an up arrow? | C7: Type = Number, not the default Percent | E7: =IF(IFERROR(D7="",FALSE),"",IF(IFERROR(AND(ISNUMBER(D7),OR(ABS(D7-'Bonus Key'!$C$6)<=0.0001)),FALSE),"✔ Correct","✘ Not yet"))
A8: B3 | B8: Add two formula rules to the whole board (A12:G29): a red fill when the 11/25 census is above staffed beds (overflow), and an amber fill when occupancy is at least 90%. In Manage Rules, put the overflow rule above the amber rule. How many rows end up amber? | C8: Both rules are TRUE for an overflow unit, and the rule on top wins the fill | E8: =IF(IFERROR(D8="",FALSE),"",IF(IFERROR(AND(ISNUMBER(D8),OR(ABS(D8-'Bonus Key'!$C$7)<=0.0001)),FALSE),"✔ Correct","✘ Not yet"))
A9: B4 | B9: Build the unit selector. Give B4 a List validation from the Hospitals list (I12:I14). Give B5 a dependent List built from the board's own Facility and Unit columns, with no named ranges. Then choose Cedar Ridge Medical Center → Intensive Care Unit. The gray cell shows the card's Nov 1–25 occupancy. What is it? | C9: OFFSET(start, rows down, 0, height, 1) with MATCH for the first row and COUNTIF for the height | D9: {=IF(Huddle!$B$8="","",Huddle!$B$8)} | E9: =IF(IFERROR(D9="",FALSE),"",IF(IFERROR(AND(ISNUMBER(D9),OR(ABS(D9-'Bonus Key'!$C$8)<=0.00051,ABS(D9-'Bonus Key'!$C$8*100)<=0.051000000000000004)),FALSE),"✔ Correct","✘ Not yet"))

Sheet Huddle
A1: 7 a.m. Bed Huddle · Wednesday, November 26, 2025
A2: Midnight census for Tuesday 11/25 vs Monday 11/24, every inpatient unit in the system. Yellow cells are yours, and gray cells hold formulas.
A3: UNIT SELECTOR
A4: Facility
A5: Unit
A6: Staffed beds | B6: =IF(OR($B$4="",$B$5=""),"",IF(COUNTIFS($A$12:$A$29,$B$4,$B$12:$B$29,$B$5)=0,"n/a",SUMIFS($C$12:$C$29,$A$12:$A$29,$B$4,$B$12:$B$29,$B$5)))
A7: Census 11/25 | B7: =IF(OR($B$4="",$B$5=""),"",IF(COUNTIFS($A$12:$A$29,$B$4,$B$12:$B$29,$B$5)=0,"n/a",SUMIFS($E$12:$E$29,$A$12:$A$29,$B$4,$B$12:$B$29,$B$5)))
A8: Occupancy, Nov 1–25 | B8: =IF(OR($B$4="",$B$5=""),"",IFERROR(SUMIFS(NovCensus!$E$2:$E$451,NovCensus!$B$2:$B$451,$B$4,NovCensus!$C$2:$C$451,$B$5)/SUMIFS(NovCensus!$D$2:$D$451,NovCensus!$B$2:$B$451,$B$4,NovCensus!$C$2:$C$451,$B$5),"n/a"))
A9: Overflow days, Nov 1–25 | B9: =IF(OR($B$4="",$B$5=""),"",IF(COUNTIFS(NovCensus!$B$2:$B$451,$B$4,NovCensus!$C$2:$C$451,$B$5)=0,"n/a",COUNTIFS(NovCensus!$B$2:$B$451,$B$4,NovCensus!$C$2:$C$451,$B$5,NovCensus!$F$2:$F$451,">1")))
A11: Facility | B11: Unit | C11: Staffed beds | D11: Census 11/24 | E11: Census 11/25 | F11: Change | G11: Occupancy | I11: Hospitals
A12: Bluestone Memorial Hospital | B12: Medical-Surgical 4 West | C12: 36 | D12: 32 | E12: 32 | F12: =E12-D12 | G12: =E12/C12 | I12: Bluestone Memorial Hospital
A13: Bluestone Memorial Hospital | B13: Medical-Surgical 5 East | C13: 32 | D13: 33 | E13: 34 | F13: =E13-D13 | G13: =E13/C13 | I13: Ashby Falls Community Hospital
A14: Bluestone Memorial Hospital | B14: Cardiac Step-Down | C14: 24 | D14: 19 | E14: 19 | F14: =E14-D14 | G14: =E14/C14 | I14: Cedar Ridge Medical Center
A15: Bluestone Memorial Hospital | B15: Intensive Care Unit | C15: 20 | D15: 17 | E15: 18 | F15: =E15-D15 | G15: =E15/C15
A16: Bluestone Memorial Hospital | B16: Orthopedics & Spine | C16: 22 | D16: 15 | E16: 16 | F16: =E16-D16 | G16: =E16/C16
A17: Bluestone Memorial Hospital | B17: Oncology | C17: 18 | D17: 16 | E17: 16 | F17: =E17-D17 | G17: =E17/C17
A18: Bluestone Memorial Hospital | B18: Neuroscience & Stroke | C18: 16 | D18: 12 | E18: 12 | F18: =E18-D18 | G18: =E18/C18
A19: Bluestone Memorial Hospital | B19: Labor & Delivery | C19: 20 | D19: 13 | E19: 14 | F19: =E19-D19 | G19: =E19/C19
A20: Bluestone Memorial Hospital | B20: Pediatrics | C20: 14 | D20: 9 | E20: 9 | F20: =E20-D20 | G20: =E20/C20
A21: Bluestone Memorial Hospital | B21: Behavioral Health | C21: 18 | D21: 19 | E21: 19 | F21: =E21-D21 | G21: =E21/C21
A22: Bluestone Memorial Hospital | B22: Observation Unit | C22: 12 | D22: 8 | E22: 8 | F22: =E22-D22 | G22: =E22/C22
A23: Ashby Falls Community Hospital | B23: Medical-Surgical | C23: 28 | D23: 25 | E23: 25 | F23: =E23-D23 | G23: =E23/C23
A24: Ashby Falls Community Hospital | B24: Intensive Care Unit | C24: 8 | D24: 6 | E24: 6 | F24: =E24-D24 | G24: =E24/C24
A25: Ashby Falls Community Hospital | B25: Labor & Delivery | C25: 10 | D25: 5 | E25: 6 | F25: =E25-D25 | G25: =E25/C25
A26: Cedar Ridge Medical Center | B26: Medical-Surgical | C26: 30 | D26: 28 | E26: 27 | F26: =E26-D26 | G26: =E26/C26
... A29: Cedar Ridge Medical Center | B29: Orthopedics | C29: 14 | D29: 10 | E29: 11 | F29: =E29-D29 | G29: =E29/C29

Sheet NovCensus
A1: CensusDate | B1: Facility | C1: Unit | D1: StaffedBeds | E1: MidnightCensus | F1: Occupancy
A2: 45962 | B2: Bluestone Memorial Hospital | C2: Medical-Surgical 4 West | D2: 36 | E2: 29 | F2: 0.80555556
A3: 45963 | B3: Bluestone Memorial Hospital | C3: Medical-Surgical 4 West | D3: 36 | E3: 32 | F3: 0.88888889
A4: 45964 | B4: Bluestone Memorial Hospital | C4: Medical-Surgical 4 West | D4: 36 | E4: 34 | F4: 0.94444444
A5: 45965 | B5: Bluestone Memorial Hospital | C5: Medical-Surgical 4 West | D5: 36 | E5: 34 | F5: 0.94444444
A6: 45966 | B6: Bluestone Memorial Hospital | C6: Medical-Surgical 4 West | D6: 36 | E6: 34 | F6: 0.94444444
A7: 45967 | B7: Bluestone Memorial Hospital | C7: Medical-Surgical 4 West | D7: 36 | E7: 32 | F7: 0.88888889
A8: 45968 | B8: Bluestone Memorial Hospital | C8: Medical-Surgical 4 West | D8: 36 | E8: 31 | F8: 0.86111111
A9: 45969 | B9: Bluestone Memorial Hospital | C9: Medical-Surgical 4 West | D9: 36 | E9: 26 | F9: 0.72222222
A10: 45970 | B10: Bluestone Memorial Hospital | C10: Medical-Surgical 4 West | D10: 36 | E10: 27 | F10: 0.75
A11: 45971 | B11: Bluestone Memorial Hospital | C11: Medical-Surgical 4 West | D11: 36 | E11: 30 | F11: 0.83333333
A12: 45972 | B12: Bluestone Memorial Hospital | C12: Medical-Surgical 4 West | D12: 36 | E12: 31 | F12: 0.86111111
A13: 45973 | B13: Bluestone Memorial Hospital | C13: Medical-Surgical 4 West | D13: 36 | E13: 34 | F13: 0.94444444
... A451: 45986 | B451: Cedar Ridge Medical Center | C451: Orthopedics | D451: 14 | E451: 11 | F451: 0.78571429

Sheet Answer Key
A1: 🔑 Answer Key — Lesson 3.2
A2: Spoiler alert — try every task before reading this sheet. Column C is the value the Check column compares against. Column D is a sample solution; column E is that same formula, live, proving it works.
A4: # | B4: Task | C4: Answer | D4: Sample solution | E4: Live result | F4: Explanation
A5: 1 | B5: IntakeLog, Payer column (F2:F51): add a List validation whose Source is the payer list on the Lists sheet (Lists!$A$2:$A$9). Then circle invalid data. How many Payer cells are circled? | C5: 5 | D5: 1. On IntakeLog, select F2:F51. 2. Data → Data Validation (Windows: Alt, A, V, V). On the Settings tab set Allow to List. 3. Click in Source, switch to the Lists sheet, and select A2:A9. The box reads =Lists!$A$2:$A$9. Click OK. 4. Click the arrow on Data → Data Validation, then Circle Invalid Data. (Clear Validation Circles removes them.) You see 5 circles. Equivalent formula: =SUMPRODUCT(--(COUNTIF(Lists!$A$2:$A$9,IntakeLog!F2:F51)=0)) | E5: {=SUMPRODUCT(--(COUNTIF(Lists!$A$2:$A$9,IntakeLog!F2:F51)=0))} | F5: A validation rule only checks values as someone types them, so the bad payers already in the log stay until you circle them. Each one is a near miss of a real payer: "Self Pay" instead of "Self-Pay", "Medicaid" instead of "State Medicaid". A drop-down list prevents exactly this. The formula counts entries whose COUNTIF in the payer list is 0, which means they aren't on it.
A6: 2 | B6: IntakeLog, VisitDate (B2:B51): the log covers December 2025 only. Allow a Date between 12/01/2025 and 12/31/2025 (type =DATE(2025,12,1) and =DATE(2025,12,31) in the boxes so it works in any regional setting). How many VisitDate cells are circled? | C6: 4 | D6: 1. Select B2:B51 on IntakeLog. 2. Data → Data Validation → Settings: Allow = Date, Data = between, Start date = =DATE(2025,12,1), End date = =DATE(2025,12,31). Click OK. 3. Click the arrow on Data → Data Validation, then Circle Invalid Data. (Clear Validation Circles removes them.) You see 4 circles. Equivalent formula: =ROWS(IntakeLog!B2:B51)-COUNTIFS(IntakeLog!B2:B51,">="&DATE(2025,12,1),IntakeLog!B2:B51,"<="&DATE(2025,12,31)) | E6: {=ROWS(IntakeLog!B2:B51)-COUNTIFS(IntakeLog!B2:B51,">="&DATE(2025,12,1),IntakeLog!B2:B51,"<="&DATE(2025,12,31))} | F6: Two entries are text that only looks like a date: 12/32/2025 doesn't exist, and 19/12/2025 was imported day-first. Both sit at the left of the cell, which is the clue that they're text. A Date rule rejects text automatically. The other two are real dates with the wrong year (2026 and 2015). COUNTIFS skips text, so "all rows minus rows with a December 2025 date" counts every bad entry.
A7: 3 | B7: IntakeLog, CopayAmt (G2:G51): allow a Decimal between 0 and 100. On the Input Message tab, add the title Copay and the message "Enter the amount collected, $0 to $100." Leave the Error Alert style as Stop. How many CopayAmt cells are circled? | C7: 3 | D7: 1. Select G2:G51. 2. Data → Data Validation → Settings: Allow = Decimal, Data = between, Minimum = 0, Maximum = 100. 3. Input Message tab: Title Copay, message Enter the amount collected, $0 to $100. 4. Error Alert tab: keep Style = Stop. Click OK. 5. Click the arrow on Data → Data Validation, then Circle Invalid Data. (Clear Validation Circles removes them.) You see 3 circles. Equivalent formula: =COUNTIF(IntakeLog!G2:G51,"<0")+COUNTIF(IntakeLog!G2:G51,">100") | E7: {=COUNTIF(IntakeLog!G2:G51,"<0")+COUNTIF(IntakeLog!G2:G51,">100")} | F7: "Between" includes both limits, so the $0.00 and $100.00 copays in the log are valid. The circled values are a negative amount (a refund typed into the wrong field), 2,500 (almost certainly $25.00 typed without the decimal point), and 350. Click any cell in the column to see your input message.
A8: 4 | B8: IntakeLog, ZIP (E2:E51): allow Text length equal to 5. How many ZIP cells are circled? | C8: 3 | D8: 1. Select E2:E51. 2. Data → Data Validation → Settings: Allow = Text length, Data = equal to, Length = 5. Click OK. 3. Click the arrow on Data → Data Validation, then Circle Invalid Data. (Clear Validation Circles removes them.) You see 3 circles. Equivalent formula: =SUMPRODUCT(--(LEN(IntakeLog!E2:E51)<>5)) | E8: {=SUMPRODUCT(--(LEN(IntakeLog!E2:E51)<>5))} | F8: Text length counts characters, so the 4-digit ZIP, the 6-digit ZIP, and the ZIP+4 entry (10 characters including the hyphen) fail. The rule also works on numbers. One ZIP in the log was stored as the number 45502 (it's right-aligned), and it passes because it has 5 characters.
A9: 5 | B9: IntakeLog, MRN (C2:C51): an MRN must be exactly 8 characters, and all of them digits. Select the column with C2 as the active cell and add a Custom validation rule that is TRUE only for a valid MRN. How many MRN cells are circled? | C9: 4 | D9: 1. Type C2:C51 in the Name Box and press Enter. The range is selected and C2 is the active cell. 2. Data → Data Validation → Settings: Allow = Custom, Formula = =AND(LEN(C2)=8,ISNUMBER(--C2)). Click OK. 3. Click the arrow on Data → Data Validation, then Circle Invalid Data. (Clear Validation Circles removes them.) You see 4 circles. Equivalent formula: =ROWS(IntakeLog!C2:C51)-SUMPRODUCT((LEN(IntakeLog!C2:C51)=8)*ISNUMBER(--IntakeLog!C2:C51)) | E9: {=ROWS(IntakeLog!C2:C51)-SUMPRODUCT((LEN(IntakeLog!C2:C51)=8)*ISNUMBER(--IntakeLog!C2:C51))} | F9: LEN catches the 7- and 9-character MRNs and the MRN that was stored as a number (Excel dropped its leading zero, leaving 7 digits). ISNUMBER(--C2) catches O9127341, where the letter O replaced a zero: the double minus tries to turn the text into a number and fails. Each test misses something the other catches, so both go inside AND. You write the formula for C2 only, and Excel adjusts it for C3, C4, and so on.
A10: 6 | B10: Dependent drop-down: on the Lists sheet, name each department column after its facility (Formulas → Create from Selection → Top row, one column at a time: E1:E16, F1:F5, G1:G6, H1:H7). Give IntakeLog Facility (H2:H51) a List validation from Lists!$C$2:$C$5. Then give Department (I2:I51) a List validation whose Source is =INDIRECT(SUBSTITUTE($H2," ","_")). How many Department cells are circled? | C10: 4 | D10: 1. On Lists, select E1:E16 and choose Formulas → Create from Selection, tick only Top row, and click OK. Repeat for F1:F5, G1:G6, H1:H7. Formulas → Name Manager (Ctrl + F3) now lists four names such as Cedar_Ridge_Medical_Center. 2. Select H2:H51 on IntakeLog → Data Validation → List, Source =Lists!$C$2:$C$5. 3. Select I2:I51 with I2 active → Data Validation → List, Source =INDIRECT(SUBSTITUTE($H2," ","_")). Click OK. 4. Click the arrow on Data → Data Validation, then Circle Invalid Data. (Clear Validation Circles removes them.) You see 4 circles. Equivalent formula (uses the facility–department map in Lists!J:K): =SUMPRODUCT(--(COUNTIFS(Lists!$J$2:$J$31,IntakeLog!H2:H51,Lists!$K$2:$K$31,IntakeLog!I2:I51)=0)) | E10: {=SUMPRODUCT(--(COUNTIFS(Lists!$J$2:$J$31,IntakeLog!H2:H51,Lists!$K$2:$K$31,IntakeLog!I2:I51)=0))} | F10: Create from Selection turns the header "Cedar Ridge Medical Center" into the name Cedar_Ridge_Medical_Center, because names can't contain spaces. SUBSTITUTE makes the same change to the facility in column H, and INDIRECT turns that text into a reference to the named range. Because $H2 has no $ before the row, every row builds its list from its own facility. The circled entries are real departments at the wrong facility: Pediatric Clinic, for example, is at the Outpatient Pavilion, not at Bluestone Memorial Hospital.
A11: 7 | B11: Labs sheet: the lab interface re-sent some results, so a few LabResultIDs appear more than once. Select A2:A322 and apply Highlight Cells Rules → Duplicate Values. How many cells are highlighted? | C11: 13 | D11: 1. On Labs, select A2:A322. 2. Home → Conditional Formatting → Highlight Cells Rules → Duplicate Values. Keep Duplicate and the light red fill, then click OK. 3. Count the highlighted cells (or filter the column by color and read the status bar): 13. Equivalent formula: =SUMPRODUCT(--(COUNTIF(Labs!A2:A322,Labs!A2:A322)>1)) | E11: {=SUMPRODUCT(--(COUNTIF(Labs!A2:A322,Labs!A2:A322)>1))} | F11: Duplicate Values highlights every copy of a repeated value, including the first one. There are 6 repeated IDs: five appear twice and one appears three times, so 13 cells light up even though only 7 rows are extra. When you clean the feed, you delete 7 rows, not 13.
A12: 8 | B12: Labs, TATMin (L2:L322): turnaround minutes from specimen collection to result. Apply Top/Bottom Rules → Top 10 Items. What is the smallest TAT that your rule highlights? | C12: 99 | D12: 1. Select L2:L322. 2. Home → Conditional Formatting → Top/Bottom Rules → Top 10 Items. Keep 10, click OK. 3. Sort or filter by color to read the smallest highlighted value. Equivalent formula: =LARGE(Labs!L2:L322,10) | E12: {=LARGE(Labs!L2:L322,10)} | F12: Top 10 Items highlights the 10 largest values plus any cell tied with the 10th, so a tie at the boundary can light up 11 or 12 cells. Here there's no tie at the boundary, so exactly 10 cells are highlighted. Either way, the smallest highlighted value is LARGE(range,10).
A13: 9 | B13: Supplies, PctOfPar (K2:K258) = QtyOnHand ÷ ParLevel. Add Data Bars, then edit the rule so Minimum is Number 0 and Maximum is Number 1. A full bar now means "stocked to par." How many items show a completely full bar? | C13: 78 | D13: 1. On Supplies, select K2:K258. 2. Home → Conditional Formatting → Data Bars and pick any fill. 3. Conditional Formatting → Manage Rules → Edit Rule. Set Minimum Type = Number, Value = 0, and Maximum Type = Number, Value = 1. Click OK twice. 4. Count the full bars: 78. Equivalent formula: =COUNTIF(Supplies!K2:K258,">=1") | E13: {=COUNTIF(Supplies!K2:K258,">=1")} | F13: With the default Automatic settings, the longest bar belongs to the largest value (about 135% of par), so an item stocked exactly to par looks only about three-quarters full. Fixing the Maximum at 1 gives bar length a meaning: every item at or above 100% of par gets a full bar, and an item at 50% gets a half bar.
A14: 10 | B14: Census sheet (Medical-Surgical 5 East, Nov–Dec 2025): apply the Red - Yellow - Green Color Scale to Occupancy (F2:F62) so the fullest days are red. In Manage Rules → Edit Rule you'll see the midpoint is the 50th percentile. Which occupancy gets the pure yellow midpoint color? Enter it as a percentage to 1 decimal place. | C14: 0.90625 | D14: 1. On Census, select F2:F62. 2. Home → Conditional Formatting → Color Scales → Red - Yellow - Green Color Scale. The first color in the name goes to the highest values, so high occupancy is red. 3. Conditional Formatting → Manage Rules → Edit Rule shows Minimum = Lowest Value, Midpoint = Percentile 50, Maximum = Highest Value. Equivalent formula: =MEDIAN(Census!F2:F62) | E14: {=MEDIAN(Census!F2:F62)} | F14: The 50th percentile is the median, the middle value when you sort the days by occupancy. Here 17 days have exactly that occupancy, so they show pure yellow. So the default color scale's middle color marks a typical day for this unit, not a target. To color against a target such as 85%, change the midpoint Type to Number (you'll do that in the bonus).
A15: 11 | B15: Labs, TATMin: apply Icon Sets → 3 Traffic Lights (Unrimmed). Edit the rule: click Reverse Icon Order, set both Types to Number, and make red show when the value is >= 60 and yellow when it is >= 45 (green below 45). How many cells show a yellow light? | C15: 79 | D15: 1. Select L2:L322 → Home → Conditional Formatting → Icon Sets → 3 Traffic Lights (Unrimmed). 2. Manage Rules → Edit Rule. Click Reverse Icon Order so red is on top. 3. Red: >=, Value 60, Type Number. Yellow: >=, Value 45, Type Number. Green covers everything below 45. Click OK twice. Equivalent formula: =COUNTIFS(Labs!L2:L322,">=45",Labs!L2:L322,"<60") | E15: {=COUNTIFS(Labs!L2:L322,">=45",Labs!L2:L322,"<60")} | F15: The default thresholds are Percent 67 and 33. They split the span between the lowest and highest TAT into thirds, so they don't mean minutes at all. Switching the Type to Number makes the thresholds literal. Reverse Icon Order puts red on the high (slow) values. Yellow covers 45 ≤ TAT < 60 because each icon's test is ">=" and the red test is checked first. (83 results are red.)
A16: 12 | B16: Labs: highlight the entire row of every critical result (AbnormalFlag HH or LL). Select A2:L322 with A2 active, choose New Rule → "Use a formula to determine which cells to format," and set a red fill. How many rows are highlighted? | C16: 14 | D16: 1. On Labs, type A2:L322 in the Name Box and press Enter. The rows are selected and A2 is the active cell. 2. Home → Conditional Formatting → New Rule → Use a formula to determine which cells to format. 3. Formula: =OR($K2="HH",$K2="LL"). Click Format → Fill, pick red, then OK twice. Equivalent formula: =COUNTIF(Labs!K2:K322,"HH")+COUNTIF(Labs!K2:K322,"LL") | E16: {=COUNTIF(Labs!K2:K322,"HH")+COUNTIF(Labs!K2:K322,"LL")} | F16: You write the rule for the active cell's row (row 2), and Excel shifts it for every other cell in the Applies-to range. $K keeps every cell in the row looking at column K, and the unlocked 2 lets each row check its own flag. Without the $, cell B2 would test L2 and the rule breaks. There are 12 HH and 2 LL results, so 14 rows turn red.
A17: 13 | B17: Supplies: add two formula rules to A2:M258. Rule 1 (red fill): the item has expired, meaning ExpirationDate is not blank and is on or before ReportDate. Rule 2 (amber fill): ExpirationDate is not blank and is on or before ReportDate + ExpiringWindowDays. ReportDate (12/31/2025) and ExpiringWindowDays (90) are named cells on the Lists sheet. Excel puts each new rule at the top of the list, so open Manage Rules and move the red rule above the amber rule. How many rows are amber? | C17: 7 | D17: 1. On Supplies, select A2:M258 with A2 active. 2. New Rule → Use a formula: =AND($L2<>"",$L2<=ReportDate) with a red fill → OK. 3. With the same range selected, add a second rule: =AND($L2<>"",$L2<=ReportDate+ExpiringWindowDays) with an amber (light orange) fill → OK. 4. Conditional Formatting → Manage Rules, set Show formatting rules for: This Worksheet. The amber rule is on top because Excel adds each new rule at the top of the list. Select the red rule and click ▲ (Move Up) so it sits above the amber rule, then click OK. Equivalent formula: =COUNTIFS(Supplies!L2:L258,">"&ReportDate,Supplies!L2:L258,"<="&ReportDate+ExpiringWindowDays) | E17: {=COUNTIFS(Supplies!L2:L258,">"&ReportDate,Supplies!L2:L258,"<="&ReportDate+ExpiringWindowDays)} | F17: Rule 2 is TRUE for 17 rows, because every expired item also expires before ReportDate + 90. The red rule sits above it and both rules set a fill, so red wins on the 10 expired rows and 7 rows stay amber. If you skip the move, the newer amber rule stays on top and you'd see 17 amber rows and no red. The $L2<>"" guard matters too: an empty cell counts as 0 (the date 1/0/1900), which is "on or before ReportDate," so without the guard all 121 non-perishable items would turn red.

Sheet Bonus Key
A1: 🔑 Bonus Key — Lesson 3.2
A2: Spoiler alert — try every task before reading this sheet. Column C is the value the Check column compares against. Column D is a sample solution; column E is that same formula, live, proving it works.
A4: # | B4: Task | C4: Answer | D4: Sample solution | E4: Live result | F4: Explanation
A5: B1 | B5: Apply a 3-color scale to Occupancy (G12:G29): Minimum = Lowest Value (green), Midpoint = Number 0.85 (yellow, the planning target), Maximum = Highest Value (red). How many units are shaded on the red side of yellow (occupancy above 85%)? | C5: 9 | D5: 1. Select G12:G29 on Huddle → Conditional Formatting → New Rule → Format all cells based on their values. 2. Format Style = 3-Color Scale. Minimum: Lowest Value, green. Midpoint: Type Number, Value 0.85, yellow. Maximum: Highest Value, red. Click OK. Equivalent formula: =COUNTIF(Huddle!G12:G29,">0.85") | E5: {=COUNTIF(Huddle!G12:G29,">0.85")} | F5: With a Number midpoint, yellow means "exactly at target" instead of "a typical unit." Every unit above 85% shades from yellow toward red, and the reddest cell is simply the fullest unit.
A6: B2 | B6: Apply Icon Sets → 3 Arrows (Colored) to Change (F12:F29). Edit the rule so both Types are Number: up arrow when the value is >= 1, sideways arrow when it is >= 0, down arrow otherwise. How many units show an up arrow? | C6: 7 | D6: 1. Select F12:F29 → Conditional Formatting → Icon Sets → 3 Arrows (Colored). 2. Manage Rules → Edit Rule: green up arrow >= 1 Number, yellow sideways arrow >= 0 Number. The red down arrow covers negative changes. Click OK twice. Equivalent formula: =COUNTIF(Huddle!F12:F29,">=1") | E6: {=COUNTIF(Huddle!F12:F29,">=1")} | F6: Census rose overnight on 7 units, held steady on 10, and fell on 1. Number thresholds keep the arrows honest on any day. The default Percent thresholds depend on the day's smallest and largest change, so a unit that gained one patient could show a sideways arrow on a busier day.
A7: B3 | B7: Add two formula rules to the whole board (A12:G29): a red fill when the 11/25 census is above staffed beds (overflow), and an amber fill when occupancy is at least 90%. In Manage Rules, put the overflow rule above the amber rule. How many rows end up amber? | C7: 3 | D7: 1. Select A12:G29 with A12 active. 2. New Rule → Use a formula: =$E12>$C12, red fill. 3. New Rule → Use a formula: =$G12>=0.9, amber fill. 4. Manage Rules (This Worksheet): Excel added the amber rule at the top because it's newer. Select the overflow rule and click ▲ so it's on top. Equivalent formula: =SUMPRODUCT((Huddle!G12:G29>=0.9)*(Huddle!E12:E29<=Huddle!C12:C29)) | E7: {=SUMPRODUCT((Huddle!G12:G29>=0.9)*(Huddle!E12:E29<=Huddle!C12:C29))} | F7: There are 2 overflow units, and both rules are TRUE for them. The overflow rule is on top, so those rows stay red, and 3 rows are amber. Two of those amber units sit at exactly 90.0%, so writing > 0.9 instead of >= 0.9 would lose them. With the rules in the wrong order every overflow row would turn amber too.
A8: B4 | B8: Build the unit selector. Give B4 a List validation from the Hospitals list (I12:I14). Give B5 a dependent List built from the board's own Facility and Unit columns, with no named ranges. Then choose Cedar Ridge Medical Center → Intensive Care Unit. The gray cell shows the card's Nov 1–25 occupancy. What is it? | C8: 0.83666667 | D8: 1. Select B4 on Huddle → Data Validation → List, Source =$I$12:$I$14. 2. Select B5 → Data Validation → List, Source: =OFFSET($B$11,MATCH($B$4,$A$12:$A$29,0),0,COUNTIF($A$12:$A$29,$B$4),1) MATCH finds the facility's first row on the board, and COUNTIF counts its units. The board is sorted by facility, so OFFSET returns exactly that facility's block of unit names. If B4 is still empty, Excel warns that the source currently evaluates to an error. Click Yes, or pick a facility in B4 first. 3. Pick Cedar Ridge Medical Center in B4, then Intensive Care Unit in B5. Read the card. If you prefer INDIRECT, copy each hospital's units into its own column under the hospital's name (like the Lists sheet in task 6), name the columns with Create from Selection, and use =INDIRECT(SUBSTITUTE($B$4," ","_")). The result is the same. | E8: {=SUMIFS(NovCensus!$E$2:$E$451,NovCensus!$B$2:$B$451,"Cedar Ridge Medical Center",NovCensus!$C$2:$C$451,"Intensive Care Unit")/SUMIFS(NovCensus!$D$2:$D$451,NovCensus!$B$2:$B$451,"Cedar Ridge Medical Center",NovCensus!$C$2:$C$451,"Intensive Care Unit")} | F8: Three hospitals each have an Intensive Care Unit, so the unit name alone is ambiguous. The dependent list forces a facility first and then offers only that facility's units, and the card's SUMIFS uses both cells. The OFFSET version needs no named ranges, so it keeps working when you add a unit to the board (as long as the board stays sorted by facility).

Sheet Huddle Key
A1: 7 a.m. Bed Huddle · Wednesday, November 26, 2025 (finished key)
A2: Midnight census for Tuesday 11/25 vs Monday 11/24, every inpatient unit in the system. Yellow cells are yours, and gray cells hold formulas.
A3: UNIT SELECTOR
A4: Facility | B4: Cedar Ridge Medical Center
A5: Unit | B5: Intensive Care Unit
A6: Staffed beds | B6: =IF(OR($B$4="",$B$5=""),"",IF(COUNTIFS($A$12:$A$29,$B$4,$B$12:$B$29,$B$5)=0,"n/a",SUMIFS($C$12:$C$29,$A$12:$A$29,$B$4,$B$12:$B$29,$B$5)))
