Workbook

Sheet Start Here
B2: Lesson 2.1
B3: Logical Functions: IF, AND, OR, IFS & More
B4: Beginner → Intermediate · about 50 minutes · Bluestone Health System (fictional)
B6: What you'll learn
B7: • | C7: Compare values to produce TRUE/FALSE and use booleans in math
B8: • | C8: Make decisions with IF, nested IF, and IFS
B9: • | C9: Combine conditions with AND, OR, NOT (and XOR)
B10: • | C10: Map codes to labels with SWITCH; trap errors with IFERROR and IFNA
B12: How to use this workbook
B13: 1. Read the guide | C13: The lesson guide (README) explains each skill with examples: https://github.com/lmansf/learn-excel/tree/main/02-formulas-functions/01-logical-functions
B14: 2. Practice | C14: Go to the 'Practice' sheet. Type a formula or value into each yellow cell.
B15: 3. Check yourself | C15: The Check column shows ✔ Correct (green) or ✘ Not yet (red). Tasks marked 'See key' are checked by comparing with the answer key.
B16: 4. Bonus | C16: Finished? Try the harder 'Bonus' sheet.
B17: 5. Answers | C17: The 'Answer Key' and 'Bonus Key' sheets are hidden. Right-click any sheet tab → Unhide… → pick one → OK. (Try first!)
B18: Note | C18: The clinical rules in this lesson (lab flags, SIRS, qSOFA, shock index, fast track) are simplified for teaching spreadsheet logic. They are not clinical guidance.
B20: Color legend
B21: Yellow cell | C21: Your answer goes here.
B22: Gray cell | C22: Pre-filled summary formula — it reads the work you did on another sheet.
B23: ✔ Correct | C23: Your answer matches the key.
B24: ✘ Not yet | C24: Not matching yet — check the hint and try again.
B26: Sheets in this workbook
B27: Labs | C27: Data: 391 rows — Excel Table 'tblLabs'
B28: ED | C28: Data: 423 rows — Excel Table 'tblED'
B29: About the data | C29: 391 lab results collected December 1–4, 2025 across Bluestone Health, and all 423 emergency department visits at Bluestone Memorial Hospital in December 2025 with triage vital signs. Triage blood pressure was not recorded for 12 of those visits.
B30: Disclaimer | C30: All people, places, and numbers are synthetic and fictional. Not clinical guidance.

Sheet Practice
A1: Lesson 2.1 · Practice
A2: Tasks 1–3 use the Labs sheet. Tasks 4–13 use the ED sheet. Several tasks ask you to fill one of the yellow columns on a data sheet: type the formula in the first data row and Excel fills the rest of the Table column for you (if it doesn't, double-click the fill handle). The gray cell on this sheet then summarizes your column. When a formula on this sheet points at a data sheet, include the sheet name (for example Labs!E38), or click the cell on that sheet and Excel adds the name for you.
A3: Type a formula or value in each yellow cell. The Check column turns green when your answer matches. Stuck? Read the hint, then the lesson guide. Answers: right-click a sheet tab → Unhide… → 'Answer Key'.
A4: ="Score: "&COUNTIF(E6:E18,"✔*")&" of 13 auto-checked tasks correct"
A5: # | B5: Task | C5: Hint | D5: Your Answer | E5: Check
A6: 1 | B6: Labs row 38 holds a White Blood Cell Count result of 11 K/uL. Write a comparison that returns TRUE if that ResultValue is greater than its RefHigh, and FALSE if not. | C6: A comparison needs no function: just =cell>cell. Include the sheet name (Labs!) in both references | E6: =IF(IFERROR(D6="",FALSE),"",IF(IFERROR(D6='Answer Key'!$C$5,FALSE),"✔ Correct","✘ Not yet"))
A7: 2 | B7: How many of the lab results are above their reference high (ResultValue greater than RefHigh)? Use one formula that turns every row's comparison into a 1 or 0 and adds them up. | C7: -- turns TRUE/FALSE into 1/0, and SUMPRODUCT adds them up | E7: =IF(IFERROR(D7="",FALSE),"",IF(IFERROR(AND(ISNUMBER(D7),OR(ABS(D7-'Answer Key'!$C$6)<=0.0001)),FALSE),"✔ Correct","✘ Not yet"))
A8: 3 | B8: Fill the yellow Flag column on the Labs sheet with a nested IF: "High" if ResultValue is greater than RefHigh, "Low" if it is less than RefLow, otherwise "Normal". A result exactly on a limit is Normal. Start in J2. The gray cell counts your "Normal" flags. | C8: IF(test, "High", IF(test, "Low", "Normal")) | D8: {=IF(COUNTA('Labs'!$J$2:$J$392)=0,"",COUNTIF('Labs'!$J$2:$J$392,"Normal"))} | E8: =IF(IFERROR(D8="",FALSE),"",IF(IFERROR(AND(ISNUMBER(D8),OR(ABS(D8-'Answer Key'!$C$7)<=0.0001)),FALSE),"✔ Correct","✘ Not yet"))
A9: 4 | B9: Fill the yellow PainLevel column on the ED sheet with IFS: PainScore 0 is "None", 1–3 is "Mild", 4–6 is "Moderate", and 7–10 is "Severe". Start in M2. The gray cell counts your "Moderate" rows. | C9: Test from the lowest band up, and end with TRUE as the catch-all | D9: {=IF(COUNTA('ED'!$M$2:$M$424)=0,"",COUNTIF('ED'!$M$2:$M$424,"Moderate"))} | E9: =IF(IFERROR(D9="",FALSE),"",IF(IFERROR(AND(ISNUMBER(D9),OR(ABS(D9-'Answer Key'!$C$8)<=0.0001)),FALSE),"✔ Correct","✘ Not yet"))
A10: 5 | B10: How many ED visits had an abnormal temperature: TempF above 100.4 OR below 96.8? | C10: Adding two TRUE/FALSE lists works like OR when both can't be TRUE at once | E10: =IF(IFERROR(D10="",FALSE),"",IF(IFERROR(AND(ISNUMBER(D10),OR(ABS(D10-'Answer Key'!$C$9)<=0.0001)),FALSE),"✔ Correct","✘ Not yet"))
A11: 6 | B11: How many visits had BOTH a fever (TempF above 100.4) AND tachycardia (HeartRate above 90)? | C11: Multiplying two TRUE/FALSE lists works like AND | E11: =IF(IFERROR(D11="",FALSE),"",IF(IFERROR(AND(ISNUMBER(D11),OR(ABS(D11-'Answer Key'!$C$10)<=0.0001)),FALSE),"✔ Correct","✘ Not yet"))
A12: 7 | B12: The sepsis coordinator already reviews visits with both signs. How many visits had exactly ONE of the two: a fever (TempF above 100.4) or tachycardia (HeartRate above 90), but not both? | C12: This is XOR logic. Use XOR in a helper column, or compare the two TRUE/FALSE lists with <> | E12: =IF(IFERROR(D12="",FALSE),"",IF(IFERROR(AND(ISNUMBER(D12),OR(ABS(D12-'Answer Key'!$C$11)<=0.0001)),FALSE),"✔ Correct","✘ Not yet"))
A13: 8 | B13: Fill the yellow FastTrack column: "Fast Track" when ESILevel is 4 or 5 AND ArrivalMode is "Walk-In" AND the ChiefComplaint is NOT "Chest Pain" or "Shortness of Breath" (it is neither one). Every other visit is "Main ED". Start in N2. The gray cell counts your "Fast Track" rows. | C13: IF(AND(…, …, NOT(OR(…, …))), "Fast Track", "Main ED") | D13: {=IF(COUNTA('ED'!$N$2:$N$424)=0,"",COUNTIF('ED'!$N$2:$N$424,"Fast Track"))} | E13: =IF(IFERROR(D13="",FALSE),"",IF(IFERROR(AND(ISNUMBER(D13),OR(ABS(D13-'Answer Key'!$C$12)<=0.0001)),FALSE),"✔ Correct","✘ Not yet"))
A14: 9 | B14: Fill the yellow SIRS column with a vital-sign SIRS score from 0 to 3: one point for an abnormal temperature (TempF above 100.4 OR below 96.8), one for HeartRate above 90, and one for RespRate above 20. Start in O2. The gray cell adds up your whole column. | C14: TRUE + TRUE = 2. Add three TRUE/FALSE tests together | D14: {=IF(COUNTA('ED'!$O$2:$O$424)=0,"",SUM('ED'!$O$2:$O$424))} | E14: =IF(IFERROR(D14="",FALSE),"",IF(IFERROR(AND(ISNUMBER(D14),OR(ABS(D14-'Answer Key'!$C$13)<=0.0001)),FALSE),"✔ Correct","✘ Not yet"))
A15: 10 | B15: How many visits are SIRS-positive, meaning a score of 2 or more in your SIRS column? | C15: COUNTIF with a ">=2" criterion | E15: =IF(IFERROR(D15="",FALSE),"",IF(IFERROR(AND(ISNUMBER(D15),OR(ABS(D15-'Answer Key'!$C$14)<=0.0001)),FALSE),"✔ Correct","✘ Not yet"))
A16: 11 | B16: Fill the yellow ESIName column with SWITCH: ESILevel 1 is "Resuscitation", 2 is "Emergent", 3 is "Urgent", 4 is "Less Urgent", 5 is "Non-Urgent". Start in P2. The gray cell counts your "Emergent" rows. | C16: SWITCH(value, 1, "…", 2, "…", …) | D16: {=IF(COUNTA('ED'!$P$2:$P$424)=0,"",COUNTIF('ED'!$P$2:$P$424,"Emergent"))} | E16: =IF(IFERROR(D16="",FALSE),"",IF(IFERROR(AND(ISNUMBER(D16),OR(ABS(D16-'Answer Key'!$C$15)<=0.0001)),FALSE),"✔ Correct","✘ Not yet"))
A17: 12 | B17: Shock index = HeartRate ÷ SystolicBP, and 1.0 or more is a warning sign. Fill the yellow ShockIndex column, wrapping the division in IFERROR so the 12 visits with no SystolicBP show a blank ("") instead of #DIV/0!. Start in Q2. The gray cell counts visits with a shock index of 1.0 or higher (it asks you to fix any errors first). | C17: IFERROR(value, value_if_error) | D17: {=IF(COUNTA('ED'!$Q$2:$Q$424)=0,"",IF(SUMPRODUCT(--ISERROR('ED'!$Q$2:$Q$424))>0,"Fix the errors first",COUNTIF('ED'!$Q$2:$Q$424,">=1")))} | E17: =IF(IFERROR(D17="",FALSE),"",IF(IFERROR(AND(ISNUMBER(D17),OR(ABS(D17-'Answer Key'!$C$16)<=0.0001)),FALSE),"✔ Correct","✘ Not yet"))
A18: 13 | B18: Visit ED211716 (ED row 13) has no SystolicBP. In the yellow cell, calculate its shock index again, but wrap the division in IFNA(…, "") instead of IFERROR. The check turns green when your cell shows the error that IFNA lets through. | C18: IFNA traps only one kind of error | E18: =IF(IFERROR(D18="",FALSE),"",IF(IFERROR(AND(IFERROR(ERROR.TYPE(D18)=2,FALSE),ISNUMBER(SEARCH("IFNA",_xlfn.FORMULATEXT(D18)))),FALSE),"✔ Correct","✘ Not yet"))

Sheet Labs
A1: LabResultID | B1: PatientID | C1: CollectedDateTime | D1: TestName | E1: ResultValue | F1: Units | G1: RefLow | H1: RefHigh | I1: Priority | J1: Flag
A2: LAB749134 | B2: PT12857 | C2: 45992.265 | D2: B-Type Natriuretic Peptide | E2: 1203 | F2: pg/mL | G2: 0 | H2: 100 | I2: STAT
A3: LAB749129 | B3: PT12857 | C3: 45992.278 | D3: Glucose | E3: 132 | F3: mg/dL | G3: 70 | H3: 99 | I3: STAT
A4: LAB749131 | B4: PT12857 | C4: 45992.279 | D4: White Blood Cell Count | E4: 10.6 | F4: K/uL | G4: 4.5 | H4: 11 | I4: Routine
A5: LAB749132 | B5: PT12857 | C5: 45992.279 | D5: Hemoglobin | E5: 15.2 | F5: g/dL | G5: 12 | H5: 17.5 | I5: Routine
A6: LAB749130 | B6: PT12857 | C6: 45992.28 | D6: Creatinine | E6: 0.99 | F6: mg/dL | G6: 0.6 | H6: 1.3 | I6: Routine
A7: LAB749133 | B7: PT12857 | C7: 45992.284 | D7: Troponin I, High Sensitivity | E7: 67 | F7: ng/L | G7: 0 | H7: 34 | I7: STAT
A8: LAB749138 | B8: PT13060 | C8: 45992.321 | D8: Hemoglobin | E8: 12.4 | F8: g/dL | G8: 12 | H8: 17.5 | I8: Routine
A9: LAB749135 | B9: PT13060 | C9: 45992.326 | D9: Glucose | E9: 114 | F9: mg/dL | G9: 70 | H9: 99 | I9: STAT
A10: LAB749136 | B10: PT13060 | C10: 45992.328 | D10: Creatinine | E10: 1.34 | F10: mg/dL | G10: 0.6 | H10: 1.3 | I10: STAT
A11: LAB749140 | B11: PT10001 | C11: 45992.329 | D11: Creatinine | E11: 0.88 | F11: mg/dL | G11: 0.6 | H11: 1.3 | I11: STAT
A12: LAB749137 | B12: PT13060 | C12: 45992.331 | D12: White Blood Cell Count | E12: 9.4 | F12: K/uL | G12: 4.5 | H12: 11 | I12: STAT
A13: LAB749139 | B13: PT10001 | C13: 45992.339 | D13: Glucose | E13: 59 | F13: mg/dL | G13: 70 | H13: 99 | I13: STAT
... A392: LAB749523 | B392: PT12993 | C392: 45995.997 | D392: White Blood Cell Count | E392: 14.8 | F392: K/uL | G392: 4.5 | H392: 11 | I392: Routine

Sheet ED
A1: EDVisitID | B1: ArrivalDateTime | C1: ArrivalMode | D1: ESILevel | E1: ChiefComplaint | F1: TempF | G1: HeartRate | H1: RespRate | I1: SystolicBP | J1: SpO2 | K1: PainScore | L1: EDDisposition | M1: PainLevel | N1: FastTrack | O1: SIRS | P1: ESIName | Q1: ShockIndex | R1: qSOFA
A2: ED211698 | B2: 45992.123 | C2: Walk-In | D2: 3 | E2: Laceration | F2: 98.2 | G2: 73 | H2: 22 | I2: 126 | J2: 89 | K2: 1 | L2: Observation
A3: ED211699 | B3: 45992.34 | C3: Ambulance | D3: 3 | E3: Fainting | F3: 98.2 | G3: 95 | H3: 14 | I3: 105 | J3: 97 | K3: 0 | L3: Discharged
A4: ED211700 | B4: 45992.358 | C4: Walk-In | D4: 3 | E4: Shortness of Breath | F4: 98.2 | G4: 94 | H4: 20 | I4: 111 | J4: 98 | K4: 0 | L4: Discharged
A5: ED211701 | B5: 45992.374 | C5: Walk-In | D5: 4 | E5: Painful Urination / Fever | F5: 100.7 | G5: 109 | H5: 15 | I5: 139 | J5: 96 | K5: 2 | L5: Admitted
A6: ED211703 | B6: 45992.486 | C6: Walk-In | D6: 4 | E6: Cough / Trouble Breathing | F6: 98.3 | G6: 134 | H6: 39 | I6: 106 | J6: 82 | K6: 0 | L6: LWBS
A7: ED211704 | B7: 45992.494 | C7: Ambulance | D7: 1 | E7: Fever / Altered Mental Status | F7: 99.4 | G7: 112 | H7: 27 | I7: 103 | J7: 89 | K7: 1 | L7: Admitted
A8: ED211705 | B8: 45992.5 | C8: Walk-In | D8: 4 | E8: Cough / Trouble Breathing | F8: 98 | G8: 120 | H8: 37 | I8: 87 | J8: 88 | K8: 0 | L8: Discharged
A9: ED211707 | B9: 45992.551 | C9: Walk-In | D9: 3 | E9: Chest Pain | F9: 97.6 | G9: 90 | H9: 16 | I9: 169 | J9: 97 | K9: 7 | L9: Discharged
A10: ED211709 | B10: 45992.641 | C10: Walk-In | D10: 3 | E10: Laceration | F10: 101 | G10: 62 | H10: 16 | I10: 149 | J10: 99 | K10: 2 | L10: Discharged
A11: ED211710 | B11: 45992.692 | C11: Walk-In | D11: 3 | E11: Cough / Fever | F11: 102.3 | G11: 98 | H11: 21 | I11: 115 | J11: 95 | K11: 0 | L11: Admitted
A12: ED211713 | B12: 45992.835 | C12: Walk-In | D12: 3 | E12: Vomiting / Diarrhea | F12: 98.9 | G12: 98 | H12: 15 | I12: 108 | J12: 98 | K12: 1 | L12: Discharged
A13: ED211716 | B13: 45992.891 | C13: Walk-In | D13: 4 | E13: Cough / Fever | F13: 98.7 | G13: 77 | H13: 16 | J13: 97 | K13: 1 | L13: Discharged
A14: ED211717 | B14: 45992.921 | C14: Walk-In | D14: 5 | E14: Ankle Injury | F14: 98.6 | G14: 79 | H14: 15 | I14: 125 | J14: 98 | K14: 4 | L14: Discharged
A15: ED211718 | B15: 45992.953 | C15: Ambulance | D15: 2 | E15: Weakness / Numbness | F15: 98.6 | G15: 85 | H15: 16 | I15: 169 | J15: 97 | K15: 1 | L15: Admitted
A16: ED211719 | B16: 45993.192 | C16: Ambulance | D16: 3 | E16: Abdominal Pain | F16: 98.6 | G16: 103 | H16: 14 | I16: 116 | J16: 97 | K16: 10 | L16: Admitted
A17: ED211720 | B17: 45993.231 | C17: Walk-In | D17: 3 | E17: Cough / Fever | F17: 102.3 | G17: 104 | H17: 21 | I17: 146 | J17: 89 | K17: 3 | L17: Discharged
A18: ED211721 | B18: 45993.327 | C18: Walk-In | D18: 4 | E18: Cough / Fever | F18: 99.1 | G18: 81 | H18: 13 | I18: 147 | J18: 99 | K18: 0 | L18: Discharged
A19: ED211723 | B19: 45993.425 | C19: Walk-In | D19: 3 | E19: Chest Pain | F19: 97.5 | G19: 84 | H19: 18 | I19: 140 | J19: 98 | K19: 4 | L19: Observation
A20: ED211724 | B20: 45993.467 | C20: Ambulance | D20: 1 | E20: Weakness / Numbness | F20: 98.3 | G20: 79 | H20: 19 | I20: 197 | J20: 86 | K20: 3 | L20: Admitted
A21: ED211725 | B21: 45993.485 | C21: Walk-In | D21: 5 | E21: Cough / Fever | F21: 99.5 | G21: 78 | H21: 17 | I21: 107 | J21: 97 | K21: 3 | L21: Discharged
A22: ED211726 | B22: 45993.489 | C22: Ambulance | D22: 2 | E22: High Blood Sugar | F22: 98.4 | G22: 78 | H22: 15 | I22: 166 | J22: 99 | K22: 2 | L22: Admitted
A23: ED211727 | B23: 45993.567 | C23: Walk-In | D23: 2 | E23: Cough / Fever | F23: 99.9 | G23: 102 | H23: 21 | I23: 137 | J23: 93 | K23: 0 | L23: Admitted
A24: ED211728 | B24: 45993.589 | C24: Walk-In | D24: 5 | E24: Ankle Injury | F24: 98.2 | G24: 80 | H24: 15 | I24: 154 | J24: 95 | K24: 4 | L24: Discharged
A25: ED211729 | B25: 45993.609 | C25: Walk-In | D25: 3 | E25: Shortness of Breath | F25: 99.1 | G25: 115 | H25: 28 | I25: 125 | J25: 85 | K25: 0 | L25: Discharged
... A49: ED211770 | B49: 45995.592 | C49: Walk-In | D49: 3 | E49: Abdominal Pain | F49: 98.5 | G49: 85 | H49: 18 | I49: 116 | J49: 98 | K49: 10 | L49: Observation
A50: ED211772 | B50: 45995.722 | C50: Walk-In | D50: 3 | E50: Weakness / Numbness | F50: 98.8 | G50: 95 | H50: 13 | J50: 98 | K50: 2 | L50: Admitted
A51: ED211773 | B51: 45995.79 | C51: Ambulance | D51: 2 | E51: Weakness / Numbness | F51: 98.7 | G51: 86 | H51: 15 | I51: 166 | J51: 97 | K51: 2 | L51: Admitted
A52: ED211774 | B52: 45995.792 | C52: Walk-In | D52: 4 | E52: Cough / Trouble Breathing | F52: 98.4 | G52: 140 | H52: 23 | I52: 101 | J52: 88 | K52: 2 | L52: Discharged
A53: ED211775 | B53: 45995.804 | C53: Ambulance | D53: 3 | E53: Vomiting / Diarrhea | F53: 98.5 | G53: 97 | H53: 18 | I53: 130 | J53: 97 | K53: 1 | L53: Observation
A54: ED211776 | B54: 45995.812 | C54: Ambulance | D54: 2 | E54: Shortness of Breath | F54: 98.4 | G54: 62 | H54: 25 | I54: 120 | J54: 89 | K54: 2 | L54: Admitted
A55: ED211777 | B55: 45995.866 | C55: Walk-In | D55: 4 | E55: Painful Urination / Fever | F55: 99.3 | G55: 81 | H55: 18 | I55: 127 | J55: 98 | K55: 0 | L55: Admitted
A56: ED211778 | B56: 45995.945 | C56: Walk-In | D56: 5 | E56: Cough / Fever | F56: 98.5 | G56: 71 | H56: 14 | I56: 125 | J56: 99 | K56: 0 | L56: Discharged
A57: ED211779 | B57: 45996.251 | C57: Walk-In | D57: 4 | E57: Shortness of Breath | F57: 98 | G57: 91 | H57: 22 | I57: 112 | J57: 97 | K57: 3 | L57: Admitted
A58: ED211780 | B58: 45996.308 | C58: Walk-In | D58: 3 | E58: Skin Redness / Swelling | F58: 101.3 | G58: 76 | H58: 11 | I58: 143 | J58: 97 | K58: 3 | L58: Discharged
A59: ED211781 | B59: 45996.34 | C59: Ambulance | D59: 3 | E59: Headache | F59: 97.6 | G59: 86 | H59: 17 | I59: 161 | J59: 97 | K59: 10 | L59: Discharged
A60: ED211782 | B60: 45996.409 | C60: Ambulance | D60: 2 | E60: Chest Pain | F60: 98.3 | G60: 94 | H60: 15 | I60: 142 | J60: 99 | K60: 9 | L60: Discharged
A61: ED211783 | B61: 45996.423 | C61: Walk-In | D61: 4 | E61: Back Pain | F61: 98.2 | G61: 92 | H61: 18 | I61: 134 | J61: 98 | K61: 6 | L61: Discharged
A62: ED211784 | B62: 45996.438 | C62: Ambulance | D62: 3 | E62: Cough / Fever | F62: 100.2 | G62: 89 | H62: 20 | I62: 104 | J62: 89 | K62: 1 | L62: Discharged
... A86: ED211813 | B86: 45997.751 | C86: Walk-In | D86: 5 | E86: Ankle Injury | F86: 98.6 | G86: 83 | H86: 17 | I86: 140 | J86: 97 | K86: 4 | L86: Left AMA
...

Sheet Bonus
A1: Lesson 2.1 · Bonus: A qSOFA-style sepsis screen at triage
A2: The sepsis committee wants to know what a quick qSOFA-style screen would flag if triage nurses scored every ED patient. This simplified, educational version (not clinical guidance) gives one point for each of three findings. (1) RespRate is 22 or more. (2) SystolicBP is 100 or less. A blank (not recorded) SystolicBP earns NO point. (3) Altered mentation, meaning the ChiefComplaint contains the word "Altered" or "Confusion" anywhere. A score of 2 or more is screen-positive. Build the score in the yellow qSOFA column on the ED sheet, then answer the questions.
A3: Type a formula or value in each yellow cell. The Check column turns green when your answer matches. Stuck? Read the hint, then the lesson guide. Answers: right-click a sheet tab → Unhide… → 'Bonus Key'.
A4: ="Score: "&COUNTIF(E6:E10,"✔*")&" of 5 auto-checked tasks correct"
A5: # | B5: Task | C5: Hint | D5: Your Answer | E5: Check
A6: B1 | B6: Fill the qSOFA column (0–3) on the ED sheet, starting in R2. The gray cell adds up your whole column. What is the total number of qSOFA points? | C6: Add three tests. Guard the BP test with I2<>"". ISNUMBER(SEARCH("altered", E2)) tests 'contains' | D6: {=IF(COUNTA('ED'!$R$2:$R$424)=0,"",SUM('ED'!$R$2:$R$424))} | E6: =IF(IFERROR(D6="",FALSE),"",IF(IFERROR(AND(ISNUMBER(D6),OR(ABS(D6-'Bonus Key'!$C$5)<=0.0001)),FALSE),"✔ Correct","✘ Not yet"))
A7: B2 | B7: How many visits are screen-positive (a qSOFA score of 2 or more)? | C7: COUNTIF on your qSOFA column | E7: =IF(IFERROR(D7="",FALSE),"",IF(IFERROR(AND(ISNUMBER(D7),OR(ABS(D7-'Bonus Key'!$C$6)<=0.0001)),FALSE),"✔ Correct","✘ Not yet"))
A8: B3 | B8: What was the average HeartRate of the screen-positive visits? Round to 1 decimal place. | C8: AVERAGE(IF(test_range>=2, values_range)). AVERAGEIF (Lesson 2.5) also works | E8: =IF(IFERROR(D8="",FALSE),"",IF(IFERROR(AND(ISNUMBER(D8),OR(ABS(D8-'Bonus Key'!$C$7)<=0.051)),FALSE),"✔ Correct","✘ Not yet"))
A9: B4 | B9: Safety check: how many screen-positive visits ended with EDDisposition "Discharged" (sent home)? | C9: Two conditions over whole columns: multiply the TRUE/FALSE lists | E9: =IF(IFERROR(D9="",FALSE),"",IF(IFERROR(AND(ISNUMBER(D9),OR(ABS(D9-'Bonus Key'!$C$8)<=0.0001)),FALSE),"✔ Correct","✘ Not yet"))
A10: B5 | B10: The two screens don't always agree. How many visits are qSOFA screen-positive (2 or more) but NOT SIRS-positive (SIRS score below 2 in your SIRS column from task 9)? | C10: Same pattern as B4. 'NOT SIRS-positive' is simply SIRS<2 | E10: =IF(IFERROR(D10="",FALSE),"",IF(IFERROR(AND(ISNUMBER(D10),OR(ABS(D10-'Bonus Key'!$C$9)<=0.0001)),FALSE),"✔ Correct","✘ Not yet"))

Sheet Answer Key
A1: 🔑 Answer Key — Lesson 2.1
A2: Spoiler alert — try every task before reading this sheet. Column C is the value the Check column compares against. Column D is a sample solution; column E is that same formula, live, proving it works.
A4: # | B4: Task | C4: Answer | D4: Sample solution | E4: Live result | F4: Explanation
A5: 1 | B5: Labs row 38 holds a White Blood Cell Count result of 11 K/uL. Write a comparison that returns TRUE if that ResultValue is greater than its RefHigh, and FALSE if not. | C5: FALSE | D5: =Labs!E38>Labs!H38 | E5: {=Labs!E38>Labs!H38} | F5: A comparison always returns TRUE or FALSE. Here the result (11) is exactly equal to the upper limit (11), and *equal* is not *greater than*, so the answer is FALSE. With >= it would be TRUE. Choosing between > and >= is a definition decision, so always check the rule you were given.
A6: 2 | B6: How many of the lab results are above their reference high (ResultValue greater than RefHigh)? Use one formula that turns every row's comparison into a 1 or 0 and adds them up. | C6: 114 | D6: =SUMPRODUCT(--(Labs!E2:E392>Labs!H2:H392)) | E6: {=SUMPRODUCT(--(Labs!E2:E392>Labs!H2:H392))} | F6: Comparing two ranges row by row gives a list of TRUE/FALSE values. The double minus (--) converts them to 1s and 0s, and SUMPRODUCT adds them. In Microsoft 365 and Excel 2021 or later, =SUM(--(…>…)) works too. Plain SUM over a column of TRUE/FALSE *cells* returns 0, because SUM ignores logical values stored in cells.
A7: 3 | B7: Fill the yellow Flag column on the Labs sheet with a nested IF: "High" if ResultValue is greater than RefHigh, "Low" if it is less than RefLow, otherwise "Normal". A result exactly on a limit is Normal. Start in J2. The gray cell counts your "Normal" flags. | C7: 254 | D7: =IF(E2>H2,"High",IF(E2<G2,"Low","Normal")) | E7: {=SUMPRODUCT((Labs!E2:E392>=Labs!G2:G392)*(Labs!E2:E392<=Labs!H2:H392))} | F7: The first IF handles High. Its *value_if_false* argument is a second IF that handles Low, and "Normal" is whatever is left. Because the tests use > and <, the 14 results sitting exactly on a limit fall through to Normal. In the Table you may see it as =IF([@ResultValue]>[@RefHigh],"High",IF([@ResultValue]<[@RefLow],"Low","Normal")), which is the same formula.
A8: 4 | B8: Fill the yellow PainLevel column on the ED sheet with IFS: PainScore 0 is "None", 1–3 is "Mild", 4–6 is "Moderate", and 7–10 is "Severe". Start in M2. The gray cell counts your "Moderate" rows. | C8: 40 | D8: =IFS(K2=0,"None",K2<=3,"Mild",K2<=6,"Moderate",TRUE,"Severe") | E8: {=SUMPRODUCT((ED!K2:K424>=4)*(ED!K2:K424<=6))} | F8: IFS returns the result of the first test that is TRUE, so order matters. Testing <=3 before <=6 means a score of 2 stops at "Mild" and never reaches "Moderate". The final TRUE,"Severe" pair is the catch-all for everything left (7–10). Without it, any value that fails every test returns #N/A.
A9: 5 | B9: How many ED visits had an abnormal temperature: TempF above 100.4 OR below 96.8? | C9: 66 | D9: =SUMPRODUCT((ED!F2:F424>100.4)+(ED!F2:F424<96.8)) | E9: {=SUMPRODUCT((ED!F2:F424>100.4)+(ED!F2:F424<96.8))} | F9: + acts as OR over whole ranges, because each row scores 1 if either test is TRUE. That's safe here because no temperature can be both above 100.4 and below 96.8. (When both tests *can* be TRUE, write --((…)+(…)>0) so a row counts once. The -- is needed because >0 turns the sums back into TRUE/FALSE.) =COUNTIF(ED!F2:F424,">100.4")+COUNTIF(ED!F2:F424,"<96.8") gives the same answer.
A10: 6 | B10: How many visits had BOTH a fever (TempF above 100.4) AND tachycardia (HeartRate above 90)? | C10: 44 | D10: =SUMPRODUCT((ED!F2:F424>100.4)*(ED!G2:G424>90)) | E10: {=SUMPRODUCT((ED!F2:F424>100.4)*(ED!G2:G424>90))} | F10: * acts as AND over whole ranges. 1 × 1 = 1 only when both tests are TRUE, and anything × 0 = 0. =SUMPRODUCT(--AND(…)) does not work, because AND collapses the whole range into a single TRUE or FALSE instead of testing row by row. To use the AND function itself, put =AND(F2>100.4,G2>90) in a helper column and count the TRUEs with COUNTIF(range,TRUE).
A11: 7 | B11: The sepsis coordinator already reviews visits with both signs. How many visits had exactly ONE of the two: a fever (TempF above 100.4) or tachycardia (HeartRate above 90), but not both? | C11: 189 | D11: =SUMPRODUCT(--((ED!F2:F424>100.4)<>(ED!G2:G424>90))) | E11: {=SUMPRODUCT(--((ED!F2:F424>100.4)<>(ED!G2:G424>90)))} | F11: "Exactly one of two" is XOR. =XOR(F2>100.4,G2>90) answers it for one row, so a helper column plus COUNTIF(range,TRUE) works. Over whole ranges, <> is XOR: TRUE<>FALSE is TRUE, while TRUE<>TRUE and FALSE<>FALSE are FALSE. Like AND and OR, the XOR function collapses a range into one value, so SUMPRODUCT(--XOR(range>…, range>…)) gives the wrong answer. Check: fever count + tachycardia count − 2 × both = exactly one.
A12: 8 | B12: Fill the yellow FastTrack column: "Fast Track" when ESILevel is 4 or 5 AND ArrivalMode is "Walk-In" AND the ChiefComplaint is NOT "Chest Pain" or "Shortness of Breath" (it is neither one). Every other visit is "Main ED". Start in N2. The gray cell counts your "Fast Track" rows. | C12: 136 | D12: =IF(AND(D2>=4,C2="Walk-In",NOT(OR(E2="Chest Pain",E2="Shortness of Breath"))),"Fast Track","Main ED") | E12: {=SUMPRODUCT((ED!D2:D424>=4)*(ED!C2:C424="Walk-In")*(ED!E2:E424<>"Chest Pain")*(ED!E2:E424<>"Shortness of Breath"))} | F12: AND needs all three parts to be TRUE. The third part, NOT(OR(complaint="Chest Pain", complaint="Shortness of Breath")), is TRUE only when the complaint is neither one. AND(…<>"Chest Pain", …<>"Shortness of Breath") is the same test written the other way round (De Morgan's law). ESILevel>=4 covers 4 and 5 because ESI only goes up to 5. Text comparisons ignore case, so "walk-in" also matches.
A13: 9 | B13: Fill the yellow SIRS column with a vital-sign SIRS score from 0 to 3: one point for an abnormal temperature (TempF above 100.4 OR below 96.8), one for HeartRate above 90, and one for RespRate above 20. Start in O2. The gray cell adds up your whole column. | C13: 397 | D13: =OR(F2>100.4,F2<96.8)+(G2>90)+(H2>20) | E13: {=SUMPRODUCT(((ED!F2:F424>100.4)+(ED!F2:F424<96.8))+(ED!G2:G424>90)+(ED!H2:H424>20))} | F13: When you do arithmetic on TRUE/FALSE, Excel treats TRUE as 1 and FALSE as 0, so adding three tests gives a score from 0 to 3 with no IF at all. The temperature point uses OR because *either* direction counts, but only once. If your column shows TRUE/FALSE instead of numbers, you used AND/OR around everything. The full SIRS criteria also include the white-blood-cell count, which isn't on this sheet.
A14: 10 | B14: How many visits are SIRS-positive, meaning a score of 2 or more in your SIRS column? | C14: 115 | D14: =COUNTIF(ED!O2:O424,">=2") | E14: {=SUMPRODUCT(--((((ED!F2:F424>100.4)+(ED!F2:F424<96.8))+(ED!G2:G424>90)+(ED!H2:H424>20))>=2))} | F14: Once the score is a number, COUNTIF can count any threshold. The key's live formula does the whole thing in one cell: it builds the score for every row as an array, then counts the rows where it is >=2.
A15: 11 | B15: Fill the yellow ESIName column with SWITCH: ESILevel 1 is "Resuscitation", 2 is "Emergent", 3 is "Urgent", 4 is "Less Urgent", 5 is "Non-Urgent". Start in P2. The gray cell counts your "Emergent" rows. | C15: 87 | D15: =SWITCH(D2,1,"Resuscitation",2,"Emergent",3,"Urgent",4,"Less Urgent",5,"Non-Urgent") | E15: {=SUMPRODUCT(--(ED!D2:D424=2))} | F15: SWITCH compares one value against a list and returns the result paired with the first exact match. It's shorter than five nested IFs, and you write the cell reference only once. Leaving out a default is a deliberate choice here. If a bad code like 6 ever appears, SWITCH returns #N/A and the problem stays visible.
A16: 12 | B16: Shock index = HeartRate ÷ SystolicBP, and 1.0 or more is a warning sign. Fill the yellow ShockIndex column, wrapping the division in IFERROR so the 12 visits with no SystolicBP show a blank ("") instead of #DIV/0!. Start in Q2. The gray cell counts visits with a shock index of 1.0 or higher (it asks you to fix any errors first). | C16: 54 | D16: =IFERROR(G2/I2,"") | E16: {=SUMPRODUCT((ED!I2:I424<>"")*(ED!G2:G424>=ED!I2:I424))} | F16: Dividing by an empty cell divides by zero, so those rows show #DIV/0!. IFERROR(G2/I2,"") returns the division when it works and an empty text string when it fails. COUNTIF then skips the blanks because they are text. =IF(I2="","",G2/I2) is an even better formula, because it handles the one problem you expect (a missing BP) and still lets any *other* mistake show up as an error.
A17: 13 | B17: Visit ED211716 (ED row 13) has no SystolicBP. In the yellow cell, calculate its shock index again, but wrap the division in IFNA(…, "") instead of IFERROR. The check turns green when your cell shows the error that IFNA lets through. | C17: #DIV/0! (IFNA traps only #N/A, so the divide-by-zero error passes through) | D17: =IFNA(ED!G13/ED!I13,"") | E17: — | F17: IFERROR catches every error type. IFNA catches only #N/A, the "value not available" error that lookups return when they can't find a match (Lesson 2.6). A divide-by-zero is a different error, so IFNA hands it straight back. That's the point of IFNA. It hides the one error you expect and leaves every other mistake visible.

Sheet Bonus Key
A1: 🔑 Bonus Key — Lesson 2.1
A2: Spoiler alert — try every task before reading this sheet. Column C is the value the Check column compares against. Column D is a sample solution; column E is that same formula, live, proving it works.
A4: # | B4: Task | C4: Answer | D4: Sample solution | E4: Live result | F4: Explanation
A5: B1 | B5: Fill the qSOFA column (0–3) on the ED sheet, starting in R2. The gray cell adds up your whole column. What is the total number of qSOFA points? | C5: 165 | D5: =(H2>=22)+AND(I2<>"",I2<=100)+OR(ISNUMBER(SEARCH("altered",E2)),ISNUMBER(SEARCH("confusion",E2))) | E5: {=SUMPRODUCT(((ED!H2:H424>=22)+(ED!I2:I424<>"")*(ED!I2:I424<=100)+ISNUMBER(SEARCH("altered",ED!E2:E424))+ISNUMBER(SEARCH("confusion",ED!E2:E424))))} | F5: Each part is a TRUE/FALSE test, and adding them gives the score. Watch for two traps. First, an empty cell counts as 0 in a comparison, so a bare I2<=100 gives a point to every visit with no BP. AND(I2<>"",I2<=100) scores only a recorded BP. Without that guard the 12 visits with no BP each gain a point, so the total is 177 instead of 165. Second, SEARCH returns the position of the text, or #VALUE! when it isn't there, so ISNUMBER(SEARCH(…)) turns that into TRUE/FALSE. SEARCH ignores case, so "altered" finds "Altered". Wrapping the two SEARCH tests in OR keeps the mentation point at 1 even if a complaint ever mentions both words.
A6: B2 | B6: How many visits are screen-positive (a qSOFA score of 2 or more)? | C6: 31 | D6: =COUNTIF(ED!R2:R424,">=2") | E6: {=SUMPRODUCT(--(((ED!H2:H424>=22)+(ED!I2:I424<>"")*(ED!I2:I424<=100)+ISNUMBER(SEARCH("altered",ED!E2:E424))+ISNUMBER(SEARCH("confusion",ED!E2:E424)))>=2))} | F6: Once the score is a number, COUNTIF counts any threshold. If your column scored the missing BPs, you'd count 35 here instead of 31, so the blank-cell guard changes a real quality number.
A7: B3 | B7: What was the average HeartRate of the screen-positive visits? Round to 1 decimal place. | C7: 115.8 | D7: =ROUND(AVERAGE(IF(ED!R2:R424>=2,ED!G2:G424)),1) | E7: {=ROUND(AVERAGE(IF(((ED!H2:H424>=22)+(ED!I2:I424<>"")*(ED!I2:I424<=100)+ISNUMBER(SEARCH("altered",ED!E2:E424))+ISNUMBER(SEARCH("confusion",ED!E2:E424)))>=2,ED!G2:G424)),1)} | F7: IF(range>=2, HeartRate) returns the heart rate for screen-positive rows and FALSE for the rest, and AVERAGE skips FALSE. Microsoft 365 and Excel 2021 evaluate this array formula automatically. In Excel 2019 and earlier, confirm it with Ctrl + Shift + Enter (Mac: ⌘ + Shift + Return). =AVERAGEIF(ED!R2:R424,">=2",ED!G2:G424) gives the same result.
A8: B4 | B8: Safety check: how many screen-positive visits ended with EDDisposition "Discharged" (sent home)? | C8: 19 | D8: =SUMPRODUCT((ED!R2:R424>=2)*(ED!L2:L424="Discharged")) | E8: {=SUMPRODUCT((((ED!H2:H424>=22)+(ED!I2:I424<>"")*(ED!I2:I424<=100)+ISNUMBER(SEARCH("altered",ED!E2:E424))+ISNUMBER(SEARCH("confusion",ED!E2:E424)))>=2)*(ED!L2:L424="Discharged"))} | F8: Multiplying the two lists keeps a 1 only where both are TRUE (AND logic), and SUMPRODUCT counts them. These are the charts a sepsis committee would pull for review, because the patients screened positive but went home.
A9: B5 | B9: The two screens don't always agree. How many visits are qSOFA screen-positive (2 or more) but NOT SIRS-positive (SIRS score below 2 in your SIRS column from task 9)? | C9: 3 | D9: =SUMPRODUCT((ED!R2:R424>=2)*(ED!O2:O424<2)) | E9: {=SUMPRODUCT((((ED!H2:H424>=22)+(ED!I2:I424<>"")*(ED!I2:I424<=100)+ISNUMBER(SEARCH("altered",ED!E2:E424))+ISNUMBER(SEARCH("confusion",ED!E2:E424)))>=2)*((((ED!F2:F424>100.4)+(ED!F2:F424<96.8))+(ED!G2:G424>90)+(ED!H2:H424>20))<2))} | F9: NOT(score>=2) is the same as score<2, so you don't need the NOT function over a range. SIRS looks at temperature, heart rate, and breathing. qSOFA looks at breathing, blood pressure, and mental status. Each catches patients the other misses, which is why hospitals don't rely on one screen alone.
