Workbook

Sheet Start Here
B2: Lesson 1.6
B3: Sorting & Filtering Data
B4: Beginner · about 45 minutes · Bluestone Health System (fictional)
B6: What you'll learn
B7: • | C7: Sort by one or several columns, including custom orders
B8: • | C8: Filter text, numbers, and dates with AutoFilter (and Top 10, by color)
B9: • | C9: Summarize only visible rows with SUBTOTAL and AGGREGATE
B10: • | C10: Use Advanced Filter for complex AND/OR criteria and unique lists
B12: How to use this workbook
B13: 1. Read the guide | C13: The lesson guide (README) explains each skill with examples: https://github.com/lmansf/learn-excel/tree/main/01-foundations/06-sorting-filtering
B14: 2. Practice | C14: Go to the 'Practice' sheet. Type a formula or value into each yellow cell.
B15: 3. Check yourself | C15: The Check column shows ✔ Correct (green) or ✘ Not yet (red).
B16: 4. Bonus | C16: Finished? Try the harder 'Bonus' sheet.
B17: 5. Answers | C17: The 'Answer Key' and 'Bonus Key' sheets are hidden. Right-click any sheet tab → Unhide… → pick one → OK. (Try first!)
B18: Note | C18: EDVisits is a plain range on purpose (not an Excel Table), so you turn AutoFilter on yourself with Ctrl+Shift+L (Mac: ⌘+Shift+F). Rows shaded orange were flagged by the triage sepsis screen.
B19: Note | C19: To put the rows back in their original order at any time, sort by EDVisitID A to Z (IDs follow arrival order).
B20: Note | C20: Use the Workspace sheet for Advanced Filter criteria ranges and results, and for trying the guide's formulas. The gray labels in its row 3 show where each task's cells go.
B22: Color legend
B23: Yellow cell | C23: Your answer goes here.
B24: ✔ Correct | C24: Your answer matches the key.
B25: ✘ Not yet | C25: Not matching yet. Check the hint and try again.
B27: Sheets in this workbook
B28: EDVisits | C28: Data: 937 rows
B29: About the data | C29: All 937 emergency department visits at Cedar Ridge Medical Center in 2025: arrival time, day and hour, arrival mode, ESI triage level, chief complaint, two triage vital signs, a shock index formula, door-to-provider minutes, and disposition. Rows shaded orange were flagged by the triage sepsis screen.
B30: Disclaimer | C30: All people, places, and numbers are synthetic and fictional. Not clinical guidance.

Sheet Practice
A1: Lesson 1.6 · Practice
A2: Every task uses the EDVisits sheet: 937 visits in rows 2–938, columns A–M. For tasks 1–10, sort or filter, then type what you see in the yellow cell: an ID, a row number, a count, or a value. Before each new filter task, clear the filters left over from the task before (Data → Clear). Tasks 9 and 10 use the Workspace sheet. Tasks 11 and 12 need an ESI 3 filter left on, so do them last.
A3: Type a formula or value in each yellow cell. The Check column turns green when your answer matches. Stuck? Read the hint, then the lesson guide. Answers: right-click a sheet tab → Unhide… → 'Answer Key'.
A4: ="Score: "&COUNTIF(E6:E17,"✔*")&" of 12 auto-checked tasks correct"
A5: # | B5: Task | C5: Hint | D5: Your Answer | E5: Check
A6: 1 | B6: Sort the EDVisits sheet by DoorToProviderMin, Largest to Smallest. Which EDVisitID is now in row 2? (That's the visit with the longest wait from arrival to first provider contact.) | C6: Click one cell in the column, then use the Z→A button | E6: =IF(IFERROR(D6="",FALSE),"",IF(IFERROR(OR(LOWER(TRIM(D6&""))=LOWER(TRIM('Answer Key'!$C$5&""))),FALSE),"✔ Correct","✘ Not yet"))
A7: 2 | B7: Use the Sort dialog (Data → Sort) to sort by three levels: ESILevel Smallest to Largest, then DoorToProviderMin Largest to Smallest, then ArrivalDateTime Oldest to Newest. Which EDVisitID is in row 11? | C7: Data → Sort, then Add Level twice. The top level wins | E7: =IF(IFERROR(D7="",FALSE),"",IF(IFERROR(OR(LOWER(TRIM(D7&""))=LOWER(TRIM('Answer Key'!$C$6&""))),FALSE),"✔ Correct","✘ Not yet"))
A8: 3 | B8: Sort by ArrivalDay using the built-in custom list Sun, Mon, Tue, Wed, Thu, Fri, Sat (Sort dialog → Order → Custom List…). On which row does the first Wednesday (Wed) visit appear? Type the row number. | C8: Sunday, Monday and Tuesday visits come first | E8: =IF(IFERROR(D8="",FALSE),"",IF(IFERROR(AND(ISNUMBER(D8),OR(ABS(D8-'Answer Key'!$C$7)<=0.0001)),FALSE),"✔ Correct","✘ Not yet"))
A9: 4 | B9: Turn on AutoFilter (Ctrl+Shift+L; Mac: ⌘+Shift+F). Show only visits with ArrivalMode = Ambulance and ESILevel 1 or 2. How many visits are visible? | C9: Filter two columns, then read the status bar | E9: =IF(IFERROR(D9="",FALSE),"",IF(IFERROR(AND(ISNUMBER(D9),OR(ABS(D9-'Answer Key'!$C$8)<=0.0001)),FALSE),"✔ Correct","✘ Not yet"))
A10: 5 | B10: Clear the filters (Data → Clear). Use the Search box in the ChiefComplaint filter to show every visit whose complaint contains the word fever anywhere. How many visits are visible? | C10: Type in the Search box, then check which items it ticks before you click OK | E10: =IF(IFERROR(D10="",FALSE),"",IF(IFERROR(AND(ISNUMBER(D10),OR(ABS(D10-'Answer Key'!$C$9)<=0.0001)),FALSE),"✔ Correct","✘ Not yet"))
A11: 6 | B11: Clear the filters. Use Number Filters → Top 10 on DoorToProviderMin to show the 10 longest waits. What is the smallest DoorToProviderMin still visible (the 10th-longest wait), in minutes? | C11: After the Top 10 filter, Minimum on the status bar finds the smallest visible wait | E11: =IF(IFERROR(D11="",FALSE),"",IF(IFERROR(AND(ISNUMBER(D11),OR(ABS(D11-'Answer Key'!$C$10)<=0.0001)),FALSE),"✔ Correct","✘ Not yet"))
A12: 7 | B12: Clear the filters. Show only visits that arrived in November 2025 on a Saturday or Sunday. How many are there? | C12: Date tree for the month, then ArrivalDay for the weekend | E12: =IF(IFERROR(D12="",FALSE),"",IF(IFERROR(AND(ISNUMBER(D12),OR(ABS(D12-'Answer Key'!$C$11)<=0.0001)),FALSE),"✔ Correct","✘ Not yet"))
A13: 8 | B13: Clear the filters. Rows shaded orange are visits that triage flagged as a positive sepsis screen. Filter to the orange rows, then also keep only those with DoorToProviderMin greater than 30. How many flagged visits waited more than 30 minutes to see a provider? | C13: Filter by Color, then Number Filters → Greater Than | E13: =IF(IFERROR(D13="",FALSE),"",IF(IFERROR(AND(ISNUMBER(D13),OR(ABS(D13-'Answer Key'!$C$12)<=0.0001)),FALSE),"✔ Correct","✘ Not yet"))
A14: 9 | B14: Clear the filters. Use Advanced Filter to find visits that were ESI level 1 OR waited more than 120 minutes for a provider. Type the criteria range in Workspace!A4:B6. Then, with the Workspace sheet active, choose Data → Advanced and copy the results to Workspace!D4. How many visits does it copy? Don't count the header. | C14: Conditions on different rows of the criteria range mean OR | E14: =IF(IFERROR(D14="",FALSE),"",IF(IFERROR(AND(ISNUMBER(D14),OR(ABS(D14-'Answer Key'!$C$13)<=0.0001)),FALSE),"✔ Correct","✘ Not yet"))
A15: 10 | B15: Use Advanced Filter with Unique records only to copy a list of the different ChiefComplaint values to Workspace!S4. How many different chief complaints are there? Don't count the header. | C15: List range: the ChiefComplaint column only. Empty the Criteria range box | E15: =IF(IFERROR(D15="",FALSE),"",IF(IFERROR(AND(ISNUMBER(D15),OR(ABS(D15-'Answer Key'!$C$14)<=0.0001)),FALSE),"✔ Correct","✘ Not yet"))
A16: 11 | B16: Filter EDVisits to ESILevel 3 only, with no other filters on. In the yellow cell, write a formula that averages DoorToProviderMin for the visible rows only, rounded to 1 decimal place with ROUND. Leave the filter on for task 12. | C16: SUBTOTAL's AVERAGE is function_num 1 (or 101) | E16: =IF(IFERROR(D16="",FALSE),"",IF(IFERROR(AND(ISNUMBER(D16),OR(ABS(D16-'Answer Key'!$C$15)<=0.0001)),FALSE),"✔ Correct","✘ Not yet"))
A17: 12 | B17: Keep the ESI 3 filter on. ShockIndex (HeartRate ÷ SystolicBP) shows #DIV/0! where no blood pressure was recorded, so =SUBTOTAL(104,EDVisits!K2:K938) returns #DIV/0!. In the yellow cell, write an AGGREGATE formula that returns the highest ShockIndex among the visible rows while ignoring the errors. Don't round it. | C17: MAX is function 4. Pick the option that ignores hidden rows AND error values | E17: =IF(IFERROR(D17="",FALSE),"",IF(IFERROR(AND(ISNUMBER(D17),OR(ABS(D17-'Answer Key'!$C$16)<=0.0051)),FALSE),"✔ Correct","✘ Not yet"))

Sheet EDVisits
A1: EDVisitID | B1: PatientID | C1: ArrivalDateTime | D1: ArrivalDay | E1: ArrivalHour | F1: ArrivalMode | G1: ESILevel | H1: ChiefComplaint | I1: HeartRate | J1: SystolicBP | K1: ShockIndex | L1: DoorToProviderMin | M1: EDDisposition
A2: ED206077 | B2: PT13365 | C2: 45658.251 | D2: Wed | E2: 6 | F2: Walk-In | G2: 4 | H2: Ankle Injury | I2: 74 | J2: 135 | K2: =I2/J2 | L2: 19 | M2: Discharged
A3: ED206081 | B3: PT11101 | C3: 45658.556 | D3: Wed | E3: 13 | F3: Walk-In | G3: 2 | H3: Shortness of Breath | I3: 76 | J3: 123 | K3: =I3/J3 | L3: 30 | M3: Admitted
A4: ED206087 | B4: PT10252 | C4: 45658.984 | D4: Wed | E4: 23 | F4: Ambulance | G4: 4 | H4: Nausea | I4: 94 | J4: 127 | K4: =I4/J4 | L4: 50 | M4: Discharged
A5: ED206088 | B5: PT12695 | C5: 45659.424 | D5: Thu | E5: 10 | F5: Walk-In | G5: 2 | H5: Cough / Fever | I5: 112 | J5: 114 | K5: =I5/J5 | L5: 26 | M5: Admitted
A6: ED206098 | B6: PT10695 | C6: 45659.758 | D6: Thu | E6: 18 | F6: Walk-In | G6: 4 | H6: Vomiting / Diarrhea | I6: 85 | J6: 123 | K6: =I6/J6 | L6: 52 | M6: Discharged
A7: ED206146 | B7: PT12933 | C7: 45662.503 | D7: Sun | E7: 12 | F7: Walk-In | G7: 4 | H7: Head Injury | I7: 86 | K7: =I7/J7 | M7: LWBS
A8: ED206148 | B8: PT11889 | C8: 45662.545 | D8: Sun | E8: 13 | F8: Ambulance | G8: 2 | H8: Shortness of Breath | I8: 91 | J8: 112 | K8: =I8/J8 | L8: 17 | M8: Admitted
A9: ED206151 | B9: PT13715 | C9: 45662.59 | D9: Sun | E9: 14 | F9: Walk-In | G9: 3 | H9: Cough / Fever | I9: 115 | J9: 105 | K9: =I9/J9 | L9: 88 | M9: Admitted
A10: ED206158 | B10: PT11204 | C10: 45662.918 | D10: Sun | E10: 22 | F10: Ambulance | G10: 2 | H10: Shortness of Breath | I10: 93 | J10: 133 | K10: =I10/J10 | L10: 9 | M10: Admitted
A11: ED206166 | B11: PT10002 | C11: 45663.377 | D11: Mon | E11: 9 | F11: Walk-In | G11: 3 | H11: Painful Urination / Fever | I11: 82 | J11: 135 | K11: =I11/J11 | L11: 20 | M11: Discharged
A12: ED206186 | B12: PT10855 | C12: 45663.776 | D12: Mon | E12: 18 | F12: Walk-In | G12: 4 | H12: Vomiting / Dizziness | I12: 84 | J12: 162 | K12: =I12/J12 | L12: 46 | M12: Admitted
A13: ED206191 | B13: PT12542 | C13: 45664.458 | D13: Tue | E13: 11 | F13: Walk-In | G13: 2 | H13: Cough / Fever | I13: 103 | J13: 136 | K13: =I13/J13 | L13: 41 | M13: Discharged
A14: ED206195 | B14: PT11582 | C14: 45664.565 | D14: Tue | E14: 13 | F14: Walk-In | G14: 3 | H14: Abdominal Pain | I14: 78 | J14: 127 | K14: =I14/J14 | L14: 65 | M14: Discharged
A15: ED206210 | B15: PT11138 | C15: 45665.358 | D15: Wed | E15: 8 | F15: Walk-In | G15: 3 | H15: Painful Urination / Fever | I15: 76 | J15: 116 | K15: =I15/J15 | L15: 50 | M15: Admitted
A16: ED206226 | B16: PT13009 | C16: 45666.103 | D16: Thu | E16: 2 | F16: Walk-In | G16: 5 | H16: Back Pain | I16: 86 | J16: 120 | K16: =I16/J16 | L16: 32 | M16: Discharged
A17: ED206228 | B17: PT11104 | C17: 45666.248 | D17: Thu | E17: 5 | F17: Walk-In | G17: 4 | H17: Cough / Fever | I17: 72 | J17: 144 | K17: =I17/J17 | L17: 51 | M17: Discharged
A18: ED206246 | B18: PT11114 | C18: 45666.984 | D18: Thu | E18: 23 | F18: Ambulance | G18: 2 | H18: Bloody Stool / Vomiting Blood | I18: 89 | J18: 91 | K18: =I18/J18 | L18: 19 | M18: Observation
A19: ED206248 | B19: PT10715 | C19: 45667.212 | D19: Fri | E19: 5 | F19: Walk-In | G19: 2 | H19: Fever / Altered Mental Status | I19: 133 | J19: 81 | K19: =I19/J19 | L19: 10 | M19: Admitted
... A33: ED206332 | B33: PT12484 | C33: 45670.594 | D33: Mon | E33: 14 | F33: Walk-In | G33: 3 | H33: Shortness of Breath | I33: 80 | J33: 145 | K33: =I33/J33 | L33: 107 | M33: Admitted
A34: ED206352 | B34: PT10219 | C34: 45671.645 | D34: Tue | E34: 15 | F34: Walk-In | G34: 4 | H34: Abdominal Pain | I34: 82 | K34: =I34/J34 | M34: LWBS
A35: ED206353 | B35: PT11403 | C35: 45671.647 | D35: Tue | E35: 15 | F35: Ambulance | G35: 2 | H35: Chest Pain | I35: 84 | J35: 158 | K35: =I35/J35 | L35: 12 | M35: Discharged
A36: ED206364 | B36: PT11719 | C36: 45672.444 | D36: Wed | E36: 10 | F36: Walk-In | G36: 4 | H36: Cough / Fever | I36: 106 | K36: =I36/J36 | M36: LWBS
A37: ED206369 | B37: PT12494 | C37: 45672.653 | D37: Wed | E37: 15 | F37: Walk-In | G37: 3 | H37: Shortness of Breath | I37: 109 | J37: 121 | K37: =I37/J37 | L37: 63 | M37: Admitted
A38: ED206371 | B38: PT10171 | C38: 45672.7 | D38: Wed | E38: 16 | F38: Walk-In | G38: 3 | H38: High Blood Sugar | I38: 106 | J38: 129 | K38: =I38/J38 | L38: 55 | M38: Admitted
A39: ED206373 | B39: PT12893 | C39: 45672.801 | D39: Wed | E39: 19 | F39: Walk-In | G39: 4 | H39: Abdominal Pain | I39: 76 | J39: 103 | K39: =I39/J39 | L39: 39 | M39: Observation
A40: ED206375 | B40: PT10610 | C40: 45672.846 | D40: Wed | E40: 20 | F40: Ambulance | G40: 3 | H40: Painful Urination / Fever | I40: 86 | J40: 134 | K40: =I40/J40 | L40: 24 | M40: Admitted
A41: ED206379 | B41: PT12636 | C41: 45673.003 | D41: Thu | E41: 0 | F41: Walk-In | G41: 3 | H41: Palpitations | I41: 139 | J41: 112 | K41: =I41/J41 | L41: 40 | M41: Admitted
A42: ED206380 | B42: PT13821 | C42: 45673.219 | D42: Thu | E42: 5 | F42: Ambulance | G42: 1 | H42: Fever / Altered Mental Status | I42: 89 | J42: 74 | K42: =I42/J42 | L42: 3 | M42: Admitted
A43: ED206396 | B43: PT10120 | C43: 45673.94 | D43: Thu | E43: 22 | F43: Walk-In | G43: 3 | H43: Painful Urination / Fever | I43: 72 | J43: 143 | K43: =I43/J43 | L43: 66 | M43: Discharged
A44: ED206401 | B44: PT13751 | C44: 45674.378 | D44: Fri | E44: 9 | F44: Walk-In | G44: 2 | H44: Shortness of Breath | I44: 82 | J44: 158 | K44: =I44/J44 | L44: 17 | M44: Observation
A45: ED206412 | B45: PT13940 | C45: 45674.722 | D45: Fri | E45: 17 | F45: Walk-In | G45: 3 | H45: Cough / Fever | I45: 105 | J45: 113 | K45: =I45/J45 | L45: 62 | M45: Observation
A46: ED206426 | B46: PT13603 | C46: 45675.466 | D46: Sat | E46: 11 | F46: Walk-In | G46: 2 | H46: Shortness of Breath | I46: 94 | J46: 112 | K46: =I46/J46 | L46: 10 | M46: Admitted
A47: ED206433 | B47: PT12325 | C47: 45676.386 | D47: Sun | E47: 9 | F47: Walk-In | G47: 3 | H47: Chest Pain | I47: 79 | J47: 149 | K47: =I47/J47 | L47: 34 | M47: Observation
A48: ED206446 | B48: PT11842 | C48: 45676.869 | D48: Sun | E48: 20 | F48: Walk-In | G48: 4 | H48: Cough / Fever | I48: 71 | J48: 143 | K48: =I48/J48 | L48: 89 | M48: Discharged
... A153: ED207185 | B153: PT11876 | C153: 45712.51 | D153: Mon | E153: 12 | F153: Walk-In | G153: 3 | H153: Shortness of Breath | I153: 128 | J153: 78 | K153: =I153/J153 | L153: 51 | M153: Discharged
A154: ED207191 | B154: PT11433 | C154: 45712.637 | D154: Mon | E154: 15 | F154: Walk-In | G154: 3 | H154: Abdominal Pain | I154: 90 | K154: =I154/J154 | M154: LWBS
A155: ED207193 | B155: PT10786 | C155: 45712.665 | D155: Mon | E155: 15 | F155: Walk-In | G155: 5 | H155: Cough / Fever | I155: 95 | J155: 101 | K155: =I155/J155 | L155: 60 | M155: Discharged
A156: ED207194 | B156: PT12858 | C156: 45712.674 | D156: Mon | E156: 16 | F156: Walk-In | G156: 2 | H156: Laceration | I156: 89 | J156: 127 | K156: =I156/J156 | L156: 18 | M156: Admitted
A157: ED207204 | B157: PT12787 | C157: 45713.214 | D157: Tue | E157: 5 | F157: Walk-In | G157: 4 | H157: Cough / Fever | I157: 90 | J157: 119 | K157: =I157/J157 | L157: 29 | M157: Discharged
...

Sheet Workspace
A1: Workspace: Advanced Filter criteria and results
A2: Copy header names from row 1 of EDVisits so they match exactly. Start Data → Advanced from this sheet when the results should land here.
A3: Task 9 criteria: A4:B6 | D3: Task 9 results: copy to D4 | S3: Task 10 list: copy to S4 | U3: Bonus criteria: U4:W6
A8: Free cells for the guide's examples: A9 and below

Sheet Bonus
A1: Lesson 1.6 · Bonus: the high-acuity evening review
A2: Cedar Ridge's ED medical director is preparing a high-acuity review for the quality committee. It covers every ESI 1 visit, plus ESI 2 patients who arrived by ambulance in the evening (ArrivalHour 18 or later, which means 6:00 pm to 11:59 pm). That rule is an OR across different columns, so AutoFilter can't do it in one step. Your practice task 11 and 12 formulas follow the ESI 3 filter, so they switch to ✘ when you clear it. That's expected. To keep them green, first copy each of those two answer cells and paste it back as a value. Then clear every filter on EDVisits (Data → Clear), insert a new sheet named Review, type the criteria range in Workspace!U4:W6, and run Data → Advanced from the Review sheet to copy the matching rows to Review!A1.
A3: Type a formula or value in each yellow cell. The Check column turns green when your answer matches. Stuck? Read the hint, then the lesson guide. Answers: right-click a sheet tab → Unhide… → 'Bonus Key'.
A4: ="Score: "&COUNTIF(E6:E9,"✔*")&" of 4 auto-checked tasks correct"
A5: # | B5: Task | C5: Hint | D5: Your Answer | E5: Check
A6: B1 | B6: How many visits does your Advanced Filter copy to the Review sheet? Don't count the header row. | C6: Two criteria rows: ESI 1 alone, and ESI 2 + Ambulance + >=18 together | E6: =IF(IFERROR(D6="",FALSE),"",IF(IFERROR(AND(ISNUMBER(D6),OR(ABS(D6-'Bonus Key'!$C$5)<=0.0001)),FALSE),"✔ Correct","✘ Not yet"))
A7: B2 | B7: In the yellow cell, write a formula for the average DoorToProviderMin of the review visits, rounded to 1 decimal place. | C7: AVERAGE over column L of the Review sheet | E7: =IF(IFERROR(D7="",FALSE),"",IF(IFERROR(AND(ISNUMBER(D7),OR(ABS(D7-'Bonus Key'!$C$6)<=0.0001)),FALSE),"✔ Correct","✘ Not yet"))
A8: B3 | B8: The director lists dispositions by level of care. Create the custom list Admitted, Observation, Transferred, Discharged, Left AMA, LWBS. Sort the Review sheet by EDDisposition with that list, then by DoorToProviderMin Largest to Smallest. Which EDVisitID is in row 44 of the Review sheet? | C8: Order → Custom List… → NEW LIST | E8: =IF(IFERROR(D8="",FALSE),"",IF(IFERROR(OR(LOWER(TRIM(D8&""))=LOWER(TRIM('Bonus Key'!$C$7&""))),FALSE),"✔ Correct","✘ Not yet"))
A9: B4 | B9: CMS reports ED wait times as medians, because a few very long waits pull an average up. Filter the Review sheet to ESILevel 2 only. Then, in the yellow cell, write an AGGREGATE formula that returns the median DoorToProviderMin of the visible Review rows. | C9: SUBTOTAL has no median, but AGGREGATE function 12 does | E9: =IF(IFERROR(D9="",FALSE),"",IF(IFERROR(AND(ISNUMBER(D9),OR(ABS(D9-'Bonus Key'!$C$8)<=0.0001)),FALSE),"✔ Correct","✘ Not yet"))

Sheet Answer Key
A1: 🔑 Answer Key — Lesson 1.6
A2: Spoiler alert: try every task before reading this sheet. Column C is the value the Check column compares against. Column D is a sample solution, and column E recalculates a formula for it live, proving the answer.
A4: # | B4: Task | C4: Answer | D4: Sample solution | E4: Live result | F4: Explanation
A5: 1 | B5: Sort the EDVisits sheet by DoorToProviderMin, Largest to Smallest. Which EDVisitID is now in row 2? (That's the visit with the longest wait from arrival to first provider contact.) | C5: ED208970 | D5: 1. Click any cell in column L (DoorToProviderMin), for example L2. 2. Click Data → Sort Z to A (the Z→A button). On a number column, the Home → Sort & Filter menu calls the same command Sort Largest to Smallest. Because you clicked a single cell, Excel sorts the whole block of data with it. 3. Read A2: ED208970, a wait of 299 minutes. | E5: {=INDEX(EDVisits!$A$2:$A$938,MATCH(MAX(EDVisits!$L$2:$L$938),EDVisits!$L$2:$L$938,0))} | F5: Clicking one cell (not selecting the column) lets Excel find the whole data block and keep every row together. Scroll to the bottom: the 15 LWBS visits with a blank wait sit in rows 924–938. Excel always sorts blanks last, whether you sort ascending or descending.
A6: 2 | B6: Use the Sort dialog (Data → Sort) to sort by three levels: ESILevel Smallest to Largest, then DoorToProviderMin Largest to Smallest, then ArrivalDateTime Oldest to Newest. Which EDVisitID is in row 11? | C6: ED208106 | D6: 1. Click any cell in the data and choose Data → Sort. Check that My data has headers is ticked. 2. Sort by ESILevel, Sort On Cell Values, Order Smallest to Largest. 3. Click Add Level: Then by DoorToProviderMin, Largest to Smallest. 4. Click Add Level again: Then by ArrivalDateTime, Oldest to Newest. Click OK. 5. Read A11: ED208106. | E6: {=INDEX(_xlfn.SORTBY(EDVisits!$A$2:$A$938,EDVisits!$G$2:$G$938,1,EDVisits!$L$2:$L$938,-1,EDVisits!$C$2:$C$938,1),10)} | F6: The first level groups the 23 ESI 1 visits at the top (rows 2–24). Inside that group the second level puts the longest waits first. Several ESI 1 patients waited exactly 3 minutes, so the third level (arrival time) breaks the tie. Without a tiebreaker, rows that tie on every level stay in whatever order they happened to be in, which depends on your earlier sorts.
A7: 3 | B7: Sort by ArrivalDay using the built-in custom list Sun, Mon, Tue, Wed, Thu, Fri, Sat (Sort dialog → Order → Custom List…). On which row does the first Wednesday (Wed) visit appear? Type the row number. | C7: 433 | D7: 1. Data → Sort. If levels from task 2 are still listed, select each one and click Delete Level. 2. Sort by ArrivalDay, Sort On Cell Values, Order Custom List…. 3. In the Custom Lists box pick Sun, Mon, Tue, Wed, Thu, Fri, Sat, then OK twice. 4. Scroll down column D until the days change from Tue to Wed: row 433. | E7: {=COUNTIF(EDVisits!$D$2:$D$938,"Sun")+COUNTIF(EDVisits!$D$2:$D$938,"Mon")+COUNTIF(EDVisits!$D$2:$D$938,"Tue")+2} | F7: A custom list sorts in the order you give it, not alphabetically. Sunday (142 visits), Monday (152) and Tuesday (137) fill rows 2–432, so Wednesday starts in row 433. An A→Z sort would have put the days in the order Fri, Mon, Sat, Sun, Thu, Tue, Wed, and the first Wednesday would land in row 801.
A8: 4 | B8: Turn on AutoFilter (Ctrl+Shift+L; Mac: ⌘+Shift+F). Show only visits with ArrivalMode = Ambulance and ESILevel 1 or 2. How many visits are visible? | C8: 137 | D8: 1. Click any cell in the data and press Ctrl+Shift+L (Mac: ⌘+Shift+F), or choose Data → Filter. 2. Open the ArrivalMode arrow, untick (Select All), tick Ambulance, OK. 3. Open the ESILevel arrow, untick 3, 4 and 5 (or use Number Filters → Less Than Or Equal To → 2), OK. 4. The status bar reads 137 of 937 records found. | E8: {=COUNTIFS(EDVisits!$F$2:$F$938,"Ambulance",EDVisits!$G$2:$G$938,"<=2")} | F8: Filters on different columns combine with AND: a row stays visible only if it passes every column's filter. Ticking 1 and 2 inside one column is OR within that column. If the status bar shows Filter Mode instead of a count, select A2:A938 and read Count on the status bar.
A9: 5 | B9: Clear the filters (Data → Clear). Use the Search box in the ChiefComplaint filter to show every visit whose complaint contains the word fever anywhere. How many visits are visible? | C9: 266 | D9: 1. Data → Clear removes the filters from task 4 but keeps the filter arrows. 2. Open the ChiefComplaint arrow and type fever in the Search box. 3. The list shrinks to 3 items (Cough / Fever, Fever / Altered Mental Status, Painful Urination / Fever). Click OK. 4. The status bar reads 266 of 937 records found. | E9: {=COUNTIF(EDVisits!$H$2:$H$938,"*fever*")} | F9: The Search box matches text anywhere in the value and ignores case, so it finds complaints that start, end, or contain fever. It works the same as Text Filters → Contains. Always glance at the ticked items before clicking OK, because a search can catch values you didn't intend.
A10: 6 | B10: Clear the filters. Use Number Filters → Top 10 on DoorToProviderMin to show the 10 longest waits. What is the smallest DoorToProviderMin still visible (the 10th-longest wait), in minutes? | C10: 160 | D10: 1. Data → Clear. 2. Open the DoorToProviderMin arrow → Number Filters → Top 10…. 3. Leave Top, 10, Items and click OK. 4. Ten rows remain. Select L2:L938 and read Minimum on the status bar, which skips filtered-out rows (right-click the status bar to turn Minimum on, as in Lesson 1.1). Or sort the column Largest to Smallest and look at the last visible row. Either way it's 160 minutes. | E10: {=LARGE(EDVisits!$L$2:$L$938,10)} | F10: Top 10 keeps the rows whose value is at least the 10th largest. Here the 10th-longest wait is 160 minutes, so exactly ten rows stay visible. If several rows had tied at the cut-off value, Excel would show all of them, so a Top 10 filter can show more than ten rows. The same dialog does Bottom 10 and Top 10 Percent.
A11: 7 | B11: Clear the filters. Show only visits that arrived in November 2025 on a Saturday or Sunday. How many are there? | C11: 26 | D11: 1. Data → Clear. 2. Open the ArrivalDateTime arrow. In the date tree, untick (Select All), expand 2025, tick November, OK. (Or use Date Filters → All Dates in the Period → November.) 3. The status bar shows 80 November visits. Now open the ArrivalDay arrow, keep only Sat and Sun, OK. 4. The status bar reads 26 of 937 records found. | E11: {=SUMPRODUCT((MONTH(EDVisits!$C$2:$C$938)=11)*((EDVisits!$D$2:$D$938="Sat")+(EDVisits!$D$2:$D$938="Sun")))} | F11: Excel groups real dates in the filter list by year, month, and day, so you can tick a whole month at once. There's no built-in weekend date filter, which is why ED exports often include a day-of-week column like ArrivalDay. Avoid Between 11/1/2025 and 11/30/2025 here: the values include times, and 11/30/2025 means midnight at the start of November 30, so visits later that day would be left out.
A12: 8 | B12: Clear the filters. Rows shaded orange are visits that triage flagged as a positive sepsis screen. Filter to the orange rows, then also keep only those with DoorToProviderMin greater than 30. How many flagged visits waited more than 30 minutes to see a provider? | C12: 29 | D12: 1. Data → Clear. 2. Open any column's arrow (EDVisitID works) → Filter by Color → pick the orange swatch under Filter by Cell Color. 68 rows remain. 3. Open the DoorToProviderMin arrow → Number Filters → Greater Than… → type 30 → OK. 4. The status bar reads 29 of 937 records found. | E12: — | F12: Color is the only marker for the sepsis flag, so Filter by Color is the only way to isolate those 68 rows. No worksheet function can read a fill color, which is why this task has no live formula in the key. Combining a color filter on one column with a number filter on another is still AND logic. Sepsis care is time-critical, so these are the waits a quality team reviews first.
A13: 9 | B13: Clear the filters. Use Advanced Filter to find visits that were ESI level 1 OR waited more than 120 minutes for a provider. Type the criteria range in Workspace!A4:B6. Then, with the Workspace sheet active, choose Data → Advanced and copy the results to Workspace!D4. How many visits does it copy? Don't count the header. | C13: 65 | D13: 1. Data → Clear on EDVisits. 2. On Workspace, type the criteria range in A4:B6. Copy the two headers from row 1 of EDVisits: | Row | A | B | |:-:|---|---| | 4 | ESILevel | DoorToProviderMin | | 5 | 1 | | | 6 | | >120 | 3. Still on Workspace, click D4, then choose Data → Advanced. Select Copy to another location. List range: EDVisits!$A$1:$M$938. Criteria range: Workspace!$A$4:$B$6. Copy to: Workspace!$D$4. OK. 4. The copy has a header row plus 65 visit rows. | E13: {=SUMPRODUCT(--(((EDVisits!$G$2:$G$938=1)+(EDVisits!$L$2:$L$938>120))>0))} | F13: Each criteria row is one way to qualify. Row 5 catches the 23 ESI 1 visits and row 6 catches the 42 waits over 120 minutes. No ESI 1 patient waited that long, so the two groups don't overlap here. When they do, a visit that meets both rows is copied once, not twice. AutoFilter can't do this, because filters on two columns always combine with AND. The criteria headers must match the data headers exactly, so copy them from row 1 of EDVisits rather than typing them.
A14: 10 | B14: Use Advanced Filter with Unique records only to copy a list of the different ChiefComplaint values to Workspace!S4. How many different chief complaints are there? Don't count the header. | C14: 28 | D14: 1. On Workspace, click S4 and choose Data → Advanced. 2. Select Copy to another location. List range: EDVisits!$H$1:$H$938 (just that one column, header included). 3. Make the Criteria range box empty: Excel may fill in Workspace!$A$4:$B$6 from task 9, so delete it. Copy to: Workspace!$S$4. Tick Unique records only. OK. 4. The list has a header plus 28 complaints. Select them and read Count on the status bar. | E14: {=SUMPRODUCT(1/COUNTIF(EDVisits!$H$2:$H$938,EDVisits!$H$2:$H$938))} | F14: With an empty criteria range every row qualifies, and Unique records only keeps the first copy of each distinct value. Because the list range is a single column, the duplicates are judged on that column alone. With the whole table as the list range, a row would only count as a duplicate if every column matched.
A15: 11 | B15: Filter EDVisits to ESILevel 3 only, with no other filters on. In the yellow cell, write a formula that averages DoorToProviderMin for the visible rows only, rounded to 1 decimal place with ROUND. Leave the filter on for task 12. | C15: 51.7 | D15: =ROUND(SUBTOTAL(101,EDVisits!L2:L938),1) | E15: {=ROUND(AVERAGEIFS(EDVisits!$L$2:$L$938,EDVisits!$G$2:$G$938,3),1)} | F15: SUBTOTAL skips rows hidden by a filter, so it looks only at the 399 ESI 3 visits. Function 1 would work too, because both 1 and 101 ignore filtered-out rows (101 also ignores rows you hide by hand). AVERAGE-type functions skip blank cells, so the 6 ESI 3 LWBS visits with no wait don't drag the average toward zero. Plain AVERAGE would ignore the filter and average all 922 waits. The key's live cell uses AVERAGEIFS (Lesson 2.5) so it works without a filter. If you clear the filter later, this check turns red, which shows SUBTOTAL responding to the filter. To keep the result, copy the cell and paste it back as a value.
A16: 12 | B16: Keep the ESI 3 filter on. ShockIndex (HeartRate ÷ SystolicBP) shows #DIV/0! where no blood pressure was recorded, so =SUBTOTAL(104,EDVisits!K2:K938) returns #DIV/0!. In the yellow cell, write an AGGREGATE formula that returns the highest ShockIndex among the visible rows while ignoring the errors. Don't round it. | C16: 1.6410256 | D16: =AGGREGATE(4,7,EDVisits!K2:K938) | E16: {=_xlfn.AGGREGATE(14,6,EDVisits!$K$2:$K$938/(EDVisits!$G$2:$G$938=3),1)} | F16: AGGREGATE(4, 7, range) means MAX (4) while ignoring hidden rows and error values (7). The 6 visible #DIV/0! cells come from LWBS patients whose blood pressure wasn't recorded. SUBTOTAL and MAX return an error as soon as the range holds one, while AGGREGATE steps over it. Option 6 would ignore errors but include the hidden rows, giving the highest shock index of the whole year. A shock index near or above 1.0 suggests the heart is racing to keep blood pressure up, which is why EDs watch it.

Sheet Bonus Key
A1: 🔑 Bonus Key — Lesson 1.6
A2: Spoiler alert: try every task before reading this sheet. Column C is the value the Check column compares against. Column D is a sample solution, and column E recalculates a formula for it live, proving the answer.
A4: # | B4: Task | C4: Answer | D4: Sample solution | E4: Live result | F4: Explanation
A5: B1 | B5: How many visits does your Advanced Filter copy to the Review sheet? Don't count the header row. | C5: 60 | D5: 1. Data → Clear on EDVisits. Insert a sheet with the + button next to the sheet tabs (or press Shift+F11; on a Mac laptop, Fn+Shift+F11), then double-click its tab and rename it Review. 2. On Workspace, type this criteria range in U4:W6, to the right of your task 10 list. Copy the headers from row 1 of EDVisits: | Row | U | V | W | |:-:|---|---|---| | 4 | ESILevel | ArrivalMode | ArrivalHour | | 5 | 1 | | | | 6 | 2 | Ambulance | >=18 | 3. Click Review!A1, then Data → Advanced → Copy to another location. List range EDVisits!$A$1:$M$938, Criteria range Workspace!$U$4:$W$6, Copy to Review!$A$1. OK. 4. Review shows a header plus 60 rows (rows 2–61). | E5: {=SUMPRODUCT(((EDVisits!$G$2:$G$938=1)+(EDVisits!$G$2:$G$938=2)*(EDVisits!$F$2:$F$938="Ambulance")*(EDVisits!$E$2:$E$938>=18)))} | F5: Row 5 of the criteria range (ESILevel = 1) catches all 23 ESI 1 visits. Row 6 is an AND: ESI 2 and Ambulance and ArrivalHour ≥ 18, which adds 37 more. The two rows together are OR. Excel only copies filtered data to the active sheet, so you must start Data → Advanced from the Review sheet, or Excel shows an error.
A6: B2 | B6: In the yellow cell, write a formula for the average DoorToProviderMin of the review visits, rounded to 1 decimal place. | C6: 15.8 | D6: =ROUND(AVERAGE(Review!L2:L61),1) (or =ROUND(AVERAGE(Review!L:L),1), because AVERAGE skips the text header). | E6: {=ROUND(SUMPRODUCT(((EDVisits!$G$2:$G$938=1)+(EDVisits!$G$2:$G$938=2)*(EDVisits!$F$2:$F$938="Ambulance")*(EDVisits!$E$2:$E$938>=18))*ISNUMBER(EDVisits!$L$2:$L$938),EDVisits!$L$2:$L$938)/SUMPRODUCT(((EDVisits!$G$2:$G$938=1)+(EDVisits!$G$2:$G$938=2)*(EDVisits!$F$2:$F$938="Ambulance")*(EDVisits!$E$2:$E$938>=18))*ISNUMBER(EDVisits!$L$2:$L$938)),1)} | F6: The Advanced Filter result is ordinary cells, so regular functions work on it. AVERAGE ignores text and blanks, so even a whole-column reference gives the right answer. The copy is a snapshot: if EDVisits changes, run the Advanced Filter again.
A7: B3 | B7: The director lists dispositions by level of care. Create the custom list Admitted, Observation, Transferred, Discharged, Left AMA, LWBS. Sort the Review sheet by EDDisposition with that list, then by DoorToProviderMin Largest to Smallest. Which EDVisitID is in row 44 of the Review sheet? | C7: ED207754 | D7: 1. On Review, click any cell in the data → Data → Sort. Sort by EDDisposition, Order Custom List…. 2. Select NEW LIST, type the six entries one per line (press Enter after each), click Add, then OK. 3. Add Level: Then by DoorToProviderMin, Largest to Smallest. OK. 4. Rows 2–43 hold the 42 Admitted visits, so row 44 is the first Observation visit: ED207754. | E7: {=INDEX(_xlfn.SORTBY(_xlfn._xlws.FILTER(EDVisits!$A$2:$A$938,((EDVisits!$G$2:$G$938=1)+(EDVisits!$G$2:$G$938=2)*(EDVisits!$F$2:$F$938="Ambulance")*(EDVisits!$E$2:$E$938>=18))),_xlfn.XMATCH(_xlfn._xlws.FILTER(EDVisits!$M$2:$M$938,((EDVisits!$G$2:$G$938=1)+(EDVisits!$G$2:$G$938=2)*(EDVisits!$F$2:$F$938="Ambulance")*(EDVisits!$E$2:$E$938>=18))),{"Admitted","Observation","Transferred","Discharged","Left AMA","LWBS"}),1,_xlfn._xlws.FILTER(EDVisits!$L$2:$L$938,((EDVisits!$G$2:$G$938=1)+(EDVisits!$G$2:$G$938=2)*(EDVisits!$F$2:$F$938="Ambulance")*(EDVisits!$E$2:$E$938>=18))),-1),43)} | F7: The review list holds 42 Admitted, 10 Observation and 8 Discharged visits, so the custom order puts Observation in rows 44–53. Row 44 is the Observation patient who waited longest (88 minutes). An A→Z sort would have put Discharged second, and a different visit in row 44. Every disposition appears in the list, even ones the review doesn't contain, so the list works on any month's data. Excel saves a custom list on your computer, so it's available in every workbook you open there.
A8: B4 | B8: CMS reports ED wait times as medians, because a few very long waits pull an average up. Filter the Review sheet to ESILevel 2 only. Then, in the yellow cell, write an AGGREGATE formula that returns the median DoorToProviderMin of the visible Review rows. | C8: 19 | D8: 1. On Review, press Ctrl+Shift+L (Mac: ⌘+Shift+F) and filter ESILevel to 2. 2. In the yellow B4 cell on the Bonus sheet, type =AGGREGATE(12,5,Review!L2:L61). The Bonus sheet isn't filtered, so the filter can't hide your formula. 3. It returns 19. | E8: {=MEDIAN(IF(((EDVisits!$G$2:$G$938=1)+(EDVisits!$G$2:$G$938=2)*(EDVisits!$F$2:$F$938="Ambulance")*(EDVisits!$E$2:$E$938>=18))*(EDVisits!$G$2:$G$938=2)*ISNUMBER(EDVisits!$L$2:$L$938),EDVisits!$L$2:$L$938))} | F8: AGGREGATE(12, 5, range) is MEDIAN (12) that ignores hidden rows (5). SUBTOTAL can't do this, because its eleven functions don't include MEDIAN, LARGE, SMALL, or PERCENTILE. The 37 ESI 2 evening ambulance patients had a median wait of 19 minutes but a mean of 23.7, because a few long waits pull the mean up. That gap is why CMS reports medians.
